Workbook

Sheet Master Goods Sheet
A1: Year | B1: Total London | C1: Total Outports | D1: Total
A2: Almonds, Bitter | B2: =SUMIFS(Antigua!$L:$L, Antigua!$B:$B, A2, Antigua!$D:$D, "London") + SUMIFS(Barbados!$L:$L, Barbados!$B:$B, A2, Barbados!$D:$D, "London") + SUMIFS(Bermuda!$L:$L, Bermuda!$B:$B, A2, Bermuda!$D:$D, "London") + SUMIFS(Jamaica!$L:$L, Jamaica!$B:$B, A2, Jamaica!$D:$D, "London") + SUMIFS(Mountserat!$L:$L, Mountserat!$B:$B, A2, Mountserat!$D:$D, "London") + SUMIFS(Nevis!$L:$L, Nevis!$B:$B, A2, Nevis!$D:$D, "London") -> 0 | C2: =SUMIFS(Antigua!$L:$L, Antigua!$B:$B, A2, Antigua!$D:$D, "Out Ports") + SUMIFS(Barbados!$L:$L, Barbados!$B:$B, A2, Barbados!$D:$D, "Out Ports") + SUMIFS(Bermuda!$L:$L, Bermuda!$B:$B, A2, Bermuda!$D:$D, "Out Ports") + SUMIFS(Jamaica!$L:$L, Jamaica!$B:$B, A2, Jamaica!$D:$D, "Out Ports") + SUMIFS(Mountserat!$L:$L, Mountserat!$B:$B, A2, Mountserat!$D:$D, "Out Ports") + SUMIFS(Nevis!$L:$L, Nevis!$B:$B, A2, Nevis!$D:$D, "Out Ports") -> 0 | D2: =B2+C2 -> 0
A3: Almonds, Sweet | B3: =SUMIFS(Antigua!$L:$L, Antigua!$B:$B, A3, Antigua!$D:$D, "London") + SUMIFS(Barbados!$L:$L, Barbados!$B:$B, A3, Barbados!$D:$D, "London") + SUMIFS(Bermuda!$L:$L, Bermuda!$B:$B, A3, Bermuda!$D:$D, "London") + SUMIFS(Jamaica!$L:$L, Jamaica!$B:$B, A3, Jamaica!$D:$D, "London") + SUMIFS(Mountserat!$L:$L, Mountserat!$B:$B, A3, Mountserat!$D:$D, "London") + SUMIFS(Nevis!$L:$L, Nevis!$B:$B, A3, Nevis!$D:$D, "London") -> 0 | C3: =SUMIFS(Antigua!$L:$L, Antigua!$B:$B, A3, Antigua!$D:$D, "Out Ports") + SUMIFS(Barbados!$L:$L, Barbados!$B:$B, A3, Barbados!$D:$D, "Out Ports") + SUMIFS(Bermuda!$L:$L, Bermuda!$B:$B, A3, Bermuda!$D:$D, "Out Ports") + SUMIFS(Jamaica!$L:$L, Jamaica!$B:$B, A3, Jamaica!$D:$D, "Out Ports") + SUMIFS(Mountserat!$L:$L, Mountserat!$B:$B, A3, Mountserat!$D:$D, "Out Ports") + SUMIFS(Nevis!$L:$L, Nevis!$B:$B, A3, Nevis!$D:$D, "Out Ports") -> 0 | D3: =B3+C3 -> 0
A4: Aloes Epatica | B4: =SUMIFS(Antigua!$L:$L, Antigua!$B:$B, A4, Antigua!$D:$D, "London") + SUMIFS(Barbados!$L:$L, Barbados!$B:$B, A4, Barbados!$D:$D, "London") + SUMIFS(Bermuda!$L:$L, Bermuda!$B:$B, A4, Bermuda!$D:$D, "London") + SUMIFS(Jamaica!$L:$L, Jamaica!$B:$B, A4, Jamaica!$D:$D, "London") + SUMIFS(Mountserat!$L:$L, Mountserat!$B:$B, A4, Mountserat!$D:$D, "London") + SUMIFS(Nevis!$L:$L, Nevis!$B:$B, A4, Nevis!$D:$D, "London") -> 0 | C4: =SUMIFS(Antigua!$L:$L, Antigua!$B:$B, A4, Antigua!$D:$D, "Out Ports") + SUMIFS(Barbados!$L:$L, Barbados!$B:$B, A4, Barbados!$D:$D, "Out Ports") + SUMIFS(Bermuda!$L:$L, Bermuda!$B:$B, A4, Bermuda!$D:$D, "Out Ports") + SUMIFS(Jamaica!$L:$L, Jamaica!$B:$B, A4, Jamaica!$D:$D, "Out Ports") + SUMIFS(Mountserat!$L:$L, Mountserat!$B:$B, A4, Mountserat!$D:$D, "Out Ports") + SUMIFS(Nevis!$L:$L, Nevis!$B:$B, A4, Nevis!$D:$D, "Out Ports") -> 0 | D4: =B4+C4 -> 0
A5: Annatto | B5: =SUMIFS(Antigua!$L:$L, Antigua!$B:$B, A5, Antigua!$D:$D, "London") + SUMIFS(Barbados!$L:$L, Barbados!$B:$B, A5, Barbados!$D:$D, "London") + SUMIFS(Bermuda!$L:$L, Bermuda!$B:$B, A5, Bermuda!$D:$D, "London") + SUMIFS(Jamaica!$L:$L, Jamaica!$B:$B, A5, Jamaica!$D:$D, "London") + SUMIFS(Mountserat!$L:$L, Mountserat!$B:$B, A5, Mountserat!$D:$D, "London") + SUMIFS(Nevis!$L:$L, Nevis!$B:$B, A5, Nevis!$D:$D, "London") -> 0.25669643 | C5: =SUMIFS(Antigua!$L:$L, Antigua!$B:$B, A5, Antigua!$D:$D, "Out Ports") + SUMIFS(Barbados!$L:$L, Barbados!$B:$B, A5, Barbados!$D:$D, "Out Ports") + SUMIFS(Bermuda!$L:$L, Bermuda!$B:$B, A5, Bermuda!$D:$D, "Out Ports") + SUMIFS(Jamaica!$L:$L, Jamaica!$B:$B, A5, Jamaica!$D:$D, "Out Ports") + SUMIFS(Mountserat!$L:$L, Mountserat!$B:$B, A5, Mountserat!$D:$D, "Out Ports") + SUMIFS(Nevis!$L:$L, Nevis!$B:$B, A5, Nevis!$D:$D, "Out Ports") -> 0 | D5: =B5+C5 -> 0.25669643
A6: Anniseeds | B6: =SUMIFS(Antigua!$L:$L, Antigua!$B:$B, A6, Antigua!$D:$D, "London") + SUMIFS(Barbados!$L:$L, Barbados!$B:$B, A6, Barbados!$D:$D, "London") + SUMIFS(Bermuda!$L:$L, Bermuda!$B:$B, A6, Bermuda!$D:$D, "London") + SUMIFS(Jamaica!$L:$L, Jamaica!$B:$B, A6, Jamaica!$D:$D, "London") + SUMIFS(Mountserat!$L:$L, Mountserat!$B:$B, A6, Mountserat!$D:$D, "London") + SUMIFS(Nevis!$L:$L, Nevis!$B:$B, A6, Nevis!$D:$D, "London") -> 0 | C6: =SUMIFS(Antigua!$L:$L, Antigua!$B:$B, A6, Antigua!$D:$D, "Out Ports") + SUMIFS(Barbados!$L:$L, Barbados!$B:$B, A6, Barbados!$D:$D, "Out Ports") + SUMIFS(Bermuda!$L:$L, Bermuda!$B:$B, A6, Bermuda!$D:$D, "Out Ports") + SUMIFS(Jamaica!$L:$L, Jamaica!$B:$B, A6, Jamaica!$D:$D, "Out Ports") + SUMIFS(Mountserat!$L:$L, Mountserat!$B:$B, A6, Mountserat!$D:$D, "Out Ports") + SUMIFS(Nevis!$L:$L, Nevis!$B:$B, A6, Nevis!$D:$D, "Out Ports") -> 0 | D6: =B6+C6 -> 0
A7: Archelia | B7: =SUMIFS(Antigua!$L:$L, Antigua!$B:$B, A7, Antigua!$D:$D, "London") + SUMIFS(Barbados!$L:$L, Barbados!$B:$B, A7, Barbados!$D:$D, "London") + SUMIFS(Bermuda!$L:$L, Bermuda!$B:$B, A7, Bermuda!$D:$D, "London") + SUMIFS(Jamaica!$L:$L, Jamaica!$B:$B, A7, Jamaica!$D:$D, "London") + SUMIFS(Mountserat!$L:$L, Mountserat!$B:$B, A7, Mountserat!$D:$D, "London") + SUMIFS(Nevis!$L:$L, Nevis!$B:$B, A7, Nevis!$D:$D, "London") -> 0 | C7: =SUMIFS(Antigua!$L:$L, Antigua!$B:$B, A7, Antigua!$D:$D, "Out Ports") + SUMIFS(Barbados!$L:$L, Barbados!$B:$B, A7, Barbados!$D:$D, "Out Ports") + SUMIFS(Bermuda!$L:$L, Bermuda!$B:$B, A7, Bermuda!$D:$D, "Out Ports") + SUMIFS(Jamaica!$L:$L, Jamaica!$B:$B, A7, Jamaica!$D:$D, "Out Ports") + SUMIFS(Mountserat!$L:$L, Mountserat!$B:$B, A7, Mountserat!$D:$D, "Out Ports") + SUMIFS(Nevis!$L:$L, Nevis!$B:$B, A7, Nevis!$D:$D, "Out Ports") -> 0 | D7: =B7+C7 -> 0
A8: Bacon | B8: =SUMIFS(Antigua!$L:$L, Antigua!$B:$B, A8, Antigua!$D:$D, "London") + SUMIFS(Barbados!$L:$L, Barbados!$B:$B, A8, Barbados!$D:$D, "London") + SUMIFS(Bermuda!$L:$L, Bermuda!$B:$B, A8, Bermuda!$D:$D, "London") + SUMIFS(Jamaica!$L:$L, Jamaica!$B:$B, A8, Jamaica!$D:$D, "London") + SUMIFS(Mountserat!$L:$L, Mountserat!$B:$B, A8, Mountserat!$D:$D, "London") + SUMIFS(Nevis!$L:$L, Nevis!$B:$B, A8, Nevis!$D:$D, "London") -> 0 | C8: =SUMIFS(Antigua!$L:$L, Antigua!$B:$B, A8, Antigua!$D:$D, "Out Ports") + SUMIFS(Barbados!$L:$L, Barbados!$B:$B, A8, Barbados!$D:$D, "Out Ports") + SUMIFS(Bermuda!$L:$L, Bermuda!$B:$B, A8, Bermuda!$D:$D, "Out Ports") + SUMIFS(Jamaica!$L:$L, Jamaica!$B:$B, A8, Jamaica!$D:$D, "Out Ports") + SUMIFS(Mountserat!$L:$L, Mountserat!$B:$B, A8, Mountserat!$D:$D, "Out Ports") + SUMIFS(Nevis!$L:$L, Nevis!$B:$B, A8, Nevis!$D:$D, "Out Ports") -> 0 | D8: =B8+C8 -> 0
A9: Balsam Artificial | B9: =SUMIFS(Antigua!$L:$L, Antigua!$B:$B, A9, Antigua!$D:$D, "London") + SUMIFS(Barbados!$L:$L, Barbados!$B:$B, A9, Barbados!$D:$D, "London") + SUMIFS(Bermuda!$L:$L, Bermuda!$B:$B, A9, Bermuda!$D:$D, "London") + SUMIFS(Jamaica!$L:$L, Jamaica!$B:$B, A9, Jamaica!$D:$D, "London") + SUMIFS(Mountserat!$L:$L, Mountserat!$B:$B, A9, Mountserat!$D:$D, "London") + SUMIFS(Nevis!$L:$L, Nevis!$B:$B, A9, Nevis!$D:$D, "London") -> 0 | C9: =SUMIFS(Antigua!$L:$L, Antigua!$B:$B, A9, Antigua!$D:$D, "Out Ports") + SUMIFS(Barbados!$L:$L, Barbados!$B:$B, A9, Barbados!$D:$D, "Out Ports") + SUMIFS(Bermuda!$L:$L, Bermuda!$B:$B, A9, Bermuda!$D:$D, "Out Ports") + SUMIFS(Jamaica!$L:$L, Jamaica!$B:$B, A9, Jamaica!$D:$D, "Out Ports") + SUMIFS(Mountserat!$L:$L, Mountserat!$B:$B, A9, Mountserat!$D:$D, "Out Ports") + SUMIFS(Nevis!$L:$L, Nevis!$B:$B, A9, Nevis!$D:$D, "Out Ports") -> 0 | D9: =B9+C9 -> 0
A10: Balsam Natural | B10: =SUMIFS(Antigua!$L:$L, Antigua!$B:$B, A10, Antigua!$D:$D, "London") + SUMIFS(Barbados!$L:$L, Barbados!$B:$B, A10, Barbados!$D:$D, "London") + SUMIFS(Bermuda!$L:$L, Bermuda!$B:$B, A10, Bermuda!$D:$D, "London") + SUMIFS(Jamaica!$L:$L, Jamaica!$B:$B, A10, Jamaica!$D:$D, "London") + SUMIFS(Mountserat!$L:$L, Mountserat!$B:$B, A10, Mountserat!$D:$D, "London") + SUMIFS(Nevis!$L:$L, Nevis!$B:$B, A10, Nevis!$D:$D, "London") -> 0 | C10: =SUMIFS(Antigua!$L:$L, Antigua!$B:$B, A10, Antigua!$D:$D, "Out Ports") + SUMIFS(Barbados!$L:$L, Barbados!$B:$B, A10, Barbados!$D:$D, "Out Ports") + SUMIFS(Bermuda!$L:$L, Bermuda!$B:$B, A10, Bermuda!$D:$D, "Out Ports") + SUMIFS(Jamaica!$L:$L, Jamaica!$B:$B, A10, Jamaica!$D:$D, "Out Ports") + SUMIFS(Mountserat!$L:$L, Mountserat!$B:$B, A10, Mountserat!$D:$D, "Out Ports") + SUMIFS(Nevis!$L:$L, Nevis!$B:$B, A10, Nevis!$D:$D, "Out Ports") -> 0 | D10: =B10+C10 -> 0
A11: Barbados Tarr | B11: =SUMIFS(Antigua!$L:$L, Antigua!$B:$B, A11, Antigua!$D:$D, "London") + SUMIFS(Barbados!$L:$L, Barbados!$B:$B, A11, Barbados!$D:$D, "London") + SUMIFS(Bermuda!$L:$L, Bermuda!$B:$B, A11, Bermuda!$D:$D, "London") + SUMIFS(Jamaica!$L:$L, Jamaica!$B:$B, A11, Jamaica!$D:$D, "London") + SUMIFS(Mountserat!$L:$L, Mountserat!$B:$B, A11, Mountserat!$D:$D, "London") + SUMIFS(Nevis!$L:$L, Nevis!$B:$B, A11, Nevis!$D:$D, "London") -> 0 | C11: =SUMIFS(Antigua!$L:$L, Antigua!$B:$B, A11, Antigua!$D:$D, "Out Ports") + SUMIFS(Barbados!$L:$L, Barbados!$B:$B, A11, Barbados!$D:$D, "Out Ports") + SUMIFS(Bermuda!$L:$L, Bermuda!$B:$B, A11, Bermuda!$D:$D, "Out Ports") + SUMIFS(Jamaica!$L:$L, Jamaica!$B:$B, A11, Jamaica!$D:$D, "Out Ports") + SUMIFS(Mountserat!$L:$L, Mountserat!$B:$B, A11, Mountserat!$D:$D, "Out Ports") + SUMIFS(Nevis!$L:$L, Nevis!$B:$B, A11, Nevis!$D:$D, "Out Ports") -> 0 | D11: =B11+C11 -> 0
A12: Barrel Staves | B12: =SUMIFS(Antigua!$L:$L, Antigua!$B:$B, A12, Antigua!$D:$D, "London") + SUMIFS(Barbados!$L:$L, Barbados!$B:$B, A12, Barbados!$D:$D, "London") + SUMIFS(Bermuda!$L:$L, Bermuda!$B:$B, A12, Bermuda!$D:$D, "London") + SUMIFS(Jamaica!$L:$L, Jamaica!$B:$B, A12, Jamaica!$D:$D, "London") + SUMIFS(Mountserat!$L:$L, Mountserat!$B:$B, A12, Mountserat!$D:$D, "London") + SUMIFS(Nevis!$L:$L, Nevis!$B:$B, A12, Nevis!$D:$D, "London") -> 0 | C12: =SUMIFS(Antigua!$L:$L, Antigua!$B:$B, A12, Antigua!$D:$D, "Out Ports") + SUMIFS(Barbados!$L:$L, Barbados!$B:$B, A12, Barbados!$D:$D, "Out Ports") + SUMIFS(Bermuda!$L:$L, Bermuda!$B:$B, A12, Bermuda!$D:$D, "Out Ports") + SUMIFS(Jamaica!$L:$L, Jamaica!$B:$B, A12, Jamaica!$D:$D, "Out Ports") + SUMIFS(Mountserat!$L:$L, Mountserat!$B:$B, A12, Mountserat!$D:$D, "Out Ports") + SUMIFS(Nevis!$L:$L, Nevis!$B:$B, A12, Nevis!$D:$D, "Out Ports") -> 0 | D12: =B12+C12 -> 0
A13: Bay Berries | B13: =SUMIFS(Antigua!$L:$L, Antigua!$B:$B, A13, Antigua!$D:$D, "London") + SUMIFS(Barbados!$L:$L, Barbados!$B:$B, A13, Barbados!$D:$D, "London") + SUMIFS(Bermuda!$L:$L, Bermuda!$B:$B, A13, Bermuda!$D:$D, "London") + SUMIFS(Jamaica!$L:$L, Jamaica!$B:$B, A13, Jamaica!$D:$D, "London") + SUMIFS(Mountserat!$L:$L, Mountserat!$B:$B, A13, Mountserat!$D:$D, "London") + SUMIFS(Nevis!$L:$L, Nevis!$B:$B, A13, Nevis!$D:$D, "London") -> 0 | C13: =SUMIFS(Antigua!$L:$L, Antigua!$B:$B, A13, Antigua!$D:$D, "Out Ports") + SUMIFS(Barbados!$L:$L, Barbados!$B:$B, A13, Barbados!$D:$D, "Out Ports") + SUMIFS(Bermuda!$L:$L, Bermuda!$B:$B, A13, Bermuda!$D:$D, "Out Ports") + SUMIFS(Jamaica!$L:$L, Jamaica!$B:$B, A13, Jamaica!$D:$D, "Out Ports") + SUMIFS(Mountserat!$L:$L, Mountserat!$B:$B, A13, Mountserat!$D:$D, "Out Ports") + SUMIFS(Nevis!$L:$L, Nevis!$B:$B, A13, Nevis!$D:$D, "Out Ports") -> 0 | D13: =B13+C13 -> 0
... A74: Wood, Sweetwood | B74: =SUMIFS(Antigua!$L:$L, Antigua!$B:$B, A74, Antigua!$D:$D, "London") + SUMIFS(Barbados!$L:$L, Barbados!$B:$B, A74, Barbados!$D:$D, "London") + SUMIFS(Bermuda!$L:$L, Bermuda!$B:$B, A74, Bermuda!$D:$D, "London") + SUMIFS(Jamaica!$L:$L, Jamaica!$B:$B, A74, Jamaica!$D:$D, "London") + SUMIFS(Mountserat!$L:$L, Mountserat!$B:$B, A74, Mountserat!$D:$D, "London") + SUMIFS(Nevis!$L:$L, Nevis!$B:$B, A74, Nevis!$D:$D, "London") -> 0 | C74: =SUMIFS(Antigua!$L:$L, Antigua!$B:$B, A74, Antigua!$D:$D, "Out Ports") + SUMIFS(Barbados!$L:$L, Barbados!$B:$B, A74, Barbados!$D:$D, "Out Ports") + SUMIFS(Bermuda!$L:$L, Bermuda!$B:$B, A74, Bermuda!$D:$D, "Out Ports") + SUMIFS(Jamaica!$L:$L, Jamaica!$B:$B, A74, Jamaica!$D:$D, "Out Ports") + SUMIFS(Mountserat!$L:$L, Mountserat!$B:$B, A74, Mountserat!$D:$D, "Out Ports") + SUMIFS(Nevis!$L:$L, Nevis!$B:$B, A74, Nevis!$D:$D, "Out Ports") -> 0 | D74: =B74+C74 -> 0

Sheet Antigua
A1: YEAR | B1: COMMODITY_NAME | C1: FROM_LOCATION | D1: TO_LOCATION | E1: ton | F1: hh | G1: quarter | H1: lb | J1: Total Pounds | L1: WEIGHT
A2: 1697 | B2: Annatto | C2: Antigua | D2: London | J2: =(E2*2240)+(F2*112)+(G2*28)+H2 -> 0 | L2: =J2/2240 -> 0
A3: 1697 | B3: Bees Wax | C3: Antigua | D3: London | J3: =(E3*2240)+(F3*112)+(G3*28)+H3 -> 0 | L3: =J3/2240 -> 0
A4: 1697 | B4: Brown Sugar | C4: Antigua | D4: London | F4: 6007 | J4: =(E4*2240)+(F4*112)+(G4*28)+H4 -> 672784 | L4: =J4/2240 -> 300.35
A5: 1697 | B5: Chocolate | C5: Antigua | D5: London | J5: =(E5*2240)+(F5*112)+(G5*28)+H5 -> 0 | L5: =J5/2240 -> 0
A6: 1697 | B6: Cocoa Nutts | C6: Antigua | D6: London | J6: =(E6*2240)+(F6*112)+(G6*28)+H6 -> 0 | L6: =J6/2240 -> 0
A7: 1697 | B7: Cotton | C7: Antigua | D7: London | H7: =13*200 -> 2600 | I7: 13 bags | J7: =(E7*2240)+(F7*112)+(G7*28)+H7 -> 2600 | L7: =J7/2240 -> 1.1607143
A8: 1697 | B8: Dry Ginger | C8: Antigua | D8: London | F8: 29 | J8: =(E8*2240)+(F8*112)+(G8*28)+H8 -> 3248 | L8: =J8/2240 -> 1.45
A9: 1697 | B9: Elephant Teeth | C9: Antigua | D9: London | J9: =(E9*2240)+(F9*112)+(G9*28)+H9 -> 0 | L9: =J9/2240 -> 0
A10: 1697 | B10: Indigo | C10: Antigua | D10: London | J10: =(E10*2240)+(F10*112)+(G10*28)+H10 -> 0 | L10: =J10/2240 -> 0
A11: 1697 | B11: Lignum Vitae | C11: Antigua | D11: London | F11: 230 | J11: =(E11*2240)+(F11*112)+(G11*28)+H11 -> 25760 | L11: =J11/2240 -> 11.5
A12: 1697 | B12: Lime Juice | C12: Antigua | D12: London | J12: =(E12*2240)+(F12*112)+(G12*28)+H12 -> 0 | L12: =J12/2240 -> 0
A13: 1697 | B13: Molasses | C13: Antigua | D13: London | J13: =(E13*2240)+(F13*112)+(G13*28)+H13 -> 0 | L13: =J13/2240 -> 0
A14: 1697 | B14: Pimento | C14: Antigua | D14: London | J14: =(E14*2240)+(F14*112)+(G14*28)+H14 -> 0 | L14: =J14/2240 -> 0
A15: 1697 | B15: Rice | C15: Antigua | D15: London | J15: =(E15*2240)+(F15*112)+(G15*28)+H15 -> 0 | L15: =J15/2240 -> 0
A16: 1697 | B16: Rum | C16: Antigua | D16: London | J16: =(E16*2240)+(F16*112)+(G16*28)+H16 -> 0 | L16: =J16/2240 -> 0
A17: 1697 | B17: Shruff | C17: Antigua | D17: London | J17: =(E17*2240)+(F17*112)+(G17*28)+H17 -> 0 | L17: =J17/2240 -> 0
A18: 1697 | B18: Succands | C18: Antigua | D18: London | J18: =(E18*2240)+(F18*112)+(G18*28)+H18 -> 0 | L18: =J18/2240 -> 0
A19: 1697 | B19: Tobacco | C19: Antigua | D19: London | H19: 11390 | J19: =(E19*2240)+(F19*112)+(G19*28)+H19 -> 11390 | L19: =J19/2240 -> 5.0848214
A20: 1697 | B20: Tortoise Shell | C20: Antigua | D20: London | J20: =(E20*2240)+(F20*112)+(G20*28)+H20 -> 0 | L20: =J20/2240 -> 0
A21: 1697 | B21: White Sugar | C21: Antigua | D21: London | G21: 1 | H21: 14 | J21: =(E21*2240)+(F21*112)+(G21*28)+H21 -> 42 | L21: =J21/2240 -> 0.01875
A22: 1697 | B22: Brown Sugar | C22: Antigua | D22: Out Ports | F22: 11100 | J22: =(E22*2240)+(F22*112)+(G22*28)+H22 -> 1243200 | L22: =J22/2240 -> 555
A23: 1697 | B23: Chocolate | C23: Antigua | D23: Out Ports | J23: =(E23*2240)+(F23*112)+(G23*28)+H23 -> 0 | L23: =J23/2240 -> 0
A24: 1697 | B24: Cocoa Nutts | C24: Antigua | D24: Out Ports | J24: =(E24*2240)+(F24*112)+(G24*28)+H24 -> 0 | L24: =J24/2240 -> 0
A25: 1697 | B25: Cotton | C25: Antigua | D25: Out Ports | F25: 203 | G25: 2 | J25: =(E25*2240)+(F25*112)+(G25*28)+H25 -> 22792 | L25: =J25/2240 -> 10.175
A26: 1697 | B26: Dry Ginger | C26: Antigua | D26: Out Ports | G26: 2 | J26: =(E26*2240)+(F26*112)+(G26*28)+H26 -> 56 | L26: =J26/2240 -> 0.025
A27: 1697 | B27: Elephant Teeth | C27: Antigua | D27: Out Ports | J27: =(E27*2240)+(F27*112)+(G27*28)+H27 -> 0 | L27: =J27/2240 -> 0
A28: 1697 | B28: Indigo | C28: Antigua | D28: Out Ports | H28: 216 | J28: =(E28*2240)+(F28*112)+(G28*28)+H28 -> 216 | L28: =J28/2240 -> 0.096428571
A29: 1697 | B29: Lignum Vitae | C29: Antigua | D29: Out Ports | F29: 307 | G29: 2 | J29: =(E29*2240)+(F29*112)+(G29*28)+H29 -> 34440 | L29: =J29/2240 -> 15.375
A30: 1697 | B30: Lime Juice | C30: Antigua | D30: Out Ports | J30: =(E30*2240)+(F30*112)+(G30*28)+H30 -> 0 | L30: =J30/2240 -> 0
A31: 1697 | B31: Madera Wine | C31: Antigua | D31: Out Ports | J31: =(E31*2240)+(F31*112)+(G31*28)+H31 -> 0 | L31: =J31/2240 -> 0
A32: 1697 | B32: Molasses | C32: Antigua | D32: Out Ports | J32: =(E32*2240)+(F32*112)+(G32*28)+H32 -> 0 | L32: =J32/2240 -> 0
A33: 1697 | B33: Pimento | C33: Antigua | D33: Out Ports | J33: =(E33*2240)+(F33*112)+(G33*28)+H33 -> 0 | L33: =J33/2240 -> 0
A34: 1697 | B34: Rice | C34: Antigua | D34: Out Ports | J34: =(E34*2240)+(F34*112)+(G34*28)+H34 -> 0 | L34: =J34/2240 -> 0
A35: 1697 | B35: Rum | C35: Antigua | D35: Out Ports | J35: =(E35*2240)+(F35*112)+(G35*28)+H35 -> 0 | L35: =J35/2240 -> 0
A36: 1697 | B36: Shruff | C36: Antigua | D36: Out Ports | J36: =(E36*2240)+(F36*112)+(G36*28)+H36 -> 0 | L36: =J36/2240 -> 0
A37: 1697 | B37: Succands | C37: Antigua | D37: Out Ports | H37: 55 | J37: =(E37*2240)+(F37*112)+(G37*28)+H37 -> 55 | L37: =J37/2240 -> 0.024553571
A38: 1697 | B38: Tobacco | C38: Antigua | D38: Out Ports | H38: 51383 | J38: =(E38*2240)+(F38*112)+(G38*28)+H38 -> 51383 | L38: =J38/2240 -> 22.938839
A39: 1697 | B39: Tortoise Shell | C39: Antigua | D39: Out Ports | J39: =(E39*2240)+(F39*112)+(G39*28)+H39 -> 0 | L39: =J39/2240 -> 0
A40: 1697 | B40: White Sugar | C40: Antigua | D40: Out Ports | F40: 11 | J40: =(E40*2240)+(F40*112)+(G40*28)+H40 -> 1232 | L40: =J40/2240 -> 0.55

Sheet Barbados
A1: YEAR | B1: COMMODITY_NAME | C1: FROM_LOCATION | D1: TO_LOCATION | E1: ton | F1: hh | G1: quarter | H1: lb | J1: Total Pounds | L1: WEIGHT
A2: 1697 | B2: Annatto | C2: Barbados | D2: London | J2: =(E2*2240)+(F2*112)+(G2*28)+H2 -> 0 | L2: =J2/2240 -> 0
A3: 1697 | B3: Bees Wax | C3: Barbados | D3: London | J3: =(E3*2240)+(F3*112)+(G3*28)+H3 -> 0 | L3: =J3/2240 -> 0
A4: 1697 | B4: Chocolate | C4: Barbados | D4: London | J4: =(E4*2240)+(F4*112)+(G4*28)+H4 -> 0 | L4: =J4/2240 -> 0
A5: 1697 | B5: Cocoa Nutts | C5: Barbados | D5: London | F5: 9 | H5: 26 | J5: =(E5*2240)+(F5*112)+(G5*28)+H5 -> 1034 | L5: =J5/2240 -> 0.46160714
A6: 1697 | B6: Cocoa Past | C6: Barbados | D6: London | J6: =(E6*2240)+(F6*112)+(G6*28)+H6 -> 0 | L6: =J6/2240 -> 0
A7: 1697 | B7: Corrants? Currants? | C7: Barbados | D7: London | J7: =(E7*2240)+(F7*112)+(G7*28)+H7 -> 0 | L7: =J7/2240 -> 0
A8: 1697 | B8: Cotton | C8: Barbados | D8: London | H8: =1104*200 -> 220800 | I8: 1104 bags | J8: =(E8*2240)+(F8*112)+(G8*28)+H8 -> 220800 | L8: =J8/2240 -> 98.571429
A9: 1697 | B9: Dry Ginger | C9: Barbados | D9: London | F9: 7237 | G9: 1 | H9: 17 | J9: =(E9*2240)+(F9*112)+(G9*28)+H9 -> 810589 | L9: =J9/2240 -> 361.87009
A10: 1697 | B10: Elephant Teeth | C10: Barbados | D10: London | F10: 114 | G10: 1 | H10: 14 | J10: =(E10*2240)+(F10*112)+(G10*28)+H10 -> 12810 | L10: =J10/2240 -> 5.71875
A11: 1697 | B11: Indigo | C11: Barbados | D11: London | H11: 407 | J11: =(E11*2240)+(F11*112)+(G11*28)+H11 -> 407 | L11: =J11/2240 -> 0.18169643
A12: 1697 | B12: Lemon Juice | C12: Barbados | D12: London | J12: =(E12*2240)+(F12*112)+(G12*28)+H12 -> 0 | L12: =J12/2240 -> 0
A13: 1697 | B13: Lignum Vitae | C13: Barbados | D13: London | J13: =(E13*2240)+(F13*112)+(G13*28)+H13 -> 0 | L13: =J13/2240 -> 0
A14: 1697 | B14: Lime Juice | C14: Barbados | D14: London | H14: 3411 | I14: 341 gal | J14: =(E14*2240)+(F14*112)+(G14*28)+H14 -> 3411 | L14: =J14/2240 -> 1.5227679
A15: 1697 | B15: Loaf Sugar | C15: Barbados | D15: London | F15: 12 | G15: 2 | J15: =(E15*2240)+(F15*112)+(G15*28)+H15 -> 1400 | L15: =J15/2240 -> 0.625
A16: 1697 | B16: Madera Wine | C16: Barbados | D16: London | J16: =(E16*2240)+(F16*112)+(G16*28)+H16 -> 0 | L16: =J16/2240 -> 0
A17: 1697 | B17: Molasses | C17: Barbados | D17: London | J17: =(E17*2240)+(F17*112)+(G17*28)+H17 -> 0 | L17: =J17/2240 -> 0
A18: 1697 | B18: Muscavado Sugar | C18: Barbados | D18: London | F18: 116316 | G18: 1 | H18: 17 | J18: =(E18*2240)+(F18*112)+(G18*28)+H18 -> 13027437 | L18: =J18/2240 -> 5815.8201
A19: 1697 | B19: Oranges | C19: Barbados | D19: London | J19: =(E19*2240)+(F19*112)+(G19*28)+H19 -> 0 | L19: =J19/2240 -> 0
A20: 1697 | B20: Raisins | C20: Barbados | D20: London | J20: =(E20*2240)+(F20*112)+(G20*28)+H20 -> 0 | L20: =J20/2240 -> 0
A21: 1697 | B21: Rice | C21: Barbados | D21: London | J21: =(E21*2240)+(F21*112)+(G21*28)+H21 -> 0 | L21: =J21/2240 -> 0
A22: 1697 | B22: Rum | C22: Barbados | D22: London | H22: 100 | I22: 10 gal | J22: =(E22*2240)+(F22*112)+(G22*28)+H22 -> 100 | L22: =J22/2240 -> 0.044642857
A23: 1697 | B23: Shruff | C23: Barbados | D23: London | F23: 19 | G23: 1 | H23: 2 | J23: =(E23*2240)+(F23*112)+(G23*28)+H23 -> 2158 | L23: =J23/2240 -> 0.96339286
A24: 1697 | B24: Succads | C24: Barbados | D24: London | H24: 3302 | J24: =(E24*2240)+(F24*112)+(G24*28)+H24 -> 3302 | L24: =J24/2240 -> 1.4741071
A25: 1697 | B25: Tobacco | C25: Barbados | D25: London | H25: 142 | J25: =(E25*2240)+(F25*112)+(G25*28)+H25 -> 142 | L25: =J25/2240 -> 0.063392857
A26: 1697 | B26: Tortoise Shell | C26: Barbados | D26: London | H26: 32 | J26: =(E26*2240)+(F26*112)+(G26*28)+H26 -> 32 | L26: =J26/2240 -> 0.014285714
A27: 1697 | B27: White Sugar | C27: Barbados | D27: London | F27: 3243 | H27: 25 | J27: =(E27*2240)+(F27*112)+(G27*28)+H27 -> 363241 | L27: =J27/2240 -> 162.16116
A28: 1697 | B28: Annatto | C28: Barbados | D28: Out Ports | J28: =(E28*2240)+(F28*112)+(G28*28)+H28 -> 0 | L28: =J28/2240 -> 0
A29: 1697 | B29: Chocolate | C29: Barbados | D29: Out Ports | J29: =(E29*2240)+(F29*112)+(G29*28)+H29 -> 0 | L29: =J29/2240 -> 0
A30: 1697 | B30: Cocoa Nutts | C30: Barbados | D30: Out Ports | F30: 1 | G30: 2 | J30: =(E30*2240)+(F30*112)+(G30*28)+H30 -> 168 | L30: =J30/2240 -> 0.075
A31: 1697 | B31: Cordage | C31: Barbados | D31: Out Ports | J31: =(E31*2240)+(F31*112)+(G31*28)+H31 -> 0 | L31: =J31/2240 -> 0
A32: 1697 | B32: Cotton | C32: Barbados | D32: Out Ports | F32: 295 | J32: =(E32*2240)+(F32*112)+(G32*28)+H32 -> 33040 | L32: =J32/2240 -> 14.75
A33: 1697 | B33: Dry Ginger | C33: Barbados | D33: Out Ports | F33: 1153 | H33: 23 | J33: =(E33*2240)+(F33*112)+(G33*28)+H33 -> 129159 | L33: =J33/2240 -> 57.660268
A34: 1697 | B34: Elephant Teeth | C34: Barbados | D34: Out Ports | J34: =(E34*2240)+(F34*112)+(G34*28)+H34 -> 0 | L34: =J34/2240 -> 0
A35: 1697 | B35: Indigo | C35: Barbados | D35: Out Ports | H35: 160 | J35: =(E35*2240)+(F35*112)+(G35*28)+H35 -> 160 | L35: =J35/2240 -> 0.071428571
A36: 1697 | B36: Lemon Juice | C36: Barbados | D36: Out Ports
A37: 1697 | B37: Lignum Vitae | C37: Barbados | D37: Out Ports | J37: =(E37*2240)+(F37*112)+(G37*28)+H37 -> 0 | L37: =J37/2240 -> 0
A38: 1697 | B38: Lime Juice | C38: Barbados | D38: Out Ports | H38: 1365 | I38: 136.5 gal | J38: =(E38*2240)+(F38*112)+(G38*28)+H38 -> 1365 | L38: =J38/2240 -> 0.609375
A39: 1697 | B39: Molasses | C39: Barbados | D39: Out Ports | J39: =(E39*2240)+(F39*112)+(G39*28)+H39 -> 0 | L39: =J39/2240 -> 0
A40: 1697 | B40: Muscavado Sugar | C40: Barbados | D40: Out Ports | F40: 10573 | G40: 1 | H40: 22 | J40: =(E40*2240)+(F40*112)+(G40*28)+H40 -> 1184226 | L40: =J40/2240 -> 528.67232
...

Sheet Bermuda
A1: YEAR | B1: COMMODITY_NAME | C1: FROM_LOCATION | D1: TO_LOCATION | E1: ton | F1: hh | G1: quarter | H1: lb | J1: Total Pounds | L1: WEIGHT
A2: 1697 | B2: Brown Sugar | C2: Bermuda | D2: London | F2: 1 | G2: 2 | J2: =(E2*2240)+(F2*112)+(G2*28)+H2 -> 168 | L2: =J2/2240 -> 0.075
A3: 1697 | B3: Elephant Teeth | C3: Bermuda | D3: London | J3: =(E3*2240)+(F3*112)+(G3*28)+H3 -> 0 | L3: =J3/2240 -> 0
A4: 1697 | B4: Indigo | C4: Bermuda | D4: London | J4: =(E4*2240)+(F4*112)+(G4*28)+H4 -> 0 | L4: =J4/2240 -> 0
A5: 1697 | B5: Lingum Vitae | C5: Bermuda | D5: London | F5: 16 | G5: 2 | J5: =(E5*2240)+(F5*112)+(G5*28)+H5 -> 1848 | L5: =J5/2240 -> 0.825
A6: 1697 | B6: Shruff | C6: Bermuda | D6: London | J6: =(E6*2240)+(F6*112)+(G6*28)+H6 -> 0 | L6: =J6/2240 -> 0
A7: 1697 | B7: Sugar Loaf | C7: Bermuda | D7: London | G7: 1 | J7: =(E7*2240)+(F7*112)+(G7*28)+H7 -> 28 | L7: =J7/2240 -> 0.0125
A8: 1697 | B8: Tobacco | C8: Bermuda | D8: London | H8: 30 | J8: =(E8*2240)+(F8*112)+(G8*28)+H8 -> 30 | L8: =J8/2240 -> 0.013392857
A9: 1697 | B9: Tortoise Shell | C9: Bermuda | D9: London | J9: =(E9*2240)+(F9*112)+(G9*28)+H9 -> 0 | L9: =J9/2240 -> 0
J10: =(E10*2240)+(F10*112)+(G10*28)+H10 -> 0
J11: =(E11*2240)+(F11*112)+(G11*28)+H11 -> 0

Sheet Carolina
A1: YEAR | B1: COMMODITY_NAME | C1: FROM_LOCATION | D1: TO_LOCATION | E1: ton | F1: hh | G1: quarter | H1: lb | J1: Total Pounds | L1: WEIGHT
A2: 1697 | B2: Brown Sugar | C2: Carolina | D2: London | J2: =(E2*2240)+(F2*112)+(G2*28)+H2 -> 0 | L2: =J2/2240 -> 0
A3: 1697 | B3: Cocoa Nuts | C3: Carolina | D3: London | J3: =(E3*2240)+(F3*112)+(G3*28)+H3 -> 0 | L3: =J3/2240 -> 0
A4: 1697 | B4: Dry Ginger | C4: Carolina | D4: London | J4: =(E4*2240)+(F4*112)+(G4*28)+H4 -> 0 | L4: =J4/2240 -> 0
A5: 1697 | B5: Elephant Teeth | C5: Carolina | D5: London | J5: =(E5*2240)+(F5*112)+(G5*28)+H5 -> 0 | L5: =J5/2240 -> 0
A6: 1697 | B6: Indigo | C6: Carolina | D6: London | J6: =(E6*2240)+(F6*112)+(G6*28)+H6 -> 0 | L6: =J6/2240 -> 0
A7: 1697 | B7: Pimento | C7: Carolina | D7: London | J7: =(E7*2240)+(F7*112)+(G7*28)+H7 -> 0 | L7: =J7/2240 -> 0
A8: 1697 | B8: Rice | C8: Carolina | D8: London | J8: =(E8*2240)+(F8*112)+(G8*28)+H8 -> 0 | L8: =J8/2240 -> 0
A9: 1697 | B9: Tobacco | C9: Carolina | D9: London | J9: =(E9*2240)+(F9*112)+(G9*28)+H9 -> 0 | L9: =J9/2240 -> 0
A10: 1697 | B10: Tortoise Shell | C10: Carolina | D10: London | J10: =(E10*2240)+(F10*112)+(G10*28)+H10 -> 0 | L10: =J10/2240 -> 0
A11: 1697 | B11: Cocoa Nuts | C11: Carolina | D11: Out Ports | F11: 7 | G11: 1 | J11: =(E11*2240)+(F11*112)+(G11*28)+H11 -> 812 | L11: =J11/2240 -> 0.3625
A12: 1697 | B12: Indigo | C12: Carolina | D12: Out Ports | H12: 14 | J12: =(E12*2240)+(F12*112)+(G12*28)+H12 -> 14 | L12: =J12/2240 -> 0.00625
A13: 1697 | B13: Muscovado Sugar | C13: Carolina | D13: Out Ports | F13: 61 | J13: =(E13*2240)+(F13*112)+(G13*28)+H13 -> 6832 | L13: =J13/2240 -> 3.05
A14: 1697 | B14: Rice | C14: Carolina | D14: Out Ports | F14: 2 | J14: =(E14*2240)+(F14*112)+(G14*28)+H14 -> 224 | L14: =J14/2240 -> 0.1
A15: 1697 | B15: Tobacco | C15: Carolina | D15: Out Ports | J15: =(E15*2240)+(F15*112)+(G15*28)+H15 -> 0 | L15: =J15/2240 -> 0
A16: 1697 | B16: Tortoise Shell | C16: Carolina | D16: Out Ports | J16: =(E16*2240)+(F16*112)+(G16*28)+H16 -> 0 | L16: =J16/2240 -> 0

Sheet Jamaica
A1: YEAR | B1: COMMODITY_NAME | C1: FROM_LOCATION | D1: TO_LOCATION | E1: ton | F1: hh | G1: quarter | H1: lb | J1: Total Pounds | L1: WEIGHT | O1: Total Not Sugar | Q1: Total Sugar
A2: 1697 | B2: Annatto | C2: Jamaica | D2: London | H2: 575 | J2: =(E2*2240)+(F2*112)+(G2*28)+H2 -> 575 | L2: =J2/2240 -> 0.25669643 | O2: =L2+L5+L6+L13+L14+L15+L16+L21+L22+L24+L28+L31+L32+L37+L39+L40+L41+L42+L43+L45+L48+L38+L47+L3+L4+L12+L17+L20+L26+L27+L30 -> 793.67857 | Q2: =L8+L11+L34+L35+L10+L33+L7+L9+L36 -> 27.322321
A3: 1697 | B3: Bees Wax | C3: Jamaica | D3: London | J3: =(E3*2240)+(F3*112)+(G3*28)+H3 -> 0 | L3: =J3/2240 -> 0
A4: 1697 | B4: Brandy | C4: Jamaica | D4: London | J4: =(E4*2240)+(F4*112)+(G4*28)+H4 -> 0 | L4: =J4/2240 -> 0
A5: 1697 | B5: Brown Sugar | C5: Jamaica | D5: London | J5: =(E5*2240)+(F5*112)+(G5*28)+H5 -> 0 | L5: =J5/2240 -> 0
A6: 1697 | B6: Cascarilla | C6: Jamaica | D6: London | J6: =(E6*2240)+(F6*112)+(G6*28)+H6 -> 0 | L6: =J6/2240 -> 0
A7: 1697 | B7: Chocolate | C7: Jamaica | D7: London | H7: 184 | J7: =(E7*2240)+(F7*112)+(G7*28)+H7 -> 184 | L7: =J7/2240 -> 0.082142857
A8: 1697 | B8: Cockeneal | C8: Jamaica | D8: London | J8: =(E8*2240)+(F8*112)+(G8*28)+H8 -> 0 | L8: =J8/2240 -> 0
A9: 1697 | B9: Cocoa Nutts | C9: Jamaica | D9: London | F9: 62 | G9: 1 | H9: 9 | J9: =(E9*2240)+(F9*112)+(G9*28)+H9 -> 6981 | L9: =J9/2240 -> 3.1165179
A10: 1697 | B10: Cotton | C10: Jamaica | D10: London | J10: =(E10*2240)+(F10*112)+(G10*28)+H10 -> 0 | L10: =J10/2240 -> 0
A11: 1697 | B11: Dry Ginger | C11: Jamaica | D11: London | F11: 371 | G11: 3 | H11: 14 | J11: =(E11*2240)+(F11*112)+(G11*28)+H11 -> 41650 | L11: =J11/2240 -> 18.59375
A12: 1697 | B12: Elephant Teeth | C12: Jamaica | D12: London | F12: 6 | G12: 3 | H12: 5 | J12: =(E12*2240)+(F12*112)+(G12*28)+H12 -> 761 | L12: =J12/2240 -> 0.33973214
A13: 1697 | B13: Indigo | C13: Jamaica | D13: London | H13: 70876 | J13: =(E13*2240)+(F13*112)+(G13*28)+H13 -> 70876 | L13: =J13/2240 -> 31.641071
A14: 1697 | B14: Lignum Vitae | C14: Jamaica | D14: London | E14: 13 | F14: 17 | J14: =(E14*2240)+(F14*112)+(G14*28)+H14 -> 31024 | L14: =J14/2240 -> 13.85
A15: 1697 | B15: Lime Juice | C15: Jamaica | D15: London | H15: 1760 | I15: 176g | J15: =(E15*2240)+(F15*112)+(G15*28)+H15 -> 1760 | L15: =J15/2240 -> 0.78571429
A16: 1697 | B16: Molasses | C16: Jamaica | D16: London | J16: =(E16*2240)+(F16*112)+(G16*28)+H16 -> 0 | L16: =J16/2240 -> 0
A17: 1697 | B17: Muscavado Sugar | C17: Jamaica | D17: London | F17: 6796 | G17: 3 | J17: =(E17*2240)+(F17*112)+(G17*28)+H17 -> 761236 | L17: =J17/2240 -> 339.8375
A18: 1697 | B18: Pimento | C18: Jamaica | D18: London | H18: 2372 | J18: =(E18*2240)+(F18*112)+(G18*28)+H18 -> 2372 | L18: =J18/2240 -> 1.0589286
A19: 1697 | B19: Rice | C19: Jamaica | D19: London | J19: =(E19*2240)+(F19*112)+(G19*28)+H19 -> 0 | L19: =J19/2240 -> 0
A20: 1697 | B20: Rum | C20: Jamaica | D20: London | J20: =(E20*2240)+(F20*112)+(G20*28)+H20 -> 0 | L20: =J20/2240 -> 0
A21: 1697 | B21: Sasparilla | C21: Jamaica | D21: London | J21: =(E21*2240)+(F21*112)+(G21*28)+H21 -> 0 | L21: =J21/2240 -> 0
A22: 1697 | B22: Shruff | C22: Jamaica | D22: London | F22: 1 | G22: 3 | H22: 21 | J22: =(E22*2240)+(F22*112)+(G22*28)+H22 -> 217 | L22: =J22/2240 -> 0.096875
A23: 1697 | B23: Snuff | C23: Jamaica | D23: London | J23: =(E23*2240)+(F23*112)+(G23*28)+H23 -> 0 | L23: =J23/2240 -> 0
A24: 1697 | B24: Succads | C24: Jamaica | D24: London | H24: 24 | J24: =(E24*2240)+(F24*112)+(G24*28)+H24 -> 24 | L24: =J24/2240 -> 0.010714286
A25: 1697 | B25: Sugar Loaf | C25: Jamaica | D25: London | J25: =(E25*2240)+(F25*112)+(G25*28)+H25 -> 0 | L25: =J25/2240 -> 0
A26: 1697 | B26: Tobacco | C26: Jamaica | D26: London | H26: 10 | J26: =(E26*2240)+(F26*112)+(G26*28)+H26 -> 10 | L26: =J26/2240 -> 0.0044642857
A27: 1697 | B27: Tortoise Shell | C27: Jamaica | D27: London | H27: 411 | J27: =(E27*2240)+(F27*112)+(G27*28)+H27 -> 411 | L27: =J27/2240 -> 0.18348214
A28: 1697 | B28: Vinellas | C28: Jamaica | D28: London | J28: =(E28*2240)+(F28*112)+(G28*28)+H28 -> 0 | L28: =J28/2240 -> 0
A29: 1697 | B29: White Sugar | C29: Jamaica | D29: London | F29: 27 | J29: =(E29*2240)+(F29*112)+(G29*28)+H29 -> 3024 | L29: =J29/2240 -> 1.35
A30: 1697 | B30: Chocolate | C30: Jamaica | D30: Out Ports | J30: =(E30*2240)+(F30*112)+(G30*28)+H30 -> 0 | L30: =J30/2240 -> 0
A31: 1697 | B31: Cocoa Nutts | C31: Jamaica | D31: Out Ports | F31: 5 | G31: 1 | J31: =(E31*2240)+(F31*112)+(G31*28)+H31 -> 588 | L31: =J31/2240 -> 0.2625
A32: 1697 | B32: Cotton | C32: Jamaica | D32: Out Ports | F32: 395 | G32: 2 | J32: =(E32*2240)+(F32*112)+(G32*28)+H32 -> 44296 | L32: =J32/2240 -> 19.775
A33: 1697 | B33: Dry Ginger | C33: Jamaica | D33: Out Ports | J33: =(E33*2240)+(F33*112)+(G33*28)+H33 -> 0 | L33: =J33/2240 -> 0
A34: 1697 | B34: Elephant Teeth | C34: Jamaica | D34: Out Ports | F34: 12 | J34: =(E34*2240)+(F34*112)+(G34*28)+H34 -> 1344 | L34: =J34/2240 -> 0.6
A35: 1697 | B35: Indigo | C35: Jamaica | D35: Out Ports | H35: 9979 | J35: =(E35*2240)+(F35*112)+(G35*28)+H35 -> 9979 | L35: =J35/2240 -> 4.4549107
A36: 1697 | B36: Lignum Vitae | C36: Jamaica | D36: Out Ports | F36: 9 | G36: 2 | J36: =(E36*2240)+(F36*112)+(G36*28)+H36 -> 1064 | L36: =J36/2240 -> 0.475
A37: 1697 | B37: Lime Juice | C37: Jamaica | D37: Out Ports | J37: =(E37*2240)+(F37*112)+(G37*28)+H37 -> 0 | L37: =J37/2240 -> 0
A38: 1697 | B38: Molasses | C38: Jamaica | D38: Out Ports | J38: =(E38*2240)+(F38*112)+(G38*28)+H38 -> 0 | L38: =J38/2240 -> 0
A39: 1697 | B39: Muscavado Sugar | C39: Jamaica | D39: Out Ports | F39: 7706 | G39: 1 | H39: 14 | J39: =(E39*2240)+(F39*112)+(G39*28)+H39 -> 863114 | L39: =J39/2240 -> 385.31875
A40: 1697 | B40: Pimento | C40: Jamaica | D40: Out Ports | H40: 2782 | J40: =(E40*2240)+(F40*112)+(G40*28)+H40 -> 2782 | L40: =J40/2240 -> 1.2419643
...

Sheet Mountserat
A1: YEAR | B1: COMMODITY_NAME | C1: FROM_LOCATION | D1: TO_LOCATION | E1: ton | F1: hh | G1: quarter | H1: lb | J1: Total Pounds | L1: WEIGHT
A2: 1697 | B2: Annatto | C2: Mountserat | D2: London | J2: =(E2*2240)+(F2*112)+(G2*28)+H2 -> 0 | L2: =J2/2240 -> 0
A3: 1697 | B3: Brown Sugar | C3: Mountserat | D3: London | F3: 1888 | G3: 2 | J3: =(E3*2240)+(F3*112)+(G3*28)+H3 -> 211512 | L3: =J3/2240 -> 94.425
A4: 1697 | B4: Cotton | C4: Mountserat | D4: London | H4: =2*200 -> 400 | I4: 2 bags | J4: =(E4*2240)+(F4*112)+(G4*28)+H4 -> 400 | L4: =J4/2240 -> 0.17857143
A5: 1697 | B5: Dry Ginger | C5: Mountserat | D5: London | J5: =(E5*2240)+(F5*112)+(G5*28)+H5 -> 0 | L5: =J5/2240 -> 0
A6: 1697 | B6: Elephants Teeth | C6: Mountserat | D6: London | J6: =(E6*2240)+(F6*112)+(G6*28)+H6 -> 0 | L6: =J6/2240 -> 0
A7: 1697 | B7: Indigo | C7: Mountserat | D7: London | H7: 4013 | J7: =(E7*2240)+(F7*112)+(G7*28)+H7 -> 4013 | L7: =J7/2240 -> 1.7915179
A8: 1697 | B8: Lignum Vitae | C8: Mountserat | D8: London | F8: 5 | J8: =(E8*2240)+(F8*112)+(G8*28)+H8 -> 560 | L8: =J8/2240 -> 0.25
A9: 1697 | B9: Lime Juice | C9: Mountserat | D9: London | H9: 1500 | I9: 150g | J9: =(E9*2240)+(F9*112)+(G9*28)+H9 -> 1500 | L9: =J9/2240 -> 0.66964286
A10: 1697 | B10: Molasses | C10: Mountserat | D10: London | J10: =(E10*2240)+(F10*112)+(G10*28)+H10 -> 0 | L10: =J10/2240 -> 0
A11: 1697 | B11: Muscovado Sugar | C11: Mountserat | D11: London | J11: =(E11*2240)+(F11*112)+(G11*28)+H11 -> 0 | L11: =J11/2240 -> 0
A12: 1697 | B12: Pimento | C12: Mountserat | D12: London | H12: 840 | J12: =(E12*2240)+(F12*112)+(G12*28)+H12 -> 840 | L12: =J12/2240 -> 0.375
A13: 1697 | B13: Rum | C13: Mountserat | D13: London | J13: =(E13*2240)+(F13*112)+(G13*28)+H13 -> 0 | L13: =J13/2240 -> 0
A14: 1697 | B14: Shruff | C14: Mountserat | D14: London | J14: =(E14*2240)+(F14*112)+(G14*28)+H14 -> 0 | L14: =J14/2240 -> 0
A15: 1697 | B15: Succands | C15: Mountserat | D15: London | J15: =(E15*2240)+(F15*112)+(G15*28)+H15 -> 0 | L15: =J15/2240 -> 0
A16: 1697 | B16: Sweet Almonds | C16: Mountserat | D16: London | J16: =(E16*2240)+(F16*112)+(G16*28)+H16 -> 0 | L16: =J16/2240 -> 0
A17: 1697 | B17: Tobacco | C17: Mountserat | D17: London | J17: =(E17*2240)+(F17*112)+(G17*28)+H17 -> 0 | L17: =J17/2240 -> 0
A18: 1697 | B18: Tortoise Shell | C18: Mountserat | D18: London | J18: =(E18*2240)+(F18*112)+(G18*28)+H18 -> 0 | L18: =J18/2240 -> 0
A19: 1697 | B19: White Sugar | C19: Mountserat | D19: London | J19: =(E19*2240)+(F19*112)+(G19*28)+H19 -> 0 | L19: =J19/2240 -> 0
A20: 1697 | B20: Cotton | C20: Mountserat | D20: Out Ports | F20: 65 | J20: =(E20*2240)+(F20*112)+(G20*28)+H20 -> 7280 | L20: =J20/2240 -> 3.25
A21: 1697 | B21: Dry Ginger | C21: Mountserat | D21: Out Ports | J21: =(E21*2240)+(F21*112)+(G21*28)+H21 -> 0 | L21: =J21/2240 -> 0
A22: 1697 | B22: Elephants Teeth | C22: Mountserat | D22: Out Ports | J22: =(E22*2240)+(F22*112)+(G22*28)+H22 -> 0 | L22: =J22/2240 -> 0
A23: 1697 | B23: Indigo | C23: Mountserat | D23: Out Ports | H23: 4500 | J23: =(E23*2240)+(F23*112)+(G23*28)+H23 -> 4500 | L23: =J23/2240 -> 2.0089286
A24: 1697 | B24: Lignum Vitae | C24: Mountserat | D24: Out Ports | J24: =(E24*2240)+(F24*112)+(G24*28)+H24 -> 0 | L24: =J24/2240 -> 0
A25: 1697 | B25: Lime Juice | C25: Mountserat | D25: Out Ports | H25: 125 | I25: 12.5g | J25: =(E25*2240)+(F25*112)+(G25*28)+H25 -> 125 | L25: =J25/2240 -> 0.055803571
A26: 1697 | B26: Molasses | C26: Mountserat | D26: Out Ports | J26: =(E26*2240)+(F26*112)+(G26*28)+H26 -> 0 | L26: =J26/2240 -> 0
A27: 1697 | B27: Muscovado Sugar | C27: Mountserat | D27: Out Ports | F27: 5929 | G27: 2 | J27: =(E27*2240)+(F27*112)+(G27*28)+H27 -> 664104 | L27: =J27/2240 -> 296.475
A28: 1697 | B28: Pimento | C28: Mountserat | D28: Out Ports | H28: 2222 | J28: =(E28*2240)+(F28*112)+(G28*28)+H28 -> 2222 | L28: =J28/2240 -> 0.99196429
A29: 1697 | B29: Shruff | C29: Mountserat | D29: Out Ports | J29: =(E29*2240)+(F29*112)+(G29*28)+H29 -> 0 | L29: =J29/2240 -> 0
A30: 1697 | B30: White Sugar | C30: Mountserat | D30: Out Ports | J30: =(E30*2240)+(F30*112)+(G30*28)+H30 -> 0 | L30: =J30/2240 -> 0

Sheet Nevis
A1: YEAR | B1: COMMODITY_NAME | C1: FROM_LOCATION | D1: TO_LOCATION | E1: ton | F1: hh | G1: quarter | H1: lb | J1: Total Pounds | L1: WEIGHT
A2: 1697 | B2: Annatto | C2: Nevis | D2: London | J2: =(E2*2240)+(F2*112)+(G2*28)+H2 -> 0 | L2: =J2/2240 -> 0
A3: 1697 | B3: Chocolate | C3: Nevis | D3: London | J3: =(E3*2240)+(F3*112)+(G3*28)+(H3) -> 0 | L3: =J3/2240 -> 0
A4: 1697 | B4: Cocoa Nutts | C4: Nevis | D4: London | F4: 2 | G4: 4 | J4: =(E4*2240)+(F4*112)+(G4*28)+(H4) -> 336 | L4: =J4/2240 -> 0.15
A5: 1697 | B5: Cotton | C5: Nevis | D5: London | J5: =(E5*2240)+(F5*112)+(G5*28)+(H5) -> 0 | L5: =J5/2240 -> 0
A6: 1697 | B6: Elephant Teeth | C6: Nevis | D6: London | J6: =(E6*2240)+(F6*112)+(G6*28)+(H6) -> 0 | L6: =J6/2240 -> 0
A7: 1697 | B7: Indigo | C7: Nevis | D7: London | H7: 44 | J7: =(E7*2240)+(F7*112)+(G7*28)+(H7) -> 44 | L7: =J7/2240 -> 0.019642857
A8: 1697 | B8: Lignum Vitae | C8: Nevis | D8: London | J8: =(E8*2240)+(F8*112)+(G8*28)+(H8) -> 0 | L8: =J8/2240 -> 0
A9: 1697 | B9: Lime Juice | C9: Nevis | D9: London | J9: =(E9*2240)+(F9*112)+(G9*28)+(H9) -> 0 | L9: =J9/2240 -> 0
A10: 1697 | B10: Molasses | C10: Nevis | D10: London | J10: =(E10*2240)+(F10*112)+(G10*28)+(H10) -> 0 | L10: =J10/2240 -> 0
A11: 1697 | B11: Muscovado Sugar | C11: Nevis | D11: London | F11: 2804 | G11: 3 | H11: 14 | J11: =(E11*2240)+(F11*112)+(G11*28)+(H11) -> 314146 | L11: =J11/2240 -> 140.24375
A12: 1697 | B12: Rum | C12: Nevis | D12: London | J12: =(E12*2240)+(F12*112)+(G12*28)+(H12) -> 0 | L12: =J12/2240 -> 0
A13: 1697 | B13: Shruff | C13: Nevis | D13: London | J13: =(E13*2240)+(F13*112)+(G13*28)+(H13) -> 0 | L13: =J13/2240 -> 0
A14: 1697 | B14: Sope Berries | C14: Nevis | D14: London | J14: =(E14*2240)+(F14*112)+(G14*28)+(H14) -> 0 | L14: =J14/2240 -> 0
A15: 1697 | B15: Succads | C15: Nevis | D15: London | J15: =(E15*2240)+(F15*112)+(G15*28)+(H15) -> 0 | L15: =J15/2240 -> 0
A16: 1697 | B16: Tobacco | C16: Nevis | D16: London | J16: =(E16*2240)+(F16*112)+(G16*28)+(H16) -> 0 | L16: =J16/2240 -> 0
A17: 1697 | B17: Tortoise Shell | C17: Nevis | D17: London | J17: =(E17*2240)+(F17*112)+(G17*28)+(H17) -> 0 | L17: =J17/2240 -> 0
A18: 1697 | B18: White Sugar | C18: Nevis | D18: London | J18: =(E18*2240)+(F18*112)+(G18*28)+(H18) -> 0 | L18: =J18/2240 -> 0
A19: 1697 | B19: Brown Sugar | C19: Nevis | D19: Out Ports | J19: =(E19*2240)+(F19*112)+(G19*28)+(H19) -> 0 | L19: =J19/2240 -> 0
A20: 1697 | B20: Chocolate | C20: Nevis | D20: Out Ports | J20: =(E20*2240)+(F20*112)+(G20*28)+(H20) -> 0 | L20: =J20/2240 -> 0
A21: 1697 | B21: Cocoa Nutts | C21: Nevis | D21: Out Ports | F21: 1 | G21: 3 | H21: 23 | J21: =(E21*2240)+(F21*112)+(G21*28)+(H21) -> 219 | L21: =J21/2240 -> 0.097767857
A22: 1697 | B22: Cotton | C22: Nevis | D22: Out Ports | F22: 35 | J22: =(E22*2240)+(F22*112)+(G22*28)+(H22) -> 3920 | L22: =J22/2240 -> 1.75
A23: 1697 | B23: Indigo | C23: Nevis | D23: Out Ports | H23: 460 | J23: =(E23*2240)+(F23*112)+(G23*28)+(H23) -> 460 | L23: =J23/2240 -> 0.20535714
A24: 1697 | B24: Lignum Vitae | C24: Nevis | D24: Out Ports | F24: 5 | J24: =(E24*2240)+(F24*112)+(G24*28)+(H24) -> 560 | L24: =J24/2240 -> 0.25
A25: 1697 | B25: Lime Juice | C25: Nevis | D25: Out Ports
A26: 1697 | B26: Molasses | C26: Nevis | D26: Out Ports | J26: =(E26*2240)+(F26*112)+(G26*28)+(H26) -> 0 | L26: =J26/2240 -> 0
A27: 1697 | B27: Muscovado Sugar | C27: Nevis | D27: Out Ports | F27: 10177 | J27: =(E27*2240)+(F27*112)+(G27*28)+(H27) -> 1139824 | L27: =J27/2240 -> 508.85
A28: 1697 | B28: Shruff | C28: Nevis | D28: Out Ports | J28: =(E28*2240)+(F28*112)+(G28*28)+(H28) -> 0 | L28: =J28/2240 -> 0
A29: 1697 | B29: Succand | C29: Nevis | D29: Out Ports | J29: =(E29*2240)+(F29*112)+(G29*28)+(H29) -> 0 | L29: =J29/2240 -> 0
A30: 1697 | B30: Tortoise Shell | C30: Nevis | D30: Out Ports | J30: =(E30*2240)+(F30*112)+(G30*28)+(H30) -> 0 | L30: =J30/2240 -> 0
A31: 1697 | B31: White Sugar | C31: Nevis | D31: Out Ports | F31: 53 | J31: =(E31*2240)+(F31*112)+(G31*28)+(H31) -> 5936 | L31: =J31/2240 -> 2.65

Sheet New England
A1: YEAR | B1: COMMODITY_NAME | C1: FROM_LOCATION | D1: TO_LOCATION | E1: ton | F1: hh | G1: quarter | H1: lb | J1: Total Pounds | L1: WEIGHT
A2: 1697 | B2: Annatto | C2: NewEngland | D2: London | J2: =(E2*2240)+(F2*112)+(G2*28)+H2 -> 0 | L2: =J2/2240 -> 0
A3: 1697 | B3: Bayberry Wax | C3: NewEngland | D3: London | J3: =(E3*2240)+(F3*112)+(G3*28)+H3 -> 0 | L3: =J3/2240 -> 0
A4: 1697 | B4: Chocolate | C4: NewEngland | D4: London | J4: =(E4*2240)+(F4*112)+(G4*28)+H4 -> 0 | L4: =J4/2240 -> 0
A5: 1697 | B5: Cocoa Nutts | C5: NewEngland | D5: London | F5: 1 | G5: 1 | H5: 20 | J5: =(E5*2240)+(F5*112)+(G5*28)+H5 -> 160 | L5: =J5/2240 -> 0.071428571
A6: 1697 | B6: Cotton | C6: NewEngland | D6: London | H6: =27*200 -> 5400 | I6: 27bags | J6: =(E6*2240)+(F6*112)+(G6*28)+H6 -> 5400 | L6: =J6/2240 -> 2.4107143
A7: 1697 | B7: Dry Ginger | C7: NewEngland | D7: London | F7: 8 | G7: 3 | H7: 14 | J7: =(E7*2240)+(F7*112)+(G7*28)+H7 -> 994 | L7: =J7/2240 -> 0.44375
A8: 1697 | B8: Elephant Teeth | C8: NewEngland | D8: London | F8: 6 | G8: 2 | J8: =(E8*2240)+(F8*112)+(G8*28)+H8 -> 728 | L8: =J8/2240 -> 0.325
A9: 1697 | B9: Hopps | C9: NewEngland | D9: London | J9: =(E9*2240)+(F9*112)+(G9*28)+H9 -> 0 | L9: =J9/2240 -> 0
A10: 1697 | B10: Indigo | C10: NewEngland | D10: London | H10: 1315 | J10: =(E10*2240)+(F10*112)+(G10*28)+H10 -> 1315 | L10: =J10/2240 -> 0.58705357
A11: 1697 | B11: Lignum Vitae | C11: NewEngland | D11: London | F11: 77 | J11: =(E11*2240)+(F11*112)+(G11*28)+H11 -> 8624 | L11: =J11/2240 -> 3.85
A12: 1697 | B12: Lime Juice | C12: NewEngland | D12: London | J12: =(E12*2240)+(F12*112)+(G12*28)+H12 -> 0 | L12: =J12/2240 -> 0
A13: 1697 | B13: Molasses | C13: NewEngland | D13: London | J13: =(E13*2240)+(F13*112)+(G13*28)+H13 -> 0 | L13: =J13/2240 -> 0
A14: 1697 | B14: Muscavado Sugar | C14: NewEngland | D14: London | F14: 15435 | G14: 1 | H14: 7 | J14: =(E14*2240)+(F14*112)+(G14*28)+H14 -> 1728755 | L14: =J14/2240 -> 771.76562
A15: 1697 | B15: Pimento | C15: NewEngland | D15: London | J15: =(E15*2240)+(F15*112)+(G15*28)+H15 -> 0 | L15: =J15/2240 -> 0
A16: 1697 | B16: Shruff | C16: NewEngland | D16: London | F16: 39 | G16: 1 | J16: =(E16*2240)+(F16*112)+(G16*28)+H16 -> 4396 | L16: =J16/2240 -> 1.9625
A17: 1697 | B17: Succands | C17: NewEngland | D17: London | J17: =(E17*2240)+(F17*112)+(G17*28)+H17 -> 0 | L17: =J17/2240 -> 0
A18: 1697 | B18: Sugar Loaf | C18: NewEngland | D18: London | J18: =(E18*2240)+(F18*112)+(G18*28)+H18 -> 0 | L18: =J18/2240 -> 0
A19: 1697 | B19: Tobacco | C19: NewEngland | D19: London | H19: 787 | J19: =(E19*2240)+(F19*112)+(G19*28)+H19 -> 787 | L19: =J19/2240 -> 0.35133929
A20: 1697 | B20: Tortoise Shell | C20: NewEngland | D20: London | J20: =(E20*2240)+(F20*112)+(G20*28)+H20 -> 0 | L20: =J20/2240 -> 0
A21: 1697 | B21: White Sugar | C21: NewEngland | D21: London | F21: 56 | J21: =(E21*2240)+(F21*112)+(G21*28)+H21 -> 6272 | L21: =J21/2240 -> 2.8
A22: 1697 | B22: Brown Sugar | C22: NewEngland | D22: Out Ports | J22: =(E22*2240)+(F22*112)+(G22*28)+H22 -> 0 | L22: =J22/2240 -> 0
A23: 1697 | B23: Cocoa Nutts | C23: NewEngland | D23: Out Ports | J23: =(E23*2240)+(F23*112)+(G23*28)+H23 -> 0 | L23: =J23/2240 -> 0
A24: 1697 | B24: Dry Ginger | C24: NewEngland | D24: Out Ports | J24: =(E24*2240)+(F24*112)+(G24*28)+H24 -> 0 | L24: =J24/2240 -> 0
A25: 1697 | B25: Hopps | C25: NewEngland | D25: Out Ports | J25: =(E25*2240)+(F25*112)+(G25*28)+H25 -> 0 | L25: =J25/2240 -> 0
A26: 1697 | B26: Molasses | C26: NewEngland | D26: Out Ports | J26: =(E26*2240)+(F26*112)+(G26*28)+H26 -> 0 | L26: =J26/2240 -> 0
A27: 1697 | B27: Tobacco | C27: NewEngland | D27: Out Ports | J27: =(E27*2240)+(F27*112)+(G27*28)+H27 -> 0 | L27: =J27/2240 -> 0
A28: 1697 | B28: White Sugar | C28: NewEngland | D28: Out Ports | J28: =(E28*2240)+(F28*112)+(G28*28)+H28 -> 0 | L28: =J28/2240 -> 0
