Workbook

Sheet Master Goods Sheet
A1: Item | B1: Total London | C1: Total Outports | D1: Total
A2: Annatto | B2: =SUMIFS(Antigua!$M:$M,Antigua!$B:$B,$A2,Antigua!$D:$D,"London")+SUMIFS(Barbados!$L:$L,Barbados!$B:$B,$A2,Barbados!$D:$D,"London")+SUMIFS(Bermuda!$L:$L,Bermuda!$B:$B,$A2,Bermuda!$D:$D,"London")+SUMIFS(Carolina!$J:$J,Carolina!$A:$A,$A2,Carolina!$B:$B,"London")+SUMIFS(Jamaica!$L:$L,Jamaica!$B:$B,$A2,Jamaica!$D:$D,"London")+SUMIFS(Mountserat!$L:$L,Mountserat!$B:$B,$A2,Mountserat!$D:$D,"London")+SUMIFS(Nevis!$L:$L,Nevis!$B:$B,$A2,Nevis!$D:$D,"London")+SUMIFS(NewEngland!$L:$L,NewEngland!$B:$B,$A2,NewEngland!$D:$D,"London") -> 6.3526786 | C2: =SUMIFS(Antigua!$M:$M, Antigua!$B:$B, $A2, Antigua!$D:$D, "Out Ports") + SUMIFS(Barbados!$L:$L, Barbados!$B:$B, $A2, Barbados!$D:$D, "Out Ports") + SUMIFS(Bermuda!$L:$L, Bermuda!$B:$B, $A2, Bermuda!$D:$D, "Out Ports") + SUMIFS(Carolina!$J:$J, Carolina!$A:$A, $A2, Carolina!$B:$B, "Out Ports") + SUMIFS(Jamaica!$L:$L, Jamaica!$B:$B, $A2, Jamaica!$D:$D, "Out Ports") + SUMIFS(Mountserat!$L:$L, Mountserat!$B:$B, $A2, Mountserat!$D:$D, "Out Ports") + SUMIFS(Nevis!$L:$L, Nevis!$B:$B, $A2, Nevis!$D:$D, "Out Ports") + SUMIFS(NewEngland!$L:$L, NewEngland!$B:$B, $A2, NewEngland!$D:$D, "Out Ports") -> 0.23973214 | D2: =ROUND((B2+C2),2) -> 6.59
A3: Bayberry Wax | B3: =SUMIFS(Antigua!$M:$M,Antigua!$B:$B,$A3,Antigua!$D:$D,"London")+SUMIFS(Barbados!$L:$L,Barbados!$B:$B,$A3,Barbados!$D:$D,"London")+SUMIFS(Bermuda!$L:$L,Bermuda!$B:$B,$A3,Bermuda!$D:$D,"London")+SUMIFS(Carolina!$J:$J,Carolina!$A:$A,$A3,Carolina!$B:$B,"London")+SUMIFS(Jamaica!$L:$L,Jamaica!$B:$B,$A3,Jamaica!$D:$D,"London")+SUMIFS(Mountserat!$L:$L,Mountserat!$B:$B,$A3,Mountserat!$D:$D,"London")+SUMIFS(Nevis!$L:$L,Nevis!$B:$B,$A3,Nevis!$D:$D,"London")+SUMIFS(NewEngland!$L:$L,NewEngland!$B:$B,$A3,NewEngland!$D:$D,"London") -> 0.45982143 | C3: =SUMIFS(Antigua!$M:$M, Antigua!$B:$B, $A3, Antigua!$D:$D, "Out Ports") + SUMIFS(Barbados!$L:$L, Barbados!$B:$B, $A3, Barbados!$D:$D, "Out Ports") + SUMIFS(Bermuda!$L:$L, Bermuda!$B:$B, $A3, Bermuda!$D:$D, "Out Ports") + SUMIFS(Carolina!$J:$J, Carolina!$A:$A, $A3, Carolina!$B:$B, "Out Ports") + SUMIFS(Jamaica!$L:$L, Jamaica!$B:$B, $A3, Jamaica!$D:$D, "Out Ports") + SUMIFS(Mountserat!$L:$L, Mountserat!$B:$B, $A3, Mountserat!$D:$D, "Out Ports") + SUMIFS(Nevis!$L:$L, Nevis!$B:$B, $A3, Nevis!$D:$D, "Out Ports") + SUMIFS(NewEngland!$L:$L, NewEngland!$B:$B, $A3, NewEngland!$D:$D, "Out Ports") -> 0.115625 | D3: =ROUND((B3+C3),2) -> 0.58
A4: Bees Wax | B4: =SUMIFS(Antigua!$M:$M,Antigua!$B:$B,$A4,Antigua!$D:$D,"London")+SUMIFS(Barbados!$L:$L,Barbados!$B:$B,$A4,Barbados!$D:$D,"London")+SUMIFS(Bermuda!$L:$L,Bermuda!$B:$B,$A4,Bermuda!$D:$D,"London")+SUMIFS(Carolina!$J:$J,Carolina!$A:$A,$A4,Carolina!$B:$B,"London")+SUMIFS(Jamaica!$L:$L,Jamaica!$B:$B,$A4,Jamaica!$D:$D,"London")+SUMIFS(Mountserat!$L:$L,Mountserat!$B:$B,$A4,Mountserat!$D:$D,"London")+SUMIFS(Nevis!$L:$L,Nevis!$B:$B,$A4,Nevis!$D:$D,"London")+SUMIFS(NewEngland!$L:$L,NewEngland!$B:$B,$A4,NewEngland!$D:$D,"London") -> 0.35625 | C4: =SUMIFS(Antigua!$M:$M, Antigua!$B:$B, $A4, Antigua!$D:$D, "Out Ports") + SUMIFS(Barbados!$L:$L, Barbados!$B:$B, $A4, Barbados!$D:$D, "Out Ports") + SUMIFS(Bermuda!$L:$L, Bermuda!$B:$B, $A4, Bermuda!$D:$D, "Out Ports") + SUMIFS(Carolina!$J:$J, Carolina!$A:$A, $A4, Carolina!$B:$B, "Out Ports") + SUMIFS(Jamaica!$L:$L, Jamaica!$B:$B, $A4, Jamaica!$D:$D, "Out Ports") + SUMIFS(Mountserat!$L:$L, Mountserat!$B:$B, $A4, Mountserat!$D:$D, "Out Ports") + SUMIFS(Nevis!$L:$L, Nevis!$B:$B, $A4, Nevis!$D:$D, "Out Ports") + SUMIFS(NewEngland!$L:$L, NewEngland!$B:$B, $A4, NewEngland!$D:$D, "Out Ports") -> 0 | D4: =ROUND((B4+C4),2) -> 0.36
A5: Brandy | B5: =SUMIFS(Antigua!$M:$M,Antigua!$B:$B,$A5,Antigua!$D:$D,"London")+SUMIFS(Barbados!$L:$L,Barbados!$B:$B,$A5,Barbados!$D:$D,"London")+SUMIFS(Bermuda!$L:$L,Bermuda!$B:$B,$A5,Bermuda!$D:$D,"London")+SUMIFS(Carolina!$J:$J,Carolina!$A:$A,$A5,Carolina!$B:$B,"London")+SUMIFS(Jamaica!$L:$L,Jamaica!$B:$B,$A5,Jamaica!$D:$D,"London")+SUMIFS(Mountserat!$L:$L,Mountserat!$B:$B,$A5,Mountserat!$D:$D,"London")+SUMIFS(Nevis!$L:$L,Nevis!$B:$B,$A5,Nevis!$D:$D,"London")+SUMIFS(NewEngland!$L:$L,NewEngland!$B:$B,$A5,NewEngland!$D:$D,"London") -> 0.013392857 | C5: =SUMIFS(Antigua!$M:$M, Antigua!$B:$B, $A5, Antigua!$D:$D, "Out Ports") + SUMIFS(Barbados!$L:$L, Barbados!$B:$B, $A5, Barbados!$D:$D, "Out Ports") + SUMIFS(Bermuda!$L:$L, Bermuda!$B:$B, $A5, Bermuda!$D:$D, "Out Ports") + SUMIFS(Carolina!$J:$J, Carolina!$A:$A, $A5, Carolina!$B:$B, "Out Ports") + SUMIFS(Jamaica!$L:$L, Jamaica!$B:$B, $A5, Jamaica!$D:$D, "Out Ports") + SUMIFS(Mountserat!$L:$L, Mountserat!$B:$B, $A5, Mountserat!$D:$D, "Out Ports") + SUMIFS(Nevis!$L:$L, Nevis!$B:$B, $A5, Nevis!$D:$D, "Out Ports") + SUMIFS(NewEngland!$L:$L, NewEngland!$B:$B, $A5, NewEngland!$D:$D, "Out Ports") -> 0 | D5: =ROUND((B5+C5),2) -> 0.01
A6: Brown Sugar | B6: =SUMIFS(Antigua!$M:$M,Antigua!$B:$B,$A6,Antigua!$D:$D,"London")+SUMIFS(Barbados!$L:$L,Barbados!$B:$B,$A6,Barbados!$D:$D,"London")+SUMIFS(Bermuda!$L:$L,Bermuda!$B:$B,$A6,Bermuda!$D:$D,"London")+SUMIFS(Carolina!$J:$J,Carolina!$A:$A,$A6,Carolina!$B:$B,"London")+SUMIFS(Jamaica!$L:$L,Jamaica!$B:$B,$A6,Jamaica!$D:$D,"London")+SUMIFS(Mountserat!$L:$L,Mountserat!$B:$B,$A6,Mountserat!$D:$D,"London")+SUMIFS(Nevis!$L:$L,Nevis!$B:$B,$A6,Nevis!$D:$D,"London")+SUMIFS(NewEngland!$L:$L,NewEngland!$B:$B,$A6,NewEngland!$D:$D,"London") -> 14638.281 | C6: =SUMIFS(Antigua!$M:$M, Antigua!$B:$B, $A6, Antigua!$D:$D, "Out Ports") + SUMIFS(Barbados!$L:$L, Barbados!$B:$B, $A6, Barbados!$D:$D, "Out Ports") + SUMIFS(Bermuda!$L:$L, Bermuda!$B:$B, $A6, Bermuda!$D:$D, "Out Ports") + SUMIFS(Carolina!$J:$J, Carolina!$A:$A, $A6, Carolina!$B:$B, "Out Ports") + SUMIFS(Jamaica!$L:$L, Jamaica!$B:$B, $A6, Jamaica!$D:$D, "Out Ports") + SUMIFS(Mountserat!$L:$L, Mountserat!$B:$B, $A6, Mountserat!$D:$D, "Out Ports") + SUMIFS(Nevis!$L:$L, Nevis!$B:$B, $A6, Nevis!$D:$D, "Out Ports") + SUMIFS(NewEngland!$L:$L, NewEngland!$B:$B, $A6, NewEngland!$D:$D, "Out Ports") -> 2026.8707 | D6: =ROUND((B6+C6),2) -> 16665.15
A7: Cascarilla | B7: =SUMIFS(Antigua!$M:$M,Antigua!$B:$B,$A7,Antigua!$D:$D,"London")+SUMIFS(Barbados!$L:$L,Barbados!$B:$B,$A7,Barbados!$D:$D,"London")+SUMIFS(Bermuda!$L:$L,Bermuda!$B:$B,$A7,Bermuda!$D:$D,"London")+SUMIFS(Carolina!$J:$J,Carolina!$A:$A,$A7,Carolina!$B:$B,"London")+SUMIFS(Jamaica!$L:$L,Jamaica!$B:$B,$A7,Jamaica!$D:$D,"London")+SUMIFS(Mountserat!$L:$L,Mountserat!$B:$B,$A7,Mountserat!$D:$D,"London")+SUMIFS(Nevis!$L:$L,Nevis!$B:$B,$A7,Nevis!$D:$D,"London")+SUMIFS(NewEngland!$L:$L,NewEngland!$B:$B,$A7,NewEngland!$D:$D,"London") -> 5 | C7: =SUMIFS(Antigua!$M:$M, Antigua!$B:$B, $A7, Antigua!$D:$D, "Out Ports") + SUMIFS(Barbados!$L:$L, Barbados!$B:$B, $A7, Barbados!$D:$D, "Out Ports") + SUMIFS(Bermuda!$L:$L, Bermuda!$B:$B, $A7, Bermuda!$D:$D, "Out Ports") + SUMIFS(Carolina!$J:$J, Carolina!$A:$A, $A7, Carolina!$B:$B, "Out Ports") + SUMIFS(Jamaica!$L:$L, Jamaica!$B:$B, $A7, Jamaica!$D:$D, "Out Ports") + SUMIFS(Mountserat!$L:$L, Mountserat!$B:$B, $A7, Mountserat!$D:$D, "Out Ports") + SUMIFS(Nevis!$L:$L, Nevis!$B:$B, $A7, Nevis!$D:$D, "Out Ports") + SUMIFS(NewEngland!$L:$L, NewEngland!$B:$B, $A7, NewEngland!$D:$D, "Out Ports") -> 0 | D7: =ROUND((B7+C7),2) -> 5
A8: Chocolate | B8: =SUMIFS(Antigua!$M:$M,Antigua!$B:$B,$A8,Antigua!$D:$D,"London")+SUMIFS(Barbados!$L:$L,Barbados!$B:$B,$A8,Barbados!$D:$D,"London")+SUMIFS(Bermuda!$L:$L,Bermuda!$B:$B,$A8,Bermuda!$D:$D,"London")+SUMIFS(Carolina!$J:$J,Carolina!$A:$A,$A8,Carolina!$B:$B,"London")+SUMIFS(Jamaica!$L:$L,Jamaica!$B:$B,$A8,Jamaica!$D:$D,"London")+SUMIFS(Mountserat!$L:$L,Mountserat!$B:$B,$A8,Mountserat!$D:$D,"London")+SUMIFS(Nevis!$L:$L,Nevis!$B:$B,$A8,Nevis!$D:$D,"London")+SUMIFS(NewEngland!$L:$L,NewEngland!$B:$B,$A8,NewEngland!$D:$D,"London") -> 6.2425781 | C8: =SUMIFS(Antigua!$M:$M, Antigua!$B:$B, $A8, Antigua!$D:$D, "Out Ports") + SUMIFS(Barbados!$L:$L, Barbados!$B:$B, $A8, Barbados!$D:$D, "Out Ports") + SUMIFS(Bermuda!$L:$L, Bermuda!$B:$B, $A8, Bermuda!$D:$D, "Out Ports") + SUMIFS(Carolina!$J:$J, Carolina!$A:$A, $A8, Carolina!$B:$B, "Out Ports") + SUMIFS(Jamaica!$L:$L, Jamaica!$B:$B, $A8, Jamaica!$D:$D, "Out Ports") + SUMIFS(Mountserat!$L:$L, Mountserat!$B:$B, $A8, Mountserat!$D:$D, "Out Ports") + SUMIFS(Nevis!$L:$L, Nevis!$B:$B, $A8, Nevis!$D:$D, "Out Ports") + SUMIFS(NewEngland!$L:$L, NewEngland!$B:$B, $A8, NewEngland!$D:$D, "Out Ports") -> 0.0087053571 | D8: =ROUND((B8+C8),2) -> 6.25
A9: Cockeneal | B9: =SUMIFS(Antigua!$M:$M,Antigua!$B:$B,$A9,Antigua!$D:$D,"London")+SUMIFS(Barbados!$L:$L,Barbados!$B:$B,$A9,Barbados!$D:$D,"London")+SUMIFS(Bermuda!$L:$L,Bermuda!$B:$B,$A9,Bermuda!$D:$D,"London")+SUMIFS(Carolina!$J:$J,Carolina!$A:$A,$A9,Carolina!$B:$B,"London")+SUMIFS(Jamaica!$L:$L,Jamaica!$B:$B,$A9,Jamaica!$D:$D,"London")+SUMIFS(Mountserat!$L:$L,Mountserat!$B:$B,$A9,Mountserat!$D:$D,"London")+SUMIFS(Nevis!$L:$L,Nevis!$B:$B,$A9,Nevis!$D:$D,"London")+SUMIFS(NewEngland!$L:$L,NewEngland!$B:$B,$A9,NewEngland!$D:$D,"London") -> 0 | C9: =SUMIFS(Antigua!$M:$M, Antigua!$B:$B, $A9, Antigua!$D:$D, "Out Ports") + SUMIFS(Barbados!$L:$L, Barbados!$B:$B, $A9, Barbados!$D:$D, "Out Ports") + SUMIFS(Bermuda!$L:$L, Bermuda!$B:$B, $A9, Bermuda!$D:$D, "Out Ports") + SUMIFS(Carolina!$J:$J, Carolina!$A:$A, $A9, Carolina!$B:$B, "Out Ports") + SUMIFS(Jamaica!$L:$L, Jamaica!$B:$B, $A9, Jamaica!$D:$D, "Out Ports") + SUMIFS(Mountserat!$L:$L, Mountserat!$B:$B, $A9, Mountserat!$D:$D, "Out Ports") + SUMIFS(Nevis!$L:$L, Nevis!$B:$B, $A9, Nevis!$D:$D, "Out Ports") + SUMIFS(NewEngland!$L:$L, NewEngland!$B:$B, $A9, NewEngland!$D:$D, "Out Ports") -> 0 | D9: =ROUND((B9+C9),2) -> 0
A10: Cocoa Nuts | B10: =SUMIFS(Antigua!$M:$M,Antigua!$B:$B,$A10,Antigua!$D:$D,"London")+SUMIFS(Barbados!$L:$L,Barbados!$B:$B,$A10,Barbados!$D:$D,"London")+SUMIFS(Bermuda!$L:$L,Bermuda!$B:$B,$A10,Bermuda!$D:$D,"London")+SUMIFS(Carolina!$J:$J,Carolina!$A:$A,$A10,Carolina!$B:$B,"London")+SUMIFS(Jamaica!$L:$L,Jamaica!$B:$B,$A10,Jamaica!$D:$D,"London")+SUMIFS(Mountserat!$L:$L,Mountserat!$B:$B,$A10,Mountserat!$D:$D,"London")+SUMIFS(Nevis!$L:$L,Nevis!$B:$B,$A10,Nevis!$D:$D,"London")+SUMIFS(NewEngland!$L:$L,NewEngland!$B:$B,$A10,NewEngland!$D:$D,"London") -> 13.302679 | C10: =SUMIFS(Antigua!$M:$M, Antigua!$B:$B, $A10, Antigua!$D:$D, "Out Ports") + SUMIFS(Barbados!$L:$L, Barbados!$B:$B, $A10, Barbados!$D:$D, "Out Ports") + SUMIFS(Bermuda!$L:$L, Bermuda!$B:$B, $A10, Bermuda!$D:$D, "Out Ports") + SUMIFS(Carolina!$J:$J, Carolina!$A:$A, $A10, Carolina!$B:$B, "Out Ports") + SUMIFS(Jamaica!$L:$L, Jamaica!$B:$B, $A10, Jamaica!$D:$D, "Out Ports") + SUMIFS(Mountserat!$L:$L, Mountserat!$B:$B, $A10, Mountserat!$D:$D, "Out Ports") + SUMIFS(Nevis!$L:$L, Nevis!$B:$B, $A10, Nevis!$D:$D, "Out Ports") + SUMIFS(NewEngland!$L:$L, NewEngland!$B:$B, $A10, NewEngland!$D:$D, "Out Ports") -> 0.35133929 | D10: =ROUND((B10+C10),2) -> 13.65
A11: Cotton | B11: =SUMIFS(Antigua!$M:$M,Antigua!$B:$B,$A11,Antigua!$D:$D,"London")+SUMIFS(Barbados!$L:$L,Barbados!$B:$B,$A11,Barbados!$D:$D,"London")+SUMIFS(Bermuda!$L:$L,Bermuda!$B:$B,$A11,Bermuda!$D:$D,"London")+SUMIFS(Carolina!$J:$J,Carolina!$A:$A,$A11,Carolina!$B:$B,"London")+SUMIFS(Jamaica!$L:$L,Jamaica!$B:$B,$A11,Jamaica!$D:$D,"London")+SUMIFS(Mountserat!$L:$L,Mountserat!$B:$B,$A11,Mountserat!$D:$D,"London")+SUMIFS(Nevis!$L:$L,Nevis!$B:$B,$A11,Nevis!$D:$D,"London")+SUMIFS(NewEngland!$L:$L,NewEngland!$B:$B,$A11,NewEngland!$D:$D,"London") -> 114.74665 | C11: =SUMIFS(Antigua!$M:$M, Antigua!$B:$B, $A11, Antigua!$D:$D, "Out Ports") + SUMIFS(Barbados!$L:$L, Barbados!$B:$B, $A11, Barbados!$D:$D, "Out Ports") + SUMIFS(Bermuda!$L:$L, Bermuda!$B:$B, $A11, Bermuda!$D:$D, "Out Ports") + SUMIFS(Carolina!$J:$J, Carolina!$A:$A, $A11, Carolina!$B:$B, "Out Ports") + SUMIFS(Jamaica!$L:$L, Jamaica!$B:$B, $A11, Jamaica!$D:$D, "Out Ports") + SUMIFS(Mountserat!$L:$L, Mountserat!$B:$B, $A11, Mountserat!$D:$D, "Out Ports") + SUMIFS(Nevis!$L:$L, Nevis!$B:$B, $A11, Nevis!$D:$D, "Out Ports") + SUMIFS(NewEngland!$L:$L, NewEngland!$B:$B, $A11, NewEngland!$D:$D, "Out Ports") -> 58.11529 | D11: =ROUND((B11+C11),2) -> 172.86
A12: Dry Ginger | B12: =SUMIFS(Antigua!$M:$M,Antigua!$B:$B,$A12,Antigua!$D:$D,"London")+SUMIFS(Barbados!$L:$L,Barbados!$B:$B,$A12,Barbados!$D:$D,"London")+SUMIFS(Bermuda!$L:$L,Bermuda!$B:$B,$A12,Bermuda!$D:$D,"London")+SUMIFS(Carolina!$J:$J,Carolina!$A:$A,$A12,Carolina!$B:$B,"London")+SUMIFS(Jamaica!$L:$L,Jamaica!$B:$B,$A12,Jamaica!$D:$D,"London")+SUMIFS(Mountserat!$L:$L,Mountserat!$B:$B,$A12,Mountserat!$D:$D,"London")+SUMIFS(Nevis!$L:$L,Nevis!$B:$B,$A12,Nevis!$D:$D,"London")+SUMIFS(NewEngland!$L:$L,NewEngland!$B:$B,$A12,NewEngland!$D:$D,"London") -> 303.43214 | C12: =SUMIFS(Antigua!$M:$M, Antigua!$B:$B, $A12, Antigua!$D:$D, "Out Ports") + SUMIFS(Barbados!$L:$L, Barbados!$B:$B, $A12, Barbados!$D:$D, "Out Ports") + SUMIFS(Bermuda!$L:$L, Bermuda!$B:$B, $A12, Bermuda!$D:$D, "Out Ports") + SUMIFS(Carolina!$J:$J, Carolina!$A:$A, $A12, Carolina!$B:$B, "Out Ports") + SUMIFS(Jamaica!$L:$L, Jamaica!$B:$B, $A12, Jamaica!$D:$D, "Out Ports") + SUMIFS(Mountserat!$L:$L, Mountserat!$B:$B, $A12, Mountserat!$D:$D, "Out Ports") + SUMIFS(Nevis!$L:$L, Nevis!$B:$B, $A12, Nevis!$D:$D, "Out Ports") + SUMIFS(NewEngland!$L:$L, NewEngland!$B:$B, $A12, NewEngland!$D:$D, "Out Ports") -> 63.707589 | D12: =ROUND((B12+C12),2) -> 367.14
A13: Elephant Teeth | B13: =SUMIFS(Antigua!$M:$M,Antigua!$B:$B,$A13,Antigua!$D:$D,"London")+SUMIFS(Barbados!$L:$L,Barbados!$B:$B,$A13,Barbados!$D:$D,"London")+SUMIFS(Bermuda!$L:$L,Bermuda!$B:$B,$A13,Bermuda!$D:$D,"London")+SUMIFS(Carolina!$J:$J,Carolina!$A:$A,$A13,Carolina!$B:$B,"London")+SUMIFS(Jamaica!$L:$L,Jamaica!$B:$B,$A13,Jamaica!$D:$D,"London")+SUMIFS(Mountserat!$L:$L,Mountserat!$B:$B,$A13,Mountserat!$D:$D,"London")+SUMIFS(Nevis!$L:$L,Nevis!$B:$B,$A13,Nevis!$D:$D,"London")+SUMIFS(NewEngland!$L:$L,NewEngland!$B:$B,$A13,NewEngland!$D:$D,"London") -> 26.82885 | C13: =SUMIFS(Antigua!$M:$M, Antigua!$B:$B, $A13, Antigua!$D:$D, "Out Ports") + SUMIFS(Barbados!$L:$L, Barbados!$B:$B, $A13, Barbados!$D:$D, "Out Ports") + SUMIFS(Bermuda!$L:$L, Bermuda!$B:$B, $A13, Bermuda!$D:$D, "Out Ports") + SUMIFS(Carolina!$J:$J, Carolina!$A:$A, $A13, Carolina!$B:$B, "Out Ports") + SUMIFS(Jamaica!$L:$L, Jamaica!$B:$B, $A13, Jamaica!$D:$D, "Out Ports") + SUMIFS(Mountserat!$L:$L, Mountserat!$B:$B, $A13, Mountserat!$D:$D, "Out Ports") + SUMIFS(Nevis!$L:$L, Nevis!$B:$B, $A13, Nevis!$D:$D, "Out Ports") + SUMIFS(NewEngland!$L:$L, NewEngland!$B:$B, $A13, NewEngland!$D:$D, "Out Ports") -> 0.0018415179 | D13: =ROUND((B13+C13),2) -> 26.83
... A30: Sasparilla | B30: =SUMIFS(Antigua!$M:$M,Antigua!$B:$B,$A30,Antigua!$D:$D,"London")+SUMIFS(Barbados!$L:$L,Barbados!$B:$B,$A30,Barbados!$D:$D,"London")+SUMIFS(Bermuda!$L:$L,Bermuda!$B:$B,$A30,Bermuda!$D:$D,"London")+SUMIFS(Carolina!$J:$J,Carolina!$A:$A,$A30,Carolina!$B:$B,"London")+SUMIFS(Jamaica!$L:$L,Jamaica!$B:$B,$A30,Jamaica!$D:$D,"London")+SUMIFS(Mountserat!$L:$L,Mountserat!$B:$B,$A30,Mountserat!$D:$D,"London")+SUMIFS(Nevis!$L:$L,Nevis!$B:$B,$A30,Nevis!$D:$D,"London")+SUMIFS(NewEngland!$L:$L,NewEngland!$B:$B,$A30,NewEngland!$D:$D,"London") -> 0 | C30: =SUMIFS(Antigua!$M:$M, Antigua!$B:$B, $A30, Antigua!$D:$D, "Out Ports") + SUMIFS(Barbados!$L:$L, Barbados!$B:$B, $A30, Barbados!$D:$D, "Out Ports") + SUMIFS(Bermuda!$L:$L, Bermuda!$B:$B, $A30, Bermuda!$D:$D, "Out Ports") + SUMIFS(Carolina!$J:$J, Carolina!$A:$A, $A30, Carolina!$B:$B, "Out Ports") + SUMIFS(Jamaica!$L:$L, Jamaica!$B:$B, $A30, Jamaica!$D:$D, "Out Ports") + SUMIFS(Mountserat!$L:$L, Mountserat!$B:$B, $A30, Mountserat!$D:$D, "Out Ports") + SUMIFS(Nevis!$L:$L, Nevis!$B:$B, $A30, Nevis!$D:$D, "Out Ports") + SUMIFS(NewEngland!$L:$L, NewEngland!$B:$B, $A30, NewEngland!$D:$D, "Out Ports") -> 0 | D30: =ROUND((B30+C30),2) -> 0

Sheet Antigua
A1: YEAR | B1: COMMODITY_NAME | C1: FROM_LOCATION | D1: TO_LOCATION | E1: ton | F1: hh | G1: quarter | H1: lb | J1: Total Pounds | L1: WEIGHT
A2: 1700 | B2: Dry Ginger | C2: Antigua | D2: London | F2: 79 | G2: 3 | J2: =(E2*2240)+(F2*112)+(G2*28)+H2 -> 8932 | L2: =J2/2240 -> 3.9875
A3: 1700 | B3: Molasses | C3: Antigua | D3: London | F3: 8960 | G3: 1 | J3: =(E3*2240)+(F3*112)+(G3*28)+H3 -> 1003548 | L3: =J3/2240 -> 448.0125
A4: 1700 | B4: Brown Sugar | C4: Antigua | D4: London | F4: 39148 | G4: 2 | H4: 12 | J4: =(E4*2240)+(F4*112)+(G4*28)+H4 -> 4384644 | L4: =J4/2240 -> 1957.4304
A5: 1700 | B5: White Sugar | C5: Antigua | D5: London | F5: 7 | G5: 2 | H5: 21 | J5: =(E5*2240)+(F5*112)+(G5*28)+H5 -> 861 | L5: =J5/2240 -> 0.384375
A6: 1700 | B6: Indigo | C6: Antigua | D6: London | H6: 60 | J6: =(E6*2240)+(F6*112)+(G6*28)+H6 -> 60 | L6: =J6/2240 -> 0.026785714
A7: 1700 | B7: Orchall? | C7: Antigua | D7: London | F7: 222 | G7: 3 | J7: =(E7*2240)+(F7*112)+(G7*28)+H7 -> 24948 | L7: =J7/2240 -> 11.1375
A8: 1700 | B8: Tobacco | C8: Antigua | D8: London | H8: 103269 | J8: =(E8*2240)+(F8*112)+(G8*28)+H8 -> 103269 | L8: =J8/2240 -> 46.102232
A9: 1700 | B9: Snuff? | C9: Antigua | D9: London | F9: 20 | G9: 3 | H9: 1 | J9: =(E9*2240)+(F9*112)+(G9*28)+H9 -> 2325 | L9: =J9/2240 -> 1.0379464
A10: 1700 | B10: Bees Wax | C10: Antigua | D10: London | F10: 4 | G10: 3 | J10: =(E10*2240)+(F10*112)+(G10*28)+H10 -> 532 | L10: =J10/2240 -> 0.2375
A11: 1700 | B11: Madera Wine | C11: Antigua | D11: London | H11: 1740 | I11: 1pipe 48gal | J11: =(E11*2240)+(F11*112)+(G11*28)+H11 -> 1740 | L11: =J11/2240 -> 0.77678571
A12: 1700 | B12: Cotton | C12: Antigua | D12: London | H12: =238*200 -> 47600 | I12: 238 Bags | J12: =(E12*2240)+(F12*112)+(G12*28)+H12 -> 47600 | L12: =J12/2240 -> 21.25
A13: 1700 | B13: Chocolate | C13: Antigua | D13: London | H13: 126 | J13: =(E13*2240)+(F13*112)+(G13*28)+H13 -> 126 | L13: =J13/2240 -> 0.05625
A14: 1700 | B14: Lime Juice | C14: Antigua | D14: London | H14: 10362 | I14: 996 Gallons | J14: =(E14*2240)+(F14*112)+(G14*28)+H14 -> 10362 | L14: =J14/2240 -> 4.6258929
A15: 1700 | B15: Rum | C15: Antigua | D15: London | H15: 4701 | I15: 470 Gallons | J15: =(E15*2240)+(F15*112)+(G15*28)+H15 -> 4701 | L15: =J15/2240 -> 2.0986607
A16: 1700 | B16: Tortoise Shell | C16: Antigua | D16: London | H16: 19 | J16: =(E16*2240)+(F16*112)+(G16*28)+H16 -> 19 | L16: =J16/2240 -> 0.0084821429
A17: 1700 | B17: Elephants Teeth | C17: Antigua | D17: London | F17: 52 | G17: 0 | H17: 3 | J17: =(E17*2240)+(F17*112)+(G17*28)+H17 -> 5827 | L17: =J17/2240 -> 2.6013393
A18: 1700 | B18: Molasses | C18: Antigua | D18: Out Ports | F18: 1900 | G18: 2 | H18: 1 | J18: =(E18*2240)+(F18*112)+(G18*28)+H18 -> 212857 | L18: =J18/2240 -> 95.025446
A19: 1700 | B19: Brown Sugar | C19: Antigua | D19: Out Ports | F19: 13622 | G19: 2 | H19: 3 | J19: =(E19*2240)+(F19*112)+(G19*28)+H19 -> 1525723 | L19: =J19/2240 -> 681.12634
A20: 1700 | B20: Shruff | C20: Antigua | D20: Out Ports | F20: 4 | H20: 26 | J20: =(E20*2240)+(F20*112)+(G20*28)+H20 -> 474 | L20: =J20/2240 -> 0.21160714
A21: 1700 | B21: Succands | C21: Antigua | D21: Out Ports | G21: 38 | J21: =(E21*2240)+(F21*112)+(G21*28)+H21 -> 1064 | L21: =J21/2240 -> 0.475
A22: 1700 | B22: Tobacco | C22: Antigua | D22: Out Ports | H22: 92152 | J22: =(E22*2240)+(F22*112)+(G22*28)+H22 -> 92152 | L22: =J22/2240 -> 41.139286
A23: 1700 | B23: Cotton | C23: Antigua | D23: Out Ports | F23: 329 | G23: 2 | H23: 20 | J23: =(E23*2240)+(F23*112)+(G23*28)+H23 -> 36924 | L23: =J23/2240 -> 16.483929
A24: 1700 | B24: Lime Juice | C24: Antigua | D24: Out Ports | H24: 739 | I24: 71 Gallons | J24: =(E24*2240)+(F24*112)+(G24*28)+H24 -> 739 | L24: =J24/2240 -> 0.32991071

Sheet Barbados
A1: YEAR | B1: COMMODITY_NAME | C1: FROM_LOCATION | D1: TO_LOCATION | E1: ton | F1: hh | G1: quarter | H1: lb | J1: Total Pounds | L1: WEIGHT
A2: 1700 | B2: Annatto | C2: Barbados | D2: London | H2: 13078 | J2: =(E2*2240)+(F2*112)+(G2*28)+H2 -> 13078 | L2: =J2/2240 -> 5.8383929
A3: 1700 | B3: Elephants Teeth | C3: Barbados | D3: London | F3: 163 | H3: 1 | J3: =(E3*2240)+(F3*112)+(G3*28)+H3 -> 18257 | L3: =J3/2240 -> 8.1504464
A4: 1700 | B4: Dry Ginger | C4: Barbados | D4: London | F4: 3795 | G4: 3 | H4: 3 | J4: =(E4*2240)+(F4*112)+(G4*28)+H4 -> 425127 | L4: =J4/2240 -> 189.78884
A5: 1700 | B5: Molasses | C5: Barbados | D5: London | F5: 16763 | G5: 3 | H5: 2 | J5: =(E5*2240)+(F5*112)+(G5*28)+H5 -> 1877542 | L5: =J5/2240 -> 838.18839
A6: 1700 | B6: Rice | C6: Barbados | D6: London | F6: 1 | J6: =(E6*2240)+(F6*112)+(G6*28)+H6 -> 112 | L6: =J6/2240 -> 0.05
A7: 1700 | B7: Brown Sugar | C7: Barbados | D7: London | F7: 214646 | G7: 2 | H7: 23 | J7: =(E7*2240)+(F7*112)+(G7*28)+H7 -> 24040431 | L7: =J7/2240 -> 10732.335
A8: 1700 | B8: Sugar Loaf | C8: Barbados | D8: London | F8: 7 | G8: 2 | H8: 11 | J8: =(E8*2240)+(F8*112)+(G8*28)+H8 -> 851 | L8: =J8/2240 -> 0.37991071
A9: 1700 | B9: White Sugar | C9: Barbados | D9: London | F9: 3762 | G9: 2 | H9: 25 | J9: =(E9*2240)+(F9*112)+(G9*28)+H9 -> 421425 | L9: =J9/2240 -> 188.13616
A10: 1700 | B10: Indigo | C10: Barbados | D10: London | H10: 209 | J10: =(E10*2240)+(F10*112)+(G10*28)+H10 -> 209 | L10: =J10/2240 -> 0.093303571
A11: 1700 | B11: Shruff? Snuff? | C11: Barbados | D11: London | F11: 113 | G11: 2 | H11: 14 | J11: =(E11*2240)+(F11*112)+(G11*28)+H11 -> 12726 | L11: =J11/2240 -> 5.68125
A12: 1700 | B12: Slude? | C12: Barbados | D12: London | H12: 508 | J12: =(E12*2240)+(F12*112)+(G12*28)+H12 -> 508 | L12: =J12/2240 -> 0.22678571
A13: 1700 | B13: Succands | C13: Barbados | D13: London | H13: 2763 | J13: =(E13*2240)+(F13*112)+(G13*28)+H13 -> 2763 | L13: =J13/2240 -> 1.2334821
A14: 1700 | B14: Tobacco | C14: Barbados | D14: London | H14: 2791 | J14: =(E14*2240)+(F14*112)+(G14*28)+H14 -> 2791 | L14: =J14/2240 -> 1.2459821
A15: 1700 | B15: Bees Wax | C15: Barbados | D15: London | F15: 2 | G15: 2 | H15: 14 | J15: =(E15*2240)+(F15*112)+(G15*28)+H15 -> 294 | L15: =J15/2240 -> 0.13125
A16: 1700 | B16: Madera Wine | C16: Barbados | D16: London | H16: 14304 | I16: 5 tuns 2hh 44 gal | J16: =(E16*2240)+(F16*112)+(G16*28)+H16 -> 14304 | L16: =J16/2240 -> 6.3857143
A17: 1700 | B17: Cocoa Nuts | C17: Barbados | D17: London | F17: 67 | G17: 1 | H17: 14 | J17: =(E17*2240)+(F17*112)+(G17*28)+H17 -> 7546 | L17: =J17/2240 -> 3.36875
A18: 1700 | B18: Cocoa Vaste? Waste? (60) | C18: Barbados | D18: London | H18: 30 | J18: =(E18*2240)+(F18*112)+(G18*28)+H18 -> 30 | L18: =J18/2240 -> 0.013392857
A19: 1700 | B19: Chocolate | C19: Barbados | D19: London | H19: 177 | J19: =(E19*2240)+(F19*112)+(G19*28)+H19 -> 177 | L19: =J19/2240 -> 0.079017857
A20: 1700 | B20: Lime Juice | C20: Barbados | D20: London | H20: 55533 | I20: 5338 Gallons | J20: =(E20*2240)+(F20*112)+(G20*28)+H20 -> 55533 | L20: =J20/2240 -> 24.791518
A21: 1700 | B21: Rum | C21: Barbados | D21: London | H21: 9642 | I21: 964 Gallons | J21: =(E21*2240)+(F21*112)+(G21*28)+H21 -> 9642 | L21: =J21/2240 -> 4.3044643
A22: 1700 | B22: Spirits | C22: Barbados | D22: London | H22: 540 | I22: 54 Gallons | J22: =(E22*2240)+(F22*112)+(G22*28)+H22 -> 540 | L22: =J22/2240 -> 0.24107143
A23: 1700 | B23: Jazz??? | C23: Barbados | D23: London | F23: 10 | G23: 2 | H23: 14 | J23: =(E23*2240)+(F23*112)+(G23*28)+H23 -> 1190 | L23: =J23/2240 -> 0.53125
A24: 1700 | B24: Tortoise Shell | C24: Barbados | D24: London | H24: 1868 | J24: =(E24*2240)+(F24*112)+(G24*28)+H24 -> 1868 | L24: =J24/2240 -> 0.83392857
A25: 1700 | B25: Water Cordial | C25: Barbados | D25: London | H25: 612.5 | I25: 61.25 Gallons | J25: =(E25*2240)+(F25*112)+(G25*28)+H25 -> 612.5 | L25: =J25/2240 -> 0.2734375
A26: 1700 | B26: Annatto | C26: Barbados | D26: Out Ports | H26: 412 | J26: =(E26*2240)+(F26*112)+(G26*28)+H26 -> 412 | L26: =J26/2240 -> 0.18392857
A27: 1700 | B27: Elephants Teeth | C27: Barbados | D27: Out Ports | F27: 1 | G27: 3 | H27: 12 | J27: =(E27*2240)+(F27*112)+(G27*28)+H27 -> 208 | L27: =J27/2240 -> 0.092857143
A28: 1700 | B28: Dry Ginger | C28: Barbados | D28: Out Ports | F28: 545 | H28: 3 | J28: =(E28*2240)+(F28*112)+(G28*28)+H28 -> 61043 | L28: =J28/2240 -> 27.251339
A29: 1700 | B29: Molasses | C29: Barbados | D29: Out Ports | F29: 3838 | G29: 3 | H29: 22 | J29: =(E29*2240)+(F29*112)+(G29*28)+H29 -> 429962 | L29: =J29/2240 -> 191.94732
A30: 1700 | B30: Rice | C30: Barbados | D30: Out Ports | G30: 2 | H30: 14 | J30: =(E30*2240)+(F30*112)+(G30*28)+H30 -> 70 | L30: =J30/2240 -> 0.03125
A31: 1700 | B31: Sugar Loaf | C31: Barbados | D31: Out Ports | G31: 2 | H31: 18 | J31: =(E31*2240)+(F31*112)+(G31*28)+H31 -> 74 | L31: =J31/2240 -> 0.033035714
A32: 1700 | B32: Muscavado Sugar | C32: Barbados | D32: Out Ports | F32: 23436 | G32: 3 | H32: 4 | J32: =(E32*2240)+(F32*112)+(G32*28)+H32 -> 2624920 | L32: =J32/2240 -> 1171.8393
A33: 1700 | B33: White Sugar | C33: Barbados | D33: Out Ports | F33: 35 | G33: 3 | H33: 1 | J33: =(E33*2240)+(F33*112)+(G33*28)+H33 -> 4005 | L33: =J33/2240 -> 1.7879464
A34: 1700 | B34: Succands | C34: Barbados | D34: Out Ports | H34: 388 | J34: =(E34*2240)+(F34*112)+(G34*28)+H34 -> 388 | L34: =J34/2240 -> 0.17321429
A35: 1700 | B35: Tobacco | C35: Barbados | D35: Out Ports | H35: 100 | J35: =(E35*2240)+(F35*112)+(G35*28)+H35 -> 100 | L35: =J35/2240 -> 0.044642857
A36: 1700 | B36: Madera Wine | C36: Barbados | D36: Out Ports | H36: 1000 | I36: 1hh 37 Gallon | J36: =(E36*2240)+(F36*112)+(G36*28)+H36 -> 1000 | L36: =J36/2240 -> 0.44642857
A37: 1700 | B37: Cotton | C37: Barbados | D37: Out Ports | F37: 207 | G37: 1 | H37: 11 | J37: =(E37*2240)+(F37*112)+(G37*28)+H37 -> 23223 | L37: =J37/2240 -> 10.367411
A38: 1700 | B38: Lime Juice | C38: Barbados | D38: Out Ports | H38: 4088 | I38: 393 Gallons | J38: =(E38*2240)+(F38*112)+(G38*28)+H38 -> 4088 | L38: =J38/2240 -> 1.825
A39: 1700 | B39: Rum | C39: Barbados | D39: Out Ports | H39: 2461 | I39: 246 Gallons | J39: =(E39*2240)+(F39*112)+(G39*28)+H39 -> 2461 | L39: =J39/2240 -> 1.0986607
A40: 1700 | B40: Spirits | C40: Barbados | D40: Out Ports | H40: 2 | J40: =(E40*2240)+(F40*112)+(G40*28)+H40 -> 2 | L40: =J40/2240 -> 0.00089285714
...

Sheet Bermuda
A1: YEAR | B1: COMMODITY_NAME | C1: FROM_LOCATION | D1: TO_LOCATION | E1: ton | F1: hh | G1: quarter | H1: lb | J1: Total Pounds | L1: WEIGHT | N1: Not Sugar | O1: Sugar
A2: 1700 | B2: Shruff? Snuff? | C2: Bermuda | D2: London | F2: 1 | G2: 3 | J2: =(E2*2240)+(F2*112)+(G2*28)+H2 -> 196 | L2: =J2/2240 -> 0.0875 | N2: =L2+L4+L5 -> 9.884375 | O2: =L3+L6 -> 27.7
A3: 1700 | B3: Muscavado Sugar | C3: Bermuda | D3: London | F3: 154 | J3: =(E3*2240)+(F3*112)+(G3*28)+H3 -> 17248 | L3: =J3/2240 -> 7.7
A4: 1700 | B4: Tobacco | C4: Bermuda | D4: London | H4: 21730 | J4: =(E4*2240)+(F4*112)+(G4*28)+H4 -> 21730 | L4: =J4/2240 -> 9.7008929
A5: 1700 | B5: Tortoise Shell | C5: Bermuda | D5: London | H5: 215 | J5: =(E5*2240)+(F5*112)+(G5*28)+H5 -> 215 | L5: =J5/2240 -> 0.095982143
A6: 1700 | B6: Muscavado Sugar | C6: Bermuda | D6: Out Ports | F6: 400 | J6: =(E6*2240)+(F6*112)+(G6*28)+H6 -> 44800 | L6: =J6/2240 -> 20

Sheet Carolina
A1: Items | B1: Import Location | C1: 1700 Ton | D1: 1700 hh | E1: 1700 quarter | F1: 1700 Stone/lb | H1: Total Pounds | J1: Total Tons | L1: Not Sugar | M1: Sugar
A2: Elephants Teeth | B2: London | D2: 17 | E2: 1 | H2: =(C2*2240)+(D2*112)+(E2*28)+F2 -> 1932 | J2: =H2/2240 -> 0.8625 | L2: =J2+J3+J5+J6+J7+J8+J9 -> 121.71116 | M2: =J4 -> 12.155804
A3: Rice | B3: London | D3: 2338 | F3: 10 | H3: =(C3*2240)+(D3*112)+(E3*28)+F3 -> 261866 | J3: =H3/2240 -> 116.90446
A4: Brown Sugar | B4: London | D4: 243 | F4: 13 | H4: =(C4*2240)+(D4*112)+(E4*28)+F4 -> 27229 | J4: =H4/2240 -> 12.155804
A5: Shruff? Snuff? | B5: London | D5: 2 | E5: 3 | H5: =(C5*2240)+(D5*112)+(E5*28)+F5 -> 308 | J5: =H5/2240 -> 0.1375
A6: Tobacco | B6: London | F6: 7562 | H6: =(C6*2240)+(D6*112)+(E6*28)+F6 -> 7562 | J6: =H6/2240 -> 3.3758929
A7: Bayberry Wax | B7: London | F7: 735 | H7: =(C7*2240)+(D7*112)+(E7*28)+F7 -> 735 | J7: =H7/2240 -> 0.328125
A8: Mirtle Wax | B8: London | F8: 80 | H8: =(C8*2240)+(D8*112)+(E8*28)+F8 -> 80 | J8: =H8/2240 -> 0.035714286
A9: Tortoise Shell | B9: London | F9: 150 | H9: =(C9*2240)+(D9*112)+(E9*28)+F9 -> 150 | J9: =H9/2240 -> 0.066964286
A10: Rice | B10: Out Ports | D10: 699 | E10: 1 | F10: 1 | H10: =(C10*2240)+(D10*112)+(E10*28)+F10 -> 78317 | J10: =H10/2240 -> 34.962946
A11: Tortoise Shell | B11: Out Ports | F11: 3 | H11: =(C11*2240)+(D11*112)+(E11*28)+F11 -> 3 | J11: =H11/2240 -> 0.0013392857

Sheet Jamaica
A1: YEAR | B1: COMMODITY_NAME | C1: FROM_LOCATION | D1: TO_LOCATION | E1: ton | F1: hh | G1: quarter | H1: lb | J1: Total Pounds | L1: WEIGHT
A2: 1700 | B2: Annatto | C2: Jamaica | D2: London | H2: 1152 | J2: =(E2*2240)+(F2*112)+(G2*28)+H2 -> 1152 | L2: =J2/2240 -> 0.51428571
A3: 1700 | B3: Elephant Teeth | C3: Jamaica | D3: London | F3: 504 | G3: 2 | H3: 18 | J3: =(E3*2240)+(F3*112)+(G3*28)+H3 -> 56522 | L3: =J3/2240 -> 25.233036
A4: 1700 | B4: Dry Ginger | C4: Jamaica | D4: London | F4: 2250 | G4: 1 | H4: 27 | J4: =(E4*2240)+(F4*112)+(G4*28)+H4 -> 252055 | L4: =J4/2240 -> 112.52455
A5: 1700 | B5: Molasses | C5: Jamaica | D5: London | F5: 298 | G5: 1 | J5: =(E5*2240)+(F5*112)+(G5*28)+H5 -> 33404 | L5: =J5/2240 -> 14.9125
A6: 1700 | B6: Muscavado Sugar | C6: Jamaica | D6: London | F6: 74401 | G6: 2 | H6: 26 | J6: =(E6*2240)+(F6*112)+(G6*28)+H6 -> 8332994 | L6: =J6/2240 -> 3720.0866
A7: 1700 | B7: White Sugar | C7: Jamaica | D7: London | F7: 32 | G7: 3 | H7: 14 | J7: =(E7*2240)+(F7*112)+(G7*28)+H7 -> 3682 | L7: =J7/2240 -> 1.64375
A8: 1700 | B8: Indigo | C8: Jamaica | D8: London | H8: 178686 | J8: =(E8*2240)+(F8*112)+(G8*28)+H8 -> 178686 | L8: =J8/2240 -> 79.770536
A9: 1700 | B9: Lemon Water | C9: Jamaica | D9: London | E9: 2 | J9: =(E9*2240)+(F9*112)+(G9*28)+H9 -> 4480 | L9: =J9/2240 -> 2
A10: 1700 | B10: Sea Horse Teeth? | C10: Jamaica | D10: London | H10: 50 | J10: =(E10*2240)+(F10*112)+(G10*28)+H10 -> 50 | L10: =J10/2240 -> 0.022321429
A11: 1700 | B11: Shruff | C11: Jamaica | D11: London | F11: 70 | G11: 0 | H11: 19 | J11: =(E11*2240)+(F11*112)+(G11*28)+H11 -> 7859 | L11: =J11/2240 -> 3.5084821
A12: 1700 | B12: Succands | C12: Jamaica | D12: London | H12: 563 | J12: =(E12*2240)+(F12*112)+(G12*28)+H12 -> 563 | L12: =J12/2240 -> 0.25133929
A13: 1700 | B13: Tobacco | C13: Jamaica | D13: London | H13: 3242 | J13: =(E13*2240)+(F13*112)+(G13*28)+H13 -> 3242 | L13: =J13/2240 -> 1.4473214
A14: 1700 | B14: Bees Wax | C14: Jamaica | D14: London | F14: 4 | G14: 2 | J14: =(E14*2240)+(F14*112)+(G14*28)+H14 -> 504 | L14: =J14/2240 -> 0.225
A15: 1700 | B15: Madera Wine | C15: Jamaica | D15: London | H15: 310 | I15: 31 Gallons | J15: =(E15*2240)+(F15*112)+(G15*28)+H15 -> 310 | L15: =J15/2240 -> 0.13839286
A16: 1700 | B16: Cotton | C16: Jamaica | D16: London | H16: =1268*200 -> 253600 | I16: 1263 Bags | J16: =(E16*2240)+(F16*112)+(G16*28)+H16 -> 253600 | L16: =J16/2240 -> 113.21429
A17: 1700 | B17: Binellos | C17: Jamaica | D17: London | F17: 157 | G17: 1 | J17: =(E17*2240)+(F17*112)+(G17*28)+H17 -> 17612 | L17: =J17/2240 -> 7.8625
A18: 1700 | B18: Cascarilla | C18: Jamaica | D18: London | G18: 400 | J18: =(E18*2240)+(F18*112)+(G18*28)+H18 -> 11200 | L18: =J18/2240 -> 5
A19: 1700 | B19: Chocolate | C19: Jamaica | D19: London | G19: 493 | J19: =(E19*2240)+(F19*112)+(G19*28)+H19 -> 13804 | L19: =J19/2240 -> 6.1625
A20: 1700 | B20: Cocoa Nuts | C20: Jamaica | D20: London | F20: 193 | H20: 25 | J20: =(E20*2240)+(F20*112)+(G20*28)+H20 -> 21641 | L20: =J20/2240 -> 9.6611607
A21: 1700 | B21: Lime Juice | C21: Jamaica | D21: London | H21: 119351 | I21: 11932 Gallons | J21: =(E21*2240)+(F21*112)+(G21*28)+H21 -> 119351 | L21: =J21/2240 -> 53.281696
A22: 1700 | B22: Pimento | C22: Jamaica | D22: London | H22: 109849 | J22: =(E22*2240)+(F22*112)+(G22*28)+H22 -> 109849 | L22: =J22/2240 -> 49.039732
A23: 1700 | B23: Rum | C23: Jamaica | D23: London | H23: 2160.5 | I23: 216 Gallons | J23: =(E23*2240)+(F23*112)+(G23*28)+H23 -> 2160.5 | L23: =J23/2240 -> 0.96450893
A24: 1700 | B24: Tortoise Shell | C24: Jamaica | D24: London | H24: 2902 | J24: =(E24*2240)+(F24*112)+(G24*28)+H24 -> 2902 | L24: =J24/2240 -> 1.2955357
A25: 1700 | B25: Annatto | C25: Jamaica | D25: Out Ports | H25: 125 | J25: =(E25*2240)+(F25*112)+(G25*28)+H25 -> 125 | L25: =J25/2240 -> 0.055803571
A26: 1700 | B26: Elephant Teeth | C26: Jamaica | D26: Out Ports | H26: 4 | J26: =(E26*2240)+(F26*112)+(G26*28)+H26 -> 4 | L26: =J26/2240 -> 0.0017857143
A27: 1700 | B27: Dry Ginger | C27: Jamaica | D27: Out Ports | F27: 726 | G27: 3 | H27: 9 | J27: =(E27*2240)+(F27*112)+(G27*28)+H27 -> 81405 | L27: =J27/2240 -> 36.341518
A28: 1700 | B28: Molasses | C28: Jamaica | D28: Out Ports | F28: 127 | J28: =(E28*2240)+(F28*112)+(G28*28)+H28 -> 14224 | L28: =J28/2240 -> 6.35
A29: 1700 | B29: Brown Sugar | C29: Jamaica | D29: Out Ports | F29: 19718 | G29: 3 | H29: 12 | J29: =(E29*2240)+(F29*112)+(G29*28)+H29 -> 2208512 | L29: =J29/2240 -> 985.94286
A30: 1700 | B30: White Sugar | C30: Jamaica | D30: Out Ports | F30: 20 | G30: 1 | H30: 3 | J30: =(E30*2240)+(F30*112)+(G30*28)+H30 -> 2271 | L30: =J30/2240 -> 1.0138393
A31: 1700 | B31: Indigo | C31: Jamaica | D31: Out Ports | H31: 19470 | J31: =(E31*2240)+(F31*112)+(G31*28)+H31 -> 19470 | L31: =J31/2240 -> 8.6919643
A32: 1700 | B32: Succands | C32: Jamaica | D32: Out Ports | H32: 210 | J32: =(E32*2240)+(F32*112)+(G32*28)+H32 -> 210 | L32: =J32/2240 -> 0.09375
A33: 1700 | B33: Tobacco | C33: Jamaica | D33: Out Ports | H33: 2475 | J33: =(E33*2240)+(F33*112)+(G33*28)+H33 -> 2475 | L33: =J33/2240 -> 1.1049107
A34: 1700 | B34: Cotton | C34: Jamaica | D34: Out Ports | F34: 709 | H34: 25 | J34: =(E34*2240)+(F34*112)+(G34*28)+H34 -> 79433 | L34: =J34/2240 -> 35.461161
A35: 1700 | B35: Chocolate | C35: Jamaica | D35: Out Ports | H35: 19.5 | J35: =(E35*2240)+(F35*112)+(G35*28)+H35 -> 19.5 | L35: =J35/2240 -> 0.0087053571
A36: 1700 | B36: Cocoa Nuts | C36: Jamaica | D36: Out Ports | H36: 787 | J36: =(E36*2240)+(F36*112)+(G36*28)+H36 -> 787 | L36: =J36/2240 -> 0.35133929
A37: 1700 | B37: Lime Juice | C37: Jamaica | D37: Out Ports | H37: 29773 | I37: 2976.5 Gallons | J37: =(E37*2240)+(F37*112)+(G37*28)+H37 -> 29773 | L37: =J37/2240 -> 13.291518
A38: 1700 | B38: Pimento | C38: Jamaica | D38: Out Ports | H38: 24825 | J38: =(E38*2240)+(F38*112)+(G38*28)+H38 -> 24825 | L38: =J38/2240 -> 11.082589
A39: 1700 | B39: Rum | C39: Jamaica | D39: Out Ports | H39: 680 | I39: 68 Gallons | J39: =(E39*2240)+(F39*112)+(G39*28)+H39 -> 680 | L39: =J39/2240 -> 0.30357143
A40: 1700 | B40: Tortoise Shell | C40: Jamaica | D40: Out Ports | H40: 616 | J40: =(E40*2240)+(F40*112)+(G40*28)+H40 -> 616 | L40: =J40/2240 -> 0.275

Sheet Mountserat
A1: YEAR | B1: COMMODITY_NAME | C1: FROM_LOCATION | D1: TO_LOCATION | E1: ton | F1: hh | G1: quarter | H1: lb | J1: Total Pounds | L1: WEIGHT
A2: 1700 | B2: Elephants Teeth | C2: Mountserat | D2: London | F2: 5 | G2: 3 | H2: 27 | J2: =(E2*2240)+(F2*112)+(G2*28)+H2 -> 671 | L2: =J2/2240 -> 0.29955357
A3: 1700 | B3: Dry Ginger | C3: Mountserat | D3: London | G3: 3 | H3: 14 | J3: =(E3*2240)+(F3*112)+(G3*28)+H3 -> 98 | L3: =J3/2240 -> 0.04375
A4: 1700 | B4: Molasses | C4: Mountserat | D4: London | F4: 197 | G4: 3 | J4: =(E4*2240)+(F4*112)+(G4*28)+H4 -> 22148 | L4: =J4/2240 -> 9.8875
A5: 1700 | B5: Brown Sugar | C5: Mountserat | D5: London | F5: 23704 | H5: 22 | J5: =(E5*2240)+(F5*112)+(G5*28)+H5 -> 2654870 | L5: =J5/2240 -> 1185.2098
A6: 1700 | B6: Indigo | C6: Mountserat | D6: London | H6: 8537 | J6: =(E6*2240)+(F6*112)+(G6*28)+H6 -> 8537 | L6: =J6/2240 -> 3.8111607
A7: 1700 | B7: Shruff | C7: Mountserat | D7: London | F7: 16 | H7: 14 | J7: =(E7*2240)+(F7*112)+(G7*28)+H7 -> 1806 | L7: =J7/2240 -> 0.80625
A8: 1700 | B8: Succands | C8: Mountserat | D8: London | H8: 162 | J8: =(E8*2240)+(F8*112)+(G8*28)+H8 -> 162 | L8: =J8/2240 -> 0.072321429
A9: 1700 | B9: Cotton | C9: Mountserat | D9: London | H9: =15*200 -> 3000 | I9: 15 Bags | J9: =(E9*2240)+(F9*112)+(G9*28)+H9 -> 3000 | L9: =J9/2240 -> 1.3392857
A10: 1700 | B10: Berries for Buttons | C10: Mountserat | D10: London | H10: 4002 | J10: =(E10*2240)+(F10*112)+(G10*28)+H10 -> 4002 | L10: =J10/2240 -> 1.7866071
A11: 1700 | B11: Lime Juice | C11: Mountserat | D11: London | H11: 4191 | I11: 419 Gallons | J11: =(E11*2240)+(F11*112)+(G11*28)+H11 -> 4191 | L11: =J11/2240 -> 1.8709821
A12: 1700 | B12: Pimento | C12: Mountserat | D12: London | H12: 2096 | J12: =(E12*2240)+(F12*112)+(G12*28)+H12 -> 2096 | L12: =J12/2240 -> 0.93571429
A13: 1700 | B13: Tortoise Shell | C13: Mountserat | D13: London | H13: 10 | J13: =(E13*2240)+(F13*112)+(G13*28)+H13 -> 10 | L13: =J13/2240 -> 0.0044642857
A14: 1700 | B14: Dry Ginger | C14: Mountserat | D14: Out Ports | F14: 2 | G14: 1 | H14: 5 | J14: =(E14*2240)+(F14*112)+(G14*28)+H14 -> 257 | L14: =J14/2240 -> 0.11473214
A15: 1700 | B15: Molasses | C15: Mountserat | D15: Out Ports | F15: 24 | G15: 3 | H15: 25 | J15: =(E15*2240)+(F15*112)+(G15*28)+H15 -> 2797 | L15: =J15/2240 -> 1.2486607
A16: 1700 | B16: Brown Sugar | C16: Mountserat | D16: Out Ports | F16: 6022 | H16: 2 | J16: =(E16*2240)+(F16*112)+(G16*28)+H16 -> 674466 | L16: =J16/2240 -> 301.10089
A17: 1700 | B17: White Sugar | C17: Mountserat | D17: Out Ports | G17: 2 | H17: 5 | J17: =(E17*2240)+(F17*112)+(G17*28)+H17 -> 61 | L17: =J17/2240 -> 0.027232143
A18: 1700 | B18: Indigo | C18: Mountserat | D18: Out Ports | H18: 726 | J18: =(E18*2240)+(F18*112)+(G18*28)+H18 -> 726 | L18: =J18/2240 -> 0.32410714
A19: 1700 | B19: Shruff | C19: Mountserat | D19: Out Ports | F19: 5 | G19: 3 | H19: 21 | J19: =(E19*2240)+(F19*112)+(G19*28)+H19 -> 665 | L19: =J19/2240 -> 0.296875
A20: 1700 | B20: Succands | C20: Mountserat | D20: Out Ports | H20: 140 | J20: =(E20*2240)+(F20*112)+(G20*28)+H20 -> 140 | L20: =J20/2240 -> 0.0625
A21: 1700 | B21: Cotton | C21: Mountserat | D21: Out Ports | F21: 29 | G21: 1 | H21: 26 | J21: =(E21*2240)+(F21*112)+(G21*28)+H21 -> 3302 | L21: =J21/2240 -> 1.4741071
A22: 1700 | B22: Lime Juice | C22: Mountserat | D22: Out Ports | H22: 3056 | I22: 305.5 Gallons | J22: =(E22*2240)+(F22*112)+(G22*28)+H22 -> 3056 | L22: =J22/2240 -> 1.3642857
A23: 1700 | B23: Pimento | C23: Mountserat | D23: Out Ports | H23: 1070 | J23: =(E23*2240)+(F23*112)+(G23*28)+H23 -> 1070 | L23: =J23/2240 -> 0.47767857

Sheet Nevis
A1: YEAR | B1: COMMODITY_NAME | C1: FROM_LOCATION | D1: TO_LOCATION | E1: ton | F1: hh | G1: quarter | H1: lb | J1: Total Pounds | L1: WEIGHT | N1: Not Sugar | P1: Sugar
A2: 1700 | B2: Elephant Teeth | C2: Nevis | D2: London | F2: 23 | G2: 1 | H2: 10 | J2: =(E2*2240)+(F2*112)+(G2*28)+(H2/16) -> 2604.625 | L2: =J2/2240 -> 1.162779 | N2: =L2+L5+L6+L7+L8+L10+L11+L13+L17+L18+L19+L20 -> 14.224749 | P2: =L3+L4+L14+L15+L16 -> 3198.7264
A3: 1700 | B3: Molasses | C3: Nevis | D3: London | F3: 1418 | G3: 3 | J3: =(E3*2240)+(F3*112)+(G3*28)+(H3/16) -> 158900 | L3: =J3/2240 -> 70.9375
A4: 1700 | B4: Brown Sugar | C4: Nevis | D4: London | F4: 47105 | H4: 20 | J4: =(E4*2240)+(F4*112)+(G4*28)+(H4/16) -> 5275761.2 | L4: =J4/2240 -> 2355.2506
A5: 1700 | B5: Indigo | C5: Nevis | D5: London | H5: 149 | J5: =(E5*2240)+(F5*112)+(G5*28)+(H5/16) -> 9.3125 | L5: =J5/2240 -> 0.0041573661
A6: 1700 | B6: Shruff | C6: Nevis | D6: London | F6: 8 | G6: 3 | J6: =(E6*2240)+(F6*112)+(G6*28)+(H6/16) -> 980 | L6: =J6/2240 -> 0.4375
A7: 1700 | B7: Succands | C7: Nevis | D7: London | H7: 128 | J7: =(E7*2240)+(F7*112)+(G7*28)+(H7/16) -> 8 | L7: =J7/2240 -> 0.0035714286
A8: 1700 | B8: Tobacco | C8: Nevis | D8: London | H8: 1068 | J8: =(E8*2240)+(F8*112)+(G8*28)+(H8/16) -> 66.75 | L8: =J8/2240 -> 0.029799107
A9: 1700 | B9: Cotton | C9: Nevis | D9: London | H9: =21*200 -> 4200 | I9: 21 Bags | J9: =(E9*2240)+(F9*112)+(G9*28)+(H9/16) -> 262.5 | L9: =J9/2240 -> 0.1171875
A10: 1700 | B10: Cocoa Nuts | C10: Nevis | D10: London | F10: 3 | G10: 2 | J10: =(E10*2240)+(F10*112)+(G10*28)+(H10/16) -> 392 | L10: =J10/2240 -> 0.175
A11: 1700 | B11: Chocolate | C11: Nevis | D11: London | H11: 22 | J11: =(E11*2240)+(F11*112)+(G11*28)+(H11/16) -> 1.375 | L11: =J11/2240 -> 0.00061383929
A12: 1700 | B12: Lime Juice | C12: Nevis | D12: London | H12: 3141 | I12: 314 Gallons | J12: =(E12*2240)+(F12*112)+(G12*28)+(H12/16) -> 196.3125 | L12: =J12/2240 -> 0.087639509
A13: 1700 | B13: Elephant Teeth | C13: Nevis | D13: Out Ports | H13: 2 | J13: =(E13*2240)+(F13*112)+(G13*28)+(H13/16) -> 0.125 | L13: =J13/2240 -> 5.5803571e-05
A14: 1700 | B14: Molasses | C14: Nevis | D14: Out Ports | F14: 690 | G14: 2 | H14: 10 | J14: =(E14*2240)+(F14*112)+(G14*28)+(H14/16) -> 77336.625 | L14: =J14/2240 -> 34.525279
A15: 1700 | B15: Brown Sugar | C15: Nevis | D15: Out Ports | F15: 14760 | H15: 5 | J15: =(E15*2240)+(F15*112)+(G15*28)+(H15/16) -> 1653120.3 | L15: =J15/2240 -> 738.00014
A16: 1700 | B16: White Sugar | C16: Nevis | D16: Out Ports | G16: 1 | H16: 16 | J16: =(E16*2240)+(F16*112)+(G16*28)+(H16/16) -> 29 | L16: =J16/2240 -> 0.012946429
A17: 1700 | B17: Indigo | C17: Nevis | D17: Out Ports | H17: 359 | J17: =(E17*2240)+(F17*112)+(G17*28)+(H17/16) -> 22.4375 | L17: =J17/2240 -> 0.010016741
A18: 1700 | B18: Shruff | C18: Nevis | D18: Out Ports | F18: 31 | G18: 3 | H18: 8 | J18: =(E18*2240)+(F18*112)+(G18*28)+(H18/16) -> 3556.5 | L18: =J18/2240 -> 1.5877232
A19: 1700 | B19: Succands | C19: Nevis | D19: Out Ports | H19: 33 | J19: =(E19*2240)+(F19*112)+(G19*28)+(H19/16) -> 2.0625 | L19: =J19/2240 -> 0.00092075893
A20: 1700 | B20: Cotton | C20: Nevis | D20: Out Ports | F20: 216 | G20: 1 | H20: 4 | J20: =(E20*2240)+(F20*112)+(G20*28)+(H20/16) -> 24220.25 | L20: =J20/2240 -> 10.812612
A21: 1700 | B21: Lime Juice | C21: Nevis | D21: Out Ports | H21: 1090 | I21: 109 Gallons | J21: =(E21*2240)+(F21*112)+(G21*28)+(H21/16) -> 68.125 | L21: =J21/2240 -> 0.030412946

Sheet NewEngland
A1: YEAR | B1: COMMODITY_NAME | C1: FROM_LOCATION | D1: TO_LOCATION | E1: ton | F1: hh | G1: quarter | H1: lb | J1: Total Pounds | L1: WEIGHT | N1: Not Sugar | P1: Sugar
A2: 1700 | B2: Opium | C2: NewEngland | D2: London | H2: 135 | J2: =(E2*2240)+(F2*112)+(G2*28)+H2 -> 135 | L2: =J2/2240 -> 0.060267857 | N2: =L2+L3+L4+L6+L9+L10+L11+L12+L13+L16+L18+L19+L20+L21+L22+L23+L25+L26+L27 -> 15.638393 | P2: =L5+L7+L24 -> 740.35
A3: 1700 | B3: Elephant Teeth | C3: NewEngland | D3: London | F3: 8 | G3: 2 | H3: 18 | J3: =(E3*2240)+(F3*112)+(G3*28)+H3 -> 970 | L3: =J3/2240 -> 0.43303571
A4: 1700 | B4: Dry Ginger | C4: NewEngland | D4: London | F4: 21 | G4: 2 | J4: =(E4*2240)+(F4*112)+(G4*28)+H4 -> 2408 | L4: =J4/2240 -> 1.075
A5: 1700 | B5: Molasses | C5: NewEngland | D5: London | F5: 7703 | G5: 3 | H5: 14 | J5: =(E5*2240)+(F5*112)+(G5*28)+H5 -> 862834 | L5: =J5/2240 -> 385.19375
A6: 1700 | B6: Rice | C6: NewEngland | D6: London | F6: 25 | G6: 2 | H6: 5 | J6: =(E6*2240)+(F6*112)+(G6*28)+H6 -> 2861 | L6: =J6/2240 -> 1.2772321
A7: 1700 | B7: Brown Sugar | C7: NewEngland | D7: London | F7: 7066 | G7: 2 | H7: 10 | J7: =(E7*2240)+(F7*112)+(G7*28)+H7 -> 791458 | L7: =J7/2240 -> 353.32946
A8: 1700 | B8: Sugar Loaf | C8: NewEngland | D8: London | H8: 4 | J8: =(E8*2240)+(F8*112)+(G8*28)+H8 -> 4 | L8: =J8/2240 -> 0.0017857143
A9: 1700 | B9: Indigo | C9: NewEngland | D9: London | H9: 454 | J9: =(E9*2240)+(F9*112)+(G9*28)+H9 -> 454 | L9: =J9/2240 -> 0.20267857
A10: 1700 | B10: Shruff | C10: NewEngland | D10: London | F10: 27 | G10: 2 | H10: 14 | J10: =(E10*2240)+(F10*112)+(G10*28)+H10 -> 3094 | L10: =J10/2240 -> 1.38125
A11: 1700 | B11: Slude | C11: NewEngland | D11: London | H11: 60 | J11: =(E11*2240)+(F11*112)+(G11*28)+H11 -> 60 | L11: =J11/2240 -> 0.026785714
A12: 1700 | B12: Succands | C12: NewEngland | D12: London | H12: 7 | J12: =(E12*2240)+(F12*112)+(G12*28)+H12 -> 7 | L12: =J12/2240 -> 0.003125
A13: 1700 | B13: Tobacco | C13: NewEngland | D13: London | H13: 15991 | J13: =(E13*2240)+(F13*112)+(G13*28)+H13 -> 15991 | L13: =J13/2240 -> 7.1388393
A14: 1700 | B14: Madera Wine | C14: NewEngland | D14: London | H14: 510 | I14: 51 Gallons | J14: =(E14*2240)+(F14*112)+(G14*28)+H14 -> 510 | L14: =J14/2240 -> 0.22767857
A15: 1700 | B15: Cotton | C15: NewEngland | D15: London | H15: 170 | I15: 1 Bag | J15: =(E15*2240)+(F15*112)+(G15*28)+H15 -> 170 | L15: =J15/2240 -> 0.075892857
A16: 1700 | B16: Bayberry Wax | C16: NewEngland | D16: London | F16: 2 | G16: 2 | H16: 15 | J16: =(E16*2240)+(F16*112)+(G16*28)+H16 -> 295 | L16: =J16/2240 -> 0.13169643
A17: 1700 | B17: Brandy | C17: NewEngland | D17: London | H17: 30 | I17: 3 Gallons | J17: =(E17*2240)+(F17*112)+(G17*28)+H17 -> 30 | L17: =J17/2240 -> 0.013392857
A18: 1700 | B18: Chocolate | C18: NewEngland | D18: London | H18: 1 | J18: =(E18*2240)+(F18*112)+(G18*28)+H18 -> 1 | L18: =J18/2240 -> 0.00044642857
A19: 1700 | B19: Cocoa Nuts | C19: NewEngland | D19: London | F19: 1 | G19: 3 | H19: 23 | J19: =(E19*2240)+(F19*112)+(G19*28)+H19 -> 219 | L19: =J19/2240 -> 0.097767857
A20: 1700 | B20: Cranberrys | C20: NewEngland | D20: London | H20: 108 | J20: =(E20*2240)+(F20*112)+(G20*28)+H20 -> 108 | L20: =J20/2240 -> 0.048214286
A21: 1700 | B21: Pimento | C21: NewEngland | D21: London | H21: 413 | J21: =(E21*2240)+(F21*112)+(G21*28)+H21 -> 413 | L21: =J21/2240 -> 0.184375
A22: 1700 | B22: Tortoise shell | C22: NewEngland | D22: London | H22: 100 | J22: =(E22*2240)+(F22*112)+(G22*28)+H22 -> 100 | L22: =J22/2240 -> 0.044642857
A23: 1700 | B23: Indigo | C23: NewEngland | D23: Out Ports | H23: 262 | J23: =(E23*2240)+(F23*112)+(G23*28)+H23 -> 262 | L23: =J23/2240 -> 0.11696429
A24: 1700 | B24: Brown Sugar | C24: NewEngland | D24: Out Ports | F24: 36 | G24: 2 | H24: 4 | J24: =(E24*2240)+(F24*112)+(G24*28)+H24 -> 4092 | L24: =J24/2240 -> 1.8267857
A25: 1700 | B25: Tobacco | C25: NewEngland | D25: Out Ports | H25: 7379 | J25: =(E25*2240)+(F25*112)+(G25*28)+H25 -> 7379 | L25: =J25/2240 -> 3.2941964
A26: 1700 | B26: Bayberry Wax | C26: NewEngland | D26: Out Ports | F26: 2 | G26: 1 | H26: 7 | J26: =(E26*2240)+(F26*112)+(G26*28)+H26 -> 259 | L26: =J26/2240 -> 0.115625
A27: 1700 | B27: Cranberrys | C27: NewEngland | D27: Out Ports | H27: 14 | J27: =(E27*2240)+(F27*112)+(G27*28)+H27 -> 14 | L27: =J27/2240 -> 0.00625
