Workbook

Sheet Master Goods Sheet
A1: Item | B1: Total London | C1: Total Outports | D1: Total
A2: Annatto | B2: =SUMIFS(Antigua!$M:$M, Antigua!$B:$B, $A2, Antigua!$D:$D, "London") + SUMIFS(Barbados!$L:$L, Barbados!$B:$B, $A2, Barbados!$D:$D, "London") + SUMIFS(Bermuda!$L:$L, Bermuda!$B:$B, $A2, Bermuda!$D:$D, "London") + SUMIFS(Carolina!$L:$L, Carolina!$B:$B, $A2, Carolina!$D:$D, "London") + SUMIFS(Jamaica!$L:$L, Jamaica!$B:$B, $A2, Jamaica!$D:$D, "London") + SUMIFS(Mountserat!$L:$L, Mountserat!$B:$B, $A2, Mountserat!$D:$D, "London") + SUMIFS(Nevis!$L:$L, Nevis!$B:$B, $A2, Nevis!$D:$D, "London") -> 3.0116071 | C2: =SUMIFS(Antigua!$M:$M, Antigua!$B:$B, $A2, Antigua!$D:$D, "Out Ports") + SUMIFS(Barbados!$L:$L, Barbados!$B:$B, $A2, Barbados!$D:$D, "Out Ports") + SUMIFS(Bermuda!$L:$L, Bermuda!$B:$B, $A2, Bermuda!$D:$D, "Out Ports") + SUMIFS(Carolina!$L:$L, Carolina!$B:$B, $A2, Carolina!$D:$D, "Out Ports") + SUMIFS(Jamaica!$L:$L, Jamaica!$B:$B, $A2, Jamaica!$D:$D, "Out Ports") + SUMIFS(Mountserat!$L:$L, Mountserat!$B:$B, $A2, Mountserat!$D:$D, "Out Ports") + SUMIFS(Nevis!$L:$L, Nevis!$B:$B, $A2, Nevis!$D:$D, "Out Ports") -> 0 | D2: =ROUND((B2+C2),2) -> 3.01
A3: Bayberry Wax | B3: =SUMIFS(Antigua!$M:$M, Antigua!$B:$B, $A3, Antigua!$D:$D, "London") + SUMIFS(Barbados!$L:$L, Barbados!$B:$B, $A3, Barbados!$D:$D, "London") + SUMIFS(Bermuda!$L:$L, Bermuda!$B:$B, $A3, Bermuda!$D:$D, "London") + SUMIFS(Carolina!$L:$L, Carolina!$B:$B, $A3, Carolina!$D:$D, "London") + SUMIFS(Jamaica!$L:$L, Jamaica!$B:$B, $A3, Jamaica!$D:$D, "London") + SUMIFS(Mountserat!$L:$L, Mountserat!$B:$B, $A3, Mountserat!$D:$D, "London") + SUMIFS(Nevis!$L:$L, Nevis!$B:$B, $A3, Nevis!$D:$D, "London") -> 0 | C3: =SUMIFS(Antigua!$M:$M, Antigua!$B:$B, $A3, Antigua!$D:$D, "Out Ports") + SUMIFS(Barbados!$L:$L, Barbados!$B:$B, $A3, Barbados!$D:$D, "Out Ports") + SUMIFS(Bermuda!$L:$L, Bermuda!$B:$B, $A3, Bermuda!$D:$D, "Out Ports") + SUMIFS(Carolina!$L:$L, Carolina!$B:$B, $A3, Carolina!$D:$D, "Out Ports") + SUMIFS(Jamaica!$L:$L, Jamaica!$B:$B, $A3, Jamaica!$D:$D, "Out Ports") + SUMIFS(Mountserat!$L:$L, Mountserat!$B:$B, $A3, Mountserat!$D:$D, "Out Ports") + SUMIFS(Nevis!$L:$L, Nevis!$B:$B, $A3, Nevis!$D:$D, "Out Ports") -> 0 | D3: =ROUND((B3+C3),2) -> 0
A4: Bees Wax | B4: =SUMIFS(Antigua!$M:$M, Antigua!$B:$B, $A4, Antigua!$D:$D, "London") + SUMIFS(Barbados!$L:$L, Barbados!$B:$B, $A4, Barbados!$D:$D, "London") + SUMIFS(Bermuda!$L:$L, Bermuda!$B:$B, $A4, Bermuda!$D:$D, "London") + SUMIFS(Carolina!$L:$L, Carolina!$B:$B, $A4, Carolina!$D:$D, "London") + SUMIFS(Jamaica!$L:$L, Jamaica!$B:$B, $A4, Jamaica!$D:$D, "London") + SUMIFS(Mountserat!$L:$L, Mountserat!$B:$B, $A4, Mountserat!$D:$D, "London") + SUMIFS(Nevis!$L:$L, Nevis!$B:$B, $A4, Nevis!$D:$D, "London") -> 0.434375 | C4: =SUMIFS(Antigua!$M:$M, Antigua!$B:$B, $A4, Antigua!$D:$D, "Out Ports") + SUMIFS(Barbados!$L:$L, Barbados!$B:$B, $A4, Barbados!$D:$D, "Out Ports") + SUMIFS(Bermuda!$L:$L, Bermuda!$B:$B, $A4, Bermuda!$D:$D, "Out Ports") + SUMIFS(Carolina!$L:$L, Carolina!$B:$B, $A4, Carolina!$D:$D, "Out Ports") + SUMIFS(Jamaica!$L:$L, Jamaica!$B:$B, $A4, Jamaica!$D:$D, "Out Ports") + SUMIFS(Mountserat!$L:$L, Mountserat!$B:$B, $A4, Mountserat!$D:$D, "Out Ports") + SUMIFS(Nevis!$L:$L, Nevis!$B:$B, $A4, Nevis!$D:$D, "Out Ports") -> 0 | D4: =ROUND((B4+C4),2) -> 0.43
A5: Brandy | B5: =SUMIFS(Antigua!$M:$M, Antigua!$B:$B, $A5, Antigua!$D:$D, "London") + SUMIFS(Barbados!$L:$L, Barbados!$B:$B, $A5, Barbados!$D:$D, "London") + SUMIFS(Bermuda!$L:$L, Bermuda!$B:$B, $A5, Bermuda!$D:$D, "London") + SUMIFS(Carolina!$L:$L, Carolina!$B:$B, $A5, Carolina!$D:$D, "London") + SUMIFS(Jamaica!$L:$L, Jamaica!$B:$B, $A5, Jamaica!$D:$D, "London") + SUMIFS(Mountserat!$L:$L, Mountserat!$B:$B, $A5, Mountserat!$D:$D, "London") + SUMIFS(Nevis!$L:$L, Nevis!$B:$B, $A5, Nevis!$D:$D, "London") -> 0 | C5: =SUMIFS(Antigua!$M:$M, Antigua!$B:$B, $A5, Antigua!$D:$D, "Out Ports") + SUMIFS(Barbados!$L:$L, Barbados!$B:$B, $A5, Barbados!$D:$D, "Out Ports") + SUMIFS(Bermuda!$L:$L, Bermuda!$B:$B, $A5, Bermuda!$D:$D, "Out Ports") + SUMIFS(Carolina!$L:$L, Carolina!$B:$B, $A5, Carolina!$D:$D, "Out Ports") + SUMIFS(Jamaica!$L:$L, Jamaica!$B:$B, $A5, Jamaica!$D:$D, "Out Ports") + SUMIFS(Mountserat!$L:$L, Mountserat!$B:$B, $A5, Mountserat!$D:$D, "Out Ports") + SUMIFS(Nevis!$L:$L, Nevis!$B:$B, $A5, Nevis!$D:$D, "Out Ports") -> 0 | D5: =ROUND((B5+C5),2) -> 0
A6: Brown Sugar | B6: =SUMIFS(Antigua!$M:$M, Antigua!$B:$B, $A6, Antigua!$D:$D, "London") + SUMIFS(Barbados!$L:$L, Barbados!$B:$B, $A6, Barbados!$D:$D, "London") + SUMIFS(Bermuda!$L:$L, Bermuda!$B:$B, $A6, Bermuda!$D:$D, "London") + SUMIFS(Carolina!$L:$L, Carolina!$B:$B, $A6, Carolina!$D:$D, "London") + SUMIFS(Jamaica!$L:$L, Jamaica!$B:$B, $A6, Jamaica!$D:$D, "London") + SUMIFS(Mountserat!$L:$L, Mountserat!$B:$B, $A6, Mountserat!$D:$D, "London") + SUMIFS(Nevis!$L:$L, Nevis!$B:$B, $A6, Nevis!$D:$D, "London") -> 15136.889 | C6: =SUMIFS(Antigua!$M:$M, Antigua!$B:$B, $A6, Antigua!$D:$D, "Out Ports") + SUMIFS(Barbados!$L:$L, Barbados!$B:$B, $A6, Barbados!$D:$D, "Out Ports") + SUMIFS(Bermuda!$L:$L, Bermuda!$B:$B, $A6, Bermuda!$D:$D, "Out Ports") + SUMIFS(Carolina!$L:$L, Carolina!$B:$B, $A6, Carolina!$D:$D, "Out Ports") + SUMIFS(Jamaica!$L:$L, Jamaica!$B:$B, $A6, Jamaica!$D:$D, "Out Ports") + SUMIFS(Mountserat!$L:$L, Mountserat!$B:$B, $A6, Mountserat!$D:$D, "Out Ports") + SUMIFS(Nevis!$L:$L, Nevis!$B:$B, $A6, Nevis!$D:$D, "Out Ports") -> 2938.1438 | D6: =ROUND((B6+C6),2) -> 18075.03
A7: Cascarilla | B7: =SUMIFS(Antigua!$M:$M, Antigua!$B:$B, $A7, Antigua!$D:$D, "London") + SUMIFS(Barbados!$L:$L, Barbados!$B:$B, $A7, Barbados!$D:$D, "London") + SUMIFS(Bermuda!$L:$L, Bermuda!$B:$B, $A7, Bermuda!$D:$D, "London") + SUMIFS(Carolina!$L:$L, Carolina!$B:$B, $A7, Carolina!$D:$D, "London") + SUMIFS(Jamaica!$L:$L, Jamaica!$B:$B, $A7, Jamaica!$D:$D, "London") + SUMIFS(Mountserat!$L:$L, Mountserat!$B:$B, $A7, Mountserat!$D:$D, "London") + SUMIFS(Nevis!$L:$L, Nevis!$B:$B, $A7, Nevis!$D:$D, "London") -> 0.041517857 | C7: =SUMIFS(Antigua!$M:$M, Antigua!$B:$B, $A7, Antigua!$D:$D, "Out Ports") + SUMIFS(Barbados!$L:$L, Barbados!$B:$B, $A7, Barbados!$D:$D, "Out Ports") + SUMIFS(Bermuda!$L:$L, Bermuda!$B:$B, $A7, Bermuda!$D:$D, "Out Ports") + SUMIFS(Carolina!$L:$L, Carolina!$B:$B, $A7, Carolina!$D:$D, "Out Ports") + SUMIFS(Jamaica!$L:$L, Jamaica!$B:$B, $A7, Jamaica!$D:$D, "Out Ports") + SUMIFS(Mountserat!$L:$L, Mountserat!$B:$B, $A7, Mountserat!$D:$D, "Out Ports") + SUMIFS(Nevis!$L:$L, Nevis!$B:$B, $A7, Nevis!$D:$D, "Out Ports") -> 0 | D7: =ROUND((B7+C7),2) -> 0.04
A8: Chocolate | B8: =SUMIFS(Antigua!$M:$M, Antigua!$B:$B, $A8, Antigua!$D:$D, "London") + SUMIFS(Barbados!$L:$L, Barbados!$B:$B, $A8, Barbados!$D:$D, "London") + SUMIFS(Bermuda!$L:$L, Bermuda!$B:$B, $A8, Bermuda!$D:$D, "London") + SUMIFS(Carolina!$L:$L, Carolina!$B:$B, $A8, Carolina!$D:$D, "London") + SUMIFS(Jamaica!$L:$L, Jamaica!$B:$B, $A8, Jamaica!$D:$D, "London") + SUMIFS(Mountserat!$L:$L, Mountserat!$B:$B, $A8, Mountserat!$D:$D, "London") + SUMIFS(Nevis!$L:$L, Nevis!$B:$B, $A8, Nevis!$D:$D, "London") -> 0.12946429 | C8: =SUMIFS(Antigua!$M:$M, Antigua!$B:$B, $A8, Antigua!$D:$D, "Out Ports") + SUMIFS(Barbados!$L:$L, Barbados!$B:$B, $A8, Barbados!$D:$D, "Out Ports") + SUMIFS(Bermuda!$L:$L, Bermuda!$B:$B, $A8, Bermuda!$D:$D, "Out Ports") + SUMIFS(Carolina!$L:$L, Carolina!$B:$B, $A8, Carolina!$D:$D, "Out Ports") + SUMIFS(Jamaica!$L:$L, Jamaica!$B:$B, $A8, Jamaica!$D:$D, "Out Ports") + SUMIFS(Mountserat!$L:$L, Mountserat!$B:$B, $A8, Mountserat!$D:$D, "Out Ports") + SUMIFS(Nevis!$L:$L, Nevis!$B:$B, $A8, Nevis!$D:$D, "Out Ports") -> 0.035267857 | D8: =ROUND((B8+C8),2) -> 0.16
A9: Cockeneal | B9: =SUMIFS(Antigua!$M:$M, Antigua!$B:$B, $A9, Antigua!$D:$D, "London") + SUMIFS(Barbados!$L:$L, Barbados!$B:$B, $A9, Barbados!$D:$D, "London") + SUMIFS(Bermuda!$L:$L, Bermuda!$B:$B, $A9, Bermuda!$D:$D, "London") + SUMIFS(Carolina!$L:$L, Carolina!$B:$B, $A9, Carolina!$D:$D, "London") + SUMIFS(Jamaica!$L:$L, Jamaica!$B:$B, $A9, Jamaica!$D:$D, "London") + SUMIFS(Mountserat!$L:$L, Mountserat!$B:$B, $A9, Mountserat!$D:$D, "London") + SUMIFS(Nevis!$L:$L, Nevis!$B:$B, $A9, Nevis!$D:$D, "London") -> 0 | C9: =SUMIFS(Antigua!$M:$M, Antigua!$B:$B, $A9, Antigua!$D:$D, "Out Ports") + SUMIFS(Barbados!$L:$L, Barbados!$B:$B, $A9, Barbados!$D:$D, "Out Ports") + SUMIFS(Bermuda!$L:$L, Bermuda!$B:$B, $A9, Bermuda!$D:$D, "Out Ports") + SUMIFS(Carolina!$L:$L, Carolina!$B:$B, $A9, Carolina!$D:$D, "Out Ports") + SUMIFS(Jamaica!$L:$L, Jamaica!$B:$B, $A9, Jamaica!$D:$D, "Out Ports") + SUMIFS(Mountserat!$L:$L, Mountserat!$B:$B, $A9, Mountserat!$D:$D, "Out Ports") + SUMIFS(Nevis!$L:$L, Nevis!$B:$B, $A9, Nevis!$D:$D, "Out Ports") -> 0 | D9: =ROUND((B9+C9),2) -> 0
A10: Cocoa Nuts | B10: =SUMIFS(Antigua!$M:$M, Antigua!$B:$B, $A10, Antigua!$D:$D, "London") + SUMIFS(Barbados!$L:$L, Barbados!$B:$B, $A10, Barbados!$D:$D, "London") + SUMIFS(Bermuda!$L:$L, Bermuda!$B:$B, $A10, Bermuda!$D:$D, "London") + SUMIFS(Carolina!$L:$L, Carolina!$B:$B, $A10, Carolina!$D:$D, "London") + SUMIFS(Jamaica!$L:$L, Jamaica!$B:$B, $A10, Jamaica!$D:$D, "London") + SUMIFS(Mountserat!$L:$L, Mountserat!$B:$B, $A10, Mountserat!$D:$D, "London") + SUMIFS(Nevis!$L:$L, Nevis!$B:$B, $A10, Nevis!$D:$D, "London") -> 67.934375 | C10: =SUMIFS(Antigua!$M:$M, Antigua!$B:$B, $A10, Antigua!$D:$D, "Out Ports") + SUMIFS(Barbados!$L:$L, Barbados!$B:$B, $A10, Barbados!$D:$D, "Out Ports") + SUMIFS(Bermuda!$L:$L, Bermuda!$B:$B, $A10, Bermuda!$D:$D, "Out Ports") + SUMIFS(Carolina!$L:$L, Carolina!$B:$B, $A10, Carolina!$D:$D, "Out Ports") + SUMIFS(Jamaica!$L:$L, Jamaica!$B:$B, $A10, Jamaica!$D:$D, "Out Ports") + SUMIFS(Mountserat!$L:$L, Mountserat!$B:$B, $A10, Mountserat!$D:$D, "Out Ports") + SUMIFS(Nevis!$L:$L, Nevis!$B:$B, $A10, Nevis!$D:$D, "Out Ports") -> 0.465625 | D10: =ROUND((B10+C10),2) -> 68.4
A11: Cotton | B11: =SUMIFS(Antigua!$M:$M, Antigua!$B:$B, $A11, Antigua!$D:$D, "London") + SUMIFS(Barbados!$L:$L, Barbados!$B:$B, $A11, Barbados!$D:$D, "London") + SUMIFS(Bermuda!$L:$L, Bermuda!$B:$B, $A11, Bermuda!$D:$D, "London") + SUMIFS(Carolina!$L:$L, Carolina!$B:$B, $A11, Carolina!$D:$D, "London") + SUMIFS(Jamaica!$L:$L, Jamaica!$B:$B, $A11, Jamaica!$D:$D, "London") + SUMIFS(Mountserat!$L:$L, Mountserat!$B:$B, $A11, Mountserat!$D:$D, "London") + SUMIFS(Nevis!$L:$L, Nevis!$B:$B, $A11, Nevis!$D:$D, "London") -> 312.5 | C11: =SUMIFS(Antigua!$M:$M, Antigua!$B:$B, $A11, Antigua!$D:$D, "Out Ports") + SUMIFS(Barbados!$L:$L, Barbados!$B:$B, $A11, Barbados!$D:$D, "Out Ports") + SUMIFS(Bermuda!$L:$L, Bermuda!$B:$B, $A11, Bermuda!$D:$D, "Out Ports") + SUMIFS(Carolina!$L:$L, Carolina!$B:$B, $A11, Carolina!$D:$D, "Out Ports") + SUMIFS(Jamaica!$L:$L, Jamaica!$B:$B, $A11, Jamaica!$D:$D, "Out Ports") + SUMIFS(Mountserat!$L:$L, Mountserat!$B:$B, $A11, Mountserat!$D:$D, "Out Ports") + SUMIFS(Nevis!$L:$L, Nevis!$B:$B, $A11, Nevis!$D:$D, "Out Ports") -> 75.404464 | D11: =ROUND((B11+C11),2) -> 387.9
A12: Dry Ginger | B12: =SUMIFS(Antigua!$M:$M, Antigua!$B:$B, $A12, Antigua!$D:$D, "London") + SUMIFS(Barbados!$L:$L, Barbados!$B:$B, $A12, Barbados!$D:$D, "London") + SUMIFS(Bermuda!$L:$L, Bermuda!$B:$B, $A12, Bermuda!$D:$D, "London") + SUMIFS(Carolina!$L:$L, Carolina!$B:$B, $A12, Carolina!$D:$D, "London") + SUMIFS(Jamaica!$L:$L, Jamaica!$B:$B, $A12, Jamaica!$D:$D, "London") + SUMIFS(Mountserat!$L:$L, Mountserat!$B:$B, $A12, Mountserat!$D:$D, "London") + SUMIFS(Nevis!$L:$L, Nevis!$B:$B, $A12, Nevis!$D:$D, "London") -> 326.42054 | C12: =SUMIFS(Antigua!$M:$M, Antigua!$B:$B, $A12, Antigua!$D:$D, "Out Ports") + SUMIFS(Barbados!$L:$L, Barbados!$B:$B, $A12, Barbados!$D:$D, "Out Ports") + SUMIFS(Bermuda!$L:$L, Bermuda!$B:$B, $A12, Bermuda!$D:$D, "Out Ports") + SUMIFS(Carolina!$L:$L, Carolina!$B:$B, $A12, Carolina!$D:$D, "Out Ports") + SUMIFS(Jamaica!$L:$L, Jamaica!$B:$B, $A12, Jamaica!$D:$D, "Out Ports") + SUMIFS(Mountserat!$L:$L, Mountserat!$B:$B, $A12, Mountserat!$D:$D, "Out Ports") + SUMIFS(Nevis!$L:$L, Nevis!$B:$B, $A12, Nevis!$D:$D, "Out Ports") -> 65.440625 | D12: =ROUND((B12+C12),2) -> 391.86
A13: Elephant Teeth | B13: =SUMIFS(Antigua!$M:$M, Antigua!$B:$B, $A13, Antigua!$D:$D, "London") + SUMIFS(Barbados!$L:$L, Barbados!$B:$B, $A13, Barbados!$D:$D, "London") + SUMIFS(Bermuda!$L:$L, Bermuda!$B:$B, $A13, Bermuda!$D:$D, "London") + SUMIFS(Carolina!$L:$L, Carolina!$B:$B, $A13, Carolina!$D:$D, "London") + SUMIFS(Jamaica!$L:$L, Jamaica!$B:$B, $A13, Jamaica!$D:$D, "London") + SUMIFS(Mountserat!$L:$L, Mountserat!$B:$B, $A13, Mountserat!$D:$D, "London") + SUMIFS(Nevis!$L:$L, Nevis!$B:$B, $A13, Nevis!$D:$D, "London") -> 37.621875 | C13: =SUMIFS(Antigua!$M:$M, Antigua!$B:$B, $A13, Antigua!$D:$D, "Out Ports") + SUMIFS(Barbados!$L:$L, Barbados!$B:$B, $A13, Barbados!$D:$D, "Out Ports") + SUMIFS(Bermuda!$L:$L, Bermuda!$B:$B, $A13, Bermuda!$D:$D, "Out Ports") + SUMIFS(Carolina!$L:$L, Carolina!$B:$B, $A13, Carolina!$D:$D, "Out Ports") + SUMIFS(Jamaica!$L:$L, Jamaica!$B:$B, $A13, Jamaica!$D:$D, "Out Ports") + SUMIFS(Mountserat!$L:$L, Mountserat!$B:$B, $A13, Mountserat!$D:$D, "Out Ports") + SUMIFS(Nevis!$L:$L, Nevis!$B:$B, $A13, Nevis!$D:$D, "Out Ports") -> 1.4049107 | D13: =ROUND((B13+C13),2) -> 39.03
... A31: Madera Wine | B31: =SUMIFS(Antigua!$M:$M, Antigua!$B:$B, $A31, Antigua!$D:$D, "London") + SUMIFS(Barbados!$L:$L, Barbados!$B:$B, $A31, Barbados!$D:$D, "London") + SUMIFS(Bermuda!$L:$L, Bermuda!$B:$B, $A31, Bermuda!$D:$D, "London") + SUMIFS(Carolina!$L:$L, Carolina!$B:$B, $A31, Carolina!$D:$D, "London") + SUMIFS(Jamaica!$L:$L, Jamaica!$B:$B, $A31, Jamaica!$D:$D, "London") + SUMIFS(Mountserat!$L:$L, Mountserat!$B:$B, $A31, Mountserat!$D:$D, "London") + SUMIFS(Nevis!$L:$L, Nevis!$B:$B, $A31, Nevis!$D:$D, "London") -> 3.3892857 | C31: =SUMIFS(Antigua!$M:$M, Antigua!$B:$B, $A31, Antigua!$D:$D, "Out Ports") + SUMIFS(Barbados!$L:$L, Barbados!$B:$B, $A31, Barbados!$D:$D, "Out Ports") + SUMIFS(Bermuda!$L:$L, Bermuda!$B:$B, $A31, Bermuda!$D:$D, "Out Ports") + SUMIFS(Carolina!$L:$L, Carolina!$B:$B, $A31, Carolina!$D:$D, "Out Ports") + SUMIFS(Jamaica!$L:$L, Jamaica!$B:$B, $A31, Jamaica!$D:$D, "Out Ports") + SUMIFS(Mountserat!$L:$L, Mountserat!$B:$B, $A31, Mountserat!$D:$D, "Out Ports") + SUMIFS(Nevis!$L:$L, Nevis!$B:$B, $A31, Nevis!$D:$D, "Out Ports") -> 0.1328125 | D31: =ROUND((B31+C31),2) -> 3.52

Sheet Antigua
A1: YEAR | B1: COMMODITY_NAME | C1: FROM_LOCATION | D1: TO_LOCATION | E1: ton | F1: hh | G1: quarter | H1: lb | J1: Total Pounds | L1: WEIGHT
A2: 1701 | B2: Bees Wax | C2: Antigua | D2: London | F2: 6 | G2: 1 | J2: =(E2*2240)+(F2*112)+(G2*28)+H2 -> 700 | L2: =J2/2240 -> 0.3125
A3: 1701 | B3: Brown Sugar | C3: Antigua | D3: London | F3: 41185 | H3: 5 | J3: =(E3*2240)+(F3*112)+(G3*28)+H3 -> 4612725 | L3: =J3/2240 -> 2059.2522
A4: 1701 | B4: Cocoa Nuts | C4: Antigua | D4: London | F4: 48 | H4: 14 | J4: =(E4*2240)+(F4*112)+(G4*28)+H4 -> 5390 | L4: =J4/2240 -> 2.40625
A5: 1701 | B5: Cocoa Past Paste? (62) | C5: Antigua | D5: London | H5: 11 | J5: =(E5*2240)+(F5*112)+(G5*28)+H5 -> 11 | L5: =J5/2240 -> 0.0049107143
A6: 1701 | B6: Cotton | C6: Antigua | D6: London | H6: =353*200 -> 70600 | I6: 353 Bag | J6: =(E6*2240)+(F6*112)+(G6*28)+H6 -> 70600 | L6: =J6/2240 -> 31.517857
A7: 1701 | B7: Dry Ginger | C7: Antigua | D7: London | F7: 102 | H7: 14 | J7: =(E7*2240)+(F7*112)+(G7*28)+H7 -> 11438 | L7: =J7/2240 -> 5.10625
A8: 1701 | B8: Elephant Teeth | C8: Antigua | D8: London | F8: 58 | G8: 1 | H8: 14 | J8: =(E8*2240)+(F8*112)+(G8*28)+H8 -> 6538 | L8: =J8/2240 -> 2.91875
A9: 1701 | B9: Lime Juice | C9: Antigua | D9: London | H9: 1460 | I9: 146 Gallons | J9: =(E9*2240)+(F9*112)+(G9*28)+H9 -> 1460 | L9: =J9/2240 -> 0.65178571
A10: 1701 | B10: Molasses | C10: Antigua | D10: London | F10: 6872 | H10: 20 | J10: =(E10*2240)+(F10*112)+(G10*28)+H10 -> 769684 | L10: =J10/2240 -> 343.60893
A11: 1701 | B11: Rum | C11: Antigua | D11: London | H11: 210 | I11: 21 Gallons | J11: =(E11*2240)+(F11*112)+(G11*28)+H11 -> 210 | L11: =J11/2240 -> 0.09375
A12: 1701 | B12: Shruff | C12: Antigua | D12: London | F12: 24 | G12: 1 | H12: 21 | J12: =(E12*2240)+(F12*112)+(G12*28)+H12 -> 2737 | L12: =J12/2240 -> 1.221875
A13: 1701 | B13: Succads | C13: Antigua | D13: London | H13: 84 | J13: =(E13*2240)+(F13*112)+(G13*28)+H13 -> 84 | L13: =J13/2240 -> 0.0375
A14: 1701 | B14: Tobacco | C14: Antigua | D14: London | H14: 32628 | J14: =(E14*2240)+(F14*112)+(G14*28)+H14 -> 32628 | L14: =J14/2240 -> 14.566071
A15: 1701 | B15: Tortoise Shell | C15: Antigua | D15: London | H15: 20 | J15: =(E15*2240)+(F15*112)+(G15*28)+H15 -> 20 | L15: =J15/2240 -> 0.0089285714
A16: 1701 | B16: White Sugar | C16: Antigua | D16: London | F16: 19 | G16: 2 | H16: 9 | J16: =(E16*2240)+(F16*112)+(G16*28)+H16 -> 2193 | L16: =J16/2240 -> 0.97901786
A17: 1701 | B17: Brown Sugar | C17: Antigua | D17: Out Ports | F17: 9769 | G17: 1 | H17: 3 | J17: =(E17*2240)+(F17*112)+(G17*28)+H17 -> 1094159 | L17: =J17/2240 -> 488.46384
A18: 1701 | B18: Cotton | C18: Antigua | D18: Out Ports | F18: 368 | G18: 2 | H18: 16 | J18: =(E18*2240)+(F18*112)+(G18*28)+H18 -> 41288 | L18: =J18/2240 -> 18.432143
A19: 1701 | B19: Dry Ginger | C19: Antigua | D19: Out Ports | F19: 11 | H19: 17 | J19: =(E19*2240)+(F19*112)+(G19*28)+H19 -> 1249 | L19: =J19/2240 -> 0.55758929
A20: 1701 | B20: Lime Juice | C20: Antigua | D20: Out Ports | H20: 740 | I20: 74 Gallons | J20: =(E20*2240)+(F20*112)+(G20*28)+H20 -> 740 | L20: =J20/2240 -> 0.33035714
A21: 1701 | B21: Madera Wine | C21: Antigua | D21: Out Ports | F21: 1 | J21: =(E21*2240)+(F21*112)+(G21*28)+H21 -> 112 | L21: =J21/2240 -> 0.05
A22: 1701 | B22: Molasses | C22: Antigua | D22: Out Ports | F22: 1427 | H22: 14 | J22: =(E22*2240)+(F22*112)+(G22*28)+H22 -> 159838 | L22: =J22/2240 -> 71.35625
A23: 1701 | B23: Refined Sugar | C23: Antigua | D23: Out Ports | G23: 1 | H23: 5 | J23: =(E23*2240)+(F23*112)+(G23*28)+H23 -> 33 | L23: =J23/2240 -> 0.014732143
A24: 1701 | B24: Rum | C24: Antigua | D24: Out Ports | H24: 70 | I24: 7 Gallons | J24: =(E24*2240)+(F24*112)+(G24*28)+H24 -> 70 | L24: =J24/2240 -> 0.03125
A25: 1701 | B25: Tobacco | C25: Antigua | D25: Out Ports | H25: 3063 | J25: =(E25*2240)+(F25*112)+(G25*28)+H25 -> 3063 | L25: =J25/2240 -> 1.3674107

Sheet Barbados
A1: YEAR | B1: COMMODITY_NAME | C1: FROM_LOCATION | D1: TO_LOCATION | E1: ton | F1: hh | G1: quarter | H1: lb | J1: Total Pounds | L1: WEIGHT | N1: Total Not sugar | P1: Total Sugar
A2: 1701 | B2: Annatto | C2: Barbados | D2: London | H2: 1840 | J2: =(E2*2240)+(F2*112)+(G2*28)+H2 -> 1840 | L2: =J2/2240 -> 0.82142857 | N2: =L2+L3+L4+L9+L10+L11+L12+L13+L16+L17+L18+L19+L20+L23+L24+L25+L29+L30+L32+L33 -> 9750.5788 | P2: =L5+L6+L7+L8+L26+L27+L28 -> 72.430804
A3: 1701 | B3: Bees Wax | C3: Barbados | D3: London | F3: 2 | G3: 2 | H3: 21 | J3: =(E3*2240)+(F3*112)+(G3*28)+H3 -> 301 | L3: =J3/2240 -> 0.134375
A4: 1701 | B4: Brown Sugar | C4: Barbados | D4: London | F4: 152776 | G4: 3 | H4: 24 | J4: =(E4*2240)+(F4*112)+(G4*28)+H4 -> 17111020 | L4: =J4/2240 -> 7638.8482
A5: 1701 | B5: Chocolate | C5: Barbados | D5: London | H5: 85 | J5: =(E5*2240)+(F5*112)+(G5*28)+H5 -> 85 | L5: =J5/2240 -> 0.037946429
A6: 1701 | B6: Chocolate Cast/past/last | C6: Barbados | D6: London | H6: 13 | J6: =(E6*2240)+(F6*112)+(G6*28)+H6 -> 13 | L6: =J6/2240 -> 0.0058035714
A7: 1701 | B7: Cocoa Nuts | C7: Barbados | D7: London | F7: 290 | H7: 8 | J7: =(E7*2240)+(F7*112)+(G7*28)+H7 -> 32488 | L7: =J7/2240 -> 14.503571
A8: 1701 | B8: Cocoa Past? Last? | C8: Barbados | D8: London | H8: 27 | J8: =(E8*2240)+(F8*112)+(G8*28)+H8 -> 27 | L8: =J8/2240 -> 0.012053571
A9: 1701 | B9: Cotton | C9: Barbados | D9: London | H9: =1366*200 -> 273200 | I9: 1366 Bags | J9: =(E9*2240)+(F9*112)+(G9*28)+H9 -> 273200 | L9: =J9/2240 -> 121.96429
A10: 1701 | B10: Dry Ginger | C10: Barbados | D10: London | F10: 4301 | G10: 3 | H10: 7 | J10: =(E10*2240)+(F10*112)+(G10*28)+H10 -> 481803 | L10: =J10/2240 -> 215.09062
A11: 1701 | B11: Elephant Teeth | C11: Barbados | D11: London | F11: 249 | H11: 21 | J11: =(E11*2240)+(F11*112)+(G11*28)+H11 -> 27909 | L11: =J11/2240 -> 12.459375
A12: 1701 | B12: Indigo | C12: Barbados | D12: London | H12: 309 | J12: =(E12*2240)+(F12*112)+(G12*28)+H12 -> 309 | L12: =J12/2240 -> 0.13794643
A13: 1701 | B13: Lime Juice | C13: Barbados | D13: London | H13: 28277 | I13: 2827 Gallons | J13: =(E13*2240)+(F13*112)+(G13*28)+H13 -> 28277 | L13: =J13/2240 -> 12.623661
A14: 1701 | B14: Loaf Sugar | C14: Barbados | D14: London | F14: 6 | G14: 2 | H14: 3 | J14: =(E14*2240)+(F14*112)+(G14*28)+H14 -> 731 | L14: =J14/2240 -> 0.32633929
A15: 1701 | B15: Madera Wine | C15: Barbados | D15: London | H15: 7592 | I15: 3 tun 3 Gallon | J15: =(E15*2240)+(F15*112)+(G15*28)+H15 -> 7592 | L15: =J15/2240 -> 3.3892857
A16: 1701 | B16: Molasses | C16: Barbados | D16: London | F16: 6648 | G16: 2 | H16: 22 | J16: =(E16*2240)+(F16*112)+(G16*28)+H16 -> 744654 | L16: =J16/2240 -> 332.43482
A17: 1701 | B17: Oranges | C17: Barbados | D17: London | H17: 9940 | J17: =(E17*2240)+(F17*112)+(G17*28)+H17 -> 9940 | L17: =J17/2240 -> 4.4375
A18: 1701 | B18: Rum | C18: Barbados | D18: London | H18: 11023 | I18: 1102 Gallons | J18: =(E18*2240)+(F18*112)+(G18*28)+H18 -> 11023 | L18: =J18/2240 -> 4.9209821
A19: 1701 | B19: Shruff | C19: Barbados | D19: London | F19: 107 | H19: 19 | J19: =(E19*2240)+(F19*112)+(G19*28)+H19 -> 12003 | L19: =J19/2240 -> 5.3584821
A20: 1701 | B20: Succads | C20: Barbados | D20: London | H20: 2781 | J20: =(E20*2240)+(F20*112)+(G20*28)+H20 -> 2781 | L20: =J20/2240 -> 1.2415179
A21: 1701 | B21: Tobacco | C21: Barbados | D21: London | H21: 5400 | J21: =(E21*2240)+(F21*112)+(G21*28)+H21 -> 5400 | L21: =J21/2240 -> 2.4107143
A22: 1701 | B22: Tortoise Shell | C22: Barbados | D22: London | H22: 198 | J22: =(E22*2240)+(F22*112)+(G22*28)+H22 -> 198 | L22: =J22/2240 -> 0.088392857
A23: 1701 | B23: White Sugar | C23: Barbados | D23: London | F23: 2911 | G23: 2 | H23: 16 | J23: =(E23*2240)+(F23*112)+(G23*28)+H23 -> 326104 | L23: =J23/2240 -> 145.58214
A24: 1701 | B24: Brown Sugar | C24: Barbados | D24: Out Ports | F24: 24988 | G24: 3 | H24: 15 | J24: =(E24*2240)+(F24*112)+(G24*28)+H24 -> 2798755 | L24: =J24/2240 -> 1249.4442
A25: 1701 | B25: Chocolate | C25: Barbados | D25: Out Ports | H25: 13 | J25: =(E25*2240)+(F25*112)+(G25*28)+H25 -> 13 | L25: =J25/2240 -> 0.0058035714
A26: 1701 | B26: Cotton | C26: Barbados | D26: Out Ports | F26: 392 | H26: 23 | J26: =(E26*2240)+(F26*112)+(G26*28)+H26 -> 43927 | L26: =J26/2240 -> 19.610268
A27: 1701 | B27: Dry Ginger | C27: Barbados | D27: Out Ports | F27: 759 | G27: 1 | H27: 16 | J27: =(E27*2240)+(F27*112)+(G27*28)+H27 -> 85052 | L27: =J27/2240 -> 37.969643
A28: 1701 | B28: Elephant Teeth | C28: Barbados | D28: Out Ports | F28: 5 | G28: 3 | H28: 9 | J28: =(E28*2240)+(F28*112)+(G28*28)+H28 -> 653 | L28: =J28/2240 -> 0.29151786
A29: 1701 | B29: Lime Juice | C29: Barbados | D29: Out Ports | H29: 6732 | I29: 673 Gallons | J29: =(E29*2240)+(F29*112)+(G29*28)+H29 -> 6732 | L29: =J29/2240 -> 3.0053571
A30: 1701 | B30: Madera Wine | C30: Barbados | D30: Out Ports | H30: 157.5 | I30: 15.75 Gallons | J30: =(E30*2240)+(F30*112)+(G30*28)+H30 -> 157.5 | L30: =J30/2240 -> 0.0703125
A31: 1701 | B31: Molasses | C31: Barbados | D31: Out Ports | F31: 1325 | G31: 3 | H31: 16 | J31: =(E31*2240)+(F31*112)+(G31*28)+H31 -> 148500 | L31: =J31/2240 -> 66.294643
A32: 1701 | B32: Rice | C32: Barbados | D32: Out Ports | F32: 22 | G32: 2 | H32: 25 | J32: =(E32*2240)+(F32*112)+(G32*28)+H32 -> 2545 | L32: =J32/2240 -> 1.1361607
A33: 1701 | B33: Rum | C33: Barbados | D33: Out Ports | H33: 1930 | I33: 193 Gallons | J33: =(E33*2240)+(F33*112)+(G33*28)+H33 -> 1930 | L33: =J33/2240 -> 0.86160714
A34: 1701 | B34: Succads | C34: Barbados | D34: Out Ports | H34: 876 | J34: =(E34*2240)+(F34*112)+(G34*28)+H34 -> 876 | L34: =J34/2240 -> 0.39107143
A35: 1701 | B35: White Sugar | C35: Barbados | D35: Out Ports | F35: 22 | G35: 1 | H35: 22 | J35: =(E35*2240)+(F35*112)+(G35*28)+H35 -> 2514 | L35: =J35/2240 -> 1.1223214

Sheet Bermuda
A1: YEAR | B1: COMMODITY_NAME | C1: FROM_LOCATION | D1: TO_LOCATION | E1: ton | F1: hh | G1: quarter | H1: lb | J1: Total Pounds | L1: WEIGHT
A2: 1701 | B2: Indigo | C2: Bermuda | D2: London | H2: 8598 | J2: =(E2*2240)+(F2*112)+(G2*28)+H2 -> 8598 | L2: =J2/2240 -> 3.8383929
A3: 1701 | B3: Brown Sugar | C3: Bermuda | D3: London | F3: 240 | G3: 2 | J3: =(E3*2240)+(F3*112)+(G3*28)+H3 -> 26936 | L3: =J3/2240 -> 12.025
A4: 1701 | B4: Shruff | C4: Bermuda | D4: London | G4: 3 | H4: 7 | J4: =(E4*2240)+(F4*112)+(G4*28)+H4 -> 91 | L4: =J4/2240 -> 0.040625
A5: 1701 | B5: Tobacco | C5: Bermuda | D5: London | H5: 15171 | J5: =(E5*2240)+(F5*112)+(G5*28)+H5 -> 15171 | L5: =J5/2240 -> 6.7727679
A6: 1701 | B6: Tortoise Shell | C6: Bermuda | D6: London | H6: 7 | J6: =(E6*2240)+(F6*112)+(G6*28)+H6 -> 7 | L6: =J6/2240 -> 0.003125

Sheet Carolina
A1: YEAR | B1: COMMODITY_NAME | C1: FROM_LOCATION | D1: TO_LOCATION | E1: ton | F1: hh | G1: quarter | H1: lb | J1: Total Pounds | L1: WEIGHT
A2: 1701 | B2: Brown Sugar | C2: Carolina | D2: London | F2: 311 | G2: 1 | J2: =(E2*2240)+(F2*112)+(G2*28)+H2 -> 34860 | L2: =J2/2240 -> 15.5625
A3: 1701 | B3: Chocolate | C3: Carolina | D3: London | H3: 6 | J3: =(E3*2240)+(F3*112)+(G3*28)+H3 -> 6 | L3: =J3/2240 -> 0.0026785714
A4: 1701 | B4: Cocoa Past | C4: Carolina | D4: London | H4: 30 | J4: =(E4*2240)+(F4*112)+(G4*28)+H4 -> 30 | L4: =J4/2240 -> 0.013392857
A5: 1701 | B5: Cotton | C5: Carolina | D5: London | H5: =5*200 -> 1000 | I5: 5 Bags | J5: =(E5*2240)+(F5*112)+(G5*28)+H5 -> 1000 | L5: =J5/2240 -> 0.44642857
A6: 1701 | B6: Elephant Teeth | C6: Carolina | D6: London | F6: 4 | J6: =(E6*2240)+(F6*112)+(G6*28)+H6 -> 448 | L6: =J6/2240 -> 0.2
A7: 1701 | B7: Indigo | C7: Carolina | D7: London | H7: 707 | J7: =(E7*2240)+(F7*112)+(G7*28)+H7 -> 707 | L7: =J7/2240 -> 0.315625
A8: 1701 | B8: Lime Juice | C8: Carolina | D8: London | H8: 1570 | I8: 157 Gallons | J8: =(E8*2240)+(F8*112)+(G8*28)+H8 -> 1570 | L8: =J8/2240 -> 0.70089286
A9: 1701 | B9: Mirtle Wax | C9: Carolina | D9: London | F9: 9 | G9: 2 | J9: =(E9*2240)+(F9*112)+(G9*28)+H9 -> 1064 | L9: =J9/2240 -> 0.475
A10: 1701 | B10: Molasses | C10: Carolina | D10: London | F10: 16 | J10: =(E10*2240)+(F10*112)+(G10*28)+H10 -> 1792 | L10: =J10/2240 -> 0.8
A11: 1701 | B11: Pimento | C11: Carolina | D11: London | H11: 850 | J11: =(E11*2240)+(F11*112)+(G11*28)+H11 -> 850 | L11: =J11/2240 -> 0.37946429
A12: 1701 | B12: Rice | C12: Carolina | D12: London | F12: 1185 | G12: 2 | H12: 17 | J12: =(E12*2240)+(F12*112)+(G12*28)+H12 -> 132793 | L12: =J12/2240 -> 59.282589
A13: 1701 | B13: Tortoise Shell | C13: Carolina | D13: London | H13: 124 | J13: =(E13*2240)+(F13*112)+(G13*28)+H13 -> 124 | L13: =J13/2240 -> 0.055357143
A14: 1701 | B14: Brown Sugar | C14: Carolina | D14: Out Ports | F14: 31 | G14: 3 | H14: 10 | J14: =(E14*2240)+(F14*112)+(G14*28)+H14 -> 3566 | L14: =J14/2240 -> 1.5919643
A15: 1701 | B15: Rice | C15: Carolina | D15: Out Ports | F15: 271 | G15: 1 | H15: 5 | J15: =(E15*2240)+(F15*112)+(G15*28)+H15 -> 30385 | L15: =J15/2240 -> 13.564732

Sheet Jamaica
A1: YEAR | B1: COMMODITY_NAME | C1: FROM_LOCATION | D1: TO_LOCATION | E1: ton | F1: hh | G1: quarter | H1: lb | J1: Total Pounds | L1: WEIGHT
A2: 1701 | B2: Annatto | C2: Jamaica | D2: London | H2: 4906 | J2: =(E2*2240)+(F2*112)+(G2*28)+H2 -> 4906 | L2: =J2/2240 -> 2.1901786
A3: 1701 | B3: Bees Wax | C3: Jamaica | D3: London | F3: 6 | J3: =(E3*2240)+(F3*112)+(G3*28)+H3 -> 672 | L3: =J3/2240 -> 0.3
A4: 1701 | B4: Brown Sugar | C4: Jamaica | D4: London | F4: 82141 | G4: 3 | H4: 18 | J4: =(E4*2240)+(F4*112)+(G4*28)+H4 -> 9199894 | L4: =J4/2240 -> 4107.0955
A5: 1701 | B5: Cascarilla | C5: Jamaica | D5: London | H5: 93 | J5: =(E5*2240)+(F5*112)+(G5*28)+H5 -> 93 | L5: =J5/2240 -> 0.041517857
A6: 1701 | B6: Chocolate | C6: Jamaica | D6: London | H6: 174 | J6: =(E6*2240)+(F6*112)+(G6*28)+H6 -> 174 | L6: =J6/2240 -> 0.077678571
A7: 1701 | B7: Chocolate Past | C7: Jamaica | D7: London | H7: 99 | J7: =(E7*2240)+(F7*112)+(G7*28)+H7 -> 99 | L7: =J7/2240 -> 0.044196429
A8: 1701 | B8: Cocoa Nuts | C8: Jamaica | D8: London | F8: 1038 | H8: 27 | J8: =(E8*2240)+(F8*112)+(G8*28)+H8 -> 116283 | L8: =J8/2240 -> 51.912054
A9: 1701 | B9: Cocoa Past | C9: Jamaica | D9: London | H9: 36 | J9: =(E9*2240)+(F9*112)+(G9*28)+H9 -> 36 | L9: =J9/2240 -> 0.016071429
A10: 1701 | B10: Cotton | C10: Jamaica | D10: London | H10: =2023.5*200 -> 404700 | I10: 2023.5 Bags | J10: =(E10*2240)+(F10*112)+(G10*28)+H10 -> 404700 | L10: =J10/2240 -> 180.66964
A11: 1701 | B11: Dry Ginger | C11: Jamaica | D11: London | F11: 2224 | G11: 1 | H11: 11 | J11: =(E11*2240)+(F11*112)+(G11*28)+H11 -> 249127 | L11: =J11/2240 -> 111.21741
A12: 1701 | B12: Elephant Teeth | C12: Jamaica | D12: London | F12: 454 | H12: 6 | J12: =(E12*2240)+(F12*112)+(G12*28)+H12 -> 50854 | L12: =J12/2240 -> 22.702679
A13: 1701 | B13: Indigo | C13: Jamaica | D13: London | H13: 156191 | J13: =(E13*2240)+(F13*112)+(G13*28)+H13 -> 156191 | L13: =J13/2240 -> 69.728125
A14: 1701 | B14: Lime Juice | C14: Jamaica | D14: London | H14: 44641 | I14: 4463 Gallons | J14: =(E14*2240)+(F14*112)+(G14*28)+H14 -> 44641 | L14: =J14/2240 -> 19.929018
A15: 1701 | B15: Loaf Sugar | C15: Jamaica | D15: London | F15: 1 | J15: =(E15*2240)+(F15*112)+(G15*28)+H15 -> 112 | L15: =J15/2240 -> 0.05
A16: 1701 | B16: Molasses | C16: Jamaica | D16: London | F16: 153 | J16: =(E16*2240)+(F16*112)+(G16*28)+H16 -> 17136 | L16: =J16/2240 -> 7.65
A17: 1701 | B17: Pimento | C17: Jamaica | D17: London | H17: 120483 | J17: =(E17*2240)+(F17*112)+(G17*28)+H17 -> 120483 | L17: =J17/2240 -> 53.787054
A18: 1701 | B18: Rum | C18: Jamaica | D18: London | H18: 6501.5 | I18: 650 Gallons | J18: =(E18*2240)+(F18*112)+(G18*28)+H18 -> 6501.5 | L18: =J18/2240 -> 2.9024554
A19: 1701 | B19: Shruff | C19: Jamaica | D19: London | F19: 36 | G19: 3 | H19: 27 | J19: =(E19*2240)+(F19*112)+(G19*28)+H19 -> 4143 | L19: =J19/2240 -> 1.8495536
A20: 1701 | B20: Succads | C20: Jamaica | D20: London | H20: 128 | J20: =(E20*2240)+(F20*112)+(G20*28)+H20 -> 128 | L20: =J20/2240 -> 0.057142857
A21: 1701 | B21: Tobacco | C21: Jamaica | D21: London | H21: 11390 | J21: =(E21*2240)+(F21*112)+(G21*28)+H21 -> 11390 | L21: =J21/2240 -> 5.0848214
A22: 1701 | B22: Tortoise Shell | C22: Jamaica | D22: London | H22: 4911 | J22: =(E22*2240)+(F22*112)+(G22*28)+H22 -> 4911 | L22: =J22/2240 -> 2.1924107
A23: 1701 | B23: White Sugar | C23: Jamaica | D23: London | F23: 19 | G23: 0 | H23: 11 | J23: =(E23*2240)+(F23*112)+(G23*28)+H23 -> 2139 | L23: =J23/2240 -> 0.95491071
A24: 1701 | B24: Brown Sugar | C24: Jamaica | D24: Out Ports | F24: 19709 | G24: 2 | H24: 24 | J24: =(E24*2240)+(F24*112)+(G24*28)+H24 -> 2207488 | L24: =J24/2240 -> 985.48571
A25: 1701 | B25: Chocolate | C25: Jamaica | D25: Out Ports | H25: 66 | J25: =(E25*2240)+(F25*112)+(G25*28)+H25 -> 66 | L25: =J25/2240 -> 0.029464286
A26: 1701 | B26: Cocoa Nuts | C26: Jamaica | D26: Out Ports | H26: 1043 | J26: =(E26*2240)+(F26*112)+(G26*28)+H26 -> 1043 | L26: =J26/2240 -> 0.465625
A27: 1701 | B27: Cotton | C27: Jamaica | D27: Out Ports | F27: 1001 | H27: 3 | J27: =(E27*2240)+(F27*112)+(G27*28)+H27 -> 112115 | L27: =J27/2240 -> 50.051339
A28: 1701 | B28: Dry Ginger | C28: Jamaica | D28: Out Ports | F28: 549 | G28: 1 | H28: 19 | J28: =(E28*2240)+(F28*112)+(G28*28)+H28 -> 61535 | L28: =J28/2240 -> 27.470982
A29: 1701 | B29: Elephant Teeth | C29: Jamaica | D29: Out Ports | F29: 22 | G29: 1 | H29: 2 | J29: =(E29*2240)+(F29*112)+(G29*28)+H29 -> 2494 | L29: =J29/2240 -> 1.1133929
A30: 1701 | B30: Indigo | C30: Jamaica | D30: Out Ports | H30: 20146 | J30: =(E30*2240)+(F30*112)+(G30*28)+H30 -> 20146 | L30: =J30/2240 -> 8.99375
A31: 1701 | B31: Lemon Juice | C31: Jamaica | D31: Out Ports | H31: 100 | I31: 10 Gallons | J31: =(E31*2240)+(F31*112)+(G31*28)+H31 -> 100 | L31: =J31/2240 -> 0.044642857
A32: 1701 | B32: Lime Juice | C32: Jamaica | D32: Out Ports | H32: 8272 | I32: 827 Gallons | J32: =(E32*2240)+(F32*112)+(G32*28)+H32 -> 8272 | L32: =J32/2240 -> 3.6928571
A33: 1701 | B33: Molasses | C33: Jamaica | D33: Out Ports | F33: 10 | J33: =(E33*2240)+(F33*112)+(G33*28)+H33 -> 1120 | L33: =J33/2240 -> 0.5
A34: 1701 | B34: Pimento | C34: Jamaica | D34: Out Ports | H34: 26556 | J34: =(E34*2240)+(F34*112)+(G34*28)+H34 -> 26556 | L34: =J34/2240 -> 11.855357
A35: 1701 | B35: Refined Sugar | C35: Jamaica | D35: Out Ports | H35: 7 | J35: =(E35*2240)+(F35*112)+(G35*28)+H35 -> 7 | L35: =J35/2240 -> 0.003125
A36: 1701 | B36: Rum | C36: Jamaica | D36: Out Ports | H36: 1370 | I36: 137 Gallons | J36: =(E36*2240)+(F36*112)+(G36*28)+H36 -> 1370 | L36: =J36/2240 -> 0.61160714
A37: 1701 | B37: Shruff | C37: Jamaica | D37: Out Ports | F37: 10 | H37: 27 | J37: =(E37*2240)+(F37*112)+(G37*28)+H37 -> 1147 | L37: =J37/2240 -> 0.51205357
A38: 1701 | B38: Succads | C38: Jamaica | D38: Out Ports | H38: 36 | J38: =(E38*2240)+(F38*112)+(G38*28)+H38 -> 36 | L38: =J38/2240 -> 0.016071429
A39: 1701 | B39: Tobacco | C39: Jamaica | D39: Out Ports | H39: 43462 | J39: =(E39*2240)+(F39*112)+(G39*28)+H39 -> 43462 | L39: =J39/2240 -> 19.402679
A40: 1701 | B40: Tortoise Shell | C40: Jamaica | D40: Out Ports | H40: 119.5 | J40: =(E40*2240)+(F40*112)+(G40*28)+H40 -> 119.5 | L40: =J40/2240 -> 0.053348214
...

Sheet Mountserat
A1: YEAR | B1: COMMODITY_NAME | C1: FROM_LOCATION | D1: TO_LOCATION | E1: ton | F1: hh | G1: quarter | H1: lb | J1: Total Pounds | L1: WEIGHT
A2: 1701 | B2: Brown Sugar | C2: Mountserat | D2: London | F2: 19363 | G2: 3 | H2: 14 | J2: =(E2*2240)+(F2*112)+(G2*28)+H2 -> 2168754 | L2: =J2/2240 -> 968.19375
A3: 1701 | B3: Cocoa Nuts | C3: Mountserat | D3: London | F3: 4 | G3: 1 | H3: 14 | J3: =(E3*2240)+(F3*112)+(G3*28)+H3 -> 490 | L3: =J3/2240 -> 0.21875
A4: 1701 | B4: Cotton | C4: Mountserat | D4: London | H4: =36*200 -> 7200 | I4: 36 Bags | J4: =(E4*2240)+(F4*112)+(G4*28)+H4 -> 7200 | L4: =J4/2240 -> 3.2142857
A5: 1701 | B5: Dry Ginger | C5: Mountserat | D5: London | F5: 2 | G5: 1 | J5: =(E5*2240)+(F5*112)+(G5*28)+H5 -> 252 | L5: =J5/2240 -> 0.1125
A6: 1701 | B6: Elephants Teeth | C6: Mountserat | D6: London | F6: 4 | G6: 1 | J6: =(E6*2240)+(F6*112)+(G6*28)+H6 -> 476 | L6: =J6/2240 -> 0.2125
A7: 1701 | B7: Indigo | C7: Mountserat | D7: London | H7: 7467 | J7: =(E7*2240)+(F7*112)+(G7*28)+H7 -> 7467 | L7: =J7/2240 -> 3.3334821
A8: 1701 | B8: Lime Juice | C8: Mountserat | D8: London | H8: 2440 | I8: 244 Gallons | J8: =(E8*2240)+(F8*112)+(G8*28)+H8 -> 2440 | L8: =J8/2240 -> 1.0892857
A9: 1701 | B9: Molasses | C9: Mountserat | D9: London | F9: 5 | J9: =(E9*2240)+(F9*112)+(G9*28)+H9 -> 560 | L9: =J9/2240 -> 0.25
A10: 1701 | B10: Oranges | C10: Mountserat | D10: London | H10: 2 | J10: =(E10*2240)+(F10*112)+(G10*28)+H10 -> 2 | L10: =J10/2240 -> 0.00089285714
A11: 1701 | B11: Pimento | C11: Mountserat | D11: London | H11: 593 | J11: =(E11*2240)+(F11*112)+(G11*28)+H11 -> 593 | L11: =J11/2240 -> 0.26473214
A12: 1701 | B12: Shruff | C12: Mountserat | D12: London | F12: 10 | G12: 3 | J12: =(E12*2240)+(F12*112)+(G12*28)+H12 -> 1204 | L12: =J12/2240 -> 0.5375
A13: 1701 | B13: Succads | C13: Mountserat | D13: London | H13: 40 | J13: =(E13*2240)+(F13*112)+(G13*28)+H13 -> 40 | L13: =J13/2240 -> 0.017857143
A14: 1701 | B14: Brown Sugar | C14: Mountserat | D14: Out Ports | F14: 2132 | H14: 11 | J14: =(E14*2240)+(F14*112)+(G14*28)+H14 -> 238795 | L14: =J14/2240 -> 106.60491
A15: 1701 | B15: Cotton | C15: Mountserat | D15: Out Ports | F15: 2 | G15: 2 | J15: =(E15*2240)+(F15*112)+(G15*28)+H15 -> 280 | L15: =J15/2240 -> 0.125
A16: 1701 | B16: Indigo | C16: Mountserat | D16: Out Ports | H16: 187 | J16: =(E16*2240)+(F16*112)+(G16*28)+H16 -> 187 | L16: =J16/2240 -> 0.083482143
A17: 1701 | B17: Lime Juice | C17: Mountserat | D17: Out Ports | H17: 630 | I17: 63 Gallons | J17: =(E17*2240)+(F17*112)+(G17*28)+H17 -> 630 | L17: =J17/2240 -> 0.28125
A18: 1701 | B18: Shruff | C18: Mountserat | D18: Out Ports | F18: 2 | J18: =(E18*2240)+(F18*112)+(G18*28)+H18 -> 224 | L18: =J18/2240 -> 0.1
A19: 1701 | B19: Succads | C19: Mountserat | D19: Out Ports | H19: 18 | J19: =(E19*2240)+(F19*112)+(G19*28)+H19 -> 18 | L19: =J19/2240 -> 0.0080357143

Sheet Nevis
A1: YEAR | B1: COMMODITY_NAME | C1: FROM_LOCATION | D1: TO_LOCATION | E1: ton | F1: hh | G1: quarter | H1: lb | J1: Total Pounds | L1: WEIGHT
A2: 1701 | B2: Brown Sugar | C2: Nevis | D2: London | F2: 47903 | G2: 1 | H2: 4 | J2: =(E2*2240)+(F2*112)+(G2*28)+(H2) -> 5365168 | L2: =J2/2240 -> 2395.1643
A3: 1701 | B3: Chocolate | C3: Nevis | D3: London | H3: 25 | J3: =(E3*2240)+(F3*112)+(G3*28)+(H3) -> 25 | L3: =J3/2240 -> 0.011160714
A4: 1701 | B4: Cocoa Nuts | C4: Nevis | D4: London | F4: 26 | J4: =(E4*2240)+(F4*112)+(G4*28)+(H4) -> 2912 | L4: =J4/2240 -> 1.3
A5: 1701 | B5: Cotton | C5: Nevis | D5: London | H5: =69.5*200 -> 13900 | I5: 69.5 Bags | J5: =(E5*2240)+(F5*112)+(G5*28)+(H5) -> 13900 | L5: =J5/2240 -> 6.2053571
A6: 1701 | B6: Elephant Teeth | C6: Nevis | D6: London | F6: 45 | H6: 22 | J6: =(E6*2240)+(F6*112)+(G6*28)+(H6) -> 5062 | L6: =J6/2240 -> 2.2598214
A7: 1701 | B7: Indigo | C7: Nevis | D7: London | H7: 721 | J7: =(E7*2240)+(F7*112)+(G7*28)+(H7) -> 721 | L7: =J7/2240 -> 0.321875
A8: 1701 | B8: Lime Juice | C8: Nevis | D8: London | H8: 5871.5 | I8: 587 Gallons | J8: =(E8*2240)+(F8*112)+(G8*28)+(H8) -> 5871.5 | L8: =J8/2240 -> 2.6212054
A9: 1701 | B9: Molasses | C9: Nevis | D9: London | F9: 222 | G9: 1 | J9: =(E9*2240)+(F9*112)+(G9*28)+(H9) -> 24892 | L9: =J9/2240 -> 11.1125
A10: 1701 | B10: Rice | C10: Nevis | D10: London | F10: 5 | G10: 1 | H10: 20 | J10: =(E10*2240)+(F10*112)+(G10*28)+(H10) -> 608 | L10: =J10/2240 -> 0.27142857
A11: 1701 | B11: Rum | C11: Nevis | D11: London | H11: 630 | I11: 63 Gallon | J11: =(E11*2240)+(F11*112)+(G11*28)+(H11) -> 630 | L11: =J11/2240 -> 0.28125
A12: 1701 | B12: Shruff | C12: Nevis | D12: London | F12: 13 | H12: 21 | J12: =(E12*2240)+(F12*112)+(G12*28)+(H12) -> 1477 | L12: =J12/2240 -> 0.659375
A13: 1701 | B13: Sope Berries | C13: Nevis | D13: London | H13: 130 | J13: =(E13*2240)+(F13*112)+(G13*28)+(H13) -> 130 | L13: =J13/2240 -> 0.058035714
A14: 1701 | B14: Succads | C14: Nevis | D14: London | H14: 177 | J14: =(E14*2240)+(F14*112)+(G14*28)+(H14) -> 177 | L14: =J14/2240 -> 0.079017857
A15: 1701 | B15: Tortoise Shell | C15: Nevis | D15: London | H15: 79 | J15: =(E15*2240)+(F15*112)+(G15*28)+(H15) -> 79 | L15: =J15/2240 -> 0.035267857
A16: 1701 | B16: White Sugar | C16: Nevis | D16: London | F16: 3 | G16: 2 | J16: =(E16*2240)+(F16*112)+(G16*28)+(H16) -> 392 | L16: =J16/2240 -> 0.175
A17: 1701 | B17: Brown Sugar | C17: Nevis | D17: Out Ports | F17: 11900 | G17: 1 | H17: 10 | J17: =(E17*2240)+(F17*112)+(G17*28)+(H17) -> 1332838 | L17: =J17/2240 -> 595.01696
A18: 1701 | B18: Cotton | C18: Nevis | D18: Out Ports | F18: 112 | G18: 1 | H18: 12 | J18: =(E18*2240)+(F18*112)+(G18*28)+(H18) -> 12584 | L18: =J18/2240 -> 5.6178571
A19: 1701 | B19: Indigo | C19: Nevis | D19: Out Ports | H19: 413 | J19: =(E19*2240)+(F19*112)+(G19*28)+(H19) -> 413 | L19: =J19/2240 -> 0.184375
A20: 1701 | B20: Lime Juice | C20: Nevis | D20: Out Ports | H20: 400 | I20: 40 Gallons | J20: =(E20*2240)+(F20*112)+(G20*28)+(H20) -> 400 | L20: =J20/2240 -> 0.17857143
A21: 1701 | B21: Madera Wine | C21: Nevis | D21: Out Ports | H21: 140 | I21: 14 Gallons | J21: =(E21*2240)+(F21*112)+(G21*28)+(H21) -> 140 | L21: =J21/2240 -> 0.0625
A22: 1701 | B22: Molasses | C22: Nevis | D22: Out Ports | F22: 22 | G22: 3 | J22: =(E22*2240)+(F22*112)+(G22*28)+(H22) -> 2548 | L22: =J22/2240 -> 1.1375
A23: 1701 | B23: Rum | C23: Nevis | D23: Out Ports | H23: 200 | I23: 20 Gallons | J23: =(E23*2240)+(F23*112)+(G23*28)+(H23) -> 200 | L23: =J23/2240 -> 0.089285714
A24: 1701 | B24: Shruff | C24: Nevis | D24: Out Ports | F24: 25 | G24: 3 | H24: 4 | J24: =(E24*2240)+(F24*112)+(G24*28)+(H24) -> 2888 | L24: =J24/2240 -> 1.2892857
A25: 1701 | B25: Succads | C25: Nevis | D25: Out Ports | H25: 57 | J25: =(E25*2240)+(F25*112)+(G25*28)+(H25) -> 57 | L25: =J25/2240 -> 0.025446429
A26: 1701 | B26: Tortoise Shell | C26: Nevis | D26: Out Ports | H26: 81 | J26: =(E26*2240)+(F26*112)+(G26*28)+(H26) -> 81 | L26: =J26/2240 -> 0.036160714

Sheet StKitts
A1: YEAR | B1: COMMODITY_NAME | C1: FROM_LOCATION | D1: TO_LOCATION | E1: ton | F1: hh | G1: quarter | H1: lb | J1: Total Pounds | L1: WEIGHT
A2: 1701 | B2: Brown Sugar | C2: StKitts | D2: London | F2: 14190 | H2: 10 | J2: =(E2*2240)+(F2*112)+(G2*28)+(H2) -> 1589290 | L2: =J2/2240 -> 709.50446
A3: 1701 | B3: Cocoa Nuts | C3: StKitts | D3: London | F3: 8 | G3: 2 | H3: 14 | J3: =(E3*2240)+(F3*112)+(G3*28)+(H3) -> 966 | L3: =J3/2240 -> 0.43125
A4: 1701 | B4: Cotton | C4: StKitts | D4: London | H4: =3*200 -> 600 | I4: 3 Bags | J4: =(E4*2240)+(F4*112)+(G4*28)+(H4) -> 600 | L4: =J4/2240 -> 0.26785714
A5: 1701 | B5: Elephant Teeth | C5: StKitts | D5: London | F5: 9 | H5: 1 | J5: =(E5*2240)+(F5*112)+(G5*28)+(H5) -> 1009 | L5: =J5/2240 -> 0.45044643
A6: 1701 | B6: Indigo | C6: StKitts | D6: London | H6: 800 | J6: =(E6*2240)+(F6*112)+(G6*28)+(H6) -> 800 | L6: =J6/2240 -> 0.35714286
A7: 1701 | B7: Molasses | C7: StKitts | D7: London | F7: 154 | J7: =(E7*2240)+(F7*112)+(G7*28)+(H7) -> 17248 | L7: =J7/2240 -> 7.7

Sheet NewEngland
A1: YEAR | B1: COMMODITY_NAME | C1: FROM_LOCATION | D1: TO_LOCATION | E1: ton | F1: hh | G1: quarter | H1: lb | J1: Total Pounds | L1: WEIGHT
A2: 1701 | B2: Bayberry Wax | C2: NewEngland | D2: London | H2: 84 | J2: =(E2*2240)+(F2*112)+(G2*28)+H2 -> 84 | L2: =J2/2240 -> 0.0375
A3: 1701 | B3: Brown Sugar | C3: NewEngland | D3: London | F3: 2636 | G3: 2 | H3: 4 | J3: =(E3*2240)+(F3*112)+(G3*28)+H3 -> 295292 | L3: =J3/2240 -> 131.82679
A4: 1701 | B4: Chocolate | C4: NewEngland | D4: London | H4: 119 | J4: =(E4*2240)+(F4*112)+(G4*28)+H4 -> 119 | L4: =J4/2240 -> 0.053125
A5: 1701 | B5: Cocoa Nuts | C5: NewEngland | D5: London | F5: 36 | G5: 2 | H5: 21 | J5: =(E5*2240)+(F5*112)+(G5*28)+H5 -> 4109 | L5: =J5/2240 -> 1.834375
A6: 1701 | B6: Cotton | C6: NewEngland | D6: London | H6: =25*200 -> 5000 | I6: 25 Bag | J6: =(E6*2240)+(F6*112)+(G6*28)+H6 -> 5000 | L6: =J6/2240 -> 2.2321429
A7: 1701 | B7: Dry Ginger | C7: NewEngland | D7: London | F7: 7 | G7: 3 | J7: =(E7*2240)+(F7*112)+(G7*28)+H7 -> 868 | L7: =J7/2240 -> 0.3875
A8: 1701 | B8: Elephant Teeth | C8: NewEngland | D8: London | G8: 2 | J8: =(E8*2240)+(F8*112)+(G8*28)+H8 -> 56 | L8: =J8/2240 -> 0.025
A9: 1701 | B9: Indigo | C9: NewEngland | D9: London | H9: 315 | J9: =(E9*2240)+(F9*112)+(G9*28)+H9 -> 315 | L9: =J9/2240 -> 0.140625
A10: 1701 | B10: Lime Juice | C10: NewEngland | D10: London | H10: 4671 | I10: 467 Gallons | J10: =(E10*2240)+(F10*112)+(G10*28)+H10 -> 4671 | L10: =J10/2240 -> 2.0852679
A11: 1701 | B11: Madera Wine | C11: NewEngland | D11: London | H11: 100 | I11: 10 Gallons | J11: =(E11*2240)+(F11*112)+(G11*28)+H11 -> 100 | L11: =J11/2240 -> 0.044642857
A12: 1701 | B12: Molasses | C12: NewEngland | D12: London | F12: 8213 | G12: 0 | H12: 21 | J12: =(E12*2240)+(F12*112)+(G12*28)+H12 -> 919877 | L12: =J12/2240 -> 410.65938
A13: 1701 | B13: Pimento | C13: NewEngland | D13: London | H13: 162 | J13: =(E13*2240)+(F13*112)+(G13*28)+H13 -> 162 | L13: =J13/2240 -> 0.072321429
A14: 1701 | B14: Shruff | C14: NewEngland | D14: London | F14: 72 | G14: 2 | H14: 0 | J14: =(E14*2240)+(F14*112)+(G14*28)+H14 -> 8120 | L14: =J14/2240 -> 3.625
A15: 1701 | B15: Succads | C15: NewEngland | D15: London | H15: 14 | J15: =(E15*2240)+(F15*112)+(G15*28)+H15 -> 14 | L15: =J15/2240 -> 0.00625
A16: 1701 | B16: Sugar Loaf | C16: NewEngland | D16: London | H16: 0 | J16: =(E16*2240)+(F16*112)+(G16*28)+H16 -> 0 | L16: =J16/2240 -> 0
A17: 1701 | B17: Tobacco | C17: NewEngland | D17: London | H17: 42959 | J17: =(E17*2240)+(F17*112)+(G17*28)+H17 -> 42959 | L17: =J17/2240 -> 19.178125
A18: 1701 | B18: Tortoise shell | C18: NewEngland | D18: London | H18: 166 | J18: =(E18*2240)+(F18*112)+(G18*28)+H18 -> 166 | L18: =J18/2240 -> 0.074107143
A19: 1701 | B19: White Sugar | C19: NewEngland | D19: London | F19: 1 | G19: 2 | H19: 0 | J19: =(E19*2240)+(F19*112)+(G19*28)+H19 -> 168 | L19: =J19/2240 -> 0.075
A20: 1701 | B20: Bees Wax | C20: NewEngland | D20: Out Ports | H20: 28 | J20: =(E20*2240)+(F20*112)+(G20*28)+H20 -> 28 | L20: =J20/2240 -> 0.0125
A21: 1701 | B21: Brown Sugar | C21: NewEngland | D21: Out Ports | F21: 178 | G21: 3 | H21: 23 | J21: =(E21*2240)+(F21*112)+(G21*28)+H21 -> 20043 | L21: =J21/2240 -> 8.9477679
A22: 1701 | B22: Molasses | C22: NewEngland | D22: Out Ports | F22: 495 | G22: 3 | H22: 11 | J22: =(E22*2240)+(F22*112)+(G22*28)+H22 -> 55535 | L22: =J22/2240 -> 24.792411
A23: 1701 | B23: Tobacco | C23: NewEngland | D23: Out Ports | H23: 1153 | J23: =(E23*2240)+(F23*112)+(G23*28)+H23 -> 1153 | L23: =J23/2240 -> 0.51473214
