Workbook

Sheet Master Goods Sheet
A1: Item | B1: Total London | C1: Total Outports | D1: Total
A2: Annatto | B2: =SUMIFS(Antigua!$L:$L, Antigua!$B:$B, $A2, Antigua!$D:$D, "London") + SUMIFS(Barbados!$L:$L, Barbados!$B:$B, $A2, Barbados!$D:$D, "London") + SUMIFS(Bermuda!$J:$J, Bermuda!$A:$A, $A2, Bermuda!$B:$B, "London") + SUMIFS(Jamaica!$L:$L, Jamaica!$B:$B, $A2, Jamaica!$D:$D, "London") + SUMIFS(Mountserat!$L:$L, Mountserat!$B:$B, $A2, Mountserat!$D:$D, "London") + SUMIFS(Nevis!$L:$L, Nevis!$B:$B, $A2, Nevis!$D:$D, "London") + SUMIFS('St Kitts'!$L:$L, 'St Kitts'!$B:$B, $A2, 'St Kitts'!$D:$D, "London") -> 1.7058036 | C2: =SUMIFS(Antigua!$L:$L, Antigua!$B:$B, $A2, Antigua!$D:$D, "Out Ports") + SUMIFS(Barbados!$L:$L, Barbados!$B:$B, $A2, Barbados!$D:$D, "Out Ports") + SUMIFS(Bermuda!$J:$J, Bermuda!$A:$A, $A2, Bermuda!$B:$B, "Out Ports") + SUMIFS(Jamaica!$L:$L, Jamaica!$B:$B, $A2, Jamaica!$D:$D, "Out Ports") + SUMIFS(Mountserat!$L:$L, Mountserat!$B:$B, $A2, Mountserat!$D:$D, "Out Ports") + SUMIFS(Nevis!$L:$L, Nevis!$B:$B, $A2, Nevis!$D:$D, "Out Ports") + SUMIFS('St Kitts'!$L:$L, 'St Kitts'!$B:$B, $A2, 'St Kitts'!$D:$D, "Out Ports") -> 0.96964286 | D2: =ROUND((B2+C2),2) -> 2.68
A3: Bayberry Wax | B3: =SUMIFS(Antigua!$L:$L, Antigua!$B:$B, $A3, Antigua!$D:$D, "London") + SUMIFS(Barbados!$L:$L, Barbados!$B:$B, $A3, Barbados!$D:$D, "London") + SUMIFS(Bermuda!$J:$J, Bermuda!$A:$A, $A3, Bermuda!$B:$B, "London") + SUMIFS(Jamaica!$L:$L, Jamaica!$B:$B, $A3, Jamaica!$D:$D, "London") + SUMIFS(Mountserat!$L:$L, Mountserat!$B:$B, $A3, Mountserat!$D:$D, "London") + SUMIFS(Nevis!$L:$L, Nevis!$B:$B, $A3, Nevis!$D:$D, "London") + SUMIFS('St Kitts'!$L:$L, 'St Kitts'!$B:$B, $A3, 'St Kitts'!$D:$D, "London") -> 0 | C3: =SUMIFS(Antigua!$L:$L, Antigua!$B:$B, $A3, Antigua!$D:$D, "Out Ports") + SUMIFS(Barbados!$L:$L, Barbados!$B:$B, $A3, Barbados!$D:$D, "Out Ports") + SUMIFS(Bermuda!$J:$J, Bermuda!$A:$A, $A3, Bermuda!$B:$B, "Out Ports") + SUMIFS(Jamaica!$L:$L, Jamaica!$B:$B, $A3, Jamaica!$D:$D, "Out Ports") + SUMIFS(Mountserat!$L:$L, Mountserat!$B:$B, $A3, Mountserat!$D:$D, "Out Ports") + SUMIFS(Nevis!$L:$L, Nevis!$B:$B, $A3, Nevis!$D:$D, "Out Ports") + SUMIFS('St Kitts'!$L:$L, 'St Kitts'!$B:$B, $A3, 'St Kitts'!$D:$D, "Out Ports") -> 0 | D3: =ROUND((B3+C3),2) -> 0
A4: Bees Wax | B4: =SUMIFS(Antigua!$L:$L, Antigua!$B:$B, $A4, Antigua!$D:$D, "London") + SUMIFS(Barbados!$L:$L, Barbados!$B:$B, $A4, Barbados!$D:$D, "London") + SUMIFS(Bermuda!$J:$J, Bermuda!$A:$A, $A4, Bermuda!$B:$B, "London") + SUMIFS(Jamaica!$L:$L, Jamaica!$B:$B, $A4, Jamaica!$D:$D, "London") + SUMIFS(Mountserat!$L:$L, Mountserat!$B:$B, $A4, Mountserat!$D:$D, "London") + SUMIFS(Nevis!$L:$L, Nevis!$B:$B, $A4, Nevis!$D:$D, "London") + SUMIFS('St Kitts'!$L:$L, 'St Kitts'!$B:$B, $A4, 'St Kitts'!$D:$D, "London") -> 0 | C4: =SUMIFS(Antigua!$L:$L, Antigua!$B:$B, $A4, Antigua!$D:$D, "Out Ports") + SUMIFS(Barbados!$L:$L, Barbados!$B:$B, $A4, Barbados!$D:$D, "Out Ports") + SUMIFS(Bermuda!$J:$J, Bermuda!$A:$A, $A4, Bermuda!$B:$B, "Out Ports") + SUMIFS(Jamaica!$L:$L, Jamaica!$B:$B, $A4, Jamaica!$D:$D, "Out Ports") + SUMIFS(Mountserat!$L:$L, Mountserat!$B:$B, $A4, Mountserat!$D:$D, "Out Ports") + SUMIFS(Nevis!$L:$L, Nevis!$B:$B, $A4, Nevis!$D:$D, "Out Ports") + SUMIFS('St Kitts'!$L:$L, 'St Kitts'!$B:$B, $A4, 'St Kitts'!$D:$D, "Out Ports") -> 0 | D4: =ROUND((B4+C4),2) -> 0
A5: Brandy | B5: =SUMIFS(Antigua!$L:$L, Antigua!$B:$B, $A5, Antigua!$D:$D, "London") + SUMIFS(Barbados!$L:$L, Barbados!$B:$B, $A5, Barbados!$D:$D, "London") + SUMIFS(Bermuda!$J:$J, Bermuda!$A:$A, $A5, Bermuda!$B:$B, "London") + SUMIFS(Jamaica!$L:$L, Jamaica!$B:$B, $A5, Jamaica!$D:$D, "London") + SUMIFS(Mountserat!$L:$L, Mountserat!$B:$B, $A5, Mountserat!$D:$D, "London") + SUMIFS(Nevis!$L:$L, Nevis!$B:$B, $A5, Nevis!$D:$D, "London") + SUMIFS('St Kitts'!$L:$L, 'St Kitts'!$B:$B, $A5, 'St Kitts'!$D:$D, "London") -> 0 | C5: =SUMIFS(Antigua!$L:$L, Antigua!$B:$B, $A5, Antigua!$D:$D, "Out Ports") + SUMIFS(Barbados!$L:$L, Barbados!$B:$B, $A5, Barbados!$D:$D, "Out Ports") + SUMIFS(Bermuda!$J:$J, Bermuda!$A:$A, $A5, Bermuda!$B:$B, "Out Ports") + SUMIFS(Jamaica!$L:$L, Jamaica!$B:$B, $A5, Jamaica!$D:$D, "Out Ports") + SUMIFS(Mountserat!$L:$L, Mountserat!$B:$B, $A5, Mountserat!$D:$D, "Out Ports") + SUMIFS(Nevis!$L:$L, Nevis!$B:$B, $A5, Nevis!$D:$D, "Out Ports") + SUMIFS('St Kitts'!$L:$L, 'St Kitts'!$B:$B, $A5, 'St Kitts'!$D:$D, "Out Ports") -> 0 | D5: =ROUND((B5+C5),2) -> 0
A6: Brown Sugar | B6: =SUMIFS(Antigua!$L:$L, Antigua!$B:$B, $A6, Antigua!$D:$D, "London") + SUMIFS(Barbados!$L:$L, Barbados!$B:$B, $A6, Barbados!$D:$D, "London") + SUMIFS(Bermuda!$J:$J, Bermuda!$A:$A, $A6, Bermuda!$B:$B, "London") + SUMIFS(Jamaica!$L:$L, Jamaica!$B:$B, $A6, Jamaica!$D:$D, "London") + SUMIFS(Mountserat!$L:$L, Mountserat!$B:$B, $A6, Mountserat!$D:$D, "London") + SUMIFS(Nevis!$L:$L, Nevis!$B:$B, $A6, Nevis!$D:$D, "London") + SUMIFS('St Kitts'!$L:$L, 'St Kitts'!$B:$B, $A6, 'St Kitts'!$D:$D, "London") -> 10831.63 | C6: =SUMIFS(Antigua!$L:$L, Antigua!$B:$B, $A6, Antigua!$D:$D, "Out Ports") + SUMIFS(Barbados!$L:$L, Barbados!$B:$B, $A6, Barbados!$D:$D, "Out Ports") + SUMIFS(Bermuda!$J:$J, Bermuda!$A:$A, $A6, Bermuda!$B:$B, "Out Ports") + SUMIFS(Jamaica!$L:$L, Jamaica!$B:$B, $A6, Jamaica!$D:$D, "Out Ports") + SUMIFS(Mountserat!$L:$L, Mountserat!$B:$B, $A6, Mountserat!$D:$D, "Out Ports") + SUMIFS(Nevis!$L:$L, Nevis!$B:$B, $A6, Nevis!$D:$D, "Out Ports") + SUMIFS('St Kitts'!$L:$L, 'St Kitts'!$B:$B, $A6, 'St Kitts'!$D:$D, "Out Ports") -> 4097.0032 | D6: =ROUND((B6+C6),2) -> 14928.63
A7: Cascarilla | B7: =SUMIFS(Antigua!$L:$L, Antigua!$B:$B, $A7, Antigua!$D:$D, "London") + SUMIFS(Barbados!$L:$L, Barbados!$B:$B, $A7, Barbados!$D:$D, "London") + SUMIFS(Bermuda!$J:$J, Bermuda!$A:$A, $A7, Bermuda!$B:$B, "London") + SUMIFS(Jamaica!$L:$L, Jamaica!$B:$B, $A7, Jamaica!$D:$D, "London") + SUMIFS(Mountserat!$L:$L, Mountserat!$B:$B, $A7, Mountserat!$D:$D, "London") + SUMIFS(Nevis!$L:$L, Nevis!$B:$B, $A7, Nevis!$D:$D, "London") + SUMIFS('St Kitts'!$L:$L, 'St Kitts'!$B:$B, $A7, 'St Kitts'!$D:$D, "London") -> 0 | C7: =SUMIFS(Antigua!$L:$L, Antigua!$B:$B, $A7, Antigua!$D:$D, "Out Ports") + SUMIFS(Barbados!$L:$L, Barbados!$B:$B, $A7, Barbados!$D:$D, "Out Ports") + SUMIFS(Bermuda!$J:$J, Bermuda!$A:$A, $A7, Bermuda!$B:$B, "Out Ports") + SUMIFS(Jamaica!$L:$L, Jamaica!$B:$B, $A7, Jamaica!$D:$D, "Out Ports") + SUMIFS(Mountserat!$L:$L, Mountserat!$B:$B, $A7, Mountserat!$D:$D, "Out Ports") + SUMIFS(Nevis!$L:$L, Nevis!$B:$B, $A7, Nevis!$D:$D, "Out Ports") + SUMIFS('St Kitts'!$L:$L, 'St Kitts'!$B:$B, $A7, 'St Kitts'!$D:$D, "Out Ports") -> 0 | D7: =ROUND((B7+C7),2) -> 0
A8: Chocolate | B8: =SUMIFS(Antigua!$L:$L, Antigua!$B:$B, $A8, Antigua!$D:$D, "London") + SUMIFS(Barbados!$L:$L, Barbados!$B:$B, $A8, Barbados!$D:$D, "London") + SUMIFS(Bermuda!$J:$J, Bermuda!$A:$A, $A8, Bermuda!$B:$B, "London") + SUMIFS(Jamaica!$L:$L, Jamaica!$B:$B, $A8, Jamaica!$D:$D, "London") + SUMIFS(Mountserat!$L:$L, Mountserat!$B:$B, $A8, Mountserat!$D:$D, "London") + SUMIFS(Nevis!$L:$L, Nevis!$B:$B, $A8, Nevis!$D:$D, "London") + SUMIFS('St Kitts'!$L:$L, 'St Kitts'!$B:$B, $A8, 'St Kitts'!$D:$D, "London") -> 0.099553571 | C8: =SUMIFS(Antigua!$L:$L, Antigua!$B:$B, $A8, Antigua!$D:$D, "Out Ports") + SUMIFS(Barbados!$L:$L, Barbados!$B:$B, $A8, Barbados!$D:$D, "Out Ports") + SUMIFS(Bermuda!$J:$J, Bermuda!$A:$A, $A8, Bermuda!$B:$B, "Out Ports") + SUMIFS(Jamaica!$L:$L, Jamaica!$B:$B, $A8, Jamaica!$D:$D, "Out Ports") + SUMIFS(Mountserat!$L:$L, Mountserat!$B:$B, $A8, Mountserat!$D:$D, "Out Ports") + SUMIFS(Nevis!$L:$L, Nevis!$B:$B, $A8, Nevis!$D:$D, "Out Ports") + SUMIFS('St Kitts'!$L:$L, 'St Kitts'!$B:$B, $A8, 'St Kitts'!$D:$D, "Out Ports") -> 0.003125 | D8: =ROUND((B8+C8),2) -> 0.1
A9: Cockeneal | B9: =SUMIFS(Antigua!$L:$L, Antigua!$B:$B, $A9, Antigua!$D:$D, "London") + SUMIFS(Barbados!$L:$L, Barbados!$B:$B, $A9, Barbados!$D:$D, "London") + SUMIFS(Bermuda!$J:$J, Bermuda!$A:$A, $A9, Bermuda!$B:$B, "London") + SUMIFS(Jamaica!$L:$L, Jamaica!$B:$B, $A9, Jamaica!$D:$D, "London") + SUMIFS(Mountserat!$L:$L, Mountserat!$B:$B, $A9, Mountserat!$D:$D, "London") + SUMIFS(Nevis!$L:$L, Nevis!$B:$B, $A9, Nevis!$D:$D, "London") + SUMIFS('St Kitts'!$L:$L, 'St Kitts'!$B:$B, $A9, 'St Kitts'!$D:$D, "London") -> 0 | C9: =SUMIFS(Antigua!$L:$L, Antigua!$B:$B, $A9, Antigua!$D:$D, "Out Ports") + SUMIFS(Barbados!$L:$L, Barbados!$B:$B, $A9, Barbados!$D:$D, "Out Ports") + SUMIFS(Bermuda!$J:$J, Bermuda!$A:$A, $A9, Bermuda!$B:$B, "Out Ports") + SUMIFS(Jamaica!$L:$L, Jamaica!$B:$B, $A9, Jamaica!$D:$D, "Out Ports") + SUMIFS(Mountserat!$L:$L, Mountserat!$B:$B, $A9, Mountserat!$D:$D, "Out Ports") + SUMIFS(Nevis!$L:$L, Nevis!$B:$B, $A9, Nevis!$D:$D, "Out Ports") + SUMIFS('St Kitts'!$L:$L, 'St Kitts'!$B:$B, $A9, 'St Kitts'!$D:$D, "Out Ports") -> 0 | D9: =ROUND((B9+C9),2) -> 0
A10: Cocoa Nuts | B10: =SUMIFS(Antigua!$L:$L, Antigua!$B:$B, $A10, Antigua!$D:$D, "London") + SUMIFS(Barbados!$L:$L, Barbados!$B:$B, $A10, Barbados!$D:$D, "London") + SUMIFS(Bermuda!$J:$J, Bermuda!$A:$A, $A10, Bermuda!$B:$B, "London") + SUMIFS(Jamaica!$L:$L, Jamaica!$B:$B, $A10, Jamaica!$D:$D, "London") + SUMIFS(Mountserat!$L:$L, Mountserat!$B:$B, $A10, Mountserat!$D:$D, "London") + SUMIFS(Nevis!$L:$L, Nevis!$B:$B, $A10, Nevis!$D:$D, "London") + SUMIFS('St Kitts'!$L:$L, 'St Kitts'!$B:$B, $A10, 'St Kitts'!$D:$D, "London") -> 64.253571 | C10: =SUMIFS(Antigua!$L:$L, Antigua!$B:$B, $A10, Antigua!$D:$D, "Out Ports") + SUMIFS(Barbados!$L:$L, Barbados!$B:$B, $A10, Barbados!$D:$D, "Out Ports") + SUMIFS(Bermuda!$J:$J, Bermuda!$A:$A, $A10, Bermuda!$B:$B, "Out Ports") + SUMIFS(Jamaica!$L:$L, Jamaica!$B:$B, $A10, Jamaica!$D:$D, "Out Ports") + SUMIFS(Mountserat!$L:$L, Mountserat!$B:$B, $A10, Mountserat!$D:$D, "Out Ports") + SUMIFS(Nevis!$L:$L, Nevis!$B:$B, $A10, Nevis!$D:$D, "Out Ports") + SUMIFS('St Kitts'!$L:$L, 'St Kitts'!$B:$B, $A10, 'St Kitts'!$D:$D, "Out Ports") -> 8.8785714 | D10: =ROUND((B10+C10),2) -> 73.13
A11: Cotton | B11: =SUMIFS(Antigua!$L:$L, Antigua!$B:$B, $A11, Antigua!$D:$D, "London") + SUMIFS(Barbados!$L:$L, Barbados!$B:$B, $A11, Barbados!$D:$D, "London") + SUMIFS(Bermuda!$J:$J, Bermuda!$A:$A, $A11, Bermuda!$B:$B, "London") + SUMIFS(Jamaica!$L:$L, Jamaica!$B:$B, $A11, Jamaica!$D:$D, "London") + SUMIFS(Mountserat!$L:$L, Mountserat!$B:$B, $A11, Mountserat!$D:$D, "London") + SUMIFS(Nevis!$L:$L, Nevis!$B:$B, $A11, Nevis!$D:$D, "London") + SUMIFS('St Kitts'!$L:$L, 'St Kitts'!$B:$B, $A11, 'St Kitts'!$D:$D, "London") -> 135.93192 | C11: =SUMIFS(Antigua!$L:$L, Antigua!$B:$B, $A11, Antigua!$D:$D, "Out Ports") + SUMIFS(Barbados!$L:$L, Barbados!$B:$B, $A11, Barbados!$D:$D, "Out Ports") + SUMIFS(Bermuda!$J:$J, Bermuda!$A:$A, $A11, Bermuda!$B:$B, "Out Ports") + SUMIFS(Jamaica!$L:$L, Jamaica!$B:$B, $A11, Jamaica!$D:$D, "Out Ports") + SUMIFS(Mountserat!$L:$L, Mountserat!$B:$B, $A11, Mountserat!$D:$D, "Out Ports") + SUMIFS(Nevis!$L:$L, Nevis!$B:$B, $A11, Nevis!$D:$D, "Out Ports") + SUMIFS('St Kitts'!$L:$L, 'St Kitts'!$B:$B, $A11, 'St Kitts'!$D:$D, "Out Ports") -> 70.96183 | D11: =ROUND((B11+C11),2) -> 206.89
A12: Dry Ginger | B12: =SUMIFS(Antigua!$L:$L, Antigua!$B:$B, $A12, Antigua!$D:$D, "London") + SUMIFS(Barbados!$L:$L, Barbados!$B:$B, $A12, Barbados!$D:$D, "London") + SUMIFS(Bermuda!$J:$J, Bermuda!$A:$A, $A12, Bermuda!$B:$B, "London") + SUMIFS(Jamaica!$L:$L, Jamaica!$B:$B, $A12, Jamaica!$D:$D, "London") + SUMIFS(Mountserat!$L:$L, Mountserat!$B:$B, $A12, Mountserat!$D:$D, "London") + SUMIFS(Nevis!$L:$L, Nevis!$B:$B, $A12, Nevis!$D:$D, "London") + SUMIFS('St Kitts'!$L:$L, 'St Kitts'!$B:$B, $A12, 'St Kitts'!$D:$D, "London") -> 812.72009 | C12: =SUMIFS(Antigua!$L:$L, Antigua!$B:$B, $A12, Antigua!$D:$D, "Out Ports") + SUMIFS(Barbados!$L:$L, Barbados!$B:$B, $A12, Barbados!$D:$D, "Out Ports") + SUMIFS(Bermuda!$J:$J, Bermuda!$A:$A, $A12, Bermuda!$B:$B, "Out Ports") + SUMIFS(Jamaica!$L:$L, Jamaica!$B:$B, $A12, Jamaica!$D:$D, "Out Ports") + SUMIFS(Mountserat!$L:$L, Mountserat!$B:$B, $A12, Mountserat!$D:$D, "Out Ports") + SUMIFS(Nevis!$L:$L, Nevis!$B:$B, $A12, Nevis!$D:$D, "Out Ports") + SUMIFS('St Kitts'!$L:$L, 'St Kitts'!$B:$B, $A12, 'St Kitts'!$D:$D, "Out Ports") -> 153.57946 | D12: =ROUND((B12+C12),2) -> 966.3
A13: Elephant Teeth | B13: =SUMIFS(Antigua!$L:$L, Antigua!$B:$B, $A13, Antigua!$D:$D, "London") + SUMIFS(Barbados!$L:$L, Barbados!$B:$B, $A13, Barbados!$D:$D, "London") + SUMIFS(Bermuda!$J:$J, Bermuda!$A:$A, $A13, Bermuda!$B:$B, "London") + SUMIFS(Jamaica!$L:$L, Jamaica!$B:$B, $A13, Jamaica!$D:$D, "London") + SUMIFS(Mountserat!$L:$L, Mountserat!$B:$B, $A13, Mountserat!$D:$D, "London") + SUMIFS(Nevis!$L:$L, Nevis!$B:$B, $A13, Nevis!$D:$D, "London") + SUMIFS('St Kitts'!$L:$L, 'St Kitts'!$B:$B, $A13, 'St Kitts'!$D:$D, "London") -> 9.8325893 | C13: =SUMIFS(Antigua!$L:$L, Antigua!$B:$B, $A13, Antigua!$D:$D, "Out Ports") + SUMIFS(Barbados!$L:$L, Barbados!$B:$B, $A13, Barbados!$D:$D, "Out Ports") + SUMIFS(Bermuda!$J:$J, Bermuda!$A:$A, $A13, Bermuda!$B:$B, "Out Ports") + SUMIFS(Jamaica!$L:$L, Jamaica!$B:$B, $A13, Jamaica!$D:$D, "Out Ports") + SUMIFS(Mountserat!$L:$L, Mountserat!$B:$B, $A13, Mountserat!$D:$D, "Out Ports") + SUMIFS(Nevis!$L:$L, Nevis!$B:$B, $A13, Nevis!$D:$D, "Out Ports") + SUMIFS('St Kitts'!$L:$L, 'St Kitts'!$B:$B, $A13, 'St Kitts'!$D:$D, "Out Ports") -> 0.50223214 | D13: =ROUND((B13+C13),2) -> 10.33
... A31: Madera Wine | B31: =SUMIFS(Antigua!$L:$L, Antigua!$B:$B, $A31, Antigua!$D:$D, "London") + SUMIFS(Barbados!$L:$L, Barbados!$B:$B, $A31, Barbados!$D:$D, "London") + SUMIFS(Bermuda!$J:$J, Bermuda!$A:$A, $A31, Bermuda!$B:$B, "London") + SUMIFS(Jamaica!$L:$L, Jamaica!$B:$B, $A31, Jamaica!$D:$D, "London") + SUMIFS(Mountserat!$L:$L, Mountserat!$B:$B, $A31, Mountserat!$D:$D, "London") + SUMIFS(Nevis!$L:$L, Nevis!$B:$B, $A31, Nevis!$D:$D, "London") + SUMIFS('St Kitts'!$L:$L, 'St Kitts'!$B:$B, $A31, 'St Kitts'!$D:$D, "London") -> 2.7080357 | C31: =SUMIFS(Antigua!$L:$L, Antigua!$B:$B, $A31, Antigua!$D:$D, "Out Ports") + SUMIFS(Barbados!$L:$L, Barbados!$B:$B, $A31, Barbados!$D:$D, "Out Ports") + SUMIFS(Bermuda!$J:$J, Bermuda!$A:$A, $A31, Bermuda!$B:$B, "Out Ports") + SUMIFS(Jamaica!$L:$L, Jamaica!$B:$B, $A31, Jamaica!$D:$D, "Out Ports") + SUMIFS(Mountserat!$L:$L, Mountserat!$B:$B, $A31, Mountserat!$D:$D, "Out Ports") + SUMIFS(Nevis!$L:$L, Nevis!$B:$B, $A31, Nevis!$D:$D, "Out Ports") + SUMIFS('St Kitts'!$L:$L, 'St Kitts'!$B:$B, $A31, 'St Kitts'!$D:$D, "Out Ports") -> 1.703125 | D31: =ROUND((B31+C31),2) -> 4.41

Sheet Antigua
A1: YEAR | B1: COMMODITY_NAME | C1: FROM_LOCATION | D1: TO_LOCATION | E1: ton | F1: hh | G1: quarter | H1: lb | J1: Total Pounds | L1: WEIGHT
A2: 1704 | B2: Annatto | C2: Antigua | D2: London | J2: =(E2*2240)+(F2*112)+(G2*28)+H2 -> 0 | L2: =J2/2240 -> 0
A3: 1704 | B3: Brown Sugar | C3: Antigua | D3: London | F3: 26698 | G3: 1 | H3: 21 | J3: =(E3*2240)+(F3*112)+(G3*28)+H3 -> 2990225 | L3: =J3/2240 -> 1334.9219
A4: 1704 | B4: Chocolate | C4: Antigua | D4: London | J4: =(E4*2240)+(F4*112)+(G4*28)+H4 -> 0 | L4: =J4/2240 -> 0
A5: 1704 | B5: Cocoa Nuts | C5: Antigua | D5: London | F5: 37 | H5: 27 | J5: =(E5*2240)+(F5*112)+(G5*28)+H5 -> 4171 | L5: =J5/2240 -> 1.8620536
A6: 1704 | B6: Cotton | C6: Antigua | D6: London | H6: =174*200 -> 34800 | I6: 174 bags | J6: =(E6*2240)+(F6*112)+(G6*28)+H6 -> 34800 | L6: =J6/2240 -> 15.535714
A7: 1704 | B7: Dry Ginger | C7: Antigua | D7: London | F7: 662 | H7: 1 | J7: =(E7*2240)+(F7*112)+(G7*28)+H7 -> 74145 | L7: =J7/2240 -> 33.100446
A8: 1704 | B8: Elephant Teeth | C8: Antigua | D8: London | F8: 43 | H8: 21 | J8: =(E8*2240)+(F8*112)+(G8*28)+H8 -> 4837 | L8: =J8/2240 -> 2.159375
A9: 1704 | B9: Indigo | C9: Antigua | D9: London | H9: 26 | J9: =(E9*2240)+(F9*112)+(G9*28)+H9 -> 26 | L9: =J9/2240 -> 0.011607143
A10: 1704 | B10: Lemon Water | C10: Antigua | D10: London | J10: =(E10*2240)+(F10*112)+(G10*28)+H10 -> 0 | L10: =J10/2240 -> 0
A11: 1704 | B11: Lignum Vitae | C11: Antigua | D11: London | F11: 957 | G11: 3 | J11: =(E11*2240)+(F11*112)+(G11*28)+H11 -> 107268 | L11: =J11/2240 -> 47.8875
A12: 1704 | B12: Lime Juice | C12: Antigua | D12: London | H12: 727 | I12: 72g | J12: =(E12*2240)+(F12*112)+(G12*28)+H12 -> 727 | L12: =J12/2240 -> 0.32455357
A13: 1704 | B13: Madera Wine | C13: Antigua | D13: London | J13: =(E13*2240)+(F13*112)+(G13*28)+H13 -> 0 | L13: =J13/2240 -> 0
A14: 1704 | B14: Molasses | C14: Antigua | D14: London | F14: 23 | J14: =(E14*2240)+(F14*112)+(G14*28)+H14 -> 2576 | L14: =J14/2240 -> 1.15
A15: 1704 | B15: Rum | C15: Antigua | D15: London | H15: 989 | I15: 98g | J15: =(E15*2240)+(F15*112)+(G15*28)+H15 -> 989 | L15: =J15/2240 -> 0.44151786
A16: 1704 | B16: Shruff | C16: Antigua | D16: London | J16: =(E16*2240)+(F16*112)+(G16*28)+H16 -> 0 | L16: =J16/2240 -> 0
A17: 1704 | B17: Succads | C17: Antigua | D17: London | H17: 42 | J17: =(E17*2240)+(F17*112)+(G17*28)+H17 -> 42 | L17: =J17/2240 -> 0.01875
A18: 1704 | B18: Tobacco | C18: Antigua | D18: London | H18: 3979 | J18: =(E18*2240)+(F18*112)+(G18*28)+H18 -> 3979 | L18: =J18/2240 -> 1.7763393
A19: 1704 | B19: Tortoise Shell | C19: Antigua | D19: London | H19: 150 | J19: =(E19*2240)+(F19*112)+(G19*28)+H19 -> 150 | L19: =J19/2240 -> 0.066964286
A20: 1704 | B20: Whalebone | C20: Antigua | D20: London | F20: 3 | H20: 19
A21: 1704 | B21: White Sugar | C21: Antigua | D21: London | F21: 2 | G21: 2 | J21: =(E21*2240)+(F21*112)+(G21*28)+H21 -> 280 | L21: =J21/2240 -> 0.125
A22: 1704 | B22: Wood, Fustick | C22: Antigua | D22: London | F22: 33 | J22: =(E22*2240)+(F22*112)+(G22*28)+H22 -> 3696 | L22: =J22/2240 -> 1.65
A23: 1704 | B23: Wood, Logwood | C23: Antigua | D23: London | E23: 7 | F23: 2 | G23: 1 | J23: =(E23*2240)+(F23*112)+(G23*28)+H23 -> 15932 | L23: =J23/2240 -> 7.1125
A24: 1704 | B24: Wood, Redwood | C24: Antigua | D24: London | F24: 17 | G24: 3 | H24: 21 | J24: =(E24*2240)+(F24*112)+(G24*28)+H24 -> 2009 | L24: =J24/2240 -> 0.896875
A25: 1704 | B25: Brown Sugar | C25: Antigua | D25: Out Ports | F25: 18239 | G25: 3 | H25: 6 | J25: =(E25*2240)+(F25*112)+(G25*28)+H25 -> 2042858 | L25: =J25/2240 -> 911.99018
A26: 1704 | B26: Cocoa | C26: Antigua | D26: Out Ports | J26: =(E26*2240)+(F26*112)+(G26*28)+H26 -> 0 | L26: =J26/2240 -> 0
A27: 1704 | B27: Cocoa Nuts | C27: Antigua | D27: Out Ports | F27: 5 | H27: 22 | J27: =(E27*2240)+(F27*112)+(G27*28)+H27 -> 582 | L27: =J27/2240 -> 0.25982143
A28: 1704 | B28: Cotton | C28: Antigua | D28: Out Ports | H28: 32765 | J28: =(E28*2240)+(F28*112)+(G28*28)+H28 -> 32765 | L28: =J28/2240 -> 14.627232
A29: 1704 | B29: Dry Ginger | C29: Antigua | D29: Out Ports | F29: 213 | G29: 2 | H29: 20 | J29: =(E29*2240)+(F29*112)+(G29*28)+H29 -> 23932 | L29: =J29/2240 -> 10.683929
A30: 1704 | B30: Fustic | C30: Antigua | D30: Out Ports | J30: =(E30*2240)+(F30*112)+(G30*28)+H30 -> 0 | L30: =J30/2240 -> 0
A31: 1704 | B31: Indigo | C31: Antigua | D31: Out Ports | J31: =(E31*2240)+(F31*112)+(G31*28)+H31 -> 0 | L31: =J31/2240 -> 0
A32: 1704 | B32: Lignum Vitae | C32: Antigua | D32: Out Ports | E32: 3 | F32: 6 | G32: 2 | J32: =(E32*2240)+(F32*112)+(G32*28)+H32 -> 7448 | L32: =J32/2240 -> 3.325
A33: 1704 | B33: Lime Juice | C33: Antigua | D33: Out Ports | H33: 252 | I33: 25g | J33: =(E33*2240)+(F33*112)+(G33*28)+H33 -> 252 | L33: =J33/2240 -> 0.1125
A34: 1704 | B34: Madera Wine | C34: Antigua | D34: Out Ports | J34: =(E34*2240)+(F34*112)+(G34*28)+H34 -> 0 | L34: =J34/2240 -> 0
A35: 1704 | B35: Molasses | C35: Antigua | D35: Out Ports | F35: 298 | H35: 19 | J35: =(E35*2240)+(F35*112)+(G35*28)+H35 -> 33395 | L35: =J35/2240 -> 14.908482
A36: 1704 | B36: Rice | C36: Antigua | D36: Out Ports | J36: =(E36*2240)+(F36*112)+(G36*28)+H36 -> 0 | L36: =J36/2240 -> 0
A37: 1704 | B37: Rum | C37: Antigua | D37: Out Ports | H37: 1352 | I37: 134g | J37: =(E37*2240)+(F37*112)+(G37*28)+H37 -> 1352 | L37: =J37/2240 -> 0.60357143
A38: 1704 | B38: Shruff | C38: Antigua | D38: Out Ports | F38: 2 | G38: 1 | J38: =(E38*2240)+(F38*112)+(G38*28)+H38 -> 252 | L38: =J38/2240 -> 0.1125
A39: 1704 | B39: Succads | C39: Antigua | D39: Out Ports | J39: =(E39*2240)+(F39*112)+(G39*28)+H39 -> 0 | L39: =J39/2240 -> 0
A40: 1704 | B40: Tobacco | C40: Antigua | D40: Out Ports | H40: 2298 | J40: =(E40*2240)+(F40*112)+(G40*28)+H40 -> 2298 | L40: =J40/2240 -> 1.0258929
...

Sheet Barbados
A1: YEAR | B1: COMMODITY_NAME | C1: FROM_LOCATION | D1: TO_LOCATION | E1: ton | F1: hh | G1: quarter | H1: lb | J1: Total Pounds | L1: WEIGHT
A2: 1704 | B2: Aloes Epatica | C2: Barbados | D2: London | H2: 1570 | J2: =(E2*2240)+(F2*112)+(G2*28)+H2 -> 1570 | L2: =J2/2240 -> 0.70089286
A3: 1704 | B3: Annatto | C3: Barbados | D3: London | H3: 1473 | J3: =(E3*2240)+(F3*112)+(G3*28)+H3 -> 1473 | L3: =J3/2240 -> 0.65758929
A4: 1704 | B4: Barrel Staves | C4: Barbados | D4: London | J4: =(E4*2240)+(F4*112)+(G4*28)+H4 -> 0 | L4: =J4/2240 -> 0
A5: 1704 | B5: Brown Sugar | C5: Barbados | D5: London | F5: 77586 | G5: 3 | H5: 20 | J5: =(E5*2240)+(F5*112)+(G5*28)+H5 -> 8689736 | L5: =J5/2240 -> 3879.3464
A6: 1704 | B6: Chocolate | C6: Barbados | D6: London | H6: 40 | J6: =(E6*2240)+(F6*112)+(G6*28)+H6 -> 40 | L6: =J6/2240 -> 0.017857143
A7: 1704 | B7: Cocheneal | C7: Barbados | D7: London | J7: =(E7*2240)+(F7*112)+(G7*28)+H7 -> 0 | L7: =J7/2240 -> 0
A8: 1704 | B8: Cocoa Nuts | C8: Barbados | D8: London | F8: 795 | G8: 12 | H8: 0 | J8: =(E8*2240)+(F8*112)+(G8*28)+H8 -> 89376 | L8: =J8/2240 -> 39.9
A9: 1704 | B9: Cocoa Paste | C9: Barbados | D9: London | J9: =(E9*2240)+(F9*112)+(G9*28)+H9 -> 0 | L9: =J9/2240 -> 0
A10: 1704 | B10: Cotton | C10: Barbados | D10: London | H10: =375*200 -> 75000 | I10: 375bags | J10: =(E10*2240)+(F10*112)+(G10*28)+H10 -> 75000 | L10: =J10/2240 -> 33.482143
A11: 1704 | B11: Dry Ginger | C11: Barbados | D11: London | F11: 2750 | G11: 1 | H11: 1 | J11: =(E11*2240)+(F11*112)+(G11*28)+H11 -> 308029 | L11: =J11/2240 -> 137.51295
A12: 1704 | B12: Elephant Teeth | C12: Barbados | D12: London | F12: 26 | G12: 1 | H12: 11 | J12: =(E12*2240)+(F12*112)+(G12*28)+H12 -> 2951 | L12: =J12/2240 -> 1.3174107
A13: 1704 | B13: Green Ginger | C13: Barbados | D13: London | J13: =(E13*2240)+(F13*112)+(G13*28)+H13 -> 0 | L13: =J13/2240 -> 0
A14: 1704 | B14: Guinea Grains | C14: Barbados | D14: London | H14: 1901 | J14: =(E14*2240)+(F14*112)+(G14*28)+H14 -> 1901 | L14: =J14/2240 -> 0.84866071
A15: 1704 | B15: Hemp | C15: Barbados | D15: London | J15: =(E15*2240)+(F15*112)+(G15*28)+H15 -> 0 | L15: =J15/2240 -> 0
A16: 1704 | B16: Indigo | C16: Barbados | D16: London | H16: 146 | J16: =(E16*2240)+(F16*112)+(G16*28)+H16 -> 146 | L16: =J16/2240 -> 0.065178571
A17: 1704 | B17: Lemon Water | C17: Barbados | D17: London | J17: =(E17*2240)+(F17*112)+(G17*28)+H17 -> 0 | L17: =J17/2240 -> 0
A18: 1704 | B18: Lignum Vitae | C18: Barbados | D18: London | E18: 2 | F18: 12 | J18: =(E18*2240)+(F18*112)+(G18*28)+H18 -> 5824 | L18: =J18/2240 -> 2.6
A19: 1704 | B19: Lime Juice | C19: Barbados | D19: London | H19: 15199 | I19: 1506g | J19: =(E19*2240)+(F19*112)+(G19*28)+H19 -> 15199 | L19: =J19/2240 -> 6.7852679
A20: 1704 | B20: Loaf Sugar | C20: Barbados | D20: London | J20: =(E20*2240)+(F20*112)+(G20*28)+H20 -> 0 | L20: =J20/2240 -> 0
A21: 1704 | B21: Madera Wine | C21: Barbados | D21: London | H21: 6066 | I21: 2t 1hh 34g | J21: =(E21*2240)+(F21*112)+(G21*28)+H21 -> 6066 | L21: =J21/2240 -> 2.7080357
A22: 1704 | B22: Molasses | C22: Barbados | D22: London | F22: 2113 | G22: 3 | H22: 11 | J22: =(E22*2240)+(F22*112)+(G22*28)+H22 -> 236751 | L22: =J22/2240 -> 105.69241
A23: 1704 | B23: Nutmeg | C23: Barbados | D23: London | H23: 60 | J23: =(E23*2240)+(F23*112)+(G23*28)+H23 -> 60 | L23: =J23/2240 -> 0.026785714
A24: 1704 | B24: Oranges | C24: Barbados | D24: London | J24: =(E24*2240)+(F24*112)+(G24*28)+H24 -> 0 | L24: =J24/2240 -> 0
A25: 1704 | B25: Pimento | C25: Barbados | D25: London | H25: 94 | J25: =(E25*2240)+(F25*112)+(G25*28)+H25 -> 94 | L25: =J25/2240 -> 0.041964286
A26: 1704 | B26: Rice | C26: Barbados | D26: London | J26: =(E26*2240)+(F26*112)+(G26*28)+H26 -> 0 | L26: =J26/2240 -> 0
A27: 1704 | B27: Rum | C27: Barbados | D27: London | H27: 15805 | I27: 1566g | J27: =(E27*2240)+(F27*112)+(G27*28)+H27 -> 15805 | L27: =J27/2240 -> 7.0558036
A28: 1704 | B28: Shruff | C28: Barbados | D28: London | F28: 56 | G28: 1 | J28: =(E28*2240)+(F28*112)+(G28*28)+H28 -> 6300 | L28: =J28/2240 -> 2.8125
A29: 1704 | B29: Snuff | C29: Barbados | D29: London | J29: =(E29*2240)+(F29*112)+(G29*28)+H29 -> 0 | L29: =J29/2240 -> 0
A30: 1704 | B30: Succads | C30: Barbados | D30: London | H30: 1288 | J30: =(E30*2240)+(F30*112)+(G30*28)+H30 -> 1288 | L30: =J30/2240 -> 0.575
A31: 1704 | B31: Tobacco | C31: Barbados | D31: London | J31: =(E31*2240)+(F31*112)+(G31*28)+H31 -> 0 | L31: =J31/2240 -> 0
A32: 1704 | B32: Tortoise Shell | C32: Barbados | D32: London | H32: 6 | J32: =(E32*2240)+(F32*112)+(G32*28)+H32 -> 6 | L32: =J32/2240 -> 0.0026785714
A33: 1704 | B33: Turmeric | C33: Barbados | D33: London | H33: 4 | J33: =(E33*2240)+(F33*112)+(G33*28)+H33 -> 4 | L33: =J33/2240 -> 0.0017857143
A34: 1704 | B34: White Sugar | C34: Barbados | D34: London | F34: 756 | H34: 16 | J34: =(E34*2240)+(F34*112)+(G34*28)+H34 -> 84688 | L34: =J34/2240 -> 37.807143
A35: 1704 | B35: Wood, Braziletto | C35: Barbados | D35: London | E35: 27 | F35: 10 | G35: 1 | J35: =(E35*2240)+(F35*112)+(G35*28)+H35 -> 61628 | L35: =J35/2240 -> 27.5125
A36: 1704 | B36: Wood, Fustick | C36: Barbados | D36: London | F36: 335 | G36: 3 | H36: 4 | J36: =(E36*2240)+(F36*112)+(G36*28)+H36 -> 37608 | L36: =J36/2240 -> 16.789286
A37: 1704 | B37: Wood, Logwood | C37: Barbados | D37: London | J37: =(E37*2240)+(F37*112)+(G37*28)+H37 -> 0 | L37: =J37/2240 -> 0
A38: 1704 | B38: Wood, Redwood | C38: Barbados | D38: London | F38: 33 | G38: 1 | H38: 19 | J38: =(E38*2240)+(F38*112)+(G38*28)+H38 -> 3743 | L38: =J38/2240 -> 1.6709821
A39: 1704 | B39: Brown Sugar | C39: Barbados | D39: Out Ports | F39: 12152 | G39: 1 | H39: 22 | J39: =(E39*2240)+(F39*112)+(G39*28)+H39 -> 1361074 | L39: =J39/2240 -> 607.62232
A40: 1704 | B40: Chocolate | C40: Barbados | D40: Out Ports | J40: =(E40*2240)+(F40*112)+(G40*28)+H40 -> 0 | L40: =J40/2240 -> 0
...

Sheet Bermuda
A1: Items | B1: Import Location | C1: ton | D1: hh | E1: quarter | F1: lb | H1: Total Pounds | J1: Total Tons
A2: Indigo | B2: Out Ports | H2: =(C2*2240)+(D2*112)+(E2*28)+F2 -> 0 | J2: =H2/2240 -> 0
A3: Wood, Logwood | B3: Out Ports | H3: =(C3*2240)+(D3*112)+(E3*28)+F3 -> 0 | J3: =H3/2240 -> 0
A4: Shruff | B4: Out Ports | H4: =(C4*2240)+(D4*112)+(E4*28)+F4 -> 0 | J4: =H4/2240 -> 0
A5: Succads | B5: Out Ports | H5: =(C5*2240)+(D5*112)+(E5*28)+F5 -> 0 | J5: =H5/2240 -> 0
A6: Cotton | B6: Out Ports | H6: =(C6*2240)+(D6*112)+(E6*28)+F6 -> 0 | J6: =H6/2240 -> 0
A7: Cocoa Nuts | B7: Out Ports | H7: =(C7*2240)+(D7*112)+(E7*28)+F7 -> 0 | J7: =H7/2240 -> 0

Sheet Jamaica
A1: YEAR | B1: COMMODITY_NAME | C1: FROM_LOCATION | D1: TO_LOCATION | E1: ton | F1: hh | G1: quarter | H1: lb | J1: Total Pounds | L1: WEIGHT
A2: 1704 | B2: Annatto | C2: Jamaica | D2: London | H2: 2348 | J2: =(E2*2240)+(F2*112)+(G2*28)+H2 -> 2348 | L2: =J2/2240 -> 1.0482143
A3: 1704 | B3: Bees Wax | C3: Jamaica | D3: London | J3: =(E3*2240)+(F3*112)+(G3*28)+H3 -> 0 | L3: =J3/2240 -> 0
A4: 1704 | B4: Brown Sugar | C4: Jamaica | D4: London | F4: 69528 | G4: 3 | H4: 5 | J4: =(E4*2240)+(F4*112)+(G4*28)+H4 -> 7787225 | L4: =J4/2240 -> 3476.4397
A5: 1704 | B5: Cascarilla | C5: Jamaica | D5: London | J5: =(E5*2240)+(F5*112)+(G5*28)+H5 -> 0 | L5: =J5/2240 -> 0
A6: 1704 | B6: Cassia Fistula | C6: Jamaica | D6: London | H6: 3240 | J6: =(E6*2240)+(F6*112)+(G6*28)+H6 -> 3240 | L6: =J6/2240 -> 1.4464286
A7: 1704 | B7: Chocolate | C7: Jamaica | D7: London | H7: 183 | J7: =(E7*2240)+(F7*112)+(G7*28)+H7 -> 183 | L7: =J7/2240 -> 0.081696429
A8: 1704 | B8: Cocheneal | C8: Jamaica | D8: London | J8: =(E8*2240)+(F8*112)+(G8*28)+H8 -> 0 | L8: =J8/2240 -> 0
A9: 1704 | B9: Cocoa Nuts | C9: Jamaica | D9: London | F9: 384 | H9: 18 | J9: =(E9*2240)+(F9*112)+(G9*28)+H9 -> 43026 | L9: =J9/2240 -> 19.208036
A10: 1704 | B10: Cocoa Paste | C10: Jamaica | D10: London | J10: =(E10*2240)+(F10*112)+(G10*28)+H10 -> 0 | L10: =J10/2240 -> 0
A11: 1704 | B11: Cocoa Wood | C11: Jamaica | D11: London | J11: =(E11*2240)+(F11*112)+(G11*28)+H11 -> 0 | L11: =J11/2240 -> 0
A12: 1704 | B12: Cortex Winteranus | C12: Jamaica | D12: London | H12: 2000 | J12: =(E12*2240)+(F12*112)+(G12*28)+H12 -> 2000 | L12: =J12/2240 -> 0.89285714
A13: 1704 | B13: Cotton | C13: Jamaica | D13: London | H13: =599.5*200 -> 119900 | I13: 599.5 bags | J13: =(E13*2240)+(F13*112)+(G13*28)+H13 -> 119900 | L13: =J13/2240 -> 53.526786
A14: 1704 | B14: Dry Ginger | C14: Jamaica | D14: London | F14: 12832 | H14: 15 | J14: =(E14*2240)+(F14*112)+(G14*28)+H14 -> 1437199 | L14: =J14/2240 -> 641.6067
A15: 1704 | B15: Elephant Teeth | C15: Jamaica | D15: London | F15: 127 | H15: 13 | J15: =(E15*2240)+(F15*112)+(G15*28)+H15 -> 14237 | L15: =J15/2240 -> 6.3558036
A16: 1704 | B16: Green Ginger | C16: Jamaica | D16: London | H16: 43 | J16: =(E16*2240)+(F16*112)+(G16*28)+H16 -> 43 | L16: =J16/2240 -> 0.019196429
A17: 1704 | B17: Indigo | C17: Jamaica | D17: London | H17: 111586 | J17: =(E17*2240)+(F17*112)+(G17*28)+H17 -> 111586 | L17: =J17/2240 -> 49.815179
A18: 1704 | B18: Jamaica Roots | C18: Jamaica | D18: London | J18: =(E18*2240)+(F18*112)+(G18*28)+H18 -> 0 | L18: =J18/2240 -> 0
A19: 1704 | B19: Lignum Vitae | C19: Jamaica | D19: London | E19: 1 | F19: 15 | J19: =(E19*2240)+(F19*112)+(G19*28)+H19 -> 3920 | L19: =J19/2240 -> 1.75
A20: 1704 | B20: Lime Juice | C20: Jamaica | D20: London | H20: 31519 | I20: 3123g | J20: =(E20*2240)+(F20*112)+(G20*28)+H20 -> 31519 | L20: =J20/2240 -> 14.070982
A21: 1704 | B21: Madera Wine | C21: Jamaica | D21: London | J21: =(E21*2240)+(F21*112)+(G21*28)+H21 -> 0 | L21: =J21/2240 -> 0
A22: 1704 | B22: Molasses | C22: Jamaica | D22: London | J22: =(E22*2240)+(F22*112)+(G22*28)+H22 -> 0 | L22: =J22/2240 -> 0
A23: 1704 | B23: Pimento | C23: Jamaica | D23: London | H23: 48329 | J23: =(E23*2240)+(F23*112)+(G23*28)+H23 -> 48329 | L23: =J23/2240 -> 21.575446
A24: 1704 | B24: Rice | C24: Jamaica | D24: London | J24: =(E24*2240)+(F24*112)+(G24*28)+H24 -> 0 | L24: =J24/2240 -> 0
A25: 1704 | B25: Rum | C25: Jamaica | D25: London | H25: 3452 | I25: 342g | J25: =(E25*2240)+(F25*112)+(G25*28)+H25 -> 3452 | L25: =J25/2240 -> 1.5410714
A26: 1704 | B26: Sasparilla | C26: Jamaica | D26: London | J26: =(E26*2240)+(F26*112)+(G26*28)+H26 -> 0 | L26: =J26/2240 -> 0
A27: 1704 | B27: Shruff | C27: Jamaica | D27: London | F27: 10 | G27: 2 | H27: 14 | J27: =(E27*2240)+(F27*112)+(G27*28)+H27 -> 1190 | L27: =J27/2240 -> 0.53125
A28: 1704 | B28: Snuff | C28: Jamaica | D28: London | J28: =(E28*2240)+(F28*112)+(G28*28)+H28 -> 0 | L28: =J28/2240 -> 0
A29: 1704 | B29: Spanish Wine | C29: Jamaica | D29: London | H29: 1151 | I29: 114g | J29: =(E29*2240)+(F29*112)+(G29*28)+H29 -> 1151 | L29: =J29/2240 -> 0.51383929
A30: 1704 | B30: Succads | C30: Jamaica | D30: London | H30: 538 | J30: =(E30*2240)+(F30*112)+(G30*28)+H30 -> 538 | L30: =J30/2240 -> 0.24017857
A31: 1704 | B31: Sugar Loaf | C31: Jamaica | D31: London | J31: =(E31*2240)+(F31*112)+(G31*28)+H31 -> 0 | L31: =J31/2240 -> 0
A32: 1704 | B32: Tobacco | C32: Jamaica | D32: London | H32: 53690 | J32: =(E32*2240)+(F32*112)+(G32*28)+H32 -> 53690 | L32: =J32/2240 -> 23.96875
A33: 1704 | B33: Tortoise Shell | C33: Jamaica | D33: London | H33: 1460 | J33: =(E33*2240)+(F33*112)+(G33*28)+H33 -> 1460 | L33: =J33/2240 -> 0.65178571
A34: 1704 | B34: White Sugar | C34: Jamaica | D34: London | F34: 65 | G34: 2 | H34: 19 | J34: =(E34*2240)+(F34*112)+(G34*28)+H34 -> 7355 | L34: =J34/2240 -> 3.2834821
A35: 1704 | B35: Wood, Braziletto | C35: Jamaica | D35: London | F35: 16 | G35: 1 | J35: =(E35*2240)+(F35*112)+(G35*28)+H35 -> 1820 | L35: =J35/2240 -> 0.8125
A36: 1704 | B36: Wood, Fustick | C36: Jamaica | D36: London | E36: 161 | F36: 2 | G36: 2 | J36: =(E36*2240)+(F36*112)+(G36*28)+H36 -> 360920 | L36: =J36/2240 -> 161.125
A37: 1704 | B37: Wood, Logwood | C37: Jamaica | D37: London | E37: 307 | F37: 8 | G37: 3 | H37: 24 | J37: =(E37*2240)+(F37*112)+(G37*28)+H37 -> 688684 | L37: =J37/2240 -> 307.44821
A38: 1704 | B38: Wood, Nicaragua | C38: Jamaica | D38: London | E38: 17 | F38: 13 | J38: =(E38*2240)+(F38*112)+(G38*28)+H38 -> 39536 | L38: =J38/2240 -> 17.65
A39: 1704 | B39: Wood, Redwood | C39: Jamaica | D39: London | F39: 70 | J39: =(E39*2240)+(F39*112)+(G39*28)+H39 -> 7840 | L39: =J39/2240 -> 3.5
A40: 1704 | B40: Wool Vigonia | C40: Jamaica | D40: London | J40: =(E40*2240)+(F40*112)+(G40*28)+H40 -> 0 | L40: =J40/2240 -> 0
...

Sheet Mountserat
A1: YEAR | B1: COMMODITY_NAME | C1: FROM_LOCATION | D1: TO_LOCATION | E1: ton | F1: hh | G1: quarter | H1: lb | J1: Total Pounds | L1: WEIGHT | O1: Total Not Sugar | Q1: Total Sugar
A2: 1704 | B2: Brown Sugar | C2: Mountserat | D2: London | F2: 7875 | G2: 3 | H2: 14 | J2: =(E2*2240)+(F2*112)+(G2*28)+H2 -> 882098 | L2: =J2/2240 -> 393.79375
A3: 1704 | B3: Chocolate | C3: Mountserat | D3: London | J3: =(E3*2240)+(F3*112)+(G3*28)+H3 -> 0 | L3: =J3/2240 -> 0
A4: 1704 | B4: Cocoa Nuts | C4: Mountserat | D4: London | J4: =(E4*2240)+(F4*112)+(G4*28)+H4 -> 0 | L4: =J4/2240 -> 0
A5: 1704 | B5: Cortex Winteranus | C5: Mountserat | D5: London | J5: =(E5*2240)+(F5*112)+(G5*28)+H5 -> 0 | L5: =J5/2240 -> 0
A6: 1704 | B6: Cotton | C6: Mountserat | D6: London | H6: =16.5*200 -> 3300 | I6: 16.5bags | J6: =(E6*2240)+(F6*112)+(G6*28)+H6 -> 3300 | L6: =J6/2240 -> 1.4732143
A7: 1704 | B7: Dry Ginger | C7: Mountserat | D7: London | J7: =(E7*2240)+(F7*112)+(G7*28)+H7 -> 0 | L7: =J7/2240 -> 0
A8: 1704 | B8: Elephants Teeth | C8: Mountserat | D8: London | J8: =(E8*2240)+(F8*112)+(G8*28)+H8 -> 0 | L8: =J8/2240 -> 0 | O8: =L8+L13+L14+L20+L22+L24+L26+L27+L6+L15+L19+L17 -> 420.58036 | Q8: =L11+L25+L10 -> 0.64732143
A9: 1704 | B9: Indigo | C9: Mountserat | D9: London | H9: 7337 | J9: =(E9*2240)+(F9*112)+(G9*28)+H9 -> 7337 | L9: =J9/2240 -> 3.2754464
A10: 1704 | B10: Lignum Vitae | C10: Mountserat | D10: London | J10: =(E10*2240)+(F10*112)+(G10*28)+H10 -> 0 | L10: =J10/2240 -> 0
A11: 1704 | B11: Lime Juice | C11: Mountserat | D11: London | H11: 474 | I11: 47g | J11: =(E11*2240)+(F11*112)+(G11*28)+H11 -> 474 | L11: =J11/2240 -> 0.21160714
A12: 1704 | B12: Madera Wine | C12: Mountserat | D12: London | J12: =(E12*2240)+(F12*112)+(G12*28)+H12 -> 0 | L12: =J12/2240 -> 0
A13: 1704 | B13: Molasses | C13: Mountserat | D13: London | J13: =(E13*2240)+(F13*112)+(G13*28)+H13 -> 0 | L13: =J13/2240 -> 0
A14: 1704 | B14: Pimento | C14: Mountserat | D14: London | H14: 1684 | J14: =(E14*2240)+(F14*112)+(G14*28)+H14 -> 1684 | L14: =J14/2240 -> 0.75178571
A15: 1704 | B15: Rum | C15: Mountserat | D15: London | J15: =(E15*2240)+(F15*112)+(G15*28)+H15 -> 0 | L15: =J15/2240 -> 0
A16: 1704 | B16: Shruff | C16: Mountserat | D16: London | J16: =(E16*2240)+(F16*112)+(G16*28)+H16 -> 0 | L16: =J16/2240 -> 0
A17: 1704 | B17: Succads | C17: Mountserat | D17: London | J17: =(E17*2240)+(F17*112)+(G17*28)+H17 -> 0 | L17: =J17/2240 -> 0
A18: 1704 | B18: Tortoise Shell | C18: Mountserat | D18: London | J18: =(E18*2240)+(F18*112)+(G18*28)+H18 -> 0 | L18: =J18/2240 -> 0
A19: 1704 | B19: White Sugar | C19: Mountserat | D19: London | J19: =(E19*2240)+(F19*112)+(G19*28)+H19 -> 0 | L19: =J19/2240 -> 0
A20: 1704 | B20: Brown Sugar | C20: Mountserat | D20: Out Ports | F20: 8299 | G20: 3 | H20: 14 | J20: =(E20*2240)+(F20*112)+(G20*28)+H20 -> 929586 | L20: =J20/2240 -> 414.99375
A21: 1704 | B21: Cocoa | C21: Mountserat | D21: Out Ports | J21: =(E21*2240)+(F21*112)+(G21*28)+H21 -> 0 | L21: =J21/2240 -> 0
A22: 1704 | B22: Cocoa Nuts | C22: Mountserat | D22: Out Ports | F22: 16 | G22: 2 | H22: 18 | J22: =(E22*2240)+(F22*112)+(G22*28)+H22 -> 1866 | L22: =J22/2240 -> 0.83303571
A23: 1704 | B23: Cotton | C23: Mountserat | D23: Out Ports | F23: 26 | G23: 3 | H23: 8 | J23: =(E23*2240)+(F23*112)+(G23*28)+H23 -> 3004 | L23: =J23/2240 -> 1.3410714
A24: 1704 | B24: Dry Ginger | C24: Mountserat | D24: Out Ports | J24: =(E24*2240)+(F24*112)+(G24*28)+H24 -> 0 | L24: =J24/2240 -> 0
A25: 1704 | B25: Elephants Teeth | C25: Mountserat | D25: Out Ports | F25: 8 | G25: 2 | H25: 24 | J25: =(E25*2240)+(F25*112)+(G25*28)+H25 -> 976 | L25: =J25/2240 -> 0.43571429
A26: 1704 | B26: Indigo | C26: Mountserat | D26: Out Ports | H26: 4190 | J26: =(E26*2240)+(F26*112)+(G26*28)+H26 -> 4190 | L26: =J26/2240 -> 1.8705357
A27: 1704 | B27: Lime Juice | C27: Mountserat | D27: Out Ports | H27: 1474 | I27: 146g | J27: =(E27*2240)+(F27*112)+(G27*28)+H27 -> 1474 | L27: =J27/2240 -> 0.65803571
A28: 1704 | B28: Pimento | C28: Mountserat | D28: Out Ports | H28: 4932 | J28: =(E28*2240)+(F28*112)+(G28*28)+H28 -> 4932 | L28: =J28/2240 -> 2.2017857
A29: 1704 | B29: Rum | C29: Mountserat | D29: Out Ports | H29: 706 | I29: 70g | J29: =(E29*2240)+(F29*112)+(G29*28)+H29 -> 706 | L29: =J29/2240 -> 0.31517857

Sheet Nevis
A1: YEAR | B1: COMMODITY_NAME | C1: FROM_LOCATION | D1: TO_LOCATION | E1: ton | F1: hh | G1: quarter | H1: lb | J1: Total Pounds | L1: WEIGHT
A2: 1704 | B2: Brown Sugar | C2: Nevis | D2: London | F2: 33514 | G2: 1 | H2: 7 | J2: =(E2*2240)+(F2*112)+(G2*28)+(H2) -> 3753603 | L2: =J2/2240 -> 1675.7156
A3: 1704 | B3: Chocolate | C3: Nevis | D3: London | J3: =(E3*2240)+(F3*112)+(G3*28)+(H3) -> 0 | L3: =J3/2240 -> 0
A4: 1704 | B4: Cocoa Nuts | C4: Nevis | D4: London | F4: 65 | G4: 2 | H4: 19 | J4: =(E4*2240)+(F4*112)+(G4*28)+(H4) -> 7355 | L4: =J4/2240 -> 3.2834821
A5: 1704 | B5: Cortex Winteranus | C5: Nevis | D5: London | J5: =(E5*2240)+(F5*112)+(G5*28)+(H5) -> 0 | L5: =J5/2240 -> 0
A6: 1704 | B6: Cotton | C6: Nevis | D6: London | H6: =357*200 -> 71400 | I6: 357bags | J6: =(E6*2240)+(F6*112)+(G6*28)+(H6) -> 71400 | L6: =J6/2240 -> 31.875
A7: 1704 | B7: Dry Ginger | C7: Nevis | D7: London | F7: 10 | J7: =(E7*2240)+(F7*112)+(G7*28)+(H7) -> 1120 | L7: =J7/2240 -> 0.5
A8: 1704 | B8: Elephant Teeth | C8: Nevis | D8: London | J8: =(E8*2240)+(F8*112)+(G8*28)+(H8) -> 0 | L8: =J8/2240 -> 0
A9: 1704 | B9: Indigo | C9: Nevis | D9: London | H9: 1034 | J9: =(E9*2240)+(F9*112)+(G9*28)+(H9) -> 1034 | L9: =J9/2240 -> 0.46160714
A10: 1704 | B10: Lignum Vitae | C10: Nevis | D10: London | J10: =(E10*2240)+(F10*112)+(G10*28)+(H10) -> 0 | L10: =J10/2240 -> 0
A11: 1704 | B11: Lime Juice | C11: Nevis | D11: London | H11: 2119 | I11: 210g | J11: =(E11*2240)+(F11*112)+(G11*28)+(H11) -> 2119 | L11: =J11/2240 -> 0.94598214
A12: 1704 | B12: Madera Wine | C12: Nevis | D12: London | J12: =(E12*2240)+(F12*112)+(G12*28)+(H12) -> 0 | L12: =J12/2240 -> 0
A13: 1704 | B13: Molasses | C13: Nevis | D13: London | F13: 2 | G13: 1 | J13: =(E13*2240)+(F13*112)+(G13*28)+(H13) -> 252 | L13: =J13/2240 -> 0.1125
A14: 1704 | B14: Pickles | C14: Nevis | D14: London | J14: =(E14*2240)+(F14*112)+(G14*28)+(H14) -> 0 | L14: =J14/2240 -> 0
A15: 1704 | B15: Pimento | C15: Nevis | D15: London | H15: 271 | J15: =(E15*2240)+(F15*112)+(G15*28)+(H15) -> 271 | L15: =J15/2240 -> 0.12098214
A16: 1704 | B16: Rum | C16: Nevis | D16: London | H16: 1130 | I16: 112g | J16: =(E16*2240)+(F16*112)+(G16*28)+(H16) -> 1130 | L16: =J16/2240 -> 0.50446429
A17: 1704 | B17: Sasparilla | C17: Nevis | D17: London | H17: 44 | J17: =(E17*2240)+(F17*112)+(G17*28)+(H17) -> 44 | L17: =J17/2240 -> 0.019642857
A18: 1704 | B18: Shruff | C18: Nevis | D18: London | J18: =(E18*2240)+(F18*112)+(G18*28)+(H18) -> 0 | L18: =J18/2240 -> 0
A19: 1704 | B19: Succads | C19: Nevis | D19: London | J19: =(E19*2240)+(F19*112)+(G19*28)+(H19) -> 0 | L19: =J19/2240 -> 0
A20: 1704 | B20: Sugar Loaf | C20: Nevis | D20: London | J20: =(E20*2240)+(F20*112)+(G20*28)+(H20) -> 0 | L20: =J20/2240 -> 0
A21: 1704 | B21: Tobacco | C21: Nevis | D21: London | H21: 2207 | J21: =(E21*2240)+(F21*112)+(G21*28)+(H21) -> 2207 | L21: =J21/2240 -> 0.98526786
A22: 1704 | B22: Tortoise Shell | C22: Nevis | D22: London | J22: =(E22*2240)+(F22*112)+(G22*28)+(H22) -> 0 | L22: =J22/2240 -> 0
A23: 1704 | B23: Tortoise Shell | C23: Nevis | D23: London | J23: =(E23*2240)+(F23*112)+(G23*28)+(H23) -> 0 | L23: =J23/2240 -> 0
A24: 1704 | B24: White Sugar | C24: Nevis | D24: London | F24: 3 | G24: 1 | H24: 21 | J24: =(E24*2240)+(F24*112)+(G24*28)+(H24) -> 385 | L24: =J24/2240 -> 0.171875
A25: 1704 | B25: Brown Sugar | C25: Nevis | D25: Out Ports | F25: 15782 | G25: 3 | H25: 2 | J25: =(E25*2240)+(F25*112)+(G25*28)+(H25) -> 1767670 | L25: =J25/2240 -> 789.13839
A26: 1704 | B26: Cocoa Nuts | C26: Nevis | D26: Out Ports | F26: 20 | G26: 1 | H26: 4 | J26: =(E26*2240)+(F26*112)+(G26*28)+(H26) -> 2272 | L26: =J26/2240 -> 1.0142857
A27: 1704 | B27: Cotton | C27: Nevis | D27: Out Ports | F27: 65 | H27: 14 | J27: =(E27*2240)+(F27*112)+(G27*28)+(H27) -> 7294 | L27: =J27/2240 -> 3.25625
A28: 1704 | B28: Elephant Teeth | C28: Nevis | D28: Out Ports | J28: =(E28*2240)+(F28*112)+(G28*28)+(H28) -> 0 | L28: =J28/2240 -> 0
A29: 1704 | B29: Indigo | C29: Nevis | D29: Out Ports | H29: 626 | J29: =(E29*2240)+(F29*112)+(G29*28)+(H29) -> 626 | L29: =J29/2240 -> 0.27946429
A30: 1704 | B30: Lignum Vitae | C30: Nevis | D30: Out Ports | F30: 47 | H30: 3 | J30: =(E30*2240)+(F30*112)+(G30*28)+(H30) -> 5267 | L30: =J30/2240 -> 2.3513393
A31: 1704 | B31: Lime Juice | C31: Nevis | D31: Out Ports | H31: 959 | I31: 95g | J31: =(E31*2240)+(F31*112)+(G31*28)+(H31) -> 959 | L31: =J31/2240 -> 0.428125
A32: 1704 | B32: Molasses | C32: Nevis | D32: Out Ports | J32: =(E32*2240)+(F32*112)+(G32*28)+(H32) -> 0 | L32: =J32/2240 -> 0
A33: 1704 | B33: Rum | C33: Nevis | D33: Out Ports | J33: =(E33*2240)+(F33*112)+(G33*28)+(H33) -> 0 | L33: =J33/2240 -> 0
A34: 1704 | B34: Shruff | C34: Nevis | D34: Out Ports | F34: 4 | G34: 2 | H34: 24 | J34: =(E34*2240)+(F34*112)+(G34*28)+(H34) -> 528 | L34: =J34/2240 -> 0.23571429
A35: 1704 | B35: Succand | C35: Nevis | D35: Out Ports | H35: 12 | J35: =(E35*2240)+(F35*112)+(G35*28)+(H35) -> 12 | L35: =J35/2240 -> 0.0053571429
A36: 1704 | B36: Tortoise Shell | C36: Nevis | D36: Out Ports | J36: =(E36*2240)+(F36*112)+(G36*28)+(H36) -> 0 | L36: =J36/2240 -> 0
A37: 1704 | B37: White Sugar | C37: Nevis | D37: Out Ports | F37: 2 | G37: 1 | H37: 9 | J37: =(E37*2240)+(F37*112)+(G37*28)+(H37) -> 261 | L37: =J37/2240 -> 0.11651786

Sheet St Kitts
A1: YEAR | B1: COMMODITY_NAME | C1: FROM_LOCATION | D1: TO_LOCATION | E1: ton | F1: hh | G1: quarter | H1: lb | J1: Total Pounds | L1: WEIGHT
A2: 1704 | B2: Annatto | C2: StKitts | D2: London | J2: =(E2*2240)+(F2*112)+(G2*28)+(H2/16) -> 0 | L2: =J2/2240 -> 0
A3: 1704 | B3: Bees Wax | C3: StKitts | D3: London | J3: =(E3*2240)+(F3*112)+(G3*28)+(H3/16) -> 0 | L3: =J3/2240 -> 0
A4: 1704 | B4: Brown Sugar | C4: StKitts | D4: London | F4: 1428 | G4: 1 | J4: =(E4*2240)+(F4*112)+(G4*28)+(H4/16) -> 159964 | L4: =J4/2240 -> 71.4125
A5: 1704 | B5: Cocoa Nuts | C5: StKitts | D5: London | J5: =(E5*2240)+(F5*112)+(G5*28)+(H5/16) -> 0 | L5: =J5/2240 -> 0
A6: 1704 | B6: Cotton | C6: StKitts | D6: London | H6: =7*200 -> 1400 | I6: 7 bags | J6: =(E6*2240)+(F6*112)+(G6*28)+(H6/16) -> 87.5 | L6: =J6/2240 -> 0.0390625
A7: 1704 | B7: Dry Ginger | C7: StKitts | D7: London | J7: =(E7*2240)+(F7*112)+(G7*28)+(H7/16) -> 0 | L7: =J7/2240 -> 0
A8: 1704 | B8: Elephant Teeth | C8: StKitts | D8: London | J8: =(E8*2240)+(F8*112)+(G8*28)+(H8/16) -> 0 | L8: =J8/2240 -> 0
A9: 1704 | B9: Indigo | C9: StKitts | D9: London | J9: =(E9*2240)+(F9*112)+(G9*28)+(H9/16) -> 0 | L9: =J9/2240 -> 0
A10: 1704 | B10: Lignum Vitae | C10: StKitts | D10: London | J10: =(E10*2240)+(F10*112)+(G10*28)+(H10/16) -> 0 | L10: =J10/2240 -> 0
A11: 1704 | B11: Molasses | C11: StKitts | D11: London | F11: 2 | G11: 2 | J11: =(E11*2240)+(F11*112)+(G11*28)+(H11/16) -> 280 | L11: =J11/2240 -> 0.125
A12: 1704 | B12: Pimento | C12: StKitts | D12: London | J12: =(E12*2240)+(F12*112)+(G12*28)+(H12/16) -> 0 | L12: =J12/2240 -> 0
A13: 1704 | B13: Rum | C13: StKitts | D13: London | J13: =(E13*2240)+(F13*112)+(G13*28)+(H13/16) -> 0 | L13: =J13/2240 -> 0
A14: 1704 | B14: Shruff | C14: StKitts | D14: London | J14: =(E14*2240)+(F14*112)+(G14*28)+(H14/16) -> 0 | L14: =J14/2240 -> 0
A15: 1704 | B15: Succads | C15: StKitts | D15: London | J15: =(E15*2240)+(F15*112)+(G15*28)+(H15/16) -> 0 | L15: =J15/2240 -> 0
A16: 1704 | B16: Wood, Logwood | C16: StKitts | D16: London | J16: =(E16*2240)+(F16*112)+(G16*28)+(H16/16) -> 0 | L16: =J16/2240 -> 0
A17: 1704 | B17: Brown Sugar | C17: StKitts | D17: Out Ports | F17: 2201 | G17: 3 | H17: 20 | J17: =(E17*2240)+(F17*112)+(G17*28)+(H17/16) -> 246597.25 | L17: =J17/2240 -> 110.08806
A18: 1704 | B18: Cotton | C18: StKitts | D18: Out Ports | F18: 16 | H18: 8 | J18: =(E18*2240)+(F18*112)+(G18*28)+(H18/16) -> 1792.5 | L18: =J18/2240 -> 0.80022321
A19: 1704 | B19: Indigo | C19: StKitts | D19: Out Ports | H19: 48 | J19: =(E19*2240)+(F19*112)+(G19*28)+(H19/16) -> 3 | L19: =J19/2240 -> 0.0013392857
