Workbook

Sheet Master Goods Sheet
A1: Item | B1: Total London | C1: Total Outports | D1: Total
A2: Annatto | B2: =SUMIFS(Antigua!$L:$L, Antigua!$B:$B, $A2, Antigua!$D:$D, "London") + SUMIFS(Barbados!$L:$L, Barbados!$B:$B, $A2, Barbados!$D:$D, "London") + SUMIFS(Bermuda!$L:$L, Bermuda!$B:$B, $A2, Bermuda!$D:$D, "London") + SUMIFS(Jamaica!$L:$L, Jamaica!$B:$B, $A2, Jamaica!$D:$D, "London") + SUMIFS(Mountserat!$L:$L, Mountserat!$B:$B, $A2, Mountserat!$D:$D, "London") + SUMIFS(Nevis!$L:$L, Nevis!$B:$B, $A2, Nevis!$D:$D, "London") + SUMIFS('St Kitts'!$L:$L, 'St Kitts'!$B:$B, $A2, 'St Kitts'!$D:$D, "London") -> 0.011160714 | C2: =SUMIFS(Antigua!$L:$L, Antigua!$B:$B, $A2, Antigua!$D:$D, "Out Ports") + SUMIFS(Barbados!$L:$L, Barbados!$B:$B, $A2, Barbados!$D:$D, "Out Ports") + SUMIFS(Bermuda!$L:$L, Bermuda!$B:$B, $A2, Bermuda!$D:$D, "Out Ports") + SUMIFS(Jamaica!$L:$L, Jamaica!$B:$B, $A2, Jamaica!$D:$D, "Out Ports") + SUMIFS(Mountserat!$L:$L, Mountserat!$B:$B, $A2, Mountserat!$D:$D, "Out Ports") + SUMIFS(Nevis!$L:$L, Nevis!$B:$B, $A2, Nevis!$D:$D, "Out Ports") + SUMIFS('St Kitts'!$L:$L, 'St Kitts'!$B:$B, $A2, 'St Kitts'!$D:$D, "Out Ports") -> 0 | D2: =ROUND((B2+C2),2) -> 0.01
A3: Bees Wax | B3: =SUMIFS(Antigua!$L:$L, Antigua!$B:$B, $A3, Antigua!$D:$D, "London") + SUMIFS(Barbados!$L:$L, Barbados!$B:$B, $A3, Barbados!$D:$D, "London") + SUMIFS(Bermuda!$L:$L, Bermuda!$B:$B, $A3, Bermuda!$D:$D, "London") + SUMIFS(Jamaica!$L:$L, Jamaica!$B:$B, $A3, Jamaica!$D:$D, "London") + SUMIFS(Mountserat!$L:$L, Mountserat!$B:$B, $A3, Mountserat!$D:$D, "London") + SUMIFS(Nevis!$L:$L, Nevis!$B:$B, $A3, Nevis!$D:$D, "London") + SUMIFS('St Kitts'!$L:$L, 'St Kitts'!$B:$B, $A3, 'St Kitts'!$D:$D, "London") -> 0 | C3: =SUMIFS(Antigua!$L:$L, Antigua!$B:$B, $A3, Antigua!$D:$D, "Out Ports") + SUMIFS(Barbados!$L:$L, Barbados!$B:$B, $A3, Barbados!$D:$D, "Out Ports") + SUMIFS(Bermuda!$L:$L, Bermuda!$B:$B, $A3, Bermuda!$D:$D, "Out Ports") + SUMIFS(Jamaica!$L:$L, Jamaica!$B:$B, $A3, Jamaica!$D:$D, "Out Ports") + SUMIFS(Mountserat!$L:$L, Mountserat!$B:$B, $A3, Mountserat!$D:$D, "Out Ports") + SUMIFS(Nevis!$L:$L, Nevis!$B:$B, $A3, Nevis!$D:$D, "Out Ports") + SUMIFS('St Kitts'!$L:$L, 'St Kitts'!$B:$B, $A3, 'St Kitts'!$D:$D, "Out Ports") -> 0 | D3: =ROUND((B3+C3),2) -> 0
A4: Brandy | B4: =SUMIFS(Antigua!$L:$L, Antigua!$B:$B, $A4, Antigua!$D:$D, "London") + SUMIFS(Barbados!$L:$L, Barbados!$B:$B, $A4, Barbados!$D:$D, "London") + SUMIFS(Bermuda!$L:$L, Bermuda!$B:$B, $A4, Bermuda!$D:$D, "London") + SUMIFS(Jamaica!$L:$L, Jamaica!$B:$B, $A4, Jamaica!$D:$D, "London") + SUMIFS(Mountserat!$L:$L, Mountserat!$B:$B, $A4, Mountserat!$D:$D, "London") + SUMIFS(Nevis!$L:$L, Nevis!$B:$B, $A4, Nevis!$D:$D, "London") + SUMIFS('St Kitts'!$L:$L, 'St Kitts'!$B:$B, $A4, 'St Kitts'!$D:$D, "London") -> 0 | C4: =SUMIFS(Antigua!$L:$L, Antigua!$B:$B, $A4, Antigua!$D:$D, "Out Ports") + SUMIFS(Barbados!$L:$L, Barbados!$B:$B, $A4, Barbados!$D:$D, "Out Ports") + SUMIFS(Bermuda!$L:$L, Bermuda!$B:$B, $A4, Bermuda!$D:$D, "Out Ports") + SUMIFS(Jamaica!$L:$L, Jamaica!$B:$B, $A4, Jamaica!$D:$D, "Out Ports") + SUMIFS(Mountserat!$L:$L, Mountserat!$B:$B, $A4, Mountserat!$D:$D, "Out Ports") + SUMIFS(Nevis!$L:$L, Nevis!$B:$B, $A4, Nevis!$D:$D, "Out Ports") + SUMIFS('St Kitts'!$L:$L, 'St Kitts'!$B:$B, $A4, 'St Kitts'!$D:$D, "Out Ports") -> 0 | D4: =ROUND((B4+C4),2) -> 0
A5: Brown Sugar | B5: =SUMIFS(Antigua!$L:$L, Antigua!$B:$B, $A5, Antigua!$D:$D, "London") + SUMIFS(Barbados!$L:$L, Barbados!$B:$B, $A5, Barbados!$D:$D, "London") + SUMIFS(Bermuda!$L:$L, Bermuda!$B:$B, $A5, Bermuda!$D:$D, "London") + SUMIFS(Jamaica!$L:$L, Jamaica!$B:$B, $A5, Jamaica!$D:$D, "London") + SUMIFS(Mountserat!$L:$L, Mountserat!$B:$B, $A5, Mountserat!$D:$D, "London") + SUMIFS(Nevis!$L:$L, Nevis!$B:$B, $A5, Nevis!$D:$D, "London") + SUMIFS('St Kitts'!$L:$L, 'St Kitts'!$B:$B, $A5, 'St Kitts'!$D:$D, "London") -> 12738.61 | C5: =SUMIFS(Antigua!$L:$L, Antigua!$B:$B, $A5, Antigua!$D:$D, "Out Ports") + SUMIFS(Barbados!$L:$L, Barbados!$B:$B, $A5, Barbados!$D:$D, "Out Ports") + SUMIFS(Bermuda!$L:$L, Bermuda!$B:$B, $A5, Bermuda!$D:$D, "Out Ports") + SUMIFS(Jamaica!$L:$L, Jamaica!$B:$B, $A5, Jamaica!$D:$D, "Out Ports") + SUMIFS(Mountserat!$L:$L, Mountserat!$B:$B, $A5, Mountserat!$D:$D, "Out Ports") + SUMIFS(Nevis!$L:$L, Nevis!$B:$B, $A5, Nevis!$D:$D, "Out Ports") + SUMIFS('St Kitts'!$L:$L, 'St Kitts'!$B:$B, $A5, 'St Kitts'!$D:$D, "Out Ports") -> 3343.1701 | D5: =ROUND((B5+C5),2) -> 16081.78
A6: Chocolate | B6: =SUMIFS(Antigua!$L:$L, Antigua!$B:$B, $A6, Antigua!$D:$D, "London") + SUMIFS(Barbados!$L:$L, Barbados!$B:$B, $A6, Barbados!$D:$D, "London") + SUMIFS(Bermuda!$L:$L, Bermuda!$B:$B, $A6, Bermuda!$D:$D, "London") + SUMIFS(Jamaica!$L:$L, Jamaica!$B:$B, $A6, Jamaica!$D:$D, "London") + SUMIFS(Mountserat!$L:$L, Mountserat!$B:$B, $A6, Mountserat!$D:$D, "London") + SUMIFS(Nevis!$L:$L, Nevis!$B:$B, $A6, Nevis!$D:$D, "London") + SUMIFS('St Kitts'!$L:$L, 'St Kitts'!$B:$B, $A6, 'St Kitts'!$D:$D, "London") -> 0.025892857 | C6: =SUMIFS(Antigua!$L:$L, Antigua!$B:$B, $A6, Antigua!$D:$D, "Out Ports") + SUMIFS(Barbados!$L:$L, Barbados!$B:$B, $A6, Barbados!$D:$D, "Out Ports") + SUMIFS(Bermuda!$L:$L, Bermuda!$B:$B, $A6, Bermuda!$D:$D, "Out Ports") + SUMIFS(Jamaica!$L:$L, Jamaica!$B:$B, $A6, Jamaica!$D:$D, "Out Ports") + SUMIFS(Mountserat!$L:$L, Mountserat!$B:$B, $A6, Mountserat!$D:$D, "Out Ports") + SUMIFS(Nevis!$L:$L, Nevis!$B:$B, $A6, Nevis!$D:$D, "Out Ports") + SUMIFS('St Kitts'!$L:$L, 'St Kitts'!$B:$B, $A6, 'St Kitts'!$D:$D, "Out Ports") -> 0.0071428571 | D6: =ROUND((B6+C6),2) -> 0.03
A7: Cocoa Nuts | B7: =SUMIFS(Antigua!$L:$L, Antigua!$B:$B, $A7, Antigua!$D:$D, "London") + SUMIFS(Barbados!$L:$L, Barbados!$B:$B, $A7, Barbados!$D:$D, "London") + SUMIFS(Bermuda!$L:$L, Bermuda!$B:$B, $A7, Bermuda!$D:$D, "London") + SUMIFS(Jamaica!$L:$L, Jamaica!$B:$B, $A7, Jamaica!$D:$D, "London") + SUMIFS(Mountserat!$L:$L, Mountserat!$B:$B, $A7, Mountserat!$D:$D, "London") + SUMIFS(Nevis!$L:$L, Nevis!$B:$B, $A7, Nevis!$D:$D, "London") + SUMIFS('St Kitts'!$L:$L, 'St Kitts'!$B:$B, $A7, 'St Kitts'!$D:$D, "London") -> 4.8823661 | C7: =SUMIFS(Antigua!$L:$L, Antigua!$B:$B, $A7, Antigua!$D:$D, "Out Ports") + SUMIFS(Barbados!$L:$L, Barbados!$B:$B, $A7, Barbados!$D:$D, "Out Ports") + SUMIFS(Bermuda!$L:$L, Bermuda!$B:$B, $A7, Bermuda!$D:$D, "Out Ports") + SUMIFS(Jamaica!$L:$L, Jamaica!$B:$B, $A7, Jamaica!$D:$D, "Out Ports") + SUMIFS(Mountserat!$L:$L, Mountserat!$B:$B, $A7, Mountserat!$D:$D, "Out Ports") + SUMIFS(Nevis!$L:$L, Nevis!$B:$B, $A7, Nevis!$D:$D, "Out Ports") + SUMIFS('St Kitts'!$L:$L, 'St Kitts'!$B:$B, $A7, 'St Kitts'!$D:$D, "Out Ports") -> 2.5421317 | D7: =ROUND((B7+C7),2) -> 7.42
A8: Cotton | B8: =SUMIFS(Antigua!$L:$L, Antigua!$B:$B, $A8, Antigua!$D:$D, "London") + SUMIFS(Barbados!$L:$L, Barbados!$B:$B, $A8, Barbados!$D:$D, "London") + SUMIFS(Bermuda!$L:$L, Bermuda!$B:$B, $A8, Bermuda!$D:$D, "London") + SUMIFS(Jamaica!$L:$L, Jamaica!$B:$B, $A8, Jamaica!$D:$D, "London") + SUMIFS(Mountserat!$L:$L, Mountserat!$B:$B, $A8, Mountserat!$D:$D, "London") + SUMIFS(Nevis!$L:$L, Nevis!$B:$B, $A8, Nevis!$D:$D, "London") + SUMIFS('St Kitts'!$L:$L, 'St Kitts'!$B:$B, $A8, 'St Kitts'!$D:$D, "London") -> 117.23214 | C8: =SUMIFS(Antigua!$L:$L, Antigua!$B:$B, $A8, Antigua!$D:$D, "Out Ports") + SUMIFS(Barbados!$L:$L, Barbados!$B:$B, $A8, Barbados!$D:$D, "Out Ports") + SUMIFS(Bermuda!$L:$L, Bermuda!$B:$B, $A8, Bermuda!$D:$D, "Out Ports") + SUMIFS(Jamaica!$L:$L, Jamaica!$B:$B, $A8, Jamaica!$D:$D, "Out Ports") + SUMIFS(Mountserat!$L:$L, Mountserat!$B:$B, $A8, Mountserat!$D:$D, "Out Ports") + SUMIFS(Nevis!$L:$L, Nevis!$B:$B, $A8, Nevis!$D:$D, "Out Ports") + SUMIFS('St Kitts'!$L:$L, 'St Kitts'!$B:$B, $A8, 'St Kitts'!$D:$D, "Out Ports") -> 45.961496 | D8: =ROUND((B8+C8),2) -> 163.19
A9: Dry Ginger | B9: =SUMIFS(Antigua!$L:$L, Antigua!$B:$B, $A9, Antigua!$D:$D, "London") + SUMIFS(Barbados!$L:$L, Barbados!$B:$B, $A9, Barbados!$D:$D, "London") + SUMIFS(Bermuda!$L:$L, Bermuda!$B:$B, $A9, Bermuda!$D:$D, "London") + SUMIFS(Jamaica!$L:$L, Jamaica!$B:$B, $A9, Jamaica!$D:$D, "London") + SUMIFS(Mountserat!$L:$L, Mountserat!$B:$B, $A9, Mountserat!$D:$D, "London") + SUMIFS(Nevis!$L:$L, Nevis!$B:$B, $A9, Nevis!$D:$D, "London") + SUMIFS('St Kitts'!$L:$L, 'St Kitts'!$B:$B, $A9, 'St Kitts'!$D:$D, "London") -> 1280.4308 | C9: =SUMIFS(Antigua!$L:$L, Antigua!$B:$B, $A9, Antigua!$D:$D, "Out Ports") + SUMIFS(Barbados!$L:$L, Barbados!$B:$B, $A9, Barbados!$D:$D, "Out Ports") + SUMIFS(Bermuda!$L:$L, Bermuda!$B:$B, $A9, Bermuda!$D:$D, "Out Ports") + SUMIFS(Jamaica!$L:$L, Jamaica!$B:$B, $A9, Jamaica!$D:$D, "Out Ports") + SUMIFS(Mountserat!$L:$L, Mountserat!$B:$B, $A9, Mountserat!$D:$D, "Out Ports") + SUMIFS(Nevis!$L:$L, Nevis!$B:$B, $A9, Nevis!$D:$D, "Out Ports") + SUMIFS('St Kitts'!$L:$L, 'St Kitts'!$B:$B, $A9, 'St Kitts'!$D:$D, "Out Ports") -> 168.61339 | D9: =ROUND((B9+C9),2) -> 1449.04
A10: Elephant Teeth | B10: =SUMIFS(Antigua!$L:$L, Antigua!$B:$B, $A10, Antigua!$D:$D, "London") + SUMIFS(Barbados!$L:$L, Barbados!$B:$B, $A10, Barbados!$D:$D, "London") + SUMIFS(Bermuda!$L:$L, Bermuda!$B:$B, $A10, Bermuda!$D:$D, "London") + SUMIFS(Jamaica!$L:$L, Jamaica!$B:$B, $A10, Jamaica!$D:$D, "London") + SUMIFS(Mountserat!$L:$L, Mountserat!$B:$B, $A10, Mountserat!$D:$D, "London") + SUMIFS(Nevis!$L:$L, Nevis!$B:$B, $A10, Nevis!$D:$D, "London") + SUMIFS('St Kitts'!$L:$L, 'St Kitts'!$B:$B, $A10, 'St Kitts'!$D:$D, "London") -> 4.7455357 | C10: =SUMIFS(Antigua!$L:$L, Antigua!$B:$B, $A10, Antigua!$D:$D, "Out Ports") + SUMIFS(Barbados!$L:$L, Barbados!$B:$B, $A10, Barbados!$D:$D, "Out Ports") + SUMIFS(Bermuda!$L:$L, Bermuda!$B:$B, $A10, Bermuda!$D:$D, "Out Ports") + SUMIFS(Jamaica!$L:$L, Jamaica!$B:$B, $A10, Jamaica!$D:$D, "Out Ports") + SUMIFS(Mountserat!$L:$L, Mountserat!$B:$B, $A10, Mountserat!$D:$D, "Out Ports") + SUMIFS(Nevis!$L:$L, Nevis!$B:$B, $A10, Nevis!$D:$D, "Out Ports") + SUMIFS('St Kitts'!$L:$L, 'St Kitts'!$B:$B, $A10, 'St Kitts'!$D:$D, "Out Ports") -> 1.08125 | D10: =ROUND((B10+C10),2) -> 5.83
A11: Indigo | B11: =SUMIFS(Antigua!$L:$L, Antigua!$B:$B, $A11, Antigua!$D:$D, "London") + SUMIFS(Barbados!$L:$L, Barbados!$B:$B, $A11, Barbados!$D:$D, "London") + SUMIFS(Bermuda!$L:$L, Bermuda!$B:$B, $A11, Bermuda!$D:$D, "London") + SUMIFS(Jamaica!$L:$L, Jamaica!$B:$B, $A11, Jamaica!$D:$D, "London") + SUMIFS(Mountserat!$L:$L, Mountserat!$B:$B, $A11, Mountserat!$D:$D, "London") + SUMIFS(Nevis!$L:$L, Nevis!$B:$B, $A11, Nevis!$D:$D, "London") + SUMIFS('St Kitts'!$L:$L, 'St Kitts'!$B:$B, $A11, 'St Kitts'!$D:$D, "London") -> 47.930357 | C11: =SUMIFS(Antigua!$L:$L, Antigua!$B:$B, $A11, Antigua!$D:$D, "Out Ports") + SUMIFS(Barbados!$L:$L, Barbados!$B:$B, $A11, Barbados!$D:$D, "Out Ports") + SUMIFS(Bermuda!$L:$L, Bermuda!$B:$B, $A11, Bermuda!$D:$D, "Out Ports") + SUMIFS(Jamaica!$L:$L, Jamaica!$B:$B, $A11, Jamaica!$D:$D, "Out Ports") + SUMIFS(Mountserat!$L:$L, Mountserat!$B:$B, $A11, Mountserat!$D:$D, "Out Ports") + SUMIFS(Nevis!$L:$L, Nevis!$B:$B, $A11, Nevis!$D:$D, "Out Ports") + SUMIFS('St Kitts'!$L:$L, 'St Kitts'!$B:$B, $A11, 'St Kitts'!$D:$D, "Out Ports") -> 68.401562 | D11: =ROUND((B11+C11),2) -> 116.33
A12: Lignum Vitae | B12: =SUMIFS(Antigua!$L:$L, Antigua!$B:$B, $A12, Antigua!$D:$D, "London") + SUMIFS(Barbados!$L:$L, Barbados!$B:$B, $A12, Barbados!$D:$D, "London") + SUMIFS(Bermuda!$L:$L, Bermuda!$B:$B, $A12, Bermuda!$D:$D, "London") + SUMIFS(Jamaica!$L:$L, Jamaica!$B:$B, $A12, Jamaica!$D:$D, "London") + SUMIFS(Mountserat!$L:$L, Mountserat!$B:$B, $A12, Mountserat!$D:$D, "London") + SUMIFS(Nevis!$L:$L, Nevis!$B:$B, $A12, Nevis!$D:$D, "London") + SUMIFS('St Kitts'!$L:$L, 'St Kitts'!$B:$B, $A12, 'St Kitts'!$D:$D, "London") -> 85.946429 | C12: =SUMIFS(Antigua!$L:$L, Antigua!$B:$B, $A12, Antigua!$D:$D, "Out Ports") + SUMIFS(Barbados!$L:$L, Barbados!$B:$B, $A12, Barbados!$D:$D, "Out Ports") + SUMIFS(Bermuda!$L:$L, Bermuda!$B:$B, $A12, Bermuda!$D:$D, "Out Ports") + SUMIFS(Jamaica!$L:$L, Jamaica!$B:$B, $A12, Jamaica!$D:$D, "Out Ports") + SUMIFS(Mountserat!$L:$L, Mountserat!$B:$B, $A12, Mountserat!$D:$D, "Out Ports") + SUMIFS(Nevis!$L:$L, Nevis!$B:$B, $A12, Nevis!$D:$D, "Out Ports") + SUMIFS('St Kitts'!$L:$L, 'St Kitts'!$B:$B, $A12, 'St Kitts'!$D:$D, "Out Ports") -> 7.1834821 | D12: =ROUND((B12+C12),2) -> 93.13
A13: Lime Juice | B13: =SUMIFS(Antigua!$L:$L, Antigua!$B:$B, $A13, Antigua!$D:$D, "London") + SUMIFS(Barbados!$L:$L, Barbados!$B:$B, $A13, Barbados!$D:$D, "London") + SUMIFS(Bermuda!$L:$L, Bermuda!$B:$B, $A13, Bermuda!$D:$D, "London") + SUMIFS(Jamaica!$L:$L, Jamaica!$B:$B, $A13, Jamaica!$D:$D, "London") + SUMIFS(Mountserat!$L:$L, Mountserat!$B:$B, $A13, Mountserat!$D:$D, "London") + SUMIFS(Nevis!$L:$L, Nevis!$B:$B, $A13, Nevis!$D:$D, "London") + SUMIFS('St Kitts'!$L:$L, 'St Kitts'!$B:$B, $A13, 'St Kitts'!$D:$D, "London") -> 33.886607 | C13: =SUMIFS(Antigua!$L:$L, Antigua!$B:$B, $A13, Antigua!$D:$D, "Out Ports") + SUMIFS(Barbados!$L:$L, Barbados!$B:$B, $A13, Barbados!$D:$D, "Out Ports") + SUMIFS(Bermuda!$L:$L, Bermuda!$B:$B, $A13, Bermuda!$D:$D, "Out Ports") + SUMIFS(Jamaica!$L:$L, Jamaica!$B:$B, $A13, Jamaica!$D:$D, "Out Ports") + SUMIFS(Mountserat!$L:$L, Mountserat!$B:$B, $A13, Mountserat!$D:$D, "Out Ports") + SUMIFS(Nevis!$L:$L, Nevis!$B:$B, $A13, Nevis!$D:$D, "Out Ports") + SUMIFS('St Kitts'!$L:$L, 'St Kitts'!$B:$B, $A13, 'St Kitts'!$D:$D, "Out Ports") -> 24.73125 | D13: =ROUND((B13+C13),2) -> 58.62
... A27: Madera Wine | B27: =SUMIFS(Antigua!$L:$L, Antigua!$B:$B, $A27, Antigua!$D:$D, "London") + SUMIFS(Barbados!$L:$L, Barbados!$B:$B, $A27, Barbados!$D:$D, "London") + SUMIFS(Bermuda!$L:$L, Bermuda!$B:$B, $A27, Bermuda!$D:$D, "London") + SUMIFS(Jamaica!$L:$L, Jamaica!$B:$B, $A27, Jamaica!$D:$D, "London") + SUMIFS(Mountserat!$L:$L, Mountserat!$B:$B, $A27, Mountserat!$D:$D, "London") + SUMIFS(Nevis!$L:$L, Nevis!$B:$B, $A27, Nevis!$D:$D, "London") + SUMIFS('St Kitts'!$L:$L, 'St Kitts'!$B:$B, $A27, 'St Kitts'!$D:$D, "London") -> 16.380357 | C27: =SUMIFS(Antigua!$L:$L, Antigua!$B:$B, $A27, Antigua!$D:$D, "Out Ports") + SUMIFS(Barbados!$L:$L, Barbados!$B:$B, $A27, Barbados!$D:$D, "Out Ports") + SUMIFS(Bermuda!$L:$L, Bermuda!$B:$B, $A27, Bermuda!$D:$D, "Out Ports") + SUMIFS(Jamaica!$L:$L, Jamaica!$B:$B, $A27, Jamaica!$D:$D, "Out Ports") + SUMIFS(Mountserat!$L:$L, Mountserat!$B:$B, $A27, Mountserat!$D:$D, "Out Ports") + SUMIFS(Nevis!$L:$L, Nevis!$B:$B, $A27, Nevis!$D:$D, "Out Ports") + SUMIFS('St Kitts'!$L:$L, 'St Kitts'!$B:$B, $A27, 'St Kitts'!$D:$D, "Out Ports") -> 0.40535714 | D27: =ROUND((B27+C27),2) -> 16.79

Sheet Antigua
A1: YEAR | B1: COMMODITY_NAME | C1: FROM_LOCATION | D1: TO_LOCATION | E1: ton | F1: hh | G1: quarter | H1: lb | J1: Total Pounds | L1: WEIGHT
A2: 1706 | B2: Annatto | C2: Antigua | D2: London | J2: =(E2*2240)+(F2*112)+(G2*28)+H2 -> 0 | L2: =J2/2240 -> 0
A3: 1706 | B3: Brown Sugar | C3: Antigua | D3: London | F3: 13338 | G3: 1 | H3: 9 | J3: =(E3*2240)+(F3*112)+(G3*28)+H3 -> 1493893 | L3: =J3/2240 -> 666.91652
A4: 1706 | B4: Chocolate | C4: Antigua | D4: London | J4: =(E4*2240)+(F4*112)+(G4*28)+H4 -> 0 | L4: =J4/2240 -> 0
A5: 1706 | B5: Cocoa Nuts | C5: Antigua | D5: London | G5: 2 | H5: 4 | J5: =(E5*2240)+(F5*112)+(G5*28)+H5 -> 60 | L5: =J5/2240 -> 0.026785714
A6: 1706 | B6: Cotton | C6: Antigua | D6: London | H6: =113*200 -> 22600 | I6: 113 bags | J6: =(E6*2240)+(F6*112)+(G6*28)+H6 -> 22600 | L6: =J6/2240 -> 10.089286
A7: 1706 | B7: Dry Ginger | C7: Antigua | D7: London | F7: 1647 | H7: 5 | J7: =(E7*2240)+(F7*112)+(G7*28)+H7 -> 184469 | L7: =J7/2240 -> 82.352232
A8: 1706 | B8: Elephant Teeth | C8: Antigua | D8: London | J8: =(E8*2240)+(F8*112)+(G8*28)+H8 -> 0 | L8: =J8/2240 -> 0
A9: 1706 | B9: Indigo | C9: Antigua | D9: London | H9: 5376 | J9: =(E9*2240)+(F9*112)+(G9*28)+H9 -> 5376 | L9: =J9/2240 -> 2.4
A10: 1706 | B10: Lemon Water | C10: Antigua | D10: London | J10: =(E10*2240)+(F10*112)+(G10*28)+H10 -> 0 | L10: =J10/2240 -> 0
A11: 1706 | B11: Lignum Vitae | C11: Antigua | D11: London | F11: 1473 | G11: 3 | H11: 27 | J11: =(E11*2240)+(F11*112)+(G11*28)+H11 -> 165087 | L11: =J11/2240 -> 73.699554
A12: 1706 | B12: Lime Juice | C12: Antigua | D12: London | H12: 2533 | I12: 251g | J12: =(E12*2240)+(F12*112)+(G12*28)+H12 -> 2533 | L12: =J12/2240 -> 1.1308036
A13: 1706 | B13: Madera Wine | C13: Antigua | D13: London | J13: =(E13*2240)+(F13*112)+(G13*28)+H13 -> 0 | L13: =J13/2240 -> 0
A14: 1706 | B14: Molasses | C14: Antigua | D14: London | F14: 442 | G14: 3 | H14: 21 | J14: =(E14*2240)+(F14*112)+(G14*28)+H14 -> 49609 | L14: =J14/2240 -> 22.146875
A15: 1706 | B15: Rum | C15: Antigua | D15: London | H15: 858 | I15: 85g | J15: =(E15*2240)+(F15*112)+(G15*28)+H15 -> 858 | L15: =J15/2240 -> 0.38303571
A16: 1706 | B16: Shruff | C16: Antigua | D16: London | F16: 5 | H16: 14 | J16: =(E16*2240)+(F16*112)+(G16*28)+H16 -> 574 | L16: =J16/2240 -> 0.25625
A17: 1706 | B17: Succads | C17: Antigua | D17: London | J17: =(E17*2240)+(F17*112)+(G17*28)+H17 -> 0 | L17: =J17/2240 -> 0
A18: 1706 | B18: Sugar Loaf | C18: Antigua | D18: London | G18: 1 | J18: =(E18*2240)+(F18*112)+(G18*28)+H18 -> 28 | L18: =J18/2240 -> 0.0125
A19: 1706 | B19: Tobacco | C19: Antigua | D19: London | J19: =(E19*2240)+(F19*112)+(G19*28)+H19 -> 0 | L19: =J19/2240 -> 0
A20: 1706 | B20: Tortoise Shell | C20: Antigua | D20: London | J20: =(E20*2240)+(F20*112)+(G20*28)+H20 -> 0 | L20: =J20/2240 -> 0
A21: 1706 | B21: White Sugar | C21: Antigua | D21: London | F21: 62 | H21: 26 | J21: =(E21*2240)+(F21*112)+(G21*28)+H21 -> 6970 | L21: =J21/2240 -> 3.1116071
A22: 1706 | B22: Brown Sugar | C22: Antigua | D22: Out Ports | F22: 4049 | H22: 23 | J22: =(E22*2240)+(F22*112)+(G22*28)+H22 -> 453511 | L22: =J22/2240 -> 202.46027
A23: 1706 | B23: Cocoa | C23: Antigua | D23: Out Ports | J23: =(E23*2240)+(F23*112)+(G23*28)+H23 -> 0 | L23: =J23/2240 -> 0
A24: 1706 | B24: Cocoa Nuts | C24: Antigua | D24: Out Ports | F24: 3 | G24: 2 | H24: 7 | J24: =(E24*2240)+(F24*112)+(G24*28)+H24 -> 399 | L24: =J24/2240 -> 0.178125
A25: 1706 | B25: Cotton | C25: Antigua | D25: Out Ports | H25: 18275 | J25: =(E25*2240)+(F25*112)+(G25*28)+H25 -> 18275 | L25: =J25/2240 -> 8.1584821
A26: 1706 | B26: Dry Ginger | C26: Antigua | D26: Out Ports | F26: 219 | G26: 2 | H26: 15 | J26: =(E26*2240)+(F26*112)+(G26*28)+H26 -> 24599 | L26: =J26/2240 -> 10.981696
A27: 1706 | B27: Indigo | C27: Antigua | D27: Out Ports | H27: 3460 | J27: =(E27*2240)+(F27*112)+(G27*28)+H27 -> 3460 | L27: =J27/2240 -> 1.5446429
A28: 1706 | B28: Lignum Vitae | C28: Antigua | D28: Out Ports | F28: 73 | G28: 1 | J28: =(E28*2240)+(F28*112)+(G28*28)+H28 -> 8204 | L28: =J28/2240 -> 3.6625
A29: 1706 | B29: Lime Juice | C29: Antigua | D29: Out Ports | H29: 3088 | I29: 306g | J29: =(E29*2240)+(F29*112)+(G29*28)+H29 -> 3088 | L29: =J29/2240 -> 1.3785714
A30: 1706 | B30: Madera Wine | C30: Antigua | D30: Out Ports | J30: =(E30*2240)+(F30*112)+(G30*28)+H30 -> 0 | L30: =J30/2240 -> 0
A31: 1706 | B31: Molasses | C31: Antigua | D31: Out Ports | J31: =(E31*2240)+(F31*112)+(G31*28)+H31 -> 0 | L31: =J31/2240 -> 0
A32: 1706 | B32: Pimento | C32: Antigua | D32: Out Ports | H32: 868 | J32: =(E32*2240)+(F32*112)+(G32*28)+H32 -> 868 | L32: =J32/2240 -> 0.3875
A33: 1706 | B33: Rice | C33: Antigua | D33: Out Ports | J33: =(E33*2240)+(F33*112)+(G33*28)+H33 -> 0 | L33: =J33/2240 -> 0
A34: 1706 | B34: Rum | C34: Antigua | D34: Out Ports | H34: 817 | I34: 81g | J34: =(E34*2240)+(F34*112)+(G34*28)+H34 -> 817 | L34: =J34/2240 -> 0.36473214
A35: 1706 | B35: Shruff | C35: Antigua | D35: Out Ports | J35: =(E35*2240)+(F35*112)+(G35*28)+H35 -> 0 | L35: =J35/2240 -> 0
A36: 1706 | B36: Succads | C36: Antigua | D36: Out Ports | H36: 16 | J36: =(E36*2240)+(F36*112)+(G36*28)+H36 -> 16 | L36: =J36/2240 -> 0.0071428571
A37: 1706 | B37: Tobacco | C37: Antigua | D37: Out Ports | J37: =(E37*2240)+(F37*112)+(G37*28)+H37 -> 0 | L37: =J37/2240 -> 0
A38: 1706 | B38: Tortoise Shell | C38: Antigua | D38: Out Ports | H38: 266 | J38: =(E38*2240)+(F38*112)+(G38*28)+H38 -> 266 | L38: =J38/2240 -> 0.11875
A39: 1706 | B39: White Sugar | C39: Antigua | D39: Out Ports | F39: 7 | H39: 6 | J39: =(E39*2240)+(F39*112)+(G39*28)+H39 -> 790 | L39: =J39/2240 -> 0.35267857
A40: 1706 | B40: Wood, Fustick | C40: Antigua | D40: Out Ports | J40: =(E40*2240)+(F40*112)+(G40*28)+H40 -> 0 | L40: =J40/2240 -> 0

Sheet Barbados
A1: YEAR | B1: COMMODITY_NAME | C1: FROM_LOCATION | D1: TO_LOCATION | E1: ton | F1: hh | G1: quarter | H1: lb | J1: Total Pounds | L1: WEIGHT
A2: 1706 | B2: Aloes Epatica | C2: Barbados | D2: London | H2: 6532 | J2: =(E2*2240)+(F2*112)+(G2*28)+H2 -> 6532 | L2: =J2/2240 -> 2.9160714
A3: 1706 | B3: Annatto | C3: Barbados | D3: London | J3: =(E3*2240)+(F3*112)+(G3*28)+H3 -> 0 | L3: =J3/2240 -> 0
A4: 1706 | B4: Barrel Staves | C4: Barbados | D4: London | J4: =(E4*2240)+(F4*112)+(G4*28)+H4 -> 0 | L4: =J4/2240 -> 0
A5: 1706 | B5: Brazilia | C5: Barbados | D5: London | J5: =(E5*2240)+(F5*112)+(G5*28)+H5 -> 0 | L5: =J5/2240 -> 0
A6: 1706 | B6: Brimstone | C6: Barbados | D6: London | F6: 40 | J6: =(E6*2240)+(F6*112)+(G6*28)+H6 -> 4480 | L6: =J6/2240 -> 2
A7: 1706 | B7: Brown Sugar | C7: Barbados | D7: London | F7: 174980 | G7: 2 | H7: 3 | J7: =(E7*2240)+(F7*112)+(G7*28)+H7 -> 19597819 | L7: =J7/2240 -> 8749.0263
A8: 1706 | B8: Cassia Fistula | C8: Barbados | D8: London | H8: 1598 | J8: =(E8*2240)+(F8*112)+(G8*28)+H8 -> 1598 | L8: =J8/2240 -> 0.71339286
A9: 1706 | B9: Chocolate | C9: Barbados | D9: London | H9: 39 | J9: =(E9*2240)+(F9*112)+(G9*28)+H9 -> 39 | L9: =J9/2240 -> 0.017410714
A10: 1706 | B10: Cocheneal | C10: Barbados | D10: London | J10: =(E10*2240)+(F10*112)+(G10*28)+H10 -> 0 | L10: =J10/2240 -> 0
A11: 1706 | B11: Cocoa Nuts | C11: Barbados | D11: London | F11: 6 | G11: 2 | H11: 21 | J11: =(E11*2240)+(F11*112)+(G11*28)+H11 -> 749 | L11: =J11/2240 -> 0.334375
A12: 1706 | B12: Cocoa Paste | C12: Barbados | D12: London | J12: =(E12*2240)+(F12*112)+(G12*28)+H12 -> 0 | L12: =J12/2240 -> 0
A13: 1706 | B13: Cotton | C13: Barbados | D13: London | H13: =1070*200 -> 214000 | I13: 1070bag | J13: =(E13*2240)+(F13*112)+(G13*28)+H13 -> 214000 | L13: =J13/2240 -> 95.535714
A14: 1706 | B14: Dry Ginger | C14: Barbados | D14: London | F14: 13287 | G14: 2 | H14: 14 | J14: =(E14*2240)+(F14*112)+(G14*28)+H14 -> 1488214 | L14: =J14/2240 -> 664.38125
A15: 1706 | B15: Elephant Teeth | C15: Barbados | D15: London | F15: 5 | G15: 1 | H15: 4 | J15: =(E15*2240)+(F15*112)+(G15*28)+H15 -> 592 | L15: =J15/2240 -> 0.26428571
A16: 1706 | B16: Green Ginger | C16: Barbados | D16: London | H16: 430 | J16: =(E16*2240)+(F16*112)+(G16*28)+H16 -> 430 | L16: =J16/2240 -> 0.19196429
A17: 1706 | B17: Hemp | C17: Barbados | D17: London | J17: =(E17*2240)+(F17*112)+(G17*28)+H17 -> 0 | L17: =J17/2240 -> 0
A18: 1706 | B18: Indigo | C18: Barbados | D18: London | H18: 432 | J18: =(E18*2240)+(F18*112)+(G18*28)+H18 -> 432 | L18: =J18/2240 -> 0.19285714
A19: 1706 | B19: Lemon Water | C19: Barbados | D19: London | J19: =(E19*2240)+(F19*112)+(G19*28)+H19 -> 0 | L19: =J19/2240 -> 0
A20: 1706 | B20: Lignum Vitae | C20: Barbados | D20: London | F20: 54 | G20: 2 | H20: 7 | J20: =(E20*2240)+(F20*112)+(G20*28)+H20 -> 6111 | L20: =J20/2240 -> 2.728125
A21: 1706 | B21: Lime Juice | C21: Barbados | D21: London | H21: 16875 | I21: 1672g | J21: =(E21*2240)+(F21*112)+(G21*28)+H21 -> 16875 | L21: =J21/2240 -> 7.5334821
A22: 1706 | B22: Loaf Sugar | C22: Barbados | D22: London | J22: =(E22*2240)+(F22*112)+(G22*28)+H22 -> 0 | L22: =J22/2240 -> 0
A23: 1706 | B23: Madera Wine | C23: Barbados | D23: London | H23: 35854 | I23: 14t 24.5g | J23: =(E23*2240)+(F23*112)+(G23*28)+H23 -> 35854 | L23: =J23/2240 -> 16.00625
A24: 1706 | B24: Molasses | C24: Barbados | D24: London | F24: 1368 | G24: 2 | J24: =(E24*2240)+(F24*112)+(G24*28)+H24 -> 153272 | L24: =J24/2240 -> 68.425
A25: 1706 | B25: Oranges | C25: Barbados | D25: London | J25: =(E25*2240)+(F25*112)+(G25*28)+H25 -> 0 | L25: =J25/2240 -> 0
A26: 1706 | B26: Pimento | C26: Barbados | D26: London | J26: =(E26*2240)+(F26*112)+(G26*28)+H26 -> 0 | L26: =J26/2240 -> 0
A27: 1706 | B27: Rice | C27: Barbados | D27: London | J27: =(E27*2240)+(F27*112)+(G27*28)+H27 -> 0 | L27: =J27/2240 -> 0
A28: 1706 | B28: Rum | C28: Barbados | D28: London | H28: 122418 | I28: 12129.5g | J28: =(E28*2240)+(F28*112)+(G28*28)+H28 -> 122418 | L28: =J28/2240 -> 54.650893
A29: 1706 | B29: Shruff | C29: Barbados | D29: London | F29: 60 | G29: 3 | H29: 26 | J29: =(E29*2240)+(F29*112)+(G29*28)+H29 -> 6830 | L29: =J29/2240 -> 3.0491071
A30: 1706 | B30: Snuff | C30: Barbados | D30: London | J30: =(E30*2240)+(F30*112)+(G30*28)+H30 -> 0 | L30: =J30/2240 -> 0
A31: 1706 | B31: Succads | C31: Barbados | D31: London | J31: =(E31*2240)+(F31*112)+(G31*28)+H31 -> 0 | L31: =J31/2240 -> 0
A32: 1706 | B32: Sugar Loaf | C32: Barbados | D32: London | G32: 1 | J32: =(E32*2240)+(F32*112)+(G32*28)+H32 -> 28 | L32: =J32/2240 -> 0.0125
A33: 1706 | B33: Tobacco | C33: Barbados | D33: London | H33: 253000 | J33: =(E33*2240)+(F33*112)+(G33*28)+H33 -> 253000 | L33: =J33/2240 -> 112.94643
A34: 1706 | B34: Tortoise Shell | C34: Barbados | D34: London | H34: 30 | J34: =(E34*2240)+(F34*112)+(G34*28)+H34 -> 30 | L34: =J34/2240 -> 0.013392857
A35: 1706 | B35: White Sugar | C35: Barbados | D35: London | F35: 2873 | G35: 1 | H35: 11 | J35: =(E35*2240)+(F35*112)+(G35*28)+H35 -> 321815 | L35: =J35/2240 -> 143.66741
A36: 1706 | B36: Wood, Fustick | C36: Barbados | D36: London | F36: 37 | J36: =(E36*2240)+(F36*112)+(G36*28)+H36 -> 4144 | L36: =J36/2240 -> 1.85
A37: 1706 | B37: Wood, Logwood | C37: Barbados | D37: London | J37: =(E37*2240)+(F37*112)+(G37*28)+H37 -> 0 | L37: =J37/2240 -> 0
A38: 1706 | B38: Wood, Redwood | C38: Barbados | D38: London | J38: =(E38*2240)+(F38*112)+(G38*28)+H38 -> 0 | L38: =J38/2240 -> 0
A39: 1706 | B39: Brown Sugar | C39: Barbados | D39: Out Ports | F39: 17914 | G39: 2 | H39: 8 | J39: =(E39*2240)+(F39*112)+(G39*28)+H39 -> 2006432 | L39: =J39/2240 -> 895.72857
A40: 1706 | B40: Chocolate | C40: Barbados | D40: Out Ports | J40: =(E40*2240)+(F40*112)+(G40*28)+H40 -> 0 | L40: =J40/2240 -> 0
...

Sheet Bermuda
A1: Items | B1: Import Location | C1: ton | D1: hh | E1: quarter | F1: lb | H1: Total Pounds | J1: Total Tons
A2: Indigo | B2: Out Ports | H2: =(C2*2240)+(D2*112)+(E2*28)+F2 -> 0 | J2: =H2/2240 -> 0
A3: Wood, Logwood | B3: Out Ports | H3: =(C3*2240)+(D3*112)+(E3*28)+F3 -> 0 | J3: =H3/2240 -> 0
A4: Shruff | B4: Out Ports | H4: =(C4*2240)+(D4*112)+(E4*28)+F4 -> 0 | J4: =H4/2240 -> 0
A5: Succads | B5: Out Ports | H5: =(C5*2240)+(D5*112)+(E5*28)+F5 -> 0 | J5: =H5/2240 -> 0
A6: Cotton | B6: Out Ports | H6: =(C6*2240)+(D6*112)+(E6*28)+F6 -> 0 | J6: =H6/2240 -> 0
A7: Cocoa Nuts | B7: Out Ports | H7: =(C7*2240)+(D7*112)+(E7*28)+F7 -> 0 | J7: =H7/2240 -> 0

Sheet Jamaica
A1: YEAR | B1: COMMODITY_NAME | C1: FROM_LOCATION | D1: TO_LOCATION | E1: ton | F1: hh | G1: quarter | H1: lb | J1: Total Pounds | L1: WEIGHT
A2: 1706 | B2: Annatto | C2: Jamaica | D2: London | H2: 25 | J2: =(E2*2240)+(F2*112)+(G2*28)+H2 -> 25 | L2: =J2/2240 -> 0.011160714
A3: 1706 | B3: Bees Wax | C3: Jamaica | D3: London | J3: =(E3*2240)+(F3*112)+(G3*28)+H3 -> 0 | L3: =J3/2240 -> 0
A4: 1706 | B4: Brown Sugar | C4: Jamaica | D4: London | F4: 51010 | G4: 3 | H4: 21 | J4: =(E4*2240)+(F4*112)+(G4*28)+H4 -> 5713225 | L4: =J4/2240 -> 2550.5469
A5: 1706 | B5: Cascarilla | C5: Jamaica | D5: London | J5: =(E5*2240)+(F5*112)+(G5*28)+H5 -> 0 | L5: =J5/2240 -> 0
A6: 1706 | B6: Chocolate | C6: Jamaica | D6: London | H6: 19 | J6: =(E6*2240)+(F6*112)+(G6*28)+H6 -> 19 | L6: =J6/2240 -> 0.0084821429
A7: 1706 | B7: Cocheneal | C7: Jamaica | D7: London | J7: =(E7*2240)+(F7*112)+(G7*28)+H7 -> 0 | L7: =J7/2240 -> 0
A8: 1706 | B8: Cocoa Nuts | C8: Jamaica | D8: London | F8: 77 | H8: 7 | J8: =(E8*2240)+(F8*112)+(G8*28)+H8 -> 8631 | L8: =J8/2240 -> 3.853125
A9: 1706 | B9: Cocoa Paste | C9: Jamaica | D9: London | H9: 22 | J9: =(E9*2240)+(F9*112)+(G9*28)+H9 -> 22 | L9: =J9/2240 -> 0.0098214286
A10: 1706 | B10: Cocoa Wood | C10: Jamaica | D10: London | J10: =(E10*2240)+(F10*112)+(G10*28)+H10 -> 0 | L10: =J10/2240 -> 0
A11: 1706 | B11: Cotton | C11: Jamaica | D11: London | H11: =116*200 -> 23200 | I11: 116bags | J11: =(E11*2240)+(F11*112)+(G11*28)+H11 -> 23200 | L11: =J11/2240 -> 10.357143
A12: 1706 | B12: Dry Ginger | C12: Jamaica | D12: London | F12: 10641 | G12: 2 | H12: 1 | J12: =(E12*2240)+(F12*112)+(G12*28)+H12 -> 1191849 | L12: =J12/2240 -> 532.07545
A13: 1706 | B13: Elephant Teeth | C13: Jamaica | D13: London | F13: 78 | H13: 14 | J13: =(E13*2240)+(F13*112)+(G13*28)+H13 -> 8750 | L13: =J13/2240 -> 3.90625
A14: 1706 | B14: Hypococania | C14: Jamaica | D14: London | H14: 311 | J14: =(E14*2240)+(F14*112)+(G14*28)+H14 -> 311 | L14: =J14/2240 -> 0.13883929
A15: 1706 | B15: Indigo | C15: Jamaica | D15: London | H15: 100941 | J15: =(E15*2240)+(F15*112)+(G15*28)+H15 -> 100941 | L15: =J15/2240 -> 45.062946
A16: 1706 | B16: Jamaica Roots | C16: Jamaica | D16: London | J16: =(E16*2240)+(F16*112)+(G16*28)+H16 -> 0 | L16: =J16/2240 -> 0
A17: 1706 | B17: Lignum Vitae | C17: Jamaica | D17: London | E17: 9 | F17: 10 | G17: 1 | H17: 14 | J17: =(E17*2240)+(F17*112)+(G17*28)+H17 -> 21322 | L17: =J17/2240 -> 9.51875
A18: 1706 | B18: Lime Juice | C18: Jamaica | D18: London | H18: 55741 | I18: 5523g | J18: =(E18*2240)+(F18*112)+(G18*28)+H18 -> 55741 | L18: =J18/2240 -> 24.884375
A19: 1706 | B19: Madera Wine | C19: Jamaica | D19: London | H19: 838 | I19: 83g | J19: =(E19*2240)+(F19*112)+(G19*28)+H19 -> 838 | L19: =J19/2240 -> 0.37410714
A20: 1706 | B20: Molasses | C20: Jamaica | D20: London | J20: =(E20*2240)+(F20*112)+(G20*28)+H20 -> 0 | L20: =J20/2240 -> 0
A21: 1706 | B21: Pimento | C21: Jamaica | D21: London | H21: 95627 | J21: =(E21*2240)+(F21*112)+(G21*28)+H21 -> 95627 | L21: =J21/2240 -> 42.690625
A22: 1706 | B22: Rice | C22: Jamaica | D22: London | J22: =(E22*2240)+(F22*112)+(G22*28)+H22 -> 0 | L22: =J22/2240 -> 0
A23: 1706 | B23: Rum | C23: Jamaica | D23: London | H23: 9109 | I23: 902.5g | J23: =(E23*2240)+(F23*112)+(G23*28)+H23 -> 9109 | L23: =J23/2240 -> 4.0665179
A24: 1706 | B24: Sasparilla | C24: Jamaica | D24: London | H24: 14877 | J24: =(E24*2240)+(F24*112)+(G24*28)+H24 -> 14877 | L24: =J24/2240 -> 6.6415179
A25: 1706 | B25: Shruff | C25: Jamaica | D25: London | F25: 14 | G25: 2 | J25: =(E25*2240)+(F25*112)+(G25*28)+H25 -> 1624 | L25: =J25/2240 -> 0.725
A26: 1706 | B26: Snuff | C26: Jamaica | D26: London | J26: =(E26*2240)+(F26*112)+(G26*28)+H26 -> 0 | L26: =J26/2240 -> 0
A27: 1706 | B27: Succads | C27: Jamaica | D27: London | H27: 312 | J27: =(E27*2240)+(F27*112)+(G27*28)+H27 -> 312 | L27: =J27/2240 -> 0.13928571
A28: 1706 | B28: Sugar Loaf | C28: Jamaica | D28: London | J28: =(E28*2240)+(F28*112)+(G28*28)+H28 -> 0 | L28: =J28/2240 -> 0
A29: 1706 | B29: Tobacco | C29: Jamaica | D29: London | H29: 8836 | J29: =(E29*2240)+(F29*112)+(G29*28)+H29 -> 8836 | L29: =J29/2240 -> 3.9446429
A30: 1706 | B30: Tortoise Shell | C30: Jamaica | D30: London | H30: 765 | J30: =(E30*2240)+(F30*112)+(G30*28)+H30 -> 765 | L30: =J30/2240 -> 0.34151786
A31: 1706 | B31: White Sugar | C31: Jamaica | D31: London | F31: 13 | H31: 1 | J31: =(E31*2240)+(F31*112)+(G31*28)+H31 -> 1457 | L31: =J31/2240 -> 0.65044643
A32: 1706 | B32: Wood, Braziletto | C32: Jamaica | D32: London | F32: 10 | J32: =(E32*2240)+(F32*112)+(G32*28)+H32 -> 1120 | L32: =J32/2240 -> 0.5
A33: 1706 | B33: Wood, Fustick | C33: Jamaica | D33: London | F33: 2448 | H33: 15 | J33: =(E33*2240)+(F33*112)+(G33*28)+H33 -> 274191 | L33: =J33/2240 -> 122.4067
A34: 1706 | B34: Wood, Logwood | C34: Jamaica | D34: London | E34: 100 | G34: 1 | H34: 7 | J34: =(E34*2240)+(F34*112)+(G34*28)+H34 -> 224035 | L34: =J34/2240 -> 100.01562
A35: 1706 | B35: Wood, Nicaragua | C35: Jamaica | D35: London | E35: 8 | F35: 14 | J35: =(E35*2240)+(F35*112)+(G35*28)+H35 -> 19488 | L35: =J35/2240 -> 8.7
A36: 1706 | B36: Wood, Redwood | C36: Jamaica | D36: London | E36: 2 | F36: 10 | G36: 2 | H36: 21 | J36: =(E36*2240)+(F36*112)+(G36*28)+H36 -> 5677 | L36: =J36/2240 -> 2.534375
A37: 1706 | B37: Wool Vigonia | C37: Jamaica | D37: London | J37: =(E37*2240)+(F37*112)+(G37*28)+H37 -> 0 | L37: =J37/2240 -> 0
A38: 1706 | B38: Brown Sugar | C38: Jamaica | D38: Out Ports | F38: 31644 | G38: 3 | H38: 19 | J38: =(E38*2240)+(F38*112)+(G38*28)+H38 -> 3544231 | L38: =J38/2240 -> 1582.246
A39: 1706 | B39: Chocolate | C39: Jamaica | D39: Out Ports | J39: =(E39*2240)+(F39*112)+(G39*28)+H39 -> 0 | L39: =J39/2240 -> 0
A40: 1706 | B40: Cocoa Nuts | C40: Jamaica | D40: Out Ports | F40: 28 | G40: 1 | H40: 23 | J40: =(E40*2240)+(F40*112)+(G40*28)+H40 -> 3187 | L40: =J40/2240 -> 1.4227679
...

Sheet Mountserat
A1: YEAR | B1: COMMODITY_NAME | C1: FROM_LOCATION | D1: TO_LOCATION | E1: ton | F1: hh | G1: quarter | H1: lb | J1: Total Pounds | L1: WEIGHT
A2: 1706 | B2: Brown Sugar | C2: Mountserat | D2: London | F2: 2091 | G2: 2 | H2: 24 | J2: =(E2*2240)+(F2*112)+(G2*28)+H2 -> 234272 | L2: =J2/2240 -> 104.58571
A3: 1706 | B3: Chocolate | C3: Mountserat | D3: London | J3: =(E3*2240)+(F3*112)+(G3*28)+H3 -> 0 | L3: =J3/2240 -> 0
A4: 1706 | B4: Cocoa Nuts | C4: Mountserat | D4: London | J4: =(E4*2240)+(F4*112)+(G4*28)+H4 -> 0 | L4: =J4/2240 -> 0
A5: 1706 | B5: Cortex Winteranus | C5: Mountserat | D5: London | J5: =(E5*2240)+(F5*112)+(G5*28)+H5 -> 0 | L5: =J5/2240 -> 0
A6: 1706 | B6: Cotton | C6: Mountserat | D6: London | J6: =(E6*2240)+(F6*112)+(G6*28)+H6 -> 0 | L6: =J6/2240 -> 0
A7: 1706 | B7: Dry Ginger | C7: Mountserat | D7: London | F7: 32 | G7: 1 | H7: 21 | J7: =(E7*2240)+(F7*112)+(G7*28)+H7 -> 3633 | L7: =J7/2240 -> 1.621875
A8: 1706 | B8: Elephants Teeth | C8: Mountserat | D8: London | J8: =(E8*2240)+(F8*112)+(G8*28)+H8 -> 0 | L8: =J8/2240 -> 0
A9: 1706 | B9: Indigo | C9: Mountserat | D9: London | H9: 475 | J9: =(E9*2240)+(F9*112)+(G9*28)+H9 -> 475 | L9: =J9/2240 -> 0.21205357
A10: 1706 | B10: Lignum Vitae | C10: Mountserat | D10: London | J10: =(E10*2240)+(F10*112)+(G10*28)+H10 -> 0 | L10: =J10/2240 -> 0
A11: 1706 | B11: Lime Juice | C11: Mountserat | D11: London | H11: 757 | I11: 75g | J11: =(E11*2240)+(F11*112)+(G11*28)+H11 -> 757 | L11: =J11/2240 -> 0.33794643
A12: 1706 | B12: Madera Wine | C12: Mountserat | D12: London | J12: =(E12*2240)+(F12*112)+(G12*28)+H12 -> 0 | L12: =J12/2240 -> 0
A13: 1706 | B13: Molasses | C13: Mountserat | D13: London | F13: 2 | G13: 2 | J13: =(E13*2240)+(F13*112)+(G13*28)+H13 -> 280 | L13: =J13/2240 -> 0.125
A14: 1706 | B14: Pimento | C14: Mountserat | D14: London | H14: 2448 | J14: =(E14*2240)+(F14*112)+(G14*28)+H14 -> 2448 | L14: =J14/2240 -> 1.0928571
A15: 1706 | B15: Rum | C15: Mountserat | D15: London | J15: =(E15*2240)+(F15*112)+(G15*28)+H15 -> 0 | L15: =J15/2240 -> 0
A16: 1706 | B16: Shruff | C16: Mountserat | D16: London | J16: =(E16*2240)+(F16*112)+(G16*28)+H16 -> 0 | L16: =J16/2240 -> 0
A17: 1706 | B17: Succads | C17: Mountserat | D17: London | J17: =(E17*2240)+(F17*112)+(G17*28)+H17 -> 0 | L17: =J17/2240 -> 0
A18: 1706 | B18: Tortoise Shell | C18: Mountserat | D18: London | J18: =(E18*2240)+(F18*112)+(G18*28)+H18 -> 0 | L18: =J18/2240 -> 0
A19: 1706 | B19: White Sugar | C19: Mountserat | D19: London | J19: =(E19*2240)+(F19*112)+(G19*28)+H19 -> 0 | L19: =J19/2240 -> 0
A20: 1706 | B20: Brown Sugar | C20: Mountserat | D20: Out Ports | F20: 6723 | G20: 2 | H20: 15 | J20: =(E20*2240)+(F20*112)+(G20*28)+H20 -> 753047 | L20: =J20/2240 -> 336.1817
A21: 1706 | B21: Cocoa | C21: Mountserat | D21: Out Ports | J21: =(E21*2240)+(F21*112)+(G21*28)+H21 -> 0 | L21: =J21/2240 -> 0
A22: 1706 | B22: Cocoa Nuts | C22: Mountserat | D22: Out Ports | J22: =(E22*2240)+(F22*112)+(G22*28)+H22 -> 0 | L22: =J22/2240 -> 0
A23: 1706 | B23: Cotton | C23: Mountserat | D23: Out Ports | H23: 244 | J23: =(E23*2240)+(F23*112)+(G23*28)+H23 -> 244 | L23: =J23/2240 -> 0.10892857
A24: 1706 | B24: Dry Ginger | C24: Mountserat | D24: Out Ports | F24: 29 | H24: 9 | J24: =(E24*2240)+(F24*112)+(G24*28)+H24 -> 3257 | L24: =J24/2240 -> 1.4540179
A25: 1706 | B25: Elephants Teeth | C25: Mountserat | D25: Out Ports | J25: =(E25*2240)+(F25*112)+(G25*28)+H25 -> 0 | L25: =J25/2240 -> 0
A26: 1706 | B26: Indigo | C26: Mountserat | D26: Out Ports | H26: 9474 | J26: =(E26*2240)+(F26*112)+(G26*28)+H26 -> 9474 | L26: =J26/2240 -> 4.2294643
A27: 1706 | B27: Lime Juice | C27: Mountserat | D27: Out Ports | H27: 2271 | I27: 225g | J27: =(E27*2240)+(F27*112)+(G27*28)+H27 -> 2271 | L27: =J27/2240 -> 1.0138393
A28: 1706 | B28: Pimento | C28: Mountserat | D28: Out Ports | H28: 665 | J28: =(E28*2240)+(F28*112)+(G28*28)+H28 -> 665 | L28: =J28/2240 -> 0.296875

Sheet Nevis
A1: YEAR | B1: COMMODITY_NAME | C1: FROM_LOCATION | D1: TO_LOCATION | E1: ton | F1: hh | G1: quarter | H1: lb | J1: Total Pounds | L1: WEIGHT
A2: 1706 | B2: Brown Sugar | C2: Nevis | D2: London | F2: 8791 | H2: 20 | J2: =(E2*2240)+(F2*112)+(G2*28)+(H2) -> 984612 | L2: =J2/2240 -> 439.55893
A3: 1706 | B3: Chocolate | C3: Nevis | D3: London | J3: =(E3*2240)+(F3*112)+(G3*28)+(H3) -> 0 | L3: =J3/2240 -> 0
A4: 1706 | B4: Cocoa Nuts | C4: Nevis | D4: London | F4: 13 | H4: 11 | J4: =(E4*2240)+(F4*112)+(G4*28)+(H4) -> 1467 | L4: =J4/2240 -> 0.65491071
A5: 1706 | B5: Cortex Winteranus | C5: Nevis | D5: London | J5: =(E5*2240)+(F5*112)+(G5*28)+(H5) -> 0 | L5: =J5/2240 -> 0
A6: 1706 | B6: Cotton | C6: Nevis | D6: London | H6: =13*200 -> 2600 | I6: 13 bags | J6: =(E6*2240)+(F6*112)+(G6*28)+(H6) -> 2600 | L6: =J6/2240 -> 1.1607143
A7: 1706 | B7: Elephant Teeth | C7: Nevis | D7: London | F7: 11 | G7: 2 | J7: =(E7*2240)+(F7*112)+(G7*28)+(H7) -> 1288 | L7: =J7/2240 -> 0.575
A8: 1706 | B8: Green Ginger | C8: Nevis | D8: London | H8: 28 | J8: =(E8*2240)+(F8*112)+(G8*28)+(H8) -> 28 | L8: =J8/2240 -> 0.0125
A9: 1706 | B9: Indigo | C9: Nevis | D9: London | H9: 140 | J9: =(E9*2240)+(F9*112)+(G9*28)+(H9) -> 140 | L9: =J9/2240 -> 0.0625
A10: 1706 | B10: Lignum Vitae | C10: Nevis | D10: London | J10: =(E10*2240)+(F10*112)+(G10*28)+(H10) -> 0 | L10: =J10/2240 -> 0
A11: 1706 | B11: Lime Juice | C11: Nevis | D11: London | J11: =(E11*2240)+(F11*112)+(G11*28)+(H11) -> 0 | L11: =J11/2240 -> 0
A12: 1706 | B12: Madera Wine | C12: Nevis | D12: London | J12: =(E12*2240)+(F12*112)+(G12*28)+(H12) -> 0 | L12: =J12/2240 -> 0
A13: 1706 | B13: Molasses | C13: Nevis | D13: London | J13: =(E13*2240)+(F13*112)+(G13*28)+(H13) -> 0 | L13: =J13/2240 -> 0
A14: 1706 | B14: Pickles | C14: Nevis | D14: London | J14: =(E14*2240)+(F14*112)+(G14*28)+(H14) -> 0 | L14: =J14/2240 -> 0
A15: 1706 | B15: Rum | C15: Nevis | D15: London | J15: =(E15*2240)+(F15*112)+(G15*28)+(H15) -> 0 | L15: =J15/2240 -> 0
A16: 1706 | B16: Shruff | C16: Nevis | D16: London | J16: =(E16*2240)+(F16*112)+(G16*28)+(H16) -> 0 | L16: =J16/2240 -> 0
A17: 1706 | B17: Succads | C17: Nevis | D17: London | H17: 129 | J17: =(E17*2240)+(F17*112)+(G17*28)+(H17) -> 129 | L17: =J17/2240 -> 0.057589286
A18: 1706 | B18: Sugar Loaf | C18: Nevis | D18: London | J18: =(E18*2240)+(F18*112)+(G18*28)+(H18) -> 0 | L18: =J18/2240 -> 0
A19: 1706 | B19: Tobacco | C19: Nevis | D19: London | J19: =(E19*2240)+(F19*112)+(G19*28)+(H19) -> 0 | L19: =J19/2240 -> 0
A20: 1706 | B20: Tortoise Shell | C20: Nevis | D20: London | H20: 89 | J20: =(E20*2240)+(F20*112)+(G20*28)+(H20) -> 89 | L20: =J20/2240 -> 0.039732143
A21: 1706 | B21: White Sugar | C21: Nevis | D21: London | F21: 10 | G21: 1 | H21: 7 | J21: =(E21*2240)+(F21*112)+(G21*28)+(H21) -> 1155 | L21: =J21/2240 -> 0.515625
A22: 1706 | B22: Brown Sugar | C22: Nevis | D22: Out Ports | F22: 2878 | H22: 8 | J22: =(E22*2240)+(F22*112)+(G22*28)+(H22) -> 322344 | L22: =J22/2240 -> 143.90357
A23: 1706 | B23: Chocolate | C23: Nevis | D23: Out Ports | H23: 16 | J23: =(E23*2240)+(F23*112)+(G23*28)+(H23) -> 16 | L23: =J23/2240 -> 0.0071428571
A24: 1706 | B24: Cocoa Nuts | C24: Nevis | D24: Out Ports | G24: 3 | H24: 7 | J24: =(E24*2240)+(F24*112)+(G24*28)+(H24) -> 91 | L24: =J24/2240 -> 0.040625
A25: 1706 | B25: Cotton | C25: Nevis | D25: Out Ports | H25: 1600 | J25: =(E25*2240)+(F25*112)+(G25*28)+(H25) -> 1600 | L25: =J25/2240 -> 0.71428571
A26: 1706 | B26: Elephant Teeth | C26: Nevis | D26: Out Ports | J26: =(E26*2240)+(F26*112)+(G26*28)+(H26) -> 0 | L26: =J26/2240 -> 0
A27: 1706 | B27: Indigo | C27: Nevis | D27: Out Ports | H27: 1223 | J27: =(E27*2240)+(F27*112)+(G27*28)+(H27) -> 1223 | L27: =J27/2240 -> 0.54598214
A28: 1706 | B28: Lignum Vitae | C28: Nevis | D28: Out Ports | J28: =(E28*2240)+(F28*112)+(G28*28)+(H28) -> 0 | L28: =J28/2240 -> 0
A29: 1706 | B29: Lime Juice | C29: Nevis | D29: Out Ports | H29: 4733 | I29: 469g | J29: =(E29*2240)+(F29*112)+(G29*28)+(H29) -> 4733 | L29: =J29/2240 -> 2.1129464
A30: 1706 | B30: Molasses | C30: Nevis | D30: Out Ports | J30: =(E30*2240)+(F30*112)+(G30*28)+(H30) -> 0 | L30: =J30/2240 -> 0
A31: 1706 | B31: Rum | C31: Nevis | D31: Out Ports | J31: =(E31*2240)+(F31*112)+(G31*28)+(H31) -> 0 | L31: =J31/2240 -> 0
A32: 1706 | B32: Shruff | C32: Nevis | D32: Out Ports | F32: 17 | J32: =(E32*2240)+(F32*112)+(G32*28)+(H32) -> 1904 | L32: =J32/2240 -> 0.85
A33: 1706 | B33: Succads | C33: Nevis | D33: Out Ports | J33: =(E33*2240)+(F33*112)+(G33*28)+(H33) -> 0 | L33: =J33/2240 -> 0
A34: 1706 | B34: Tortoise Shell | C34: Nevis | D34: Out Ports | J34: =(E34*2240)+(F34*112)+(G34*28)+(H34) -> 0 | L34: =J34/2240 -> 0

Sheet St Kitts
A1: YEAR | B1: COMMODITY_NAME | C1: FROM_LOCATION | D1: TO_LOCATION | E1: ton | F1: hh | G1: quarter | H1: lb | J1: Total Pounds | L1: Total Tons
A2: 1706 | B2: Annatto | C2: StKitts | D2: London | J2: =(E2*2240)+(F2*112)+(G2*28)+(H2/16) -> 0 | L2: =J2/2240 -> 0
A3: 1706 | B3: Bees Wax | C3: StKitts | D3: London | J3: =(E3*2240)+(F3*112)+(G3*28)+(H3/16) -> 0 | L3: =J3/2240 -> 0
A4: 1706 | B4: Brown Sugar | C4: StKitts | D4: London | F4: 4559 | G4: 2 | H4: 14 | J4: =(E4*2240)+(F4*112)+(G4*28)+(H4/16) -> 510664.88 | L4: =J4/2240 -> 227.97539
A5: 1706 | B5: Cocoa Nuts | C5: StKitts | D5: London | G5: 1 | H5: 24 | J5: =(E5*2240)+(F5*112)+(G5*28)+(H5/16) -> 29.5 | L5: =J5/2240 -> 0.013169643
A6: 1706 | B6: Cotton | C6: StKitts | D6: London | H6: =16*200 -> 3200 | I6: 16 bags | J6: =(E6*2240)+(F6*112)+(G6*28)+(H6/16) -> 200 | L6: =J6/2240 -> 0.089285714
A7: 1706 | B7: Dry Ginger | C7: StKitts | D7: London | J7: =(E7*2240)+(F7*112)+(G7*28)+(H7/16) -> 0 | L7: =J7/2240 -> 0
A8: 1706 | B8: Elephant Teeth | C8: StKitts | D8: London | J8: =(E8*2240)+(F8*112)+(G8*28)+(H8/16) -> 0 | L8: =J8/2240 -> 0
A9: 1706 | B9: Indigo | C9: StKitts | D9: London | J9: =(E9*2240)+(F9*112)+(G9*28)+(H9/16) -> 0 | L9: =J9/2240 -> 0
A10: 1706 | B10: Lignum Vitae | C10: StKitts | D10: London | J10: =(E10*2240)+(F10*112)+(G10*28)+(H10/16) -> 0 | L10: =J10/2240 -> 0
A11: 1706 | B11: Molasses | C11: StKitts | D11: London | J11: =(E11*2240)+(F11*112)+(G11*28)+(H11/16) -> 0 | L11: =J11/2240 -> 0
A12: 1706 | B12: Pimento | C12: StKitts | D12: London | J12: =(E12*2240)+(F12*112)+(G12*28)+(H12/16) -> 0 | L12: =J12/2240 -> 0
A13: 1706 | B13: Rum | C13: StKitts | D13: London | J13: =(E13*2240)+(F13*112)+(G13*28)+(H13/16) -> 0 | L13: =J13/2240 -> 0
A14: 1706 | B14: Shruff | C14: StKitts | D14: London | J14: =(E14*2240)+(F14*112)+(G14*28)+(H14/16) -> 0 | L14: =J14/2240 -> 0
A15: 1706 | B15: Succads | C15: StKitts | D15: London | J15: =(E15*2240)+(F15*112)+(G15*28)+(H15/16) -> 0 | L15: =J15/2240 -> 0
A16: 1706 | B16: Wood, Logwood | C16: StKitts | D16: London | J16: =(E16*2240)+(F16*112)+(G16*28)+(H16/16) -> 0 | L16: =J16/2240 -> 0
A17: 1706 | B17: Brown Sugar | C17: StKitts | D17: Out Ports | F17: 3653 | J17: =(E17*2240)+(F17*112)+(G17*28)+(H17/16) -> 409136 | L17: =J17/2240 -> 182.65
A18: 1706 | B18: Cocoa Nuts | C18: StKitts | D18: Out Ports | F18: 18 | H18: 22 | J18: =(E18*2240)+(F18*112)+(G18*28)+(H18/16) -> 2017.375 | L18: =J18/2240 -> 0.90061384
A19: 1706 | B19: Cotton | C19: StKitts | D19: Out Ports | H19: 3500 | J19: =(E19*2240)+(F19*112)+(G19*28)+(H19/16) -> 218.75 | L19: =J19/2240 -> 0.09765625
A20: 1706 | B20: Dry Ginger | C20: StKitts | D20: Out Ports | F20: 45 | J20: =(E20*2240)+(F20*112)+(G20*28)+(H20/16) -> 5040 | L20: =J20/2240 -> 2.25
A21: 1706 | B21: Guiney Grains | C21: StKitts | D21: Out Ports | F21: 2 | G21: 3 | H21: 14 | J21: =(E21*2240)+(F21*112)+(G21*28)+(H21/16) -> 308.875 | L21: =J21/2240 -> 0.13789062
A22: 1706 | B22: Indigo | C22: StKitts | D22: Out Ports | H22: 200 | J22: =(E22*2240)+(F22*112)+(G22*28)+(H22/16) -> 12.5 | L22: =J22/2240 -> 0.0055803571
A23: 1706 | B23: Molasses | C23: StKitts | D23: Out Ports | F23: 434 | G23: 2 | H23: 19 | J23: =(E23*2240)+(F23*112)+(G23*28)+(H23/16) -> 48665.188 | L23: =J23/2240 -> 21.72553
