Workbook

Sheet Master Goods Sheet
A1: Item | B1: Total London | C1: Total Outports | D1: Total
A2: Annatto | B2: =SUMIFS(Antigua!$L:$L, Antigua!$B:$B, $A2, Antigua!$D:$D, "London") + SUMIFS(Barbados!$L:$L, Barbados!$B:$B, $A2, Barbados!$D:$D, "London") + SUMIFS(Bermuda!$L:$L, Bermuda!$B:$B, $A2, Bermuda!$D:$D, "London") + SUMIFS(Carolina!$L:$L, Carolina!$B:$B, $A2, Carolina!$D:$D, "London") + SUMIFS(Jamaica!$L:$L, Jamaica!$B:$B, $A2, Jamaica!$D:$D, "London") + SUMIFS(Mountserat!$L:$L, Mountserat!$B:$B, $A2, Mountserat!$D:$D, "London") + SUMIFS(Nevis!$L:$L, Nevis!$B:$B, $A2, Nevis!$D:$D, "London") + SUMIFS(NewEngland!$J:$J, NewEngland!$A:$A, $A2, NewEngland!$B:$B, "London") -> 0.84508929 | C2: =SUMIFS(Antigua!$L:$L, Antigua!$B:$B, $A2, Antigua!$D:$D, "Out Ports") + SUMIFS(Barbados!$L:$L, Barbados!$B:$B, $A2, Barbados!$D:$D, "Out Ports") + SUMIFS(Bermuda!$L:$L, Bermuda!$B:$B, $A2, Bermuda!$D:$D, "Out Ports") + SUMIFS(Carolina!$L:$L, Carolina!$B:$B, $A2, Carolina!$D:$D, "Out Ports") + SUMIFS(Jamaica!$L:$L, Jamaica!$B:$B, $A2, Jamaica!$D:$D, "Out Ports") + SUMIFS(Mountserat!$L:$L, Mountserat!$B:$B, $A2, Mountserat!$D:$D, "Out Ports") + SUMIFS(Nevis!$L:$L, Nevis!$B:$B, $A2, Nevis!$D:$D, "Out Ports") + SUMIFS(NewEngland!$J:$J, NewEngland!$A:$A, $A2, NewEngland!$B:$B, "Out Ports") -> 0 | D2: =ROUND((B2+C2),2) -> 0.85
A3: Bayberry Wax | B3: =SUMIFS(Antigua!$L:$L, Antigua!$B:$B, $A3, Antigua!$D:$D, "London") + SUMIFS(Barbados!$L:$L, Barbados!$B:$B, $A3, Barbados!$D:$D, "London") + SUMIFS(Bermuda!$L:$L, Bermuda!$B:$B, $A3, Bermuda!$D:$D, "London") + SUMIFS(Carolina!$L:$L, Carolina!$B:$B, $A3, Carolina!$D:$D, "London") + SUMIFS(Jamaica!$L:$L, Jamaica!$B:$B, $A3, Jamaica!$D:$D, "London") + SUMIFS(Mountserat!$L:$L, Mountserat!$B:$B, $A3, Mountserat!$D:$D, "London") + SUMIFS(Nevis!$L:$L, Nevis!$B:$B, $A3, Nevis!$D:$D, "London") + SUMIFS(NewEngland!$J:$J, NewEngland!$A:$A, $A3, NewEngland!$B:$B, "London") -> 0 | C3: =SUMIFS(Antigua!$L:$L, Antigua!$B:$B, $A3, Antigua!$D:$D, "Out Ports") + SUMIFS(Barbados!$L:$L, Barbados!$B:$B, $A3, Barbados!$D:$D, "Out Ports") + SUMIFS(Bermuda!$L:$L, Bermuda!$B:$B, $A3, Bermuda!$D:$D, "Out Ports") + SUMIFS(Carolina!$L:$L, Carolina!$B:$B, $A3, Carolina!$D:$D, "Out Ports") + SUMIFS(Jamaica!$L:$L, Jamaica!$B:$B, $A3, Jamaica!$D:$D, "Out Ports") + SUMIFS(Mountserat!$L:$L, Mountserat!$B:$B, $A3, Mountserat!$D:$D, "Out Ports") + SUMIFS(Nevis!$L:$L, Nevis!$B:$B, $A3, Nevis!$D:$D, "Out Ports") + SUMIFS(NewEngland!$J:$J, NewEngland!$A:$A, $A3, NewEngland!$B:$B, "Out Ports") -> 0 | D3: =ROUND((B3+C3),2) -> 0
A4: Bees Wax | B4: =SUMIFS(Antigua!$L:$L, Antigua!$B:$B, $A4, Antigua!$D:$D, "London") + SUMIFS(Barbados!$L:$L, Barbados!$B:$B, $A4, Barbados!$D:$D, "London") + SUMIFS(Bermuda!$L:$L, Bermuda!$B:$B, $A4, Bermuda!$D:$D, "London") + SUMIFS(Carolina!$L:$L, Carolina!$B:$B, $A4, Carolina!$D:$D, "London") + SUMIFS(Jamaica!$L:$L, Jamaica!$B:$B, $A4, Jamaica!$D:$D, "London") + SUMIFS(Mountserat!$L:$L, Mountserat!$B:$B, $A4, Mountserat!$D:$D, "London") + SUMIFS(Nevis!$L:$L, Nevis!$B:$B, $A4, Nevis!$D:$D, "London") + SUMIFS(NewEngland!$J:$J, NewEngland!$A:$A, $A4, NewEngland!$B:$B, "London") -> 0 | C4: =SUMIFS(Antigua!$L:$L, Antigua!$B:$B, $A4, Antigua!$D:$D, "Out Ports") + SUMIFS(Barbados!$L:$L, Barbados!$B:$B, $A4, Barbados!$D:$D, "Out Ports") + SUMIFS(Bermuda!$L:$L, Bermuda!$B:$B, $A4, Bermuda!$D:$D, "Out Ports") + SUMIFS(Carolina!$L:$L, Carolina!$B:$B, $A4, Carolina!$D:$D, "Out Ports") + SUMIFS(Jamaica!$L:$L, Jamaica!$B:$B, $A4, Jamaica!$D:$D, "Out Ports") + SUMIFS(Mountserat!$L:$L, Mountserat!$B:$B, $A4, Mountserat!$D:$D, "Out Ports") + SUMIFS(Nevis!$L:$L, Nevis!$B:$B, $A4, Nevis!$D:$D, "Out Ports") + SUMIFS(NewEngland!$J:$J, NewEngland!$A:$A, $A4, NewEngland!$B:$B, "Out Ports") -> 0 | D4: =ROUND((B4+C4),2) -> 0
A5: Brandy | B5: =SUMIFS(Antigua!$L:$L, Antigua!$B:$B, $A5, Antigua!$D:$D, "London") + SUMIFS(Barbados!$L:$L, Barbados!$B:$B, $A5, Barbados!$D:$D, "London") + SUMIFS(Bermuda!$L:$L, Bermuda!$B:$B, $A5, Bermuda!$D:$D, "London") + SUMIFS(Carolina!$L:$L, Carolina!$B:$B, $A5, Carolina!$D:$D, "London") + SUMIFS(Jamaica!$L:$L, Jamaica!$B:$B, $A5, Jamaica!$D:$D, "London") + SUMIFS(Mountserat!$L:$L, Mountserat!$B:$B, $A5, Mountserat!$D:$D, "London") + SUMIFS(Nevis!$L:$L, Nevis!$B:$B, $A5, Nevis!$D:$D, "London") + SUMIFS(NewEngland!$J:$J, NewEngland!$A:$A, $A5, NewEngland!$B:$B, "London") -> 0 | C5: =SUMIFS(Antigua!$L:$L, Antigua!$B:$B, $A5, Antigua!$D:$D, "Out Ports") + SUMIFS(Barbados!$L:$L, Barbados!$B:$B, $A5, Barbados!$D:$D, "Out Ports") + SUMIFS(Bermuda!$L:$L, Bermuda!$B:$B, $A5, Bermuda!$D:$D, "Out Ports") + SUMIFS(Carolina!$L:$L, Carolina!$B:$B, $A5, Carolina!$D:$D, "Out Ports") + SUMIFS(Jamaica!$L:$L, Jamaica!$B:$B, $A5, Jamaica!$D:$D, "Out Ports") + SUMIFS(Mountserat!$L:$L, Mountserat!$B:$B, $A5, Mountserat!$D:$D, "Out Ports") + SUMIFS(Nevis!$L:$L, Nevis!$B:$B, $A5, Nevis!$D:$D, "Out Ports") + SUMIFS(NewEngland!$J:$J, NewEngland!$A:$A, $A5, NewEngland!$B:$B, "Out Ports") -> 0.089285714 | D5: =ROUND((B5+C5),2) -> 0.09
A6: Brown Sugar | B6: =SUMIFS(Antigua!$L:$L, Antigua!$B:$B, $A6, Antigua!$D:$D, "London") + SUMIFS(Barbados!$L:$L, Barbados!$B:$B, $A6, Barbados!$D:$D, "London") + SUMIFS(Bermuda!$L:$L, Bermuda!$B:$B, $A6, Bermuda!$D:$D, "London") + SUMIFS(Carolina!$L:$L, Carolina!$B:$B, $A6, Carolina!$D:$D, "London") + SUMIFS(Jamaica!$L:$L, Jamaica!$B:$B, $A6, Jamaica!$D:$D, "London") + SUMIFS(Mountserat!$L:$L, Mountserat!$B:$B, $A6, Mountserat!$D:$D, "London") + SUMIFS(Nevis!$L:$L, Nevis!$B:$B, $A6, Nevis!$D:$D, "London") + SUMIFS(NewEngland!$J:$J, NewEngland!$A:$A, $A6, NewEngland!$B:$B, "London") -> 14746.743 | C6: =SUMIFS(Antigua!$L:$L, Antigua!$B:$B, $A6, Antigua!$D:$D, "Out Ports") + SUMIFS(Barbados!$L:$L, Barbados!$B:$B, $A6, Barbados!$D:$D, "Out Ports") + SUMIFS(Bermuda!$L:$L, Bermuda!$B:$B, $A6, Bermuda!$D:$D, "Out Ports") + SUMIFS(Carolina!$L:$L, Carolina!$B:$B, $A6, Carolina!$D:$D, "Out Ports") + SUMIFS(Jamaica!$L:$L, Jamaica!$B:$B, $A6, Jamaica!$D:$D, "Out Ports") + SUMIFS(Mountserat!$L:$L, Mountserat!$B:$B, $A6, Mountserat!$D:$D, "Out Ports") + SUMIFS(Nevis!$L:$L, Nevis!$B:$B, $A6, Nevis!$D:$D, "Out Ports") + SUMIFS(NewEngland!$J:$J, NewEngland!$A:$A, $A6, NewEngland!$B:$B, "Out Ports") -> 6050.9638 | D6: =ROUND((B6+C6),2) -> 20797.71
A7: Cascarilla | B7: =SUMIFS(Antigua!$L:$L, Antigua!$B:$B, $A7, Antigua!$D:$D, "London") + SUMIFS(Barbados!$L:$L, Barbados!$B:$B, $A7, Barbados!$D:$D, "London") + SUMIFS(Bermuda!$L:$L, Bermuda!$B:$B, $A7, Bermuda!$D:$D, "London") + SUMIFS(Carolina!$L:$L, Carolina!$B:$B, $A7, Carolina!$D:$D, "London") + SUMIFS(Jamaica!$L:$L, Jamaica!$B:$B, $A7, Jamaica!$D:$D, "London") + SUMIFS(Mountserat!$L:$L, Mountserat!$B:$B, $A7, Mountserat!$D:$D, "London") + SUMIFS(Nevis!$L:$L, Nevis!$B:$B, $A7, Nevis!$D:$D, "London") + SUMIFS(NewEngland!$J:$J, NewEngland!$A:$A, $A7, NewEngland!$B:$B, "London") -> 1.8705357 | C7: =SUMIFS(Antigua!$L:$L, Antigua!$B:$B, $A7, Antigua!$D:$D, "Out Ports") + SUMIFS(Barbados!$L:$L, Barbados!$B:$B, $A7, Barbados!$D:$D, "Out Ports") + SUMIFS(Bermuda!$L:$L, Bermuda!$B:$B, $A7, Bermuda!$D:$D, "Out Ports") + SUMIFS(Carolina!$L:$L, Carolina!$B:$B, $A7, Carolina!$D:$D, "Out Ports") + SUMIFS(Jamaica!$L:$L, Jamaica!$B:$B, $A7, Jamaica!$D:$D, "Out Ports") + SUMIFS(Mountserat!$L:$L, Mountserat!$B:$B, $A7, Mountserat!$D:$D, "Out Ports") + SUMIFS(Nevis!$L:$L, Nevis!$B:$B, $A7, Nevis!$D:$D, "Out Ports") + SUMIFS(NewEngland!$J:$J, NewEngland!$A:$A, $A7, NewEngland!$B:$B, "Out Ports") -> 0 | D7: =ROUND((B7+C7),2) -> 1.87
A8: Chocolate | B8: =SUMIFS(Antigua!$L:$L, Antigua!$B:$B, $A8, Antigua!$D:$D, "London") + SUMIFS(Barbados!$L:$L, Barbados!$B:$B, $A8, Barbados!$D:$D, "London") + SUMIFS(Bermuda!$L:$L, Bermuda!$B:$B, $A8, Bermuda!$D:$D, "London") + SUMIFS(Carolina!$L:$L, Carolina!$B:$B, $A8, Carolina!$D:$D, "London") + SUMIFS(Jamaica!$L:$L, Jamaica!$B:$B, $A8, Jamaica!$D:$D, "London") + SUMIFS(Mountserat!$L:$L, Mountserat!$B:$B, $A8, Mountserat!$D:$D, "London") + SUMIFS(Nevis!$L:$L, Nevis!$B:$B, $A8, Nevis!$D:$D, "London") + SUMIFS(NewEngland!$J:$J, NewEngland!$A:$A, $A8, NewEngland!$B:$B, "London") -> 0.075892857 | C8: =SUMIFS(Antigua!$L:$L, Antigua!$B:$B, $A8, Antigua!$D:$D, "Out Ports") + SUMIFS(Barbados!$L:$L, Barbados!$B:$B, $A8, Barbados!$D:$D, "Out Ports") + SUMIFS(Bermuda!$L:$L, Bermuda!$B:$B, $A8, Bermuda!$D:$D, "Out Ports") + SUMIFS(Carolina!$L:$L, Carolina!$B:$B, $A8, Carolina!$D:$D, "Out Ports") + SUMIFS(Jamaica!$L:$L, Jamaica!$B:$B, $A8, Jamaica!$D:$D, "Out Ports") + SUMIFS(Mountserat!$L:$L, Mountserat!$B:$B, $A8, Mountserat!$D:$D, "Out Ports") + SUMIFS(Nevis!$L:$L, Nevis!$B:$B, $A8, Nevis!$D:$D, "Out Ports") + SUMIFS(NewEngland!$J:$J, NewEngland!$A:$A, $A8, NewEngland!$B:$B, "Out Ports") -> 0.0125 | D8: =ROUND((B8+C8),2) -> 0.09
A9: Cocheneal | B9: =SUMIFS(Antigua!$L:$L, Antigua!$B:$B, $A9, Antigua!$D:$D, "London") + SUMIFS(Barbados!$L:$L, Barbados!$B:$B, $A9, Barbados!$D:$D, "London") + SUMIFS(Bermuda!$L:$L, Bermuda!$B:$B, $A9, Bermuda!$D:$D, "London") + SUMIFS(Carolina!$L:$L, Carolina!$B:$B, $A9, Carolina!$D:$D, "London") + SUMIFS(Jamaica!$L:$L, Jamaica!$B:$B, $A9, Jamaica!$D:$D, "London") + SUMIFS(Mountserat!$L:$L, Mountserat!$B:$B, $A9, Mountserat!$D:$D, "London") + SUMIFS(Nevis!$L:$L, Nevis!$B:$B, $A9, Nevis!$D:$D, "London") + SUMIFS(NewEngland!$J:$J, NewEngland!$A:$A, $A9, NewEngland!$B:$B, "London") -> 0.055803571 | C9: =SUMIFS(Antigua!$L:$L, Antigua!$B:$B, $A9, Antigua!$D:$D, "Out Ports") + SUMIFS(Barbados!$L:$L, Barbados!$B:$B, $A9, Barbados!$D:$D, "Out Ports") + SUMIFS(Bermuda!$L:$L, Bermuda!$B:$B, $A9, Bermuda!$D:$D, "Out Ports") + SUMIFS(Carolina!$L:$L, Carolina!$B:$B, $A9, Carolina!$D:$D, "Out Ports") + SUMIFS(Jamaica!$L:$L, Jamaica!$B:$B, $A9, Jamaica!$D:$D, "Out Ports") + SUMIFS(Mountserat!$L:$L, Mountserat!$B:$B, $A9, Mountserat!$D:$D, "Out Ports") + SUMIFS(Nevis!$L:$L, Nevis!$B:$B, $A9, Nevis!$D:$D, "Out Ports") + SUMIFS(NewEngland!$J:$J, NewEngland!$A:$A, $A9, NewEngland!$B:$B, "Out Ports") -> 0 | D9: =ROUND((B9+C9),2) -> 0.06
A10: Cocoa Nuts | B10: =SUMIFS(Antigua!$L:$L, Antigua!$B:$B, $A10, Antigua!$D:$D, "London") + SUMIFS(Barbados!$L:$L, Barbados!$B:$B, $A10, Barbados!$D:$D, "London") + SUMIFS(Bermuda!$L:$L, Bermuda!$B:$B, $A10, Bermuda!$D:$D, "London") + SUMIFS(Carolina!$L:$L, Carolina!$B:$B, $A10, Carolina!$D:$D, "London") + SUMIFS(Jamaica!$L:$L, Jamaica!$B:$B, $A10, Jamaica!$D:$D, "London") + SUMIFS(Mountserat!$L:$L, Mountserat!$B:$B, $A10, Mountserat!$D:$D, "London") + SUMIFS(Nevis!$L:$L, Nevis!$B:$B, $A10, Nevis!$D:$D, "London") + SUMIFS(NewEngland!$J:$J, NewEngland!$A:$A, $A10, NewEngland!$B:$B, "London") -> 74.829018 | C10: =SUMIFS(Antigua!$L:$L, Antigua!$B:$B, $A10, Antigua!$D:$D, "Out Ports") + SUMIFS(Barbados!$L:$L, Barbados!$B:$B, $A10, Barbados!$D:$D, "Out Ports") + SUMIFS(Bermuda!$L:$L, Bermuda!$B:$B, $A10, Bermuda!$D:$D, "Out Ports") + SUMIFS(Carolina!$L:$L, Carolina!$B:$B, $A10, Carolina!$D:$D, "Out Ports") + SUMIFS(Jamaica!$L:$L, Jamaica!$B:$B, $A10, Jamaica!$D:$D, "Out Ports") + SUMIFS(Mountserat!$L:$L, Mountserat!$B:$B, $A10, Mountserat!$D:$D, "Out Ports") + SUMIFS(Nevis!$L:$L, Nevis!$B:$B, $A10, Nevis!$D:$D, "Out Ports") + SUMIFS(NewEngland!$J:$J, NewEngland!$A:$A, $A10, NewEngland!$B:$B, "Out Ports") -> 123.85446 | D10: =ROUND((B10+C10),2) -> 198.68
A11: Cotton | B11: =SUMIFS(Antigua!$L:$L, Antigua!$B:$B, $A11, Antigua!$D:$D, "London") + SUMIFS(Barbados!$L:$L, Barbados!$B:$B, $A11, Barbados!$D:$D, "London") + SUMIFS(Bermuda!$L:$L, Bermuda!$B:$B, $A11, Bermuda!$D:$D, "London") + SUMIFS(Carolina!$L:$L, Carolina!$B:$B, $A11, Carolina!$D:$D, "London") + SUMIFS(Jamaica!$L:$L, Jamaica!$B:$B, $A11, Jamaica!$D:$D, "London") + SUMIFS(Mountserat!$L:$L, Mountserat!$B:$B, $A11, Mountserat!$D:$D, "London") + SUMIFS(Nevis!$L:$L, Nevis!$B:$B, $A11, Nevis!$D:$D, "London") + SUMIFS(NewEngland!$J:$J, NewEngland!$A:$A, $A11, NewEngland!$B:$B, "London") -> 157.22232 | C11: =SUMIFS(Antigua!$L:$L, Antigua!$B:$B, $A11, Antigua!$D:$D, "Out Ports") + SUMIFS(Barbados!$L:$L, Barbados!$B:$B, $A11, Barbados!$D:$D, "Out Ports") + SUMIFS(Bermuda!$L:$L, Bermuda!$B:$B, $A11, Bermuda!$D:$D, "Out Ports") + SUMIFS(Carolina!$L:$L, Carolina!$B:$B, $A11, Carolina!$D:$D, "Out Ports") + SUMIFS(Jamaica!$L:$L, Jamaica!$B:$B, $A11, Jamaica!$D:$D, "Out Ports") + SUMIFS(Mountserat!$L:$L, Mountserat!$B:$B, $A11, Mountserat!$D:$D, "Out Ports") + SUMIFS(Nevis!$L:$L, Nevis!$B:$B, $A11, Nevis!$D:$D, "Out Ports") + SUMIFS(NewEngland!$J:$J, NewEngland!$A:$A, $A11, NewEngland!$B:$B, "Out Ports") -> 147.21473 | D11: =ROUND((B11+C11),2) -> 304.44
A12: Dry Ginger | B12: =SUMIFS(Antigua!$L:$L, Antigua!$B:$B, $A12, Antigua!$D:$D, "London") + SUMIFS(Barbados!$L:$L, Barbados!$B:$B, $A12, Barbados!$D:$D, "London") + SUMIFS(Bermuda!$L:$L, Bermuda!$B:$B, $A12, Bermuda!$D:$D, "London") + SUMIFS(Carolina!$L:$L, Carolina!$B:$B, $A12, Carolina!$D:$D, "London") + SUMIFS(Jamaica!$L:$L, Jamaica!$B:$B, $A12, Jamaica!$D:$D, "London") + SUMIFS(Mountserat!$L:$L, Mountserat!$B:$B, $A12, Mountserat!$D:$D, "London") + SUMIFS(Nevis!$L:$L, Nevis!$B:$B, $A12, Nevis!$D:$D, "London") + SUMIFS(NewEngland!$J:$J, NewEngland!$A:$A, $A12, NewEngland!$B:$B, "London") -> 653.13616 | C12: =SUMIFS(Antigua!$L:$L, Antigua!$B:$B, $A12, Antigua!$D:$D, "Out Ports") + SUMIFS(Barbados!$L:$L, Barbados!$B:$B, $A12, Barbados!$D:$D, "Out Ports") + SUMIFS(Bermuda!$L:$L, Bermuda!$B:$B, $A12, Bermuda!$D:$D, "Out Ports") + SUMIFS(Carolina!$L:$L, Carolina!$B:$B, $A12, Carolina!$D:$D, "Out Ports") + SUMIFS(Jamaica!$L:$L, Jamaica!$B:$B, $A12, Jamaica!$D:$D, "Out Ports") + SUMIFS(Mountserat!$L:$L, Mountserat!$B:$B, $A12, Mountserat!$D:$D, "Out Ports") + SUMIFS(Nevis!$L:$L, Nevis!$B:$B, $A12, Nevis!$D:$D, "Out Ports") + SUMIFS(NewEngland!$J:$J, NewEngland!$A:$A, $A12, NewEngland!$B:$B, "Out Ports") -> 50.662946 | D12: =ROUND((B12+C12),2) -> 703.8
A13: Elephant Teeth | B13: =SUMIFS(Antigua!$L:$L, Antigua!$B:$B, $A13, Antigua!$D:$D, "London") + SUMIFS(Barbados!$L:$L, Barbados!$B:$B, $A13, Barbados!$D:$D, "London") + SUMIFS(Bermuda!$L:$L, Bermuda!$B:$B, $A13, Bermuda!$D:$D, "London") + SUMIFS(Carolina!$L:$L, Carolina!$B:$B, $A13, Carolina!$D:$D, "London") + SUMIFS(Jamaica!$L:$L, Jamaica!$B:$B, $A13, Jamaica!$D:$D, "London") + SUMIFS(Mountserat!$L:$L, Mountserat!$B:$B, $A13, Mountserat!$D:$D, "London") + SUMIFS(Nevis!$L:$L, Nevis!$B:$B, $A13, Nevis!$D:$D, "London") + SUMIFS(NewEngland!$J:$J, NewEngland!$A:$A, $A13, NewEngland!$B:$B, "London") -> 8.9084821 | C13: =SUMIFS(Antigua!$L:$L, Antigua!$B:$B, $A13, Antigua!$D:$D, "Out Ports") + SUMIFS(Barbados!$L:$L, Barbados!$B:$B, $A13, Barbados!$D:$D, "Out Ports") + SUMIFS(Bermuda!$L:$L, Bermuda!$B:$B, $A13, Bermuda!$D:$D, "Out Ports") + SUMIFS(Carolina!$L:$L, Carolina!$B:$B, $A13, Carolina!$D:$D, "Out Ports") + SUMIFS(Jamaica!$L:$L, Jamaica!$B:$B, $A13, Jamaica!$D:$D, "Out Ports") + SUMIFS(Mountserat!$L:$L, Mountserat!$B:$B, $A13, Mountserat!$D:$D, "Out Ports") + SUMIFS(Nevis!$L:$L, Nevis!$B:$B, $A13, Nevis!$D:$D, "Out Ports") + SUMIFS(NewEngland!$J:$J, NewEngland!$A:$A, $A13, NewEngland!$B:$B, "Out Ports") -> 9.2424107 | D13: =ROUND((B13+C13),2) -> 18.15
... A36: Wood, Nicaragua | B36: =SUMIFS(Antigua!$L:$L, Antigua!$B:$B, $A36, Antigua!$D:$D, "London") + SUMIFS(Barbados!$L:$L, Barbados!$B:$B, $A36, Barbados!$D:$D, "London") + SUMIFS(Bermuda!$L:$L, Bermuda!$B:$B, $A36, Bermuda!$D:$D, "London") + SUMIFS(Carolina!$L:$L, Carolina!$B:$B, $A36, Carolina!$D:$D, "London") + SUMIFS(Jamaica!$L:$L, Jamaica!$B:$B, $A36, Jamaica!$D:$D, "London") + SUMIFS(Mountserat!$L:$L, Mountserat!$B:$B, $A36, Mountserat!$D:$D, "London") + SUMIFS(Nevis!$L:$L, Nevis!$B:$B, $A36, Nevis!$D:$D, "London") + SUMIFS(NewEngland!$J:$J, NewEngland!$A:$A, $A36, NewEngland!$B:$B, "London") -> 0 | C36: =SUMIFS(Antigua!$L:$L, Antigua!$B:$B, $A36, Antigua!$D:$D, "Out Ports") + SUMIFS(Barbados!$L:$L, Barbados!$B:$B, $A36, Barbados!$D:$D, "Out Ports") + SUMIFS(Bermuda!$L:$L, Bermuda!$B:$B, $A36, Bermuda!$D:$D, "Out Ports") + SUMIFS(Carolina!$L:$L, Carolina!$B:$B, $A36, Carolina!$D:$D, "Out Ports") + SUMIFS(Jamaica!$L:$L, Jamaica!$B:$B, $A36, Jamaica!$D:$D, "Out Ports") + SUMIFS(Mountserat!$L:$L, Mountserat!$B:$B, $A36, Mountserat!$D:$D, "Out Ports") + SUMIFS(Nevis!$L:$L, Nevis!$B:$B, $A36, Nevis!$D:$D, "Out Ports") + SUMIFS(NewEngland!$J:$J, NewEngland!$A:$A, $A36, NewEngland!$B:$B, "Out Ports") -> 33.449554 | D36: =ROUND((B36+C36),2) -> 33.45

Sheet Antigua
A1: YEAR | B1: COMMODITY_NAME | C1: FROM_LOCATION | D1: TO_LOCATION | E1: ton | F1: hh | G1: quarter | H1: lb | J1: Total Pounds | L1: WEIGHT
A2: 1710 | B2: Annatto | C2: Antigua | D2: London | H2: 1325 | J2: =(E2*2240)+(F2*112)+(G2*28)+H2 -> 1325 | L2: =J2/2240 -> 0.59151786
A3: 1710 | B3: Brown Sugar | C3: Antigua | D3: London | F3: 93845 | G3: 1 | H3: 11 | J3: =(E3*2240)+(F3*112)+(G3*28)+H3 -> 10510679 | L3: =J3/2240 -> 4692.2674
A4: 1710 | B4: Chocolate | C4: Antigua | D4: London | H4: 30 | J4: =(E4*2240)+(F4*112)+(G4*28)+H4 -> 30 | L4: =J4/2240 -> 0.013392857
A5: 1710 | B5: Cocoa Nuts | C5: Antigua | D5: London | F5: 69 | H5: 8 | J5: =(E5*2240)+(F5*112)+(G5*28)+H5 -> 7736 | L5: =J5/2240 -> 3.4535714
A6: 1710 | B6: Cotton | C6: Antigua | D6: London | H6: 212078 | J6: =(E6*2240)+(F6*112)+(G6*28)+H6 -> 212078 | L6: =J6/2240 -> 94.677679
A7: 1710 | B7: Dry Ginger | C7: Antigua | D7: London | F7: 2647 | G7: 2 | H7: 21 | J7: =(E7*2240)+(F7*112)+(G7*28)+H7 -> 296541 | L7: =J7/2240 -> 132.38438
A8: 1710 | B8: Elephant Teeth | C8: Antigua | D8: London | F8: 91 | G8: 2 | H8: 14 | J8: =(E8*2240)+(F8*112)+(G8*28)+H8 -> 10262 | L8: =J8/2240 -> 4.58125
A9: 1710 | B9: Indigo | C9: Antigua | D9: London | H9: 2417 | J9: =(E9*2240)+(F9*112)+(G9*28)+H9 -> 2417 | L9: =J9/2240 -> 1.0790179
A10: 1710 | B10: Lemon Water | C10: Antigua | D10: London | J10: =(E10*2240)+(F10*112)+(G10*28)+H10 -> 0 | L10: =J10/2240 -> 0
A11: 1710 | B11: Lignum Vitae | C11: Antigua | D11: London | F11: 5023 | J11: =(E11*2240)+(F11*112)+(G11*28)+H11 -> 562576 | L11: =J11/2240 -> 251.15
A12: 1710 | B12: Lime Juice | C12: Antigua | D12: London | J12: =(E12*2240)+(F12*112)+(G12*28)+H12 -> 0 | L12: =J12/2240 -> 0
A13: 1710 | B13: Madera Wine | C13: Antigua | D13: London | H13: 18225 | I13: 0.29233796 | J13: =(E13*2240)+(F13*112)+(G13*28)+H13 -> 18225 | L13: =J13/2240 -> 8.1361607
A14: 1710 | B14: Molasses | C14: Antigua | D14: London | E14: 127 | F14: 17 | G14: 1 | H14: 21 | J14: =(E14*2240)+(F14*112)+(G14*28)+H14 -> 286433 | L14: =J14/2240 -> 127.87188
A15: 1710 | B15: Oyl Turpyn | C15: Antigua | D15: London | F15: 23 | G15: 2 | H15: 10 | J15: =(E15*2240)+(F15*112)+(G15*28)+H15 -> 2642 | L15: =J15/2240 -> 1.1794643
A16: 1710 | B16: Pimento | C16: Antigua | D16: London | H16: 483 | J16: =(E16*2240)+(F16*112)+(G16*28)+H16 -> 483 | L16: =J16/2240 -> 0.215625
A17: 1710 | B17: Rice | C17: Antigua | D17: London | F17: 8 | G17: 2 | J17: =(E17*2240)+(F17*112)+(G17*28)+H17 -> 952 | L17: =J17/2240 -> 0.425
A18: 1710 | B18: Rum | C18: Antigua | D18: London | H18: 33979 | I18: 3397g | J18: =(E18*2240)+(F18*112)+(G18*28)+H18 -> 33979 | L18: =J18/2240 -> 15.169196
A19: 1710 | B19: Shruff | C19: Antigua | D19: London | F19: 22 | J19: =(E19*2240)+(F19*112)+(G19*28)+H19 -> 2464 | L19: =J19/2240 -> 1.1
A20: 1710 | B20: Succands | C20: Antigua | D20: London | H20: 376 | J20: =(E20*2240)+(F20*112)+(G20*28)+H20 -> 376 | L20: =J20/2240 -> 0.16785714
A21: 1710 | B21: Tobacco | C21: Antigua | D21: London | J21: =(E21*2240)+(F21*112)+(G21*28)+H21 -> 0 | L21: =J21/2240 -> 0
A22: 1710 | B22: Tortoise Shell | C22: Antigua | D22: London | H22: 21 | J22: =(E22*2240)+(F22*112)+(G22*28)+H22 -> 21 | L22: =J22/2240 -> 0.009375
A23: 1710 | B23: Turpentine Common | C23: Antigua | D23: London | F23: 161 | G23: 1 | H23: 0 | J23: =(E23*2240)+(F23*112)+(G23*28)+H23 -> 18060 | L23: =J23/2240 -> 8.0625
A24: 1710 | B24: White Sugar | C24: Antigua | D24: London | F24: 52 | G24: 3 | J24: =(E24*2240)+(F24*112)+(G24*28)+H24 -> 5908 | L24: =J24/2240 -> 2.6375
A25: 1710 | B25: Wood, Fustick | C25: Antigua | D25: London | E25: 2 | F25: 13 | J25: =(E25*2240)+(F25*112)+(G25*28)+H25 -> 5936 | L25: =J25/2240 -> 2.65
A26: 1710 | B26: Wood, Logwood | C26: Antigua | D26: London | E26: 6 | F26: 15 | G26: 3 | J26: =(E26*2240)+(F26*112)+(G26*28)+H26 -> 15204 | L26: =J26/2240 -> 6.7875
A27: 1710 | B27: Brown Sugar | C27: Antigua | D27: Out Ports | F27: 18619 | H27: 22 | J27: =(E27*2240)+(F27*112)+(G27*28)+H27 -> 2085350 | L27: =J27/2240 -> 930.95982
A28: 1710 | B28: Cocoa Nuts | C28: Antigua | D28: Out Ports | F28: 56 | G28: 2 | H28: 24 | J28: =(E28*2240)+(F28*112)+(G28*28)+H28 -> 6352 | L28: =J28/2240 -> 2.8357143
A29: 1710 | B29: Cocoa Paste | C29: Antigua | D29: Out Ports | H29: 24 | J29: =(E29*2240)+(F29*112)+(G29*28)+H29 -> 24 | L29: =J29/2240 -> 0.010714286
A30: 1710 | B30: Cotton | C30: Antigua | D30: Out Ports | H30: 98812 | J30: =(E30*2240)+(F30*112)+(G30*28)+H30 -> 98812 | L30: =J30/2240 -> 44.1125
A31: 1710 | B31: Dry Ginger | C31: Antigua | D31: Out Ports | F31: 68 | H31: 20 | J31: =(E31*2240)+(F31*112)+(G31*28)+H31 -> 7636 | L31: =J31/2240 -> 3.4089286
A32: 1710 | B32: Elephant Teeth | C32: Antigua | D32: Out Ports | H32: 17 | J32: =(E32*2240)+(F32*112)+(G32*28)+H32 -> 17 | L32: =J32/2240 -> 0.0075892857
A33: 1710 | B33: Indigo | C33: Antigua | D33: Out Ports | H33: 8980 | J33: =(E33*2240)+(F33*112)+(G33*28)+H33 -> 8980 | L33: =J33/2240 -> 4.0089286
A34: 1710 | B34: Lignum Vitae | C34: Antigua | D34: Out Ports | F34: 677 | G34: 3 | H34: 15 | J34: =(E34*2240)+(F34*112)+(G34*28)+H34 -> 75923 | L34: =J34/2240 -> 33.894196
A35: 1710 | B35: Lime Juice | C35: Antigua | D35: Out Ports | H35: 770 | I35: 77g | J35: =(E35*2240)+(F35*112)+(G35*28)+H35 -> 770 | L35: =J35/2240 -> 0.34375
A36: 1710 | B36: Madera Wine | C36: Antigua | D36: Out Ports | H36: 380 | I36: 38g | J36: =(E36*2240)+(F36*112)+(G36*28)+H36 -> 380 | L36: =J36/2240 -> 0.16964286
A37: 1710 | B37: Molasses | C37: Antigua | D37: Out Ports | F37: 1018 | H37: 11 | J37: =(E37*2240)+(F37*112)+(G37*28)+H37 -> 114027 | L37: =J37/2240 -> 50.904911
A38: 1710 | B38: Rice | C38: Antigua | D38: Out Ports | J38: =(E38*2240)+(F38*112)+(G38*28)+H38 -> 0 | L38: =J38/2240 -> 0
A39: 1710 | B39: Rum | C39: Antigua | D39: Out Ports | H39: 13348 | I39: 1334.5g | J39: =(E39*2240)+(F39*112)+(G39*28)+H39 -> 13348 | L39: =J39/2240 -> 5.9589286
A40: 1710 | B40: Shruff | C40: Antigua | D40: Out Ports | F40: 3 | H40: 1 | J40: =(E40*2240)+(F40*112)+(G40*28)+H40 -> 337 | L40: =J40/2240 -> 0.15044643
...

Sheet Barbados
A1: YEAR | B1: COMMODITY_NAME | C1: FROM_LOCATION | D1: TO_LOCATION | E1: ton | F1: hh | G1: quarter | H1: lb | J1: Total Pounds | L1: WEIGHT
A2: 1710 | B2: Aloes Epatica | C2: Barbados | D2: London | H2: 9762 | J2: =(E2*2240)+(F2*112)+(G2*28)+H2 -> 9762 | L2: =J2/2240 -> 4.3580357
A3: 1710 | B3: Annatto | C3: Barbados | D3: London | H3: 268 | J3: =(E3*2240)+(F3*112)+(G3*28)+H3 -> 268 | L3: =J3/2240 -> 0.11964286
A4: 1710 | B4: Barrel Staves | C4: Barbados | D4: London | J4: =(E4*2240)+(F4*112)+(G4*28)+H4 -> 0 | L4: =J4/2240 -> 0
A5: 1710 | B5: Brazilia | C5: Barbados | D5: London | J5: =(E5*2240)+(F5*112)+(G5*28)+H5 -> 0 | L5: =J5/2240 -> 0
A6: 1710 | B6: Brown Sugar | C6: Barbados | D6: London | F6: 129655 | G6: 1 | H6: 6 | J6: =(E6*2240)+(F6*112)+(G6*28)+H6 -> 14521394 | L6: =J6/2240 -> 6482.7652
A7: 1710 | B7: Cassia Fistula | C7: Barbados | D7: London | H7: 3688 | J7: =(E7*2240)+(F7*112)+(G7*28)+H7 -> 3688 | L7: =J7/2240 -> 1.6464286
A8: 1710 | B8: Chocolate | C8: Barbados | D8: London | H8: 80 | J8: =(E8*2240)+(F8*112)+(G8*28)+H8 -> 80 | L8: =J8/2240 -> 0.035714286
A9: 1710 | B9: Cocheneal | C9: Barbados | D9: London | J9: =(E9*2240)+(F9*112)+(G9*28)+H9 -> 0 | L9: =J9/2240 -> 0
A10: 1710 | B10: Cocoa Nuts | C10: Barbados | D10: London | F10: 81 | G10: 2 | H10: 4 | J10: =(E10*2240)+(F10*112)+(G10*28)+H10 -> 9132 | L10: =J10/2240 -> 4.0767857
A11: 1710 | B11: Cocoa Paste | C11: Barbados | D11: London | H11: 16 | J11: =(E11*2240)+(F11*112)+(G11*28)+H11 -> 16 | L11: =J11/2240 -> 0.0071428571
A12: 1710 | B12: Cortex Winteranus | C12: Barbados | D12: London | H12: 19 | J12: =(E12*2240)+(F12*112)+(G12*28)+H12 -> 19 | L12: =J12/2240 -> 0.0084821429
A13: 1710 | B13: Cotton | C13: Barbados | D13: London | H13: =407.5*200 -> 81500 | I13: 407.5 bags | J13: =(E13*2240)+(F13*112)+(G13*28)+H13 -> 81500 | L13: =J13/2240 -> 36.383929
A14: 1710 | B14: Dry Ginger | C14: Barbados | D14: London | F14: 7833 | G14: 2 | H14: 8 | J14: =(E14*2240)+(F14*112)+(G14*28)+H14 -> 877360 | L14: =J14/2240 -> 391.67857
A15: 1710 | B15: Elephant Teeth | C15: Barbados | D15: London | F15: 1 | G15: 1 | H15: 25 | J15: =(E15*2240)+(F15*112)+(G15*28)+H15 -> 165 | L15: =J15/2240 -> 0.073660714
A16: 1710 | B16: Green Ginger | C16: Barbados | D16: London | J16: =(E16*2240)+(F16*112)+(G16*28)+H16 -> 0 | L16: =J16/2240 -> 0
A17: 1710 | B17: Hemp | C17: Barbados | D17: London | J17: =(E17*2240)+(F17*112)+(G17*28)+H17 -> 0 | L17: =J17/2240 -> 0
A18: 1710 | B18: Indigo | C18: Barbados | D18: London | H18: 1771 | J18: =(E18*2240)+(F18*112)+(G18*28)+H18 -> 1771 | L18: =J18/2240 -> 0.790625
A19: 1710 | B19: Lemon Water | C19: Barbados | D19: London | J19: =(E19*2240)+(F19*112)+(G19*28)+H19 -> 0 | L19: =J19/2240 -> 0
A20: 1710 | B20: Lignum Vitae | C20: Barbados | D20: London | F20: 79 | J20: =(E20*2240)+(F20*112)+(G20*28)+H20 -> 8848 | L20: =J20/2240 -> 3.95
A21: 1710 | B21: Lime Juice | C21: Barbados | D21: London | H21: 55144 | I21: 5513g | J21: =(E21*2240)+(F21*112)+(G21*28)+H21 -> 55144 | L21: =J21/2240 -> 24.617857
A22: 1710 | B22: Loaf Sugar | C22: Barbados | D22: London | J22: =(E22*2240)+(F22*112)+(G22*28)+H22 -> 0 | L22: =J22/2240 -> 0
A23: 1710 | B23: Madera Wine | C23: Barbados | D23: London | H23: 48352 | I23: 0.79219907 | J23: =(E23*2240)+(F23*112)+(G23*28)+H23 -> 48352 | L23: =J23/2240 -> 21.585714
A24: 1710 | B24: Molasses | C24: Barbados | D24: London | F24: 597 | G24: 1 | H24: 7 | J24: =(E24*2240)+(F24*112)+(G24*28)+H24 -> 66899 | L24: =J24/2240 -> 29.865625
A25: 1710 | B25: Oranges | C25: Barbados | D25: London | J25: =(E25*2240)+(F25*112)+(G25*28)+H25 -> 0 | L25: =J25/2240 -> 0
A26: 1710 | B26: Pimento | C26: Barbados | D26: London | H26: 196 | J26: =(E26*2240)+(F26*112)+(G26*28)+H26 -> 196 | L26: =J26/2240 -> 0.0875
A27: 1710 | B27: Rice | C27: Barbados | D27: London | F27: 20 | G27: 3 | J27: =(E27*2240)+(F27*112)+(G27*28)+H27 -> 2324 | L27: =J27/2240 -> 1.0375
A28: 1710 | B28: Rum | C28: Barbados | D28: London | H28: 90948 | I28: 9092.5g | J28: =(E28*2240)+(F28*112)+(G28*28)+H28 -> 90948 | L28: =J28/2240 -> 40.601786
A29: 1710 | B29: Shruff | C29: Barbados | D29: London | F29: 125 | G29: 3 | H29: 21 | J29: =(E29*2240)+(F29*112)+(G29*28)+H29 -> 14105 | L29: =J29/2240 -> 6.296875
A30: 1710 | B30: Snuff | C30: Barbados | D30: London | J30: =(E30*2240)+(F30*112)+(G30*28)+H30 -> 0 | L30: =J30/2240 -> 0
A31: 1710 | B31: Succands | C31: Barbados | D31: London | H31: 838 | J31: =(E31*2240)+(F31*112)+(G31*28)+H31 -> 838 | L31: =J31/2240 -> 0.37410714
A32: 1710 | B32: Tobacco | C32: Barbados | D32: London | J32: =(E32*2240)+(F32*112)+(G32*28)+H32 -> 0 | L32: =J32/2240 -> 0
A33: 1710 | B33: Tortoise Shell | C33: Barbados | D33: London | H33: 75 | J33: =(E33*2240)+(F33*112)+(G33*28)+H33 -> 75 | L33: =J33/2240 -> 0.033482143
A34: 1710 | B34: White Sugar | C34: Barbados | D34: London | F34: 926 | G34: 2 | H34: 27 | J34: =(E34*2240)+(F34*112)+(G34*28)+H34 -> 103795 | L34: =J34/2240 -> 46.337054
A35: 1710 | B35: Wood, Fustick | C35: Barbados | D35: London | E35: 1 | F35: 12 | G35: 3 | J35: =(E35*2240)+(F35*112)+(G35*28)+H35 -> 3668 | L35: =J35/2240 -> 1.6375
A36: 1710 | B36: Wood, Logwood | C36: Barbados | D36: London | J36: =(E36*2240)+(F36*112)+(G36*28)+H36 -> 0 | L36: =J36/2240 -> 0
A37: 1710 | B37: Wood, Redwood | C37: Barbados | D37: London | J37: =(E37*2240)+(F37*112)+(G37*28)+H37 -> 0 | L37: =J37/2240 -> 0
A38: 1710 | B38: Brandy | C38: Barbados | D38: Out Ports | H38: 200 | I38: 20g | J38: =(E38*2240)+(F38*112)+(G38*28)+H38 -> 200 | L38: =J38/2240 -> 0.089285714
A39: 1710 | B39: Brown Sugar | C39: Barbados | D39: Out Ports | F39: 20651 | G39: 3 | H39: 5 | J39: =(E39*2240)+(F39*112)+(G39*28)+H39 -> 2313001 | L39: =J39/2240 -> 1032.5897
A40: 1710 | B40: Chocolate | C40: Barbados | D40: Out Ports | H40: 28 | J40: =(E40*2240)+(F40*112)+(G40*28)+H40 -> 28 | L40: =J40/2240 -> 0.0125
...

Sheet Bermuda
A1: YEAR | B1: COMMODITY_NAME | C1: FROM_LOCATION | D1: TO_LOCATION | E1: ton | F1: hh | G1: quarter | H1: lb | J1: Total Pounds | L1: WEIGHT
A2: 1710 | B2: Indigo | C2: Bermuda | D2: Out Ports | J2: =(E2*2240)+(F2*112)+(G2*28)+H2 -> 0 | L2: =J2/2240 -> 0
A3: 1710 | B3: Wood, Logwood | C3: Bermuda | D3: Out Ports | J3: =(E3*2240)+(F3*112)+(G3*28)+H3 -> 0 | L3: =J3/2240 -> 0
A4: 1710 | B4: Shruff | C4: Bermuda | D4: Out Ports | J4: =(E4*2240)+(F4*112)+(G4*28)+H4 -> 0 | L4: =J4/2240 -> 0
A5: 1710 | B5: Succands | C5: Bermuda | D5: Out Ports | J5: =(E5*2240)+(F5*112)+(G5*28)+H5 -> 0 | L5: =J5/2240 -> 0
A6: 1710 | B6: Cotton | C6: Bermuda | D6: Out Ports | J6: =(E6*2240)+(F6*112)+(G6*28)+H6 -> 0 | L6: =J6/2240 -> 0
A7: 1710 | B7: Cocoa Nuts | C7: Bermuda | D7: Out Ports | J7: =(E7*2240)+(F7*112)+(G7*28)+H7 -> 0 | L7: =J7/2240 -> 0

Sheet Carolina
A1: YEAR | B1: COMMODITY_NAME | C1: FROM_LOCATION | D1: TO_LOCATION | E1: ton | F1: hh | G1: quarter | H1: lb | J1: Total Pounds | L1: WEIGHT | N1: Not Sugar | P1: Sugar
A2: 1710 | B2: Elephant Teeth | D2: London | J2: =(E2*2240)+(F2*112)+(G2*28)+H2 -> 0 | L2: =J2/2240 -> 0 | N2: =L2+L4+L5+L6+L8+L9+L11+L12+L14+L15+L17 -> 0 | P2: =L13 -> 0
A3: 1710 | B3: Dry Ginger | D3: London | J3: =(E3*2240)+(F3*112)+(G3*28)+H3 -> 0 | L3: =J3/2240 -> 0
A4: 1710 | B4: Rice | D4: London | J4: =(E4*2240)+(F4*112)+(G4*28)+H4 -> 0 | L4: =J4/2240 -> 0
A5: 1710 | B5: Tobacco | D5: London | J5: =(E5*2240)+(F5*112)+(G5*28)+H5 -> 0 | L5: =J5/2240 -> 0
A6: 1710 | B6: Chocolate | D6: London | J6: =(E6*2240)+(F6*112)+(G6*28)+H6 -> 0 | L6: =J6/2240 -> 0
A7: 1710 | B7: Brown Sugar | D7: London | J7: =(E7*2240)+(F7*112)+(G7*28)+H7 -> 0 | L7: =J7/2240 -> 0
A8: 1710 | B8: Cocoa Nuts | D8: London | J8: =(E8*2240)+(F8*112)+(G8*28)+H8 -> 0 | L8: =J8/2240 -> 0
A9: 1710 | B9: Tortoise Shell | D9: London | J9: =(E9*2240)+(F9*112)+(G9*28)+H9 -> 0 | L9: =J9/2240 -> 0
A10: 1710 | B10: Cortex Winteranus | D10: Out Ports | J10: =(E10*2240)+(F10*112)+(G10*28)+H10 -> 0 | L10: =J10/2240 -> 0
A11: 1710 | B11: Elephant Teeth | D11: Out Ports | J11: =(E11*2240)+(F11*112)+(G11*28)+H11 -> 0 | L11: =J11/2240 -> 0
A12: 1710 | B12: Indigo | D12: Out Ports | J12: =(E12*2240)+(F12*112)+(G12*28)+H12 -> 0 | L12: =J12/2240 -> 0
A13: 1710 | B13: Rice | D13: Out Ports | J13: =(E13*2240)+(F13*112)+(G13*28)+H13 -> 0 | L13: =J13/2240 -> 0
A14: 1710 | B14: Brown Sugar | D14: Out Ports | J14: =(E14*2240)+(F14*112)+(G14*28)+H14 -> 0 | L14: =J14/2240 -> 0
... A23: 1710 | B23: Rum | D23: London | J23: =(E23*2240)+(F23*112)+(G23*28)+H23 -> 0 | L23: =J23/2240 -> 0

Sheet Jamaica
A1: YEAR | B1: COMMODITY_NAME | C1: FROM_LOCATION | D1: TO_LOCATION | E1: ton | F1: hh | G1: quarter | H1: lb | J1: Total Pounds | L1: WEIGHT
A2: 1710 | B2: Annatto | C2: Jamaica | D2: London | H2: 300 | J2: =(E2*2240)+(F2*112)+(G2*28)+H2 -> 300 | L2: =J2/2240 -> 0.13392857
A3: 1710 | B3: Bees Wax | C3: Jamaica | D3: London | J3: =(E3*2240)+(F3*112)+(G3*28)+H3 -> 0 | L3: =J3/2240 -> 0
A4: 1710 | B4: Brown Sugar | C4: Jamaica | D4: London | F4: 55665 | G4: 3 | H4: 25 | J4: =(E4*2240)+(F4*112)+(G4*28)+H4 -> 6234589 | L4: =J4/2240 -> 2783.2987
A5: 1710 | B5: Cascarilla | C5: Jamaica | D5: London | H5: 4190 | J5: =(E5*2240)+(F5*112)+(G5*28)+H5 -> 4190 | L5: =J5/2240 -> 1.8705357
A6: 1710 | B6: Chocolate | C6: Jamaica | D6: London | H6: 53 | J6: =(E6*2240)+(F6*112)+(G6*28)+H6 -> 53 | L6: =J6/2240 -> 0.023660714
A7: 1710 | B7: Cocheneal | C7: Jamaica | D7: London | H7: 125 | J7: =(E7*2240)+(F7*112)+(G7*28)+H7 -> 125 | L7: =J7/2240 -> 0.055803571
A8: 1710 | B8: Cocoa Nuts | C8: Jamaica | D8: London | F8: 1323 | G8: 3 | H8: 25 | J8: =(E8*2240)+(F8*112)+(G8*28)+H8 -> 148285 | L8: =J8/2240 -> 66.198661
A9: 1710 | B9: Cocoa Paste | C9: Jamaica | D9: London | H9: 6 | J9: =(E9*2240)+(F9*112)+(G9*28)+H9 -> 6 | L9: =J9/2240 -> 0.0026785714
A10: 1710 | B10: Cocoa Wood | C10: Jamaica | D10: London | J10: =(E10*2240)+(F10*112)+(G10*28)+H10 -> 0 | L10: =J10/2240 -> 0
A11: 1710 | B11: Cortex Winteranus | C11: Jamaica | D11: London | H11: 25807 | J11: =(E11*2240)+(F11*112)+(G11*28)+H11 -> 25807 | L11: =J11/2240 -> 11.520982
A12: 1710 | B12: Cotton | C12: Jamaica | D12: London | H12: =209*200 -> 41800 | I12: 209 bags | J12: =(E12*2240)+(F12*112)+(G12*28)+H12 -> 41800 | L12: =J12/2240 -> 18.660714
A13: 1710 | B13: Dry Ginger | C13: Jamaica | D13: London | F13: 2521 | G13: 1 | H13: 24 | J13: =(E13*2240)+(F13*112)+(G13*28)+H13 -> 282404 | L13: =J13/2240 -> 126.07321
A14: 1710 | B14: Elephant Teeth | C14: Jamaica | D14: London | F14: 84 | H14: 15 | J14: =(E14*2240)+(F14*112)+(G14*28)+H14 -> 9423 | L14: =J14/2240 -> 4.2066964
A15: 1710 | B15: Guiney Grains | C15: Jamaica | D15: London | F15: 7 | G15: 2 | J15: =(E15*2240)+(F15*112)+(G15*28)+H15 -> 840 | L15: =J15/2240 -> 0.375
A16: 1710 | B16: Indigo | C16: Jamaica | D16: London | H16: 96620 | J16: =(E16*2240)+(F16*112)+(G16*28)+H16 -> 96620 | L16: =J16/2240 -> 43.133929
A17: 1710 | B17: Jamaica Roots | C17: Jamaica | D17: London | H17: 34 | J17: =(E17*2240)+(F17*112)+(G17*28)+H17 -> 34 | L17: =J17/2240 -> 0.015178571
A18: 1710 | B18: Lignum Vitae | C18: Jamaica | D18: London | J18: =(E18*2240)+(F18*112)+(G18*28)+H18 -> 0 | L18: =J18/2240 -> 0
A19: 1710 | B19: Lime Juice | C19: Jamaica | D19: London | H19: 33679 | I19: 3367g | J19: =(E19*2240)+(F19*112)+(G19*28)+H19 -> 33679 | L19: =J19/2240 -> 15.035268
A20: 1710 | B20: Madera Wine | C20: Jamaica | D20: London | H20: 6862 | I20: 2t 2hh 56g | J20: =(E20*2240)+(F20*112)+(G20*28)+H20 -> 6862 | L20: =J20/2240 -> 3.0633929
A21: 1710 | B21: Molasses | C21: Jamaica | D21: London | F21: 240 | J21: =(E21*2240)+(F21*112)+(G21*28)+H21 -> 26880 | L21: =J21/2240 -> 12
A22: 1710 | B22: Pimento | C22: Jamaica | D22: London | H22: 137185 | J22: =(E22*2240)+(F22*112)+(G22*28)+H22 -> 137185 | L22: =J22/2240 -> 61.243304
A23: 1710 | B23: Rice | C23: Jamaica | D23: London | J23: =(E23*2240)+(F23*112)+(G23*28)+H23 -> 0 | L23: =J23/2240 -> 0
A24: 1710 | B24: Rum | C24: Jamaica | D24: London | H24: 13108 | I24: 1310.5g | J24: =(E24*2240)+(F24*112)+(G24*28)+H24 -> 13108 | L24: =J24/2240 -> 5.8517857
A25: 1710 | B25: Sasparilla | C25: Jamaica | D25: London | H25: 22597 | J25: =(E25*2240)+(F25*112)+(G25*28)+H25 -> 22597 | L25: =J25/2240 -> 10.087946
A26: 1710 | B26: Shruff | C26: Jamaica | D26: London | J26: =(E26*2240)+(F26*112)+(G26*28)+H26 -> 0 | L26: =J26/2240 -> 0
A27: 1710 | B27: Snuff | C27: Jamaica | D27: London | H27: 7322 | J27: =(E27*2240)+(F27*112)+(G27*28)+H27 -> 7322 | L27: =J27/2240 -> 3.26875
A28: 1710 | B28: Succands | C28: Jamaica | D28: London | H28: 602 | J28: =(E28*2240)+(F28*112)+(G28*28)+H28 -> 602 | L28: =J28/2240 -> 0.26875
A29: 1710 | B29: Sugar Loaf | C29: Jamaica | D29: London | J29: =(E29*2240)+(F29*112)+(G29*28)+H29 -> 0 | L29: =J29/2240 -> 0
A30: 1710 | B30: Tobacco | C30: Jamaica | D30: London | J30: =(E30*2240)+(F30*112)+(G30*28)+H30 -> 0 | L30: =J30/2240 -> 0
A31: 1710 | B31: Tortoise Shell | C31: Jamaica | D31: London | H31: 1741 | J31: =(E31*2240)+(F31*112)+(G31*28)+H31 -> 1741 | L31: =J31/2240 -> 0.77723214
A32: 1710 | B32: White Sugar | C32: Jamaica | D32: London | F32: 34 | H32: 15 | J32: =(E32*2240)+(F32*112)+(G32*28)+H32 -> 3823 | L32: =J32/2240 -> 1.7066964
A33: 1710 | B33: Wood, Braziletto | C33: Jamaica | D33: London | J33: =(E33*2240)+(F33*112)+(G33*28)+H33 -> 0 | L33: =J33/2240 -> 0
A34: 1710 | B34: Wood, Logwood | C34: Jamaica | D34: London | E34: 254 | F34: 4 | J34: =(E34*2240)+(F34*112)+(G34*28)+H34 -> 569408 | L34: =J34/2240 -> 254.2
A35: 1710 | B35: Wood, Nicaragua | C35: Jamaica | D35: London | J35: =(E35*2240)+(F35*112)+(G35*28)+H35 -> 0 | L35: =J35/2240 -> 0
A36: 1710 | B36: Wood, Wood, Fustick | C36: Jamaica | D36: London | E36: 440 | F36: 12 | G36: 3 | H36: 21 | J36: =(E36*2240)+(F36*112)+(G36*28)+H36 -> 987049 | L36: =J36/2240 -> 440.64688
A37: 1710 | B37: Wool Vigonia | C37: Jamaica | D37: London | H37: =12*200 -> 2400 | I37: 12 bags | J37: =(E37*2240)+(F37*112)+(G37*28)+H37 -> 2400 | L37: =J37/2240 -> 1.0714286
A38: 1710 | B38: Brown Sugar | C38: Jamaica | D38: Out Ports | F38: 56653 | G38: 2 | H38: 17 | J38: =(E38*2240)+(F38*112)+(G38*28)+H38 -> 6345209 | L38: =J38/2240 -> 2832.6826
A39: 1710 | B39: Chocolate | C39: Jamaica | D39: Out Ports | J39: =(E39*2240)+(F39*112)+(G39*28)+H39 -> 0 | L39: =J39/2240 -> 0
A40: 1710 | B40: Cocoa Nuts | C40: Jamaica | D40: Out Ports | F40: 2412 | H40: 26 | J40: =(E40*2240)+(F40*112)+(G40*28)+H40 -> 270170 | L40: =J40/2240 -> 120.61161
...

Sheet Mountserat
A1: YEAR | B1: COMMODITY_NAME | C1: FROM_LOCATION | D1: TO_LOCATION | E1: ton | F1: hh | G1: quarter | H1: lb | J1: Total Pounds | L1: WEIGHT
A2: 1710 | B2: Brown Sugar | C2: Mountserat | D2: London | F2: 15768 | H2: 27 | J2: =(E2*2240)+(F2*112)+(G2*28)+H2 -> 1766043 | L2: =J2/2240 -> 788.41205
A3: 1710 | B3: Chocolate | C3: Mountserat | D3: London | H3: 7 | J3: =(E3*2240)+(F3*112)+(G3*28)+H3 -> 7 | L3: =J3/2240 -> 0.003125
A4: 1710 | B4: Cocoa Nuts | C4: Mountserat | D4: London | F4: 22 | J4: =(E4*2240)+(F4*112)+(G4*28)+H4 -> 2464 | L4: =J4/2240 -> 1.1
A5: 1710 | B5: Cortex Winteranus | C5: Mountserat | D5: London | J5: =(E5*2240)+(F5*112)+(G5*28)+H5 -> 0 | L5: =J5/2240 -> 0
A6: 1710 | B6: Cotton | C6: Mountserat | D6: London | H6: =5*200 -> 1000 | I6: 5 bag | J6: =(E6*2240)+(F6*112)+(G6*28)+H6 -> 1000 | L6: =J6/2240 -> 0.44642857
A7: 1710 | B7: Dry Ginger | C7: Mountserat | D7: London | J7: =(E7*2240)+(F7*112)+(G7*28)+H7 -> 0 | L7: =J7/2240 -> 0
A8: 1710 | B8: Elephants Teeth | C8: Mountserat | D8: London | J8: =(E8*2240)+(F8*112)+(G8*28)+H8 -> 0 | L8: =J8/2240 -> 0
A9: 1710 | B9: Indigo | C9: Mountserat | D9: London | H9: 3089 | J9: =(E9*2240)+(F9*112)+(G9*28)+H9 -> 3089 | L9: =J9/2240 -> 1.3790179
A10: 1710 | B10: Lignum Vitae | C10: Mountserat | D10: London | F10: 80 | J10: =(E10*2240)+(F10*112)+(G10*28)+H10 -> 8960 | L10: =J10/2240 -> 4
A11: 1710 | B11: Lime Juice | C11: Mountserat | D11: London | H11: 200 | I11: 20g | J11: =(E11*2240)+(F11*112)+(G11*28)+H11 -> 200 | L11: =J11/2240 -> 0.089285714
A12: 1710 | B12: Madera Wine | C12: Mountserat | D12: London | H12: 2660 | I12: 1t 14g | J12: =(E12*2240)+(F12*112)+(G12*28)+H12 -> 2660 | L12: =J12/2240 -> 1.1875
A13: 1710 | B13: Molasses | C13: Mountserat | D13: London | J13: =(E13*2240)+(F13*112)+(G13*28)+H13 -> 0 | L13: =J13/2240 -> 0
A14: 1710 | B14: Pimento | C14: Mountserat | D14: London | H14: 1012 | J14: =(E14*2240)+(F14*112)+(G14*28)+H14 -> 1012 | L14: =J14/2240 -> 0.45178571
A15: 1710 | B15: Rice | C15: Mountserat | D15: London | F15: 3 | G15: 2 | J15: =(E15*2240)+(F15*112)+(G15*28)+H15 -> 392 | L15: =J15/2240 -> 0.175
A16: 1710 | B16: Rum | C16: Mountserat | D16: London | H16: 1700 | I16: 170g | J16: =(E16*2240)+(F16*112)+(G16*28)+H16 -> 1700 | L16: =J16/2240 -> 0.75892857
A17: 1710 | B17: Shruff | C17: Mountserat | D17: London | F17: 5 | G17: 3 | H17: 7 | J17: =(E17*2240)+(F17*112)+(G17*28)+H17 -> 651 | L17: =J17/2240 -> 0.290625
A18: 1710 | B18: Succands | C18: Mountserat | D18: London | H18: 48 | J18: =(E18*2240)+(F18*112)+(G18*28)+H18 -> 48 | L18: =J18/2240 -> 0.021428571
A19: 1710 | B19: Tortoise Shell | C19: Mountserat | D19: London | J19: =(E19*2240)+(F19*112)+(G19*28)+H19 -> 0 | L19: =J19/2240 -> 0
A20: 1710 | B20: White Sugar | C20: Mountserat | D20: London | J20: =(E20*2240)+(F20*112)+(G20*28)+H20 -> 0 | L20: =J20/2240 -> 0
A21: 1710 | B21: Brown Sugar | C21: Mountserat | D21: Out Ports | F21: 1303 | H21: 4 | J21: =(E21*2240)+(F21*112)+(G21*28)+H21 -> 145940 | L21: =J21/2240 -> 65.151786
A22: 1710 | B22: Cocoa | C22: Mountserat | D22: Out Ports | J22: =(E22*2240)+(F22*112)+(G22*28)+H22 -> 0 | L22: =J22/2240 -> 0
A23: 1710 | B23: Cocoa Nuts | C23: Mountserat | D23: Out Ports | H23: 102 | J23: =(E23*2240)+(F23*112)+(G23*28)+H23 -> 102 | L23: =J23/2240 -> 0.045535714
A24: 1710 | B24: Cotton | C24: Mountserat | D24: Out Ports | H24: 40 | J24: =(E24*2240)+(F24*112)+(G24*28)+H24 -> 40 | L24: =J24/2240 -> 0.017857143
A25: 1710 | B25: Dry Ginger | C25: Mountserat | D25: Out Ports | J25: =(E25*2240)+(F25*112)+(G25*28)+H25 -> 0 | L25: =J25/2240 -> 0
A26: 1710 | B26: Elephants Teeth | C26: Mountserat | D26: Out Ports | J26: =(E26*2240)+(F26*112)+(G26*28)+H26 -> 0 | L26: =J26/2240 -> 0
A27: 1710 | B27: Indigo | C27: Mountserat | D27: Out Ports | H27: 9205 | J27: =(E27*2240)+(F27*112)+(G27*28)+H27 -> 9205 | L27: =J27/2240 -> 4.109375
A28: 1710 | B28: Lime Juice | C28: Mountserat | D28: Out Ports | H28: 1310 | I28: 131g | J28: =(E28*2240)+(F28*112)+(G28*28)+H28 -> 1310 | L28: =J28/2240 -> 0.58482143
A29: 1710 | B29: Pimento | C29: Mountserat | D29: Out Ports | H29: 666 | J29: =(E29*2240)+(F29*112)+(G29*28)+H29 -> 666 | L29: =J29/2240 -> 0.29732143
A30: 1710 | B30: Rum | C30: Mountserat | D30: Out Ports | H30: 2140.5 | I30: 214g | J30: =(E30*2240)+(F30*112)+(G30*28)+H30 -> 2140.5 | L30: =J30/2240 -> 0.95558036
A31: 1710 | B31: Sweetmeats | C31: Mountserat | D31: Out Ports | H31: 100 | J31: =(E31*2240)+(F31*112)+(G31*28)+H31 -> 100 | L31: =J31/2240 -> 0.044642857
A32: 1710 | B32: Wood, Logwood | C32: Mountserat | D32: Out Ports | E32: 9 | F32: 10 | G32: 3 | H32: 16 | J32: =(E32*2240)+(F32*112)+(G32*28)+H32 -> 21380 | L32: =J32/2240 -> 9.5446429

Sheet Nevis
A1: YEAR | B1: COMMODITY_NAME | C1: FROM_LOCATION | D1: TO_LOCATION | E1: ton | F1: hh | G1: quarter | H1: lb | J1: Total Pounds | L1: WEIGHT
A2: 1710 | B2: Brown Sugar | C2: Nevis | D2: London | J2: =(E2*2240)+(F2*112)+(G2*28)+(H2) -> 0 | L2: =J2/2240 -> 0
A3: 1710 | B3: Chocolate | C3: Nevis | D3: London | J3: =(E3*2240)+(F3*112)+(G3*28)+(H3) -> 0 | L3: =J3/2240 -> 0
A4: 1710 | B4: Cocoa Nuts | C4: Nevis | D4: London | J4: =(E4*2240)+(F4*112)+(G4*28)+(H4) -> 0 | L4: =J4/2240 -> 0
A5: 1710 | B5: Cortex Winteranus | C5: Nevis | D5: London | J5: =(E5*2240)+(F5*112)+(G5*28)+(H5) -> 0 | L5: =J5/2240 -> 0
A6: 1710 | B6: Cotton | C6: Nevis | D6: London | H6: =79*200 -> 15800 | I6: 79 bag | J6: =(E6*2240)+(F6*112)+(G6*28)+(H6) -> 15800 | L6: =J6/2240 -> 7.0535714
A7: 1710 | B7: Dry Ginger | C7: Nevis | D7: London | F7: 60 | J7: =(E7*2240)+(F7*112)+(G7*28)+(H7) -> 6720 | L7: =J7/2240 -> 3
A8: 1710 | B8: Elephant Teeth | C8: Nevis | D8: London | G8: 3 | H8: 21 | J8: =(E8*2240)+(F8*112)+(G8*28)+(H8) -> 105 | L8: =J8/2240 -> 0.046875
A9: 1710 | B9: Indigo | C9: Nevis | D9: London | H9: 504 | J9: =(E9*2240)+(F9*112)+(G9*28)+(H9) -> 504 | L9: =J9/2240 -> 0.225
A10: 1710 | B10: Lignum Vitae | C10: Nevis | D10: London | F10: 15 | G10: 3 | J10: =(E10*2240)+(F10*112)+(G10*28)+(H10) -> 1764 | L10: =J10/2240 -> 0.7875
A11: 1710 | B11: Lime Juice | C11: Nevis | D11: London | J11: =(E11*2240)+(F11*112)+(G11*28)+(H11) -> 0 | L11: =J11/2240 -> 0
A12: 1710 | B12: Madera Wine | C12: Nevis | D12: London | H12: 2440.5 | I12: 3hh 55g | J12: =(E12*2240)+(F12*112)+(G12*28)+(H12) -> 2440.5 | L12: =J12/2240 -> 1.0895089
A13: 1710 | B13: Molasses | C13: Nevis | D13: London | F13: 70 | G13: 2 | J13: =(E13*2240)+(F13*112)+(G13*28)+(H13) -> 7896 | L13: =J13/2240 -> 3.525
A14: 1710 | B14: Muscovado Sugar | C14: Nevis | D14: London | F14: 43283 | G14: 2 | H14: 3 | J14: =(E14*2240)+(F14*112)+(G14*28)+(H14) -> 4847755 | L14: =J14/2240 -> 2164.1763
A15: 1710 | B15: Pickles | C15: Nevis | D15: London | J15: =(E15*2240)+(F15*112)+(G15*28)+(H15) -> 0 | L15: =J15/2240 -> 0
A16: 1710 | B16: Rum | C16: Nevis | D16: London | J16: =(E16*2240)+(F16*112)+(G16*28)+(H16) -> 0 | L16: =J16/2240 -> 0
A17: 1710 | B17: Shruff | C17: Nevis | D17: London | G17: 3 | H17: 14 | J17: =(E17*2240)+(F17*112)+(G17*28)+(H17) -> 98 | L17: =J17/2240 -> 0.04375
A18: 1710 | B18: Succands | C18: Nevis | D18: London | H18: 80 | J18: =(E18*2240)+(F18*112)+(G18*28)+(H18) -> 80 | L18: =J18/2240 -> 0.035714286
A19: 1710 | B19: Sugar Loaf | C19: Nevis | D19: London | J19: =(E19*2240)+(F19*112)+(G19*28)+(H19) -> 0 | L19: =J19/2240 -> 0
A20: 1710 | B20: Tobacco | C20: Nevis | D20: London | J20: =(E20*2240)+(F20*112)+(G20*28)+(H20) -> 0 | L20: =J20/2240 -> 0
A21: 1710 | B21: Tortoise Shell | C21: Nevis | D21: London | J21: =(E21*2240)+(F21*112)+(G21*28)+(H21) -> 0 | L21: =J21/2240 -> 0
A22: 1710 | B22: White Sugar | C22: Nevis | D22: London | F22: 18 | G22: 3 | H22: 14 | J22: =(E22*2240)+(F22*112)+(G22*28)+(H22) -> 2114 | L22: =J22/2240 -> 0.94375
A23: 1710 | B23: Brown Sugar | C23: Nevis | D23: Out Ports | F23: 23791 | G23: 2 | H23: 11 | J23: =(E23*2240)+(F23*112)+(G23*28)+(H23) -> 2664659 | L23: =J23/2240 -> 1189.5799
A24: 1710 | B24: Cocoa Nuts | C24: Nevis | D24: Out Ports | F24: 6 | G24: 1 | H24: 17 | J24: =(E24*2240)+(F24*112)+(G24*28)+(H24) -> 717 | L24: =J24/2240 -> 0.32008929
A25: 1710 | B25: Cotton | C25: Nevis | D25: Out Ports | H25: 25142 | J25: =(E25*2240)+(F25*112)+(G25*28)+(H25) -> 25142 | L25: =J25/2240 -> 11.224107
A26: 1710 | B26: Elephant Teeth | C26: Nevis | D26: Out Ports | F26: 4 | G26: 1 | H26: 1 | J26: =(E26*2240)+(F26*112)+(G26*28)+(H26) -> 477 | L26: =J26/2240 -> 0.21294643
A27: 1710 | B27: Guiney Grains | C27: Nevis | D27: Out Ports | F27: 5 | G27: 3 | H27: 14 | J27: =(E27*2240)+(F27*112)+(G27*28)+(H27) -> 658 | L27: =J27/2240 -> 0.29375
A28: 1710 | B28: Indigo | C28: Nevis | D28: Out Ports | H28: 8748 | J28: =(E28*2240)+(F28*112)+(G28*28)+(H28) -> 8748 | L28: =J28/2240 -> 3.9053571
A29: 1710 | B29: Lignum Vitae | C29: Nevis | D29: Out Ports | J29: =(E29*2240)+(F29*112)+(G29*28)+(H29) -> 0 | L29: =J29/2240 -> 0
A30: 1710 | B30: Lime Juice | C30: Nevis | D30: Out Ports | H30: 230 | I30: 23g | J30: =(E30*2240)+(F30*112)+(G30*28)+(H30) -> 230 | L30: =J30/2240 -> 0.10267857
A31: 1710 | B31: Molasses | C31: Nevis | D31: Out Ports | F31: 242 | G31: 3 | H31: 7 | J31: =(E31*2240)+(F31*112)+(G31*28)+(H31) -> 27195 | L31: =J31/2240 -> 12.140625
A32: 1710 | B32: Pimento | C32: Nevis | D32: Out Ports | H32: 90 | J32: =(E32*2240)+(F32*112)+(G32*28)+(H32) -> 90 | L32: =J32/2240 -> 0.040178571
A33: 1710 | B33: Rum | C33: Nevis | D33: Out Ports | H33: 1380 | I33: 138g | J33: =(E33*2240)+(F33*112)+(G33*28)+(H33) -> 1380 | L33: =J33/2240 -> 0.61607143
A34: 1710 | B34: Shruff | C34: Nevis | D34: Out Ports | F34: 3 | G34: 2 | H34: 18 | J34: =(E34*2240)+(F34*112)+(G34*28)+(H34) -> 410 | L34: =J34/2240 -> 0.18303571
A35: 1710 | B35: Succands | C35: Nevis | D35: Out Ports | H35: 85 | J35: =(E35*2240)+(F35*112)+(G35*28)+(H35) -> 85 | L35: =J35/2240 -> 0.037946429
A36: 1710 | B36: Tortoise Shell | C36: Nevis | D36: Out Ports | H36: 2 | J36: =(E36*2240)+(F36*112)+(G36*28)+(H36) -> 2 | L36: =J36/2240 -> 0.00089285714
A37: 1710 | B37: White Sugar | C37: Nevis | D37: Out Ports | F37: 12 | G37: 1 | H37: 5 | J37: =(E37*2240)+(F37*112)+(G37*28)+(H37) -> 1377 | L37: =J37/2240 -> 0.61473214

Sheet St Kitts
A1: YEAR | B1: COMMODITY_NAME | C1: FROM_LOCATION | D1: TO_LOCATION | E1: ton | F1: hh | G1: quarter | H1: lb | J1: Total Pounds | L1: WEIGHT
A2: 1710 | B2: Annatto | C2: StKitts | D2: London | J2: =(E2*2240)+(F2*112)+(G2*28)+(H2/16) -> 0 | L2: =J2/2240 -> 0
A3: 1710 | B3: Bees Wax | C3: StKitts | D3: London | J3: =(E3*2240)+(F3*112)+(G3*28)+(H3/16) -> 0 | L3: =J3/2240 -> 0
A4: 1710 | B4: Brown Sugar | C4: StKitts | D4: London | F4: 23918 | G4: 1 | J4: =(E4*2240)+(F4*112)+(G4*28)+(H4/16) -> 2678844 | L4: =J4/2240 -> 1195.9125
A5: 1710 | B5: Chocolate | C5: StKitts | D5: London | H5: 12 | J5: =(E5*2240)+(F5*112)+(G5*28)+(H5/16) -> 0.75 | L5: =J5/2240 -> 0.00033482143
A6: 1710 | B6: Cocoa Nuts | C6: StKitts | D6: London | J6: =(E6*2240)+(F6*112)+(G6*28)+(H6/16) -> 0 | L6: =J6/2240 -> 0
A7: 1710 | B7: Cotton | C7: StKitts | D7: London | H7: =77*200 -> 15400 | I7: 77bag | J7: =(E7*2240)+(F7*112)+(G7*28)+(H7/16) -> 962.5 | L7: =J7/2240 -> 0.4296875
A8: 1710 | B8: Dry Ginger | C8: StKitts | D8: London | J8: =(E8*2240)+(F8*112)+(G8*28)+(H8/16) -> 0 | L8: =J8/2240 -> 0
A9: 1710 | B9: Elephant Teeth | C9: StKitts | D9: London | J9: =(E9*2240)+(F9*112)+(G9*28)+(H9/16) -> 0 | L9: =J9/2240 -> 0
A10: 1710 | B10: Indigo | C10: StKitts | D10: London | H10: 1022 | J10: =(E10*2240)+(F10*112)+(G10*28)+(H10/16) -> 63.875 | L10: =J10/2240 -> 0.028515625
A11: 1710 | B11: Lignum Vitae | C11: StKitts | D11: London | F11: 41 | G11: 1 | H11: 14 | J11: =(E11*2240)+(F11*112)+(G11*28)+(H11/16) -> 4620.875 | L11: =J11/2240 -> 2.0628906
A12: 1710 | B12: Madera Wine | C12: StKitts | D12: London | H12: 970 | I12: 1hh 34g | J12: =(E12*2240)+(F12*112)+(G12*28)+(H12/16) -> 60.625 | L12: =J12/2240 -> 0.027064732
A13: 1710 | B13: Molasses | C13: StKitts | D13: London | J13: =(E13*2240)+(F13*112)+(G13*28)+(H13/16) -> 0 | L13: =J13/2240 -> 0
A14: 1710 | B14: Pimento | C14: StKitts | D14: London | J14: =(E14*2240)+(F14*112)+(G14*28)+(H14/16) -> 0 | L14: =J14/2240 -> 0
A15: 1710 | B15: Rum | C15: StKitts | D15: London | H15: 550 | I15: 55g | J15: =(E15*2240)+(F15*112)+(G15*28)+(H15/16) -> 34.375 | L15: =J15/2240 -> 0.015345982
A16: 1710 | B16: Shruff | C16: StKitts | D16: London | F16: 3 | G16: 2 | J16: =(E16*2240)+(F16*112)+(G16*28)+(H16/16) -> 392 | L16: =J16/2240 -> 0.175
A17: 1710 | B17: Succands | C17: StKitts | D17: London | G17: 88 | J17: =(E17*2240)+(F17*112)+(G17*28)+(H17/16) -> 2464 | L17: =J17/2240 -> 1.1
A18: 1710 | B18: Wood, Logwood | C18: StKitts | D18: London | J18: =(E18*2240)+(F18*112)+(G18*28)+(H18/16) -> 0 | L18: =J18/2240 -> 0
A19: 1710 | B19: Brown Sugar | C19: StKitts | D19: Out Ports | F19: 6300 | G19: 2 | H19: 2 | J19: =(E19*2240)+(F19*112)+(G19*28)+(H19/16) -> 705656.12 | L19: =J19/2240 -> 315.02506
A20: 1710 | B20: Cotton | C20: StKitts | D20: Out Ports | H20: 17832 | J20: =(E20*2240)+(F20*112)+(G20*28)+(H20/16) -> 1114.5 | L20: =J20/2240 -> 0.49754464
A21: 1710 | B21: Indigo | C21: StKitts | D21: Out Ports | H21: 817 | J21: =(E21*2240)+(F21*112)+(G21*28)+(H21/16) -> 51.0625 | L21: =J21/2240 -> 0.022795759
A22: 1710 | B22: Pimento | C22: StKitts | D22: Out Ports | H22: 81 | J22: =(E22*2240)+(F22*112)+(G22*28)+(H22/16) -> 5.0625 | L22: =J22/2240 -> 0.0022600446

Sheet NewEngland
A1: Items | B1: Import Location | C1: ton | D1: hh | E1: quarter | F1: lb | H1: Total Pounds | J1: Total Tons
A2: Lignum Vitae | B2: London | H2: =(C2*2240)+(D2*112)+(E2*28)+F2 -> 0 | J2: =H2/2240 -> 0
A3: Braziletto Wood | B3: London | H3: =(C3*2240)+(D3*112)+(E3*28)+F3 -> 0 | J3: =H3/2240 -> 0
A4: Wood, Wood, Fustick | B4: London | H4: =(C4*2240)+(D4*112)+(E4*28)+F4 -> 0 | J4: =H4/2240 -> 0
A5: Wood, Logwood | B5: London | H5: =(C5*2240)+(D5*112)+(E5*28)+F5 -> 0 | J5: =H5/2240 -> 0
A6: Cortex Winteranus | B6: London | H6: =(C6*2240)+(D6*112)+(E6*28)+F6 -> 0 | J6: =H6/2240 -> 0
A7: Turpentine Common | B7: London | H7: =(C7*2240)+(D7*112)+(E7*28)+F7 -> 0 | J7: =H7/2240 -> 0
A8: Dry Ginger | B8: London | H8: =(C8*2240)+(D8*112)+(E8*28)+F8 -> 0 | J8: =H8/2240 -> 0
A9: Molasses | B9: London | H9: =(C9*2240)+(D9*112)+(E9*28)+F9 -> 0 | J9: =H9/2240 -> 0
A10: Brown Sugar | B10: London | H10: =(C10*2240)+(D10*112)+(E10*28)+F10 -> 0 | J10: =H10/2240 -> 0
A11: White Sugar | B11: London | H11: =(C11*2240)+(D11*112)+(E11*28)+F11 -> 0 | J11: =H11/2240 -> 0
A12: Rice | B12: London | H12: =(C12*2240)+(D12*112)+(E12*28)+F12 -> 0 | J12: =H12/2240 -> 0
A13: Shruff | B13: London | H13: =(C13*2240)+(D13*112)+(E13*28)+F13 -> 0 | J13: =H13/2240 -> 0
... A34: Rum | B34: Out Ports | H34: =(C34*2240)+(D34*112)+(E34*28)+F34 -> 0 | J34: =H34/2240 -> 0
