Workbook

Sheet Master Goods Sheet
A1: Item | B1: Total London | C1: Total Outports | D1: Total
A2: Annatto | B2: =SUMIFS(Antigua!$L:$L, Antigua!$B:$B, $A2, Antigua!$D:$D, "London") + SUMIFS(Barbados!$L:$L, Barbados!$B:$B, $A2, Barbados!$D:$D, "London") + SUMIFS(Bermuda!$L:$L, Bermuda!$B:$B, $A2, Bermuda!$D:$D, "London") + SUMIFS(Carolina!$L:$L, Carolina!$B:$B, $A2, Carolina!$D:$D, "London") + SUMIFS(Jamaica!$L:$L, Jamaica!$B:$B, $A2, Jamaica!$D:$D, "London") + SUMIFS(Mountserat!$L:$L, Mountserat!$B:$B, $A2, Mountserat!$D:$D, "London") + SUMIFS(Nevis!$L:$L, Nevis!$B:$B, $A2, Nevis!$D:$D, "London") + SUMIFS(NewEngland!$L:$L, NewEngland!$B:$B, $A2, NewEngland!$D:$D, "London") -> 0 | C2: =SUMIFS(Antigua!$L:$L, Antigua!$B:$B, $A2, Antigua!$D:$D, "Out Ports") + SUMIFS(Barbados!$L:$L, Barbados!$B:$B, $A2, Barbados!$D:$D, "Out Ports") + SUMIFS(Bermuda!$L:$L, Bermuda!$B:$B, $A2, Bermuda!$D:$D, "Out Ports") + SUMIFS(Carolina!$L:$L, Carolina!$B:$B, $A2, Carolina!$D:$D, "Out Ports") + SUMIFS(Jamaica!$L:$L, Jamaica!$B:$B, $A2, Jamaica!$D:$D, "Out Ports") + SUMIFS(Mountserat!$L:$L, Mountserat!$B:$B, $A2, Mountserat!$D:$D, "Out Ports") + SUMIFS(Nevis!$L:$L, Nevis!$B:$B, $A2, Nevis!$D:$D, "Out Ports") + SUMIFS(NewEngland!$L:$L, NewEngland!$B:$B, $A2, NewEngland!$D:$D, "Out Ports") -> 0 | D2: =ROUND((B2+C2),2) -> 0
A3: Bayberry Wax | B3: =SUMIFS(Antigua!$L:$L, Antigua!$B:$B, $A3, Antigua!$D:$D, "London") + SUMIFS(Barbados!$L:$L, Barbados!$B:$B, $A3, Barbados!$D:$D, "London") + SUMIFS(Bermuda!$L:$L, Bermuda!$B:$B, $A3, Bermuda!$D:$D, "London") + SUMIFS(Carolina!$L:$L, Carolina!$B:$B, $A3, Carolina!$D:$D, "London") + SUMIFS(Jamaica!$L:$L, Jamaica!$B:$B, $A3, Jamaica!$D:$D, "London") + SUMIFS(Mountserat!$L:$L, Mountserat!$B:$B, $A3, Mountserat!$D:$D, "London") + SUMIFS(Nevis!$L:$L, Nevis!$B:$B, $A3, Nevis!$D:$D, "London") + SUMIFS(NewEngland!$L:$L, NewEngland!$B:$B, $A3, NewEngland!$D:$D, "London") -> 0 | C3: =SUMIFS(Antigua!$L:$L, Antigua!$B:$B, $A3, Antigua!$D:$D, "Out Ports") + SUMIFS(Barbados!$L:$L, Barbados!$B:$B, $A3, Barbados!$D:$D, "Out Ports") + SUMIFS(Bermuda!$L:$L, Bermuda!$B:$B, $A3, Bermuda!$D:$D, "Out Ports") + SUMIFS(Carolina!$L:$L, Carolina!$B:$B, $A3, Carolina!$D:$D, "Out Ports") + SUMIFS(Jamaica!$L:$L, Jamaica!$B:$B, $A3, Jamaica!$D:$D, "Out Ports") + SUMIFS(Mountserat!$L:$L, Mountserat!$B:$B, $A3, Mountserat!$D:$D, "Out Ports") + SUMIFS(Nevis!$L:$L, Nevis!$B:$B, $A3, Nevis!$D:$D, "Out Ports") + SUMIFS(NewEngland!$L:$L, NewEngland!$B:$B, $A3, NewEngland!$D:$D, "Out Ports") -> 0 | D3: =ROUND((B3+C3),2) -> 0
A4: Bees Wax | B4: =SUMIFS(Antigua!$L:$L, Antigua!$B:$B, $A4, Antigua!$D:$D, "London") + SUMIFS(Barbados!$L:$L, Barbados!$B:$B, $A4, Barbados!$D:$D, "London") + SUMIFS(Bermuda!$L:$L, Bermuda!$B:$B, $A4, Bermuda!$D:$D, "London") + SUMIFS(Carolina!$L:$L, Carolina!$B:$B, $A4, Carolina!$D:$D, "London") + SUMIFS(Jamaica!$L:$L, Jamaica!$B:$B, $A4, Jamaica!$D:$D, "London") + SUMIFS(Mountserat!$L:$L, Mountserat!$B:$B, $A4, Mountserat!$D:$D, "London") + SUMIFS(Nevis!$L:$L, Nevis!$B:$B, $A4, Nevis!$D:$D, "London") + SUMIFS(NewEngland!$L:$L, NewEngland!$B:$B, $A4, NewEngland!$D:$D, "London") -> 0.39375 | C4: =SUMIFS(Antigua!$L:$L, Antigua!$B:$B, $A4, Antigua!$D:$D, "Out Ports") + SUMIFS(Barbados!$L:$L, Barbados!$B:$B, $A4, Barbados!$D:$D, "Out Ports") + SUMIFS(Bermuda!$L:$L, Bermuda!$B:$B, $A4, Bermuda!$D:$D, "Out Ports") + SUMIFS(Carolina!$L:$L, Carolina!$B:$B, $A4, Carolina!$D:$D, "Out Ports") + SUMIFS(Jamaica!$L:$L, Jamaica!$B:$B, $A4, Jamaica!$D:$D, "Out Ports") + SUMIFS(Mountserat!$L:$L, Mountserat!$B:$B, $A4, Mountserat!$D:$D, "Out Ports") + SUMIFS(Nevis!$L:$L, Nevis!$B:$B, $A4, Nevis!$D:$D, "Out Ports") + SUMIFS(NewEngland!$L:$L, NewEngland!$B:$B, $A4, NewEngland!$D:$D, "Out Ports") -> 0 | D4: =ROUND((B4+C4),2) -> 0.39
A5: Brandy | B5: =SUMIFS(Antigua!$L:$L, Antigua!$B:$B, $A5, Antigua!$D:$D, "London") + SUMIFS(Barbados!$L:$L, Barbados!$B:$B, $A5, Barbados!$D:$D, "London") + SUMIFS(Bermuda!$L:$L, Bermuda!$B:$B, $A5, Bermuda!$D:$D, "London") + SUMIFS(Carolina!$L:$L, Carolina!$B:$B, $A5, Carolina!$D:$D, "London") + SUMIFS(Jamaica!$L:$L, Jamaica!$B:$B, $A5, Jamaica!$D:$D, "London") + SUMIFS(Mountserat!$L:$L, Mountserat!$B:$B, $A5, Mountserat!$D:$D, "London") + SUMIFS(Nevis!$L:$L, Nevis!$B:$B, $A5, Nevis!$D:$D, "London") + SUMIFS(NewEngland!$L:$L, NewEngland!$B:$B, $A5, NewEngland!$D:$D, "London") -> 0 | C5: =SUMIFS(Antigua!$L:$L, Antigua!$B:$B, $A5, Antigua!$D:$D, "Out Ports") + SUMIFS(Barbados!$L:$L, Barbados!$B:$B, $A5, Barbados!$D:$D, "Out Ports") + SUMIFS(Bermuda!$L:$L, Bermuda!$B:$B, $A5, Bermuda!$D:$D, "Out Ports") + SUMIFS(Carolina!$L:$L, Carolina!$B:$B, $A5, Carolina!$D:$D, "Out Ports") + SUMIFS(Jamaica!$L:$L, Jamaica!$B:$B, $A5, Jamaica!$D:$D, "Out Ports") + SUMIFS(Mountserat!$L:$L, Mountserat!$B:$B, $A5, Mountserat!$D:$D, "Out Ports") + SUMIFS(Nevis!$L:$L, Nevis!$B:$B, $A5, Nevis!$D:$D, "Out Ports") + SUMIFS(NewEngland!$L:$L, NewEngland!$B:$B, $A5, NewEngland!$D:$D, "Out Ports") -> 0 | D5: =ROUND((B5+C5),2) -> 0
A6: Brown Sugar | B6: =SUMIFS(Antigua!$L:$L, Antigua!$B:$B, $A6, Antigua!$D:$D, "London") + SUMIFS(Barbados!$L:$L, Barbados!$B:$B, $A6, Barbados!$D:$D, "London") + SUMIFS(Bermuda!$L:$L, Bermuda!$B:$B, $A6, Bermuda!$D:$D, "London") + SUMIFS(Carolina!$L:$L, Carolina!$B:$B, $A6, Carolina!$D:$D, "London") + SUMIFS(Jamaica!$L:$L, Jamaica!$B:$B, $A6, Jamaica!$D:$D, "London") + SUMIFS(Mountserat!$L:$L, Mountserat!$B:$B, $A6, Mountserat!$D:$D, "London") + SUMIFS(Nevis!$L:$L, Nevis!$B:$B, $A6, Nevis!$D:$D, "London") + SUMIFS(NewEngland!$L:$L, NewEngland!$B:$B, $A6, NewEngland!$D:$D, "London") -> 11352.3 | C6: =SUMIFS(Antigua!$L:$L, Antigua!$B:$B, $A6, Antigua!$D:$D, "Out Ports") + SUMIFS(Barbados!$L:$L, Barbados!$B:$B, $A6, Barbados!$D:$D, "Out Ports") + SUMIFS(Bermuda!$L:$L, Bermuda!$B:$B, $A6, Bermuda!$D:$D, "Out Ports") + SUMIFS(Carolina!$L:$L, Carolina!$B:$B, $A6, Carolina!$D:$D, "Out Ports") + SUMIFS(Jamaica!$L:$L, Jamaica!$B:$B, $A6, Jamaica!$D:$D, "Out Ports") + SUMIFS(Mountserat!$L:$L, Mountserat!$B:$B, $A6, Mountserat!$D:$D, "Out Ports") + SUMIFS(Nevis!$L:$L, Nevis!$B:$B, $A6, Nevis!$D:$D, "Out Ports") + SUMIFS(NewEngland!$L:$L, NewEngland!$B:$B, $A6, NewEngland!$D:$D, "Out Ports") -> 5250.9982 | D6: =ROUND((B6+C6),2) -> 16603.3
A7: Cascarilla | B7: =SUMIFS(Antigua!$L:$L, Antigua!$B:$B, $A7, Antigua!$D:$D, "London") + SUMIFS(Barbados!$L:$L, Barbados!$B:$B, $A7, Barbados!$D:$D, "London") + SUMIFS(Bermuda!$L:$L, Bermuda!$B:$B, $A7, Bermuda!$D:$D, "London") + SUMIFS(Carolina!$L:$L, Carolina!$B:$B, $A7, Carolina!$D:$D, "London") + SUMIFS(Jamaica!$L:$L, Jamaica!$B:$B, $A7, Jamaica!$D:$D, "London") + SUMIFS(Mountserat!$L:$L, Mountserat!$B:$B, $A7, Mountserat!$D:$D, "London") + SUMIFS(Nevis!$L:$L, Nevis!$B:$B, $A7, Nevis!$D:$D, "London") + SUMIFS(NewEngland!$L:$L, NewEngland!$B:$B, $A7, NewEngland!$D:$D, "London") -> 0 | C7: =SUMIFS(Antigua!$L:$L, Antigua!$B:$B, $A7, Antigua!$D:$D, "Out Ports") + SUMIFS(Barbados!$L:$L, Barbados!$B:$B, $A7, Barbados!$D:$D, "Out Ports") + SUMIFS(Bermuda!$L:$L, Bermuda!$B:$B, $A7, Bermuda!$D:$D, "Out Ports") + SUMIFS(Carolina!$L:$L, Carolina!$B:$B, $A7, Carolina!$D:$D, "Out Ports") + SUMIFS(Jamaica!$L:$L, Jamaica!$B:$B, $A7, Jamaica!$D:$D, "Out Ports") + SUMIFS(Mountserat!$L:$L, Mountserat!$B:$B, $A7, Mountserat!$D:$D, "Out Ports") + SUMIFS(Nevis!$L:$L, Nevis!$B:$B, $A7, Nevis!$D:$D, "Out Ports") + SUMIFS(NewEngland!$L:$L, NewEngland!$B:$B, $A7, NewEngland!$D:$D, "Out Ports") -> 0 | D7: =ROUND((B7+C7),2) -> 0
A8: Chocolate | B8: =SUMIFS(Antigua!$L:$L, Antigua!$B:$B, $A8, Antigua!$D:$D, "London") + SUMIFS(Barbados!$L:$L, Barbados!$B:$B, $A8, Barbados!$D:$D, "London") + SUMIFS(Bermuda!$L:$L, Bermuda!$B:$B, $A8, Bermuda!$D:$D, "London") + SUMIFS(Carolina!$L:$L, Carolina!$B:$B, $A8, Carolina!$D:$D, "London") + SUMIFS(Jamaica!$L:$L, Jamaica!$B:$B, $A8, Jamaica!$D:$D, "London") + SUMIFS(Mountserat!$L:$L, Mountserat!$B:$B, $A8, Mountserat!$D:$D, "London") + SUMIFS(Nevis!$L:$L, Nevis!$B:$B, $A8, Nevis!$D:$D, "London") + SUMIFS(NewEngland!$L:$L, NewEngland!$B:$B, $A8, NewEngland!$D:$D, "London") -> 0.0080357143 | C8: =SUMIFS(Antigua!$L:$L, Antigua!$B:$B, $A8, Antigua!$D:$D, "Out Ports") + SUMIFS(Barbados!$L:$L, Barbados!$B:$B, $A8, Barbados!$D:$D, "Out Ports") + SUMIFS(Bermuda!$L:$L, Bermuda!$B:$B, $A8, Bermuda!$D:$D, "Out Ports") + SUMIFS(Carolina!$L:$L, Carolina!$B:$B, $A8, Carolina!$D:$D, "Out Ports") + SUMIFS(Jamaica!$L:$L, Jamaica!$B:$B, $A8, Jamaica!$D:$D, "Out Ports") + SUMIFS(Mountserat!$L:$L, Mountserat!$B:$B, $A8, Mountserat!$D:$D, "Out Ports") + SUMIFS(Nevis!$L:$L, Nevis!$B:$B, $A8, Nevis!$D:$D, "Out Ports") + SUMIFS(NewEngland!$L:$L, NewEngland!$B:$B, $A8, NewEngland!$D:$D, "Out Ports") -> 0.13258929 | D8: =ROUND((B8+C8),2) -> 0.14
A9: Cockeneal | B9: =SUMIFS(Antigua!$L:$L, Antigua!$B:$B, $A9, Antigua!$D:$D, "London") + SUMIFS(Barbados!$L:$L, Barbados!$B:$B, $A9, Barbados!$D:$D, "London") + SUMIFS(Bermuda!$L:$L, Bermuda!$B:$B, $A9, Bermuda!$D:$D, "London") + SUMIFS(Carolina!$L:$L, Carolina!$B:$B, $A9, Carolina!$D:$D, "London") + SUMIFS(Jamaica!$L:$L, Jamaica!$B:$B, $A9, Jamaica!$D:$D, "London") + SUMIFS(Mountserat!$L:$L, Mountserat!$B:$B, $A9, Mountserat!$D:$D, "London") + SUMIFS(Nevis!$L:$L, Nevis!$B:$B, $A9, Nevis!$D:$D, "London") + SUMIFS(NewEngland!$L:$L, NewEngland!$B:$B, $A9, NewEngland!$D:$D, "London") -> 0 | C9: =SUMIFS(Antigua!$L:$L, Antigua!$B:$B, $A9, Antigua!$D:$D, "Out Ports") + SUMIFS(Barbados!$L:$L, Barbados!$B:$B, $A9, Barbados!$D:$D, "Out Ports") + SUMIFS(Bermuda!$L:$L, Bermuda!$B:$B, $A9, Bermuda!$D:$D, "Out Ports") + SUMIFS(Carolina!$L:$L, Carolina!$B:$B, $A9, Carolina!$D:$D, "Out Ports") + SUMIFS(Jamaica!$L:$L, Jamaica!$B:$B, $A9, Jamaica!$D:$D, "Out Ports") + SUMIFS(Mountserat!$L:$L, Mountserat!$B:$B, $A9, Mountserat!$D:$D, "Out Ports") + SUMIFS(Nevis!$L:$L, Nevis!$B:$B, $A9, Nevis!$D:$D, "Out Ports") + SUMIFS(NewEngland!$L:$L, NewEngland!$B:$B, $A9, NewEngland!$D:$D, "Out Ports") -> 0 | D9: =ROUND((B9+C9),2) -> 0
A10: Cocoa Nuts | B10: =SUMIFS(Antigua!$L:$L, Antigua!$B:$B, $A10, Antigua!$D:$D, "London") + SUMIFS(Barbados!$L:$L, Barbados!$B:$B, $A10, Barbados!$D:$D, "London") + SUMIFS(Bermuda!$L:$L, Bermuda!$B:$B, $A10, Bermuda!$D:$D, "London") + SUMIFS(Carolina!$L:$L, Carolina!$B:$B, $A10, Carolina!$D:$D, "London") + SUMIFS(Jamaica!$L:$L, Jamaica!$B:$B, $A10, Jamaica!$D:$D, "London") + SUMIFS(Mountserat!$L:$L, Mountserat!$B:$B, $A10, Mountserat!$D:$D, "London") + SUMIFS(Nevis!$L:$L, Nevis!$B:$B, $A10, Nevis!$D:$D, "London") + SUMIFS(NewEngland!$L:$L, NewEngland!$B:$B, $A10, NewEngland!$D:$D, "London") -> 71.500893 | C10: =SUMIFS(Antigua!$L:$L, Antigua!$B:$B, $A10, Antigua!$D:$D, "Out Ports") + SUMIFS(Barbados!$L:$L, Barbados!$B:$B, $A10, Barbados!$D:$D, "Out Ports") + SUMIFS(Bermuda!$L:$L, Bermuda!$B:$B, $A10, Bermuda!$D:$D, "Out Ports") + SUMIFS(Carolina!$L:$L, Carolina!$B:$B, $A10, Carolina!$D:$D, "Out Ports") + SUMIFS(Jamaica!$L:$L, Jamaica!$B:$B, $A10, Jamaica!$D:$D, "Out Ports") + SUMIFS(Mountserat!$L:$L, Mountserat!$B:$B, $A10, Mountserat!$D:$D, "Out Ports") + SUMIFS(Nevis!$L:$L, Nevis!$B:$B, $A10, Nevis!$D:$D, "Out Ports") + SUMIFS(NewEngland!$L:$L, NewEngland!$B:$B, $A10, NewEngland!$D:$D, "Out Ports") -> 47.311161 | D10: =ROUND((B10+C10),2) -> 118.81
A11: Cotton | B11: =SUMIFS(Antigua!$L:$L, Antigua!$B:$B, $A11, Antigua!$D:$D, "London") + SUMIFS(Barbados!$L:$L, Barbados!$B:$B, $A11, Barbados!$D:$D, "London") + SUMIFS(Bermuda!$L:$L, Bermuda!$B:$B, $A11, Bermuda!$D:$D, "London") + SUMIFS(Carolina!$L:$L, Carolina!$B:$B, $A11, Carolina!$D:$D, "London") + SUMIFS(Jamaica!$L:$L, Jamaica!$B:$B, $A11, Jamaica!$D:$D, "London") + SUMIFS(Mountserat!$L:$L, Mountserat!$B:$B, $A11, Mountserat!$D:$D, "London") + SUMIFS(Nevis!$L:$L, Nevis!$B:$B, $A11, Nevis!$D:$D, "London") + SUMIFS(NewEngland!$L:$L, NewEngland!$B:$B, $A11, NewEngland!$D:$D, "London") -> 122.46964 | C11: =SUMIFS(Antigua!$L:$L, Antigua!$B:$B, $A11, Antigua!$D:$D, "Out Ports") + SUMIFS(Barbados!$L:$L, Barbados!$B:$B, $A11, Barbados!$D:$D, "Out Ports") + SUMIFS(Bermuda!$L:$L, Bermuda!$B:$B, $A11, Bermuda!$D:$D, "Out Ports") + SUMIFS(Carolina!$L:$L, Carolina!$B:$B, $A11, Carolina!$D:$D, "Out Ports") + SUMIFS(Jamaica!$L:$L, Jamaica!$B:$B, $A11, Jamaica!$D:$D, "Out Ports") + SUMIFS(Mountserat!$L:$L, Mountserat!$B:$B, $A11, Mountserat!$D:$D, "Out Ports") + SUMIFS(Nevis!$L:$L, Nevis!$B:$B, $A11, Nevis!$D:$D, "Out Ports") + SUMIFS(NewEngland!$L:$L, NewEngland!$B:$B, $A11, NewEngland!$D:$D, "Out Ports") -> 115.75491 | D11: =ROUND((B11+C11),2) -> 238.22
A12: Dry Ginger | B12: =SUMIFS(Antigua!$L:$L, Antigua!$B:$B, $A12, Antigua!$D:$D, "London") + SUMIFS(Barbados!$L:$L, Barbados!$B:$B, $A12, Barbados!$D:$D, "London") + SUMIFS(Bermuda!$L:$L, Bermuda!$B:$B, $A12, Bermuda!$D:$D, "London") + SUMIFS(Carolina!$L:$L, Carolina!$B:$B, $A12, Carolina!$D:$D, "London") + SUMIFS(Jamaica!$L:$L, Jamaica!$B:$B, $A12, Jamaica!$D:$D, "London") + SUMIFS(Mountserat!$L:$L, Mountserat!$B:$B, $A12, Mountserat!$D:$D, "London") + SUMIFS(Nevis!$L:$L, Nevis!$B:$B, $A12, Nevis!$D:$D, "London") + SUMIFS(NewEngland!$L:$L, NewEngland!$B:$B, $A12, NewEngland!$D:$D, "London") -> 326.675 | C12: =SUMIFS(Antigua!$L:$L, Antigua!$B:$B, $A12, Antigua!$D:$D, "Out Ports") + SUMIFS(Barbados!$L:$L, Barbados!$B:$B, $A12, Barbados!$D:$D, "Out Ports") + SUMIFS(Bermuda!$L:$L, Bermuda!$B:$B, $A12, Bermuda!$D:$D, "Out Ports") + SUMIFS(Carolina!$L:$L, Carolina!$B:$B, $A12, Carolina!$D:$D, "Out Ports") + SUMIFS(Jamaica!$L:$L, Jamaica!$B:$B, $A12, Jamaica!$D:$D, "Out Ports") + SUMIFS(Mountserat!$L:$L, Mountserat!$B:$B, $A12, Mountserat!$D:$D, "Out Ports") + SUMIFS(Nevis!$L:$L, Nevis!$B:$B, $A12, Nevis!$D:$D, "Out Ports") + SUMIFS(NewEngland!$L:$L, NewEngland!$B:$B, $A12, NewEngland!$D:$D, "Out Ports") -> 81.850446 | D12: =ROUND((B12+C12),2) -> 408.53
A13: Elephant Teeth | B13: =SUMIFS(Antigua!$L:$L, Antigua!$B:$B, $A13, Antigua!$D:$D, "London") + SUMIFS(Barbados!$L:$L, Barbados!$B:$B, $A13, Barbados!$D:$D, "London") + SUMIFS(Bermuda!$L:$L, Bermuda!$B:$B, $A13, Bermuda!$D:$D, "London") + SUMIFS(Carolina!$L:$L, Carolina!$B:$B, $A13, Carolina!$D:$D, "London") + SUMIFS(Jamaica!$L:$L, Jamaica!$B:$B, $A13, Jamaica!$D:$D, "London") + SUMIFS(Mountserat!$L:$L, Mountserat!$B:$B, $A13, Mountserat!$D:$D, "London") + SUMIFS(Nevis!$L:$L, Nevis!$B:$B, $A13, Nevis!$D:$D, "London") + SUMIFS(NewEngland!$L:$L, NewEngland!$B:$B, $A13, NewEngland!$D:$D, "London") -> 1.4544643 | C13: =SUMIFS(Antigua!$L:$L, Antigua!$B:$B, $A13, Antigua!$D:$D, "Out Ports") + SUMIFS(Barbados!$L:$L, Barbados!$B:$B, $A13, Barbados!$D:$D, "Out Ports") + SUMIFS(Bermuda!$L:$L, Bermuda!$B:$B, $A13, Bermuda!$D:$D, "Out Ports") + SUMIFS(Carolina!$L:$L, Carolina!$B:$B, $A13, Carolina!$D:$D, "Out Ports") + SUMIFS(Jamaica!$L:$L, Jamaica!$B:$B, $A13, Jamaica!$D:$D, "Out Ports") + SUMIFS(Mountserat!$L:$L, Mountserat!$B:$B, $A13, Mountserat!$D:$D, "Out Ports") + SUMIFS(Nevis!$L:$L, Nevis!$B:$B, $A13, Nevis!$D:$D, "Out Ports") + SUMIFS(NewEngland!$L:$L, NewEngland!$B:$B, $A13, NewEngland!$D:$D, "Out Ports") -> 9.1361607 | D13: =ROUND((B13+C13),2) -> 10.59
... A31: Madera Wine | B31: =SUMIFS(Antigua!$L:$L, Antigua!$B:$B, $A31, Antigua!$D:$D, "London") + SUMIFS(Barbados!$L:$L, Barbados!$B:$B, $A31, Barbados!$D:$D, "London") + SUMIFS(Bermuda!$L:$L, Bermuda!$B:$B, $A31, Bermuda!$D:$D, "London") + SUMIFS(Carolina!$L:$L, Carolina!$B:$B, $A31, Carolina!$D:$D, "London") + SUMIFS(Jamaica!$L:$L, Jamaica!$B:$B, $A31, Jamaica!$D:$D, "London") + SUMIFS(Mountserat!$L:$L, Mountserat!$B:$B, $A31, Mountserat!$D:$D, "London") + SUMIFS(Nevis!$L:$L, Nevis!$B:$B, $A31, Nevis!$D:$D, "London") + SUMIFS(NewEngland!$L:$L, NewEngland!$B:$B, $A31, NewEngland!$D:$D, "London") -> 41.049107 | C31: =SUMIFS(Antigua!$L:$L, Antigua!$B:$B, $A31, Antigua!$D:$D, "Out Ports") + SUMIFS(Barbados!$L:$L, Barbados!$B:$B, $A31, Barbados!$D:$D, "Out Ports") + SUMIFS(Bermuda!$L:$L, Bermuda!$B:$B, $A31, Bermuda!$D:$D, "Out Ports") + SUMIFS(Carolina!$L:$L, Carolina!$B:$B, $A31, Carolina!$D:$D, "Out Ports") + SUMIFS(Jamaica!$L:$L, Jamaica!$B:$B, $A31, Jamaica!$D:$D, "Out Ports") + SUMIFS(Mountserat!$L:$L, Mountserat!$B:$B, $A31, Mountserat!$D:$D, "Out Ports") + SUMIFS(Nevis!$L:$L, Nevis!$B:$B, $A31, Nevis!$D:$D, "Out Ports") + SUMIFS(NewEngland!$L:$L, NewEngland!$B:$B, $A31, NewEngland!$D:$D, "Out Ports") -> 2.0379464 | D31: =ROUND((B31+C31),2) -> 43.09

Sheet Antigua
A1: YEAR | B1: COMMODITY_NAME | C1: FROM_LOCATION | D1: TO_LOCATION | E1: ton | F1: hh | G1: quarter | H1: lb | J1: Total Pounds | L1: WEIGHT
A2: 1711 | B2: Brown Sugar | C2: Antigua | D2: London | F2: 22156 | H2: 1 | J2: =(E2*2240)+(F2*112)+(G2*28)+H2 -> 2481473 | L2: =J2/2240 -> 1107.8004
A3: 1711 | B3: Chocolate | C3: Antigua | D3: London | J3: =(E3*2240)+(F3*112)+(G3*28)+H3 -> 0 | L3: =J3/2240 -> 0
A4: 1711 | B4: Cocoa Nuts | C4: Antigua | D4: London | F4: 21 | H4: 14 | J4: =(E4*2240)+(F4*112)+(G4*28)+H4 -> 2366 | L4: =J4/2240 -> 1.05625
A5: 1711 | B5: Cotton | C5: Antigua | D5: London | F5: 473 | H5: 5 | J5: =(E5*2240)+(F5*112)+(G5*28)+H5 -> 52981 | L5: =J5/2240 -> 23.652232
A6: 1711 | B6: Dry Ginger | C6: Antigua | D6: London | F6: 303 | G6: 3 | H6: 23 | J6: =(E6*2240)+(F6*112)+(G6*28)+H6 -> 34043 | L6: =J6/2240 -> 15.197768
A7: 1711 | B7: Elephant Teeth | C7: Antigua | D7: London | F7: 23 | G7: 3 | H7: 21 | J7: =(E7*2240)+(F7*112)+(G7*28)+H7 -> 2681 | L7: =J7/2240 -> 1.196875
A8: 1711 | B8: Indigo | C8: Antigua | D8: London | H8: 3191 | J8: =(E8*2240)+(F8*112)+(G8*28)+H8 -> 3191 | L8: =J8/2240 -> 1.4245536
A9: 1711 | B9: Lemon Water | C9: Antigua | D9: London | J9: =(E9*2240)+(F9*112)+(G9*28)+H9 -> 0 | L9: =J9/2240 -> 0
A10: 1711 | B10: Lignum Vitae | C10: Antigua | D10: London | F10: 2897 | G10: 1 | H10: 9 | J10: =(E10*2240)+(F10*112)+(G10*28)+H10 -> 324501 | L10: =J10/2240 -> 144.86652
A11: 1711 | B11: Lime Juice | C11: Antigua | D11: London | J11: =(E11*2240)+(F11*112)+(G11*28)+H11 -> 0 | L11: =J11/2240 -> 0
A12: 1711 | B12: Madera Wine | C12: Antigua | D12: London | H12: 4998 | I12: 2tun 1hh 10gal | J12: =(E12*2240)+(F12*112)+(G12*28)+H12 -> 4998 | L12: =J12/2240 -> 2.23125
A13: 1711 | B13: Molasses | C13: Antigua | D13: London | F13: 814 | G13: 3 | H13: 8 | J13: =(E13*2240)+(F13*112)+(G13*28)+H13 -> 91260 | L13: =J13/2240 -> 40.741071
A14: 1711 | B14: Rum | C14: Antigua | D14: London | H14: 7007 | I14: 809 gal | J14: =(E14*2240)+(F14*112)+(G14*28)+H14 -> 7007 | L14: =J14/2240 -> 3.128125
A15: 1711 | B15: Shruff | C15: Antigua | D15: London | F15: 19 | G15: 3 | J15: =(E15*2240)+(F15*112)+(G15*28)+H15 -> 2212 | L15: =J15/2240 -> 0.9875
A16: 1711 | B16: Succands | C16: Antigua | D16: London | H16: 296 | J16: =(E16*2240)+(F16*112)+(G16*28)+H16 -> 296 | L16: =J16/2240 -> 0.13214286
A17: 1711 | B17: Tobacco | C17: Antigua | D17: London | H17: 11000 | J17: =(E17*2240)+(F17*112)+(G17*28)+H17 -> 11000 | L17: =J17/2240 -> 4.9107143
A18: 1711 | B18: Tortoise Shell | C18: Antigua | D18: London | H18: 6 | J18: =(E18*2240)+(F18*112)+(G18*28)+H18 -> 6 | L18: =J18/2240 -> 0.0026785714
A19: 1711 | B19: White Sugar | C19: Antigua | D19: London | F19: 5 | G19: 1 | J19: =(E19*2240)+(F19*112)+(G19*28)+H19 -> 588 | L19: =J19/2240 -> 0.2625
A20: 1711 | B20: Brown Sugar | C20: Antigua | D20: Out Ports | F20: 6168 | H20: 10 | J20: =(E20*2240)+(F20*112)+(G20*28)+H20 -> 690826 | L20: =J20/2240 -> 308.40446
A21: 1711 | B21: Cocoa | C21: Antigua | D21: Out Ports | H21: 304 | J21: =(E21*2240)+(F21*112)+(G21*28)+H21 -> 304 | L21: =J21/2240 -> 0.13571429
A22: 1711 | B22: Cocoa Nuts | C22: Antigua | D22: Out Ports | F22: 14 | H22: 11 | J22: =(E22*2240)+(F22*112)+(G22*28)+H22 -> 1579 | L22: =J22/2240 -> 0.70491071
A23: 1711 | B23: Cotton | C23: Antigua | D23: Out Ports | H23: 32545 | J23: =(E23*2240)+(F23*112)+(G23*28)+H23 -> 32545 | L23: =J23/2240 -> 14.529018
A24: 1711 | B24: Dry Ginger | C24: Antigua | D24: Out Ports | F24: 171 | G24: 1 | H24: 21 | J24: =(E24*2240)+(F24*112)+(G24*28)+H24 -> 19201 | L24: =J24/2240 -> 8.571875
A25: 1711 | B25: Indigo | C25: Antigua | D25: Out Ports | H25: 699 | J25: =(E25*2240)+(F25*112)+(G25*28)+H25 -> 699 | L25: =J25/2240 -> 0.31205357
A26: 1711 | B26: Lignum Vitae | C26: Antigua | D26: Out Ports | F26: 1032 | H26: 21 | J26: =(E26*2240)+(F26*112)+(G26*28)+H26 -> 115605 | L26: =J26/2240 -> 51.609375
A27: 1711 | B27: Lime Juice | C27: Antigua | D27: Out Ports | J27: =(E27*2240)+(F27*112)+(G27*28)+H27 -> 0 | L27: =J27/2240 -> 0
A28: 1711 | B28: Madera Wine | C28: Antigua | D28: Out Ports | J28: =(E28*2240)+(F28*112)+(G28*28)+H28 -> 0 | L28: =J28/2240 -> 0
A29: 1711 | B29: Molasses | C29: Antigua | D29: Out Ports | F29: 389 | G29: 3 | H29: 13 | J29: =(E29*2240)+(F29*112)+(G29*28)+H29 -> 43665 | L29: =J29/2240 -> 19.493304
A30: 1711 | B30: Rice | C30: Antigua | D30: Out Ports | J30: =(E30*2240)+(F30*112)+(G30*28)+H30 -> 0 | L30: =J30/2240 -> 0
A31: 1711 | B31: Rum | C31: Antigua | D31: Out Ports | H31: 2391 | I31: 276gal | J31: =(E31*2240)+(F31*112)+(G31*28)+H31 -> 2391 | L31: =J31/2240 -> 1.0674107
A32: 1711 | B32: Shruff | C32: Antigua | D32: Out Ports | F32: 1 | G32: 2 | J32: =(E32*2240)+(F32*112)+(G32*28)+H32 -> 168 | L32: =J32/2240 -> 0.075
A33: 1711 | B33: Succands | C33: Antigua | D33: Out Ports | H33: 20 | J33: =(E33*2240)+(F33*112)+(G33*28)+H33 -> 20 | L33: =J33/2240 -> 0.0089285714
A34: 1711 | B34: Tobacco | C34: Antigua | D34: Out Ports | J34: =(E34*2240)+(F34*112)+(G34*28)+H34 -> 0 | L34: =J34/2240 -> 0
A35: 1711 | B35: Tortoise Shell | C35: Antigua | D35: Out Ports | J35: =(E35*2240)+(F35*112)+(G35*28)+H35 -> 0 | L35: =J35/2240 -> 0
A36: 1711 | B36: White Sugar | C36: Antigua | D36: Out Ports | F36: 11 | G36: 1 | H36: 21 | J36: =(E36*2240)+(F36*112)+(G36*28)+H36 -> 1281 | L36: =J36/2240 -> 0.571875
A37: 1711 | B37: Wood, Fustick | C37: Antigua | D37: Out Ports | J37: =(E37*2240)+(F37*112)+(G37*28)+H37 -> 0 | L37: =J37/2240 -> 0

Sheet Barbados
A1: YEAR | B1: COMMODITY_NAME | C1: FROM_LOCATION | D1: TO_LOCATION | E1: ton | F1: hh | G1: quarter | H1: lb | J1: Total Pounds | L1: WEIGHT
A2: 1711 | B2: Aloes Epatica | C2: Barbados | D2: London | H2: 35203 | J2: =(E2*2240)+(F2*112)+(G2*28)+H2 -> 35203 | L2: =J2/2240 -> 15.715625
A3: 1711 | B3: Annatto | C3: Barbados | D3: London | J3: =(E3*2240)+(F3*112)+(G3*28)+H3 -> 0 | L3: =J3/2240 -> 0
A4: 1711 | B4: Barrel Staves | C4: Barbados | D4: London | F4: 253 | H4: 14 | J4: =(E4*2240)+(F4*112)+(G4*28)+H4 -> 28350 | L4: =J4/2240 -> 12.65625
A5: 1711 | B5: Brown Sugar | C5: Barbados | D5: London | F5: 137360 | G5: 3 | H5: 7 | J5: =(E5*2240)+(F5*112)+(G5*28)+H5 -> 15384411 | L5: =J5/2240 -> 6868.0406
A6: 1711 | B6: Chocolate Paste | C6: Barbados | D6: London | H6: 72 | J6: =(E6*2240)+(F6*112)+(G6*28)+H6 -> 72 | L6: =J6/2240 -> 0.032142857
A7: 1711 | B7: Cocoa Nuts | C7: Barbados | D7: London | F7: 22 | G7: 1 | H7: 26 | J7: =(E7*2240)+(F7*112)+(G7*28)+H7 -> 2518 | L7: =J7/2240 -> 1.1241071
A8: 1711 | B8: Cocoa Paste | C8: Barbados | D8: London | H8: 8 | J8: =(E8*2240)+(F8*112)+(G8*28)+H8 -> 8 | L8: =J8/2240 -> 0.0035714286
A9: 1711 | B9: Cotton | C9: Barbados | D9: London | F9: 1405 | G9: 1 | H9: 6 | J9: =(E9*2240)+(F9*112)+(G9*28)+H9 -> 157394 | L9: =J9/2240 -> 70.265179
A10: 1711 | B10: Dry Ginger | C10: Barbados | D10: London | F10: 4893 | G10: 3 | J10: =(E10*2240)+(F10*112)+(G10*28)+H10 -> 548100 | L10: =J10/2240 -> 244.6875
A11: 1711 | B11: Elephant Teeth | C11: Barbados | D11: London | F11: 3 | G11: 1 | H11: 5 | J11: =(E11*2240)+(F11*112)+(G11*28)+H11 -> 369 | L11: =J11/2240 -> 0.16473214
A12: 1711 | B12: Green Ginger | C12: Barbados | D12: London | H12: 94 | J12: =(E12*2240)+(F12*112)+(G12*28)+H12 -> 94 | L12: =J12/2240 -> 0.041964286
A13: 1711 | B13: Hemp | C13: Barbados | D13: London | F13: 1600 | J13: =(E13*2240)+(F13*112)+(G13*28)+H13 -> 179200 | L13: =J13/2240 -> 80
A14: 1711 | B14: Indigo | C14: Barbados | D14: London | H14: 2270 | J14: =(E14*2240)+(F14*112)+(G14*28)+H14 -> 2270 | L14: =J14/2240 -> 1.0133929
A15: 1711 | B15: Lemon Water | C15: Barbados | D15: London | J15: =(E15*2240)+(F15*112)+(G15*28)+H15 -> 0 | L15: =J15/2240 -> 0
A16: 1711 | B16: Lignum Vitae | C16: Barbados | D16: London | F16: 53 | J16: =(E16*2240)+(F16*112)+(G16*28)+H16 -> 5936 | L16: =J16/2240 -> 2.65
A17: 1711 | B17: Lime Juice | C17: Barbados | D17: London | H17: 53153 | I17: 6136 gal | J17: =(E17*2240)+(F17*112)+(G17*28)+H17 -> 53153 | L17: =J17/2240 -> 23.729018
A18: 1711 | B18: Loaf Sugar | C18: Barbados | D18: London | J18: =(E18*2240)+(F18*112)+(G18*28)+H18 -> 0 | L18: =J18/2240 -> 0
A19: 1711 | B19: Madera Wine | C19: Barbados | D19: London | H19: 71847 | I19: 32tun 3hh 41gal | J19: =(E19*2240)+(F19*112)+(G19*28)+H19 -> 71847 | L19: =J19/2240 -> 32.074554
A20: 1711 | B20: Molasses | C20: Barbados | D20: London | F20: 134 | J20: =(E20*2240)+(F20*112)+(G20*28)+H20 -> 15008 | L20: =J20/2240 -> 6.7
A21: 1711 | B21: Oranges | C21: Barbados | D21: London | J21: =(E21*2240)+(F21*112)+(G21*28)+H21 -> 0 | L21: =J21/2240 -> 0
A22: 1711 | B22: Pimento | C22: Barbados | D22: London | H22: 65 | J22: =(E22*2240)+(F22*112)+(G22*28)+H22 -> 65 | L22: =J22/2240 -> 0.029017857
A23: 1711 | B23: Rice | C23: Barbados | D23: London | F23: 37 | G23: 2 | H23: 16 | J23: =(E23*2240)+(F23*112)+(G23*28)+H23 -> 4216 | L23: =J23/2240 -> 1.8821429
A24: 1711 | B24: Rum | C24: Barbados | D24: London | H24: 77157 | I24: 8907.5gal | J24: =(E24*2240)+(F24*112)+(G24*28)+H24 -> 77157 | L24: =J24/2240 -> 34.445089
A25: 1711 | B25: Shruff | C25: Barbados | D25: London | F25: 62 | G25: 3 | H25: 5 | J25: =(E25*2240)+(F25*112)+(G25*28)+H25 -> 7033 | L25: =J25/2240 -> 3.1397321
A26: 1711 | B26: Snuff | C26: Barbados | D26: London | H26: 227 | J26: =(E26*2240)+(F26*112)+(G26*28)+H26 -> 227 | L26: =J26/2240 -> 0.10133929
A27: 1711 | B27: Succands | C27: Barbados | D27: London | H27: 1941 | J27: =(E27*2240)+(F27*112)+(G27*28)+H27 -> 1941 | L27: =J27/2240 -> 0.86651786
A28: 1711 | B28: Tobacco | C28: Barbados | D28: London | J28: =(E28*2240)+(F28*112)+(G28*28)+H28 -> 0 | L28: =J28/2240 -> 0
A29: 1711 | B29: Tortoise Shell | C29: Barbados | D29: London | H29: 128 | J29: =(E29*2240)+(F29*112)+(G29*28)+H29 -> 128 | L29: =J29/2240 -> 0.057142857
A30: 1711 | B30: White Sugar | C30: Barbados | D30: London | F30: 715 | G30: 2 | H30: 20 | J30: =(E30*2240)+(F30*112)+(G30*28)+H30 -> 80156 | L30: =J30/2240 -> 35.783929
A31: 1711 | B31: Wood, Braziletto | C31: Barbados | D31: London | F31: 200 | J31: =(E31*2240)+(F31*112)+(G31*28)+H31 -> 22400 | L31: =J31/2240 -> 10
A32: 1711 | B32: Brown Sugar | C32: Barbados | D32: Out Ports | F32: 29773 | H32: 15 | J32: =(E32*2240)+(F32*112)+(G32*28)+H32 -> 3334591 | L32: =J32/2240 -> 1488.6567
A33: 1711 | B33: Chocolate | C33: Barbados | D33: Out Ports | H33: 280 | J33: =(E33*2240)+(F33*112)+(G33*28)+H33 -> 280 | L33: =J33/2240 -> 0.125
A34: 1711 | B34: Cocoa Nuts | C34: Barbados | D34: Out Ports | F34: 123 | G34: 1 | H34: 20 | J34: =(E34*2240)+(F34*112)+(G34*28)+H34 -> 13824 | L34: =J34/2240 -> 6.1714286
A35: 1711 | B35: Cotton | C35: Barbados | D35: Out Ports | H35: 64934 | J35: =(E35*2240)+(F35*112)+(G35*28)+H35 -> 64934 | L35: =J35/2240 -> 28.988393
A36: 1711 | B36: Dry Ginger | C36: Barbados | D36: Out Ports | F36: 203 | G36: 3 | H36: 2 | J36: =(E36*2240)+(F36*112)+(G36*28)+H36 -> 22822 | L36: =J36/2240 -> 10.188393
A37: 1711 | B37: Indigo | C37: Barbados | D37: Out Ports | H37: 558 | J37: =(E37*2240)+(F37*112)+(G37*28)+H37 -> 558 | L37: =J37/2240 -> 0.24910714
A38: 1711 | B38: Lignum Vitae | C38: Barbados | D38: Out Ports | F38: 11 | G38: 2 | H38: 13 | J38: =(E38*2240)+(F38*112)+(G38*28)+H38 -> 1301 | L38: =J38/2240 -> 0.58080357
A39: 1711 | B39: Lime Juice | C39: Barbados | D39: Out Ports | H39: 24515 | I39: 2830gal | J39: =(E39*2240)+(F39*112)+(G39*28)+H39 -> 24515 | L39: =J39/2240 -> 10.944196
A40: 1711 | B40: Madera Wine | C40: Barbados | D40: Out Ports | H40: 4565 | I40: 2tun 23gal | J40: =(E40*2240)+(F40*112)+(G40*28)+H40 -> 4565 | L40: =J40/2240 -> 2.0379464
...

Sheet Bermuda
A1: YEAR | B1: COMMODTY_NAME | C1: FROM_LOCATION | D1: TO_LOCATION | E1: ton | F1: hh | G1: quarter | H1: lb | J1: Total Pounds | L1: WEIGHT
A2: 1711 | B2: Indigo | C2: Bermuda | D2: Out Ports | H2: 141 | J2: =(E2*2240)+(F2*112)+(G2*28)+H2 -> 141 | L2: =J2/2240 -> 0.062946429
A3: 1711 | B3: Wood, Logwood | C3: Bermuda | D3: Out Ports | E3: 44 | F3: 12 | G3: 3 | H3: 8 | J3: =(E3*2240)+(F3*112)+(G3*28)+H3 -> 99996 | L3: =J3/2240 -> 44.641071
A4: 1711 | B4: Shruff | C4: Bermuda | D4: Out Ports | F4: 1 | J4: =(E4*2240)+(F4*112)+(G4*28)+H4 -> 112 | L4: =J4/2240 -> 0.05
A5: 1711 | B5: Succands | C5: Bermuda | D5: Out Ports | H5: 87 | J5: =(E5*2240)+(F5*112)+(G5*28)+H5 -> 87 | L5: =J5/2240 -> 0.038839286
A6: 1711 | B6: Cotton | C6: Bermuda | D6: Out Ports | H6: 112 | J6: =(E6*2240)+(F6*112)+(G6*28)+H6 -> 112 | L6: =J6/2240 -> 0.05
A7: 1711 | B7: Cocoa Nuts | C7: Bermuda | D7: Out Ports | H7: 41 | J7: =(E7*2240)+(F7*112)+(G7*28)+H7 -> 41 | L7: =J7/2240 -> 0.018303571

Sheet Carolina
A1: YEAR | B1: COMMODITY_NAME | C1: FROM_LOCATION | D1: TO_LOCATION | E1: ton | F1: hh | G1: quarter | H1: lb | J1: Total Pounds | L1: WEIGHT
A2: 1711 | B2: Bees Wax | C2: Carolina | D2: London | F2: 1 | G2: 3 | H2: 14 | J2: =(E2*2240)+(F2*112)+(G2*28)+H2 -> 210 | L2: =J2/2240 -> 0.09375
A3: 1711 | B3: Brown Sugar | C3: Carolina | D3: London | H3: 14 | J3: =(E3*2240)+(F3*112)+(G3*28)+H3 -> 14 | L3: =J3/2240 -> 0.00625
A4: 1711 | B4: Chocolate | C4: Carolina | D4: London | J4: =(E4*2240)+(F4*112)+(G4*28)+H4 -> 0 | L4: =J4/2240 -> 0
A5: 1711 | B5: Cocoa Nuts | C5: Carolina | D5: London | F5: 431 | G5: 3 | H5: 21 | J5: =(E5*2240)+(F5*112)+(G5*28)+H5 -> 48377 | L5: =J5/2240 -> 21.596875
A6: 1711 | B6: Dry Ginger | C6: Carolina | D6: London | G6: 3 | J6: =(E6*2240)+(F6*112)+(G6*28)+H6 -> 84 | L6: =J6/2240 -> 0.0375
A7: 1711 | B7: Elephant Teeth | C7: Carolina | D7: London | H7: 12 | J7: =(E7*2240)+(F7*112)+(G7*28)+H7 -> 12 | L7: =J7/2240 -> 0.0053571429
A8: 1711 | B8: Rice | C8: Carolina | D8: London | F8: 2800 | G8: 2 | H8: 7 | J8: =(E8*2240)+(F8*112)+(G8*28)+H8 -> 313663 | L8: =J8/2240 -> 140.02812
A9: 1711 | B9: Tobacco | C9: Carolina | D9: London | J9: =(E9*2240)+(F9*112)+(G9*28)+H9 -> 0 | L9: =J9/2240 -> 0
A10: 1711 | B10: Tortoise Shell | C10: Carolina | D10: London | H10: 11 | J10: =(E10*2240)+(F10*112)+(G10*28)+H10 -> 11 | L10: =J10/2240 -> 0.0049107143
A11: 1711 | B11: Wood, Braziletto | C11: Carolina | D11: London | E11: 6 | F11: 14 | J11: =(E11*2240)+(F11*112)+(G11*28)+H11 -> 15008 | L11: =J11/2240 -> 6.7
A12: 1711 | B12: Wood, Logwood | C12: Carolina | D12: London | E12: 1 | F12: 7 | G12: 3 | J12: =(E12*2240)+(F12*112)+(G12*28)+H12 -> 3108 | L12: =J12/2240 -> 1.3875
A13: 1711 | B13: Brown Sugar | C13: Carolina | D13: Out Ports | J13: =(E13*2240)+(F13*112)+(G13*28)+H13 -> 0 | L13: =J13/2240 -> 0
A14: 1711 | B14: Cocoa | C14: Carolina | D14: Out Ports | F14: 52 | G14: 16 | H14: 11 | J14: =(E14*2240)+(F14*112)+(G14*28)+H14 -> 6283 | L14: =J14/2240 -> 2.8049107
A15: 1711 | B15: Cocoa Nuts | C15: Carolina | D15: Out Ports | F15: 29 | H15: 3 | J15: =(E15*2240)+(F15*112)+(G15*28)+H15 -> 3251 | L15: =J15/2240 -> 1.4513393
A16: 1711 | B16: Cortex Winteranus | C16: Carolina | D16: Out Ports | H16: 542 | J16: =(E16*2240)+(F16*112)+(G16*28)+H16 -> 542 | L16: =J16/2240 -> 0.24196429
A17: 1711 | B17: Cotton | C17: Carolina | D17: Out Ports | H17: 13664 | J17: =(E17*2240)+(F17*112)+(G17*28)+H17 -> 13664 | L17: =J17/2240 -> 6.1
A18: 1711 | B18: Elephant Teeth | C18: Carolina | D18: Out Ports | J18: =(E18*2240)+(F18*112)+(G18*28)+H18 -> 0 | L18: =J18/2240 -> 0
A19: 1711 | B19: Indigo | C19: Carolina | D19: Out Ports | J19: =(E19*2240)+(F19*112)+(G19*28)+H19 -> 0 | L19: =J19/2240 -> 0
A20: 1711 | B20: Lime Juice | C20: Carolina | D20: Out Ports | H20: 156 | I20: 15 gal | J20: =(E20*2240)+(F20*112)+(G20*28)+H20 -> 156 | L20: =J20/2240 -> 0.069642857
A21: 1711 | B21: Rice | C21: Carolina | D21: Out Ports | F21: 5877 | H21: 1 | J21: =(E21*2240)+(F21*112)+(G21*28)+H21 -> 658225 | L21: =J21/2240 -> 293.85045

Sheet Jamaica
A1: YEAR | B1: COMMODITY_NAME | C1: FROM_LOCATION | D1: TO_LOCATION | E1: ton | F1: hh | G1: quarter | H1: lb | J1: Total Pounds | L1: WEIGHT | O1: Total Not Sugar | Q1: Total Sugar
A2: 1711 | B2: Annatto | C2: Jamaica | D2: London | J2: =(E2*2240)+(F2*112)+(G2*28)+H2 -> 0 | L2: =J2/2240 -> 0
A3: 1711 | B3: Bees Wax | C3: Jamaica | D3: London | F3: 6 | J3: =(E3*2240)+(F3*112)+(G3*28)+H3 -> 672 | L3: =J3/2240 -> 0.3
A4: 1711 | B4: Braziletto Wood | C4: Jamaica | D4: London | F4: 2 | J4: =(E4*2240)+(F4*112)+(G4*28)+H4 -> 224 | L4: =J4/2240 -> 0.1
A5: 1711 | B5: Brown Sugar | C5: Jamaica | D5: London | F5: 39849 | G5: 1 | H5: 14 | J5: =(E5*2240)+(F5*112)+(G5*28)+H5 -> 4463130 | L5: =J5/2240 -> 1992.4688
A6: 1711 | B6: Chocolate | C6: Jamaica | D6: London | H6: 18 | J6: =(E6*2240)+(F6*112)+(G6*28)+H6 -> 18 | L6: =J6/2240 -> 0.0080357143
A7: 1711 | B7: Cocoa Nuts | C7: Jamaica | D7: London | F7: 801 | G7: 3 | J7: =(E7*2240)+(F7*112)+(G7*28)+H7 -> 89796 | L7: =J7/2240 -> 40.0875
A8: 1711 | B8: Cocoa Paster | C8: Jamaica | D8: London | H8: 12 | J8: =(E8*2240)+(F8*112)+(G8*28)+H8 -> 12 | L8: =J8/2240 -> 0.0053571429
A9: 1711 | B9: Cocoa Wood | C9: Jamaica | D9: London | E9: 7 | F9: 7 | G9: 1 | J9: =(E9*2240)+(F9*112)+(G9*28)+H9 -> 16492 | L9: =J9/2240 -> 7.3625
A10: 1711 | B10: Cotton | C10: Jamaica | D10: London | F10: 450 | J10: =(E10*2240)+(F10*112)+(G10*28)+H10 -> 50400 | L10: =J10/2240 -> 22.5
A11: 1711 | B11: Dry Ginger | C11: Jamaica | D11: London | F11: 1325 | G11: 2 | H11: 19 | J11: =(E11*2240)+(F11*112)+(G11*28)+H11 -> 148475 | L11: =J11/2240 -> 66.283482
A12: 1711 | B12: Elephant Teeth | C12: Jamaica | D12: London | J12: =(E12*2240)+(F12*112)+(G12*28)+H12 -> 0 | L12: =J12/2240 -> 0
A13: 1711 | B13: Indigo | C13: Jamaica | D13: London | H13: 14569 | J13: =(E13*2240)+(F13*112)+(G13*28)+H13 -> 14569 | L13: =J13/2240 -> 6.5040179
A14: 1711 | B14: Jamaica Roots | C14: Jamaica | D14: London | F14: 18 | G14: 1 | H14: 26 | J14: =(E14*2240)+(F14*112)+(G14*28)+H14 -> 2070 | L14: =J14/2240 -> 0.92410714
A15: 1711 | B15: Lime Juice | C15: Jamaica | D15: London | H15: 17977 | I15: 1728gal | J15: =(E15*2240)+(F15*112)+(G15*28)+H15 -> 17977 | L15: =J15/2240 -> 8.0254464
A16: 1711 | B16: Madera Wine | C16: Jamaica | D16: London | H16: 4254 | I16: 1tun 2hh 31gal | J16: =(E16*2240)+(F16*112)+(G16*28)+H16 -> 4254 | L16: =J16/2240 -> 1.8991071
A17: 1711 | B17: Molasses | C17: Jamaica | D17: London | F17: 50 | G17: 2 | H17: 20 | J17: =(E17*2240)+(F17*112)+(G17*28)+H17 -> 5676 | L17: =J17/2240 -> 2.5339286
A18: 1711 | B18: Pimento | C18: Jamaica | D18: London | H18: 56000 | J18: =(E18*2240)+(F18*112)+(G18*28)+H18 -> 56000 | L18: =J18/2240 -> 25
A19: 1711 | B19: Rum | C19: Jamaica | D19: London | H19: 42991 | I19: 4132.5gal | J19: =(E19*2240)+(F19*112)+(G19*28)+H19 -> 42991 | L19: =J19/2240 -> 19.192411
A20: 1711 | B20: Shruff | C20: Jamaica | D20: London | J20: =(E20*2240)+(F20*112)+(G20*28)+H20 -> 0 | L20: =J20/2240 -> 0
A21: 1711 | B21: Snuff | C21: Jamaica | D21: London | H21: 564 | J21: =(E21*2240)+(F21*112)+(G21*28)+H21 -> 564 | L21: =J21/2240 -> 0.25178571
A22: 1711 | B22: Succands | C22: Jamaica | D22: London | H22: 360 | J22: =(E22*2240)+(F22*112)+(G22*28)+H22 -> 360 | L22: =J22/2240 -> 0.16071429
A23: 1711 | B23: Sugar Loaf | C23: Jamaica | D23: London | J23: =(E23*2240)+(F23*112)+(G23*28)+H23 -> 0 | L23: =J23/2240 -> 0
A24: 1711 | B24: Tobacco | C24: Jamaica | D24: London | J24: =(E24*2240)+(F24*112)+(G24*28)+H24 -> 0 | L24: =J24/2240 -> 0
A25: 1711 | B25: Tortoise Shell | C25: Jamaica | D25: London | H25: 644 | J25: =(E25*2240)+(F25*112)+(G25*28)+H25 -> 644 | L25: =J25/2240 -> 0.2875
A26: 1711 | B26: White Sugar | C26: Jamaica | D26: London | J26: =(E26*2240)+(F26*112)+(G26*28)+H26 -> 0 | L26: =J26/2240 -> 0
A27: 1711 | B27: Wood, Fustick | C27: Jamaica | D27: London | E27: 252 | F27: 10 | G27: 3 | H27: 20 | J27: =(E27*2240)+(F27*112)+(G27*28)+H27 -> 565704 | L27: =J27/2240 -> 252.54643
A28: 1711 | B28: Wood, Logwood | C28: Jamaica | D28: London | E28: 133 | F28: 16 | G28: 1 | H28: 10 | J28: =(E28*2240)+(F28*112)+(G28*28)+H28 -> 299750 | L28: =J28/2240 -> 133.81696
A29: 1711 | B29: Wood, Nicaragua | C29: Jamaica | D29: London | E29: 34 | F29: 5 | G29: 1 | J29: =(E29*2240)+(F29*112)+(G29*28)+H29 -> 76748 | L29: =J29/2240 -> 34.2625
A30: 1711 | B30: Wool Vigonia | C30: Jamaica | D30: London | F30: 51 | G30: 2 | H30: 12 | I30: Vigonia is related to a llama??? | J30: =(E30*2240)+(F30*112)+(G30*28)+H30 -> 5780 | L30: =J30/2240 -> 2.5803571
A31: 1711 | B31: Brown Sugar | C31: Jamaica | D31: Out Ports | F31: 57994 | G31: 2 | H31: 26 | J31: =(E31*2240)+(F31*112)+(G31*28)+H31 -> 6495410 | L31: =J31/2240 -> 2899.7366
A32: 1711 | B32: Chocolate | C32: Jamaica | D32: Out Ports | H32: 17 | J32: =(E32*2240)+(F32*112)+(G32*28)+H32 -> 17 | L32: =J32/2240 -> 0.0075892857
A33: 1711 | B33: Cocoa Nuts | C33: Jamaica | D33: Out Ports | F33: 777 | G33: 3 | H33: 16 | J33: =(E33*2240)+(F33*112)+(G33*28)+H33 -> 87124 | L33: =J33/2240 -> 38.894643
A34: 1711 | B34: Cocoa Wood | C34: Jamaica | D34: Out Ports | F34: 142 | G34: 3 | H34: 8
A35: 1711 | B35: Cortex Winteranus | C35: Jamaica | D35: Out Ports | H35: 1832 | J35: =(E35*2240)+(F35*112)+(G35*28)+H35 -> 1832 | L35: =J35/2240 -> 0.81785714
A36: 1711 | B36: Cotton | C36: Jamaica | D36: Out Ports | H36: 127320 | J36: =(E36*2240)+(F36*112)+(G36*28)+H36 -> 127320 | L36: =J36/2240 -> 56.839286
A37: 1711 | B37: Dry Ginger | C37: Jamaica | D37: Out Ports | F37: 1234 | G37: 3 | H37: 26 | J37: =(E37*2240)+(F37*112)+(G37*28)+H37 -> 138318 | L37: =J37/2240 -> 61.749107
A38: 1711 | B38: Elephant Teeth | C38: Jamaica | D38: Out Ports | F38: 182 | G38: 2 | H38: 25 | J38: =(E38*2240)+(F38*112)+(G38*28)+H38 -> 20465 | L38: =J38/2240 -> 9.1361607
A39: 1711 | B39: Indigo | C39: Jamaica | D39: Out Ports | H39: 48660 | J39: =(E39*2240)+(F39*112)+(G39*28)+H39 -> 48660 | L39: =J39/2240 -> 21.723214
A40: 1711 | B40: Lignum Vitae | C40: Jamaica | D40: Out Ports | F40: 107 | G40: 2 | H40: 8 | J40: =(E40*2240)+(F40*112)+(G40*28)+H40 -> 12048 | L40: =J40/2240 -> 5.3785714
...

Sheet Mountserat
A1: YEAR | B1: COMMODITY_NAME | C1: FROM_LOCATION | D1: TO_LOCATION | E1: ton | F1: hh | G1: quarter | H1: lb | J1: Total Pounds | L1: WEIGHT
A2: 1711 | B2: Brown Sugar | C2: Mountserat | D2: London | F2: 9017 | H2: 15 | J2: =(E2*2240)+(F2*112)+(G2*28)+H2 -> 1009919 | L2: =J2/2240 -> 450.8567
A3: 1711 | B3: Chocolate | C3: Mountserat | D3: London | J3: =(E3*2240)+(F3*112)+(G3*28)+H3 -> 0 | L3: =J3/2240 -> 0
A4: 1711 | B4: Cocoa Nuts | C4: Mountserat | D4: London | F4: 6 | G4: 2 | H4: 5 | J4: =(E4*2240)+(F4*112)+(G4*28)+H4 -> 733 | L4: =J4/2240 -> 0.32723214
A5: 1711 | B5: Cortex Winteranus | C5: Mountserat | D5: London | H5: 1166 | J5: =(E5*2240)+(F5*112)+(G5*28)+H5 -> 1166 | L5: =J5/2240 -> 0.52053571
A6: 1711 | B6: Cotton | C6: Mountserat | D6: London | F6: 6 | J6: =(E6*2240)+(F6*112)+(G6*28)+H6 -> 672 | L6: =J6/2240 -> 0.3
A7: 1711 | B7: Elephants Teeth | C7: Mountserat | D7: London | J7: =(E7*2240)+(F7*112)+(G7*28)+H7 -> 0 | L7: =J7/2240 -> 0
A8: 1711 | B8: Indigo | C8: Mountserat | D8: London | H8: 14747 | J8: =(E8*2240)+(F8*112)+(G8*28)+H8 -> 14747 | L8: =J8/2240 -> 6.5834821
A9: 1711 | B9: Lignum Vitae | C9: Mountserat | D9: London | J9: =(E9*2240)+(F9*112)+(G9*28)+H9 -> 0 | L9: =J9/2240 -> 0
A10: 1711 | B10: Lime Juice | C10: Mountserat | D10: London | J10: =(E10*2240)+(F10*112)+(G10*28)+H10 -> 0 | L10: =J10/2240 -> 0
A11: 1711 | B11: Madera Wine | C11: Mountserat | D11: London | H11: 1540 | I11: 2hh 22gal | J11: =(E11*2240)+(F11*112)+(G11*28)+H11 -> 1540 | L11: =J11/2240 -> 0.6875
A12: 1711 | B12: Molasses | C12: Mountserat | D12: London | J12: =(E12*2240)+(F12*112)+(G12*28)+H12 -> 0 | L12: =J12/2240 -> 0
A13: 1711 | B13: Pimento | C13: Mountserat | D13: London | H13: 2585 | J13: =(E13*2240)+(F13*112)+(G13*28)+H13 -> 2585 | L13: =J13/2240 -> 1.1540179
A14: 1711 | B14: Rum | C14: Mountserat | D14: London | H14: 676 | I14: 65 gal | J14: =(E14*2240)+(F14*112)+(G14*28)+H14 -> 676 | L14: =J14/2240 -> 0.30178571
A15: 1711 | B15: Shruff | C15: Mountserat | D15: London | F15: 1 | H15: 14 | J15: =(E15*2240)+(F15*112)+(G15*28)+H15 -> 126 | L15: =J15/2240 -> 0.05625
A16: 1711 | B16: Succands | C16: Mountserat | D16: London | J16: =(E16*2240)+(F16*112)+(G16*28)+H16 -> 0 | L16: =J16/2240 -> 0
A17: 1711 | B17: Tortoise Shell | C17: Mountserat | D17: London | H17: 40 | J17: =(E17*2240)+(F17*112)+(G17*28)+H17 -> 40 | L17: =J17/2240 -> 0.017857143
A18: 1711 | B18: White Sugar | C18: Mountserat | D18: London | F18: 38 | G18: 2 | H18: 10 | J18: =(E18*2240)+(F18*112)+(G18*28)+H18 -> 4322 | L18: =J18/2240 -> 1.9294643
A19: 1711 | B19: Brown Sugar | C19: Mountserat | D19: Out Ports | F19: 3055 | G19: 3 | H19: 26 | J19: =(E19*2240)+(F19*112)+(G19*28)+H19 -> 342270 | L19: =J19/2240 -> 152.79911
A20: 1711 | B20: Cocoa | C20: Mountserat | D20: Out Ports | H20: 499 | J20: =(E20*2240)+(F20*112)+(G20*28)+H20 -> 499 | L20: =J20/2240 -> 0.22276786
A21: 1711 | B21: Cocoa Nuts | C21: Mountserat | D21: Out Ports | F21: 1 | G21: 1 | H21: 18 | J21: =(E21*2240)+(F21*112)+(G21*28)+H21 -> 158 | L21: =J21/2240 -> 0.070535714
A22: 1711 | B22: Cotton | C22: Mountserat | D22: Out Ports | H22: 1220 | J22: =(E22*2240)+(F22*112)+(G22*28)+H22 -> 1220 | L22: =J22/2240 -> 0.54464286
A23: 1711 | B23: Dry Ginger | C23: Mountserat | D23: Out Ports | F23: 24 | G23: 1 | H23: 22 | J23: =(E23*2240)+(F23*112)+(G23*28)+H23 -> 2738 | L23: =J23/2240 -> 1.2223214
A24: 1711 | B24: Elephants Teeth | C24: Mountserat | D24: Out Ports | J24: =(E24*2240)+(F24*112)+(G24*28)+H24 -> 0 | L24: =J24/2240 -> 0
A25: 1711 | B25: Indigo | C25: Mountserat | D25: Out Ports | H25: 18047 | J25: =(E25*2240)+(F25*112)+(G25*28)+H25 -> 18047 | L25: =J25/2240 -> 8.0566964
A26: 1711 | B26: Lime Juice | C26: Mountserat | D26: Out Ports | H26: 1560 | I26: 150 gal | J26: =(E26*2240)+(F26*112)+(G26*28)+H26 -> 1560 | L26: =J26/2240 -> 0.69642857
A27: 1711 | B27: Pimento | C27: Mountserat | D27: Out Ports | H27: 5095 | J27: =(E27*2240)+(F27*112)+(G27*28)+H27 -> 5095 | L27: =J27/2240 -> 2.2745536

Sheet Nevis
A1: YEAR | B1: COMMODITY_NAME | C1: FROM_LOCATION | D1: TO_LOCATION | E1: ton | F1: hh | G1: quarter | H1: lb | J1: Total Pounds | L1: WEIGHT | N1: Total Not Sugar | P1: Total Sugar
A2: 1711 | B2: Brown Sugar | C2: Nevis | D2: London | F2: 14085 | J2: =(E2*2240)+(F2*112)+(G2*28)+(H2) -> 1577520 | L2: =J2/2240 -> 704.25
A3: 1711 | B3: Chocolate | C3: Nevis | D3: London | J3: =(E3*2240)+(F3*112)+(G3*28)+(H3) -> 0 | L3: =J3/2240 -> 0
A4: 1711 | B4: Cocoa Nuts | C4: Nevis | D4: London | J4: =(E4*2240)+(F4*112)+(G4*28)+(H4) -> 0 | L4: =J4/2240 -> 0
A5: 1711 | B5: Cortex Winteranus | C5: Nevis | D5: London | H5: 4356 | J5: =(E5*2240)+(F5*112)+(G5*28)+(H5) -> 4356 | L5: =J5/2240 -> 1.9446429
A6: 1711 | B6: Cotton | C6: Nevis | D6: London | F6: 115 | H6: 5 | J6: =(E6*2240)+(F6*112)+(G6*28)+(H6) -> 12885 | L6: =J6/2240 -> 5.7522321
A7: 1711 | B7: Elephant Teeth | C7: Nevis | D7: London | F7: 1 | G7: 3 | J7: =(E7*2240)+(F7*112)+(G7*28)+(H7) -> 196 | L7: =J7/2240 -> 0.0875 | N7: =L7+L13+L16+L17+L20+L23+L24+L28+L33+L34+L35+L36+L37+L15 -> 9.4316964 | P7: =L9+L10+L11+L32 -> 32.469196
A8: 1711 | B8: Indigo | C8: Nevis | D8: London | H8: 480 | J8: =(E8*2240)+(F8*112)+(G8*28)+(H8) -> 480 | L8: =J8/2240 -> 0.21428571
A9: 1711 | B9: Lignum Vitae | C9: Nevis | D9: London | F9: 579 | J9: =(E9*2240)+(F9*112)+(G9*28)+(H9) -> 64848 | L9: =J9/2240 -> 28.95
A10: 1711 | B10: Lime Juice | C10: Nevis | D10: London | H10: 208 | I10: 20gal | J10: =(E10*2240)+(F10*112)+(G10*28)+(H10) -> 208 | L10: =J10/2240 -> 0.092857143
A11: 1711 | B11: Madera Wine | C11: Nevis | D11: London | H11: 7355 | I11: 2tun 3hh 14gal | J11: =(E11*2240)+(F11*112)+(G11*28)+(H11) -> 7355 | L11: =J11/2240 -> 3.2834821
A12: 1711 | B12: Molasses | C12: Nevis | D12: London | F12: 40 | G12: 3 | H12: 7 | J12: =(E12*2240)+(F12*112)+(G12*28)+(H12) -> 4571 | L12: =J12/2240 -> 2.040625
A13: 1711 | B13: Pickles | C13: Nevis | D13: London | J13: =(E13*2240)+(F13*112)+(G13*28)+(H13) -> 0 | L13: =J13/2240 -> 0
A14: 1711 | B14: Rum | C14: Nevis | D14: London | H14: 676 | I14: 65gal | J14: =(E14*2240)+(F14*112)+(G14*28)+(H14) -> 676 | L14: =J14/2240 -> 0.30178571
A15: 1711 | B15: Shruff | C15: Nevis | D15: London | F15: 8 | G15: 2 | J15: =(E15*2240)+(F15*112)+(G15*28)+(H15) -> 952 | L15: =J15/2240 -> 0.425
A16: 1711 | B16: Succands | C16: Nevis | D16: London | J16: =(E16*2240)+(F16*112)+(G16*28)+(H16) -> 0 | L16: =J16/2240 -> 0
A17: 1711 | B17: Sugar Loaf | C17: Nevis | D17: London | J17: =(E17*2240)+(F17*112)+(G17*28)+(H17) -> 0 | L17: =J17/2240 -> 0
A18: 1711 | B18: Tobacco | C18: Nevis | D18: London | J18: =(E18*2240)+(F18*112)+(G18*28)+(H18) -> 0 | L18: =J18/2240 -> 0
A19: 1711 | B19: Tortoise Shell | C19: Nevis | D19: London | J19: =(E19*2240)+(F19*112)+(G19*28)+(H19) -> 0 | L19: =J19/2240 -> 0
A20: 1711 | B20: Tortoise Shell | C20: Nevis | D20: London | H20: 5 | J20: =(E20*2240)+(F20*112)+(G20*28)+(H20) -> 5 | L20: =J20/2240 -> 0.0022321429
A21: 1711 | B21: White Sugar | C21: Nevis | D21: London | J21: =(E21*2240)+(F21*112)+(G21*28)+(H21) -> 0 | L21: =J21/2240 -> 0
A22: 1711 | B22: Brown Sugar | C22: Nevis | D22: Out Ports | F22: 7828 | G22: 1 | H22: 10 | J22: =(E22*2240)+(F22*112)+(G22*28)+(H22) -> 876774 | L22: =J22/2240 -> 391.41696
A23: 1711 | B23: Cocoa Nuts | C23: Nevis | D23: Out Ports | J23: =(E23*2240)+(F23*112)+(G23*28)+(H23) -> 0 | L23: =J23/2240 -> 0
A24: 1711 | B24: Cotton | C24: Nevis | D24: Out Ports | H24: 19496 | J24: =(E24*2240)+(F24*112)+(G24*28)+(H24) -> 19496 | L24: =J24/2240 -> 8.7035714
A25: 1711 | B25: Elephant Teeth | C25: Nevis | D25: Out Ports | J25: =(E25*2240)+(F25*112)+(G25*28)+(H25) -> 0 | L25: =J25/2240 -> 0
A26: 1711 | B26: Indigo | C26: Nevis | D26: Out Ports | H26: 4069 | J26: =(E26*2240)+(F26*112)+(G26*28)+(H26) -> 4069 | L26: =J26/2240 -> 1.8165179
A27: 1711 | B27: Lignum Vitae | C27: Nevis | D27: Out Ports | F27: 7 | G27: 0 | H27: 17 | J27: =(E27*2240)+(F27*112)+(G27*28)+(H27) -> 801 | L27: =J27/2240 -> 0.35758929
A28: 1711 | B28: Lime Juice | C28: Nevis | D28: Out Ports | H28: 478 | I28: 46gal | J28: =(E28*2240)+(F28*112)+(G28*28)+(H28) -> 478 | L28: =J28/2240 -> 0.21339286
A29: 1711 | B29: Molasses | C29: Nevis | D29: Out Ports | F29: 8 | G29: 1 | H29: 6 | J29: =(E29*2240)+(F29*112)+(G29*28)+(H29) -> 930 | L29: =J29/2240 -> 0.41517857
A30: 1711 | B30: Rum | C30: Nevis | D30: Out Ports | H30: 385 | I30: 37gal | J30: =(E30*2240)+(F30*112)+(G30*28)+(H30) -> 385 | L30: =J30/2240 -> 0.171875
A31: 1711 | B31: Shruff | C31: Nevis | D31: Out Ports | F31: 2 | G31: 2 | H31: 24 | J31: =(E31*2240)+(F31*112)+(G31*28)+(H31) -> 304 | L31: =J31/2240 -> 0.13571429
A32: 1711 | B32: Succand | C32: Nevis | D32: Out Ports | H32: 320 | J32: =(E32*2240)+(F32*112)+(G32*28)+(H32) -> 320 | L32: =J32/2240 -> 0.14285714
A33: 1711 | B33: Tortoise Shell | C33: Nevis | D33: Out Ports | J33: =(E33*2240)+(F33*112)+(G33*28)+(H33) -> 0 | L33: =J33/2240 -> 0

Sheet St Kitts
A1: Items | B1: Import Location | C1: 1700 Ton | D1: 1700 hh | E1: 1700 quarter | F1: 1700 Stone/lb/oz? | H1: Total Pounds | J1: Total Tons
A2: Elephant Teeth | B2: London | H2: =(C2*2240)+(D2*112)+(E2*28)+(F2/16) -> 0 | J2: =H2/2240 -> 0
A3: Molasses | B3: London | H3: =(C3*2240)+(D3*112)+(E3*28)+(F3/16) -> 0 | J3: =H3/2240 -> 0
A4: Brown Sugar | B4: London | H4: =(C4*2240)+(D4*112)+(E4*28)+(F4/16) -> 0 | J4: =H4/2240 -> 0
A5: Indigo | B5: London | H5: =(C5*2240)+(D5*112)+(E5*28)+(F5/16) -> 0 | J5: =H5/2240 -> 0
A6: Cotton | B6: London | H6: =(C6*2240)+(D6*112)+(E6*28)+(F6/16) -> 0 | J6: =H6/2240 -> 0
A7: Cocoa Nuts | B7: London | H7: =(C7*2240)+(D7*112)+(E7*28)+(F7/16) -> 0 | J7: =H7/2240 -> 0

Sheet NewEngland
A1: YEAR | B1: COMMODITY_NAME | C1: FROM_LOCATION | D1: TO_LOCATION | E1: ton | F1: hh | G1: quarter | H1: lb | J1: Total Pounds | L1: WEIGHT
A2: 1711 | B2: Bayberries | C2: NewEngland | D2: London | J2: =(E2*2240)+(F2*112)+(G2*28)+H2 -> 0 | L2: =J2/2240 -> 0
A3: 1711 | B3: Bayberry Wax | C3: NewEngland | D3: London | J3: =(E3*2240)+(F3*112)+(G3*28)+H3 -> 0 | L3: =J3/2240 -> 0
A4: 1711 | B4: Brown Sugar | C4: NewEngland | D4: London | F4: 4577 | G4: 2 | H4: 5 | J4: =(E4*2240)+(F4*112)+(G4*28)+H4 -> 512685 | L4: =J4/2240 -> 228.87723
A5: 1711 | B5: Cocoa Nuts | C5: NewEngland | D5: London | F5: 146 | H5: 20 | J5: =(E5*2240)+(F5*112)+(G5*28)+H5 -> 16372 | L5: =J5/2240 -> 7.3089286
A6: 1711 | B6: Cortex Winteranus | C6: NewEngland | D6: London | H6: 240 | J6: =(E6*2240)+(F6*112)+(G6*28)+H6 -> 240 | L6: =J6/2240 -> 0.10714286
A7: 1711 | B7: Cotton | C7: NewEngland | D7: London | J7: =(E7*2240)+(F7*112)+(G7*28)+H7 -> 0 | L7: =J7/2240 -> 0
A8: 1711 | B8: Dry Ginger | C8: NewEngland | D8: London | F8: 9 | G8: 1 | H8: 14 | J8: =(E8*2240)+(F8*112)+(G8*28)+H8 -> 1050 | L8: =J8/2240 -> 0.46875
A9: 1711 | B9: Indigo | C9: NewEngland | D9: London | H9: 7757 | J9: =(E9*2240)+(F9*112)+(G9*28)+H9 -> 7757 | L9: =J9/2240 -> 3.4629464
A10: 1711 | B10: Lignum Vitae | C10: NewEngland | D10: London | J10: =(E10*2240)+(F10*112)+(G10*28)+H10 -> 0 | L10: =J10/2240 -> 0
A11: 1711 | B11: Lime Juice | C11: NewEngland | D11: London | J11: =(E11*2240)+(F11*112)+(G11*28)+H11 -> 0 | L11: =J11/2240 -> 0
A12: 1711 | B12: Madera Wine | C12: NewEngland | D12: London | H12: 1956 | I12: 2hh 62gal | J12: =(E12*2240)+(F12*112)+(G12*28)+H12 -> 1956 | L12: =J12/2240 -> 0.87321429
A13: 1711 | B13: Molasses | C13: NewEngland | D13: London | F13: 262 | J13: =(E13*2240)+(F13*112)+(G13*28)+H13 -> 29344 | L13: =J13/2240 -> 13.1
A14: 1711 | B14: Rice | C14: NewEngland | D14: London | F14: 63 | G14: 2 | H14: 7 | J14: =(E14*2240)+(F14*112)+(G14*28)+H14 -> 7119 | L14: =J14/2240 -> 3.178125
A15: 1711 | B15: Rum | C15: NewEngland | D15: London | H15: 4681 | I15: 450gal | J15: =(E15*2240)+(F15*112)+(G15*28)+H15 -> 4681 | L15: =J15/2240 -> 2.0897321
A16: 1711 | B16: Shruff | C16: NewEngland | D16: London | F16: 7 | G16: 2 | J16: =(E16*2240)+(F16*112)+(G16*28)+H16 -> 840 | L16: =J16/2240 -> 0.375
A17: 1711 | B17: Tobacco | C17: NewEngland | D17: London | H17: 710 | J17: =(E17*2240)+(F17*112)+(G17*28)+H17 -> 710 | L17: =J17/2240 -> 0.31696429
A18: 1711 | B18: Tortoise Shell | C18: NewEngland | D18: London | J18: =(E18*2240)+(F18*112)+(G18*28)+H18 -> 0 | L18: =J18/2240 -> 0
A19: 1711 | B19: Turpentine Common | C19: NewEngland | D19: London | F19: 3261 | G19: 3 | H19: 16 | J19: =(E19*2240)+(F19*112)+(G19*28)+H19 -> 365332 | L19: =J19/2240 -> 163.09464
A20: 1711 | B20: White Sugar | C20: NewEngland | D20: London | F20: 10 | G20: 3 | H20: 18 | J20: =(E20*2240)+(F20*112)+(G20*28)+H20 -> 1222 | L20: =J20/2240 -> 0.54553571
A21: 1711 | B21: Wood, Braziletto | C21: NewEngland | D21: London | F21: 297 | G21: 1 | J21: =(E21*2240)+(F21*112)+(G21*28)+H21 -> 33292 | L21: =J21/2240 -> 14.8625
A22: 1711 | B22: Wood, Fustick | C22: NewEngland | D22: London | E22: 39 | F22: 16 | G22: 2 | H22: 14 | J22: =(E22*2240)+(F22*112)+(G22*28)+H22 -> 89222 | L22: =J22/2240 -> 39.83125
A23: 1711 | B23: Wood, Logwood | C23: NewEngland | D23: London | E23: 108 | F23: 10 | G23: 2 | H23: 25 | J23: =(E23*2240)+(F23*112)+(G23*28)+H23 -> 243121 | L23: =J23/2240 -> 108.53616
A24: 1711 | B24: Brown Sugar | C24: NewEngland | D24: Out Ports | F24: 199 | G24: 2 | H24: 21 | J24: =(E24*2240)+(F24*112)+(G24*28)+H24 -> 22365 | L24: =J24/2240 -> 9.984375
A25: 1711 | B25: Dry Ginger | C25: NewEngland | D25: Out Ports | F25: 2 | G25: 1 | H25: 14 | J25: =(E25*2240)+(F25*112)+(G25*28)+H25 -> 266 | L25: =J25/2240 -> 0.11875
A26: 1711 | B26: Hops | C26: NewEngland | D26: Out Ports | F26: 21 | G26: 2 | H26: 14 | J26: =(E26*2240)+(F26*112)+(G26*28)+H26 -> 2422 | L26: =J26/2240 -> 1.08125
A27: 1711 | B27: Lignum Vitae | C27: NewEngland | D27: Out Ports | F27: 18 | G27: 2 | H27: 14 | J27: =(E27*2240)+(F27*112)+(G27*28)+H27 -> 2086 | L27: =J27/2240 -> 0.93125
A28: 1711 | B28: Molasses | C28: NewEngland | D28: Out Ports | F28: 143 | G28: 1 | H28: 25 | J28: =(E28*2240)+(F28*112)+(G28*28)+H28 -> 16069 | L28: =J28/2240 -> 7.1736607
A29: 1711 | B29: Rice | C29: NewEngland | D29: Out Ports | F29: 110 | G29: 1 | J29: =(E29*2240)+(F29*112)+(G29*28)+H29 -> 12348 | L29: =J29/2240 -> 5.5125
A30: 1711 | B30: Rum | C30: NewEngland | D30: Out Ports | H30: 1628 | I30: 156.5gal | J30: =(E30*2240)+(F30*112)+(G30*28)+H30 -> 1628 | L30: =J30/2240 -> 0.72678571
A31: 1711 | B31: Tobacco | C31: NewEngland | D31: Out Ports | J31: =(E31*2240)+(F31*112)+(G31*28)+H31 -> 0 | L31: =J31/2240 -> 0
A32: 1711 | B32: Wood, Braziletto | C32: NewEngland | D32: Out Ports | E32: 1 | J32: =(E32*2240)+(F32*112)+(G32*28)+H32 -> 2240 | L32: =J32/2240 -> 1
A33: 1711 | B33: Wood, Fustick | C33: NewEngland | D33: Out Ports | E33: 100 | F33: 12 | G33: 3 | H33: 14 | J33: =(E33*2240)+(F33*112)+(G33*28)+H33 -> 225442 | L33: =J33/2240 -> 100.64375
A34: 1711 | B34: Wood, Logwood | C34: NewEngland | D34: Out Ports | E34: 19 | F34: 2 | G34: 1 | H34: 21 | J34: =(E34*2240)+(F34*112)+(G34*28)+H34 -> 42833 | L34: =J34/2240 -> 19.121875
