Workbook

Sheet Master Goods Sheet
A1: Item | B1: Total London | C1: Total Outports | D1: Total
A2: Annatto | B2: =SUMIFS(Antigua!$L:$L, Antigua!$B:$B, $A2, Antigua!$D:$D, "London") + SUMIFS(Barbados!$L:$L, Barbados!$B:$B, $A2, Barbados!$D:$D, "London") + SUMIFS(Bermuda!$L:$L, Bermuda!$B:$B, $A2, Bermuda!$D:$D, "London") + SUMIFS(Carolina!$L:$L, Carolina!$B:$B, $A2, Carolina!$D:$D, "London") + SUMIFS(Jamaica!$L:$L, Jamaica!$B:$B, $A2, Jamaica!$D:$D, "London") + SUMIFS(Mountserat!$L:$L, Mountserat!$B:$B, $A2, Mountserat!$D:$D, "London") + SUMIFS(Nevis!$L:$L, Nevis!$B:$B, $A2, Nevis!$D:$D, "London") + SUMIFS(NewEngland!$L:$L, NewEngland!$B:$B, $A2, NewEngland!$D:$D, "London") -> 2.3053571 | C2: =SUMIFS(Antigua!$L:$L, Antigua!$B:$B, $A2, Antigua!$D:$D, "Out Ports") + SUMIFS(Barbados!$L:$L, Barbados!$B:$B, $A2, Barbados!$D:$D, "Out Ports") + SUMIFS(Bermuda!$L:$L, Bermuda!$B:$B, $A2, Bermuda!$D:$D, "Out Ports") + SUMIFS(Carolina!$L:$L, Carolina!$B:$B, $A2, Carolina!$D:$D, "Out Ports") + SUMIFS(Jamaica!$L:$L, Jamaica!$B:$B, $A2, Jamaica!$D:$D, "Out Ports") + SUMIFS(Mountserat!$L:$L, Mountserat!$B:$B, $A2, Mountserat!$D:$D, "Out Ports") + SUMIFS(Nevis!$L:$L, Nevis!$B:$B, $A2, Nevis!$D:$D, "Out Ports") + SUMIFS(NewEngland!$L:$L, NewEngland!$B:$B, $A2, NewEngland!$D:$D, "Out Ports") -> 1.3049107 | D2: =ROUND((B2+C2),2) -> 3.61
A3: Bayberry Wax | B3: =SUMIFS(Antigua!$L:$L, Antigua!$B:$B, $A3, Antigua!$D:$D, "London") + SUMIFS(Barbados!$L:$L, Barbados!$B:$B, $A3, Barbados!$D:$D, "London") + SUMIFS(Bermuda!$L:$L, Bermuda!$B:$B, $A3, Bermuda!$D:$D, "London") + SUMIFS(Carolina!$L:$L, Carolina!$B:$B, $A3, Carolina!$D:$D, "London") + SUMIFS(Jamaica!$L:$L, Jamaica!$B:$B, $A3, Jamaica!$D:$D, "London") + SUMIFS(Mountserat!$L:$L, Mountserat!$B:$B, $A3, Mountserat!$D:$D, "London") + SUMIFS(Nevis!$L:$L, Nevis!$B:$B, $A3, Nevis!$D:$D, "London") + SUMIFS(NewEngland!$L:$L, NewEngland!$B:$B, $A3, NewEngland!$D:$D, "London") -> 0 | C3: =SUMIFS(Antigua!$L:$L, Antigua!$B:$B, $A3, Antigua!$D:$D, "Out Ports") + SUMIFS(Barbados!$L:$L, Barbados!$B:$B, $A3, Barbados!$D:$D, "Out Ports") + SUMIFS(Bermuda!$L:$L, Bermuda!$B:$B, $A3, Bermuda!$D:$D, "Out Ports") + SUMIFS(Carolina!$L:$L, Carolina!$B:$B, $A3, Carolina!$D:$D, "Out Ports") + SUMIFS(Jamaica!$L:$L, Jamaica!$B:$B, $A3, Jamaica!$D:$D, "Out Ports") + SUMIFS(Mountserat!$L:$L, Mountserat!$B:$B, $A3, Mountserat!$D:$D, "Out Ports") + SUMIFS(Nevis!$L:$L, Nevis!$B:$B, $A3, Nevis!$D:$D, "Out Ports") + SUMIFS(NewEngland!$L:$L, NewEngland!$B:$B, $A3, NewEngland!$D:$D, "Out Ports") -> 0 | D3: =ROUND((B3+C3),2) -> 0
A4: Bees Wax | B4: =SUMIFS(Antigua!$L:$L, Antigua!$B:$B, $A4, Antigua!$D:$D, "London") + SUMIFS(Barbados!$L:$L, Barbados!$B:$B, $A4, Barbados!$D:$D, "London") + SUMIFS(Bermuda!$L:$L, Bermuda!$B:$B, $A4, Bermuda!$D:$D, "London") + SUMIFS(Carolina!$L:$L, Carolina!$B:$B, $A4, Carolina!$D:$D, "London") + SUMIFS(Jamaica!$L:$L, Jamaica!$B:$B, $A4, Jamaica!$D:$D, "London") + SUMIFS(Mountserat!$L:$L, Mountserat!$B:$B, $A4, Mountserat!$D:$D, "London") + SUMIFS(Nevis!$L:$L, Nevis!$B:$B, $A4, Nevis!$D:$D, "London") + SUMIFS(NewEngland!$L:$L, NewEngland!$B:$B, $A4, NewEngland!$D:$D, "London") -> 0 | C4: =SUMIFS(Antigua!$L:$L, Antigua!$B:$B, $A4, Antigua!$D:$D, "Out Ports") + SUMIFS(Barbados!$L:$L, Barbados!$B:$B, $A4, Barbados!$D:$D, "Out Ports") + SUMIFS(Bermuda!$L:$L, Bermuda!$B:$B, $A4, Bermuda!$D:$D, "Out Ports") + SUMIFS(Carolina!$L:$L, Carolina!$B:$B, $A4, Carolina!$D:$D, "Out Ports") + SUMIFS(Jamaica!$L:$L, Jamaica!$B:$B, $A4, Jamaica!$D:$D, "Out Ports") + SUMIFS(Mountserat!$L:$L, Mountserat!$B:$B, $A4, Mountserat!$D:$D, "Out Ports") + SUMIFS(Nevis!$L:$L, Nevis!$B:$B, $A4, Nevis!$D:$D, "Out Ports") + SUMIFS(NewEngland!$L:$L, NewEngland!$B:$B, $A4, NewEngland!$D:$D, "Out Ports") -> 1.75 | D4: =ROUND((B4+C4),2) -> 1.75
A5: Brandy | B5: =SUMIFS(Antigua!$L:$L, Antigua!$B:$B, $A5, Antigua!$D:$D, "London") + SUMIFS(Barbados!$L:$L, Barbados!$B:$B, $A5, Barbados!$D:$D, "London") + SUMIFS(Bermuda!$L:$L, Bermuda!$B:$B, $A5, Bermuda!$D:$D, "London") + SUMIFS(Carolina!$L:$L, Carolina!$B:$B, $A5, Carolina!$D:$D, "London") + SUMIFS(Jamaica!$L:$L, Jamaica!$B:$B, $A5, Jamaica!$D:$D, "London") + SUMIFS(Mountserat!$L:$L, Mountserat!$B:$B, $A5, Mountserat!$D:$D, "London") + SUMIFS(Nevis!$L:$L, Nevis!$B:$B, $A5, Nevis!$D:$D, "London") + SUMIFS(NewEngland!$L:$L, NewEngland!$B:$B, $A5, NewEngland!$D:$D, "London") -> 0 | C5: =SUMIFS(Antigua!$L:$L, Antigua!$B:$B, $A5, Antigua!$D:$D, "Out Ports") + SUMIFS(Barbados!$L:$L, Barbados!$B:$B, $A5, Barbados!$D:$D, "Out Ports") + SUMIFS(Bermuda!$L:$L, Bermuda!$B:$B, $A5, Bermuda!$D:$D, "Out Ports") + SUMIFS(Carolina!$L:$L, Carolina!$B:$B, $A5, Carolina!$D:$D, "Out Ports") + SUMIFS(Jamaica!$L:$L, Jamaica!$B:$B, $A5, Jamaica!$D:$D, "Out Ports") + SUMIFS(Mountserat!$L:$L, Mountserat!$B:$B, $A5, Mountserat!$D:$D, "Out Ports") + SUMIFS(Nevis!$L:$L, Nevis!$B:$B, $A5, Nevis!$D:$D, "Out Ports") + SUMIFS(NewEngland!$L:$L, NewEngland!$B:$B, $A5, NewEngland!$D:$D, "Out Ports") -> 0 | D5: =ROUND((B5+C5),2) -> 0
A6: Brown Sugar | B6: =SUMIFS(Antigua!$L:$L, Antigua!$B:$B, $A6, Antigua!$D:$D, "London") + SUMIFS(Barbados!$L:$L, Barbados!$B:$B, $A6, Barbados!$D:$D, "London") + SUMIFS(Bermuda!$L:$L, Bermuda!$B:$B, $A6, Bermuda!$D:$D, "London") + SUMIFS(Carolina!$L:$L, Carolina!$B:$B, $A6, Carolina!$D:$D, "London") + SUMIFS(Jamaica!$L:$L, Jamaica!$B:$B, $A6, Jamaica!$D:$D, "London") + SUMIFS(Mountserat!$L:$L, Mountserat!$B:$B, $A6, Mountserat!$D:$D, "London") + SUMIFS(Nevis!$L:$L, Nevis!$B:$B, $A6, Nevis!$D:$D, "London") + SUMIFS(NewEngland!$L:$L, NewEngland!$B:$B, $A6, NewEngland!$D:$D, "London") -> 22675.917 | C6: =SUMIFS(Antigua!$L:$L, Antigua!$B:$B, $A6, Antigua!$D:$D, "Out Ports") + SUMIFS(Barbados!$L:$L, Barbados!$B:$B, $A6, Barbados!$D:$D, "Out Ports") + SUMIFS(Bermuda!$L:$L, Bermuda!$B:$B, $A6, Bermuda!$D:$D, "Out Ports") + SUMIFS(Carolina!$L:$L, Carolina!$B:$B, $A6, Carolina!$D:$D, "Out Ports") + SUMIFS(Jamaica!$L:$L, Jamaica!$B:$B, $A6, Jamaica!$D:$D, "Out Ports") + SUMIFS(Mountserat!$L:$L, Mountserat!$B:$B, $A6, Mountserat!$D:$D, "Out Ports") + SUMIFS(Nevis!$L:$L, Nevis!$B:$B, $A6, Nevis!$D:$D, "Out Ports") + SUMIFS(NewEngland!$L:$L, NewEngland!$B:$B, $A6, NewEngland!$D:$D, "Out Ports") -> 6899.7406 | D6: =ROUND((B6+C6),2) -> 29575.66
A7: Cascarilla | B7: =SUMIFS(Antigua!$L:$L, Antigua!$B:$B, $A7, Antigua!$D:$D, "London") + SUMIFS(Barbados!$L:$L, Barbados!$B:$B, $A7, Barbados!$D:$D, "London") + SUMIFS(Bermuda!$L:$L, Bermuda!$B:$B, $A7, Bermuda!$D:$D, "London") + SUMIFS(Carolina!$L:$L, Carolina!$B:$B, $A7, Carolina!$D:$D, "London") + SUMIFS(Jamaica!$L:$L, Jamaica!$B:$B, $A7, Jamaica!$D:$D, "London") + SUMIFS(Mountserat!$L:$L, Mountserat!$B:$B, $A7, Mountserat!$D:$D, "London") + SUMIFS(Nevis!$L:$L, Nevis!$B:$B, $A7, Nevis!$D:$D, "London") + SUMIFS(NewEngland!$L:$L, NewEngland!$B:$B, $A7, NewEngland!$D:$D, "London") -> 1.0415179 | C7: =SUMIFS(Antigua!$L:$L, Antigua!$B:$B, $A7, Antigua!$D:$D, "Out Ports") + SUMIFS(Barbados!$L:$L, Barbados!$B:$B, $A7, Barbados!$D:$D, "Out Ports") + SUMIFS(Bermuda!$L:$L, Bermuda!$B:$B, $A7, Bermuda!$D:$D, "Out Ports") + SUMIFS(Carolina!$L:$L, Carolina!$B:$B, $A7, Carolina!$D:$D, "Out Ports") + SUMIFS(Jamaica!$L:$L, Jamaica!$B:$B, $A7, Jamaica!$D:$D, "Out Ports") + SUMIFS(Mountserat!$L:$L, Mountserat!$B:$B, $A7, Mountserat!$D:$D, "Out Ports") + SUMIFS(Nevis!$L:$L, Nevis!$B:$B, $A7, Nevis!$D:$D, "Out Ports") + SUMIFS(NewEngland!$L:$L, NewEngland!$B:$B, $A7, NewEngland!$D:$D, "Out Ports") -> 0 | D7: =ROUND((B7+C7),2) -> 1.04
A8: Chocolate | B8: =SUMIFS(Antigua!$L:$L, Antigua!$B:$B, $A8, Antigua!$D:$D, "London") + SUMIFS(Barbados!$L:$L, Barbados!$B:$B, $A8, Barbados!$D:$D, "London") + SUMIFS(Bermuda!$L:$L, Bermuda!$B:$B, $A8, Bermuda!$D:$D, "London") + SUMIFS(Carolina!$L:$L, Carolina!$B:$B, $A8, Carolina!$D:$D, "London") + SUMIFS(Jamaica!$L:$L, Jamaica!$B:$B, $A8, Jamaica!$D:$D, "London") + SUMIFS(Mountserat!$L:$L, Mountserat!$B:$B, $A8, Mountserat!$D:$D, "London") + SUMIFS(Nevis!$L:$L, Nevis!$B:$B, $A8, Nevis!$D:$D, "London") + SUMIFS(NewEngland!$L:$L, NewEngland!$B:$B, $A8, NewEngland!$D:$D, "London") -> 0.083928571 | C8: =SUMIFS(Antigua!$L:$L, Antigua!$B:$B, $A8, Antigua!$D:$D, "Out Ports") + SUMIFS(Barbados!$L:$L, Barbados!$B:$B, $A8, Barbados!$D:$D, "Out Ports") + SUMIFS(Bermuda!$L:$L, Bermuda!$B:$B, $A8, Bermuda!$D:$D, "Out Ports") + SUMIFS(Carolina!$L:$L, Carolina!$B:$B, $A8, Carolina!$D:$D, "Out Ports") + SUMIFS(Jamaica!$L:$L, Jamaica!$B:$B, $A8, Jamaica!$D:$D, "Out Ports") + SUMIFS(Mountserat!$L:$L, Mountserat!$B:$B, $A8, Mountserat!$D:$D, "Out Ports") + SUMIFS(Nevis!$L:$L, Nevis!$B:$B, $A8, Nevis!$D:$D, "Out Ports") + SUMIFS(NewEngland!$L:$L, NewEngland!$B:$B, $A8, NewEngland!$D:$D, "Out Ports") -> 0 | D8: =ROUND((B8+C8),2) -> 0.08
A9: Cockeneal | B9: =SUMIFS(Antigua!$L:$L, Antigua!$B:$B, $A9, Antigua!$D:$D, "London") + SUMIFS(Barbados!$L:$L, Barbados!$B:$B, $A9, Barbados!$D:$D, "London") + SUMIFS(Bermuda!$L:$L, Bermuda!$B:$B, $A9, Bermuda!$D:$D, "London") + SUMIFS(Carolina!$L:$L, Carolina!$B:$B, $A9, Carolina!$D:$D, "London") + SUMIFS(Jamaica!$L:$L, Jamaica!$B:$B, $A9, Jamaica!$D:$D, "London") + SUMIFS(Mountserat!$L:$L, Mountserat!$B:$B, $A9, Mountserat!$D:$D, "London") + SUMIFS(Nevis!$L:$L, Nevis!$B:$B, $A9, Nevis!$D:$D, "London") + SUMIFS(NewEngland!$L:$L, NewEngland!$B:$B, $A9, NewEngland!$D:$D, "London") -> 0 | C9: =SUMIFS(Antigua!$L:$L, Antigua!$B:$B, $A9, Antigua!$D:$D, "Out Ports") + SUMIFS(Barbados!$L:$L, Barbados!$B:$B, $A9, Barbados!$D:$D, "Out Ports") + SUMIFS(Bermuda!$L:$L, Bermuda!$B:$B, $A9, Bermuda!$D:$D, "Out Ports") + SUMIFS(Carolina!$L:$L, Carolina!$B:$B, $A9, Carolina!$D:$D, "Out Ports") + SUMIFS(Jamaica!$L:$L, Jamaica!$B:$B, $A9, Jamaica!$D:$D, "Out Ports") + SUMIFS(Mountserat!$L:$L, Mountserat!$B:$B, $A9, Mountserat!$D:$D, "Out Ports") + SUMIFS(Nevis!$L:$L, Nevis!$B:$B, $A9, Nevis!$D:$D, "Out Ports") + SUMIFS(NewEngland!$L:$L, NewEngland!$B:$B, $A9, NewEngland!$D:$D, "Out Ports") -> 0 | D9: =ROUND((B9+C9),2) -> 0
A10: Cocoa Nuts | B10: =SUMIFS(Antigua!$L:$L, Antigua!$B:$B, $A10, Antigua!$D:$D, "London") + SUMIFS(Barbados!$L:$L, Barbados!$B:$B, $A10, Barbados!$D:$D, "London") + SUMIFS(Bermuda!$L:$L, Bermuda!$B:$B, $A10, Bermuda!$D:$D, "London") + SUMIFS(Carolina!$L:$L, Carolina!$B:$B, $A10, Carolina!$D:$D, "London") + SUMIFS(Jamaica!$L:$L, Jamaica!$B:$B, $A10, Jamaica!$D:$D, "London") + SUMIFS(Mountserat!$L:$L, Mountserat!$B:$B, $A10, Mountserat!$D:$D, "London") + SUMIFS(Nevis!$L:$L, Nevis!$B:$B, $A10, Nevis!$D:$D, "London") + SUMIFS(NewEngland!$L:$L, NewEngland!$B:$B, $A10, NewEngland!$D:$D, "London") -> 143.33795 | C10: =SUMIFS(Antigua!$L:$L, Antigua!$B:$B, $A10, Antigua!$D:$D, "Out Ports") + SUMIFS(Barbados!$L:$L, Barbados!$B:$B, $A10, Barbados!$D:$D, "Out Ports") + SUMIFS(Bermuda!$L:$L, Bermuda!$B:$B, $A10, Bermuda!$D:$D, "Out Ports") + SUMIFS(Carolina!$L:$L, Carolina!$B:$B, $A10, Carolina!$D:$D, "Out Ports") + SUMIFS(Jamaica!$L:$L, Jamaica!$B:$B, $A10, Jamaica!$D:$D, "Out Ports") + SUMIFS(Mountserat!$L:$L, Mountserat!$B:$B, $A10, Mountserat!$D:$D, "Out Ports") + SUMIFS(Nevis!$L:$L, Nevis!$B:$B, $A10, Nevis!$D:$D, "Out Ports") + SUMIFS(NewEngland!$L:$L, NewEngland!$B:$B, $A10, NewEngland!$D:$D, "Out Ports") -> 34.181696 | D10: =ROUND((B10+C10),2) -> 177.52
A11: Cotton | B11: =SUMIFS(Antigua!$L:$L, Antigua!$B:$B, $A11, Antigua!$D:$D, "London") + SUMIFS(Barbados!$L:$L, Barbados!$B:$B, $A11, Barbados!$D:$D, "London") + SUMIFS(Bermuda!$L:$L, Bermuda!$B:$B, $A11, Bermuda!$D:$D, "London") + SUMIFS(Carolina!$L:$L, Carolina!$B:$B, $A11, Carolina!$D:$D, "London") + SUMIFS(Jamaica!$L:$L, Jamaica!$B:$B, $A11, Jamaica!$D:$D, "London") + SUMIFS(Mountserat!$L:$L, Mountserat!$B:$B, $A11, Mountserat!$D:$D, "London") + SUMIFS(Nevis!$L:$L, Nevis!$B:$B, $A11, Nevis!$D:$D, "London") + SUMIFS(NewEngland!$L:$L, NewEngland!$B:$B, $A11, NewEngland!$D:$D, "London") -> 584.81786 | C11: =SUMIFS(Antigua!$L:$L, Antigua!$B:$B, $A11, Antigua!$D:$D, "Out Ports") + SUMIFS(Barbados!$L:$L, Barbados!$B:$B, $A11, Barbados!$D:$D, "Out Ports") + SUMIFS(Bermuda!$L:$L, Bermuda!$B:$B, $A11, Bermuda!$D:$D, "Out Ports") + SUMIFS(Carolina!$L:$L, Carolina!$B:$B, $A11, Carolina!$D:$D, "Out Ports") + SUMIFS(Jamaica!$L:$L, Jamaica!$B:$B, $A11, Jamaica!$D:$D, "Out Ports") + SUMIFS(Mountserat!$L:$L, Mountserat!$B:$B, $A11, Mountserat!$D:$D, "Out Ports") + SUMIFS(Nevis!$L:$L, Nevis!$B:$B, $A11, Nevis!$D:$D, "Out Ports") + SUMIFS(NewEngland!$L:$L, NewEngland!$B:$B, $A11, NewEngland!$D:$D, "Out Ports") -> 215.04018 | D11: =ROUND((B11+C11),2) -> 799.86
A12: Dry Ginger | B12: =SUMIFS(Antigua!$L:$L, Antigua!$B:$B, $A12, Antigua!$D:$D, "London") + SUMIFS(Barbados!$L:$L, Barbados!$B:$B, $A12, Barbados!$D:$D, "London") + SUMIFS(Bermuda!$L:$L, Bermuda!$B:$B, $A12, Bermuda!$D:$D, "London") + SUMIFS(Carolina!$L:$L, Carolina!$B:$B, $A12, Carolina!$D:$D, "London") + SUMIFS(Jamaica!$L:$L, Jamaica!$B:$B, $A12, Jamaica!$D:$D, "London") + SUMIFS(Mountserat!$L:$L, Mountserat!$B:$B, $A12, Mountserat!$D:$D, "London") + SUMIFS(Nevis!$L:$L, Nevis!$B:$B, $A12, Nevis!$D:$D, "London") + SUMIFS(NewEngland!$L:$L, NewEngland!$B:$B, $A12, NewEngland!$D:$D, "London") -> 484.29464 | C12: =SUMIFS(Antigua!$L:$L, Antigua!$B:$B, $A12, Antigua!$D:$D, "Out Ports") + SUMIFS(Barbados!$L:$L, Barbados!$B:$B, $A12, Barbados!$D:$D, "Out Ports") + SUMIFS(Bermuda!$L:$L, Bermuda!$B:$B, $A12, Bermuda!$D:$D, "Out Ports") + SUMIFS(Carolina!$L:$L, Carolina!$B:$B, $A12, Carolina!$D:$D, "Out Ports") + SUMIFS(Jamaica!$L:$L, Jamaica!$B:$B, $A12, Jamaica!$D:$D, "Out Ports") + SUMIFS(Mountserat!$L:$L, Mountserat!$B:$B, $A12, Mountserat!$D:$D, "Out Ports") + SUMIFS(Nevis!$L:$L, Nevis!$B:$B, $A12, Nevis!$D:$D, "Out Ports") + SUMIFS(NewEngland!$L:$L, NewEngland!$B:$B, $A12, NewEngland!$D:$D, "Out Ports") -> 105.725 | D12: =ROUND((B12+C12),2) -> 590.02
A13: Elephant Teeth | B13: =SUMIFS(Antigua!$L:$L, Antigua!$B:$B, $A13, Antigua!$D:$D, "London") + SUMIFS(Barbados!$L:$L, Barbados!$B:$B, $A13, Barbados!$D:$D, "London") + SUMIFS(Bermuda!$L:$L, Bermuda!$B:$B, $A13, Bermuda!$D:$D, "London") + SUMIFS(Carolina!$L:$L, Carolina!$B:$B, $A13, Carolina!$D:$D, "London") + SUMIFS(Jamaica!$L:$L, Jamaica!$B:$B, $A13, Jamaica!$D:$D, "London") + SUMIFS(Mountserat!$L:$L, Mountserat!$B:$B, $A13, Mountserat!$D:$D, "London") + SUMIFS(Nevis!$L:$L, Nevis!$B:$B, $A13, Nevis!$D:$D, "London") + SUMIFS(NewEngland!$L:$L, NewEngland!$B:$B, $A13, NewEngland!$D:$D, "London") -> 23.807589 | C13: =SUMIFS(Antigua!$L:$L, Antigua!$B:$B, $A13, Antigua!$D:$D, "Out Ports") + SUMIFS(Barbados!$L:$L, Barbados!$B:$B, $A13, Barbados!$D:$D, "Out Ports") + SUMIFS(Bermuda!$L:$L, Bermuda!$B:$B, $A13, Bermuda!$D:$D, "Out Ports") + SUMIFS(Carolina!$L:$L, Carolina!$B:$B, $A13, Carolina!$D:$D, "Out Ports") + SUMIFS(Jamaica!$L:$L, Jamaica!$B:$B, $A13, Jamaica!$D:$D, "Out Ports") + SUMIFS(Mountserat!$L:$L, Mountserat!$B:$B, $A13, Mountserat!$D:$D, "Out Ports") + SUMIFS(Nevis!$L:$L, Nevis!$B:$B, $A13, Nevis!$D:$D, "Out Ports") + SUMIFS(NewEngland!$L:$L, NewEngland!$B:$B, $A13, NewEngland!$D:$D, "Out Ports") -> 15.263393 | D13: =ROUND((B13+C13),2) -> 39.07
... A31: Madera Wine | B31: =SUMIFS(Antigua!$L:$L, Antigua!$B:$B, $A31, Antigua!$D:$D, "London") + SUMIFS(Barbados!$L:$L, Barbados!$B:$B, $A31, Barbados!$D:$D, "London") + SUMIFS(Bermuda!$L:$L, Bermuda!$B:$B, $A31, Bermuda!$D:$D, "London") + SUMIFS(Carolina!$L:$L, Carolina!$B:$B, $A31, Carolina!$D:$D, "London") + SUMIFS(Jamaica!$L:$L, Jamaica!$B:$B, $A31, Jamaica!$D:$D, "London") + SUMIFS(Mountserat!$L:$L, Mountserat!$B:$B, $A31, Mountserat!$D:$D, "London") + SUMIFS(Nevis!$L:$L, Nevis!$B:$B, $A31, Nevis!$D:$D, "London") + SUMIFS(NewEngland!$L:$L, NewEngland!$B:$B, $A31, NewEngland!$D:$D, "London") -> 28.350893 | C31: =SUMIFS(Antigua!$L:$L, Antigua!$B:$B, $A31, Antigua!$D:$D, "Out Ports") + SUMIFS(Barbados!$L:$L, Barbados!$B:$B, $A31, Barbados!$D:$D, "Out Ports") + SUMIFS(Bermuda!$L:$L, Bermuda!$B:$B, $A31, Bermuda!$D:$D, "Out Ports") + SUMIFS(Carolina!$L:$L, Carolina!$B:$B, $A31, Carolina!$D:$D, "Out Ports") + SUMIFS(Jamaica!$L:$L, Jamaica!$B:$B, $A31, Jamaica!$D:$D, "Out Ports") + SUMIFS(Mountserat!$L:$L, Mountserat!$B:$B, $A31, Mountserat!$D:$D, "Out Ports") + SUMIFS(Nevis!$L:$L, Nevis!$B:$B, $A31, Nevis!$D:$D, "Out Ports") + SUMIFS(NewEngland!$L:$L, NewEngland!$B:$B, $A31, NewEngland!$D:$D, "Out Ports") -> 2.8397321 | D31: =ROUND((B31+C31),2) -> 31.19

Sheet Africa
A1: Items | B1: Import Location | C1: 1700 Ton | D1: 1700 hh | E1: 1700 quarter | F1: 1700 Stone/lb | G1: Total Pounds | I1: Total Tons

Sheet Canaries
A1: Items | B1: Import Location | C1: 1700 Ton | D1: 1700 hh | E1: 1700 quarter | F1: 1700 lb | G1: Total Pounds | I1: Total Tons

Sheet Antigua
A1: YEAR | B1: COMMODITY_NAME | C1: FROM_LOCATION | D1: TO_LOCATION | E1: ton | F1: hh | G1: quarter | H1: lb | J1: Total Pounds | L1: WEIGHT
A2: 1716 | B2: Annatto | C2: Antigua | D2: London | H2: 2030 | J2: =(E2*2240)+(F2*112)+(G2*28)+H2 -> 2030 | L2: =J2/2240 -> 0.90625
A3: 1716 | B3: Brown Sugar | C3: Antigua | D3: London | F3: 96694 | G3: 3 | H3: 16 | J3: =(E3*2240)+(F3*112)+(G3*28)+H3 -> 10829828 | L3: =J3/2240 -> 4834.7446
A4: 1716 | B4: Chocolate | C4: Antigua | D4: London | J4: =(E4*2240)+(F4*112)+(G4*28)+H4 -> 0 | L4: =J4/2240 -> 0
A5: 1716 | B5: Cocoa Nuts | C5: Antigua | D5: London | F5: 90 | G5: 3 | H5: 16 | J5: =(E5*2240)+(F5*112)+(G5*28)+H5 -> 10180 | L5: =J5/2240 -> 4.5446429
A6: 1716 | B6: Cotton | C6: Antigua | D6: London | H6: 224952 | J6: =(E6*2240)+(F6*112)+(G6*28)+H6 -> 224952 | L6: =J6/2240 -> 100.425
A7: 1716 | B7: Dry Ginger | C7: Antigua | D7: London | F7: 571 | H7: 21 | J7: =(E7*2240)+(F7*112)+(G7*28)+H7 -> 63973 | L7: =J7/2240 -> 28.559375
A8: 1716 | B8: Elephant Teeth | C8: Antigua | D8: London | F8: 4 | H8: 14 | J8: =(E8*2240)+(F8*112)+(G8*28)+H8 -> 462 | L8: =J8/2240 -> 0.20625
A9: 1716 | B9: Indigo | C9: Antigua | D9: London | H9: 4595 | J9: =(E9*2240)+(F9*112)+(G9*28)+H9 -> 4595 | L9: =J9/2240 -> 2.0513393
A10: 1716 | B10: Lemon Water | C10: Antigua | D10: London | J10: =(E10*2240)+(F10*112)+(G10*28)+H10 -> 0 | L10: =J10/2240 -> 0
A11: 1716 | B11: Lignum Vitae | C11: Antigua | D11: London | F11: 866 | H11: 14 | J11: =(E11*2240)+(F11*112)+(G11*28)+H11 -> 97006 | L11: =J11/2240 -> 43.30625
A12: 1716 | B12: Lime Juice | C12: Antigua | D12: London | H12: 1960.5 | I12: 196g | J12: =(E12*2240)+(F12*112)+(G12*28)+H12 -> 1960.5 | L12: =J12/2240 -> 0.87522321
A13: 1716 | B13: Madera Wine | C13: Antigua | D13: London | H13: 23676 | I13: 9t 1h 36g | J13: =(E13*2240)+(F13*112)+(G13*28)+H13 -> 23676 | L13: =J13/2240 -> 10.569643
A14: 1716 | B14: Molasses | C14: Antigua | D14: London | F14: 289 | G14: 3 | H14: 0 | J14: =(E14*2240)+(F14*112)+(G14*28)+H14 -> 32452 | L14: =J14/2240 -> 14.4875
A15: 1716 | B15: Rum | C15: Antigua | D15: London | H15: 21240 | I15: 2123.5g | J15: =(E15*2240)+(F15*112)+(G15*28)+H15 -> 21240 | L15: =J15/2240 -> 9.4821429
A16: 1716 | B16: Shruff | C16: Antigua | D16: London | F16: 43 | G16: 3 | H16: 17 | J16: =(E16*2240)+(F16*112)+(G16*28)+H16 -> 4917 | L16: =J16/2240 -> 2.1950893
A17: 1716 | B17: Succands | C17: Antigua | D17: London | H17: 374 | J17: =(E17*2240)+(F17*112)+(G17*28)+H17 -> 374 | L17: =J17/2240 -> 0.16696429
A18: 1716 | B18: Tobacco | C18: Antigua | D18: London | J18: =(E18*2240)+(F18*112)+(G18*28)+H18 -> 0 | L18: =J18/2240 -> 0
A19: 1716 | B19: Tortoise Shell | C19: Antigua | D19: London | J19: =(E19*2240)+(F19*112)+(G19*28)+H19 -> 0 | L19: =J19/2240 -> 0
A20: 1716 | B20: White Sugar | C20: Antigua | D20: London | G20: 3 | H20: 22 | J20: =(E20*2240)+(F20*112)+(G20*28)+H20 -> 106 | L20: =J20/2240 -> 0.047321429
A21: 1716 | B21: Brown Sugar | C21: Antigua | D21: Out Ports | F21: 24584 | G21: 2 | J21: =(E21*2240)+(F21*112)+(G21*28)+H21 -> 2753464 | L21: =J21/2240 -> 1229.225
A22: 1716 | B22: Cocoa | C22: Antigua | D22: Out Ports | J22: =(E22*2240)+(F22*112)+(G22*28)+H22 -> 0 | L22: =J22/2240 -> 0
A23: 1716 | B23: Cocoa Nuts | C23: Antigua | D23: Out Ports | F23: 21 | G23: 3 | H23: 22 | J23: =(E23*2240)+(F23*112)+(G23*28)+H23 -> 2458 | L23: =J23/2240 -> 1.0973214
A24: 1716 | B24: Cortex Peru | C24: Antigua | D24: Out Ports | H24: 103 | J24: =(E24*2240)+(F24*112)+(G24*28)+H24 -> 103 | L24: =J24/2240 -> 0.045982143
A25: 1716 | B25: Cotton | C25: Antigua | D25: Out Ports | H25: 180291 | J25: =(E25*2240)+(F25*112)+(G25*28)+H25 -> 180291 | L25: =J25/2240 -> 80.487054
A26: 1716 | B26: Dry Ginger | C26: Antigua | D26: Out Ports | F26: 116 | H26: 21 | J26: =(E26*2240)+(F26*112)+(G26*28)+H26 -> 13013 | L26: =J26/2240 -> 5.809375
A27: 1716 | B27: Elephant Teeth | C27: Antigua | D27: Out Ports | F27: 62 | G27: 1 | H27: 4 | J27: =(E27*2240)+(F27*112)+(G27*28)+H27 -> 6976 | L27: =J27/2240 -> 3.1142857
A28: 1716 | B28: Fustic | C28: Antigua | D28: Out Ports | J28: =(E28*2240)+(F28*112)+(G28*28)+H28 -> 0 | L28: =J28/2240 -> 0
A29: 1716 | B29: Guiney Grains | C29: Antigua | D29: Out Ports | H29: 8138 | J29: =(E29*2240)+(F29*112)+(G29*28)+H29 -> 8138 | L29: =J29/2240 -> 3.6330357
A30: 1716 | B30: Indigo | C30: Antigua | D30: Out Ports | H30: 795 | J30: =(E30*2240)+(F30*112)+(G30*28)+H30 -> 795 | L30: =J30/2240 -> 0.35491071
A31: 1716 | B31: Lignum Vitae | C31: Antigua | D31: Out Ports | E31: 18 | F31: 1 | G31: 3 | H31: 17 | J31: =(E31*2240)+(F31*112)+(G31*28)+H31 -> 40533 | L31: =J31/2240 -> 18.095089
A32: 1716 | B32: Lime Juice | C32: Antigua | D32: Out Ports | H32: 1130 | I32: 113g | J32: =(E32*2240)+(F32*112)+(G32*28)+H32 -> 1130 | L32: =J32/2240 -> 0.50446429
A33: 1716 | B33: Logwood | C33: Antigua | D33: Out Ports | F33: 17 | G33: 0 | H33: 3 | J33: =(E33*2240)+(F33*112)+(G33*28)+H33 -> 1907 | L33: =J33/2240 -> 0.85133929
A34: 1716 | B34: Madera Wine | C34: Antigua | D34: Out Ports | H34: 3571 | I34: 1t 1h 42g | J34: =(E34*2240)+(F34*112)+(G34*28)+H34 -> 3571 | L34: =J34/2240 -> 1.5941964
A35: 1716 | B35: Molasses | C35: Antigua | D35: Out Ports | F35: 260 | G35: 2 | H35: 22 | J35: =(E35*2240)+(F35*112)+(G35*28)+H35 -> 29198 | L35: =J35/2240 -> 13.034821
A36: 1716 | B36: Redwood | C36: Antigua | D36: Out Ports | E36: 8 | F36: 19 | G36: 3 | H36: 7 | J36: =(E36*2240)+(F36*112)+(G36*28)+H36 -> 20139 | L36: =J36/2240 -> 8.990625
A37: 1716 | B37: Rice | C37: Antigua | D37: Out Ports | J37: =(E37*2240)+(F37*112)+(G37*28)+H37 -> 0 | L37: =J37/2240 -> 0
A38: 1716 | B38: Rum | C38: Antigua | D38: Out Ports | H38: 8082 | I38: 808g | J38: =(E38*2240)+(F38*112)+(G38*28)+H38 -> 8082 | L38: =J38/2240 -> 3.6080357
A39: 1716 | B39: Shruff | C39: Antigua | D39: Out Ports | F39: 10 | G39: 3 | H39: 9 | J39: =(E39*2240)+(F39*112)+(G39*28)+H39 -> 1213 | L39: =J39/2240 -> 0.54151786
A40: 1716 | B40: Succands | C40: Antigua | D40: Out Ports | H40: 672 | J40: =(E40*2240)+(F40*112)+(G40*28)+H40 -> 672 | L40: =J40/2240 -> 0.3
...

Sheet Barbados
A1: YEAR | B1: COMMODITY_NAME | C1: FROM_LOCATION | D1: TO_LOCATION | E1: ton | F1: hh | G1: quarter | H1: lb | J1: Total Pounds | L1: WEIGHT
A2: 1716 | B2: Annatto | C2: Barbados | D2: London | H2: 3134 | J2: =(E2*2240)+(F2*112)+(G2*28)+H2 -> 3134 | L2: =J2/2240 -> 1.3991071
A3: 1716 | B3: Aloes Epatica | C3: Barbados | D3: London | H3: 19399 | J3: =(E3*2240)+(F3*112)+(G3*28)+H3 -> 19399 | L3: =J3/2240 -> 8.6602679
A4: 1716 | B4: Brazilia | C4: Barbados | D4: London | J4: =(E4*2240)+(F4*112)+(G4*28)+H4 -> 0 | L4: =J4/2240 -> 0
A5: 1716 | B5: Brown Sugar | C5: Barbados | D5: London | F5: 163179 | G5: 3 | H5: 19 | J5: =(E5*2240)+(F5*112)+(G5*28)+H5 -> 18276151 | L5: =J5/2240 -> 8158.996
A6: 1716 | B6: Cocheneal | C6: Barbados | D6: London | H6: 1193 | J6: =(E6*2240)+(F6*112)+(G6*28)+H6 -> 1193 | L6: =J6/2240 -> 0.53258929
A7: 1716 | B7: Chocolate Paste | C7: Barbados | D7: London | J7: =(E7*2240)+(F7*112)+(G7*28)+H7 -> 0 | L7: =J7/2240 -> 0
A8: 1716 | B8: Fustick Wood | C8: Barbados | D8: London | E8: 196 | F8: 4 | G8: 3 | H8: 15 | J8: =(E8*2240)+(F8*112)+(G8*28)+H8 -> 439587 | L8: =J8/2240 -> 196.2442
A9: 1716 | B9: Green Ginger | C9: Barbados | D9: London | J9: =(E9*2240)+(F9*112)+(G9*28)+H9 -> 0 | L9: =J9/2240 -> 0
A10: 1716 | B10: Cocoa Nuts | C10: Barbados | D10: London | F10: 2538 | G10: 2 | H10: 18 | J10: =(E10*2240)+(F10*112)+(G10*28)+H10 -> 284330 | L10: =J10/2240 -> 126.93304
A11: 1716 | B11: Cocoa Paste | C11: Barbados | D11: London | J11: =(E11*2240)+(F11*112)+(G11*28)+H11 -> 0 | L11: =J11/2240 -> 0
A12: 1716 | B12: Cotton | C12: Barbados | D12: London | H12: 58016 | J12: =(E12*2240)+(F12*112)+(G12*28)+H12 -> 58016 | L12: =J12/2240 -> 25.9
A13: 1716 | B13: Dry Ginger | C13: Barbados | D13: London | F13: 2896 | G13: 3 | H13: 23 | J13: =(E13*2240)+(F13*112)+(G13*28)+H13 -> 324459 | L13: =J13/2240 -> 144.84777
A14: 1716 | B14: Elephant Teeth | C14: Barbados | D14: London | F14: 310 | G14: 1 | H14: 15 | J14: =(E14*2240)+(F14*112)+(G14*28)+H14 -> 34763 | L14: =J14/2240 -> 15.519196
A15: 1716 | B15: Lemon Water | C15: Barbados | D15: London | J15: =(E15*2240)+(F15*112)+(G15*28)+H15 -> 0 | L15: =J15/2240 -> 0
A16: 1716 | B16: Lime Juice | C16: Barbados | D16: London | H16: 5561 | I16: 556g | J16: =(E16*2240)+(F16*112)+(G16*28)+H16 -> 5561 | L16: =J16/2240 -> 2.4825893
A17: 1716 | B17: Loaf Sugar | C17: Barbados | D17: London | J17: =(E17*2240)+(F17*112)+(G17*28)+H17 -> 0 | L17: =J17/2240 -> 0
A18: 1716 | B18: Logwood | C18: Barbados | D18: London | E18: 50 | F18: 1 | G18: 2 | H18: 20 | J18: =(E18*2240)+(F18*112)+(G18*28)+H18 -> 112188 | L18: =J18/2240 -> 50.083929
A19: 1716 | B19: Rice | C19: Barbados | D19: London | F19: 1469 | H19: 7 | J19: =(E19*2240)+(F19*112)+(G19*28)+H19 -> 164535 | L19: =J19/2240 -> 73.453125
A20: 1716 | B20: Madera Wine | C20: Barbados | D20: London | H20: 31268 | I20: 12t 1h 39g | J20: =(E20*2240)+(F20*112)+(G20*28)+H20 -> 31268 | L20: =J20/2240 -> 13.958929
A21: 1716 | B21: Molasses | C21: Barbados | D21: London | F21: 413 | G21: 1 | J21: =(E21*2240)+(F21*112)+(G21*28)+H21 -> 46284 | L21: =J21/2240 -> 20.6625
A22: 1716 | B22: Oranges | C22: Barbados | D22: London | J22: =(E22*2240)+(F22*112)+(G22*28)+H22 -> 0 | L22: =J22/2240 -> 0
A23: 1716 | B23: Redwood | C23: Barbados | D23: London | E23: 93 | F23: 8 | G23: 2 | H23: 14 | J23: =(E23*2240)+(F23*112)+(G23*28)+H23 -> 209286 | L23: =J23/2240 -> 93.43125
A24: 1716 | B24: Rum | C24: Barbados | D24: London | H24: 66447 | I24: 6643g | J24: =(E24*2240)+(F24*112)+(G24*28)+H24 -> 66447 | L24: =J24/2240 -> 29.663839
A25: 1716 | B25: Shruff | C25: Barbados | D25: London | F25: 84 | G25: 2 | H25: 15 | J25: =(E25*2240)+(F25*112)+(G25*28)+H25 -> 9479 | L25: =J25/2240 -> 4.2316964
A26: 1716 | B26: Succands | C26: Barbados | D26: London | H26: 1771 | J26: =(E26*2240)+(F26*112)+(G26*28)+H26 -> 1771 | L26: =J26/2240 -> 0.790625
A27: 1716 | B27: Tobacco | C27: Barbados | D27: London | H27: 4025 | J27: =(E27*2240)+(F27*112)+(G27*28)+H27 -> 4025 | L27: =J27/2240 -> 1.796875
A28: 1716 | B28: Tortoise Shell | C28: Barbados | D28: London | H28: 23.5 | J28: =(E28*2240)+(F28*112)+(G28*28)+H28 -> 23.5 | L28: =J28/2240 -> 0.010491071
A29: 1716 | B29: Lignum Vitae | C29: Barbados | D29: London | J29: =(E29*2240)+(F29*112)+(G29*28)+H29 -> 0 | L29: =J29/2240 -> 0
A30: 1716 | B30: White Sugar | C30: Barbados | D30: London | F30: 192 | G30: 2 | H30: 7 | J30: =(E30*2240)+(F30*112)+(G30*28)+H30 -> 21567 | L30: =J30/2240 -> 9.628125
A31: 1716 | B31: Indigo | C31: Barbados | D31: London | H31: 27403 | J31: =(E31*2240)+(F31*112)+(G31*28)+H31 -> 27403 | L31: =J31/2240 -> 12.233482
A32: 1716 | B32: Barrel Staves | C32: Barbados | D32: London | J32: =(E32*2240)+(F32*112)+(G32*28)+H32 -> 0 | L32: =J32/2240 -> 0
A33: 1716 | B33: Pimento | C33: Barbados | D33: London | J33: =(E33*2240)+(F33*112)+(G33*28)+H33 -> 0 | L33: =J33/2240 -> 0
A34: 1716 | B34: Hemp | C34: Barbados | D34: London | J34: =(E34*2240)+(F34*112)+(G34*28)+H34 -> 0 | L34: =J34/2240 -> 0
A35: 1716 | B35: Snuff | C35: Barbados | D35: London | J35: =(E35*2240)+(F35*112)+(G35*28)+H35 -> 0 | L35: =J35/2240 -> 0
A36: 1716 | B36: Annatto | C36: Barbados | D36: Out Ports | H36: 2853 | J36: =(E36*2240)+(F36*112)+(G36*28)+H36 -> 2853 | L36: =J36/2240 -> 1.2736607
A37: 1716 | B37: Brown Sugar | C37: Barbados | D37: Out Ports | F37: 48683 | H37: 23 | J37: =(E37*2240)+(F37*112)+(G37*28)+H37 -> 5452519 | L37: =J37/2240 -> 2434.1603
A38: 1716 | B38: Chocolate | C38: Barbados | D38: Out Ports | J38: =(E38*2240)+(F38*112)+(G38*28)+H38 -> 0 | L38: =J38/2240 -> 0
A39: 1716 | B39: Cocoa Nuts | C39: Barbados | D39: Out Ports | F39: 631 | G39: 1 | J39: =(E39*2240)+(F39*112)+(G39*28)+H39 -> 70700 | L39: =J39/2240 -> 31.5625
A40: 1716 | B40: Cotton | C40: Barbados | D40: Out Ports | H40: 97157 | J40: =(E40*2240)+(F40*112)+(G40*28)+H40 -> 97157 | L40: =J40/2240 -> 43.373661
...

Sheet Bermuda
A1: YEAR | B1: COMMODITY_NAME | C1: FROM_LOCATION | D1: TO_LOCATION | E1: ton | F1: hh | G1: quarter | H1: lb | J1: Total Pounds | L1: WEIGHT
A2: 1716 | B2: Indigo | C2: Bermuda | D2: Out Ports | J2: =(E2*2240)+(F2*112)+(G2*28)+H2 -> 0 | L2: =J2/2240 -> 0
A3: 1716 | B3: Logwood | C3: Bermuda | D3: Out Ports | J3: =(E3*2240)+(F3*112)+(G3*28)+H3 -> 0 | L3: =J3/2240 -> 0
A4: 1716 | B4: Shruff | C4: Bermuda | D4: Out Ports | J4: =(E4*2240)+(F4*112)+(G4*28)+H4 -> 0 | L4: =J4/2240 -> 0
A5: 1716 | B5: Succands | C5: Bermuda | D5: Out Ports | J5: =(E5*2240)+(F5*112)+(G5*28)+H5 -> 0 | L5: =J5/2240 -> 0
A6: 1716 | B6: Cotton | C6: Bermuda | D6: Out Ports | J6: =(E6*2240)+(F6*112)+(G6*28)+H6 -> 0 | L6: =J6/2240 -> 0
A7: 1716 | B7: Cocoa Nuts | C7: Bermuda | D7: Out Ports | J7: =(E7*2240)+(F7*112)+(G7*28)+H7 -> 0 | L7: =J7/2240 -> 0

Sheet Carolina
A1: YEAR | B1: COMMODITY_NAME | C1: FROM_LOCATION | D1: TO_LOCATION | E1: ton | F1: hh | G1: quarter | H1: lb | J1: Total Pounds | L1: WEIGHT
A2: 1716 | B2: Elephant Teeth | C2: Carolina | D2: London | J2: =(E2*2240)+(F2*112)+(G2*28)+H2 -> 0 | L2: =J2/2240 -> 0
A3: 1716 | B3: Dry Ginger | C3: Carolina | D3: London | J3: =(E3*2240)+(F3*112)+(G3*28)+H3 -> 0 | L3: =J3/2240 -> 0
A4: 1716 | B4: Rice | C4: Carolina | D4: London | F4: 19907 | G4: 1 | H4: 16 | J4: =(E4*2240)+(F4*112)+(G4*28)+H4 -> 2229628 | L4: =J4/2240 -> 995.36964
A5: 1716 | B5: Tobacco | C5: Carolina | D5: London | H5: 146 | J5: =(E5*2240)+(F5*112)+(G5*28)+H5 -> 146 | L5: =J5/2240 -> 0.065178571
A6: 1716 | B6: Chocolate | C6: Carolina | D6: London | J6: =(E6*2240)+(F6*112)+(G6*28)+H6 -> 0 | L6: =J6/2240 -> 0
A7: 1716 | B7: Brown Sugar | C7: Carolina | D7: London | F7: 24 | J7: =(E7*2240)+(F7*112)+(G7*28)+H7 -> 2688 | L7: =J7/2240 -> 1.2
A8: 1716 | B8: Cocoa Nuts | C8: Carolina | D8: London | J8: =(E8*2240)+(F8*112)+(G8*28)+H8 -> 0 | L8: =J8/2240 -> 0
A9: 1716 | B9: Tortoise Shell | C9: Carolina | D9: London | J9: =(E9*2240)+(F9*112)+(G9*28)+H9 -> 0 | L9: =J9/2240 -> 0
A10: 1716 | B10: Cortex Winteranus | C10: Carolina | D10: Out Ports | J10: =(E10*2240)+(F10*112)+(G10*28)+H10 -> 0 | L10: =J10/2240 -> 0
A11: 1716 | B11: Elephant Teeth | C11: Carolina | D11: Out Ports | J11: =(E11*2240)+(F11*112)+(G11*28)+H11 -> 0 | L11: =J11/2240 -> 0
A12: 1716 | B12: Indigo | C12: Carolina | D12: Out Ports | J12: =(E12*2240)+(F12*112)+(G12*28)+H12 -> 0 | L12: =J12/2240 -> 0
A13: 1716 | B13: Rice | C13: Carolina | D13: Out Ports | J13: =(E13*2240)+(F13*112)+(G13*28)+H13 -> 0 | L13: =J13/2240 -> 0
A14: 1716 | B14: Brown Sugar | C14: Carolina | D14: Out Ports | J14: =(E14*2240)+(F14*112)+(G14*28)+H14 -> 0 | L14: =J14/2240 -> 0
A15: 1716 | B15: Cotton | C15: Carolina | D15: Out Ports | J15: =(E15*2240)+(F15*112)+(G15*28)+H15 -> 0 | L15: =J15/2240 -> 0
A16: 1716 | B16: Cocoa | C16: Carolina | D16: Out Ports | J16: =(E16*2240)+(F16*112)+(G16*28)+H16 -> 0 | L16: =J16/2240 -> 0
A17: 1716 | B17: Cocoa Nuts | C17: Carolina | D17: Out Ports | J17: =(E17*2240)+(F17*112)+(G17*28)+H17 -> 0 | L17: =J17/2240 -> 0
A18: 1716 | B18: Lime Juice | C18: Carolina | D18: Out Ports | J18: =(E18*2240)+(F18*112)+(G18*28)+H18 -> 0 | L18: =J18/2240 -> 0
A19: 1716 | B19: Bees Wax | C19: Carolina | D19: London | J19: =(E19*2240)+(F19*112)+(G19*28)+H19 -> 0 | L19: =J19/2240 -> 0
A20: 1716 | B20: Braziletto Wood | C20: Carolina | D20: London | E20: 11 | F20: 19 | G20: 3 | J20: =(E20*2240)+(F20*112)+(G20*28)+H20 -> 26852 | L20: =J20/2240 -> 11.9875
A21: 1716 | B21: Logwood | C21: Carolina | D21: London | E21: 336 | F21: 2 | G21: 1 | H21: 10 | J21: =(E21*2240)+(F21*112)+(G21*28)+H21 -> 752902 | L21: =J21/2240 -> 336.11696
A22: 1716 | B22: Lignum Vitae | C22: Carolina | D22: London | F22: 84 | G22: 3 | H22: 7 | J22: =(E22*2240)+(F22*112)+(G22*28)+H22 -> 9499 | L22: =J22/2240 -> 4.240625
A23: 1716 | B23: Rum | C23: Carolina | D23: London | H23: 2860 | I23: 286g | J23: =(E23*2240)+(F23*112)+(G23*28)+H23 -> 2860 | L23: =J23/2240 -> 1.2767857

Sheet Jamaica
A1: YEAR | B1: COMMODITY_NAME | C1: FROM_LOCATION | D1: TO_LOCATION | E1: ton | F1: hh | G1: quarter | H1: lb | J1: Total Pounds | L1: WEIGHT | O1: Total Not Sugar | Q1: Total Sugar
A2: 1716 | B2: Annatto | C2: Jamaica | D2: London | J2: =(E2*2240)+(F2*112)+(G2*28)+H2 -> 0 | L2: =J2/2240 -> 0
A3: 1716 | B3: Bees Wax | C3: Jamaica | D3: London | J3: =(E3*2240)+(F3*112)+(G3*28)+H3 -> 0 | L3: =J3/2240 -> 0
A4: 1716 | B4: Braziletto Wood | C4: Jamaica | D4: London | E4: 18 | F4: 16 | G4: 2 | H4: 21 | J4: =(E4*2240)+(F4*112)+(G4*28)+H4 -> 42189 | L4: =J4/2240 -> 18.834375
A5: 1716 | B5: Brown Sugar | C5: Jamaica | D5: London | F5: 123217 | G5: 1 | H5: 4 | J5: =(E5*2240)+(F5*112)+(G5*28)+H5 -> 13800336 | L5: =J5/2240 -> 6160.8643
A6: 1716 | B6: Cascarilla | C6: Jamaica | D6: London | H6: 2333 | J6: =(E6*2240)+(F6*112)+(G6*28)+H6 -> 2333 | L6: =J6/2240 -> 1.0415179
A7: 1716 | B7: Chocolate | C7: Jamaica | D7: London | H7: 177 | J7: =(E7*2240)+(F7*112)+(G7*28)+H7 -> 177 | L7: =J7/2240 -> 0.079017857
A8: 1716 | B8: Cocheneal | C8: Jamaica | D8: London | H8: 3728 | J8: =(E8*2240)+(F8*112)+(G8*28)+H8 -> 3728 | L8: =J8/2240 -> 1.6642857
A9: 1716 | B9: Cocoa Nuts | C9: Jamaica | D9: London | F9: 146 | G9: 3 | H9: 21 | J9: =(E9*2240)+(F9*112)+(G9*28)+H9 -> 16457 | L9: =J9/2240 -> 7.346875
A10: 1716 | B10: Cocoa Paste | C10: Jamaica | D10: London | J10: =(E10*2240)+(F10*112)+(G10*28)+H10 -> 0 | L10: =J10/2240 -> 0
A11: 1716 | B11: Cocoa Wood | C11: Jamaica | D11: London | J11: =(E11*2240)+(F11*112)+(G11*28)+H11 -> 0 | L11: =J11/2240 -> 0
A12: 1716 | B12: Cotton | C12: Jamaica | D12: London | H12: 980880 | J12: =(E12*2240)+(F12*112)+(G12*28)+H12 -> 980880 | L12: =J12/2240 -> 437.89286
A13: 1716 | B13: Wool Vigonia | C13: Jamaica | D13: London | J13: =(E13*2240)+(F13*112)+(G13*28)+H13 -> 0 | L13: =J13/2240 -> 0
A14: 1716 | B14: Dry Ginger | C14: Jamaica | D14: London | F14: 6207 | J14: =(E14*2240)+(F14*112)+(G14*28)+H14 -> 695184 | L14: =J14/2240 -> 310.35
A15: 1716 | B15: Elephant Teeth | C15: Jamaica | D15: London | F15: 161 | G15: 2 | H15: 16 | J15: =(E15*2240)+(F15*112)+(G15*28)+H15 -> 18104 | L15: =J15/2240 -> 8.0821429
A16: 1716 | B16: Fustick Wood | C16: Jamaica | D16: London | E16: 892 | F16: 7 | G16: 1 | H16: 26 | J16: =(E16*2240)+(F16*112)+(G16*28)+H16 -> 1998918 | L16: =J16/2240 -> 892.37411
A17: 1716 | B17: Indigo | C17: Jamaica | D17: London | H17: 146728 | J17: =(E17*2240)+(F17*112)+(G17*28)+H17 -> 146728 | L17: =J17/2240 -> 65.503571
A18: 1716 | B18: Jamaica Roots | C18: Jamaica | D18: London | J18: =(E18*2240)+(F18*112)+(G18*28)+H18 -> 0 | L18: =J18/2240 -> 0
A19: 1716 | B19: Lignum Vitae | C19: Jamaica | D19: London | E19: 11 | F19: 17 | G19: 1 | H19: 14 | J19: =(E19*2240)+(F19*112)+(G19*28)+H19 -> 26586 | L19: =J19/2240 -> 11.86875
A20: 1716 | B20: Lime Juice | C20: Jamaica | D20: London | H20: 20815 | I20: 2081g | J20: =(E20*2240)+(F20*112)+(G20*28)+H20 -> 20815 | L20: =J20/2240 -> 9.2924107
A21: 1716 | B21: Logwood | C21: Jamaica | D21: London | E21: 323 | F21: 17 | G21: 2 | H21: 9 | J21: =(E21*2240)+(F21*112)+(G21*28)+H21 -> 725489 | L21: =J21/2240 -> 323.87902
A22: 1716 | B22: Madera Wine | C22: Jamaica | D22: London | J22: =(E22*2240)+(F22*112)+(G22*28)+H22 -> 0 | L22: =J22/2240 -> 0
A23: 1716 | B23: Molasses | C23: Jamaica | D23: London | J23: =(E23*2240)+(F23*112)+(G23*28)+H23 -> 0 | L23: =J23/2240 -> 0
A24: 1716 | B24: Nicaragua Wood | C24: Jamaica | D24: London | J24: =(E24*2240)+(F24*112)+(G24*28)+H24 -> 0 | L24: =J24/2240 -> 0
A25: 1716 | B25: Pimento | C25: Jamaica | D25: London | H25: 166442 | J25: =(E25*2240)+(F25*112)+(G25*28)+H25 -> 166442 | L25: =J25/2240 -> 74.304464
A26: 1716 | B26: Rice | C26: Jamaica | D26: London | F26: 837 | G26: 3 | H26: 20 | J26: =(E26*2240)+(F26*112)+(G26*28)+H26 -> 93848 | L26: =J26/2240 -> 41.896429
A27: 1716 | B27: Rum | C27: Jamaica | D27: London | H27: 171194 | I27: 17115g | J27: =(E27*2240)+(F27*112)+(G27*28)+H27 -> 171194 | L27: =J27/2240 -> 76.425893
A28: 1716 | B28: Sasparilla | C28: Jamaica | D28: London | H28: 28737 | J28: =(E28*2240)+(F28*112)+(G28*28)+H28 -> 28737 | L28: =J28/2240 -> 12.829018
A29: 1716 | B29: Shruff | C29: Jamaica | D29: London | F29: 46 | G29: 3 | H29: 21 | J29: =(E29*2240)+(F29*112)+(G29*28)+H29 -> 5257 | L29: =J29/2240 -> 2.346875
A30: 1716 | B30: Snuff | C30: Jamaica | D30: London | J30: =(E30*2240)+(F30*112)+(G30*28)+H30 -> 0 | L30: =J30/2240 -> 0
A31: 1716 | B31: Succands | C31: Jamaica | D31: London | H31: 1267 | J31: =(E31*2240)+(F31*112)+(G31*28)+H31 -> 1267 | L31: =J31/2240 -> 0.565625
A32: 1716 | B32: Sugar Loaf | C32: Jamaica | D32: London | J32: =(E32*2240)+(F32*112)+(G32*28)+H32 -> 0 | L32: =J32/2240 -> 0
A33: 1716 | B33: Tobacco | C33: Jamaica | D33: London | J33: =(E33*2240)+(F33*112)+(G33*28)+H33 -> 0 | L33: =J33/2240 -> 0
A34: 1716 | B34: Tortoise Shell | C34: Jamaica | D34: London | H34: 1967 | J34: =(E34*2240)+(F34*112)+(G34*28)+H34 -> 1967 | L34: =J34/2240 -> 0.878125
A35: 1716 | B35: White Sugar | C35: Jamaica | D35: London | F35: 1 | G35: 1 | H35: 21 | J35: =(E35*2240)+(F35*112)+(G35*28)+H35 -> 161 | L35: =J35/2240 -> 0.071875
A36: 1716 | B36: Annatto | C36: Jamaica | D36: Out Ports | H36: 70 | J36: =(E36*2240)+(F36*112)+(G36*28)+H36 -> 70 | L36: =J36/2240 -> 0.03125
A37: 1716 | B37: Cortex Winteranus | C37: Jamaica | D37: Out Ports | J37: =(E37*2240)+(F37*112)+(G37*28)+H37 -> 0 | L37: =J37/2240 -> 0
A38: 1716 | B38: Braziletto Wood | C38: Jamaica | D38: Out Ports | E38: 2 | F38: 18 | H38: 24 | J38: =(E38*2240)+(F38*112)+(G38*28)+H38 -> 6520 | L38: =J38/2240 -> 2.9107143
A39: 1716 | B39: Brown Sugar | C39: Jamaica | D39: Out Ports | F39: 43207 | G39: 2 | H39: 21 | J39: =(E39*2240)+(F39*112)+(G39*28)+H39 -> 4839261 | L39: =J39/2240 -> 2160.3844
A40: 1716 | B40: Molasses | C40: Jamaica | D40: Out Ports | F40: 10 | J40: =(E40*2240)+(F40*112)+(G40*28)+H40 -> 1120 | L40: =J40/2240 -> 0.5
...

Sheet Mountserat
A1: YEAR | B1: COMMODITY_NAME | C1: FROM_LOCATION | D1: TO_LOCATION | E1: ton | F1: hh | G1: quarter | H1: lb | J1: Total Pounds | L1: WEIGHT
A2: 1716 | B2: Cortex Winteranus | C2: Mountserat | D2: London | J2: =(E2*2240)+(F2*112)+(G2*28)+H2 -> 0 | L2: =J2/2240 -> 0
A3: 1716 | B3: Lignum Vitae | C3: Mountserat | D3: London | J3: =(E3*2240)+(F3*112)+(G3*28)+H3 -> 0 | L3: =J3/2240 -> 0
A4: 1716 | B4: Dry Ginger | C4: Mountserat | D4: London | F4: 10 | G4: 3 | J4: =(E4*2240)+(F4*112)+(G4*28)+H4 -> 1204 | L4: =J4/2240 -> 0.5375
A5: 1716 | B5: Elephants Teeth | C5: Mountserat | D5: London | F5: 2 | J5: =(E5*2240)+(F5*112)+(G5*28)+H5 -> 224 | L5: =J5/2240 -> 0.1
A6: 1716 | B6: Madera Wine | C6: Mountserat | D6: London | H6: 140 | I6: 14gal | J6: =(E6*2240)+(F6*112)+(G6*28)+H6 -> 140 | L6: =J6/2240 -> 0.0625
A7: 1716 | B7: Molasses | C7: Mountserat | D7: London | F7: 12 | J7: =(E7*2240)+(F7*112)+(G7*28)+H7 -> 1344 | L7: =J7/2240 -> 0.6
A8: 1716 | B8: Brown Sugar | C8: Mountserat | D8: London | F8: 21058 | H8: 25 | J8: =(E8*2240)+(F8*112)+(G8*28)+H8 -> 2358521 | L8: =J8/2240 -> 1052.9112
A9: 1716 | B9: White Sugar | C9: Mountserat | D9: London | J9: =(E9*2240)+(F9*112)+(G9*28)+H9 -> 0 | L9: =J9/2240 -> 0
A10: 1716 | B10: Indigo | C10: Mountserat | D10: London | H10: 34489 | J10: =(E10*2240)+(F10*112)+(G10*28)+H10 -> 34489 | L10: =J10/2240 -> 15.396875
A11: 1716 | B11: Shruff | C11: Mountserat | D11: London | H11: 14 | J11: =(E11*2240)+(F11*112)+(G11*28)+H11 -> 14 | L11: =J11/2240 -> 0.00625
A12: 1716 | B12: Succands | C12: Mountserat | D12: London | J12: =(E12*2240)+(F12*112)+(G12*28)+H12 -> 0 | L12: =J12/2240 -> 0
A13: 1716 | B13: Cotton | C13: Mountserat | D13: London | H13: 2240 | J13: =(E13*2240)+(F13*112)+(G13*28)+H13 -> 2240 | L13: =J13/2240 -> 1
A14: 1716 | B14: Chocolate | C14: Mountserat | D14: London | J14: =(E14*2240)+(F14*112)+(G14*28)+H14 -> 0 | L14: =J14/2240 -> 0
A15: 1716 | B15: Cocoa Nuts | C15: Mountserat | D15: London | F15: 2 | H15: 5 | J15: =(E15*2240)+(F15*112)+(G15*28)+H15 -> 229 | L15: =J15/2240 -> 0.10223214
A16: 1716 | B16: Lime Juice | C16: Mountserat | D16: London | H16: 1120 | I16: 112gal | J16: =(E16*2240)+(F16*112)+(G16*28)+H16 -> 1120 | L16: =J16/2240 -> 0.5
A17: 1716 | B17: Pimento | C17: Mountserat | D17: London | I17: 63 | J17: =(E17*2240)+(F17*112)+(G17*28)+H17 -> 0 | L17: =J17/2240 -> 0
A18: 1716 | B18: Rum | C18: Mountserat | D18: London | H18: 3350 | I18: 335gal | J18: =(E18*2240)+(F18*112)+(G18*28)+H18 -> 3350 | L18: =J18/2240 -> 1.4955357
A19: 1716 | B19: Tortoise Shell | C19: Mountserat | D19: London | J19: =(E19*2240)+(F19*112)+(G19*28)+H19 -> 0 | L19: =J19/2240 -> 0
A20: 1716 | B20: Dry Ginger | C20: Mountserat | D20: Out Ports | J20: =(E20*2240)+(F20*112)+(G20*28)+H20 -> 0 | L20: =J20/2240 -> 0
A21: 1716 | B21: Elephants Teeth | C21: Mountserat | D21: Out Ports | J21: =(E21*2240)+(F21*112)+(G21*28)+H21 -> 0 | L21: =J21/2240 -> 0
A22: 1716 | B22: Brown Sugar | C22: Mountserat | D22: Out Ports | F22: 5698 | H22: 14 | J22: =(E22*2240)+(F22*112)+(G22*28)+H22 -> 638190 | L22: =J22/2240 -> 284.90625
A23: 1716 | B23: Indigo | C23: Mountserat | D23: Out Ports | H23: 5456 | J23: =(E23*2240)+(F23*112)+(G23*28)+H23 -> 5456 | L23: =J23/2240 -> 2.4357143
A24: 1716 | B24: Pimento | C24: Mountserat | D24: Out Ports | H24: 167 | J24: =(E24*2240)+(F24*112)+(G24*28)+H24 -> 167 | L24: =J24/2240 -> 0.074553571
A25: 1716 | B25: Cotton | C25: Mountserat | D25: Out Ports | H25: 6384 | J25: =(E25*2240)+(F25*112)+(G25*28)+H25 -> 6384 | L25: =J25/2240 -> 2.85
A26: 1716 | B26: Cocoa | C26: Mountserat | D26: Out Ports | J26: =(E26*2240)+(F26*112)+(G26*28)+H26 -> 0 | L26: =J26/2240 -> 0
A27: 1716 | B27: Cocoa Nuts | C27: Mountserat | D27: Out Ports | J27: =(E27*2240)+(F27*112)+(G27*28)+H27 -> 0 | L27: =J27/2240 -> 0
A28: 1716 | B28: Rum | C28: Mountserat | D28: Out Ports | H28: 900 | I28: 90g | J28: =(E28*2240)+(F28*112)+(G28*28)+H28 -> 900 | L28: =J28/2240 -> 0.40178571
A29: 1716 | B29: Lime Juice | C29: Mountserat | D29: Out Ports | H29: 600 | I29: 60g | J29: =(E29*2240)+(F29*112)+(G29*28)+H29 -> 600 | L29: =J29/2240 -> 0.26785714
A30: 1716 | B30: White Sugar | C30: Mountserat | D30: Out Ports | G30: 2 | J30: =(E30*2240)+(F30*112)+(G30*28)+H30 -> 56 | L30: =J30/2240 -> 0.025

Sheet Nevis
A1: YEAR | B1: COMMODITY_NAME | C1: FROM_LOCATION | D1: TO_LOCATION | E1: ton | F1: hh | G1: quarter | H1: lb | J1: Total Pounds | L1: WEIGHT | N1: Total Not Sugar | P1: Total Sugar
A2: 1716 | B2: Elephant Teeth | C2: Nevis | D2: London | J2: =(E2*2240)+(F2*112)+(G2*28)+(H2) -> 0 | L2: =J2/2240 -> 0 | N2: =L2+L8+L11+L12+L15+L18+L19+L26+L35+L24+L25+L36+L38+L10 -> 56.061384 | P2: =L4+L5+L6+L23 -> 3258.2661
A3: 1716 | B3: Cortex Winteranus | C3: Nevis | D3: London | J3: =(E3*2240)+(F3*112)+(G3*28)+(H3) -> 0 | L3: =J3/2240 -> 0
A4: 1716 | B4: Sugar Loaf | C4: Nevis | D4: London | J4: =(E4*2240)+(F4*112)+(G4*28)+(H4) -> 0 | L4: =J4/2240 -> 0
A5: 1716 | B5: Brown Sugar | C5: Nevis | D5: London | F5: 49344 | H5: 3 | J5: =(E5*2240)+(F5*112)+(G5*28)+(H5) -> 5526531 | L5: =J5/2240 -> 2467.2013
A6: 1716 | B6: White Sugar | C6: Nevis | D6: London | J6: =(E6*2240)+(F6*112)+(G6*28)+(H6) -> 0 | L6: =J6/2240 -> 0
A7: 1716 | B7: Molasses | C7: Nevis | D7: London | F7: 57 | G7: 2 | J7: =(E7*2240)+(F7*112)+(G7*28)+(H7) -> 6440 | L7: =J7/2240 -> 2.875
A8: 1716 | B8: Indigo | C8: Nevis | D8: London | H8: 737 | J8: =(E8*2240)+(F8*112)+(G8*28)+(H8) -> 737 | L8: =J8/2240 -> 0.32901786
A9: 1716 | B9: Lime Juice | C9: Nevis | D9: London | J9: =(E9*2240)+(F9*112)+(G9*28)+(H9) -> 0 | L9: =J9/2240 -> 0
A10: 1716 | B10: Lignum Vitae | C10: Nevis | D10: London | E10: 32 | G10: 2 | H10: 7 | J10: =(E10*2240)+(F10*112)+(G10*28)+(H10) -> 71743 | L10: =J10/2240 -> 32.028125
A11: 1716 | B11: Shruff | C11: Nevis | D11: London | F11: 17 | G11: 1 | H11: 14 | J11: =(E11*2240)+(F11*112)+(G11*28)+(H11) -> 1946 | L11: =J11/2240 -> 0.86875
A12: 1716 | B12: Succands | C12: Nevis | D12: London | H12: 49 | J12: =(E12*2240)+(F12*112)+(G12*28)+(H12) -> 49 | L12: =J12/2240 -> 0.021875
A13: 1716 | B13: Tobacco | C13: Nevis | D13: London | J13: =(E13*2240)+(F13*112)+(G13*28)+(H13) -> 0 | L13: =J13/2240 -> 0
A14: 1716 | B14: Cotton | C14: Nevis | D14: London | H14: 40992 | J14: =(E14*2240)+(F14*112)+(G14*28)+(H14) -> 40992 | L14: =J14/2240 -> 18.3
A15: 1716 | B15: Cocoa Nuts | C15: Nevis | D15: London | F15: 30 | H15: 25 | J15: =(E15*2240)+(F15*112)+(G15*28)+(H15) -> 3385 | L15: =J15/2240 -> 1.5111607
A16: 1716 | B16: Chocolate | C16: Nevis | D16: London | H16: 11 | J16: =(E16*2240)+(F16*112)+(G16*28)+(H16) -> 11 | L16: =J16/2240 -> 0.0049107143
A17: 1716 | B17: Rum | C17: Nevis | D17: London | H17: 7022 | I17: 702g | J17: =(E17*2240)+(F17*112)+(G17*28)+(H17) -> 7022 | L17: =J17/2240 -> 3.1348214
A18: 1716 | B18: Tortoise Shell | C18: Nevis | D18: London | J18: =(E18*2240)+(F18*112)+(G18*28)+(H18) -> 0 | L18: =J18/2240 -> 0
A19: 1716 | B19: Pickles | C19: Nevis | D19: London | J19: =(E19*2240)+(F19*112)+(G19*28)+(H19) -> 0 | L19: =J19/2240 -> 0
A20: 1716 | B20: Madera Wine | C20: Nevis | D20: London | H20: 8422 | I20: 3t 1h 23g | J20: =(E20*2240)+(F20*112)+(G20*28)+(H20) -> 8422 | L20: =J20/2240 -> 3.7598214
A21: 1716 | B21: Tortoise Shell | C21: Nevis | D21: London | H21: 9 | J21: =(E21*2240)+(F21*112)+(G21*28)+(H21) -> 9 | L21: =J21/2240 -> 0.0040178571
A22: 1716 | B22: Bees Wax | C22: Nevis | D22: Out Ports | F22: 35 | J22: =(E22*2240)+(F22*112)+(G22*28)+(H22) -> 3920 | L22: =J22/2240 -> 1.75
A23: 1716 | B23: Brown Sugar | C23: Nevis | D23: Out Ports | F23: 15821 | G23: 1 | H23: 5 | J23: =(E23*2240)+(F23*112)+(G23*28)+(H23) -> 1771985 | L23: =J23/2240 -> 791.06473
A24: 1716 | B24: Cotton | C24: Nevis | D24: Out Ports | H24: 40772 | J24: =(E24*2240)+(F24*112)+(G24*28)+(H24) -> 40772 | L24: =J24/2240 -> 18.201786
A25: 1716 | B25: Cocoa Nuts | C25: Nevis | D25: Out Ports | F25: 27 | H25: 22 | J25: =(E25*2240)+(F25*112)+(G25*28)+(H25) -> 3046 | L25: =J25/2240 -> 1.3598214
A26: 1716 | B26: Elephant Teeth | C26: Nevis | D26: Out Ports | F26: 30 | G26: 1 | H26: 9 | J26: =(E26*2240)+(F26*112)+(G26*28)+(H26) -> 3397 | L26: =J26/2240 -> 1.5165179
A27: 1716 | B27: Guiney Grains | C27: Nevis | D27: Out Ports | H27: 23507 | J27: =(E27*2240)+(F27*112)+(G27*28)+(H27) -> 23507 | L27: =J27/2240 -> 10.494196
A28: 1716 | B28: Indigo | C28: Nevis | D28: Out Ports | H28: 1372 | J28: =(E28*2240)+(F28*112)+(G28*28)+(H28) -> 1372 | L28: =J28/2240 -> 0.6125
A29: 1716 | B29: Lignum Vitae | C29: Nevis | D29: Out Ports | F29: 47 | G29: 1 | H29: 18 | J29: =(E29*2240)+(F29*112)+(G29*28)+(H29) -> 5310 | L29: =J29/2240 -> 2.3705357
A30: 1716 | B30: Lime Juice | C30: Nevis | D30: Out Ports | J30: =(E30*2240)+(F30*112)+(G30*28)+(H30) -> 0 | L30: =J30/2240 -> 0
A31: 1716 | B31: Molasses | C31: Nevis | D31: Out Ports | F31: 60 | J31: =(E31*2240)+(F31*112)+(G31*28)+(H31) -> 6720 | L31: =J31/2240 -> 3
A32: 1716 | B32: Redwood | C32: Nevis | D32: Out Ports | F32: 15 | G32: 3 | H32: 9 | J32: =(E32*2240)+(F32*112)+(G32*28)+(H32) -> 1773 | L32: =J32/2240 -> 0.79151786
A33: 1716 | B33: Rice | C33: Nevis | D33: Out Ports | F33: 6 | G33: 3 | H33: 24 | J33: =(E33*2240)+(F33*112)+(G33*28)+(H33) -> 780 | L33: =J33/2240 -> 0.34821429
A34: 1716 | B34: Rum | C34: Nevis | D34: Out Ports | H34: 3210 | I34: 321g | J34: =(E34*2240)+(F34*112)+(G34*28)+(H34) -> 3210 | L34: =J34/2240 -> 1.4330357
A35: 1716 | B35: Shruff | C35: Nevis | D35: Out Ports | F35: 4 | H35: 16 | J35: =(E35*2240)+(F35*112)+(G35*28)+(H35) -> 464 | L35: =J35/2240 -> 0.20714286
A36: 1716 | B36: Succand | C36: Nevis | D36: Out Ports | H36: 36 | J36: =(E36*2240)+(F36*112)+(G36*28)+(H36) -> 36 | L36: =J36/2240 -> 0.016071429
A37: 1716 | B37: Tobacco | C37: Nevis | D37: Out Ports | H37: 3600 | J37: =(E37*2240)+(F37*112)+(G37*28)+(H37) -> 3600 | L37: =J37/2240 -> 1.6071429
A38: 1716 | B38: Tortoise Shell | C38: Nevis | D38: Out Ports | H38: 2.5 | J38: =(E38*2240)+(F38*112)+(G38*28)+(H38) -> 2.5 | L38: =J38/2240 -> 0.0011160714

Sheet St Kitts
A1: YEAR | B1: COMMODITY_NAME | C1: FROM_LOCATION | D1: TO_LOCATION | E1: ton | F1: hh | G1: quarter | H1: lb | J1: Total Pounds | L1: WEIGHT
A2: 1716 | B2: Elephant Teeth | C2: StKitts | D2: London | F2: 40 | G2: 3 | H2: 27 | J2: =(E2*2240)+(F2*112)+(G2*28)+(H2/16) -> 4565.6875 | L2: =J2/2240 -> 2.0382533
A3: 1716 | B3: Annatto | C3: StKitts | D3: London | H3: 2392 | J3: =(E3*2240)+(F3*112)+(G3*28)+(H3/16) -> 149.5 | L3: =J3/2240 -> 0.066741071
A4: 1716 | B4: Molasses | C4: StKitts | D4: London | J4: =(E4*2240)+(F4*112)+(G4*28)+(H4/16) -> 0 | L4: =J4/2240 -> 0
A5: 1716 | B5: Brown Sugar | C5: StKitts | D5: London | F5: 64670 | G5: 3 | H5: 22 | J5: =(E5*2240)+(F5*112)+(G5*28)+(H5/16) -> 7243125.4 | L5: =J5/2240 -> 3233.5381
A6: 1716 | B6: Indigo | C6: StKitts | D6: London | H6: 3904 | J6: =(E6*2240)+(F6*112)+(G6*28)+(H6/16) -> 244 | L6: =J6/2240 -> 0.10892857
A7: 1716 | B7: Cotton | C7: StKitts | D7: London | H7: 31808 | J7: =(E7*2240)+(F7*112)+(G7*28)+(H7/16) -> 1988 | L7: =J7/2240 -> 0.8875
A8: 1716 | B8: Cocoa Nuts | C8: StKitts | D8: London | F8: 31 | H8: 13 | J8: =(E8*2240)+(F8*112)+(G8*28)+(H8/16) -> 3472.8125 | L8: =J8/2240 -> 1.5503627
A9: 1716 | B9: Dry Ginger | C9: StKitts | D9: London | F9: 90 | G9: 3 | J9: =(E9*2240)+(F9*112)+(G9*28)+(H9/16) -> 10164 | L9: =J9/2240 -> 4.5375
A10: 1716 | B10: Lignum Vitae | C10: StKitts | D10: London | E10: 61 | F10: 19 | H10: 6 | J10: =(E10*2240)+(F10*112)+(G10*28)+(H10/16) -> 138768.38 | L10: =J10/2240 -> 61.950167
A11: 1716 | B11: Logwood | C11: StKitts | D11: London | E11: 6 | F11: 13 | G11: 2 | H11: 14 | J11: =(E11*2240)+(F11*112)+(G11*28)+(H11/16) -> 14952.875 | L11: =J11/2240 -> 6.6753906
A12: 1716 | B12: Shruff | C12: StKitts | D12: London | F12: 16 | H12: 10 | J12: =(E12*2240)+(F12*112)+(G12*28)+(H12/16) -> 1792.625 | L12: =J12/2240 -> 0.80027902
A13: 1716 | B13: Succands | C13: StKitts | D13: London | H13: 253 | J13: =(E13*2240)+(F13*112)+(G13*28)+(H13/16) -> 15.8125 | L13: =J13/2240 -> 0.0070591518
A14: 1716 | B14: Bees Wax | C14: StKitts | D14: London | F14: 6 | G14: 1 | H14: 14 | J14: =(E14*2240)+(F14*112)+(G14*28)+(H14/16) -> 700.875 | L14: =J14/2240 -> 0.31289062
A15: 1716 | B15: Pimento | C15: StKitts | D15: London | H15: 2000 | J15: =(E15*2240)+(F15*112)+(G15*28)+(H15/16) -> 125 | L15: =J15/2240 -> 0.055803571
A16: 1716 | B16: Rum | C16: StKitts | D16: London | H16: 6148 | I16: 591g | J16: =(E16*2240)+(F16*112)+(G16*28)+(H16/16) -> 384.25 | L16: =J16/2240 -> 0.17154018
A17: 1716 | B17: Elephant Teeth | C17: StKitts | D17: Out Ports | F17: 4 | G17: 2 | H17: 22 | J17: =(E17*2240)+(F17*112)+(G17*28)+(H17/16) -> 505.375 | L17: =J17/2240 -> 0.22561384
A18: 1716 | B18: Indigo | C18: StKitts | D18: Out Ports | H18: 2458 | J18: =(E18*2240)+(F18*112)+(G18*28)+(H18/16) -> 153.625 | L18: =J18/2240 -> 0.068582589
A19: 1716 | B19: Lignum Vitae | C19: StKitts | D19: Out Ports | F19: 125 | G19: 1 | H19: 19 | J19: =(E19*2240)+(F19*112)+(G19*28)+(H19/16) -> 14029.188 | L19: =J19/2240 -> 6.2630301
A20: 1716 | B20: Molasses | C20: StKitts | D20: Out Ports | F20: 9 | H20: 11 | J20: =(E20*2240)+(F20*112)+(G20*28)+(H20/16) -> 1008.6875 | L20: =J20/2240 -> 0.45030692
A21: 1716 | B21: Succands | C21: StKitts | D21: Out Ports | H21: 98 | J21: =(E21*2240)+(F21*112)+(G21*28)+(H21/16) -> 6.125 | L21: =J21/2240 -> 0.002734375
A22: 1716 | B22: Brown Sugar | C22: StKitts | D22: Out Ports | F22: 17147 | G22: 3 | H22: 10 | J22: =(E22*2240)+(F22*112)+(G22*28)+(H22/16) -> 1920548.6 | L22: =J22/2240 -> 857.38778
A23: 1716 | B23: Cotton | C23: StKitts | D23: Out Ports | H23: 46646 | J23: =(E23*2240)+(F23*112)+(G23*28)+(H23/16) -> 2915.375 | L23: =J23/2240 -> 1.3015067

Sheet NewEngland
A1: YEAR | B1: COMMODITY_NAME | C1: FROM_LOCATION | D1: TO_LOCATION | E1: ton | F1: hh | G1: quarter | H1: lb | J1: Total Pounds | L1: WEIGHT
A2: 1716 | B2: Lignum Vitae | C2: NewEngland | D2: London | J2: =(E2*2240)+(F2*112)+(G2*28)+H2 -> 0 | L2: =J2/2240 -> 0
A3: 1716 | B3: Braziletto Wood | C3: NewEngland | D3: London | E3: 35 | F3: 15 | H3: 20 | J3: =(E3*2240)+(F3*112)+(G3*28)+H3 -> 80100 | L3: =J3/2240 -> 35.758929
A4: 1716 | B4: Fustick Wood | C4: NewEngland | D4: London | E4: 114 | F4: 9 | G4: 3 | H4: 20 | J4: =(E4*2240)+(F4*112)+(G4*28)+H4 -> 256472 | L4: =J4/2240 -> 114.49643
A5: 1716 | B5: Logwood | C5: NewEngland | D5: London | E5: 613 | F5: 12 | G5: 3 | H5: 7 | J5: =(E5*2240)+(F5*112)+(G5*28)+H5 -> 1374555 | L5: =J5/2240 -> 613.64062
A6: 1716 | B6: Cortex Winteranus | C6: NewEngland | D6: London | J6: =(E6*2240)+(F6*112)+(G6*28)+H6 -> 0 | L6: =J6/2240 -> 0
A7: 1716 | B7: Turpentine Common | C7: NewEngland | D7: London | J7: =(E7*2240)+(F7*112)+(G7*28)+H7 -> 0 | L7: =J7/2240 -> 0
A8: 1716 | B8: Dry Ginger | C8: NewEngland | D8: London | J8: =(E8*2240)+(F8*112)+(G8*28)+H8 -> 0 | L8: =J8/2240 -> 0
A9: 1716 | B9: Molasses | C9: NewEngland | D9: London | J9: =(E9*2240)+(F9*112)+(G9*28)+H9 -> 0 | L9: =J9/2240 -> 0
A10: 1716 | B10: Brown Sugar | C10: NewEngland | D10: London | J10: =(E10*2240)+(F10*112)+(G10*28)+H10 -> 0 | L10: =J10/2240 -> 0
A11: 1716 | B11: White Sugar | C11: NewEngland | D11: London | J11: =(E11*2240)+(F11*112)+(G11*28)+H11 -> 0 | L11: =J11/2240 -> 0
A12: 1716 | B12: Rice | C12: NewEngland | D12: London | J12: =(E12*2240)+(F12*112)+(G12*28)+H12 -> 0 | L12: =J12/2240 -> 0
A13: 1716 | B13: Shruff | C13: NewEngland | D13: London | F13: 14 | G13: 1 | H13: 14 | J13: =(E13*2240)+(F13*112)+(G13*28)+H13 -> 1610 | L13: =J13/2240 -> 0.71875
A14: 1716 | B14: Indigo | C14: NewEngland | D14: London | J14: =(E14*2240)+(F14*112)+(G14*28)+H14 -> 0 | L14: =J14/2240 -> 0
A15: 1716 | B15: Tobacco | C15: NewEngland | D15: London | H15: 200 | J15: =(E15*2240)+(F15*112)+(G15*28)+H15 -> 200 | L15: =J15/2240 -> 0.089285714
A16: 1716 | B16: Cotton | C16: NewEngland | D16: London | H16: 2912 | J16: =(E16*2240)+(F16*112)+(G16*28)+H16 -> 2912 | L16: =J16/2240 -> 1.3
A17: 1716 | B17: Bayberries | C17: NewEngland | D17: London | J17: =(E17*2240)+(F17*112)+(G17*28)+H17 -> 0 | L17: =J17/2240 -> 0
A18: 1716 | B18: Bayberry Wax | C18: NewEngland | D18: London | J18: =(E18*2240)+(F18*112)+(G18*28)+H18 -> 0 | L18: =J18/2240 -> 0
A19: 1716 | B19: Tortoise Shell | C19: NewEngland | D19: London | J19: =(E19*2240)+(F19*112)+(G19*28)+H19 -> 0 | L19: =J19/2240 -> 0
A20: 1716 | B20: Cocoa Nuts | C20: NewEngland | D20: London | F20: 58 | J20: =(E20*2240)+(F20*112)+(G20*28)+H20 -> 6496 | L20: =J20/2240 -> 2.9
A21: 1716 | B21: Rum | C21: NewEngland | D21: London | H21: 3875 | I21: 372.5g | J21: =(E21*2240)+(F21*112)+(G21*28)+H21 -> 3875 | L21: =J21/2240 -> 1.7299107
A22: 1716 | B22: Lime Juice | C22: NewEngland | D22: London | J22: =(E22*2240)+(F22*112)+(G22*28)+H22 -> 0 | L22: =J22/2240 -> 0
A23: 1716 | B23: Madera Wine | C23: NewEngland | D23: London | J23: =(E23*2240)+(F23*112)+(G23*28)+H23 -> 0 | L23: =J23/2240 -> 0
A24: 1716 | B24: Lignum Vitae | C24: NewEngland | D24: Out Ports | J24: =(E24*2240)+(F24*112)+(G24*28)+H24 -> 0 | L24: =J24/2240 -> 0
A25: 1716 | B25: Dry Ginger | C25: NewEngland | D25: Out Ports | J25: =(E25*2240)+(F25*112)+(G25*28)+H25 -> 0 | L25: =J25/2240 -> 0
A26: 1716 | B26: Molasses | C26: NewEngland | D26: Out Ports | J26: =(E26*2240)+(F26*112)+(G26*28)+H26 -> 0 | L26: =J26/2240 -> 0
A27: 1716 | B27: Brown Sugar | C27: NewEngland | D27: Out Ports | J27: =(E27*2240)+(F27*112)+(G27*28)+H27 -> 0 | L27: =J27/2240 -> 0
A28: 1716 | B28: Rice | C28: NewEngland | D28: Out Ports | J28: =(E28*2240)+(F28*112)+(G28*28)+H28 -> 0 | L28: =J28/2240 -> 0
A29: 1716 | B29: Tobacco | C29: NewEngland | D29: Out Ports | J29: =(E29*2240)+(F29*112)+(G29*28)+H29 -> 0 | L29: =J29/2240 -> 0
A30: 1716 | B30: Hops | C30: NewEngland | D30: Out Ports | J30: =(E30*2240)+(F30*112)+(G30*28)+H30 -> 0 | L30: =J30/2240 -> 0
A31: 1716 | B31: Braziletto Wood | C31: NewEngland | D31: Out Ports | J31: =(E31*2240)+(F31*112)+(G31*28)+H31 -> 0 | L31: =J31/2240 -> 0
A32: 1716 | B32: Fustick Wood | C32: NewEngland | D32: Out Ports | J32: =(E32*2240)+(F32*112)+(G32*28)+H32 -> 0 | L32: =J32/2240 -> 0
A33: 1716 | B33: Logwood | C33: NewEngland | D33: Out Ports | J33: =(E33*2240)+(F33*112)+(G33*28)+H33 -> 0 | L33: =J33/2240 -> 0
A34: 1716 | B34: Rum | C34: NewEngland | D34: Out Ports | J34: =(E34*2240)+(F34*112)+(G34*28)+H34 -> 0 | L34: =J34/2240 -> 0
