Workbook

Sheet Master Goods Sheet
A1: Item | B1: Total London | C1: Total Outports | D1: Total
A2: Annatto | B2: =SUMIFS(Antigua!$L:$L, Antigua!$B:$B, $A2, Antigua!$D:$D, "London") + SUMIFS(Barbados!$L:$L, Barbados!$B:$B, $A2, Barbados!$D:$D, "London") + SUMIFS(Bermuda!$L:$L, Bermuda!$B:$B, $A2, Bermuda!$D:$D, "London") + SUMIFS(Carolina!$L:$L, Carolina!$B:$B, $A2, Carolina!$D:$D, "London") + SUMIFS(Jamaica!$L:$L, Jamaica!$B:$B, $A2, Jamaica!$D:$D, "London") + SUMIFS(Mountserat!$L:$L, Mountserat!$B:$B, $A2, Mountserat!$D:$D, "London") + SUMIFS(Nevis!$L:$L, Nevis!$B:$B, $A2, Nevis!$D:$D, "London") + SUMIFS(NewEngland!$J:$J, NewEngland!$A:$A, $A2, NewEngland!$B:$B, "London") + SUMIFS(StKitts!$L:$L, StKitts!$B:$B, $A2, StKitts!$D:$D, "London") + SUMIFS(GeneralWI!$L:$L, GeneralWI!$B:$B, $A2, GeneralWI!$D:$D, "London") -> 6.4245536 | C2: =SUMIFS(Antigua!$L:$L, Antigua!$B:$B, $A2, Antigua!$D:$D, "Out Ports") + SUMIFS(Barbados!$L:$L, Barbados!$B:$B, $A2, Barbados!$D:$D, "Out Ports") + SUMIFS(Bermuda!$L:$L, Bermuda!$B:$B, $A2, Bermuda!$D:$D, "Out Ports") + SUMIFS(Carolina!$L:$L, Carolina!$B:$B, $A2, Carolina!$D:$D, "Out Ports") + SUMIFS(Jamaica!$L:$L, Jamaica!$B:$B, $A2, Jamaica!$D:$D, "Out Ports") + SUMIFS(Mountserat!$L:$L, Mountserat!$B:$B, $A2, Mountserat!$D:$D, "Out Ports") + SUMIFS(Nevis!$L:$L, Nevis!$B:$B, $A2, Nevis!$D:$D, "Out Ports") + SUMIFS(NewEngland!$J:$J, NewEngland!$A:$A, $A2, NewEngland!$B:$B, "Out Ports") + SUMIFS(StKitts!$L:$L, StKitts!$B:$B, $A2, StKitts!$D:$D, "Out Ports") + SUMIFS(GeneralWI!$L:$L, GeneralWI!$B:$B, $A2, GeneralWI!$D:$D, "Out Ports") -> 0.21116071 | D2: =ROUND((B2+C2),2) -> 6.64
A3: Bayberry Wax | B3: =SUMIFS(Antigua!$L:$L, Antigua!$B:$B, $A3, Antigua!$D:$D, "London") + SUMIFS(Barbados!$L:$L, Barbados!$B:$B, $A3, Barbados!$D:$D, "London") + SUMIFS(Bermuda!$L:$L, Bermuda!$B:$B, $A3, Bermuda!$D:$D, "London") + SUMIFS(Carolina!$L:$L, Carolina!$B:$B, $A3, Carolina!$D:$D, "London") + SUMIFS(Jamaica!$L:$L, Jamaica!$B:$B, $A3, Jamaica!$D:$D, "London") + SUMIFS(Mountserat!$L:$L, Mountserat!$B:$B, $A3, Mountserat!$D:$D, "London") + SUMIFS(Nevis!$L:$L, Nevis!$B:$B, $A3, Nevis!$D:$D, "London") + SUMIFS(NewEngland!$J:$J, NewEngland!$A:$A, $A3, NewEngland!$B:$B, "London") + SUMIFS(StKitts!$L:$L, StKitts!$B:$B, $A3, StKitts!$D:$D, "London") + SUMIFS(GeneralWI!$L:$L, GeneralWI!$B:$B, $A3, GeneralWI!$D:$D, "London") -> 0 | C3: =SUMIFS(Antigua!$L:$L, Antigua!$B:$B, $A3, Antigua!$D:$D, "Out Ports") + SUMIFS(Barbados!$L:$L, Barbados!$B:$B, $A3, Barbados!$D:$D, "Out Ports") + SUMIFS(Bermuda!$L:$L, Bermuda!$B:$B, $A3, Bermuda!$D:$D, "Out Ports") + SUMIFS(Carolina!$L:$L, Carolina!$B:$B, $A3, Carolina!$D:$D, "Out Ports") + SUMIFS(Jamaica!$L:$L, Jamaica!$B:$B, $A3, Jamaica!$D:$D, "Out Ports") + SUMIFS(Mountserat!$L:$L, Mountserat!$B:$B, $A3, Mountserat!$D:$D, "Out Ports") + SUMIFS(Nevis!$L:$L, Nevis!$B:$B, $A3, Nevis!$D:$D, "Out Ports") + SUMIFS(NewEngland!$J:$J, NewEngland!$A:$A, $A3, NewEngland!$B:$B, "Out Ports") + SUMIFS(StKitts!$L:$L, StKitts!$B:$B, $A3, StKitts!$D:$D, "Out Ports") + SUMIFS(GeneralWI!$L:$L, GeneralWI!$B:$B, $A3, GeneralWI!$D:$D, "Out Ports") -> 0 | D3: =ROUND((B3+C3),2) -> 0
A4: Bees Wax | B4: =SUMIFS(Antigua!$L:$L, Antigua!$B:$B, $A4, Antigua!$D:$D, "London") + SUMIFS(Barbados!$L:$L, Barbados!$B:$B, $A4, Barbados!$D:$D, "London") + SUMIFS(Bermuda!$L:$L, Bermuda!$B:$B, $A4, Bermuda!$D:$D, "London") + SUMIFS(Carolina!$L:$L, Carolina!$B:$B, $A4, Carolina!$D:$D, "London") + SUMIFS(Jamaica!$L:$L, Jamaica!$B:$B, $A4, Jamaica!$D:$D, "London") + SUMIFS(Mountserat!$L:$L, Mountserat!$B:$B, $A4, Mountserat!$D:$D, "London") + SUMIFS(Nevis!$L:$L, Nevis!$B:$B, $A4, Nevis!$D:$D, "London") + SUMIFS(NewEngland!$J:$J, NewEngland!$A:$A, $A4, NewEngland!$B:$B, "London") + SUMIFS(StKitts!$L:$L, StKitts!$B:$B, $A4, StKitts!$D:$D, "London") + SUMIFS(GeneralWI!$L:$L, GeneralWI!$B:$B, $A4, GeneralWI!$D:$D, "London") -> 0 | C4: =SUMIFS(Antigua!$L:$L, Antigua!$B:$B, $A4, Antigua!$D:$D, "Out Ports") + SUMIFS(Barbados!$L:$L, Barbados!$B:$B, $A4, Barbados!$D:$D, "Out Ports") + SUMIFS(Bermuda!$L:$L, Bermuda!$B:$B, $A4, Bermuda!$D:$D, "Out Ports") + SUMIFS(Carolina!$L:$L, Carolina!$B:$B, $A4, Carolina!$D:$D, "Out Ports") + SUMIFS(Jamaica!$L:$L, Jamaica!$B:$B, $A4, Jamaica!$D:$D, "Out Ports") + SUMIFS(Mountserat!$L:$L, Mountserat!$B:$B, $A4, Mountserat!$D:$D, "Out Ports") + SUMIFS(Nevis!$L:$L, Nevis!$B:$B, $A4, Nevis!$D:$D, "Out Ports") + SUMIFS(NewEngland!$J:$J, NewEngland!$A:$A, $A4, NewEngland!$B:$B, "Out Ports") + SUMIFS(StKitts!$L:$L, StKitts!$B:$B, $A4, StKitts!$D:$D, "Out Ports") + SUMIFS(GeneralWI!$L:$L, GeneralWI!$B:$B, $A4, GeneralWI!$D:$D, "Out Ports") -> 0 | D4: =ROUND((B4+C4),2) -> 0
A5: Brandy | B5: =SUMIFS(Antigua!$L:$L, Antigua!$B:$B, $A5, Antigua!$D:$D, "London") + SUMIFS(Barbados!$L:$L, Barbados!$B:$B, $A5, Barbados!$D:$D, "London") + SUMIFS(Bermuda!$L:$L, Bermuda!$B:$B, $A5, Bermuda!$D:$D, "London") + SUMIFS(Carolina!$L:$L, Carolina!$B:$B, $A5, Carolina!$D:$D, "London") + SUMIFS(Jamaica!$L:$L, Jamaica!$B:$B, $A5, Jamaica!$D:$D, "London") + SUMIFS(Mountserat!$L:$L, Mountserat!$B:$B, $A5, Mountserat!$D:$D, "London") + SUMIFS(Nevis!$L:$L, Nevis!$B:$B, $A5, Nevis!$D:$D, "London") + SUMIFS(NewEngland!$J:$J, NewEngland!$A:$A, $A5, NewEngland!$B:$B, "London") + SUMIFS(StKitts!$L:$L, StKitts!$B:$B, $A5, StKitts!$D:$D, "London") + SUMIFS(GeneralWI!$L:$L, GeneralWI!$B:$B, $A5, GeneralWI!$D:$D, "London") -> 0 | C5: =SUMIFS(Antigua!$L:$L, Antigua!$B:$B, $A5, Antigua!$D:$D, "Out Ports") + SUMIFS(Barbados!$L:$L, Barbados!$B:$B, $A5, Barbados!$D:$D, "Out Ports") + SUMIFS(Bermuda!$L:$L, Bermuda!$B:$B, $A5, Bermuda!$D:$D, "Out Ports") + SUMIFS(Carolina!$L:$L, Carolina!$B:$B, $A5, Carolina!$D:$D, "Out Ports") + SUMIFS(Jamaica!$L:$L, Jamaica!$B:$B, $A5, Jamaica!$D:$D, "Out Ports") + SUMIFS(Mountserat!$L:$L, Mountserat!$B:$B, $A5, Mountserat!$D:$D, "Out Ports") + SUMIFS(Nevis!$L:$L, Nevis!$B:$B, $A5, Nevis!$D:$D, "Out Ports") + SUMIFS(NewEngland!$J:$J, NewEngland!$A:$A, $A5, NewEngland!$B:$B, "Out Ports") + SUMIFS(StKitts!$L:$L, StKitts!$B:$B, $A5, StKitts!$D:$D, "Out Ports") + SUMIFS(GeneralWI!$L:$L, GeneralWI!$B:$B, $A5, GeneralWI!$D:$D, "Out Ports") -> 0 | D5: =ROUND((B5+C5),2) -> 0
A6: Brown Sugar | B6: =SUMIFS(Antigua!$L:$L, Antigua!$B:$B, $A6, Antigua!$D:$D, "London") + SUMIFS(Barbados!$L:$L, Barbados!$B:$B, $A6, Barbados!$D:$D, "London") + SUMIFS(Bermuda!$L:$L, Bermuda!$B:$B, $A6, Bermuda!$D:$D, "London") + SUMIFS(Carolina!$L:$L, Carolina!$B:$B, $A6, Carolina!$D:$D, "London") + SUMIFS(Jamaica!$L:$L, Jamaica!$B:$B, $A6, Jamaica!$D:$D, "London") + SUMIFS(Mountserat!$L:$L, Mountserat!$B:$B, $A6, Mountserat!$D:$D, "London") + SUMIFS(Nevis!$L:$L, Nevis!$B:$B, $A6, Nevis!$D:$D, "London") + SUMIFS(NewEngland!$J:$J, NewEngland!$A:$A, $A6, NewEngland!$B:$B, "London") + SUMIFS(StKitts!$L:$L, StKitts!$B:$B, $A6, StKitts!$D:$D, "London") + SUMIFS(GeneralWI!$L:$L, GeneralWI!$B:$B, $A6, GeneralWI!$D:$D, "London") -> 27283.554 | C6: =SUMIFS(Antigua!$L:$L, Antigua!$B:$B, $A6, Antigua!$D:$D, "Out Ports") + SUMIFS(Barbados!$L:$L, Barbados!$B:$B, $A6, Barbados!$D:$D, "Out Ports") + SUMIFS(Bermuda!$L:$L, Bermuda!$B:$B, $A6, Bermuda!$D:$D, "Out Ports") + SUMIFS(Carolina!$L:$L, Carolina!$B:$B, $A6, Carolina!$D:$D, "Out Ports") + SUMIFS(Jamaica!$L:$L, Jamaica!$B:$B, $A6, Jamaica!$D:$D, "Out Ports") + SUMIFS(Mountserat!$L:$L, Mountserat!$B:$B, $A6, Mountserat!$D:$D, "Out Ports") + SUMIFS(Nevis!$L:$L, Nevis!$B:$B, $A6, Nevis!$D:$D, "Out Ports") + SUMIFS(NewEngland!$J:$J, NewEngland!$A:$A, $A6, NewEngland!$B:$B, "Out Ports") + SUMIFS(StKitts!$L:$L, StKitts!$B:$B, $A6, StKitts!$D:$D, "Out Ports") + SUMIFS(GeneralWI!$L:$L, GeneralWI!$B:$B, $A6, GeneralWI!$D:$D, "Out Ports") -> 7702.0478 | D6: =ROUND((B6+C6),2) -> 34985.6
A7: Cascarilla | B7: =SUMIFS(Antigua!$L:$L, Antigua!$B:$B, $A7, Antigua!$D:$D, "London") + SUMIFS(Barbados!$L:$L, Barbados!$B:$B, $A7, Barbados!$D:$D, "London") + SUMIFS(Bermuda!$L:$L, Bermuda!$B:$B, $A7, Bermuda!$D:$D, "London") + SUMIFS(Carolina!$L:$L, Carolina!$B:$B, $A7, Carolina!$D:$D, "London") + SUMIFS(Jamaica!$L:$L, Jamaica!$B:$B, $A7, Jamaica!$D:$D, "London") + SUMIFS(Mountserat!$L:$L, Mountserat!$B:$B, $A7, Mountserat!$D:$D, "London") + SUMIFS(Nevis!$L:$L, Nevis!$B:$B, $A7, Nevis!$D:$D, "London") + SUMIFS(NewEngland!$J:$J, NewEngland!$A:$A, $A7, NewEngland!$B:$B, "London") + SUMIFS(StKitts!$L:$L, StKitts!$B:$B, $A7, StKitts!$D:$D, "London") + SUMIFS(GeneralWI!$L:$L, GeneralWI!$B:$B, $A7, GeneralWI!$D:$D, "London") -> 1.3151786 | C7: =SUMIFS(Antigua!$L:$L, Antigua!$B:$B, $A7, Antigua!$D:$D, "Out Ports") + SUMIFS(Barbados!$L:$L, Barbados!$B:$B, $A7, Barbados!$D:$D, "Out Ports") + SUMIFS(Bermuda!$L:$L, Bermuda!$B:$B, $A7, Bermuda!$D:$D, "Out Ports") + SUMIFS(Carolina!$L:$L, Carolina!$B:$B, $A7, Carolina!$D:$D, "Out Ports") + SUMIFS(Jamaica!$L:$L, Jamaica!$B:$B, $A7, Jamaica!$D:$D, "Out Ports") + SUMIFS(Mountserat!$L:$L, Mountserat!$B:$B, $A7, Mountserat!$D:$D, "Out Ports") + SUMIFS(Nevis!$L:$L, Nevis!$B:$B, $A7, Nevis!$D:$D, "Out Ports") + SUMIFS(NewEngland!$J:$J, NewEngland!$A:$A, $A7, NewEngland!$B:$B, "Out Ports") + SUMIFS(StKitts!$L:$L, StKitts!$B:$B, $A7, StKitts!$D:$D, "Out Ports") + SUMIFS(GeneralWI!$L:$L, GeneralWI!$B:$B, $A7, GeneralWI!$D:$D, "Out Ports") -> 0 | D7: =ROUND((B7+C7),2) -> 1.32
A8: Chocolate | B8: =SUMIFS(Antigua!$L:$L, Antigua!$B:$B, $A8, Antigua!$D:$D, "London") + SUMIFS(Barbados!$L:$L, Barbados!$B:$B, $A8, Barbados!$D:$D, "London") + SUMIFS(Bermuda!$L:$L, Bermuda!$B:$B, $A8, Bermuda!$D:$D, "London") + SUMIFS(Carolina!$L:$L, Carolina!$B:$B, $A8, Carolina!$D:$D, "London") + SUMIFS(Jamaica!$L:$L, Jamaica!$B:$B, $A8, Jamaica!$D:$D, "London") + SUMIFS(Mountserat!$L:$L, Mountserat!$B:$B, $A8, Mountserat!$D:$D, "London") + SUMIFS(Nevis!$L:$L, Nevis!$B:$B, $A8, Nevis!$D:$D, "London") + SUMIFS(NewEngland!$J:$J, NewEngland!$A:$A, $A8, NewEngland!$B:$B, "London") + SUMIFS(StKitts!$L:$L, StKitts!$B:$B, $A8, StKitts!$D:$D, "London") + SUMIFS(GeneralWI!$L:$L, GeneralWI!$B:$B, $A8, GeneralWI!$D:$D, "London") -> 0.024107143 | C8: =SUMIFS(Antigua!$L:$L, Antigua!$B:$B, $A8, Antigua!$D:$D, "Out Ports") + SUMIFS(Barbados!$L:$L, Barbados!$B:$B, $A8, Barbados!$D:$D, "Out Ports") + SUMIFS(Bermuda!$L:$L, Bermuda!$B:$B, $A8, Bermuda!$D:$D, "Out Ports") + SUMIFS(Carolina!$L:$L, Carolina!$B:$B, $A8, Carolina!$D:$D, "Out Ports") + SUMIFS(Jamaica!$L:$L, Jamaica!$B:$B, $A8, Jamaica!$D:$D, "Out Ports") + SUMIFS(Mountserat!$L:$L, Mountserat!$B:$B, $A8, Mountserat!$D:$D, "Out Ports") + SUMIFS(Nevis!$L:$L, Nevis!$B:$B, $A8, Nevis!$D:$D, "Out Ports") + SUMIFS(NewEngland!$J:$J, NewEngland!$A:$A, $A8, NewEngland!$B:$B, "Out Ports") + SUMIFS(StKitts!$L:$L, StKitts!$B:$B, $A8, StKitts!$D:$D, "Out Ports") + SUMIFS(GeneralWI!$L:$L, GeneralWI!$B:$B, $A8, GeneralWI!$D:$D, "Out Ports") -> 0.025 | D8: =ROUND((B8+C8),2) -> 0.05
A9: Cocheneal | B9: =SUMIFS(Antigua!$L:$L, Antigua!$B:$B, $A9, Antigua!$D:$D, "London") + SUMIFS(Barbados!$L:$L, Barbados!$B:$B, $A9, Barbados!$D:$D, "London") + SUMIFS(Bermuda!$L:$L, Bermuda!$B:$B, $A9, Bermuda!$D:$D, "London") + SUMIFS(Carolina!$L:$L, Carolina!$B:$B, $A9, Carolina!$D:$D, "London") + SUMIFS(Jamaica!$L:$L, Jamaica!$B:$B, $A9, Jamaica!$D:$D, "London") + SUMIFS(Mountserat!$L:$L, Mountserat!$B:$B, $A9, Mountserat!$D:$D, "London") + SUMIFS(Nevis!$L:$L, Nevis!$B:$B, $A9, Nevis!$D:$D, "London") + SUMIFS(NewEngland!$J:$J, NewEngland!$A:$A, $A9, NewEngland!$B:$B, "London") + SUMIFS(StKitts!$L:$L, StKitts!$B:$B, $A9, StKitts!$D:$D, "London") + SUMIFS(GeneralWI!$L:$L, GeneralWI!$B:$B, $A9, GeneralWI!$D:$D, "London") -> 0.17098214 | C9: =SUMIFS(Antigua!$L:$L, Antigua!$B:$B, $A9, Antigua!$D:$D, "Out Ports") + SUMIFS(Barbados!$L:$L, Barbados!$B:$B, $A9, Barbados!$D:$D, "Out Ports") + SUMIFS(Bermuda!$L:$L, Bermuda!$B:$B, $A9, Bermuda!$D:$D, "Out Ports") + SUMIFS(Carolina!$L:$L, Carolina!$B:$B, $A9, Carolina!$D:$D, "Out Ports") + SUMIFS(Jamaica!$L:$L, Jamaica!$B:$B, $A9, Jamaica!$D:$D, "Out Ports") + SUMIFS(Mountserat!$L:$L, Mountserat!$B:$B, $A9, Mountserat!$D:$D, "Out Ports") + SUMIFS(Nevis!$L:$L, Nevis!$B:$B, $A9, Nevis!$D:$D, "Out Ports") + SUMIFS(NewEngland!$J:$J, NewEngland!$A:$A, $A9, NewEngland!$B:$B, "Out Ports") + SUMIFS(StKitts!$L:$L, StKitts!$B:$B, $A9, StKitts!$D:$D, "Out Ports") + SUMIFS(GeneralWI!$L:$L, GeneralWI!$B:$B, $A9, GeneralWI!$D:$D, "Out Ports") -> 0 | D9: =ROUND((B9+C9),2) -> 0.17
A10: Cocoa Nuts | B10: =SUMIFS(Antigua!$L:$L, Antigua!$B:$B, $A10, Antigua!$D:$D, "London") + SUMIFS(Barbados!$L:$L, Barbados!$B:$B, $A10, Barbados!$D:$D, "London") + SUMIFS(Bermuda!$L:$L, Bermuda!$B:$B, $A10, Bermuda!$D:$D, "London") + SUMIFS(Carolina!$L:$L, Carolina!$B:$B, $A10, Carolina!$D:$D, "London") + SUMIFS(Jamaica!$L:$L, Jamaica!$B:$B, $A10, Jamaica!$D:$D, "London") + SUMIFS(Mountserat!$L:$L, Mountserat!$B:$B, $A10, Mountserat!$D:$D, "London") + SUMIFS(Nevis!$L:$L, Nevis!$B:$B, $A10, Nevis!$D:$D, "London") + SUMIFS(NewEngland!$J:$J, NewEngland!$A:$A, $A10, NewEngland!$B:$B, "London") + SUMIFS(StKitts!$L:$L, StKitts!$B:$B, $A10, StKitts!$D:$D, "London") + SUMIFS(GeneralWI!$L:$L, GeneralWI!$B:$B, $A10, GeneralWI!$D:$D, "London") -> 14.854464 | C10: =SUMIFS(Antigua!$L:$L, Antigua!$B:$B, $A10, Antigua!$D:$D, "Out Ports") + SUMIFS(Barbados!$L:$L, Barbados!$B:$B, $A10, Barbados!$D:$D, "Out Ports") + SUMIFS(Bermuda!$L:$L, Bermuda!$B:$B, $A10, Bermuda!$D:$D, "Out Ports") + SUMIFS(Carolina!$L:$L, Carolina!$B:$B, $A10, Carolina!$D:$D, "Out Ports") + SUMIFS(Jamaica!$L:$L, Jamaica!$B:$B, $A10, Jamaica!$D:$D, "Out Ports") + SUMIFS(Mountserat!$L:$L, Mountserat!$B:$B, $A10, Mountserat!$D:$D, "Out Ports") + SUMIFS(Nevis!$L:$L, Nevis!$B:$B, $A10, Nevis!$D:$D, "Out Ports") + SUMIFS(NewEngland!$J:$J, NewEngland!$A:$A, $A10, NewEngland!$B:$B, "Out Ports") + SUMIFS(StKitts!$L:$L, StKitts!$B:$B, $A10, StKitts!$D:$D, "Out Ports") + SUMIFS(GeneralWI!$L:$L, GeneralWI!$B:$B, $A10, GeneralWI!$D:$D, "Out Ports") -> 3.7633929 | D10: =ROUND((B10+C10),2) -> 18.62
A11: Cotton | B11: =SUMIFS(Antigua!$L:$L, Antigua!$B:$B, $A11, Antigua!$D:$D, "London") + SUMIFS(Barbados!$L:$L, Barbados!$B:$B, $A11, Barbados!$D:$D, "London") + SUMIFS(Bermuda!$L:$L, Bermuda!$B:$B, $A11, Bermuda!$D:$D, "London") + SUMIFS(Carolina!$L:$L, Carolina!$B:$B, $A11, Carolina!$D:$D, "London") + SUMIFS(Jamaica!$L:$L, Jamaica!$B:$B, $A11, Jamaica!$D:$D, "London") + SUMIFS(Mountserat!$L:$L, Mountserat!$B:$B, $A11, Mountserat!$D:$D, "London") + SUMIFS(Nevis!$L:$L, Nevis!$B:$B, $A11, Nevis!$D:$D, "London") + SUMIFS(NewEngland!$J:$J, NewEngland!$A:$A, $A11, NewEngland!$B:$B, "London") + SUMIFS(StKitts!$L:$L, StKitts!$B:$B, $A11, StKitts!$D:$D, "London") + SUMIFS(GeneralWI!$L:$L, GeneralWI!$B:$B, $A11, GeneralWI!$D:$D, "London") -> 360.44643 | C11: =SUMIFS(Antigua!$L:$L, Antigua!$B:$B, $A11, Antigua!$D:$D, "Out Ports") + SUMIFS(Barbados!$L:$L, Barbados!$B:$B, $A11, Barbados!$D:$D, "Out Ports") + SUMIFS(Bermuda!$L:$L, Bermuda!$B:$B, $A11, Bermuda!$D:$D, "Out Ports") + SUMIFS(Carolina!$L:$L, Carolina!$B:$B, $A11, Carolina!$D:$D, "Out Ports") + SUMIFS(Jamaica!$L:$L, Jamaica!$B:$B, $A11, Jamaica!$D:$D, "Out Ports") + SUMIFS(Mountserat!$L:$L, Mountserat!$B:$B, $A11, Mountserat!$D:$D, "Out Ports") + SUMIFS(Nevis!$L:$L, Nevis!$B:$B, $A11, Nevis!$D:$D, "Out Ports") + SUMIFS(NewEngland!$J:$J, NewEngland!$A:$A, $A11, NewEngland!$B:$B, "Out Ports") + SUMIFS(StKitts!$L:$L, StKitts!$B:$B, $A11, StKitts!$D:$D, "Out Ports") + SUMIFS(GeneralWI!$L:$L, GeneralWI!$B:$B, $A11, GeneralWI!$D:$D, "Out Ports") -> 317.49643 | D11: =ROUND((B11+C11),2) -> 677.94
A12: Dry Ginger | B12: =SUMIFS(Antigua!$L:$L, Antigua!$B:$B, $A12, Antigua!$D:$D, "London") + SUMIFS(Barbados!$L:$L, Barbados!$B:$B, $A12, Barbados!$D:$D, "London") + SUMIFS(Bermuda!$L:$L, Bermuda!$B:$B, $A12, Bermuda!$D:$D, "London") + SUMIFS(Carolina!$L:$L, Carolina!$B:$B, $A12, Carolina!$D:$D, "London") + SUMIFS(Jamaica!$L:$L, Jamaica!$B:$B, $A12, Jamaica!$D:$D, "London") + SUMIFS(Mountserat!$L:$L, Mountserat!$B:$B, $A12, Mountserat!$D:$D, "London") + SUMIFS(Nevis!$L:$L, Nevis!$B:$B, $A12, Nevis!$D:$D, "London") + SUMIFS(NewEngland!$J:$J, NewEngland!$A:$A, $A12, NewEngland!$B:$B, "London") + SUMIFS(StKitts!$L:$L, StKitts!$B:$B, $A12, StKitts!$D:$D, "London") + SUMIFS(GeneralWI!$L:$L, GeneralWI!$B:$B, $A12, GeneralWI!$D:$D, "London") -> 1018.8054 | C12: =SUMIFS(Antigua!$L:$L, Antigua!$B:$B, $A12, Antigua!$D:$D, "Out Ports") + SUMIFS(Barbados!$L:$L, Barbados!$B:$B, $A12, Barbados!$D:$D, "Out Ports") + SUMIFS(Bermuda!$L:$L, Bermuda!$B:$B, $A12, Bermuda!$D:$D, "Out Ports") + SUMIFS(Carolina!$L:$L, Carolina!$B:$B, $A12, Carolina!$D:$D, "Out Ports") + SUMIFS(Jamaica!$L:$L, Jamaica!$B:$B, $A12, Jamaica!$D:$D, "Out Ports") + SUMIFS(Mountserat!$L:$L, Mountserat!$B:$B, $A12, Mountserat!$D:$D, "Out Ports") + SUMIFS(Nevis!$L:$L, Nevis!$B:$B, $A12, Nevis!$D:$D, "Out Ports") + SUMIFS(NewEngland!$J:$J, NewEngland!$A:$A, $A12, NewEngland!$B:$B, "Out Ports") + SUMIFS(StKitts!$L:$L, StKitts!$B:$B, $A12, StKitts!$D:$D, "Out Ports") + SUMIFS(GeneralWI!$L:$L, GeneralWI!$B:$B, $A12, GeneralWI!$D:$D, "Out Ports") -> 226.59866 | D12: =ROUND((B12+C12),2) -> 1245.4
A13: Elephant Teeth | B13: =SUMIFS(Antigua!$L:$L, Antigua!$B:$B, $A13, Antigua!$D:$D, "London") + SUMIFS(Barbados!$L:$L, Barbados!$B:$B, $A13, Barbados!$D:$D, "London") + SUMIFS(Bermuda!$L:$L, Bermuda!$B:$B, $A13, Bermuda!$D:$D, "London") + SUMIFS(Carolina!$L:$L, Carolina!$B:$B, $A13, Carolina!$D:$D, "London") + SUMIFS(Jamaica!$L:$L, Jamaica!$B:$B, $A13, Jamaica!$D:$D, "London") + SUMIFS(Mountserat!$L:$L, Mountserat!$B:$B, $A13, Mountserat!$D:$D, "London") + SUMIFS(Nevis!$L:$L, Nevis!$B:$B, $A13, Nevis!$D:$D, "London") + SUMIFS(NewEngland!$J:$J, NewEngland!$A:$A, $A13, NewEngland!$B:$B, "London") + SUMIFS(StKitts!$L:$L, StKitts!$B:$B, $A13, StKitts!$D:$D, "London") + SUMIFS(GeneralWI!$L:$L, GeneralWI!$B:$B, $A13, GeneralWI!$D:$D, "London") -> 47.051786 | C13: =SUMIFS(Antigua!$L:$L, Antigua!$B:$B, $A13, Antigua!$D:$D, "Out Ports") + SUMIFS(Barbados!$L:$L, Barbados!$B:$B, $A13, Barbados!$D:$D, "Out Ports") + SUMIFS(Bermuda!$L:$L, Bermuda!$B:$B, $A13, Bermuda!$D:$D, "Out Ports") + SUMIFS(Carolina!$L:$L, Carolina!$B:$B, $A13, Carolina!$D:$D, "Out Ports") + SUMIFS(Jamaica!$L:$L, Jamaica!$B:$B, $A13, Jamaica!$D:$D, "Out Ports") + SUMIFS(Mountserat!$L:$L, Mountserat!$B:$B, $A13, Mountserat!$D:$D, "Out Ports") + SUMIFS(Nevis!$L:$L, Nevis!$B:$B, $A13, Nevis!$D:$D, "Out Ports") + SUMIFS(NewEngland!$J:$J, NewEngland!$A:$A, $A13, NewEngland!$B:$B, "Out Ports") + SUMIFS(StKitts!$L:$L, StKitts!$B:$B, $A13, StKitts!$D:$D, "Out Ports") + SUMIFS(GeneralWI!$L:$L, GeneralWI!$B:$B, $A13, GeneralWI!$D:$D, "Out Ports") -> 14.426786 | D13: =ROUND((B13+C13),2) -> 61.48
... A31: Madera Wine | B31: =SUMIFS(Antigua!$L:$L, Antigua!$B:$B, $A31, Antigua!$D:$D, "London") + SUMIFS(Barbados!$L:$L, Barbados!$B:$B, $A31, Barbados!$D:$D, "London") + SUMIFS(Bermuda!$L:$L, Bermuda!$B:$B, $A31, Bermuda!$D:$D, "London") + SUMIFS(Carolina!$L:$L, Carolina!$B:$B, $A31, Carolina!$D:$D, "London") + SUMIFS(Jamaica!$L:$L, Jamaica!$B:$B, $A31, Jamaica!$D:$D, "London") + SUMIFS(Mountserat!$L:$L, Mountserat!$B:$B, $A31, Mountserat!$D:$D, "London") + SUMIFS(Nevis!$L:$L, Nevis!$B:$B, $A31, Nevis!$D:$D, "London") + SUMIFS(NewEngland!$J:$J, NewEngland!$A:$A, $A31, NewEngland!$B:$B, "London") + SUMIFS(StKitts!$L:$L, StKitts!$B:$B, $A31, StKitts!$D:$D, "London") + SUMIFS(GeneralWI!$L:$L, GeneralWI!$B:$B, $A31, GeneralWI!$D:$D, "London") -> 69.877679 | C31: =SUMIFS(Antigua!$L:$L, Antigua!$B:$B, $A31, Antigua!$D:$D, "Out Ports") + SUMIFS(Barbados!$L:$L, Barbados!$B:$B, $A31, Barbados!$D:$D, "Out Ports") + SUMIFS(Bermuda!$L:$L, Bermuda!$B:$B, $A31, Bermuda!$D:$D, "Out Ports") + SUMIFS(Carolina!$L:$L, Carolina!$B:$B, $A31, Carolina!$D:$D, "Out Ports") + SUMIFS(Jamaica!$L:$L, Jamaica!$B:$B, $A31, Jamaica!$D:$D, "Out Ports") + SUMIFS(Mountserat!$L:$L, Mountserat!$B:$B, $A31, Mountserat!$D:$D, "Out Ports") + SUMIFS(Nevis!$L:$L, Nevis!$B:$B, $A31, Nevis!$D:$D, "Out Ports") + SUMIFS(NewEngland!$J:$J, NewEngland!$A:$A, $A31, NewEngland!$B:$B, "Out Ports") + SUMIFS(StKitts!$L:$L, StKitts!$B:$B, $A31, StKitts!$D:$D, "Out Ports") + SUMIFS(GeneralWI!$L:$L, GeneralWI!$B:$B, $A31, GeneralWI!$D:$D, "Out Ports") -> 5.4973214 | D31: =ROUND((B31+C31),2) -> 75.38

Sheet Africa
A1: Items | B1: Import Location | C1: 1700 Ton | D1: 1700 hh | E1: 1700 quarter | F1: 1700 Stone/lb | G1: Total Pounds | I1: Total Tons

Sheet Canaries
A1: Items | B1: Import Location | C1: 1700 Ton | D1: 1700 hh | E1: 1700 quarter | F1: 1700 lb | G1: Total Pounds | I1: Total Tons

Sheet Antigua
A1: YEAR | B1: COMMODITY_NAME | C1: FROM_LOCATION | D1: TO_LOCATION | E1: ton | F1: hh | G1: quarter | H1: lb | J1: Total Pounds | L1: WEIGHT | N1: Not Sugar | O1: Sugar
A2: 1720 | B2: Annatto | C2: Antigua | D2: London | H2: 13048 | J2: =(E2*2240)+(F2*112)+(G2*28)+H2 -> 13048 | L2: =J2/2240 -> 5.825
A3: 1720 | B3: Brown Sugar | C3: Antigua | D3: London | F3: 90791 | G3: 1 | H3: 1 | J3: =(E3*2240)+(F3*112)+(G3*28)+H3 -> 10168621 | L3: =J3/2240 -> 4539.5629
A4: 1720 | B4: Chocolate | C4: Antigua | D4: London | H4: 40 | J4: =(E4*2240)+(F4*112)+(G4*28)+H4 -> 40 | L4: =J4/2240 -> 0.017857143
A5: 1720 | B5: Cocoa Nuts | C5: Antigua | D5: London | F5: 32 | G5: 4 | H5: 10 | J5: =(E5*2240)+(F5*112)+(G5*28)+H5 -> 3706 | L5: =J5/2240 -> 1.6544643
A6: 1720 | B6: Cotton | C6: Antigua | D6: London | H6: 223400 | J6: =(E6*2240)+(F6*112)+(G6*28)+H6 -> 223400 | L6: =J6/2240 -> 99.732143
A7: 1720 | B7: Dry Ginger | C7: Antigua | D7: London | F7: 899 | G7: 1 | H7: 9 | J7: =(E7*2240)+(F7*112)+(G7*28)+H7 -> 100725 | L7: =J7/2240 -> 44.966518
A8: 1720 | B8: Elephant Teeth | C8: Antigua | D8: London | F8: 9 | G8: 2 | H8: 7 | J8: =(E8*2240)+(F8*112)+(G8*28)+H8 -> 1071 | L8: =J8/2240 -> 0.478125 | N8: =L8+L10+L14+L16+L17+L18+L19+L22+L24+L33+L34+L35+L41+L42+L43+L45+L46+L50 -> 69.969643 | O8: =L11+L12+L13+L36+L37+L38 -> 17.65
A9: 1720 | B9: Indigo | C9: Antigua | D9: London | J9: =(E9*2240)+(F9*112)+(G9*28)+H9 -> 0 | L9: =J9/2240 -> 0
A10: 1720 | B10: Lemon Water | C10: Antigua | D10: London | J10: =(E10*2240)+(F10*112)+(G10*28)+H10 -> 0 | L10: =J10/2240 -> 0
A11: 1720 | B11: Lignum Vitae | C11: Antigua | D11: London | F11: 24 | H11: 17 | J11: =(E11*2240)+(F11*112)+(G11*28)+H11 -> 2705 | L11: =J11/2240 -> 1.2075893
A12: 1720 | B12: Lime Juice | C12: Antigua | D12: London | H12: 1070 | I12: 107g | J12: =(E12*2240)+(F12*112)+(G12*28)+H12 -> 1070 | L12: =J12/2240 -> 0.47767857
A13: 1720 | B13: Madera Wine | C13: Antigua | D13: London | H13: 16824 | I13: 0.25189815 | J13: =(E13*2240)+(F13*112)+(G13*28)+H13 -> 16824 | L13: =J13/2240 -> 7.5107143
A14: 1720 | B14: Molasses | C14: Antigua | D14: London | J14: =(E14*2240)+(F14*112)+(G14*28)+H14 -> 0 | L14: =J14/2240 -> 0
A15: 1720 | B15: Pickles | C15: Antigua | D15: London | F15: 1 | G15: 9 | J15: =(E15*2240)+(F15*112)+(G15*28)+H15 -> 364 | L15: =J15/2240 -> 0.1625
A16: 1720 | B16: Rice | C16: Antigua | D16: London | F16: 126 | G16: 3 | J16: =(E16*2240)+(F16*112)+(G16*28)+H16 -> 14196 | L16: =J16/2240 -> 6.3375
A17: 1720 | B17: Rum | C17: Antigua | D17: London | H17: 109726 | I17: 10872g | J17: =(E17*2240)+(F17*112)+(G17*28)+H17 -> 109726 | L17: =J17/2240 -> 48.984821
A18: 1720 | B18: Shruff | C18: Antigua | D18: London | F18: 39 | G18: 2 | H18: 4 | J18: =(E18*2240)+(F18*112)+(G18*28)+H18 -> 4428 | L18: =J18/2240 -> 1.9767857
A19: 1720 | B19: Succands | C19: Antigua | D19: London | H19: 230 | J19: =(E19*2240)+(F19*112)+(G19*28)+H19 -> 230 | L19: =J19/2240 -> 0.10267857
A20: 1720 | B20: Tobacco | C20: Antigua | D20: London | H20: 34 | J20: =(E20*2240)+(F20*112)+(G20*28)+H20 -> 34 | L20: =J20/2240 -> 0.015178571
A21: 1720 | B21: Tortoise Shell | C21: Antigua | D21: London | H21: 147 | J21: =(E21*2240)+(F21*112)+(G21*28)+H21 -> 147 | L21: =J21/2240 -> 0.065625
A22: 1720 | B22: White Sugar | C22: Antigua | D22: London | J22: =(E22*2240)+(F22*112)+(G22*28)+H22 -> 0 | L22: =J22/2240 -> 0
A23: 1720 | B23: Wood, Fustick | C23: Antigua | D23: London | E23: 11 | F23: 19 | H23: 4 | J23: =(E23*2240)+(F23*112)+(G23*28)+H23 -> 26772 | L23: =J23/2240 -> 11.951786
A24: 1720 | B24: Wood, Redwood | C24: Antigua | D24: London | F24: 7 | J24: =(E24*2240)+(F24*112)+(G24*28)+H24 -> 784 | L24: =J24/2240 -> 0.35
A25: 1720 | B25: Wood, Sweetwood | C25: Antigua | D25: London | F25: 14 | G25: 3 | J25: =(E25*2240)+(F25*112)+(G25*28)+H25 -> 1652 | L25: =J25/2240 -> 0.7375
A26: 1720 | B26: Annatto | C26: Antigua | D26: Out Ports | H26: 473 | J26: =(E26*2240)+(F26*112)+(G26*28)+H26 -> 473 | L26: =J26/2240 -> 0.21116071
A27: 1720 | B27: Brown Sugar | C27: Antigua | D27: Out Ports | F27: 22405 | G27: 3 | H27: 21 | J27: =(E27*2240)+(F27*112)+(G27*28)+H27 -> 2509465 | L27: =J27/2240 -> 1120.2969
A28: 1720 | B28: Cocoa | C28: Antigua | D28: Out Ports | J28: =(E28*2240)+(F28*112)+(G28*28)+H28 -> 0 | L28: =J28/2240 -> 0
A29: 1720 | B29: Cocoa Nuts | C29: Antigua | D29: Out Ports | G29: 1 | H29: 7 | J29: =(E29*2240)+(F29*112)+(G29*28)+H29 -> 35 | L29: =J29/2240 -> 0.015625
A30: 1720 | B30: Cotton | C30: Antigua | D30: Out Ports | H30: 183640 | J30: =(E30*2240)+(F30*112)+(G30*28)+H30 -> 183640 | L30: =J30/2240 -> 81.982143
A31: 1720 | B31: Dry Ginger | C31: Antigua | D31: Out Ports | F31: 138 | G31: 1 | H31: 1 | J31: =(E31*2240)+(F31*112)+(G31*28)+H31 -> 15485 | L31: =J31/2240 -> 6.9129464
A32: 1720 | B32: Indigo | C32: Antigua | D32: Out Ports | H32: 737 | J32: =(E32*2240)+(F32*112)+(G32*28)+H32 -> 737 | L32: =J32/2240 -> 0.32901786
A33: 1720 | B33: Lignum Vitae | C33: Antigua | D33: Out Ports | F33: 123 | G33: 1 | H33: 8 | J33: =(E33*2240)+(F33*112)+(G33*28)+H33 -> 13812 | L33: =J33/2240 -> 6.1660714
A34: 1720 | B34: Lime Juice | C34: Antigua | D34: Out Ports | H34: 11859 | I34: 1175g | J34: =(E34*2240)+(F34*112)+(G34*28)+H34 -> 11859 | L34: =J34/2240 -> 5.2941964
A35: 1720 | B35: Madera Wine | C35: Antigua | D35: Out Ports | H35: 626 | I35: 62g | J35: =(E35*2240)+(F35*112)+(G35*28)+H35 -> 626 | L35: =J35/2240 -> 0.27946429
A36: 1720 | B36: Molasses | C36: Antigua | D36: Out Ports | F36: 75 | J36: =(E36*2240)+(F36*112)+(G36*28)+H36 -> 8400 | L36: =J36/2240 -> 3.75
A37: 1720 | B37: Rice | C37: Antigua | D37: Out Ports | J37: =(E37*2240)+(F37*112)+(G37*28)+H37 -> 0 | L37: =J37/2240 -> 0
A38: 1720 | B38: Rum | C38: Antigua | D38: Out Ports | H38: 10537 | I38: 1044g | J38: =(E38*2240)+(F38*112)+(G38*28)+H38 -> 10537 | L38: =J38/2240 -> 4.7040179
A39: 1720 | B39: Shruff | C39: Antigua | D39: Out Ports | F39: 5 | H39: 25 | J39: =(E39*2240)+(F39*112)+(G39*28)+H39 -> 585 | L39: =J39/2240 -> 0.26116071
A40: 1720 | B40: Succands | C40: Antigua | D40: Out Ports | H40: 20 | J40: =(E40*2240)+(F40*112)+(G40*28)+H40 -> 20 | L40: =J40/2240 -> 0.0089285714
...

Sheet Barbados
A1: YEAR | B1: COMMODITY_NAME | C1: FROM_LOCATION | D1: TO_LOCATION | E1: ton | F1: hh | G1: quarter | H1: lb | J1: Total Pounds | L1: WEIGHT
A2: 1720 | B2: Aloes Epatica | C2: Barbados | D2: London | H2: 4985 | J2: =(E2*2240)+(F2*112)+(G2*28)+H2 -> 4985 | L2: =J2/2240 -> 2.2254464
A3: 1720 | B3: Annatto | C3: Barbados | D3: London | J3: =(E3*2240)+(F3*112)+(G3*28)+H3 -> 0 | L3: =J3/2240 -> 0
A4: 1720 | B4: Barrel Staves | C4: Barbados | D4: London | J4: =(E4*2240)+(F4*112)+(G4*28)+H4 -> 0 | L4: =J4/2240 -> 0
A5: 1720 | B5: Brown Sugar | C5: Barbados | D5: London | F5: 180588 | G5: 1 | H5: 24 | J5: =(E5*2240)+(F5*112)+(G5*28)+H5 -> 20225908 | L5: =J5/2240 -> 9029.4232
A6: 1720 | B6: Chocolate | C6: Barbados | D6: London | H6: 14 | J6: =(E6*2240)+(F6*112)+(G6*28)+H6 -> 14 | L6: =J6/2240 -> 0.00625
A7: 1720 | B7: Cocheneal | C7: Barbados | D7: London | J7: =(E7*2240)+(F7*112)+(G7*28)+H7 -> 0 | L7: =J7/2240 -> 0
A8: 1720 | B8: Cocoa Nuts | C8: Barbados | D8: London | F8: 156 | G8: 2 | H8: 13 | J8: =(E8*2240)+(F8*112)+(G8*28)+H8 -> 17541 | L8: =J8/2240 -> 7.8308036
A9: 1720 | B9: Cocoa Paste | C9: Barbados | D9: London | J9: =(E9*2240)+(F9*112)+(G9*28)+H9 -> 0 | L9: =J9/2240 -> 0
A10: 1720 | B10: Cotton | C10: Barbados | D10: London | H10: =521*200 -> 104200 | I10: 521 Bags | J10: =(E10*2240)+(F10*112)+(G10*28)+H10 -> 104200 | L10: =J10/2240 -> 46.517857
A11: 1720 | B11: Dry Ginger | C11: Barbados | D11: London | F11: 6163 | G11: 2 | H11: 14 | J11: =(E11*2240)+(F11*112)+(G11*28)+H11 -> 690326 | L11: =J11/2240 -> 308.18125
A12: 1720 | B12: Elephant Teeth | C12: Barbados | D12: London | F12: 328 | G12: 2 | H12: 20 | J12: =(E12*2240)+(F12*112)+(G12*28)+H12 -> 36812 | L12: =J12/2240 -> 16.433929
A13: 1720 | B13: Green Ginger | C13: Barbados | D13: London | H13: 434 | J13: =(E13*2240)+(F13*112)+(G13*28)+H13 -> 434 | L13: =J13/2240 -> 0.19375
A14: 1720 | B14: Hemp | C14: Barbados | D14: London | J14: =(E14*2240)+(F14*112)+(G14*28)+H14 -> 0 | L14: =J14/2240 -> 0
A15: 1720 | B15: Indigo | C15: Barbados | D15: London | H15: 2306 | J15: =(E15*2240)+(F15*112)+(G15*28)+H15 -> 2306 | L15: =J15/2240 -> 1.0294643
A16: 1720 | B16: Lemon Water | C16: Barbados | D16: London | J16: =(E16*2240)+(F16*112)+(G16*28)+H16 -> 0 | L16: =J16/2240 -> 0
A17: 1720 | B17: Lignum Vitae | C17: Barbados | D17: London | E17: 1 | F17: 2 | G17: 2 | H17: 14 | J17: =(E17*2240)+(F17*112)+(G17*28)+H17 -> 2534 | L17: =J17/2240 -> 1.13125
A18: 1720 | B18: Lime Juice | C18: Barbados | D18: London | H18: 49463 | I18: 4901g | J18: =(E18*2240)+(F18*112)+(G18*28)+H18 -> 49463 | L18: =J18/2240 -> 22.081696
A19: 1720 | B19: Loaf Sugar | C19: Barbados | D19: London | J19: =(E19*2240)+(F19*112)+(G19*28)+H19 -> 0 | L19: =J19/2240 -> 0
A20: 1720 | B20: Madera Wine | C20: Barbados | D20: London | H20: 92357 | I20: 1.5008796 | J20: =(E20*2240)+(F20*112)+(G20*28)+H20 -> 92357 | L20: =J20/2240 -> 41.230804
A21: 1720 | B21: Molasses | C21: Barbados | D21: London | J21: =(E21*2240)+(F21*112)+(G21*28)+H21 -> 0 | L21: =J21/2240 -> 0
A22: 1720 | B22: Oranges | C22: Barbados | D22: London | I22: 2560N | J22: =(E22*2240)+(F22*112)+(G22*28)+H22 -> 0 | L22: =J22/2240 -> 0
A23: 1720 | B23: Pickles | C23: Barbados | D23: London | F23: 24 | G23: 4 | J23: =(E23*2240)+(F23*112)+(G23*28)+H23 -> 2800 | L23: =J23/2240 -> 1.25
A24: 1720 | B24: Pimento | C24: Barbados | D24: London | J24: =(E24*2240)+(F24*112)+(G24*28)+H24 -> 0 | L24: =J24/2240 -> 0
A25: 1720 | B25: Rice | C25: Barbados | D25: London | F25: 776 | G25: 2 | H25: 25 | J25: =(E25*2240)+(F25*112)+(G25*28)+H25 -> 86993 | L25: =J25/2240 -> 38.836161
A26: 1720 | B26: Rum | C26: Barbados | D26: London | H26: 216380 | I26: 21439.5g | J26: =(E26*2240)+(F26*112)+(G26*28)+H26 -> 216380 | L26: =J26/2240 -> 96.598214
A27: 1720 | B27: Shruff | C27: Barbados | D27: London | F27: 183 | G27: 3 | J27: =(E27*2240)+(F27*112)+(G27*28)+H27 -> 20580 | L27: =J27/2240 -> 9.1875
A28: 1720 | B28: Snuff | C28: Barbados | D28: London | H28: 100 | J28: =(E28*2240)+(F28*112)+(G28*28)+H28 -> 100 | L28: =J28/2240 -> 0.044642857
A29: 1720 | B29: Succands | C29: Barbados | D29: London | H29: 1426 | J29: =(E29*2240)+(F29*112)+(G29*28)+H29 -> 1426 | L29: =J29/2240 -> 0.63660714
A30: 1720 | B30: Tobacco | C30: Barbados | D30: London | H30: 4345 | J30: =(E30*2240)+(F30*112)+(G30*28)+H30 -> 4345 | L30: =J30/2240 -> 1.9397321
A31: 1720 | B31: Tortoise Shell | C31: Barbados | D31: London | H31: 195 | J31: =(E31*2240)+(F31*112)+(G31*28)+H31 -> 195 | L31: =J31/2240 -> 0.087053571
A32: 1720 | B32: White Sugar | C32: Barbados | D32: London | F32: 18 | J32: =(E32*2240)+(F32*112)+(G32*28)+H32 -> 2016 | L32: =J32/2240 -> 0.9
A33: 1720 | B33: Wood, Braziletto | C33: Barbados | D33: London | E33: 41 | F33: 2 | G33: 3 | H33: 17 | J33: =(E33*2240)+(F33*112)+(G33*28)+H33 -> 92165 | L33: =J33/2240 -> 41.145089
A34: 1720 | B34: Wood, Fustick Wood | C34: Barbados | D34: London | E34: 96 | F34: 18 | G34: 2 | H34: 12 | J34: =(E34*2240)+(F34*112)+(G34*28)+H34 -> 217124 | L34: =J34/2240 -> 96.930357
A35: 1720 | B35: Wood, Logwood | C35: Barbados | D35: London | J35: =(E35*2240)+(F35*112)+(G35*28)+H35 -> 0 | L35: =J35/2240 -> 0
A36: 1720 | B36: Wood, Redwood | C36: Barbados | D36: London | E36: 12 | F36: 11 | H36: 20 | J36: =(E36*2240)+(F36*112)+(G36*28)+H36 -> 28132 | L36: =J36/2240 -> 12.558929
A37: 1720 | B37: Aloes Epatica | C37: Barbados | D37: Out Ports | H37: 1443 | J37: =(E37*2240)+(F37*112)+(G37*28)+H37 -> 1443 | L37: =J37/2240 -> 0.64419643
A38: 1720 | B38: Annatto | C38: Barbados | D38: Out Ports | J38: =(E38*2240)+(F38*112)+(G38*28)+H38 -> 0 | L38: =J38/2240 -> 0
A39: 1720 | B39: Barrel Staves | C39: Barbados | D39: Out Ports | J39: =(E39*2240)+(F39*112)+(G39*28)+H39 -> 0 | L39: =J39/2240 -> 0
A40: 1720 | B40: Brown Sugar | C40: Barbados | D40: Out Ports | F40: 25551 | G40: 1 | H40: 21 | J40: =(E40*2240)+(F40*112)+(G40*28)+H40 -> 2861761 | L40: =J40/2240 -> 1277.5719
...

Sheet Bermuda
A1: YEAR | B1: COMMODITY_NAME | C1: FROM_LOCATION | D1: TO_LOCATION | E1: ton | F1: hh | G1: quarter | H1: lb | J1: Total Pounds | L1: WEIGHT
A2: 1720 | B2: Indigo | C2: Bermuda | D2: Out Ports | H2: 229 | J2: =(E2*2240)+(F2*112)+(G2*28)+H2 -> 229 | L2: =J2/2240 -> 0.10223214
A3: 1720 | B3: Wood, Logwood | C3: Bermuda | D3: Out Ports | J3: =(E3*2240)+(F3*112)+(G3*28)+H3 -> 0 | L3: =J3/2240 -> 0
A4: 1720 | B4: Shruff | C4: Bermuda | D4: Out Ports | G4: 3 | H4: 22 | J4: =(E4*2240)+(F4*112)+(G4*28)+H4 -> 106 | L4: =J4/2240 -> 0.047321429
A5: 1720 | B5: Succands | C5: Bermuda | D5: Out Ports | J5: =(E5*2240)+(F5*112)+(G5*28)+H5 -> 0 | L5: =J5/2240 -> 0
A6: 1720 | B6: Cotton | C6: Bermuda | D6: Out Ports | J6: =(E6*2240)+(F6*112)+(G6*28)+H6 -> 0 | L6: =J6/2240 -> 0
A7: 1720 | B7: Cocoa Nuts | C7: Bermuda | D7: Out Ports | F7: 1 | H7: 10 | J7: =(E7*2240)+(F7*112)+(G7*28)+H7 -> 122 | L7: =J7/2240 -> 0.054464286
A8: 1720 | B8: Rice | C8: Bermuda | D8: Out Ports | F8: 118 | G8: 2 | H8: 22 | J8: =(E8*2240)+(F8*112)+(G8*28)+H8 -> 13294 | L8: =J8/2240 -> 5.9348214
A9: 1720 | B9: Brown Sugar | C9: Bermuda | D9: Out Ports | F9: 100 | J9: =(E9*2240)+(F9*112)+(G9*28)+H9 -> 11200 | L9: =J9/2240 -> 5
A10: 1720 | B10: Wood, Braziletto | C10: Bermuda | D10: Out Ports | E10: 19 | F10: 13 | H10: 20 | J10: =(E10*2240)+(F10*112)+(G10*28)+H10 -> 44036 | L10: =J10/2240 -> 19.658929
A11: 1720 | B11: Cotton | C11: Bermuda | D11: Out Ports | H11: 500 | J11: =(E11*2240)+(F11*112)+(G11*28)+H11 -> 500 | L11: =J11/2240 -> 0.22321429

Sheet Carolina
A1: YEAR | B1: COMMODITY_NAME | C1: FROM_LOCATION | D1: TO_LOCATION | E1: ton | F1: hh | G1: quarter | H1: lb | J1: Total Pounds | L1: WEIGHT
A2: 1720 | B2: Elephant Teeth | C2: Carolina | D2: London | F2: 73 | H2: 13 | J2: =(E2*2240)+(F2*112)+(G2*28)+H2 -> 8189 | L2: =J2/2240 -> 3.6558036
A3: 1720 | B3: Dry Ginger | C3: Carolina | D3: London | J3: =(E3*2240)+(F3*112)+(G3*28)+H3 -> 0 | L3: =J3/2240 -> 0
A4: 1720 | B4: Rice | C4: Carolina | D4: London | F4: 27951 | G4: 2 | H4: 17 | J4: =(E4*2240)+(F4*112)+(G4*28)+H4 -> 3130585 | L4: =J4/2240 -> 1397.5826
A5: 1720 | B5: Tobacco | C5: Carolina | D5: London | J5: =(E5*2240)+(F5*112)+(G5*28)+H5 -> 0 | L5: =J5/2240 -> 0
A6: 1720 | B6: Chocolate | C6: Carolina | D6: London | J6: =(E6*2240)+(F6*112)+(G6*28)+H6 -> 0 | L6: =J6/2240 -> 0
A7: 1720 | B7: Brown Sugar | C7: Carolina | D7: London | F7: 82 | G7: 1 | J7: =(E7*2240)+(F7*112)+(G7*28)+H7 -> 9212 | L7: =J7/2240 -> 4.1125
A8: 1720 | B8: Cocoa Nuts | C8: Carolina | D8: London | J8: =(E8*2240)+(F8*112)+(G8*28)+H8 -> 0 | L8: =J8/2240 -> 0
A9: 1720 | B9: Tortoise Shell | C9: Carolina | D9: London | J9: =(E9*2240)+(F9*112)+(G9*28)+H9 -> 0 | L9: =J9/2240 -> 0
A10: 1720 | B10: Bees Wax | C10: Carolina | D10: London | J10: =(E10*2240)+(F10*112)+(G10*28)+H10 -> 0 | L10: =J10/2240 -> 0
A11: 1720 | B11: Braziletto Wood | C11: Carolina | D11: London | J11: =(E11*2240)+(F11*112)+(G11*28)+H11 -> 0 | L11: =J11/2240 -> 0
A12: 1720 | B12: Logwood | C12: Carolina | D12: London | J12: =(E12*2240)+(F12*112)+(G12*28)+H12 -> 0 | L12: =J12/2240 -> 0
A13: 1720 | B13: Lignum Vitae | C13: Carolina | D13: London | J13: =(E13*2240)+(F13*112)+(G13*28)+H13 -> 0 | L13: =J13/2240 -> 0
A14: 1720 | B14: Rum | C14: Carolina | D14: London | J14: =(E14*2240)+(F14*112)+(G14*28)+H14 -> 0 | L14: =J14/2240 -> 0
A15: 1720 | B15: Cortex Winteranus | C15: Carolina | D15: Out Ports | J15: =(E15*2240)+(F15*112)+(G15*28)+H15 -> 0 | L15: =J15/2240 -> 0
A16: 1720 | B16: Elephant Teeth | C16: Carolina | D16: Out Ports | J16: =(E16*2240)+(F16*112)+(G16*28)+H16 -> 0 | L16: =J16/2240 -> 0
A17: 1720 | B17: Indigo | C17: Carolina | D17: Out Ports | J17: =(E17*2240)+(F17*112)+(G17*28)+H17 -> 0 | L17: =J17/2240 -> 0
A18: 1720 | B18: Rice | C18: Carolina | D18: Out Ports | J18: =(E18*2240)+(F18*112)+(G18*28)+H18 -> 0 | L18: =J18/2240 -> 0
A19: 1720 | B19: Brown Sugar | C19: Carolina | D19: Out Ports | J19: =(E19*2240)+(F19*112)+(G19*28)+H19 -> 0 | L19: =J19/2240 -> 0
... A23: 1720 | B23: Lime Juice | C23: Carolina | D23: Out Ports | J23: =(E23*2240)+(F23*112)+(G23*28)+H23 -> 0 | L23: =J23/2240 -> 0

Sheet Jamaica
A1: YEAR | B1: COMMODITY_NAME | C1: FROM_LOCATION | D1: TO_LOCATION | E1: ton | F1: hh | G1: quarter | H1: lb | J1: Total Pounds | L1: WEIGHT | O1: Total Not Sugar | Q1: Total Sugar
A2: 1720 | B2: Annatto | C2: Jamaica | D2: London | H2: 1343 | J2: =(E2*2240)+(F2*112)+(G2*28)+H2 -> 1343 | L2: =J2/2240 -> 0.59955357
A3: 1720 | B3: Bees Wax | C3: Jamaica | D3: London | J3: =(E3*2240)+(F3*112)+(G3*28)+H3 -> 0 | L3: =J3/2240 -> 0
A4: 1720 | B4: Brown Sugar | C4: Jamaica | D4: London | F4: 143675 | G4: 2 | H4: 18 | J4: =(E4*2240)+(F4*112)+(G4*28)+H4 -> 16091674 | L4: =J4/2240 -> 7183.783
A5: 1720 | B5: Cascarilla | C5: Jamaica | D5: London | H5: 2946 | J5: =(E5*2240)+(F5*112)+(G5*28)+H5 -> 2946 | L5: =J5/2240 -> 1.3151786
A6: 1720 | B6: Chocolate | C6: Jamaica | D6: London | J6: =(E6*2240)+(F6*112)+(G6*28)+H6 -> 0 | L6: =J6/2240 -> 0
A7: 1720 | B7: Cocheneal | C7: Jamaica | D7: London | H7: 383 | J7: =(E7*2240)+(F7*112)+(G7*28)+H7 -> 383 | L7: =J7/2240 -> 0.17098214
A8: 1720 | B8: Cocoa Nuts | C8: Jamaica | D8: London | F8: 102 | G8: 2 | H8: 16 | J8: =(E8*2240)+(F8*112)+(G8*28)+H8 -> 11496 | L8: =J8/2240 -> 5.1321429
A9: 1720 | B9: Cocoa Paste | C9: Jamaica | D9: London | J9: =(E9*2240)+(F9*112)+(G9*28)+H9 -> 0 | L9: =J9/2240 -> 0
A10: 1720 | B10: Cocoa Wood | C10: Jamaica | D10: London | J10: =(E10*2240)+(F10*112)+(G10*28)+H10 -> 0 | L10: =J10/2240 -> 0
A11: 1720 | B11: Cotton | C11: Jamaica | D11: London | H11: =1965*200 -> 393000 | I11: 1965 Bags | J11: =(E11*2240)+(F11*112)+(G11*28)+H11 -> 393000 | L11: =J11/2240 -> 175.44643
A12: 1720 | B12: Dry Ginger | C12: Jamaica | D12: London | F12: 12705 | G12: 1 | H12: 10 | J12: =(E12*2240)+(F12*112)+(G12*28)+H12 -> 1422998 | L12: =J12/2240 -> 635.26696
A13: 1720 | B13: Elephant Teeth | C13: Jamaica | D13: London | F13: 503 | G13: 2 | H13: 10 | J13: =(E13*2240)+(F13*112)+(G13*28)+H13 -> 56402 | L13: =J13/2240 -> 25.179464
A14: 1720 | B14: Indigo | C14: Jamaica | D14: London | H14: =60277+91641 -> 151918 | J14: =(E14*2240)+(F14*112)+(G14*28)+H14 -> 151918 | L14: =J14/2240 -> 67.820536
A15: 1720 | B15: Jamaica Roots | C15: Jamaica | D15: London | J15: =(E15*2240)+(F15*112)+(G15*28)+H15 -> 0 | L15: =J15/2240 -> 0
A16: 1720 | B16: Lignum Vitae | C16: Jamaica | D16: London | F16: 17 | G16: 3 | J16: =(E16*2240)+(F16*112)+(G16*28)+H16 -> 1988 | L16: =J16/2240 -> 0.8875
A17: 1720 | B17: Lime Juice | C17: Jamaica | D17: London | H17: 83829 | I17: 8306g | J17: =(E17*2240)+(F17*112)+(G17*28)+H17 -> 83829 | L17: =J17/2240 -> 37.423661
A18: 1720 | B18: Madera Wine | C18: Jamaica | D18: London | H18: 36384 | I18: 0.58418981 | J18: =(E18*2240)+(F18*112)+(G18*28)+H18 -> 36384 | L18: =J18/2240 -> 16.242857
A19: 1720 | B19: Molasses | C19: Jamaica | D19: London | F19: 2 | G19: 2 | H19: 14 | J19: =(E19*2240)+(F19*112)+(G19*28)+H19 -> 294 | L19: =J19/2240 -> 0.13125
A20: 1720 | B20: Pimento | C20: Jamaica | D20: London | H20: 182964 | J20: =(E20*2240)+(F20*112)+(G20*28)+H20 -> 182964 | L20: =J20/2240 -> 81.680357
A21: 1720 | B21: Rice | C21: Jamaica | D21: London | F21: 3 | G21: 1 | H21: 14 | J21: =(E21*2240)+(F21*112)+(G21*28)+H21 -> 378 | L21: =J21/2240 -> 0.16875
A22: 1720 | B22: Rum | C22: Jamaica | D22: London | H22: 260923 | I22: 25853g | J22: =(E22*2240)+(F22*112)+(G22*28)+H22 -> 260923 | L22: =J22/2240 -> 116.48348
A23: 1720 | B23: Sasparilla | C23: Jamaica | D23: London | H23: 48716 | J23: =(E23*2240)+(F23*112)+(G23*28)+H23 -> 48716 | L23: =J23/2240 -> 21.748214
A24: 1720 | B24: Shruff | C24: Jamaica | D24: London | F24: 130 | G24: 1 | H24: 3 | J24: =(E24*2240)+(F24*112)+(G24*28)+H24 -> 14591 | L24: =J24/2240 -> 6.5138393
A25: 1720 | B25: Snuff | C25: Jamaica | D25: London | H25: 3 | J25: =(E25*2240)+(F25*112)+(G25*28)+H25 -> 3 | L25: =J25/2240 -> 0.0013392857
A26: 1720 | B26: Succands | C26: Jamaica | D26: London | H26: 1311 | J26: =(E26*2240)+(F26*112)+(G26*28)+H26 -> 1311 | L26: =J26/2240 -> 0.58526786
A27: 1720 | B27: Sugar Loaf | C27: Jamaica | D27: London | J27: =(E27*2240)+(F27*112)+(G27*28)+H27 -> 0 | L27: =J27/2240 -> 0
A28: 1720 | B28: Tobacco | C28: Jamaica | D28: London | H28: 52 | J28: =(E28*2240)+(F28*112)+(G28*28)+H28 -> 52 | L28: =J28/2240 -> 0.023214286
A29: 1720 | B29: Tortoise Shell | C29: Jamaica | D29: London | H29: 4202 | J29: =(E29*2240)+(F29*112)+(G29*28)+H29 -> 4202 | L29: =J29/2240 -> 1.8758929
A30: 1720 | B30: White Sugar | C30: Jamaica | D30: London | J30: =(E30*2240)+(F30*112)+(G30*28)+H30 -> 0 | L30: =J30/2240 -> 0
A31: 1720 | B31: Wood, Braziletto | C31: Jamaica | D31: London | E31: 9 | F31: 5 | H31: 22 | J31: =(E31*2240)+(F31*112)+(G31*28)+H31 -> 20742 | L31: =J31/2240 -> 9.2598214
A32: 1720 | B32: Wood, Fustick | C32: Jamaica | D32: London | E32: 157 | F32: 6 | H32: 6 | J32: =(E32*2240)+(F32*112)+(G32*28)+H32 -> 352358 | L32: =J32/2240 -> 157.30268
A33: 1720 | B33: Wood, Logwood | C33: Jamaica | D33: London | E33: 237 | F33: 6 | G33: 3 | H33: 6 | J33: =(E33*2240)+(F33*112)+(G33*28)+H33 -> 531642 | L33: =J33/2240 -> 237.34018
A34: 1720 | B34: Wood, Nicaragua | C34: Jamaica | D34: London | E34: 54 | F34: 5 | G34: 1 | H34: 10 | J34: =(E34*2240)+(F34*112)+(G34*28)+H34 -> 121558 | L34: =J34/2240 -> 54.266964
A35: 1720 | B35: Wood, Redwood | C35: Jamaica | D35: London | E35: 38 | F35: 5 | J35: =(E35*2240)+(F35*112)+(G35*28)+H35 -> 85680 | L35: =J35/2240 -> 38.25
A36: 1720 | B36: Wool Vigonia | C36: Jamaica | D36: London | J36: =(E36*2240)+(F36*112)+(G36*28)+H36 -> 0 | L36: =J36/2240 -> 0
A37: 1720 | B37: Brown Sugar | C37: Jamaica | D37: Out Ports | F37: 65899 | G37: 3 | H37: 27 | J37: =(E37*2240)+(F37*112)+(G37*28)+H37 -> 7380799 | L37: =J37/2240 -> 3294.9996
A38: 1720 | B38: Chocolate | C38: Jamaica | D38: Out Ports | J38: =(E38*2240)+(F38*112)+(G38*28)+H38 -> 0 | L38: =J38/2240 -> 0
A39: 1720 | B39: Cocoa Nuts | C39: Jamaica | D39: Out Ports | F39: 28 | G39: 1 | H39: 14 | J39: =(E39*2240)+(F39*112)+(G39*28)+H39 -> 3178 | L39: =J39/2240 -> 1.41875
A40: 1720 | B40: Cocoa Wood | C40: Jamaica | D40: Out Ports | J40: =(E40*2240)+(F40*112)+(G40*28)+H40 -> 0 | L40: =J40/2240 -> 0
...

Sheet Mountserat
A1: YEAR | B1: COMMODITY_NAME | C1: FROM_LOCATION | D1: TO_LOCATION | E1: ton | F1: hh | G1: quarter | H1: lb | J1: Total Pounds | L1: WEIGHT
A2: 1720 | B2: Brown Sugar | C2: Mountserat | D2: London | F2: 16363 | G2: 3 | H2: 9 | J2: =(E2*2240)+(F2*112)+(G2*28)+H2 -> 1832749 | L2: =J2/2240 -> 818.19152
A3: 1720 | B3: Chocolate | C3: Mountserat | D3: London | J3: =(E3*2240)+(F3*112)+(G3*28)+H3 -> 0 | L3: =J3/2240 -> 0
A4: 1720 | B4: Cocoa Nuts | C4: Mountserat | D4: London | J4: =(E4*2240)+(F4*112)+(G4*28)+H4 -> 0 | L4: =J4/2240 -> 0
A5: 1720 | B5: Cortex Winteranus | C5: Mountserat | D5: London | J5: =(E5*2240)+(F5*112)+(G5*28)+H5 -> 0 | L5: =J5/2240 -> 0
A6: 1720 | B6: Cotton | C6: Mountserat | D6: London | H6: =47*200 -> 9400 | I6: 47 Bags | J6: =(E6*2240)+(F6*112)+(G6*28)+H6 -> 9400 | L6: =J6/2240 -> 4.1964286
A7: 1720 | B7: Dry Ginger | C7: Mountserat | D7: London | J7: =(E7*2240)+(F7*112)+(G7*28)+H7 -> 0 | L7: =J7/2240 -> 0
A8: 1720 | B8: Elephants Teeth | C8: Mountserat | D8: London | J8: =(E8*2240)+(F8*112)+(G8*28)+H8 -> 0 | L8: =J8/2240 -> 0
A9: 1720 | B9: Indigo | C9: Mountserat | D9: London | H9: 7841 | J9: =(E9*2240)+(F9*112)+(G9*28)+H9 -> 7841 | L9: =J9/2240 -> 3.5004464
A10: 1720 | B10: Lignum Vitae | C10: Mountserat | D10: London | J10: =(E10*2240)+(F10*112)+(G10*28)+H10 -> 0 | L10: =J10/2240 -> 0
A11: 1720 | B11: Lime Juice | C11: Mountserat | D11: London | J11: =(E11*2240)+(F11*112)+(G11*28)+H11 -> 0 | L11: =J11/2240 -> 0
A12: 1720 | B12: Madera Wine | C12: Mountserat | D12: London | J12: =(E12*2240)+(F12*112)+(G12*28)+H12 -> 0 | L12: =J12/2240 -> 0
A13: 1720 | B13: Molasses | C13: Mountserat | D13: London | J13: =(E13*2240)+(F13*112)+(G13*28)+H13 -> 0 | L13: =J13/2240 -> 0
A14: 1720 | B14: Pimento | C14: Mountserat | D14: London | J14: =(E14*2240)+(F14*112)+(G14*28)+H14 -> 0 | L14: =J14/2240 -> 0
A15: 1720 | B15: Rum | C15: Mountserat | D15: London | H15: 10809 | I15: 1071g | J15: =(E15*2240)+(F15*112)+(G15*28)+H15 -> 10809 | L15: =J15/2240 -> 4.8254464
A16: 1720 | B16: Shruff | C16: Mountserat | D16: London | F16: 10 | H16: 27 | J16: =(E16*2240)+(F16*112)+(G16*28)+H16 -> 1147 | L16: =J16/2240 -> 0.51205357
A17: 1720 | B17: Succands | C17: Mountserat | D17: London | J17: =(E17*2240)+(F17*112)+(G17*28)+H17 -> 0 | L17: =J17/2240 -> 0
A18: 1720 | B18: Tortoise Shell | C18: Mountserat | D18: London | J18: =(E18*2240)+(F18*112)+(G18*28)+H18 -> 0 | L18: =J18/2240 -> 0
A19: 1720 | B19: White Sugar | C19: Mountserat | D19: London | J19: =(E19*2240)+(F19*112)+(G19*28)+H19 -> 0 | L19: =J19/2240 -> 0
A20: 1720 | B20: Brown Sugar | C20: Mountserat | D20: Out Ports | F20: 10257 | G20: 3 | H20: 19 | J20: =(E20*2240)+(F20*112)+(G20*28)+H20 -> 1148887 | L20: =J20/2240 -> 512.89598
A21: 1720 | B21: Cocoa | C21: Mountserat | D21: Out Ports | J21: =(E21*2240)+(F21*112)+(G21*28)+H21 -> 0 | L21: =J21/2240 -> 0
A22: 1720 | B22: Cocoa Nuts | C22: Mountserat | D22: Out Ports | J22: =(E22*2240)+(F22*112)+(G22*28)+H22 -> 0 | L22: =J22/2240 -> 0
A23: 1720 | B23: Cotton | C23: Mountserat | D23: Out Ports | H23: 8832 | J23: =(E23*2240)+(F23*112)+(G23*28)+H23 -> 8832 | L23: =J23/2240 -> 3.9428571
A24: 1720 | B24: Dry Ginger | C24: Mountserat | D24: Out Ports | J24: =(E24*2240)+(F24*112)+(G24*28)+H24 -> 0 | L24: =J24/2240 -> 0
A25: 1720 | B25: Elephants Teeth | C25: Mountserat | D25: Out Ports | F25: 7 | H25: 24 | J25: =(E25*2240)+(F25*112)+(G25*28)+H25 -> 808 | L25: =J25/2240 -> 0.36071429
A26: 1720 | B26: Indigo | C26: Mountserat | D26: Out Ports | H26: 1766 | J26: =(E26*2240)+(F26*112)+(G26*28)+H26 -> 1766 | L26: =J26/2240 -> 0.78839286
A27: 1720 | B27: Lime Juice | C27: Mountserat | D27: Out Ports | H27: 1867 | I27: 185g | J27: =(E27*2240)+(F27*112)+(G27*28)+H27 -> 1867 | L27: =J27/2240 -> 0.83348214
A28: 1720 | B28: Pimento | C28: Mountserat | D28: Out Ports | J28: =(E28*2240)+(F28*112)+(G28*28)+H28 -> 0 | L28: =J28/2240 -> 0
A29: 1720 | B29: Rum | C29: Mountserat | D29: Out Ports | H29: 2119 | I29: 210g | J29: =(E29*2240)+(F29*112)+(G29*28)+H29 -> 2119 | L29: =J29/2240 -> 0.94598214
A30: 1720 | B30: Shruff | C30: Mountserat | D30: Out Ports | F30: 2 | G30: 3 | H30: 20 | J30: =(E30*2240)+(F30*112)+(G30*28)+H30 -> 328 | L30: =J30/2240 -> 0.14642857
A31: 1720 | B31: Wood, Redwood | C31: Mountserat | D31: Out Ports | E31: 4 | F31: 10 | J31: =(E31*2240)+(F31*112)+(G31*28)+H31 -> 10080 | L31: =J31/2240 -> 4.5

Sheet Nevis
A1: YEAR | B1: COMMODITY_NAME | C1: FROM_LOCATION | D1: TO_LOCATION | E1: ton | F1: hh | G1: quarter | H1: lb | J1: Total Pounds | L1: WEIGHT
A2: 1720 | B2: Brown Sugar | C2: Nevis | D2: London | F2: 37372 | G2: 2 | H2: 13 | J2: =(E2*2240)+(F2*112)+(G2*28)+(H2) -> 4185733 | L2: =J2/2240 -> 1868.6308
A3: 1720 | B3: Chocolate | C3: Nevis | D3: London | J3: =(E3*2240)+(F3*112)+(G3*28)+(H3) -> 0 | L3: =J3/2240 -> 0
A4: 1720 | B4: Cocoa Nuts | C4: Nevis | D4: London | J4: =(E4*2240)+(F4*112)+(G4*28)+(H4) -> 0 | L4: =J4/2240 -> 0
A5: 1720 | B5: Cortex Winteranus | C5: Nevis | D5: London | J5: =(E5*2240)+(F5*112)+(G5*28)+(H5) -> 0 | L5: =J5/2240 -> 0
A6: 1720 | B6: Cotton | C6: Nevis | D6: London | H6: =69*200 -> 13800 | I6: 69 Bags | J6: =(E6*2240)+(F6*112)+(G6*28)+(H6) -> 13800 | L6: =J6/2240 -> 6.1607143
A7: 1720 | B7: Elephant Teeth | C7: Nevis | D7: London | F7: 13 | G7: 3 | J7: =(E7*2240)+(F7*112)+(G7*28)+(H7) -> 1540 | L7: =J7/2240 -> 0.6875
A8: 1720 | B8: Indigo | C8: Nevis | D8: London | H8: 236 | J8: =(E8*2240)+(F8*112)+(G8*28)+(H8) -> 236 | L8: =J8/2240 -> 0.10535714
A9: 1720 | B9: Lignum Vitae | C9: Nevis | D9: London | J9: =(E9*2240)+(F9*112)+(G9*28)+(H9) -> 0 | L9: =J9/2240 -> 0
A10: 1720 | B10: Lime Juice | C10: Nevis | D10: London | J10: =(E10*2240)+(F10*112)+(G10*28)+(H10) -> 0 | L10: =J10/2240 -> 0
A11: 1720 | B11: Madera Wine | C11: Nevis | D11: London | H11: 4007 | I11: 0.043275463 | J11: =(E11*2240)+(F11*112)+(G11*28)+(H11) -> 4007 | L11: =J11/2240 -> 1.7888393
A12: 1720 | B12: Molasses | C12: Nevis | D12: London | J12: =(E12*2240)+(F12*112)+(G12*28)+(H12) -> 0 | L12: =J12/2240 -> 0
A13: 1720 | B13: Pickles | C13: Nevis | D13: London | J13: =(E13*2240)+(F13*112)+(G13*28)+(H13) -> 0 | L13: =J13/2240 -> 0
A14: 1720 | B14: Rum | C14: Nevis | D14: London | H14: 4945 | I14: 490g | J14: =(E14*2240)+(F14*112)+(G14*28)+(H14) -> 4945 | L14: =J14/2240 -> 2.2075893
A15: 1720 | B15: Shruff | C15: Nevis | D15: London | F15: 16 | H15: 21 | J15: =(E15*2240)+(F15*112)+(G15*28)+(H15) -> 1813 | L15: =J15/2240 -> 0.809375
A16: 1720 | B16: Succands | C16: Nevis | D16: London | H16: 9 | J16: =(E16*2240)+(F16*112)+(G16*28)+(H16) -> 9 | L16: =J16/2240 -> 0.0040178571
A17: 1720 | B17: Sugar Loaf | C17: Nevis | D17: London | J17: =(E17*2240)+(F17*112)+(G17*28)+(H17) -> 0 | L17: =J17/2240 -> 0
A18: 1720 | B18: Tobacco | C18: Nevis | D18: London | J18: =(E18*2240)+(F18*112)+(G18*28)+(H18) -> 0 | L18: =J18/2240 -> 0
A19: 1720 | B19: Tortoise Shell | C19: Nevis | D19: London | J19: =(E19*2240)+(F19*112)+(G19*28)+(H19) -> 0 | L19: =J19/2240 -> 0
A20: 1720 | B20: Tortoise Shell | C20: Nevis | D20: London | H20: 12 | J20: =(E20*2240)+(F20*112)+(G20*28)+(H20) -> 12 | L20: =J20/2240 -> 0.0053571429
A21: 1720 | B21: White Sugar | C21: Nevis | D21: London | J21: =(E21*2240)+(F21*112)+(G21*28)+(H21) -> 0 | L21: =J21/2240 -> 0
A22: 1720 | B22: Brown Sugar | C22: Nevis | D22: Out Ports | F22: 11633 | G22: 2 | H22: 27 | J22: =(E22*2240)+(F22*112)+(G22*28)+(H22) -> 1302979 | L22: =J22/2240 -> 581.68705
A23: 1720 | B23: Cocoa Nuts | C23: Nevis | D23: Out Ports | F23: 44 | G23: 3 | J23: =(E23*2240)+(F23*112)+(G23*28)+(H23) -> 5012 | L23: =J23/2240 -> 2.2375
A24: 1720 | B24: Cotton | C24: Nevis | D24: Out Ports | H24: 28020 | J24: =(E24*2240)+(F24*112)+(G24*28)+(H24) -> 28020 | L24: =J24/2240 -> 12.508929
A25: 1720 | B25: Elephant Teeth | C25: Nevis | D25: Out Ports | F25: 10 | G25: 1 | H25: 13 | J25: =(E25*2240)+(F25*112)+(G25*28)+(H25) -> 1161 | L25: =J25/2240 -> 0.51830357
A26: 1720 | B26: Indigo | C26: Nevis | D26: Out Ports | H26: 28 | J26: =(E26*2240)+(F26*112)+(G26*28)+(H26) -> 28 | L26: =J26/2240 -> 0.0125
A27: 1720 | B27: Lignum Vitae | C27: Nevis | D27: Out Ports | J27: =(E27*2240)+(F27*112)+(G27*28)+(H27) -> 0 | L27: =J27/2240 -> 0
A28: 1720 | B28: Lime Juice | C28: Nevis | D28: Out Ports | J28: =(E28*2240)+(F28*112)+(G28*28)+(H28) -> 0 | L28: =J28/2240 -> 0
A29: 1720 | B29: Madera Wine | C29: Nevis | D29: Out Ports | H29: 1232 | I29: 0.0013773148 | J29: =(E29*2240)+(F29*112)+(G29*28)+(H29) -> 1232 | L29: =J29/2240 -> 0.55
A30: 1720 | B30: Molasses | C30: Nevis | D30: Out Ports | J30: =(E30*2240)+(F30*112)+(G30*28)+(H30) -> 0 | L30: =J30/2240 -> 0
A31: 1720 | B31: Wood, Redwood | C31: Nevis | D31: Out Ports | E31: 3 | F31: 7 | H31: 17 | J31: =(E31*2240)+(F31*112)+(G31*28)+(H31) -> 7521 | L31: =J31/2240 -> 3.3575893
A32: 1720 | B32: Rum | C32: Nevis | D32: Out Ports | H32: 3230 | I32: 320g | J32: =(E32*2240)+(F32*112)+(G32*28)+(H32) -> 3230 | L32: =J32/2240 -> 1.4419643
A33: 1720 | B33: Shruff | C33: Nevis | D33: Out Ports | F33: 12 | H33: 14 | J33: =(E33*2240)+(F33*112)+(G33*28)+(H33) -> 1358 | L33: =J33/2240 -> 0.60625
A34: 1720 | B34: Succands | C34: Nevis | D34: Out Ports | H34: 11 | J34: =(E34*2240)+(F34*112)+(G34*28)+(H34) -> 11 | L34: =J34/2240 -> 0.0049107143
A35: 1720 | B35: Tortoise Shell | C35: Nevis | D35: Out Ports | J35: =(E35*2240)+(F35*112)+(G35*28)+(H35) -> 0 | L35: =J35/2240 -> 0

Sheet StKitts
A1: YEAR | B1: COMMODITY_NAME | C1: FROM_LOCATION | D1: TO_LOCATION | E1: ton | F1: hh | G1: quarter | H1: lb | J1: Total Pounds | L1: WEIGHT
A2: 1720 | B2: Annatto | C2: StKitts | D2: London | J2: =(E2*2240)+(F2*112)+(G2*28)+(H2) -> 0 | L2: =J2/2240 -> 0
A3: 1720 | B3: Bees Wax | C3: StKitts | D3: London | J3: =(E3*2240)+(F3*112)+(G3*28)+(H3) -> 0 | L3: =J3/2240 -> 0
A4: 1720 | B4: Brown Sugar | C4: StKitts | D4: London | F4: 73742 | G4: 1 | H4: 15 | J4: =(E4*2240)+(F4*112)+(G4*28)+(H4) -> 8259147 | L4: =J4/2240 -> 3687.1192
A5: 1720 | B5: Cocoa Nuts | C5: StKitts | D5: London | F5: 4 | G5: 2 | H5: 27 | J5: =(E5*2240)+(F5*112)+(G5*28)+(H5) -> 531 | L5: =J5/2240 -> 0.23705357
A6: 1720 | B6: Cotton | C6: StKitts | D6: London | H6: =290*200 -> 58000 | I6: 290 Bags | J6: =(E6*2240)+(F6*112)+(G6*28)+(H6) -> 58000 | L6: =J6/2240 -> 25.892857
A7: 1720 | B7: Dry Ginger | C7: StKitts | D7: London | F7: 4 | G7: 3 | H7: 7 | J7: =(E7*2240)+(F7*112)+(G7*28)+(H7) -> 539 | L7: =J7/2240 -> 0.240625
A8: 1720 | B8: Elephant Teeth | C8: StKitts | D8: London | F8: 12 | H8: 17 | J8: =(E8*2240)+(F8*112)+(G8*28)+(H8) -> 1361 | L8: =J8/2240 -> 0.60758929
A9: 1720 | B9: Indigo | C9: StKitts | D9: London | H9: 1408 | J9: =(E9*2240)+(F9*112)+(G9*28)+(H9) -> 1408 | L9: =J9/2240 -> 0.62857143
A10: 1720 | B10: Lignum Vitae | C10: StKitts | D10: London | E10: 5 | F10: 2 | G10: 3 | J10: =(E10*2240)+(F10*112)+(G10*28)+(H10) -> 11508 | L10: =J10/2240 -> 5.1375
A11: 1720 | B11: Lime Juice | C11: StKitts | D11: London | H11: 303 | I11: 30 g | J11: =(E11*2240)+(F11*112)+(G11*28)+(H11) -> 303 | L11: =J11/2240 -> 0.13526786
A12: 1720 | B12: Madera Wine | C12: StKitts | D12: London | H12: 6954 | I12: 0.085405093 | J12: =(E12*2240)+(F12*112)+(G12*28)+(H12) -> 6954 | L12: =J12/2240 -> 3.1044643
A13: 1720 | B13: Molasses | C13: StKitts | D13: London | J13: =(E13*2240)+(F13*112)+(G13*28)+(H13) -> 0 | L13: =J13/2240 -> 0
A14: 1720 | B14: Pimento | C14: StKitts | D14: London | J14: =(E14*2240)+(F14*112)+(G14*28)+(H14) -> 0 | L14: =J14/2240 -> 0
A15: 1720 | B15: Rice | C15: StKitts | D15: London | F15: 14 | H15: 7 | J15: =(E15*2240)+(F15*112)+(G15*28)+(H15) -> 1575 | L15: =J15/2240 -> 0.703125
A16: 1720 | B16: Rum | C16: StKitts | D16: London | H16: 22315 | I16: 2211 g | J16: =(E16*2240)+(F16*112)+(G16*28)+(H16) -> 22315 | L16: =J16/2240 -> 9.9620536
A17: 1720 | B17: Shruff | C17: StKitts | D17: London | F17: 20 | H17: 15 | J17: =(E17*2240)+(F17*112)+(G17*28)+(H17) -> 2255 | L17: =J17/2240 -> 1.0066964
A18: 1720 | B18: Succands | C18: StKitts | D18: London | H18: 186 | J18: =(E18*2240)+(F18*112)+(G18*28)+(H18) -> 186 | L18: =J18/2240 -> 0.083035714
A19: 1720 | B19: Tortoise Shells | C19: StKitts | D19: London | H19: 16 | J19: =(E19*2240)+(F19*112)+(G19*28)+(H19) -> 16 | L19: =J19/2240 -> 0.0071428571
A20: 1720 | B20: Wood, Fustick | C20: StKitts | D20: London | E20: 25 | F20: 5 | G20: 2 | J20: =(E20*2240)+(F20*112)+(G20*28)+(H20) -> 56616 | L20: =J20/2240 -> 25.275
A21: 1720 | B21: Wood, Logwood | C21: StKitts | D21: London | J21: =(E21*2240)+(F21*112)+(G21*28)+(H21) -> 0 | L21: =J21/2240 -> 0
A22: 1720 | B22: Wood, Redwood | C22: StKitts | D22: London | E22: 9 | F22: 19 | J22: =(E22*2240)+(F22*112)+(G22*28)+(H22) -> 22288 | L22: =J22/2240 -> 9.95
A23: 1720 | B23: Brown Sugar | C23: StKitts | D23: Out Ports | F23: 18191 | G23: 3 | H23: 20 | J23: =(E23*2240)+(F23*112)+(G23*28)+(H23) -> 2037496 | L23: =J23/2240 -> 909.59643
A24: 1720 | B24: Cotton | C24: StKitts | D24: Out Ports | H24: 73712 | J24: =(E24*2240)+(F24*112)+(G24*28)+(H24) -> 73712 | L24: =J24/2240 -> 32.907143
A25: 1720 | B25: Elephant Teeth | C25: StKitts | D25: Out Ports | F25: 18 | G25: 2 | H25: 10 | J25: =(E25*2240)+(F25*112)+(G25*28)+(H25) -> 2082 | L25: =J25/2240 -> 0.92946429
A26: 1720 | B26: Indigo | C26: StKitts | D26: Out Ports | H26: 1023 | J26: =(E26*2240)+(F26*112)+(G26*28)+(H26) -> 1023 | L26: =J26/2240 -> 0.45669643
A27: 1720 | B27: Rum | C27: StKitts | D27: Out Ports | H27: 146 | I27: 14.5g | J27: =(E27*2240)+(F27*112)+(G27*28)+(H27) -> 146 | L27: =J27/2240 -> 0.065178571
A28: 1720 | B28: Shruff | C28: StKitts | D28: Out Ports | F28: 2 | G28: 3 | H28: 4 | J28: =(E28*2240)+(F28*112)+(G28*28)+(H28) -> 312 | L28: =J28/2240 -> 0.13928571
A29: 1720 | B29: Swedish Iron | C29: StKitts | D29: Out Ports | E29: 2 | J29: =(E29*2240)+(F29*112)+(G29*28)+(H29) -> 4480 | L29: =J29/2240 -> 2

Sheet NewEngland
A1: Items | B1: Import Location | C1: ton | D1: hh | E1: quarter | F1: lb | H1: Total Pounds | J1: Total Tons
A2: Lignum Vitae | B2: London | H2: =(C2*2240)+(D2*112)+(E2*28)+F2 -> 0 | J2: =H2/2240 -> 0
A3: Braziletto Wood | B3: London | H3: =(C3*2240)+(D3*112)+(E3*28)+F3 -> 0 | J3: =H3/2240 -> 0
A4: Fustick Wood | B4: London | H4: =(C4*2240)+(D4*112)+(E4*28)+F4 -> 0 | J4: =H4/2240 -> 0
A5: Logwood | B5: London | H5: =(C5*2240)+(D5*112)+(E5*28)+F5 -> 0 | J5: =H5/2240 -> 0
A6: Cortex Winteranus | B6: London | H6: =(C6*2240)+(D6*112)+(E6*28)+F6 -> 0 | J6: =H6/2240 -> 0
A7: Turpentine Common | B7: London | H7: =(C7*2240)+(D7*112)+(E7*28)+F7 -> 0 | J7: =H7/2240 -> 0
A8: Dry Ginger | B8: London | H8: =(C8*2240)+(D8*112)+(E8*28)+F8 -> 0 | J8: =H8/2240 -> 0
A9: Molasses | B9: London | H9: =(C9*2240)+(D9*112)+(E9*28)+F9 -> 0 | J9: =H9/2240 -> 0
A10: Brown Sugar | B10: London | H10: =(C10*2240)+(D10*112)+(E10*28)+F10 -> 0 | J10: =H10/2240 -> 0
A11: White Sugar | B11: London | H11: =(C11*2240)+(D11*112)+(E11*28)+F11 -> 0 | J11: =H11/2240 -> 0
A12: Rice | B12: London | H12: =(C12*2240)+(D12*112)+(E12*28)+F12 -> 0 | J12: =H12/2240 -> 0
A13: Shruff | B13: London | H13: =(C13*2240)+(D13*112)+(E13*28)+F13 -> 0 | J13: =H13/2240 -> 0
... A34: Rum | B34: Out Ports | H34: =(C34*2240)+(D34*112)+(E34*28)+F34 -> 0 | J34: =H34/2240 -> 0

Sheet GeneralWI
A1: YEAR | B1: COMMODITY_NAME | C1: FROM_LOCATION | D1: TO_LOCATION | E1: ton | F1: hh | G1: quarter | H1: lb | J1: Total Pounds | L1: WEIGHT
A2: 1720 | B2: Annatto | C2: GeneralWI | D2: London | J2: =(E2*2240)+(F2*112)+(G2*28)+H2 -> 0 | L2: =J2/2240 -> 0
A3: 1720 | B3: Bees Wax | C3: GeneralWI | D3: London | J3: =(E3*2240)+(F3*112)+(G3*28)+H3 -> 0 | L3: =J3/2240 -> 0
A4: 1720 | B4: Wood, Braziletto | C4: GeneralWI | D4: London | J4: =(E4*2240)+(F4*112)+(G4*28)+H4 -> 0 | L4: =J4/2240 -> 0
A5: 1720 | B5: Brown Sugar | C5: GeneralWI | D5: London | F5: 3054 | G5: 2 | H5: 14 | J5: =(E5*2240)+(F5*112)+(G5*28)+H5 -> 342118 | L5: =J5/2240 -> 152.73125
A6: 1720 | B6: Cascarilla | C6: GeneralWI | D6: London
A7: 1720 | B7: Chocolate | C7: GeneralWI | D7: London | J7: =(E7*2240)+(F7*112)+(G7*28)+H7 -> 0 | L7: =J7/2240 -> 0
A8: 1720 | B8: Cocheneal | C8: GeneralWI | D8: London | J8: =(E8*2240)+(F8*112)+(G8*28)+H8 -> 0 | L8: =J8/2240 -> 0
A9: 1720 | B9: Cocoa Nuts | C9: GeneralWI | D9: London | J9: =(E9*2240)+(F9*112)+(G9*28)+H9 -> 0 | L9: =J9/2240 -> 0
A10: 1720 | B10: Cocoa Paste | C10: GeneralWI | D10: London | J10: =(E10*2240)+(F10*112)+(G10*28)+H10 -> 0 | L10: =J10/2240 -> 0
A11: 1720 | B11: Cocoa Wood | C11: GeneralWI | D11: London | J11: =(E11*2240)+(F11*112)+(G11*28)+H11 -> 0 | L11: =J11/2240 -> 0
A12: 1720 | B12: Cotton | C12: GeneralWI | D12: London | H12: =28*200 -> 5600 | I12: 28 bags | J12: =(E12*2240)+(F12*112)+(G12*28)+H12 -> 5600 | L12: =J12/2240 -> 2.5
A13: 1720 | B13: Dry Ginger | C13: GeneralWI | D13: London | F13: 603 | J13: =(E13*2240)+(F13*112)+(G13*28)+H13 -> 67536 | L13: =J13/2240 -> 30.15
A14: 1720 | B14: Elephant Teeth | C14: GeneralWI | D14: London | H14: 21 | J14: =(E14*2240)+(F14*112)+(G14*28)+H14 -> 21 | L14: =J14/2240 -> 0.009375
A15: 1720 | B15: Wood, Fustick | C15: GeneralWI | D15: London | J15: =(E15*2240)+(F15*112)+(G15*28)+H15 -> 0 | L15: =J15/2240 -> 0
A16: 1720 | B16: Indigo | C16: GeneralWI | D16: London | H16: 3000 | J16: =(E16*2240)+(F16*112)+(G16*28)+H16 -> 3000 | L16: =J16/2240 -> 1.3392857
