Workbook

Sheet Master Goods Sheet
A1: Item | B1: Total London | C1: Total Outports | D1: Total
A2: Annatto | B2: =SUMIFS(Antigua!$L:$L, Antigua!$B:$B, $A2, Antigua!$D:$D, "London") + SUMIFS(Barbados!$L:$L, Barbados!$B:$B, $A2, Barbados!$D:$D, "London") + SUMIFS(Bermuda!$L:$L, Bermuda!$B:$B, $A2, Bermuda!$D:$D, "London") + SUMIFS(Jamaica!$L:$L, Jamaica!$B:$B, $A2, Jamaica!$D:$D, "London") + SUMIFS(Mountserat!$L:$L, Mountserat!$B:$B, $A2, Mountserat!$D:$D, "London") + SUMIFS(Nevis!$L:$L, Nevis!$B:$B, $A2, Nevis!$D:$D, "London") + SUMIFS('St Kitts'!$L:$L, 'St Kitts'!$B:$B, $A2, 'St Kitts'!$D:$D, "London")+ SUMIFS(General!$L:$L, General!$B:$B, $A2, General!$D:$D, "London") -> 2.4946429 | C2: =SUMIFS(Antigua!$L:$L, Antigua!$B:$B, $A2, Antigua!$D:$D, "Out Ports") + SUMIFS(Barbados!$L:$L, Barbados!$B:$B, $A2, Barbados!$D:$D, "Out Ports") + SUMIFS(Bermuda!$L:$L, Bermuda!$B:$B, $A2, Bermuda!$D:$D, "Out Ports") + SUMIFS(Jamaica!$L:$L, Jamaica!$B:$B, $A2, Jamaica!$D:$D, "Out Ports") + SUMIFS(Mountserat!$L:$L, Mountserat!$B:$B, $A2, Mountserat!$D:$D, "Out Ports") + SUMIFS(Nevis!$L:$L, Nevis!$B:$B, $A2, Nevis!$D:$D, "Out Ports") + SUMIFS('St Kitts'!$L:$L, 'St Kitts'!$B:$B, $A2, 'St Kitts'!$D:$D, "Out Ports") + SUMIFS(General!$L:$L, General!$B:$B, $A2, General!$D:$D, "Out Ports") -> 0.074107143 | D2: =ROUND((B2+C2),2) -> 2.57
A3: Bees Wax | B3: =SUMIFS(Antigua!$L:$L, Antigua!$B:$B, $A3, Antigua!$D:$D, "London") + SUMIFS(Barbados!$L:$L, Barbados!$B:$B, $A3, Barbados!$D:$D, "London") + SUMIFS(Bermuda!$L:$L, Bermuda!$B:$B, $A3, Bermuda!$D:$D, "London") + SUMIFS(Jamaica!$L:$L, Jamaica!$B:$B, $A3, Jamaica!$D:$D, "London") + SUMIFS(Mountserat!$L:$L, Mountserat!$B:$B, $A3, Mountserat!$D:$D, "London") + SUMIFS(Nevis!$L:$L, Nevis!$B:$B, $A3, Nevis!$D:$D, "London") + SUMIFS('St Kitts'!$L:$L, 'St Kitts'!$B:$B, $A3, 'St Kitts'!$D:$D, "London")+ SUMIFS(General!$L:$L, General!$B:$B, $A3, General!$D:$D, "London") -> 0.68392857 | C3: =SUMIFS(Antigua!$L:$L, Antigua!$B:$B, $A3, Antigua!$D:$D, "Out Ports") + SUMIFS(Barbados!$L:$L, Barbados!$B:$B, $A3, Barbados!$D:$D, "Out Ports") + SUMIFS(Bermuda!$L:$L, Bermuda!$B:$B, $A3, Bermuda!$D:$D, "Out Ports") + SUMIFS(Jamaica!$L:$L, Jamaica!$B:$B, $A3, Jamaica!$D:$D, "Out Ports") + SUMIFS(Mountserat!$L:$L, Mountserat!$B:$B, $A3, Mountserat!$D:$D, "Out Ports") + SUMIFS(Nevis!$L:$L, Nevis!$B:$B, $A3, Nevis!$D:$D, "Out Ports") + SUMIFS('St Kitts'!$L:$L, 'St Kitts'!$B:$B, $A3, 'St Kitts'!$D:$D, "Out Ports") + SUMIFS(General!$L:$L, General!$B:$B, $A3, General!$D:$D, "Out Ports") -> 0 | D3: =ROUND((B3+C3),2) -> 0.68
A4: Brown Sugar | B4: =SUMIFS(Antigua!$L:$L, Antigua!$B:$B, $A4, Antigua!$D:$D, "London") + SUMIFS(Barbados!$L:$L, Barbados!$B:$B, $A4, Barbados!$D:$D, "London") + SUMIFS(Bermuda!$L:$L, Bermuda!$B:$B, $A4, Bermuda!$D:$D, "London") + SUMIFS(Jamaica!$L:$L, Jamaica!$B:$B, $A4, Jamaica!$D:$D, "London") + SUMIFS(Mountserat!$L:$L, Mountserat!$B:$B, $A4, Mountserat!$D:$D, "London") + SUMIFS(Nevis!$L:$L, Nevis!$B:$B, $A4, Nevis!$D:$D, "London") + SUMIFS('St Kitts'!$L:$L, 'St Kitts'!$B:$B, $A4, 'St Kitts'!$D:$D, "London")+ SUMIFS(General!$L:$L, General!$B:$B, $A4, General!$D:$D, "London") -> 17677.282 | C4: =SUMIFS(Antigua!$L:$L, Antigua!$B:$B, $A4, Antigua!$D:$D, "Out Ports") + SUMIFS(Barbados!$L:$L, Barbados!$B:$B, $A4, Barbados!$D:$D, "Out Ports") + SUMIFS(Bermuda!$L:$L, Bermuda!$B:$B, $A4, Bermuda!$D:$D, "Out Ports") + SUMIFS(Jamaica!$L:$L, Jamaica!$B:$B, $A4, Jamaica!$D:$D, "Out Ports") + SUMIFS(Mountserat!$L:$L, Mountserat!$B:$B, $A4, Mountserat!$D:$D, "Out Ports") + SUMIFS(Nevis!$L:$L, Nevis!$B:$B, $A4, Nevis!$D:$D, "Out Ports") + SUMIFS('St Kitts'!$L:$L, 'St Kitts'!$B:$B, $A4, 'St Kitts'!$D:$D, "Out Ports") + SUMIFS(General!$L:$L, General!$B:$B, $A4, General!$D:$D, "Out Ports") -> 7078.9295 | D4: =ROUND((B4+C4),2) -> 24756.21
A5: Chocolate | B5: =SUMIFS(Antigua!$L:$L, Antigua!$B:$B, $A5, Antigua!$D:$D, "London") + SUMIFS(Barbados!$L:$L, Barbados!$B:$B, $A5, Barbados!$D:$D, "London") + SUMIFS(Bermuda!$L:$L, Bermuda!$B:$B, $A5, Bermuda!$D:$D, "London") + SUMIFS(Jamaica!$L:$L, Jamaica!$B:$B, $A5, Jamaica!$D:$D, "London") + SUMIFS(Mountserat!$L:$L, Mountserat!$B:$B, $A5, Mountserat!$D:$D, "London") + SUMIFS(Nevis!$L:$L, Nevis!$B:$B, $A5, Nevis!$D:$D, "London") + SUMIFS('St Kitts'!$L:$L, 'St Kitts'!$B:$B, $A5, 'St Kitts'!$D:$D, "London")+ SUMIFS(General!$L:$L, General!$B:$B, $A5, General!$D:$D, "London") -> 0 | C5: =SUMIFS(Antigua!$L:$L, Antigua!$B:$B, $A5, Antigua!$D:$D, "Out Ports") + SUMIFS(Barbados!$L:$L, Barbados!$B:$B, $A5, Barbados!$D:$D, "Out Ports") + SUMIFS(Bermuda!$L:$L, Bermuda!$B:$B, $A5, Bermuda!$D:$D, "Out Ports") + SUMIFS(Jamaica!$L:$L, Jamaica!$B:$B, $A5, Jamaica!$D:$D, "Out Ports") + SUMIFS(Mountserat!$L:$L, Mountserat!$B:$B, $A5, Mountserat!$D:$D, "Out Ports") + SUMIFS(Nevis!$L:$L, Nevis!$B:$B, $A5, Nevis!$D:$D, "Out Ports") + SUMIFS('St Kitts'!$L:$L, 'St Kitts'!$B:$B, $A5, 'St Kitts'!$D:$D, "Out Ports") + SUMIFS(General!$L:$L, General!$B:$B, $A5, General!$D:$D, "Out Ports") -> 0 | D5: =ROUND((B5+C5),2) -> 0
A6: Cocheneal | B6: =SUMIFS(Antigua!$L:$L, Antigua!$B:$B, $A6, Antigua!$D:$D, "London") + SUMIFS(Barbados!$L:$L, Barbados!$B:$B, $A6, Barbados!$D:$D, "London") + SUMIFS(Bermuda!$L:$L, Bermuda!$B:$B, $A6, Bermuda!$D:$D, "London") + SUMIFS(Jamaica!$L:$L, Jamaica!$B:$B, $A6, Jamaica!$D:$D, "London") + SUMIFS(Mountserat!$L:$L, Mountserat!$B:$B, $A6, Mountserat!$D:$D, "London") + SUMIFS(Nevis!$L:$L, Nevis!$B:$B, $A6, Nevis!$D:$D, "London") + SUMIFS('St Kitts'!$L:$L, 'St Kitts'!$B:$B, $A6, 'St Kitts'!$D:$D, "London")+ SUMIFS(General!$L:$L, General!$B:$B, $A6, General!$D:$D, "London") -> 0.13214286 | C6: =SUMIFS(Antigua!$L:$L, Antigua!$B:$B, $A6, Antigua!$D:$D, "Out Ports") + SUMIFS(Barbados!$L:$L, Barbados!$B:$B, $A6, Barbados!$D:$D, "Out Ports") + SUMIFS(Bermuda!$L:$L, Bermuda!$B:$B, $A6, Bermuda!$D:$D, "Out Ports") + SUMIFS(Jamaica!$L:$L, Jamaica!$B:$B, $A6, Jamaica!$D:$D, "Out Ports") + SUMIFS(Mountserat!$L:$L, Mountserat!$B:$B, $A6, Mountserat!$D:$D, "Out Ports") + SUMIFS(Nevis!$L:$L, Nevis!$B:$B, $A6, Nevis!$D:$D, "Out Ports") + SUMIFS('St Kitts'!$L:$L, 'St Kitts'!$B:$B, $A6, 'St Kitts'!$D:$D, "Out Ports") + SUMIFS(General!$L:$L, General!$B:$B, $A6, General!$D:$D, "Out Ports") -> 0 | D6: =ROUND((B6+C6),2) -> 0.13
A7: Cocoa Nuts | B7: =SUMIFS(Antigua!$L:$L, Antigua!$B:$B, $A7, Antigua!$D:$D, "London") + SUMIFS(Barbados!$L:$L, Barbados!$B:$B, $A7, Barbados!$D:$D, "London") + SUMIFS(Bermuda!$L:$L, Bermuda!$B:$B, $A7, Bermuda!$D:$D, "London") + SUMIFS(Jamaica!$L:$L, Jamaica!$B:$B, $A7, Jamaica!$D:$D, "London") + SUMIFS(Mountserat!$L:$L, Mountserat!$B:$B, $A7, Mountserat!$D:$D, "London") + SUMIFS(Nevis!$L:$L, Nevis!$B:$B, $A7, Nevis!$D:$D, "London") + SUMIFS('St Kitts'!$L:$L, 'St Kitts'!$B:$B, $A7, 'St Kitts'!$D:$D, "London")+ SUMIFS(General!$L:$L, General!$B:$B, $A7, General!$D:$D, "London") -> 3.8084821 | C7: =SUMIFS(Antigua!$L:$L, Antigua!$B:$B, $A7, Antigua!$D:$D, "Out Ports") + SUMIFS(Barbados!$L:$L, Barbados!$B:$B, $A7, Barbados!$D:$D, "Out Ports") + SUMIFS(Bermuda!$L:$L, Bermuda!$B:$B, $A7, Bermuda!$D:$D, "Out Ports") + SUMIFS(Jamaica!$L:$L, Jamaica!$B:$B, $A7, Jamaica!$D:$D, "Out Ports") + SUMIFS(Mountserat!$L:$L, Mountserat!$B:$B, $A7, Mountserat!$D:$D, "Out Ports") + SUMIFS(Nevis!$L:$L, Nevis!$B:$B, $A7, Nevis!$D:$D, "Out Ports") + SUMIFS('St Kitts'!$L:$L, 'St Kitts'!$B:$B, $A7, 'St Kitts'!$D:$D, "Out Ports") + SUMIFS(General!$L:$L, General!$B:$B, $A7, General!$D:$D, "Out Ports") -> 0.54285714 | D7: =ROUND((B7+C7),2) -> 4.35
A8: Cotton | B8: =SUMIFS(Antigua!$L:$L, Antigua!$B:$B, $A8, Antigua!$D:$D, "London") + SUMIFS(Barbados!$L:$L, Barbados!$B:$B, $A8, Barbados!$D:$D, "London") + SUMIFS(Bermuda!$L:$L, Bermuda!$B:$B, $A8, Bermuda!$D:$D, "London") + SUMIFS(Jamaica!$L:$L, Jamaica!$B:$B, $A8, Jamaica!$D:$D, "London") + SUMIFS(Mountserat!$L:$L, Mountserat!$B:$B, $A8, Mountserat!$D:$D, "London") + SUMIFS(Nevis!$L:$L, Nevis!$B:$B, $A8, Nevis!$D:$D, "London") + SUMIFS('St Kitts'!$L:$L, 'St Kitts'!$B:$B, $A8, 'St Kitts'!$D:$D, "London")+ SUMIFS(General!$L:$L, General!$B:$B, $A8, General!$D:$D, "London") -> 273.64286 | C8: =SUMIFS(Antigua!$L:$L, Antigua!$B:$B, $A8, Antigua!$D:$D, "Out Ports") + SUMIFS(Barbados!$L:$L, Barbados!$B:$B, $A8, Barbados!$D:$D, "Out Ports") + SUMIFS(Bermuda!$L:$L, Bermuda!$B:$B, $A8, Bermuda!$D:$D, "Out Ports") + SUMIFS(Jamaica!$L:$L, Jamaica!$B:$B, $A8, Jamaica!$D:$D, "Out Ports") + SUMIFS(Mountserat!$L:$L, Mountserat!$B:$B, $A8, Mountserat!$D:$D, "Out Ports") + SUMIFS(Nevis!$L:$L, Nevis!$B:$B, $A8, Nevis!$D:$D, "Out Ports") + SUMIFS('St Kitts'!$L:$L, 'St Kitts'!$B:$B, $A8, 'St Kitts'!$D:$D, "Out Ports") + SUMIFS(General!$L:$L, General!$B:$B, $A8, General!$D:$D, "Out Ports") -> 301.96071 | D8: =ROUND((B8+C8),2) -> 575.6
A9: Dry Ginger | B9: =SUMIFS(Antigua!$L:$L, Antigua!$B:$B, $A9, Antigua!$D:$D, "London") + SUMIFS(Barbados!$L:$L, Barbados!$B:$B, $A9, Barbados!$D:$D, "London") + SUMIFS(Bermuda!$L:$L, Bermuda!$B:$B, $A9, Bermuda!$D:$D, "London") + SUMIFS(Jamaica!$L:$L, Jamaica!$B:$B, $A9, Jamaica!$D:$D, "London") + SUMIFS(Mountserat!$L:$L, Mountserat!$B:$B, $A9, Mountserat!$D:$D, "London") + SUMIFS(Nevis!$L:$L, Nevis!$B:$B, $A9, Nevis!$D:$D, "London") + SUMIFS('St Kitts'!$L:$L, 'St Kitts'!$B:$B, $A9, 'St Kitts'!$D:$D, "London")+ SUMIFS(General!$L:$L, General!$B:$B, $A9, General!$D:$D, "London") -> 861.73482 | C9: =SUMIFS(Antigua!$L:$L, Antigua!$B:$B, $A9, Antigua!$D:$D, "Out Ports") + SUMIFS(Barbados!$L:$L, Barbados!$B:$B, $A9, Barbados!$D:$D, "Out Ports") + SUMIFS(Bermuda!$L:$L, Bermuda!$B:$B, $A9, Bermuda!$D:$D, "Out Ports") + SUMIFS(Jamaica!$L:$L, Jamaica!$B:$B, $A9, Jamaica!$D:$D, "Out Ports") + SUMIFS(Mountserat!$L:$L, Mountserat!$B:$B, $A9, Mountserat!$D:$D, "Out Ports") + SUMIFS(Nevis!$L:$L, Nevis!$B:$B, $A9, Nevis!$D:$D, "Out Ports") + SUMIFS('St Kitts'!$L:$L, 'St Kitts'!$B:$B, $A9, 'St Kitts'!$D:$D, "Out Ports") + SUMIFS(General!$L:$L, General!$B:$B, $A9, General!$D:$D, "Out Ports") -> 436.4317 | D9: =ROUND((B9+C9),2) -> 1298.17
A10: Elephant Teeth | B10: =SUMIFS(Antigua!$L:$L, Antigua!$B:$B, $A10, Antigua!$D:$D, "London") + SUMIFS(Barbados!$L:$L, Barbados!$B:$B, $A10, Barbados!$D:$D, "London") + SUMIFS(Bermuda!$L:$L, Bermuda!$B:$B, $A10, Bermuda!$D:$D, "London") + SUMIFS(Jamaica!$L:$L, Jamaica!$B:$B, $A10, Jamaica!$D:$D, "London") + SUMIFS(Mountserat!$L:$L, Mountserat!$B:$B, $A10, Mountserat!$D:$D, "London") + SUMIFS(Nevis!$L:$L, Nevis!$B:$B, $A10, Nevis!$D:$D, "London") + SUMIFS('St Kitts'!$L:$L, 'St Kitts'!$B:$B, $A10, 'St Kitts'!$D:$D, "London")+ SUMIFS(General!$L:$L, General!$B:$B, $A10, General!$D:$D, "London") -> 22.16875 | C10: =SUMIFS(Antigua!$L:$L, Antigua!$B:$B, $A10, Antigua!$D:$D, "Out Ports") + SUMIFS(Barbados!$L:$L, Barbados!$B:$B, $A10, Barbados!$D:$D, "Out Ports") + SUMIFS(Bermuda!$L:$L, Bermuda!$B:$B, $A10, Bermuda!$D:$D, "Out Ports") + SUMIFS(Jamaica!$L:$L, Jamaica!$B:$B, $A10, Jamaica!$D:$D, "Out Ports") + SUMIFS(Mountserat!$L:$L, Mountserat!$B:$B, $A10, Mountserat!$D:$D, "Out Ports") + SUMIFS(Nevis!$L:$L, Nevis!$B:$B, $A10, Nevis!$D:$D, "Out Ports") + SUMIFS('St Kitts'!$L:$L, 'St Kitts'!$B:$B, $A10, 'St Kitts'!$D:$D, "Out Ports") + SUMIFS(General!$L:$L, General!$B:$B, $A10, General!$D:$D, "Out Ports") -> 16.225 | D10: =ROUND((B10+C10),2) -> 38.39
A11: Indigo | B11: =SUMIFS(Antigua!$L:$L, Antigua!$B:$B, $A11, Antigua!$D:$D, "London") + SUMIFS(Barbados!$L:$L, Barbados!$B:$B, $A11, Barbados!$D:$D, "London") + SUMIFS(Bermuda!$L:$L, Bermuda!$B:$B, $A11, Bermuda!$D:$D, "London") + SUMIFS(Jamaica!$L:$L, Jamaica!$B:$B, $A11, Jamaica!$D:$D, "London") + SUMIFS(Mountserat!$L:$L, Mountserat!$B:$B, $A11, Mountserat!$D:$D, "London") + SUMIFS(Nevis!$L:$L, Nevis!$B:$B, $A11, Nevis!$D:$D, "London") + SUMIFS('St Kitts'!$L:$L, 'St Kitts'!$B:$B, $A11, 'St Kitts'!$D:$D, "London")+ SUMIFS(General!$L:$L, General!$B:$B, $A11, General!$D:$D, "London") -> 125.08482 | C11: =SUMIFS(Antigua!$L:$L, Antigua!$B:$B, $A11, Antigua!$D:$D, "Out Ports") + SUMIFS(Barbados!$L:$L, Barbados!$B:$B, $A11, Barbados!$D:$D, "Out Ports") + SUMIFS(Bermuda!$L:$L, Bermuda!$B:$B, $A11, Bermuda!$D:$D, "Out Ports") + SUMIFS(Jamaica!$L:$L, Jamaica!$B:$B, $A11, Jamaica!$D:$D, "Out Ports") + SUMIFS(Mountserat!$L:$L, Mountserat!$B:$B, $A11, Mountserat!$D:$D, "Out Ports") + SUMIFS(Nevis!$L:$L, Nevis!$B:$B, $A11, Nevis!$D:$D, "Out Ports") + SUMIFS('St Kitts'!$L:$L, 'St Kitts'!$B:$B, $A11, 'St Kitts'!$D:$D, "Out Ports") + SUMIFS(General!$L:$L, General!$B:$B, $A11, General!$D:$D, "Out Ports") -> 60.832143 | D11: =ROUND((B11+C11),2) -> 185.92
A12: Lignum Vitae | B12: =SUMIFS(Antigua!$L:$L, Antigua!$B:$B, $A12, Antigua!$D:$D, "London") + SUMIFS(Barbados!$L:$L, Barbados!$B:$B, $A12, Barbados!$D:$D, "London") + SUMIFS(Bermuda!$L:$L, Bermuda!$B:$B, $A12, Bermuda!$D:$D, "London") + SUMIFS(Jamaica!$L:$L, Jamaica!$B:$B, $A12, Jamaica!$D:$D, "London") + SUMIFS(Mountserat!$L:$L, Mountserat!$B:$B, $A12, Mountserat!$D:$D, "London") + SUMIFS(Nevis!$L:$L, Nevis!$B:$B, $A12, Nevis!$D:$D, "London") + SUMIFS('St Kitts'!$L:$L, 'St Kitts'!$B:$B, $A12, 'St Kitts'!$D:$D, "London")+ SUMIFS(General!$L:$L, General!$B:$B, $A12, General!$D:$D, "London") -> 20.391071 | C12: =SUMIFS(Antigua!$L:$L, Antigua!$B:$B, $A12, Antigua!$D:$D, "Out Ports") + SUMIFS(Barbados!$L:$L, Barbados!$B:$B, $A12, Barbados!$D:$D, "Out Ports") + SUMIFS(Bermuda!$L:$L, Bermuda!$B:$B, $A12, Bermuda!$D:$D, "Out Ports") + SUMIFS(Jamaica!$L:$L, Jamaica!$B:$B, $A12, Jamaica!$D:$D, "Out Ports") + SUMIFS(Mountserat!$L:$L, Mountserat!$B:$B, $A12, Mountserat!$D:$D, "Out Ports") + SUMIFS(Nevis!$L:$L, Nevis!$B:$B, $A12, Nevis!$D:$D, "Out Ports") + SUMIFS('St Kitts'!$L:$L, 'St Kitts'!$B:$B, $A12, 'St Kitts'!$D:$D, "Out Ports") + SUMIFS(General!$L:$L, General!$B:$B, $A12, General!$D:$D, "Out Ports") -> 13.264732 | D12: =ROUND((B12+C12),2) -> 33.66
A13: Lime Juice | B13: =SUMIFS(Antigua!$L:$L, Antigua!$B:$B, $A13, Antigua!$D:$D, "London") + SUMIFS(Barbados!$L:$L, Barbados!$B:$B, $A13, Barbados!$D:$D, "London") + SUMIFS(Bermuda!$L:$L, Bermuda!$B:$B, $A13, Bermuda!$D:$D, "London") + SUMIFS(Jamaica!$L:$L, Jamaica!$B:$B, $A13, Jamaica!$D:$D, "London") + SUMIFS(Mountserat!$L:$L, Mountserat!$B:$B, $A13, Mountserat!$D:$D, "London") + SUMIFS(Nevis!$L:$L, Nevis!$B:$B, $A13, Nevis!$D:$D, "London") + SUMIFS('St Kitts'!$L:$L, 'St Kitts'!$B:$B, $A13, 'St Kitts'!$D:$D, "London")+ SUMIFS(General!$L:$L, General!$B:$B, $A13, General!$D:$D, "London") -> 25.803571 | C13: =SUMIFS(Antigua!$L:$L, Antigua!$B:$B, $A13, Antigua!$D:$D, "Out Ports") + SUMIFS(Barbados!$L:$L, Barbados!$B:$B, $A13, Barbados!$D:$D, "Out Ports") + SUMIFS(Bermuda!$L:$L, Bermuda!$B:$B, $A13, Bermuda!$D:$D, "Out Ports") + SUMIFS(Jamaica!$L:$L, Jamaica!$B:$B, $A13, Jamaica!$D:$D, "Out Ports") + SUMIFS(Mountserat!$L:$L, Mountserat!$B:$B, $A13, Mountserat!$D:$D, "Out Ports") + SUMIFS(Nevis!$L:$L, Nevis!$B:$B, $A13, Nevis!$D:$D, "Out Ports") + SUMIFS('St Kitts'!$L:$L, 'St Kitts'!$B:$B, $A13, 'St Kitts'!$D:$D, "Out Ports") + SUMIFS(General!$L:$L, General!$B:$B, $A13, General!$D:$D, "Out Ports") -> 9.8388393 | D13: =ROUND((B13+C13),2) -> 35.64
... A32: Wood, Sweetwood | B32: =SUMIFS(Antigua!$L:$L, Antigua!$B:$B, $A32, Antigua!$D:$D, "London") + SUMIFS(Barbados!$L:$L, Barbados!$B:$B, $A32, Barbados!$D:$D, "London") + SUMIFS(Bermuda!$L:$L, Bermuda!$B:$B, $A32, Bermuda!$D:$D, "London") + SUMIFS(Jamaica!$L:$L, Jamaica!$B:$B, $A32, Jamaica!$D:$D, "London") + SUMIFS(Mountserat!$L:$L, Mountserat!$B:$B, $A32, Mountserat!$D:$D, "London") + SUMIFS(Nevis!$L:$L, Nevis!$B:$B, $A32, Nevis!$D:$D, "London") + SUMIFS('St Kitts'!$L:$L, 'St Kitts'!$B:$B, $A32, 'St Kitts'!$D:$D, "London")+ SUMIFS(General!$L:$L, General!$B:$B, $A32, General!$D:$D, "London") -> 2.55 | C32: =SUMIFS(Antigua!$L:$L, Antigua!$B:$B, $A32, Antigua!$D:$D, "Out Ports") + SUMIFS(Barbados!$L:$L, Barbados!$B:$B, $A32, Barbados!$D:$D, "Out Ports") + SUMIFS(Bermuda!$L:$L, Bermuda!$B:$B, $A32, Bermuda!$D:$D, "Out Ports") + SUMIFS(Jamaica!$L:$L, Jamaica!$B:$B, $A32, Jamaica!$D:$D, "Out Ports") + SUMIFS(Mountserat!$L:$L, Mountserat!$B:$B, $A32, Mountserat!$D:$D, "Out Ports") + SUMIFS(Nevis!$L:$L, Nevis!$B:$B, $A32, Nevis!$D:$D, "Out Ports") + SUMIFS('St Kitts'!$L:$L, 'St Kitts'!$B:$B, $A32, 'St Kitts'!$D:$D, "Out Ports") + SUMIFS(General!$L:$L, General!$B:$B, $A32, General!$D:$D, "Out Ports") -> 0 | D32: =ROUND((B32+C32),2) -> 2.55

Sheet Africa
A1: Items | B1: Import Location | C1: 1700 Ton | D1: 1700 hh | E1: 1700 quarter | F1: 1700 Stone/lb | G1: Total Pounds | I1: Total Tons

Sheet Canaries
A1: Items | B1: Import Location | C1: 1700 Ton | D1: 1700 hh | E1: 1700 quarter | F1: 1700 lb | G1: Total Pounds | I1: Total Tons

Sheet Antigua
A1: YEAR | B1: COMMODITY_NAME | C1: FROM_LOCATION | D1: TO_LOCATION | E1: ton | F1: hh | G1: quarter | H1: lb | J1: Total Pounds | L1: WEIGHT
A2: 1721 | B2: Annatto | C2: Antigua | D2: London | H2: 4000 | J2: =(E2*2240)+(F2*112)+(G2*28)+H2 -> 4000 | L2: =J2/2240 -> 1.7857143
A3: 1721 | B3: Brown Sugar | C3: Antigua | D3: London | F3: 28359 | G3: 2 | H3: 10 | J3: =(E3*2240)+(F3*112)+(G3*28)+H3 -> 3176274 | L3: =J3/2240 -> 1417.9795
A4: 1721 | B4: Chocolate | C4: Antigua | D4: London | J4: =(E4*2240)+(F4*112)+(G4*28)+H4 -> 0 | L4: =J4/2240 -> 0
A5: 1721 | B5: Cocoa Nuts | C5: Antigua | D5: London | F5: 7 | G5: 2 | H5: 24 | J5: =(E5*2240)+(F5*112)+(G5*28)+H5 -> 864 | L5: =J5/2240 -> 0.38571429
A6: 1721 | B6: Cotton | C6: Antigua | D6: London | H6: =895*200 -> 179000 | I6: 895bags | J6: =(E6*2240)+(F6*112)+(G6*28)+H6 -> 179000 | L6: =J6/2240 -> 79.910714
A7: 1721 | B7: Dry Ginger | C7: Antigua | D7: London | F7: 1219 | G7: 3 | H7: 17 | J7: =(E7*2240)+(F7*112)+(G7*28)+H7 -> 136629 | L7: =J7/2240 -> 60.995089
A8: 1721 | B8: Elephant Teeth | C8: Antigua | D8: London | F8: 26 | J8: =(E8*2240)+(F8*112)+(G8*28)+H8 -> 2912 | L8: =J8/2240 -> 1.3
A9: 1721 | B9: Green Ginger | C9: Antigua | D9: London | H9: 18 | J9: =(E9*2240)+(F9*112)+(G9*28)+H9 -> 18 | L9: =J9/2240 -> 0.0080357143
A10: 1721 | B10: Indigo | C10: Antigua | D10: London | H10: 349 | J10: =(E10*2240)+(F10*112)+(G10*28)+H10 -> 349 | L10: =J10/2240 -> 0.15580357
A11: 1721 | B11: Lemon Water | C11: Antigua | D11: London | J11: =(E11*2240)+(F11*112)+(G11*28)+H11 -> 0 | L11: =J11/2240 -> 0
A12: 1721 | B12: Lignum Vitae | C12: Antigua | D12: London | E12: 2 | F12: 15 | G12: 3 | J12: =(E12*2240)+(F12*112)+(G12*28)+H12 -> 6244 | L12: =J12/2240 -> 2.7875
A13: 1721 | B13: Lime Juice | C13: Antigua | D13: London | J13: =(E13*2240)+(F13*112)+(G13*28)+H13 -> 0 | L13: =J13/2240 -> 0
A14: 1721 | B14: Madera Wine | C14: Antigua | D14: London | H14: 5743 | I14: 2t 1h 2g | J14: =(E14*2240)+(F14*112)+(G14*28)+H14 -> 5743 | L14: =J14/2240 -> 2.5638393
A15: 1721 | B15: Molasses | C15: Antigua | D15: London | J15: =(E15*2240)+(F15*112)+(G15*28)+H15 -> 0 | L15: =J15/2240 -> 0
A16: 1721 | B16: Pickles | C16: Antigua | D16: London | F16: 5 | G16: 2 | H16: 6 | J16: =(E16*2240)+(F16*112)+(G16*28)+H16 -> 622 | L16: =J16/2240 -> 0.27767857
A17: 1721 | B17: Rum | C17: Antigua | D17: London | H17: 40976 | I17: 4060g | J17: =(E17*2240)+(F17*112)+(G17*28)+H17 -> 40976 | L17: =J17/2240 -> 18.292857
A18: 1721 | B18: Shruff | C18: Antigua | D18: London | F18: 22 | H18: 21 | J18: =(E18*2240)+(F18*112)+(G18*28)+H18 -> 2485 | L18: =J18/2240 -> 1.109375
A19: 1721 | B19: Succads | C19: Antigua | D19: London | H19: 437 | J19: =(E19*2240)+(F19*112)+(G19*28)+H19 -> 437 | L19: =J19/2240 -> 0.19508929
A20: 1721 | B20: Tobacco | C20: Antigua | D20: London | J20: =(E20*2240)+(F20*112)+(G20*28)+H20 -> 0 | L20: =J20/2240 -> 0
A21: 1721 | B21: Tortoise Shell | C21: Antigua | D21: London | J21: =(E21*2240)+(F21*112)+(G21*28)+H21 -> 0 | L21: =J21/2240 -> 0
A22: 1721 | B22: White Sugar | C22: Antigua | D22: London | J22: =(E22*2240)+(F22*112)+(G22*28)+H22 -> 0 | L22: =J22/2240 -> 0
A23: 1721 | B23: Brown Sugar | C23: Antigua | D23: Out Ports | F23: 14590 | G23: 1 | H23: 17 | J23: =(E23*2240)+(F23*112)+(G23*28)+H23 -> 1634125 | L23: =J23/2240 -> 729.52009
A24: 1721 | B24: Cocoa | C24: Antigua | D24: Out Ports | J24: =(E24*2240)+(F24*112)+(G24*28)+H24 -> 0 | L24: =J24/2240 -> 0
A25: 1721 | B25: Cocoa Nuts | C25: Antigua | D25: Out Ports | J25: =(E25*2240)+(F25*112)+(G25*28)+H25 -> 0 | L25: =J25/2240 -> 0
A26: 1721 | B26: Cotton | C26: Antigua | D26: Out Ports | H26: 131128 | J26: =(E26*2240)+(F26*112)+(G26*28)+H26 -> 131128 | L26: =J26/2240 -> 58.539286
A27: 1721 | B27: Dry Ginger | C27: Antigua | D27: Out Ports | F27: 837 | G27: 3 | H27: 18 | J27: =(E27*2240)+(F27*112)+(G27*28)+H27 -> 93846 | L27: =J27/2240 -> 41.895536
A28: 1721 | B28: Fustic | C28: Antigua | D28: Out Ports | J28: =(E28*2240)+(F28*112)+(G28*28)+H28 -> 0 | L28: =J28/2240 -> 0
A29: 1721 | B29: Indigo | C29: Antigua | D29: Out Ports | H29: 1497 | J29: =(E29*2240)+(F29*112)+(G29*28)+H29 -> 1497 | L29: =J29/2240 -> 0.66830357
A30: 1721 | B30: Lignum Vitae | C30: Antigua | D30: Out Ports | F30: 144 | H30: 8 | J30: =(E30*2240)+(F30*112)+(G30*28)+H30 -> 16136 | L30: =J30/2240 -> 7.2035714
A31: 1721 | B31: Lime Juice | C31: Antigua | D31: Out Ports | H31: 1352 | I31: 130g | J31: =(E31*2240)+(F31*112)+(G31*28)+H31 -> 1352 | L31: =J31/2240 -> 0.60357143
A32: 1721 | B32: Madera Wine | C32: Antigua | D32: Out Ports | H32: 104 | I32: 10g | J32: =(E32*2240)+(F32*112)+(G32*28)+H32 -> 104 | L32: =J32/2240 -> 0.046428571
A33: 1721 | B33: Molasses | C33: Antigua | D33: Out Ports | J33: =(E33*2240)+(F33*112)+(G33*28)+H33 -> 0 | L33: =J33/2240 -> 0
A34: 1721 | B34: Rice | C34: Antigua | D34: Out Ports | J34: =(E34*2240)+(F34*112)+(G34*28)+H34 -> 0 | L34: =J34/2240 -> 0
A35: 1721 | B35: Rum | C35: Antigua | D35: Out Ports | H35: 2320 | I35: 223g | J35: =(E35*2240)+(F35*112)+(G35*28)+H35 -> 2320 | L35: =J35/2240 -> 1.0357143
A36: 1721 | B36: Shruff | C36: Antigua | D36: Out Ports | F36: 10 | G36: 3 | H36: 4 | J36: =(E36*2240)+(F36*112)+(G36*28)+H36 -> 1208 | L36: =J36/2240 -> 0.53928571
A37: 1721 | B37: Succads | C37: Antigua | D37: Out Ports | H37: 60 | J37: =(E37*2240)+(F37*112)+(G37*28)+H37 -> 60 | L37: =J37/2240 -> 0.026785714
A38: 1721 | B38: Tobacco | C38: Antigua | D38: Out Ports | H38: 1120 | J38: =(E38*2240)+(F38*112)+(G38*28)+H38 -> 1120 | L38: =J38/2240 -> 0.5
A39: 1721 | B39: Tortoise Shell | C39: Antigua | D39: Out Ports | H39: 15 | J39: =(E39*2240)+(F39*112)+(G39*28)+H39 -> 15 | L39: =J39/2240 -> 0.0066964286
A40: 1721 | B40: White Sugar | C40: Antigua | D40: Out Ports | J40: =(E40*2240)+(F40*112)+(G40*28)+H40 -> 0 | L40: =J40/2240 -> 0

Sheet Barbados
A1: YEAR | B1: COMMODITY_NAME | C1: FROM_LOCATION | D1: TO_LOCATION | E1: ton | F1: hh | G1: quarter | H1: lb | J1: Total Pounds | L1: WEIGHT
A2: 1721 | B2: Almonds, Bitter | C2: Barbados | D2: London | F2: 113 | J2: =(E2*2240)+(F2*112)+(G2*28)+H2 -> 12656 | L2: =J2/2240 -> 5.65
A3: 1721 | B3: Almonds, Sweet | C3: Barbados | D3: London | F3: 140 | J3: =(E3*2240)+(F3*112)+(G3*28)+H3 -> 15680 | L3: =J3/2240 -> 7
A4: 1721 | B4: Aloes Epatica | C4: Barbados | D4: London | H4: 21382 | J4: =(E4*2240)+(F4*112)+(G4*28)+H4 -> 21382 | L4: =J4/2240 -> 9.5455357
A5: 1721 | B5: Annatto | C5: Barbados | D5: London | H5: 1367 | J5: =(E5*2240)+(F5*112)+(G5*28)+H5 -> 1367 | L5: =J5/2240 -> 0.61026786
A6: 1721 | B6: Anniseeds | C6: Barbados | D6: London | F6: 25 | J6: =(E6*2240)+(F6*112)+(G6*28)+H6 -> 2800 | L6: =J6/2240 -> 1.25
A7: 1721 | B7: Barrel Staves | C7: Barbados | D7: London | J7: =(E7*2240)+(F7*112)+(G7*28)+H7 -> 0 | L7: =J7/2240 -> 0
A8: 1721 | B8: Bees Wax | C8: Barbados | D8: London | F8: 13 | G8: 2 | H8: 20 | J8: =(E8*2240)+(F8*112)+(G8*28)+H8 -> 1532 | L8: =J8/2240 -> 0.68392857
A9: 1721 | B9: Brimstone | C9: Barbados | D9: London | F9: 4 | G9: 1 | H9: 21 | J9: =(E9*2240)+(F9*112)+(G9*28)+H9 -> 497 | L9: =J9/2240 -> 0.221875
A10: 1721 | B10: Brown Sugar | C10: Barbados | D10: London | F10: 60168 | H10: 3 | J10: =(E10*2240)+(F10*112)+(G10*28)+H10 -> 6738819 | L10: =J10/2240 -> 3008.4013
A11: 1721 | B11: Cassia Fistula | C11: Barbados | D11: London | H11: 6260 | J11: =(E11*2240)+(F11*112)+(G11*28)+H11 -> 6260 | L11: =J11/2240 -> 2.7946429
A12: 1721 | B12: Chocolate Paste | C12: Barbados | D12: London | J12: =(E12*2240)+(F12*112)+(G12*28)+H12 -> 0 | L12: =J12/2240 -> 0
A13: 1721 | B13: Cocheneal | C13: Barbados | D13: London | J13: =(E13*2240)+(F13*112)+(G13*28)+H13 -> 0 | L13: =J13/2240 -> 0
A14: 1721 | B14: Cocoa Nuts | C14: Barbados | D14: London | F14: 39 | G14: 3 | H14: 23 | J14: =(E14*2240)+(F14*112)+(G14*28)+H14 -> 4475 | L14: =J14/2240 -> 1.9977679
A15: 1721 | B15: Cocoa Paste | C15: Barbados | D15: London | J15: =(E15*2240)+(F15*112)+(G15*28)+H15 -> 0 | L15: =J15/2240 -> 0
A16: 1721 | B16: Cotton | C16: Barbados | D16: London | H16: =376*200 -> 75200 | I16: 376bags | J16: =(E16*2240)+(F16*112)+(G16*28)+H16 -> 75200 | L16: =J16/2240 -> 33.571429
A17: 1721 | B17: Dry Ginger | C17: Barbados | D17: London | F17: 2948 | G17: 3 | H17: 133 | J17: =(E17*2240)+(F17*112)+(G17*28)+H17 -> 330393 | L17: =J17/2240 -> 147.49687
A18: 1721 | B18: Elephant Teeth | C18: Barbados | D18: London | F18: 236 | H18: 22 | J18: =(E18*2240)+(F18*112)+(G18*28)+H18 -> 26454 | L18: =J18/2240 -> 11.809821
A19: 1721 | B19: Green Ginger | C19: Barbados | D19: London | J19: =(E19*2240)+(F19*112)+(G19*28)+H19 -> 0 | L19: =J19/2240 -> 0
A20: 1721 | B20: Hemp | C20: Barbados | D20: London | J20: =(E20*2240)+(F20*112)+(G20*28)+H20 -> 0 | L20: =J20/2240 -> 0
A21: 1721 | B21: Indigo | C21: Barbados | D21: London | H21: 25454 | J21: =(E21*2240)+(F21*112)+(G21*28)+H21 -> 25454 | L21: =J21/2240 -> 11.363393
A22: 1721 | B22: Lemon Water | C22: Barbados | D22: London | J22: =(E22*2240)+(F22*112)+(G22*28)+H22 -> 0 | L22: =J22/2240 -> 0
A23: 1721 | B23: Lignum Vitae | C23: Barbados | D23: London | J23: =(E23*2240)+(F23*112)+(G23*28)+H23 -> 0 | L23: =J23/2240 -> 0
A24: 1721 | B24: Lime Juice | C24: Barbados | D24: London | H24: 3745 | I24: 360g | J24: =(E24*2240)+(F24*112)+(G24*28)+H24 -> 3745 | L24: =J24/2240 -> 1.671875
A25: 1721 | B25: Loaf Sugar | C25: Barbados | D25: London | J25: =(E25*2240)+(F25*112)+(G25*28)+H25 -> 0 | L25: =J25/2240 -> 0
A26: 1721 | B26: Madera Wine | C26: Barbados | D26: London | H26: 49415 | I26: 18t 3h 25g | J26: =(E26*2240)+(F26*112)+(G26*28)+H26 -> 49415 | L26: =J26/2240 -> 22.060268
A27: 1721 | B27: Molasses | C27: Barbados | D27: London | J27: =(E27*2240)+(F27*112)+(G27*28)+H27 -> 0 | L27: =J27/2240 -> 0
A28: 1721 | B28: Oranges | C28: Barbados | D28: London | J28: =(E28*2240)+(F28*112)+(G28*28)+H28 -> 0 | L28: =J28/2240 -> 0
A29: 1721 | B29: Pickles | C29: Barbados | D29: London | H29: 22 | J29: =(E29*2240)+(F29*112)+(G29*28)+H29 -> 22 | L29: =J29/2240 -> 0.0098214286
A30: 1721 | B30: Pimento | C30: Barbados | D30: London | J30: =(E30*2240)+(F30*112)+(G30*28)+H30 -> 0 | L30: =J30/2240 -> 0
A31: 1721 | B31: Rice | C31: Barbados | D31: London | F31: 3 | J31: =(E31*2240)+(F31*112)+(G31*28)+H31 -> 336 | L31: =J31/2240 -> 0.15
A32: 1721 | B32: Rum | C32: Barbados | D32: London | H32: 106040 | I32: 10193g | J32: =(E32*2240)+(F32*112)+(G32*28)+H32 -> 106040 | L32: =J32/2240 -> 47.339286
A33: 1721 | B33: Shruff | C33: Barbados | D33: London | F33: 123 | G33: 3 | H33: 17 | J33: =(E33*2240)+(F33*112)+(G33*28)+H33 -> 13877 | L33: =J33/2240 -> 6.1950893
A34: 1721 | B34: Snuff | C34: Barbados | D34: London | H34: 65 | J34: =(E34*2240)+(F34*112)+(G34*28)+H34 -> 65 | L34: =J34/2240 -> 0.029017857
A35: 1721 | B35: Succads | C35: Barbados | D35: London | H35: 1176 | J35: =(E35*2240)+(F35*112)+(G35*28)+H35 -> 1176 | L35: =J35/2240 -> 0.525
A36: 1721 | B36: Tobacco | C36: Barbados | D36: London | J36: =(E36*2240)+(F36*112)+(G36*28)+H36 -> 0 | L36: =J36/2240 -> 0
A37: 1721 | B37: Tortoise Shell | C37: Barbados | D37: London | H37: 337 | J37: =(E37*2240)+(F37*112)+(G37*28)+H37 -> 337 | L37: =J37/2240 -> 0.15044643
A38: 1721 | B38: White Sugar | C38: Barbados | D38: London | G38: 1 | H38: 7 | J38: =(E38*2240)+(F38*112)+(G38*28)+H38 -> 35 | L38: =J38/2240 -> 0.015625
A39: 1721 | B39: Wood, Braziletto | C39: Barbados | D39: London | E39: 5 | F39: 19 | J39: =(E39*2240)+(F39*112)+(G39*28)+H39 -> 13328 | L39: =J39/2240 -> 5.95
A40: 1721 | B40: Wood, Fustick | C40: Barbados | D40: London | E40: 73 | G40: 1 | J40: =(E40*2240)+(F40*112)+(G40*28)+H40 -> 163548 | L40: =J40/2240 -> 73.0125
...

Sheet Bermuda
A1: YEAR | B1: COMMODITY_NAME | C1: FROM_LOCATION | D1: TO_LOCATION | E1: ton | F1: hh | G1: quarter | H1: lb | J1: Total Pounds | L1: WEIGHT
A2: 1721 | B2: Bermudos Plat | C2: Bermuda | D2: London | F2: 1651 | J2: =(E2*2240)+(F2*112)+(G2*28)+H2 -> 184912 | L2: =J2/2240 -> 82.55
A3: 1721 | B3: Cocoa Nuts | C3: Bermuda | D3: London | F3: 1 | G3: 1 | H3: 6 | J3: =(E3*2240)+(F3*112)+(G3*28)+H3 -> 146 | L3: =J3/2240 -> 0.065178571
A4: 1721 | B4: Cotton | C4: Bermuda | D4: London | H4: 60 | J4: =(E4*2240)+(F4*112)+(G4*28)+H4 -> 60 | L4: =J4/2240 -> 0.026785714
A5: 1721 | B5: Wood, Braziletto | C5: Bermuda | D5: London | E5: 5 | F5: 10 | G5: 1 | J5: =(E5*2240)+(F5*112)+(G5*28)+H5 -> 12348 | L5: =J5/2240 -> 5.5125
A6: 1721 | B6: Wood, Logwood | C6: Bermuda | D6: London | E6: 27 | F6: 19 | G6: 3 | J6: =(E6*2240)+(F6*112)+(G6*28)+H6 -> 62692 | L6: =J6/2240 -> 27.9875
A7: 1721 | B7: Indigo | C7: Bermuda | D7: Out Ports | J7: =(E7*2240)+(F7*112)+(G7*28)+H7 -> 0 | L7: =J7/2240 -> 0
A8: 1721 | B8: Logwood | C8: Bermuda | D8: Out Ports | J8: =(E8*2240)+(F8*112)+(G8*28)+H8 -> 0 | L8: =J8/2240 -> 0
A9: 1721 | B9: Shruff | C9: Bermuda | D9: Out Ports | J9: =(E9*2240)+(F9*112)+(G9*28)+H9 -> 0 | L9: =J9/2240 -> 0
A10: 1721 | B10: Succads | C10: Bermuda | D10: Out Ports | J10: =(E10*2240)+(F10*112)+(G10*28)+H10 -> 0 | L10: =J10/2240 -> 0
A11: 1721 | B11: Cotton | C11: Bermuda | D11: Out Ports | J11: =(E11*2240)+(F11*112)+(G11*28)+H11 -> 0 | L11: =J11/2240 -> 0
A12: 1721 | B12: Cocoa Nuts | C12: Bermuda | D12: Out Ports | J12: =(E12*2240)+(F12*112)+(G12*28)+H12 -> 0 | L12: =J12/2240 -> 0
A13: 1721 | B13: Wood, Braziletto | C13: Bermuda | D13: Out Ports | E13: 13 | F13: 9 | G13: 1 | H13: 25 | J13: =(E13*2240)+(F13*112)+(G13*28)+H13 -> 30181 | L13: =J13/2240 -> 13.473661
A14: 1721 | B14: Wood, Logwood | C14: Bermuda | D14: Out Ports | E14: 2 | F14: 18 | G14: 3 | H14: 15 | J14: =(E14*2240)+(F14*112)+(G14*28)+H14 -> 6595 | L14: =J14/2240 -> 2.9441964

Sheet Carolina
A1: YEAR | B1: COMMODITY_NAME | C1: FROM_LOCATION | D1: TO_LOCATION | E1: ton | F1: hh | G1: quarter | H1: lb | J1: Total Pounds | L1: WEIGHT
A2: 1721 | B2: Almonds, Bitter | C2: Carolina | D2: London | J2: =(E2*2240)+(F2*112)+(G2*28)+H2 -> 0 | L2: =J2/2240 -> 0
A3: 1721 | B3: Almonds, Sweet | C3: Carolina | D3: London | J3: =(E3*2240)+(F3*112)+(G3*28)+H3 -> 0 | L3: =J3/2240 -> 0
A4: 1721 | B4: Aloes Epatica | C4: Carolina | D4: London | J4: =(E4*2240)+(F4*112)+(G4*28)+H4 -> 0 | L4: =J4/2240 -> 0
A5: 1721 | B5: Annatto | C5: Carolina | D5: London | J5: =(E5*2240)+(F5*112)+(G5*28)+H5 -> 0 | L5: =J5/2240 -> 0
A6: 1721 | B6: Anniseeds | C6: Carolina | D6: London | J6: =(E6*2240)+(F6*112)+(G6*28)+H6 -> 0 | L6: =J6/2240 -> 0
A7: 1721 | B7: Barrel Staves | C7: Carolina | D7: London | J7: =(E7*2240)+(F7*112)+(G7*28)+H7 -> 0 | L7: =J7/2240 -> 0
A8: 1721 | B8: Bees Wax | C8: Carolina | D8: London | J8: =(E8*2240)+(F8*112)+(G8*28)+H8 -> 0 | L8: =J8/2240 -> 0
A9: 1721 | B9: Brimstone | C9: Carolina | D9: London | J9: =(E9*2240)+(F9*112)+(G9*28)+H9 -> 0 | L9: =J9/2240 -> 0
A10: 1721 | B10: Brown Sugar | C10: Carolina | D10: London | J10: =(E10*2240)+(F10*112)+(G10*28)+H10 -> 0 | L10: =J10/2240 -> 0
A11: 1721 | B11: Cassia Fistula | C11: Carolina | D11: London | J11: =(E11*2240)+(F11*112)+(G11*28)+H11 -> 0 | L11: =J11/2240 -> 0
A12: 1721 | B12: Chocolate Paste | C12: Carolina | D12: London | J12: =(E12*2240)+(F12*112)+(G12*28)+H12 -> 0 | L12: =J12/2240 -> 0
A13: 1721 | B13: Cocheneal | C13: Carolina | D13: London | J13: =(E13*2240)+(F13*112)+(G13*28)+H13 -> 0 | L13: =J13/2240 -> 0
... A17: 1721 | B17: Dry Ginger | C17: Carolina | D17: London | J17: =(E17*2240)+(F17*112)+(G17*28)+H17 -> 0 | L17: =J17/2240 -> 0
A18: 1721 | B18: Elephant Teeth | C18: Carolina | D18: London | F18: 10 | J18: =(E18*2240)+(F18*112)+(G18*28)+H18 -> 1120 | L18: =J18/2240 -> 0.5
A19: 1721 | B19: Green Ginger | C19: Carolina | D19: London | J19: =(E19*2240)+(F19*112)+(G19*28)+H19 -> 0 | L19: =J19/2240 -> 0
A20: 1721 | B20: Hemp | C20: Carolina | D20: London | J20: =(E20*2240)+(F20*112)+(G20*28)+H20 -> 0 | L20: =J20/2240 -> 0
A21: 1721 | B21: Indigo | C21: Carolina | D21: London | H21: 60 | J21: =(E21*2240)+(F21*112)+(G21*28)+H21 -> 60 | L21: =J21/2240 -> 0.026785714
A22: 1721 | B22: Lemon Water | C22: Carolina | D22: London | J22: =(E22*2240)+(F22*112)+(G22*28)+H22 -> 0 | L22: =J22/2240 -> 0
A23: 1721 | B23: Lignum Vitae | C23: Carolina | D23: London | J23: =(E23*2240)+(F23*112)+(G23*28)+H23 -> 0 | L23: =J23/2240 -> 0
A24: 1721 | B24: Lime Juice | C24: Carolina | D24: London | J24: =(E24*2240)+(F24*112)+(G24*28)+H24 -> 0 | L24: =J24/2240 -> 0
A25: 1721 | B25: Loaf Sugar | C25: Carolina | D25: London | J25: =(E25*2240)+(F25*112)+(G25*28)+H25 -> 0 | L25: =J25/2240 -> 0
A26: 1721 | B26: Madera Wine | C26: Carolina | D26: London | J26: =(E26*2240)+(F26*112)+(G26*28)+H26 -> 0 | L26: =J26/2240 -> 0
A27: 1721 | B27: Molasses | C27: Carolina | D27: London | J27: =(E27*2240)+(F27*112)+(G27*28)+H27 -> 0 | L27: =J27/2240 -> 0
A28: 1721 | B28: Oranges | C28: Carolina | D28: London | J28: =(E28*2240)+(F28*112)+(G28*28)+H28 -> 0 | L28: =J28/2240 -> 0
A29: 1721 | B29: Pickles | C29: Carolina | D29: London | J29: =(E29*2240)+(F29*112)+(G29*28)+H29 -> 0 | L29: =J29/2240 -> 0
A30: 1721 | B30: Pimento | C30: Carolina | D30: London | J30: =(E30*2240)+(F30*112)+(G30*28)+H30 -> 0 | L30: =J30/2240 -> 0
A31: 1721 | B31: Rice | C31: Carolina | D31: London | F31: 31441 | G31: 2 | H31: 20 | J31: =(E31*2240)+(F31*112)+(G31*28)+H31 -> 3521468 | L31: =J31/2240 -> 1572.0839
A32: 1721 | B32: Rum | C32: Carolina | D32: London | H32: 3454 | I32: 332g | J32: =(E32*2240)+(F32*112)+(G32*28)+H32 -> 3454 | L32: =J32/2240 -> 1.5419643
A33: 1721 | B33: Sassafras | C33: Carolina | D33: London | F33: 155 | G33: 1 | H33: 16 | J33: =(E33*2240)+(F33*112)+(G33*28)+H33 -> 17404 | L33: =J33/2240 -> 7.7696429
A34: 1721 | B34: Shruff | C34: Carolina | D34: London | J34: =(E34*2240)+(F34*112)+(G34*28)+H34 -> 0 | L34: =J34/2240 -> 0
A35: 1721 | B35: Snuff | C35: Carolina | D35: London | J35: =(E35*2240)+(F35*112)+(G35*28)+H35 -> 0 | L35: =J35/2240 -> 0
A36: 1721 | B36: Succads | C36: Carolina | D36: London | J36: =(E36*2240)+(F36*112)+(G36*28)+H36 -> 0 | L36: =J36/2240 -> 0
A37: 1721 | B37: Tobacco | C37: Carolina | D37: London | H37: 44597 | J37: =(E37*2240)+(F37*112)+(G37*28)+H37 -> 44597 | L37: =J37/2240 -> 19.909375
A38: 1721 | B38: Tortoise Shell | C38: Carolina | D38: London | J38: =(E38*2240)+(F38*112)+(G38*28)+H38 -> 0 | L38: =J38/2240 -> 0
A39: 1721 | B39: White Sugar | C39: Carolina | D39: London | J39: =(E39*2240)+(F39*112)+(G39*28)+H39 -> 0 | L39: =J39/2240 -> 0
A40: 1721 | B40: Wood, Braziletto | C40: Carolina | D40: London | E40: 10 | F40: 4 | G40: 3 | H40: 21 | J40: =(E40*2240)+(F40*112)+(G40*28)+H40 -> 22953 | L40: =J40/2240 -> 10.246875
A41: 1721 | B41: Wood, Fustick | C41: Carolina | D41: London | J41: =(E41*2240)+(F41*112)+(G41*28)+H41 -> 0 | L41: =J41/2240 -> 0
A42: 1721 | B42: Wood, Logwood | C42: Carolina | D42: London | J42: =(E42*2240)+(F42*112)+(G42*28)+H42 -> 0 | L42: =J42/2240 -> 0
A43: 1721 | B43: Wood, Redwood | C43: Carolina | D43: London | F43: 6 | J43: =(E43*2240)+(F43*112)+(G43*28)+H43 -> 672 | L43: =J43/2240 -> 0.3
...

Sheet Jamaica
A1: YEAR | B1: COMMODITY_NAME | C1: FROM_LOCATION | D1: TO_LOCATION | E1: ton | F1: hh | G1: quarter | H1: lb | J1: Total Pounds | L1: WEIGHT
A2: 1721 | B2: Almonds, Bitter | C2: Jamaica | D2: London | J2: =(E2*2240)+(F2*112)+(G2*28)+H2 -> 0 | L2: =J2/2240 -> 0
A3: 1721 | B3: Almonds, Sweet | C3: Jamaica | D3: London | J3: =(E3*2240)+(F3*112)+(G3*28)+H3 -> 0 | L3: =J3/2240 -> 0
A4: 1721 | B4: Aloes Epatica | C4: Jamaica | D4: London | J4: =(E4*2240)+(F4*112)+(G4*28)+H4 -> 0 | L4: =J4/2240 -> 0
A5: 1721 | B5: Annatto | C5: Jamaica | D5: London | H5: 221 | J5: =(E5*2240)+(F5*112)+(G5*28)+H5 -> 221 | L5: =J5/2240 -> 0.098660714
A6: 1721 | B6: Anniseeds | C6: Jamaica | D6: London | J6: =(E6*2240)+(F6*112)+(G6*28)+H6 -> 0 | L6: =J6/2240 -> 0
A7: 1721 | B7: Bacon | C7: Jamaica | D7: London | F7: 3 | H7: 20 | J7: =(E7*2240)+(F7*112)+(G7*28)+H7 -> 356 | L7: =J7/2240 -> 0.15892857
A8: 1721 | B8: Barrel Staves | C8: Jamaica | D8: London | J8: =(E8*2240)+(F8*112)+(G8*28)+H8 -> 0 | L8: =J8/2240 -> 0
A9: 1721 | B9: Bees Wax | C9: Jamaica | D9: London | J9: =(E9*2240)+(F9*112)+(G9*28)+H9 -> 0 | L9: =J9/2240 -> 0
A10: 1721 | B10: Brimstone | C10: Jamaica | D10: London | J10: =(E10*2240)+(F10*112)+(G10*28)+H10 -> 0 | L10: =J10/2240 -> 0
A11: 1721 | B11: Brown Sugar | C11: Jamaica | D11: London | F11: 164048 | G11: 1 | H11: 12 | J11: =(E11*2240)+(F11*112)+(G11*28)+H11 -> 18373416 | L11: =J11/2240 -> 8202.4179
A12: 1721 | B12: Cassia Fistula | C12: Jamaica | D12: London | H12: 80 | J12: =(E12*2240)+(F12*112)+(G12*28)+H12 -> 80 | L12: =J12/2240 -> 0.035714286
A13: 1721 | B13: Chocolate Paste | C13: Jamaica | D13: London | J13: =(E13*2240)+(F13*112)+(G13*28)+H13 -> 0 | L13: =J13/2240 -> 0
A14: 1721 | B14: Cocheneal | C14: Jamaica | D14: London | H14: 296 | J14: =(E14*2240)+(F14*112)+(G14*28)+H14 -> 296 | L14: =J14/2240 -> 0.13214286
A15: 1721 | B15: Cocoa Nuts | C15: Jamaica | D15: London | F15: 27 | H15: 2 | J15: =(E15*2240)+(F15*112)+(G15*28)+H15 -> 3026 | L15: =J15/2240 -> 1.3508929
A16: 1721 | B16: Cocoa Paste | C16: Jamaica | D16: London | J16: =(E16*2240)+(F16*112)+(G16*28)+H16 -> 0 | L16: =J16/2240 -> 0
A17: 1721 | B17: Cortex Winteranus | C17: Jamaica | D17: London | H17: 455 | J17: =(E17*2240)+(F17*112)+(G17*28)+H17 -> 455 | L17: =J17/2240 -> 0.203125
A18: 1721 | B18: Cotton | C18: Jamaica | D18: London | H18: =1499.5*200 -> 299900 | I18: 1499.5 bags | J18: =(E18*2240)+(F18*112)+(G18*28)+H18 -> 299900 | L18: =J18/2240 -> 133.88393
A19: 1721 | B19: Dry Ginger | C19: Jamaica | D19: London | F19: 12839 | G19: 1 | H19: 5 | J19: =(E19*2240)+(F19*112)+(G19*28)+H19 -> 1438001 | L19: =J19/2240 -> 641.96473
A20: 1721 | B20: Elephant Teeth | C20: Jamaica | D20: London | F20: 167 | G20: 2 | H20: 2 | J20: =(E20*2240)+(F20*112)+(G20*28)+H20 -> 18762 | L20: =J20/2240 -> 8.3758929
A21: 1721 | B21: Green Ginger | C21: Jamaica | D21: London | J21: =(E21*2240)+(F21*112)+(G21*28)+H21 -> 0 | L21: =J21/2240 -> 0
A22: 1721 | B22: Hemp | C22: Jamaica | D22: London | J22: =(E22*2240)+(F22*112)+(G22*28)+H22 -> 0 | L22: =J22/2240 -> 0
A23: 1721 | B23: Indigo | C23: Jamaica | D23: London | H23: =110105+135238 -> 245343 | J23: =(E23*2240)+(F23*112)+(G23*28)+H23 -> 245343 | L23: =J23/2240 -> 109.52813
A24: 1721 | B24: Lemon Water | C24: Jamaica | D24: London | J24: =(E24*2240)+(F24*112)+(G24*28)+H24 -> 0 | L24: =J24/2240 -> 0
A25: 1721 | B25: Lignum Vitae | C25: Jamaica | D25: London | E25: 7 | F25: 18 | G25: 3 | J25: =(E25*2240)+(F25*112)+(G25*28)+H25 -> 17780 | L25: =J25/2240 -> 7.9375
A26: 1721 | B26: Lime Juice | C26: Jamaica | D26: London | H26: 54055 | I26: 5196g | J26: =(E26*2240)+(F26*112)+(G26*28)+H26 -> 54055 | L26: =J26/2240 -> 24.131696
A27: 1721 | B27: Loaf Sugar | C27: Jamaica | D27: London | J27: =(E27*2240)+(F27*112)+(G27*28)+H27 -> 0 | L27: =J27/2240 -> 0
A28: 1721 | B28: Madera Wine | C28: Jamaica | D28: London | H28: 17712 | I28: 6t 3h 54g | J28: =(E28*2240)+(F28*112)+(G28*28)+H28 -> 17712 | L28: =J28/2240 -> 7.9071429
A29: 1721 | B29: Molasses | C29: Jamaica | D29: London | J29: =(E29*2240)+(F29*112)+(G29*28)+H29 -> 0 | L29: =J29/2240 -> 0
A30: 1721 | B30: Oranges | C30: Jamaica | D30: London | J30: =(E30*2240)+(F30*112)+(G30*28)+H30 -> 0 | L30: =J30/2240 -> 0
A31: 1721 | B31: Pickles | C31: Jamaica | D31: London | J31: =(E31*2240)+(F31*112)+(G31*28)+H31 -> 0 | L31: =J31/2240 -> 0
A32: 1721 | B32: Pimento | C32: Jamaica | D32: London | H32: 187812 | J32: =(E32*2240)+(F32*112)+(G32*28)+H32 -> 187812 | L32: =J32/2240 -> 83.844643
A33: 1721 | B33: Rice | C33: Jamaica | D33: London | F33: 17 | J33: =(E33*2240)+(F33*112)+(G33*28)+H33 -> 1904 | L33: =J33/2240 -> 0.85
A34: 1721 | B34: Rum | C34: Jamaica | D34: London | H34: 299487 | I34: 29674g | J34: =(E34*2240)+(F34*112)+(G34*28)+H34 -> 299487 | L34: =J34/2240 -> 133.69955
A35: 1721 | B35: Sarsparila | C35: Jamaica | D35: London | H35: 1879 | J35: =(E35*2240)+(F35*112)+(G35*28)+H35 -> 1879 | L35: =J35/2240 -> 0.83883929
A36: 1721 | B36: Shruff | C36: Jamaica | D36: London | F36: 45 | H36: 9 | J36: =(E36*2240)+(F36*112)+(G36*28)+H36 -> 5049 | L36: =J36/2240 -> 2.2540179
A37: 1721 | B37: Snuff | C37: Jamaica | D37: London | H37: 6830 | J37: =(E37*2240)+(F37*112)+(G37*28)+H37 -> 6830 | L37: =J37/2240 -> 3.0491071
A38: 1721 | B38: Succads | C38: Jamaica | D38: London | H38: 684 | J38: =(E38*2240)+(F38*112)+(G38*28)+H38 -> 684 | L38: =J38/2240 -> 0.30535714
A39: 1721 | B39: Tobacco | C39: Jamaica | D39: London | J39: =(E39*2240)+(F39*112)+(G39*28)+H39 -> 0 | L39: =J39/2240 -> 0
A40: 1721 | B40: Tortoise Shell | C40: Jamaica | D40: London | H40: 3496 | J40: =(E40*2240)+(F40*112)+(G40*28)+H40 -> 3496 | L40: =J40/2240 -> 1.5607143
...

Sheet Mountserat
A1: YEAR | B1: COMMODITY_NAME | C1: FROM_LOCATION | D1: TO_LOCATION | E1: ton | F1: hh | G1: quarter | H1: lb | J1: Total Pounds | L1: WEIGHT
A2: 1721 | B2: Almonds, Bitter | C2: Mountserat | D2: London | J2: =(E2*2240)+(F2*112)+(G2*28)+H2 -> 0 | L2: =J2/2240 -> 0
A3: 1721 | B3: Almonds, Sweet | C3: Mountserat | D3: London | J3: =(E3*2240)+(F3*112)+(G3*28)+H3 -> 0 | L3: =J3/2240 -> 0
A4: 1721 | B4: Aloes Epatica | C4: Mountserat | D4: London | J4: =(E4*2240)+(F4*112)+(G4*28)+H4 -> 0 | L4: =J4/2240 -> 0
A5: 1721 | B5: Annatto | C5: Mountserat | D5: London | J5: =(E5*2240)+(F5*112)+(G5*28)+H5 -> 0 | L5: =J5/2240 -> 0
A6: 1721 | B6: Anniseeds | C6: Mountserat | D6: London | J6: =(E6*2240)+(F6*112)+(G6*28)+H6 -> 0 | L6: =J6/2240 -> 0
A7: 1721 | B7: Bacon | C7: Mountserat | D7: London | J7: =(E7*2240)+(F7*112)+(G7*28)+H7 -> 0 | L7: =J7/2240 -> 0
A8: 1721 | B8: Barrel Staves | C8: Mountserat | D8: London | J8: =(E8*2240)+(F8*112)+(G8*28)+H8 -> 0 | L8: =J8/2240 -> 0
A9: 1721 | B9: Bees Wax | C9: Mountserat | D9: London | J9: =(E9*2240)+(F9*112)+(G9*28)+H9 -> 0 | L9: =J9/2240 -> 0
A10: 1721 | B10: Brimstone | C10: Mountserat | D10: London | J10: =(E10*2240)+(F10*112)+(G10*28)+H10 -> 0 | L10: =J10/2240 -> 0
A11: 1721 | B11: Brown Sugar | C11: Mountserat | D11: London | F11: 14306 | G11: 3 | H11: 16 | J11: =(E11*2240)+(F11*112)+(G11*28)+H11 -> 1602372 | L11: =J11/2240 -> 715.34464
A12: 1721 | B12: Cassia Fistula | C12: Mountserat | D12: London | J12: =(E12*2240)+(F12*112)+(G12*28)+H12 -> 0 | L12: =J12/2240 -> 0
A13: 1721 | B13: Chocolate Paste | C13: Mountserat | D13: London | J13: =(E13*2240)+(F13*112)+(G13*28)+H13 -> 0 | L13: =J13/2240 -> 0
A14: 1721 | B14: Cocheneal | C14: Mountserat | D14: London | J14: =(E14*2240)+(F14*112)+(G14*28)+H14 -> 0 | L14: =J14/2240 -> 0
A15: 1721 | B15: Cocoa Nuts | C15: Mountserat | D15: London | J15: =(E15*2240)+(F15*112)+(G15*28)+H15 -> 0 | L15: =J15/2240 -> 0
A16: 1721 | B16: Cocoa Paste | C16: Mountserat | D16: London | J16: =(E16*2240)+(F16*112)+(G16*28)+H16 -> 0 | L16: =J16/2240 -> 0
A17: 1721 | B17: Cortex Winteranus | C17: Mountserat | D17: London | J17: =(E17*2240)+(F17*112)+(G17*28)+H17 -> 0 | L17: =J17/2240 -> 0
A18: 1721 | B18: Cotton | C18: Mountserat | D18: London | H18: =99*200 -> 19800 | I18: 99bags | J18: =(E18*2240)+(F18*112)+(G18*28)+H18 -> 19800 | L18: =J18/2240 -> 8.8392857
A19: 1721 | B19: Dry Ginger | C19: Mountserat | D19: London | F19: 102 | J19: =(E19*2240)+(F19*112)+(G19*28)+H19 -> 11424 | L19: =J19/2240 -> 5.1
A20: 1721 | B20: Elephant Teeth | C20: Mountserat | D20: London | F20: 13 | H20: 11 | J20: =(E20*2240)+(F20*112)+(G20*28)+H20 -> 1467 | L20: =J20/2240 -> 0.65491071
A21: 1721 | B21: Green Ginger | C21: Mountserat | D21: London | J21: =(E21*2240)+(F21*112)+(G21*28)+H21 -> 0 | L21: =J21/2240 -> 0
A22: 1721 | B22: Hemp | C22: Mountserat | D22: London | J22: =(E22*2240)+(F22*112)+(G22*28)+H22 -> 0 | L22: =J22/2240 -> 0
A23: 1721 | B23: Indigo | C23: Mountserat | D23: London | H23: 8781 | J23: =(E23*2240)+(F23*112)+(G23*28)+H23 -> 8781 | L23: =J23/2240 -> 3.9200893
A24: 1721 | B24: Lemon Water | C24: Mountserat | D24: London | J24: =(E24*2240)+(F24*112)+(G24*28)+H24 -> 0 | L24: =J24/2240 -> 0
A25: 1721 | B25: Lignum Vitae | C25: Mountserat | D25: London | J25: =(E25*2240)+(F25*112)+(G25*28)+H25 -> 0 | L25: =J25/2240 -> 0
A26: 1721 | B26: Lime Juice | C26: Mountserat | D26: London | J26: =(E26*2240)+(F26*112)+(G26*28)+H26 -> 0 | L26: =J26/2240 -> 0
A27: 1721 | B27: Loaf Sugar | C27: Mountserat | D27: London | J27: =(E27*2240)+(F27*112)+(G27*28)+H27 -> 0 | L27: =J27/2240 -> 0
A28: 1721 | B28: Madera Wine | C28: Mountserat | D28: London | H28: 787 | I28: 78g | J28: =(E28*2240)+(F28*112)+(G28*28)+H28 -> 787 | L28: =J28/2240 -> 0.35133929
A29: 1721 | B29: Molasses | C29: Mountserat | D29: London | J29: =(E29*2240)+(F29*112)+(G29*28)+H29 -> 0 | L29: =J29/2240 -> 0
A30: 1721 | B30: Oranges | C30: Mountserat | D30: London | J30: =(E30*2240)+(F30*112)+(G30*28)+H30 -> 0 | L30: =J30/2240 -> 0
A31: 1721 | B31: Pickles | C31: Mountserat | D31: London | J31: =(E31*2240)+(F31*112)+(G31*28)+H31 -> 0 | L31: =J31/2240 -> 0
A32: 1721 | B32: Pimento | C32: Mountserat | D32: London | J32: =(E32*2240)+(F32*112)+(G32*28)+H32 -> 0 | L32: =J32/2240 -> 0
A33: 1721 | B33: Rice | C33: Mountserat | D33: London | J33: =(E33*2240)+(F33*112)+(G33*28)+H33 -> 0 | L33: =J33/2240 -> 0
A34: 1721 | B34: Rum | C34: Mountserat | D34: London | H34: 6146 | I34: 609g | J34: =(E34*2240)+(F34*112)+(G34*28)+H34 -> 6146 | L34: =J34/2240 -> 2.74375
A35: 1721 | B35: Sarsparila | C35: Mountserat | D35: London | J35: =(E35*2240)+(F35*112)+(G35*28)+H35 -> 0 | L35: =J35/2240 -> 0
A36: 1721 | B36: Shruff | C36: Mountserat | D36: London | F36: 17 | H36: 21 | J36: =(E36*2240)+(F36*112)+(G36*28)+H36 -> 1925 | L36: =J36/2240 -> 0.859375
A37: 1721 | B37: Snuff | C37: Mountserat | D37: London | J37: =(E37*2240)+(F37*112)+(G37*28)+H37 -> 0 | L37: =J37/2240 -> 0
A38: 1721 | B38: Succads | C38: Mountserat | D38: London | H38: 20 | J38: =(E38*2240)+(F38*112)+(G38*28)+H38 -> 20 | L38: =J38/2240 -> 0.0089285714
A39: 1721 | B39: Tobacco | C39: Mountserat | D39: London | J39: =(E39*2240)+(F39*112)+(G39*28)+H39 -> 0 | L39: =J39/2240 -> 0
A40: 1721 | B40: Tortoise Shell | C40: Mountserat | D40: London | J40: =(E40*2240)+(F40*112)+(G40*28)+H40 -> 0 | L40: =J40/2240 -> 0
...

Sheet Nevis
A1: YEAR | B1: COMMODITY_NAME | C1: FROM_LOCATION | D1: TO_LOCATION | E1: ton | F1: hh | G1: quarter | H1: lb | J1: Total Pounds | L1: WEIGHT
A2: 1721 | B2: Almonds, Bitter | C2: Nevis | D2: London | J2: =(E2*2240)+(F2*112)+(G2*28)+H2 -> 0 | L2: =J2/2240 -> 0
A3: 1721 | B3: Almonds, Sweet | C3: Nevis | D3: London | J3: =(E3*2240)+(F3*112)+(G3*28)+H3 -> 0 | L3: =J3/2240 -> 0
A4: 1721 | B4: Aloes Epatica | C4: Nevis | D4: London | J4: =(E4*2240)+(F4*112)+(G4*28)+H4 -> 0 | L4: =J4/2240 -> 0
A5: 1721 | B5: Annatto | C5: Nevis | D5: London | J5: =(E5*2240)+(F5*112)+(G5*28)+H5 -> 0 | L5: =J5/2240 -> 0
A6: 1721 | B6: Anniseeds | C6: Nevis | D6: London | J6: =(E6*2240)+(F6*112)+(G6*28)+H6 -> 0 | L6: =J6/2240 -> 0
A7: 1721 | B7: Bacon | C7: Nevis | D7: London | J7: =(E7*2240)+(F7*112)+(G7*28)+H7 -> 0 | L7: =J7/2240 -> 0
A8: 1721 | B8: Barrel Staves | C8: Nevis | D8: London | J8: =(E8*2240)+(F8*112)+(G8*28)+H8 -> 0 | L8: =J8/2240 -> 0
A9: 1721 | B9: Bees Wax | C9: Nevis | D9: London | J9: =(E9*2240)+(F9*112)+(G9*28)+H9 -> 0 | L9: =J9/2240 -> 0
A10: 1721 | B10: Brimstone | C10: Nevis | D10: London | J10: =(E10*2240)+(F10*112)+(G10*28)+H10 -> 0 | L10: =J10/2240 -> 0
A11: 1721 | B11: Brown Sugar | C11: Nevis | D11: London | F11: 30870 | G11: 2 | H11: 17 | J11: =(E11*2240)+(F11*112)+(G11*28)+H11 -> 3457513 | L11: =J11/2240 -> 1543.5326
A12: 1721 | B12: Cassia Fistula | C12: Nevis | D12: London | J12: =(E12*2240)+(F12*112)+(G12*28)+H12 -> 0 | L12: =J12/2240 -> 0
A13: 1721 | B13: Chocolate Paste | C13: Nevis | D13: London | J13: =(E13*2240)+(F13*112)+(G13*28)+H13 -> 0 | L13: =J13/2240 -> 0
A14: 1721 | B14: Cocheneal | C14: Nevis | D14: London | J14: =(E14*2240)+(F14*112)+(G14*28)+H14 -> 0 | L14: =J14/2240 -> 0
A15: 1721 | B15: Cocoa Nuts | C15: Nevis | D15: London | J15: =(E15*2240)+(F15*112)+(G15*28)+H15 -> 0 | L15: =J15/2240 -> 0
A16: 1721 | B16: Cocoa Paste | C16: Nevis | D16: London | J16: =(E16*2240)+(F16*112)+(G16*28)+H16 -> 0 | L16: =J16/2240 -> 0
A17: 1721 | B17: Cortex Winteranus | C17: Nevis | D17: London | J17: =(E17*2240)+(F17*112)+(G17*28)+H17 -> 0 | L17: =J17/2240 -> 0
A18: 1721 | B18: Cotton | C18: Nevis | D18: London | H18: =39*200 -> 7800 | I18: 39bags | J18: =(E18*2240)+(F18*112)+(G18*28)+H18 -> 7800 | L18: =J18/2240 -> 3.4821429
A19: 1721 | B19: Dry Ginger | C19: Nevis | D19: London | F19: 10 | G19: 1 | H19: 21 | J19: =(E19*2240)+(F19*112)+(G19*28)+H19 -> 1169 | L19: =J19/2240 -> 0.521875
A20: 1721 | B20: Elephant Teeth | C20: Nevis | D20: London | J20: =(E20*2240)+(F20*112)+(G20*28)+H20 -> 0 | L20: =J20/2240 -> 0
A21: 1721 | B21: Green Ginger | C21: Nevis | D21: London | J21: =(E21*2240)+(F21*112)+(G21*28)+H21 -> 0 | L21: =J21/2240 -> 0
A22: 1721 | B22: Hemp | C22: Nevis | D22: London | J22: =(E22*2240)+(F22*112)+(G22*28)+H22 -> 0 | L22: =J22/2240 -> 0
A23: 1721 | B23: Indigo | C23: Nevis | D23: London | H23: 21 | J23: =(E23*2240)+(F23*112)+(G23*28)+H23 -> 21 | L23: =J23/2240 -> 0.009375
A24: 1721 | B24: Lemon Water | C24: Nevis | D24: London | J24: =(E24*2240)+(F24*112)+(G24*28)+H24 -> 0 | L24: =J24/2240 -> 0
A25: 1721 | B25: Lignum Vitae | C25: Nevis | D25: London | E25: 1 | J25: =(E25*2240)+(F25*112)+(G25*28)+H25 -> 2240 | L25: =J25/2240 -> 1
A26: 1721 | B26: Lime Juice | C26: Nevis | D26: London | J26: =(E26*2240)+(F26*112)+(G26*28)+H26 -> 0 | L26: =J26/2240 -> 0
A27: 1721 | B27: Loaf Sugar | C27: Nevis | D27: London | J27: =(E27*2240)+(F27*112)+(G27*28)+H27 -> 0 | L27: =J27/2240 -> 0
A28: 1721 | B28: Madera Wine | C28: Nevis | D28: London | H28: 1827 | I28: 2h 55g | J28: =(E28*2240)+(F28*112)+(G28*28)+H28 -> 1827 | L28: =J28/2240 -> 0.815625
A29: 1721 | B29: Molasses | C29: Nevis | D29: London | F29: 2 | G29: 2 | H29: 9 | J29: =(E29*2240)+(F29*112)+(G29*28)+H29 -> 289 | L29: =J29/2240 -> 0.12901786
A30: 1721 | B30: Oranges | C30: Nevis | D30: London | J30: =(E30*2240)+(F30*112)+(G30*28)+H30 -> 0 | L30: =J30/2240 -> 0
A31: 1721 | B31: Pickles | C31: Nevis | D31: London | J31: =(E31*2240)+(F31*112)+(G31*28)+H31 -> 0 | L31: =J31/2240 -> 0
A32: 1721 | B32: Pimento | C32: Nevis | D32: London | J32: =(E32*2240)+(F32*112)+(G32*28)+H32 -> 0 | L32: =J32/2240 -> 0
A33: 1721 | B33: Rice | C33: Nevis | D33: London | J33: =(E33*2240)+(F33*112)+(G33*28)+H33 -> 0 | L33: =J33/2240 -> 0
A34: 1721 | B34: Rum | C34: Nevis | D34: London | H34: 3230 | I34: 320g | J34: =(E34*2240)+(F34*112)+(G34*28)+H34 -> 3230 | L34: =J34/2240 -> 1.4419643
A35: 1721 | B35: Sarsparila | C35: Nevis | D35: London | J35: =(E35*2240)+(F35*112)+(G35*28)+H35 -> 0 | L35: =J35/2240 -> 0
A36: 1721 | B36: Shruff | C36: Nevis | D36: London | F36: 13 | G36: 2 | H36: 25 | J36: =(E36*2240)+(F36*112)+(G36*28)+H36 -> 1537 | L36: =J36/2240 -> 0.68616071
A37: 1721 | B37: Snuff | C37: Nevis | D37: London | J37: =(E37*2240)+(F37*112)+(G37*28)+H37 -> 0 | L37: =J37/2240 -> 0
A38: 1721 | B38: Succads | C38: Nevis | D38: London | H38: 18 | J38: =(E38*2240)+(F38*112)+(G38*28)+H38 -> 18 | L38: =J38/2240 -> 0.0080357143
A39: 1721 | B39: Tobacco | C39: Nevis | D39: London | J39: =(E39*2240)+(F39*112)+(G39*28)+H39 -> 0 | L39: =J39/2240 -> 0
A40: 1721 | B40: Tortoise Shell | C40: Nevis | D40: London | H40: 44 | J40: =(E40*2240)+(F40*112)+(G40*28)+H40 -> 44 | L40: =J40/2240 -> 0.019642857
...

Sheet St Kitts
A1: YEAR | B1: COMMODITY_NAME | C1: FROM_LOCATION | D1: TO_LOCATION | E1: ton | F1: hh | G1: quarter | H1: lb | J1: Total Pounds | L1: WEIGHT
A2: 1721 | B2: Almonds, Bitter | C2: StKitts | D2: London | J2: =(E2*2240)+(F2*112)+(G2*28)+H2 -> 0 | L2: =J2/2240 -> 0
A3: 1721 | B3: Almonds, Sweet | C3: StKitts | D3: London | J3: =(E3*2240)+(F3*112)+(G3*28)+H3 -> 0 | L3: =J3/2240 -> 0
A4: 1721 | B4: Aloes Epatica | C4: StKitts | D4: London | J4: =(E4*2240)+(F4*112)+(G4*28)+H4 -> 0 | L4: =J4/2240 -> 0
A5: 1721 | B5: Annatto | C5: StKitts | D5: London | J5: =(E5*2240)+(F5*112)+(G5*28)+H5 -> 0 | L5: =J5/2240 -> 0
A6: 1721 | B6: Anniseeds | C6: StKitts | D6: London | J6: =(E6*2240)+(F6*112)+(G6*28)+H6 -> 0 | L6: =J6/2240 -> 0
A7: 1721 | B7: Bacon | C7: StKitts | D7: London | J7: =(E7*2240)+(F7*112)+(G7*28)+H7 -> 0 | L7: =J7/2240 -> 0
A8: 1721 | B8: Barrel Staves | C8: StKitts | D8: London | J8: =(E8*2240)+(F8*112)+(G8*28)+H8 -> 0 | L8: =J8/2240 -> 0
A9: 1721 | B9: Bees Wax | C9: StKitts | D9: London | J9: =(E9*2240)+(F9*112)+(G9*28)+H9 -> 0 | L9: =J9/2240 -> 0
A10: 1721 | B10: Brimstone | C10: StKitts | D10: London | J10: =(E10*2240)+(F10*112)+(G10*28)+H10 -> 0 | L10: =J10/2240 -> 0
A11: 1721 | B11: Brown Sugar | C11: StKitts | D11: London | F11: 54208 | G11: 1 | H11: 14 | J11: =(E11*2240)+(F11*112)+(G11*28)+H11 -> 6071338 | L11: =J11/2240 -> 2710.4187
A12: 1721 | B12: Cassia Fistula | C12: StKitts | D12: London | J12: =(E12*2240)+(F12*112)+(G12*28)+H12 -> 0 | L12: =J12/2240 -> 0
A13: 1721 | B13: Chocolate Paste | C13: StKitts | D13: London | J13: =(E13*2240)+(F13*112)+(G13*28)+H13 -> 0 | L13: =J13/2240 -> 0
A14: 1721 | B14: Cocheneal | C14: StKitts | D14: London | J14: =(E14*2240)+(F14*112)+(G14*28)+H14 -> 0 | L14: =J14/2240 -> 0
A15: 1721 | B15: Cocoa Nuts | C15: StKitts | D15: London | H15: 20 | J15: =(E15*2240)+(F15*112)+(G15*28)+H15 -> 20 | L15: =J15/2240 -> 0.0089285714
A16: 1721 | B16: Cocoa Paste | C16: StKitts | D16: London | J16: =(E16*2240)+(F16*112)+(G16*28)+H16 -> 0 | L16: =J16/2240 -> 0
A17: 1721 | B17: Cortex Winteranus | C17: StKitts | D17: London | J17: =(E17*2240)+(F17*112)+(G17*28)+H17 -> 0 | L17: =J17/2240 -> 0
A18: 1721 | B18: Cotton | C18: StKitts | D18: London | H18: =147*200 -> 29400 | I18: 147bags | J18: =(E18*2240)+(F18*112)+(G18*28)+H18 -> 29400 | L18: =J18/2240 -> 13.125
A19: 1721 | B19: Dry Ginger | C19: StKitts | D19: London | F19: 43 | H19: 14 | J19: =(E19*2240)+(F19*112)+(G19*28)+H19 -> 4830 | L19: =J19/2240 -> 2.15625
A20: 1721 | B20: Elephant Teeth | C20: StKitts | D20: London | G20: 2 | H20: 7 | J20: =(E20*2240)+(F20*112)+(G20*28)+H20 -> 63 | L20: =J20/2240 -> 0.028125
A21: 1721 | B21: Green Ginger | C21: StKitts | D21: London | J21: =(E21*2240)+(F21*112)+(G21*28)+H21 -> 0 | L21: =J21/2240 -> 0
A22: 1721 | B22: Hemp | C22: StKitts | D22: London | J22: =(E22*2240)+(F22*112)+(G22*28)+H22 -> 0 | L22: =J22/2240 -> 0
A23: 1721 | B23: Indigo | C23: StKitts | D23: London | H23: 162 | J23: =(E23*2240)+(F23*112)+(G23*28)+H23 -> 162 | L23: =J23/2240 -> 0.072321429
A24: 1721 | B24: Lemon Water | C24: StKitts | D24: London | J24: =(E24*2240)+(F24*112)+(G24*28)+H24 -> 0 | L24: =J24/2240 -> 0
A25: 1721 | B25: Lignum Vitae | C25: StKitts | D25: London | E25: 8 | F25: 13 | G25: 1 | H25: 8 | J25: =(E25*2240)+(F25*112)+(G25*28)+H25 -> 19412 | L25: =J25/2240 -> 8.6660714
A26: 1721 | B26: Lime Juice | C26: StKitts | D26: London | J26: =(E26*2240)+(F26*112)+(G26*28)+H26 -> 0 | L26: =J26/2240 -> 0
A27: 1721 | B27: Loaf Sugar | C27: StKitts | D27: London | J27: =(E27*2240)+(F27*112)+(G27*28)+H27 -> 0 | L27: =J27/2240 -> 0
A28: 1721 | B28: Madera Wine | C28: StKitts | D28: London | H28: 7135 | I28: 2t 3h 14g | J28: =(E28*2240)+(F28*112)+(G28*28)+H28 -> 7135 | L28: =J28/2240 -> 3.1852679
A29: 1721 | B29: Molasses | C29: StKitts | D29: London | F29: 8 | G29: 1 | J29: =(E29*2240)+(F29*112)+(G29*28)+H29 -> 924 | L29: =J29/2240 -> 0.4125
A30: 1721 | B30: Oranges | C30: StKitts | D30: London | J30: =(E30*2240)+(F30*112)+(G30*28)+H30 -> 0 | L30: =J30/2240 -> 0
A31: 1721 | B31: Pickles | C31: StKitts | D31: London | J31: =(E31*2240)+(F31*112)+(G31*28)+H31 -> 0 | L31: =J31/2240 -> 0
A32: 1721 | B32: Pimento | C32: StKitts | D32: London | J32: =(E32*2240)+(F32*112)+(G32*28)+H32 -> 0 | L32: =J32/2240 -> 0
A33: 1721 | B33: Rice | C33: StKitts | D33: London | J33: =(E33*2240)+(F33*112)+(G33*28)+H33 -> 0 | L33: =J33/2240 -> 0
A34: 1721 | B34: Rum | C34: StKitts | D34: London | H34: 15472 | I34: 1533g | J34: =(E34*2240)+(F34*112)+(G34*28)+H34 -> 15472 | L34: =J34/2240 -> 6.9071429
A35: 1721 | B35: Sarsparila | C35: StKitts | D35: London | J35: =(E35*2240)+(F35*112)+(G35*28)+H35 -> 0 | L35: =J35/2240 -> 0
A36: 1721 | B36: Shruff | C36: StKitts | D36: London | F36: 31 | G36: 3 | H36: 27 | J36: =(E36*2240)+(F36*112)+(G36*28)+H36 -> 3583 | L36: =J36/2240 -> 1.5995536
A37: 1721 | B37: Snuff | C37: StKitts | D37: London | J37: =(E37*2240)+(F37*112)+(G37*28)+H37 -> 0 | L37: =J37/2240 -> 0
A38: 1721 | B38: Succads | C38: StKitts | D38: London | H38: 250 | J38: =(E38*2240)+(F38*112)+(G38*28)+H38 -> 250 | L38: =J38/2240 -> 0.11160714
A39: 1721 | B39: Tobacco | C39: StKitts | D39: London | J39: =(E39*2240)+(F39*112)+(G39*28)+H39 -> 0 | L39: =J39/2240 -> 0
A40: 1721 | B40: Tortoise Shell | C40: StKitts | D40: London | J40: =(E40*2240)+(F40*112)+(G40*28)+H40 -> 0 | L40: =J40/2240 -> 0
...

Sheet NewEngland
A1: YEAR | B1: COMMODITY_NAME | C1: FROM_LOCATION | D1: TO_LOCATION | E1: ton | F1: hh | G1: quarter | H1: lb | J1: Total Pounds | L1: WEIGHT
A2: 1721 | B2: Almonds, Bitter | C2: NewEngland | D2: London | J2: =(E2*2240)+(F2*112)+(G2*28)+H2 -> 0 | L2: =J2/2240 -> 0
A3: 1721 | B3: Almonds, Sweet | C3: NewEngland | D3: London | J3: =(E3*2240)+(F3*112)+(G3*28)+H3 -> 0 | L3: =J3/2240 -> 0
A4: 1721 | B4: Aloes Epatica | C4: NewEngland | D4: London | J4: =(E4*2240)+(F4*112)+(G4*28)+H4 -> 0 | L4: =J4/2240 -> 0
A5: 1721 | B5: Annatto | C5: NewEngland | D5: London | H5: 451 | J5: =(E5*2240)+(F5*112)+(G5*28)+H5 -> 451 | L5: =J5/2240 -> 0.20133929
A6: 1721 | B6: Anniseeds | C6: NewEngland | D6: London | J6: =(E6*2240)+(F6*112)+(G6*28)+H6 -> 0 | L6: =J6/2240 -> 0
A7: 1721 | B7: Bacon | C7: NewEngland | D7: London | J7: =(E7*2240)+(F7*112)+(G7*28)+H7 -> 0 | L7: =J7/2240 -> 0
A8: 1721 | B8: Barrel Staves | C8: NewEngland | D8: London | J8: =(E8*2240)+(F8*112)+(G8*28)+H8 -> 0 | L8: =J8/2240 -> 0
A9: 1721 | B9: Bees Wax | C9: NewEngland | D9: London | H9: 12 | J9: =(E9*2240)+(F9*112)+(G9*28)+H9 -> 12 | L9: =J9/2240 -> 0.0053571429
A10: 1721 | B10: Brimstone | C10: NewEngland | D10: London | J10: =(E10*2240)+(F10*112)+(G10*28)+H10 -> 0 | L10: =J10/2240 -> 0
A11: 1721 | B11: Brown Sugar | C11: NewEngland | D11: London | F11: 805 | G11: 2 | H11: 23 | J11: =(E11*2240)+(F11*112)+(G11*28)+H11 -> 90239 | L11: =J11/2240 -> 40.285268
A12: 1721 | B12: Cassia Fistula | C12: NewEngland | D12: London | J12: =(E12*2240)+(F12*112)+(G12*28)+H12 -> 0 | L12: =J12/2240 -> 0
A13: 1721 | B13: Chocolate Paste | C13: NewEngland | D13: London | J13: =(E13*2240)+(F13*112)+(G13*28)+H13 -> 0 | L13: =J13/2240 -> 0
A14: 1721 | B14: Cocheneal | C14: NewEngland | D14: London | J14: =(E14*2240)+(F14*112)+(G14*28)+H14 -> 0 | L14: =J14/2240 -> 0
A15: 1721 | B15: Cocoa Nuts | C15: NewEngland | D15: London | F15: 8 | G15: 3 | H15: 17 | J15: =(E15*2240)+(F15*112)+(G15*28)+H15 -> 997 | L15: =J15/2240 -> 0.44508929
A16: 1721 | B16: Cocoa Paste | C16: NewEngland | D16: London | J16: =(E16*2240)+(F16*112)+(G16*28)+H16 -> 0 | L16: =J16/2240 -> 0
A17: 1721 | B17: Cortex Winteranus | C17: NewEngland | D17: London | J17: =(E17*2240)+(F17*112)+(G17*28)+H17 -> 0 | L17: =J17/2240 -> 0
A18: 1721 | B18: Cotton | C18: NewEngland | D18: London | H18: 200 | I18: 1 bag | J18: =(E18*2240)+(F18*112)+(G18*28)+H18 -> 200 | L18: =J18/2240 -> 0.089285714
A19: 1721 | B19: Dry Ginger | C19: NewEngland | D19: London | J19: =(E19*2240)+(F19*112)+(G19*28)+H19 -> 0 | L19: =J19/2240 -> 0
A20: 1721 | B20: Elephant Teeth | C20: NewEngland | D20: London | J20: =(E20*2240)+(F20*112)+(G20*28)+H20 -> 0 | L20: =J20/2240 -> 0
A21: 1721 | B21: Green Ginger | C21: NewEngland | D21: London | J21: =(E21*2240)+(F21*112)+(G21*28)+H21 -> 0 | L21: =J21/2240 -> 0
