Workbook

Sheet Master Goods Sheet
A1: Item | B1: Total London | C1: Total Outports | D1: Total
A2: Annatto | B2: =SUMIFS(Antigua!$L:$L, Antigua!$B:$B, $A2, Antigua!$D:$D, "London") + SUMIFS(Barbados!$L:$L, Barbados!$B:$B, $A2, Barbados!$D:$D, "London") + SUMIFS(Bermuda!$L:$L, Bermuda!$B:$B, $A2, Bermuda!$D:$D, "London") + SUMIFS(Jamaica!$L:$L, Jamaica!$B:$B, $A2, Jamaica!$D:$D, "London") + SUMIFS(Mountserat!$L:$L, Mountserat!$B:$B, $A2, Mountserat!$D:$D, "London") + SUMIFS(Nevis!$L:$L, Nevis!$B:$B, $A2, Nevis!$D:$D, "London") + SUMIFS('St Kitts'!$L:$L, 'St Kitts'!$B:$B, $A2, 'St Kitts'!$D:$D, "London") + SUMIFS(General!$L:$L, General!$B:$B, $A2, General!$D:$D, "London") -> 0.058035714 | C2: =SUMIFS(Antigua!$L:$L, Antigua!$B:$B, $A2, Antigua!$D:$D, "Out Ports") + SUMIFS(Barbados!$L:$L, Barbados!$B:$B, $A2, Barbados!$D:$D, "Out Ports") + SUMIFS(Bermuda!$L:$L, Bermuda!$B:$B, $A2, Bermuda!$D:$D, "Out Ports") + SUMIFS(Jamaica!$L:$L, Jamaica!$B:$B, $A2, Jamaica!$D:$D, "Out Ports") + SUMIFS(Mountserat!$L:$L, Mountserat!$B:$B, $A2, Mountserat!$D:$D, "Out Ports") + SUMIFS(Nevis!$L:$L, Nevis!$B:$B, $A2, Nevis!$D:$D, "Out Ports") + SUMIFS('St Kitts'!$L:$L, 'St Kitts'!$B:$B, $A2, 'St Kitts'!$D:$D, "Out Ports") + SUMIFS(General!$L:$L, General!$B:$B, $A2, General!$D:$D, "Out Ports") -> 0 | D2: =ROUND((B2+C2),2) -> 0.06
A3: Bees Wax | B3: =SUMIFS(Antigua!$L:$L, Antigua!$B:$B, $A3, Antigua!$D:$D, "London") + SUMIFS(Barbados!$L:$L, Barbados!$B:$B, $A3, Barbados!$D:$D, "London") + SUMIFS(Bermuda!$L:$L, Bermuda!$B:$B, $A3, Bermuda!$D:$D, "London") + SUMIFS(Jamaica!$L:$L, Jamaica!$B:$B, $A3, Jamaica!$D:$D, "London") + SUMIFS(Mountserat!$L:$L, Mountserat!$B:$B, $A3, Mountserat!$D:$D, "London") + SUMIFS(Nevis!$L:$L, Nevis!$B:$B, $A3, Nevis!$D:$D, "London") + SUMIFS('St Kitts'!$L:$L, 'St Kitts'!$B:$B, $A3, 'St Kitts'!$D:$D, "London") + SUMIFS(General!$L:$L, General!$B:$B, $A3, General!$D:$D, "London") -> 0.43035714 | C3: =SUMIFS(Antigua!$L:$L, Antigua!$B:$B, $A3, Antigua!$D:$D, "Out Ports") + SUMIFS(Barbados!$L:$L, Barbados!$B:$B, $A3, Barbados!$D:$D, "Out Ports") + SUMIFS(Bermuda!$L:$L, Bermuda!$B:$B, $A3, Bermuda!$D:$D, "Out Ports") + SUMIFS(Jamaica!$L:$L, Jamaica!$B:$B, $A3, Jamaica!$D:$D, "Out Ports") + SUMIFS(Mountserat!$L:$L, Mountserat!$B:$B, $A3, Mountserat!$D:$D, "Out Ports") + SUMIFS(Nevis!$L:$L, Nevis!$B:$B, $A3, Nevis!$D:$D, "Out Ports") + SUMIFS('St Kitts'!$L:$L, 'St Kitts'!$B:$B, $A3, 'St Kitts'!$D:$D, "Out Ports") + SUMIFS(General!$L:$L, General!$B:$B, $A3, General!$D:$D, "Out Ports") -> 0.63571429 | D3: =ROUND((B3+C3),2) -> 1.07
A4: Brown Sugar | B4: =SUMIFS(Antigua!$L:$L, Antigua!$B:$B, $A4, Antigua!$D:$D, "London") + SUMIFS(Barbados!$L:$L, Barbados!$B:$B, $A4, Barbados!$D:$D, "London") + SUMIFS(Bermuda!$L:$L, Bermuda!$B:$B, $A4, Bermuda!$D:$D, "London") + SUMIFS(Jamaica!$L:$L, Jamaica!$B:$B, $A4, Jamaica!$D:$D, "London") + SUMIFS(Mountserat!$L:$L, Mountserat!$B:$B, $A4, Mountserat!$D:$D, "London") + SUMIFS(Nevis!$L:$L, Nevis!$B:$B, $A4, Nevis!$D:$D, "London") + SUMIFS('St Kitts'!$L:$L, 'St Kitts'!$B:$B, $A4, 'St Kitts'!$D:$D, "London") + SUMIFS(General!$L:$L, General!$B:$B, $A4, General!$D:$D, "London") -> 25980.199 | C4: =SUMIFS(Antigua!$L:$L, Antigua!$B:$B, $A4, Antigua!$D:$D, "Out Ports") + SUMIFS(Barbados!$L:$L, Barbados!$B:$B, $A4, Barbados!$D:$D, "Out Ports") + SUMIFS(Bermuda!$L:$L, Bermuda!$B:$B, $A4, Bermuda!$D:$D, "Out Ports") + SUMIFS(Jamaica!$L:$L, Jamaica!$B:$B, $A4, Jamaica!$D:$D, "Out Ports") + SUMIFS(Mountserat!$L:$L, Mountserat!$B:$B, $A4, Mountserat!$D:$D, "Out Ports") + SUMIFS(Nevis!$L:$L, Nevis!$B:$B, $A4, Nevis!$D:$D, "Out Ports") + SUMIFS('St Kitts'!$L:$L, 'St Kitts'!$B:$B, $A4, 'St Kitts'!$D:$D, "Out Ports") + SUMIFS(General!$L:$L, General!$B:$B, $A4, General!$D:$D, "Out Ports") -> 6964.0321 | D4: =ROUND((B4+C4),2) -> 32944.23
A5: Chocolate | B5: =SUMIFS(Antigua!$L:$L, Antigua!$B:$B, $A5, Antigua!$D:$D, "London") + SUMIFS(Barbados!$L:$L, Barbados!$B:$B, $A5, Barbados!$D:$D, "London") + SUMIFS(Bermuda!$L:$L, Bermuda!$B:$B, $A5, Bermuda!$D:$D, "London") + SUMIFS(Jamaica!$L:$L, Jamaica!$B:$B, $A5, Jamaica!$D:$D, "London") + SUMIFS(Mountserat!$L:$L, Mountserat!$B:$B, $A5, Mountserat!$D:$D, "London") + SUMIFS(Nevis!$L:$L, Nevis!$B:$B, $A5, Nevis!$D:$D, "London") + SUMIFS('St Kitts'!$L:$L, 'St Kitts'!$B:$B, $A5, 'St Kitts'!$D:$D, "London") + SUMIFS(General!$L:$L, General!$B:$B, $A5, General!$D:$D, "London") -> 0 | C5: =SUMIFS(Antigua!$L:$L, Antigua!$B:$B, $A5, Antigua!$D:$D, "Out Ports") + SUMIFS(Barbados!$L:$L, Barbados!$B:$B, $A5, Barbados!$D:$D, "Out Ports") + SUMIFS(Bermuda!$L:$L, Bermuda!$B:$B, $A5, Bermuda!$D:$D, "Out Ports") + SUMIFS(Jamaica!$L:$L, Jamaica!$B:$B, $A5, Jamaica!$D:$D, "Out Ports") + SUMIFS(Mountserat!$L:$L, Mountserat!$B:$B, $A5, Mountserat!$D:$D, "Out Ports") + SUMIFS(Nevis!$L:$L, Nevis!$B:$B, $A5, Nevis!$D:$D, "Out Ports") + SUMIFS('St Kitts'!$L:$L, 'St Kitts'!$B:$B, $A5, 'St Kitts'!$D:$D, "Out Ports") + SUMIFS(General!$L:$L, General!$B:$B, $A5, General!$D:$D, "Out Ports") -> 0 | D5: =ROUND((B5+C5),2) -> 0
A6: Cocoa Nuts | B6: =SUMIFS(Antigua!$L:$L, Antigua!$B:$B, $A6, Antigua!$D:$D, "London") + SUMIFS(Barbados!$L:$L, Barbados!$B:$B, $A6, Barbados!$D:$D, "London") + SUMIFS(Bermuda!$L:$L, Bermuda!$B:$B, $A6, Bermuda!$D:$D, "London") + SUMIFS(Jamaica!$L:$L, Jamaica!$B:$B, $A6, Jamaica!$D:$D, "London") + SUMIFS(Mountserat!$L:$L, Mountserat!$B:$B, $A6, Mountserat!$D:$D, "London") + SUMIFS(Nevis!$L:$L, Nevis!$B:$B, $A6, Nevis!$D:$D, "London") + SUMIFS('St Kitts'!$L:$L, 'St Kitts'!$B:$B, $A6, 'St Kitts'!$D:$D, "London") + SUMIFS(General!$L:$L, General!$B:$B, $A6, General!$D:$D, "London") -> 6.8138393 | C6: =SUMIFS(Antigua!$L:$L, Antigua!$B:$B, $A6, Antigua!$D:$D, "Out Ports") + SUMIFS(Barbados!$L:$L, Barbados!$B:$B, $A6, Barbados!$D:$D, "Out Ports") + SUMIFS(Bermuda!$L:$L, Bermuda!$B:$B, $A6, Bermuda!$D:$D, "Out Ports") + SUMIFS(Jamaica!$L:$L, Jamaica!$B:$B, $A6, Jamaica!$D:$D, "Out Ports") + SUMIFS(Mountserat!$L:$L, Mountserat!$B:$B, $A6, Mountserat!$D:$D, "Out Ports") + SUMIFS(Nevis!$L:$L, Nevis!$B:$B, $A6, Nevis!$D:$D, "Out Ports") + SUMIFS('St Kitts'!$L:$L, 'St Kitts'!$B:$B, $A6, 'St Kitts'!$D:$D, "Out Ports") + SUMIFS(General!$L:$L, General!$B:$B, $A6, General!$D:$D, "Out Ports") -> 2.2571429 | D6: =ROUND((B6+C6),2) -> 9.07
A7: Cotton | B7: =SUMIFS(Antigua!$L:$L, Antigua!$B:$B, $A7, Antigua!$D:$D, "London") + SUMIFS(Barbados!$L:$L, Barbados!$B:$B, $A7, Barbados!$D:$D, "London") + SUMIFS(Bermuda!$L:$L, Bermuda!$B:$B, $A7, Bermuda!$D:$D, "London") + SUMIFS(Jamaica!$L:$L, Jamaica!$B:$B, $A7, Jamaica!$D:$D, "London") + SUMIFS(Mountserat!$L:$L, Mountserat!$B:$B, $A7, Mountserat!$D:$D, "London") + SUMIFS(Nevis!$L:$L, Nevis!$B:$B, $A7, Nevis!$D:$D, "London") + SUMIFS('St Kitts'!$L:$L, 'St Kitts'!$B:$B, $A7, 'St Kitts'!$D:$D, "London") + SUMIFS(General!$L:$L, General!$B:$B, $A7, General!$D:$D, "London") -> 238.57143 | C7: =SUMIFS(Antigua!$L:$L, Antigua!$B:$B, $A7, Antigua!$D:$D, "Out Ports") + SUMIFS(Barbados!$L:$L, Barbados!$B:$B, $A7, Barbados!$D:$D, "Out Ports") + SUMIFS(Bermuda!$L:$L, Bermuda!$B:$B, $A7, Bermuda!$D:$D, "Out Ports") + SUMIFS(Jamaica!$L:$L, Jamaica!$B:$B, $A7, Jamaica!$D:$D, "Out Ports") + SUMIFS(Mountserat!$L:$L, Mountserat!$B:$B, $A7, Mountserat!$D:$D, "Out Ports") + SUMIFS(Nevis!$L:$L, Nevis!$B:$B, $A7, Nevis!$D:$D, "Out Ports") + SUMIFS('St Kitts'!$L:$L, 'St Kitts'!$B:$B, $A7, 'St Kitts'!$D:$D, "Out Ports") + SUMIFS(General!$L:$L, General!$B:$B, $A7, General!$D:$D, "Out Ports") -> 447.27321 | D7: =ROUND((B7+C7),2) -> 685.84
A8: Dry Ginger | B8: =SUMIFS(Antigua!$L:$L, Antigua!$B:$B, $A8, Antigua!$D:$D, "London") + SUMIFS(Barbados!$L:$L, Barbados!$B:$B, $A8, Barbados!$D:$D, "London") + SUMIFS(Bermuda!$L:$L, Bermuda!$B:$B, $A8, Bermuda!$D:$D, "London") + SUMIFS(Jamaica!$L:$L, Jamaica!$B:$B, $A8, Jamaica!$D:$D, "London") + SUMIFS(Mountserat!$L:$L, Mountserat!$B:$B, $A8, Mountserat!$D:$D, "London") + SUMIFS(Nevis!$L:$L, Nevis!$B:$B, $A8, Nevis!$D:$D, "London") + SUMIFS('St Kitts'!$L:$L, 'St Kitts'!$B:$B, $A8, 'St Kitts'!$D:$D, "London") + SUMIFS(General!$L:$L, General!$B:$B, $A8, General!$D:$D, "London") -> 862.91295 | C8: =SUMIFS(Antigua!$L:$L, Antigua!$B:$B, $A8, Antigua!$D:$D, "Out Ports") + SUMIFS(Barbados!$L:$L, Barbados!$B:$B, $A8, Barbados!$D:$D, "Out Ports") + SUMIFS(Bermuda!$L:$L, Bermuda!$B:$B, $A8, Bermuda!$D:$D, "Out Ports") + SUMIFS(Jamaica!$L:$L, Jamaica!$B:$B, $A8, Jamaica!$D:$D, "Out Ports") + SUMIFS(Mountserat!$L:$L, Mountserat!$B:$B, $A8, Mountserat!$D:$D, "Out Ports") + SUMIFS(Nevis!$L:$L, Nevis!$B:$B, $A8, Nevis!$D:$D, "Out Ports") + SUMIFS('St Kitts'!$L:$L, 'St Kitts'!$B:$B, $A8, 'St Kitts'!$D:$D, "Out Ports") + SUMIFS(General!$L:$L, General!$B:$B, $A8, General!$D:$D, "Out Ports") -> 268.37768 | D8: =ROUND((B8+C8),2) -> 1131.29
A9: Elephant Teeth | B9: =SUMIFS(Antigua!$L:$L, Antigua!$B:$B, $A9, Antigua!$D:$D, "London") + SUMIFS(Barbados!$L:$L, Barbados!$B:$B, $A9, Barbados!$D:$D, "London") + SUMIFS(Bermuda!$L:$L, Bermuda!$B:$B, $A9, Bermuda!$D:$D, "London") + SUMIFS(Jamaica!$L:$L, Jamaica!$B:$B, $A9, Jamaica!$D:$D, "London") + SUMIFS(Mountserat!$L:$L, Mountserat!$B:$B, $A9, Mountserat!$D:$D, "London") + SUMIFS(Nevis!$L:$L, Nevis!$B:$B, $A9, Nevis!$D:$D, "London") + SUMIFS('St Kitts'!$L:$L, 'St Kitts'!$B:$B, $A9, 'St Kitts'!$D:$D, "London") + SUMIFS(General!$L:$L, General!$B:$B, $A9, General!$D:$D, "London") -> 28.794643 | C9: =SUMIFS(Antigua!$L:$L, Antigua!$B:$B, $A9, Antigua!$D:$D, "Out Ports") + SUMIFS(Barbados!$L:$L, Barbados!$B:$B, $A9, Barbados!$D:$D, "Out Ports") + SUMIFS(Bermuda!$L:$L, Bermuda!$B:$B, $A9, Bermuda!$D:$D, "Out Ports") + SUMIFS(Jamaica!$L:$L, Jamaica!$B:$B, $A9, Jamaica!$D:$D, "Out Ports") + SUMIFS(Mountserat!$L:$L, Mountserat!$B:$B, $A9, Mountserat!$D:$D, "Out Ports") + SUMIFS(Nevis!$L:$L, Nevis!$B:$B, $A9, Nevis!$D:$D, "Out Ports") + SUMIFS('St Kitts'!$L:$L, 'St Kitts'!$B:$B, $A9, 'St Kitts'!$D:$D, "Out Ports") + SUMIFS(General!$L:$L, General!$B:$B, $A9, General!$D:$D, "Out Ports") -> 20.799107 | D9: =ROUND((B9+C9),2) -> 49.59
A10: Indigo | B10: =SUMIFS(Antigua!$L:$L, Antigua!$B:$B, $A10, Antigua!$D:$D, "London") + SUMIFS(Barbados!$L:$L, Barbados!$B:$B, $A10, Barbados!$D:$D, "London") + SUMIFS(Bermuda!$L:$L, Bermuda!$B:$B, $A10, Bermuda!$D:$D, "London") + SUMIFS(Jamaica!$L:$L, Jamaica!$B:$B, $A10, Jamaica!$D:$D, "London") + SUMIFS(Mountserat!$L:$L, Mountserat!$B:$B, $A10, Mountserat!$D:$D, "London") + SUMIFS(Nevis!$L:$L, Nevis!$B:$B, $A10, Nevis!$D:$D, "London") + SUMIFS('St Kitts'!$L:$L, 'St Kitts'!$B:$B, $A10, 'St Kitts'!$D:$D, "London") + SUMIFS(General!$L:$L, General!$B:$B, $A10, General!$D:$D, "London") -> 62.836607 | C10: =SUMIFS(Antigua!$L:$L, Antigua!$B:$B, $A10, Antigua!$D:$D, "Out Ports") + SUMIFS(Barbados!$L:$L, Barbados!$B:$B, $A10, Barbados!$D:$D, "Out Ports") + SUMIFS(Bermuda!$L:$L, Bermuda!$B:$B, $A10, Bermuda!$D:$D, "Out Ports") + SUMIFS(Jamaica!$L:$L, Jamaica!$B:$B, $A10, Jamaica!$D:$D, "Out Ports") + SUMIFS(Mountserat!$L:$L, Mountserat!$B:$B, $A10, Mountserat!$D:$D, "Out Ports") + SUMIFS(Nevis!$L:$L, Nevis!$B:$B, $A10, Nevis!$D:$D, "Out Ports") + SUMIFS('St Kitts'!$L:$L, 'St Kitts'!$B:$B, $A10, 'St Kitts'!$D:$D, "Out Ports") + SUMIFS(General!$L:$L, General!$B:$B, $A10, General!$D:$D, "Out Ports") -> 48.925893 | D10: =ROUND((B10+C10),2) -> 111.76
A11: Lignum Vitae | B11: =SUMIFS(Antigua!$L:$L, Antigua!$B:$B, $A11, Antigua!$D:$D, "London") + SUMIFS(Barbados!$L:$L, Barbados!$B:$B, $A11, Barbados!$D:$D, "London") + SUMIFS(Bermuda!$L:$L, Bermuda!$B:$B, $A11, Bermuda!$D:$D, "London") + SUMIFS(Jamaica!$L:$L, Jamaica!$B:$B, $A11, Jamaica!$D:$D, "London") + SUMIFS(Mountserat!$L:$L, Mountserat!$B:$B, $A11, Mountserat!$D:$D, "London") + SUMIFS(Nevis!$L:$L, Nevis!$B:$B, $A11, Nevis!$D:$D, "London") + SUMIFS('St Kitts'!$L:$L, 'St Kitts'!$B:$B, $A11, 'St Kitts'!$D:$D, "London") + SUMIFS(General!$L:$L, General!$B:$B, $A11, General!$D:$D, "London") -> 39.082143 | C11: =SUMIFS(Antigua!$L:$L, Antigua!$B:$B, $A11, Antigua!$D:$D, "Out Ports") + SUMIFS(Barbados!$L:$L, Barbados!$B:$B, $A11, Barbados!$D:$D, "Out Ports") + SUMIFS(Bermuda!$L:$L, Bermuda!$B:$B, $A11, Bermuda!$D:$D, "Out Ports") + SUMIFS(Jamaica!$L:$L, Jamaica!$B:$B, $A11, Jamaica!$D:$D, "Out Ports") + SUMIFS(Mountserat!$L:$L, Mountserat!$B:$B, $A11, Mountserat!$D:$D, "Out Ports") + SUMIFS(Nevis!$L:$L, Nevis!$B:$B, $A11, Nevis!$D:$D, "Out Ports") + SUMIFS('St Kitts'!$L:$L, 'St Kitts'!$B:$B, $A11, 'St Kitts'!$D:$D, "Out Ports") + SUMIFS(General!$L:$L, General!$B:$B, $A11, General!$D:$D, "Out Ports") -> 10.488839 | D11: =ROUND((B11+C11),2) -> 49.57
A12: Lime Juice | B12: =SUMIFS(Antigua!$L:$L, Antigua!$B:$B, $A12, Antigua!$D:$D, "London") + SUMIFS(Barbados!$L:$L, Barbados!$B:$B, $A12, Barbados!$D:$D, "London") + SUMIFS(Bermuda!$L:$L, Bermuda!$B:$B, $A12, Bermuda!$D:$D, "London") + SUMIFS(Jamaica!$L:$L, Jamaica!$B:$B, $A12, Jamaica!$D:$D, "London") + SUMIFS(Mountserat!$L:$L, Mountserat!$B:$B, $A12, Mountserat!$D:$D, "London") + SUMIFS(Nevis!$L:$L, Nevis!$B:$B, $A12, Nevis!$D:$D, "London") + SUMIFS('St Kitts'!$L:$L, 'St Kitts'!$B:$B, $A12, 'St Kitts'!$D:$D, "London") + SUMIFS(General!$L:$L, General!$B:$B, $A12, General!$D:$D, "London") -> 1.2642857 | C12: =SUMIFS(Antigua!$L:$L, Antigua!$B:$B, $A12, Antigua!$D:$D, "Out Ports") + SUMIFS(Barbados!$L:$L, Barbados!$B:$B, $A12, Barbados!$D:$D, "Out Ports") + SUMIFS(Bermuda!$L:$L, Bermuda!$B:$B, $A12, Bermuda!$D:$D, "Out Ports") + SUMIFS(Jamaica!$L:$L, Jamaica!$B:$B, $A12, Jamaica!$D:$D, "Out Ports") + SUMIFS(Mountserat!$L:$L, Mountserat!$B:$B, $A12, Mountserat!$D:$D, "Out Ports") + SUMIFS(Nevis!$L:$L, Nevis!$B:$B, $A12, Nevis!$D:$D, "Out Ports") + SUMIFS('St Kitts'!$L:$L, 'St Kitts'!$B:$B, $A12, 'St Kitts'!$D:$D, "Out Ports") + SUMIFS(General!$L:$L, General!$B:$B, $A12, General!$D:$D, "Out Ports") -> 4.5263393 | D12: =ROUND((B12+C12),2) -> 5.79
A13: Molasses | B13: =SUMIFS(Antigua!$L:$L, Antigua!$B:$B, $A13, Antigua!$D:$D, "London") + SUMIFS(Barbados!$L:$L, Barbados!$B:$B, $A13, Barbados!$D:$D, "London") + SUMIFS(Bermuda!$L:$L, Bermuda!$B:$B, $A13, Bermuda!$D:$D, "London") + SUMIFS(Jamaica!$L:$L, Jamaica!$B:$B, $A13, Jamaica!$D:$D, "London") + SUMIFS(Mountserat!$L:$L, Mountserat!$B:$B, $A13, Mountserat!$D:$D, "London") + SUMIFS(Nevis!$L:$L, Nevis!$B:$B, $A13, Nevis!$D:$D, "London") + SUMIFS('St Kitts'!$L:$L, 'St Kitts'!$B:$B, $A13, 'St Kitts'!$D:$D, "London") + SUMIFS(General!$L:$L, General!$B:$B, $A13, General!$D:$D, "London") -> 34.9375 | C13: =SUMIFS(Antigua!$L:$L, Antigua!$B:$B, $A13, Antigua!$D:$D, "Out Ports") + SUMIFS(Barbados!$L:$L, Barbados!$B:$B, $A13, Barbados!$D:$D, "Out Ports") + SUMIFS(Bermuda!$L:$L, Bermuda!$B:$B, $A13, Bermuda!$D:$D, "Out Ports") + SUMIFS(Jamaica!$L:$L, Jamaica!$B:$B, $A13, Jamaica!$D:$D, "Out Ports") + SUMIFS(Mountserat!$L:$L, Mountserat!$B:$B, $A13, Mountserat!$D:$D, "Out Ports") + SUMIFS(Nevis!$L:$L, Nevis!$B:$B, $A13, Nevis!$D:$D, "Out Ports") + SUMIFS('St Kitts'!$L:$L, 'St Kitts'!$B:$B, $A13, 'St Kitts'!$D:$D, "Out Ports") + SUMIFS(General!$L:$L, General!$B:$B, $A13, General!$D:$D, "Out Ports") -> 15.640625 | D13: =ROUND((B13+C13),2) -> 50.58
... A31: Wood, Sweetwood | B31: =SUMIFS(Antigua!$L:$L, Antigua!$B:$B, $A31, Antigua!$D:$D, "London") + SUMIFS(Barbados!$L:$L, Barbados!$B:$B, $A31, Barbados!$D:$D, "London") + SUMIFS(Bermuda!$L:$L, Bermuda!$B:$B, $A31, Bermuda!$D:$D, "London") + SUMIFS(Jamaica!$L:$L, Jamaica!$B:$B, $A31, Jamaica!$D:$D, "London") + SUMIFS(Mountserat!$L:$L, Mountserat!$B:$B, $A31, Mountserat!$D:$D, "London") + SUMIFS(Nevis!$L:$L, Nevis!$B:$B, $A31, Nevis!$D:$D, "London") + SUMIFS('St Kitts'!$L:$L, 'St Kitts'!$B:$B, $A31, 'St Kitts'!$D:$D, "London") + SUMIFS(General!$L:$L, General!$B:$B, $A31, General!$D:$D, "London") -> 0 | C31: =SUMIFS(Antigua!$L:$L, Antigua!$B:$B, $A31, Antigua!$D:$D, "Out Ports") + SUMIFS(Barbados!$L:$L, Barbados!$B:$B, $A31, Barbados!$D:$D, "Out Ports") + SUMIFS(Bermuda!$L:$L, Bermuda!$B:$B, $A31, Bermuda!$D:$D, "Out Ports") + SUMIFS(Jamaica!$L:$L, Jamaica!$B:$B, $A31, Jamaica!$D:$D, "Out Ports") + SUMIFS(Mountserat!$L:$L, Mountserat!$B:$B, $A31, Mountserat!$D:$D, "Out Ports") + SUMIFS(Nevis!$L:$L, Nevis!$B:$B, $A31, Nevis!$D:$D, "Out Ports") + SUMIFS('St Kitts'!$L:$L, 'St Kitts'!$B:$B, $A31, 'St Kitts'!$D:$D, "Out Ports") + SUMIFS(General!$L:$L, General!$B:$B, $A31, General!$D:$D, "Out Ports") -> 0.05 | D31: =ROUND((B31+C31),2) -> 0.05

Sheet Antigua
A1: YEAR | B1: COMMODITY_NAME | C1: FROM_LOCATION | D1: TO_LOCATION | E1: ton | F1: hh | G1: quarter | H1: lb | J1: Total Pounds | L1: WEIGHT
A2: 1723 | B2: Aloes Epatica | C2: Antigua | D2: London | H2: 2465 | J2: =(E2*2240)+(F2*112)+(G2*28)+H2 -> 2465 | L2: =J2/2240 -> 1.1004464
A3: 1723 | B3: Annatto | C3: Antigua | D3: London | J3: =(E3*2240)+(F3*112)+(G3*28)+H3 -> 0 | L3: =J3/2240 -> 0
A4: 1723 | B4: Brown Sugar | C4: Antigua | D4: London | F4: 124182 | G4: 2 | H4: 16 | J4: =(E4*2240)+(F4*112)+(G4*28)+H4 -> 13908456 | L4: =J4/2240 -> 6209.1321
A5: 1723 | B5: Chocolate | C5: Antigua | D5: London | J5: =(E5*2240)+(F5*112)+(G5*28)+H5 -> 0 | L5: =J5/2240 -> 0
A6: 1723 | B6: Cocoa Nuts | C6: Antigua | D6: London | F6: 17 | H6: 14 | J6: =(E6*2240)+(F6*112)+(G6*28)+H6 -> 1918 | L6: =J6/2240 -> 0.85625
A7: 1723 | B7: Cotton | C7: Antigua | D7: London | H7: =1332*200 -> 266400 | I7: 1332bags | J7: =(E7*2240)+(F7*112)+(G7*28)+H7 -> 266400 | L7: =J7/2240 -> 118.92857
A8: 1723 | B8: Dry Ginger | C8: Antigua | D8: London | F8: 2625 | H8: 15 | J8: =(E8*2240)+(F8*112)+(G8*28)+H8 -> 294015 | L8: =J8/2240 -> 131.2567
A9: 1723 | B9: Elephant Teeth | C9: Antigua | D9: London | J9: =(E9*2240)+(F9*112)+(G9*28)+H9 -> 0 | L9: =J9/2240 -> 0
A10: 1723 | B10: Green Ginger | C10: Antigua | D10: London | H10: 5 | J10: =(E10*2240)+(F10*112)+(G10*28)+H10 -> 5 | L10: =J10/2240 -> 0.0022321429
A11: 1723 | B11: Indigo | C11: Antigua | D11: London | H11: 1508 | J11: =(E11*2240)+(F11*112)+(G11*28)+H11 -> 1508 | L11: =J11/2240 -> 0.67321429
A12: 1723 | B12: Lemon Water | C12: Antigua | D12: London | J12: =(E12*2240)+(F12*112)+(G12*28)+H12 -> 0 | L12: =J12/2240 -> 0
A13: 1723 | B13: Lignum Vitae | C13: Antigua | D13: London | E13: 21 | F13: 7 | G13: 3 | J13: =(E13*2240)+(F13*112)+(G13*28)+H13 -> 47908 | L13: =J13/2240 -> 21.3875
A14: 1723 | B14: Lime Juice | C14: Antigua | D14: London | J14: =(E14*2240)+(F14*112)+(G14*28)+H14 -> 0 | L14: =J14/2240 -> 0
A15: 1723 | B15: Madera Wine | C15: Antigua | D15: London | H15: 24666 | I15: 9t 2h 50g | J15: =(E15*2240)+(F15*112)+(G15*28)+H15 -> 24666 | L15: =J15/2240 -> 11.011607
A16: 1723 | B16: Molasses | C16: Antigua | D16: London | J16: =(E16*2240)+(F16*112)+(G16*28)+H16 -> 0 | L16: =J16/2240 -> 0
A17: 1723 | B17: Pickles | C17: Antigua | D17: London | J17: =(E17*2240)+(F17*112)+(G17*28)+H17 -> 0 | L17: =J17/2240 -> 0
A18: 1723 | B18: Pimento | C18: Antigua | D18: London | H18: 245 | J18: =(E18*2240)+(F18*112)+(G18*28)+H18 -> 245 | L18: =J18/2240 -> 0.109375
A19: 1723 | B19: Rum | C19: Antigua | D19: London | H19: 385920 | I19: 38238g | J19: =(E19*2240)+(F19*112)+(G19*28)+H19 -> 385920 | L19: =J19/2240 -> 172.28571
A20: 1723 | B20: Shruff | C20: Antigua | D20: London | F20: 30 | H20: 14 | J20: =(E20*2240)+(F20*112)+(G20*28)+H20 -> 3374 | L20: =J20/2240 -> 1.50625
A21: 1723 | B21: Succads | C21: Antigua | D21: London | H21: 444 | J21: =(E21*2240)+(F21*112)+(G21*28)+H21 -> 444 | L21: =J21/2240 -> 0.19821429
A22: 1723 | B22: Tobacco | C22: Antigua | D22: London | J22: =(E22*2240)+(F22*112)+(G22*28)+H22 -> 0 | L22: =J22/2240 -> 0
A23: 1723 | B23: Tortoise Shell | C23: Antigua | D23: London | J23: =(E23*2240)+(F23*112)+(G23*28)+H23 -> 0 | L23: =J23/2240 -> 0
A24: 1723 | B24: White Sugar | C24: Antigua | D24: London | J24: =(E24*2240)+(F24*112)+(G24*28)+H24 -> 0 | L24: =J24/2240 -> 0
A25: 1723 | B25: Wood, Fustick | C25: Antigua | D25: London | E25: 25 | J25: =(E25*2240)+(F25*112)+(G25*28)+H25 -> 56000 | L25: =J25/2240 -> 25
A26: 1723 | B26: Brown Sugar | C26: Antigua | D26: Out Ports | F26: 25178 | G26: 2 | H26: 18 | J26: =(E26*2240)+(F26*112)+(G26*28)+H26 -> 2820010 | L26: =J26/2240 -> 1258.933
A27: 1723 | B27: Cocoa | C27: Antigua | D27: Out Ports | J27: =(E27*2240)+(F27*112)+(G27*28)+H27 -> 0 | L27: =J27/2240 -> 0
A28: 1723 | B28: Cocoa Nuts | C28: Antigua | D28: Out Ports | F28: 5 | G28: 2 | J28: =(E28*2240)+(F28*112)+(G28*28)+H28 -> 616 | L28: =J28/2240 -> 0.275
A29: 1723 | B29: Cotton | C29: Antigua | D29: Out Ports | F29: 3778 | G29: 3 | H29: 9 | J29: =(E29*2240)+(F29*112)+(G29*28)+H29 -> 423229 | L29: =J29/2240 -> 188.94152
A30: 1723 | B30: Dry Ginger | C30: Antigua | D30: Out Ports | F30: 395 | G30: 3 | H30: 13 | J30: =(E30*2240)+(F30*112)+(G30*28)+H30 -> 44337 | L30: =J30/2240 -> 19.793304
A31: 1723 | B31: Elephant Teeth | C31: Antigua | D31: Out Ports | G31: 1 | H31: 14 | J31: =(E31*2240)+(F31*112)+(G31*28)+H31 -> 42 | L31: =J31/2240 -> 0.01875
A32: 1723 | B32: Indigo | C32: Antigua | D32: Out Ports | H32: 3315 | J32: =(E32*2240)+(F32*112)+(G32*28)+H32 -> 3315 | L32: =J32/2240 -> 1.4799107
A33: 1723 | B33: Lignum Vitae | C33: Antigua | D33: Out Ports | F33: 12 | J33: =(E33*2240)+(F33*112)+(G33*28)+H33 -> 1344 | L33: =J33/2240 -> 0.6
A34: 1723 | B34: Lime Juice | C34: Antigua | D34: Out Ports | H34: 520 | I34: 50g | J34: =(E34*2240)+(F34*112)+(G34*28)+H34 -> 520 | L34: =J34/2240 -> 0.23214286
A35: 1723 | B35: Madera Wine | C35: Antigua | D35: Out Ports | J35: =(E35*2240)+(F35*112)+(G35*28)+H35 -> 0 | L35: =J35/2240 -> 0
A36: 1723 | B36: Molasses | C36: Antigua | D36: Out Ports | F36: 47 | G36: 1 | H36: 11 | J36: =(E36*2240)+(F36*112)+(G36*28)+H36 -> 5303 | L36: =J36/2240 -> 2.3674107
A37: 1723 | B37: Rice | C37: Antigua | D37: Out Ports | J37: =(E37*2240)+(F37*112)+(G37*28)+H37 -> 0 | L37: =J37/2240 -> 0
A38: 1723 | B38: Rum | C38: Antigua | D38: Out Ports | H38: 29975 | I38: 2970g | J38: =(E38*2240)+(F38*112)+(G38*28)+H38 -> 29975 | L38: =J38/2240 -> 13.381696
A39: 1723 | B39: Shruff | C39: Antigua | D39: Out Ports | J39: =(E39*2240)+(F39*112)+(G39*28)+H39 -> 0 | L39: =J39/2240 -> 0
A40: 1723 | B40: Succads | C40: Antigua | D40: Out Ports | H40: 13 | J40: =(E40*2240)+(F40*112)+(G40*28)+H40 -> 13 | L40: =J40/2240 -> 0.0058035714
...

Sheet Barbados
A1: YEAR | B1: COMMODITY_NAME | C1: FROM_LOCATION | D1: TO_LOCATION | E1: ton | F1: hh | G1: quarter | H1: lb | J1: Total Pounds | L1: WEIGHT
A2: 1723 | B2: Almonds, Bitter | C2: Barbados | D2: London | F2: 35 | J2: =(E2*2240)+(F2*112)+(G2*28)+H2 -> 3920 | L2: =J2/2240 -> 1.75
A3: 1723 | B3: Almonds, Sweet | C3: Barbados | D3: London | J3: =(E3*2240)+(F3*112)+(G3*28)+H3 -> 0 | L3: =J3/2240 -> 0
A4: 1723 | B4: Aloes Epatica | C4: Barbados | D4: London | H4: 37078 | J4: =(E4*2240)+(F4*112)+(G4*28)+H4 -> 37078 | L4: =J4/2240 -> 16.552679
A5: 1723 | B5: Annatto | C5: Barbados | D5: London | H5: 130 | J5: =(E5*2240)+(F5*112)+(G5*28)+H5 -> 130 | L5: =J5/2240 -> 0.058035714
A6: 1723 | B6: Anniseeds | C6: Barbados | D6: London | J6: =(E6*2240)+(F6*112)+(G6*28)+H6 -> 0 | L6: =J6/2240 -> 0
A7: 1723 | B7: Barrel Staves | C7: Barbados | D7: London | J7: =(E7*2240)+(F7*112)+(G7*28)+H7 -> 0 | L7: =J7/2240 -> 0
A8: 1723 | B8: Bees Wax | C8: Barbados | D8: London | H8: 40 | J8: =(E8*2240)+(F8*112)+(G8*28)+H8 -> 40 | L8: =J8/2240 -> 0.017857143
A9: 1723 | B9: Bermudos Plat | C9: Barbados | D9: London | F9: 2039 | G9: 3 | H9: 6 | J9: =(E9*2240)+(F9*112)+(G9*28)+H9 -> 228458 | L9: =J9/2240 -> 101.99018
A10: 1723 | B10: Brimstone | C10: Barbados | D10: London | J10: =(E10*2240)+(F10*112)+(G10*28)+H10 -> 0 | L10: =J10/2240 -> 0
A11: 1723 | B11: Brown Sugar | C11: Barbados | D11: London | F11: 143299 | G11: 2 | H11: 1 | J11: =(E11*2240)+(F11*112)+(G11*28)+H11 -> 16049545 | L11: =J11/2240 -> 7164.9754
A12: 1723 | B12: Cassia Fistula | C12: Barbados | D12: London | H12: 717 | J12: =(E12*2240)+(F12*112)+(G12*28)+H12 -> 717 | L12: =J12/2240 -> 0.32008929
A13: 1723 | B13: Chocolate Paste | C13: Barbados | D13: London | J13: =(E13*2240)+(F13*112)+(G13*28)+H13 -> 0 | L13: =J13/2240 -> 0
A14: 1723 | B14: Cocheneal | C14: Barbados | D14: London | J14: =(E14*2240)+(F14*112)+(G14*28)+H14 -> 0 | L14: =J14/2240 -> 0
A15: 1723 | B15: Cocoa Nuts | C15: Barbados | D15: London | F15: 115 | H15: 15 | J15: =(E15*2240)+(F15*112)+(G15*28)+H15 -> 12895 | L15: =J15/2240 -> 5.7566964
A16: 1723 | B16: Cocoa Paste | C16: Barbados | D16: London | J16: =(E16*2240)+(F16*112)+(G16*28)+H16 -> 0 | L16: =J16/2240 -> 0
A17: 1723 | B17: Cotton | C17: Barbados | D17: London | H17: =583*200 -> 116600 | I17: 583bags | J17: =(E17*2240)+(F17*112)+(G17*28)+H17 -> 116600 | L17: =J17/2240 -> 52.053571
A18: 1723 | B18: Dry Ginger | C18: Barbados | D18: London | F18: 4660 | G18: 3 | H18: 21 | J18: =(E18*2240)+(F18*112)+(G18*28)+H18 -> 522025 | L18: =J18/2240 -> 233.04688
A19: 1723 | B19: Elephant Teeth | C19: Barbados | D19: London | F19: 99 | H19: 16 | J19: =(E19*2240)+(F19*112)+(G19*28)+H19 -> 11104 | L19: =J19/2240 -> 4.9571429
A20: 1723 | B20: Green Ginger | C20: Barbados | D20: London | H20: 327 | J20: =(E20*2240)+(F20*112)+(G20*28)+H20 -> 327 | L20: =J20/2240 -> 0.14598214
A21: 1723 | B21: Hemp | C21: Barbados | D21: London | J21: =(E21*2240)+(F21*112)+(G21*28)+H21 -> 0 | L21: =J21/2240 -> 0
A22: 1723 | B22: Indigo | C22: Barbados | D22: London | H22: 9288 | J22: =(E22*2240)+(F22*112)+(G22*28)+H22 -> 9288 | L22: =J22/2240 -> 4.1464286
A23: 1723 | B23: Lemon Water | C23: Barbados | D23: London | J23: =(E23*2240)+(F23*112)+(G23*28)+H23 -> 0 | L23: =J23/2240 -> 0
A24: 1723 | B24: Lignum Vitae | C24: Barbados | D24: London | J24: =(E24*2240)+(F24*112)+(G24*28)+H24 -> 0 | L24: =J24/2240 -> 0
A25: 1723 | B25: Lime Juice | C25: Barbados | D25: London | H25: 2580 | I25: 248g | J25: =(E25*2240)+(F25*112)+(G25*28)+H25 -> 2580 | L25: =J25/2240 -> 1.1517857
A26: 1723 | B26: Loaf Sugar | C26: Barbados | D26: London | J26: =(E26*2240)+(F26*112)+(G26*28)+H26 -> 0 | L26: =J26/2240 -> 0
A27: 1723 | B27: Madera Wine | C27: Barbados | D27: London | H27: 60586 | I27: 23t 3h 18g | J27: =(E27*2240)+(F27*112)+(G27*28)+H27 -> 60586 | L27: =J27/2240 -> 27.047321
A28: 1723 | B28: Molasses | C28: Barbados | D28: London | F28: 540 | G28: 3 | J28: =(E28*2240)+(F28*112)+(G28*28)+H28 -> 60564 | L28: =J28/2240 -> 27.0375
A29: 1723 | B29: Oranges | C29: Barbados | D29: London | J29: =(E29*2240)+(F29*112)+(G29*28)+H29 -> 0 | L29: =J29/2240 -> 0
A30: 1723 | B30: Pickles | C30: Barbados | D30: London | J30: =(E30*2240)+(F30*112)+(G30*28)+H30 -> 0 | L30: =J30/2240 -> 0
A31: 1723 | B31: Pimento | C31: Barbados | D31: London | J31: =(E31*2240)+(F31*112)+(G31*28)+H31 -> 0 | L31: =J31/2240 -> 0
A32: 1723 | B32: Rice | C32: Barbados | D32: London | F32: 4 | H32: 27 | J32: =(E32*2240)+(F32*112)+(G32*28)+H32 -> 475 | L32: =J32/2240 -> 0.21205357
A33: 1723 | B33: Rum | C33: Barbados | D33: London | H33: 630220 | I33: 62444g | J33: =(E33*2240)+(F33*112)+(G33*28)+H33 -> 630220 | L33: =J33/2240 -> 281.34821
A34: 1723 | B34: Shruff | C34: Barbados | D34: London | F34: 428 | G34: 1 | H34: 10 | J34: =(E34*2240)+(F34*112)+(G34*28)+H34 -> 47974 | L34: =J34/2240 -> 21.416964
A35: 1723 | B35: Snuff | C35: Barbados | D35: London | J35: =(E35*2240)+(F35*112)+(G35*28)+H35 -> 0 | L35: =J35/2240 -> 0
A36: 1723 | B36: Succads | C36: Barbados | D36: London | H36: 1980 | J36: =(E36*2240)+(F36*112)+(G36*28)+H36 -> 1980 | L36: =J36/2240 -> 0.88392857
A37: 1723 | B37: Tobacco | C37: Barbados | D37: London | J37: =(E37*2240)+(F37*112)+(G37*28)+H37 -> 0 | L37: =J37/2240 -> 0
A38: 1723 | B38: Tortoise Shell | C38: Barbados | D38: London | J38: =(E38*2240)+(F38*112)+(G38*28)+H38 -> 0 | L38: =J38/2240 -> 0
A39: 1723 | B39: White Sugar | C39: Barbados | D39: London | J39: =(E39*2240)+(F39*112)+(G39*28)+H39 -> 0 | L39: =J39/2240 -> 0
A40: 1723 | B40: Wood, Braziletto | C40: Barbados | D40: London | J40: =(E40*2240)+(F40*112)+(G40*28)+H40 -> 0 | L40: =J40/2240 -> 0
...

Sheet Bermuda
A1: YEAR | B1: COMMODITY_NAME | C1: FROM_LOCATION | D1: TO_LOCATION | E1: ton | F1: hh | G1: quarter | H1: lb | J1: Total Pounds | L1: WEIGHT
A2: 1723 | B2: Bermudos Plat | C2: Bermuda | D2: London | F2: 2698 | J2: =(E2*2240)+(F2*112)+(G2*28)+H2 -> 302176 | L2: =J2/2240 -> 134.9
A3: 1723 | B3: Cocoa Nuts | C3: Bermuda | D3: London | J3: =(E3*2240)+(F3*112)+(G3*28)+H3 -> 0 | L3: =J3/2240 -> 0
A4: 1723 | B4: Cotton | C4: Bermuda | D4: London | H4: =2*200 -> 400 | I4: 2bags | J4: =(E4*2240)+(F4*112)+(G4*28)+H4 -> 400 | L4: =J4/2240 -> 0.17857143
A5: 1723 | B5: Indigo | C5: Bermuda | D5: London | H5: 176 | J5: =(E5*2240)+(F5*112)+(G5*28)+H5 -> 176 | L5: =J5/2240 -> 0.078571429
A6: 1723 | B6: Madera Wine | C6: Bermuda | D6: London | H6: 6762 | I6: 2t 2h 40g | J6: =(E6*2240)+(F6*112)+(G6*28)+H6 -> 6762 | L6: =J6/2240 -> 3.01875
A7: 1723 | B7: Molasses | C7: Bermuda | D7: London | F7: 158 | J7: =(E7*2240)+(F7*112)+(G7*28)+H7 -> 17696 | L7: =J7/2240 -> 7.9
A8: 1723 | B8: Pimento | C8: Bermuda | D8: London | H8: 153 | J8: =(E8*2240)+(F8*112)+(G8*28)+H8 -> 153 | L8: =J8/2240 -> 0.068303571
A9: 1723 | B9: Rice | C9: Bermuda | D9: London | F9: 39 | G9: 2 | H9: 21 | J9: =(E9*2240)+(F9*112)+(G9*28)+H9 -> 4445 | L9: =J9/2240 -> 1.984375
A10: 1723 | B10: Rum | C10: Bermuda | D10: London | H10: 19196 | I10: 1902g | J10: =(E10*2240)+(F10*112)+(G10*28)+H10 -> 19196 | L10: =J10/2240 -> 8.5696429
A11: 1723 | B11: Shruff | C11: Bermuda | D11: London | F11: 3 | G11: 1 | J11: =(E11*2240)+(F11*112)+(G11*28)+H11 -> 364 | L11: =J11/2240 -> 0.1625
A12: 1723 | B12: Wood, Braziletto | C12: Bermuda | D12: London | E12: 73 | F12: 10 | G12: 2 | J12: =(E12*2240)+(F12*112)+(G12*28)+H12 -> 164696 | L12: =J12/2240 -> 73.525
A13: 1723 | B13: Wood, Logwood | C13: Bermuda | D13: London | E13: 49 | F13: 2 | G13: 2 | J13: =(E13*2240)+(F13*112)+(G13*28)+H13 -> 110040 | L13: =J13/2240 -> 49.125
A14: 1723 | B14: Cotton | C14: Bermuda | D14: Out Ports | J14: =(E14*2240)+(F14*112)+(G14*28)+H14 -> 0 | L14: =J14/2240 -> 0
A15: 1723 | B15: Cocoa Nuts | C15: Bermuda | D15: Out Ports | J15: =(E15*2240)+(F15*112)+(G15*28)+H15 -> 0 | L15: =J15/2240 -> 0
A16: 1723 | B16: Indigo | C16: Bermuda | D16: Out Ports | J16: =(E16*2240)+(F16*112)+(G16*28)+H16 -> 0 | L16: =J16/2240 -> 0
A17: 1723 | B17: Molasses | C17: Bermuda | D17: Out Ports | F17: 17 | G17: 3 | H17: 3 | J17: =(E17*2240)+(F17*112)+(G17*28)+H17 -> 1991 | L17: =J17/2240 -> 0.88883929
A18: 1723 | B18: Rum | C18: Bermuda | D18: Out Ports | H18: 2755 | I18: 273g | J18: =(E18*2240)+(F18*112)+(G18*28)+H18 -> 2755 | L18: =J18/2240 -> 1.2299107
A19: 1723 | B19: Shruff | C19: Bermuda | D19: Out Ports | J19: =(E19*2240)+(F19*112)+(G19*28)+H19 -> 0 | L19: =J19/2240 -> 0
A20: 1723 | B20: Succads | C20: Bermuda | D20: Out Ports | J20: =(E20*2240)+(F20*112)+(G20*28)+H20 -> 0 | L20: =J20/2240 -> 0
A21: 1723 | B21: Wood, Braziletto | C21: Bermuda | D21: Out Ports | J21: =(E21*2240)+(F21*112)+(G21*28)+H21 -> 0 | L21: =J21/2240 -> 0
A22: 1723 | B22: Wood, Logwood | C22: Bermuda | D22: Out Ports | J22: =(E22*2240)+(F22*112)+(G22*28)+H22 -> 0 | L22: =J22/2240 -> 0

Sheet Jamaica
A1: YEAR | B1: COMMODITY_NAME | C1: FROM_LOCATION | D1: TO_LOCATION | E1: ton | F1: hh | G1: quarter | H1: lb | J1: Total Pounds | L1: WEIGHT
A2: 1723 | B2: Almonds, Bitter | C2: Jamaica | D2: London | J2: =(E2*2240)+(F2*112)+(G2*28)+H2 -> 0 | L2: =J2/2240 -> 0
A3: 1723 | B3: Almonds, Sweet | C3: Jamaica | D3: London | J3: =(E3*2240)+(F3*112)+(G3*28)+H3 -> 0 | L3: =J3/2240 -> 0
A4: 1723 | B4: Aloes Epatica | C4: Jamaica | D4: London | J4: =(E4*2240)+(F4*112)+(G4*28)+H4 -> 0 | L4: =J4/2240 -> 0
A5: 1723 | B5: Annatto | C5: Jamaica | D5: London | J5: =(E5*2240)+(F5*112)+(G5*28)+H5 -> 0 | L5: =J5/2240 -> 0
A6: 1723 | B6: Anniseeds | C6: Jamaica | D6: London | J6: =(E6*2240)+(F6*112)+(G6*28)+H6 -> 0 | L6: =J6/2240 -> 0
A7: 1723 | B7: Bacon | C7: Jamaica | D7: London | J7: =(E7*2240)+(F7*112)+(G7*28)+H7 -> 0 | L7: =J7/2240 -> 0
A8: 1723 | B8: Barrel Staves | C8: Jamaica | D8: London | J8: =(E8*2240)+(F8*112)+(G8*28)+H8 -> 0 | L8: =J8/2240 -> 0
A9: 1723 | B9: Bees Wax | C9: Jamaica | D9: London | F9: 8 | G9: 1 | J9: =(E9*2240)+(F9*112)+(G9*28)+H9 -> 924 | L9: =J9/2240 -> 0.4125
A10: 1723 | B10: Brimstone | C10: Jamaica | D10: London | J10: =(E10*2240)+(F10*112)+(G10*28)+H10 -> 0 | L10: =J10/2240 -> 0
A11: 1723 | B11: Brown Sugar | C11: Jamaica | D11: London | F11: 68069 | H11: 24 | J11: =(E11*2240)+(F11*112)+(G11*28)+H11 -> 7623752 | L11: =J11/2240 -> 3403.4607
A12: 1723 | B12: Cascarilla | C12: Jamaica | D12: London | H12: 4815
A13: 1723 | B13: Cassia Fistula | C13: Jamaica | D13: London | J13: =(E13*2240)+(F13*112)+(G13*28)+H13 -> 0 | L13: =J13/2240 -> 0
A14: 1723 | B14: Chocolate Paste | C14: Jamaica | D14: London | J14: =(E14*2240)+(F14*112)+(G14*28)+H14 -> 0 | L14: =J14/2240 -> 0
A15: 1723 | B15: Cocheneal | C15: Jamaica | D15: London | H15: 3815 | J15: =(E15*2240)+(F15*112)+(G15*28)+H15 -> 3815 | L15: =J15/2240 -> 1.703125
A16: 1723 | B16: Cocoa Nuts | C16: Jamaica | D16: London | F16: 2 | G16: 3 | H16: 2 | J16: =(E16*2240)+(F16*112)+(G16*28)+H16 -> 310 | L16: =J16/2240 -> 0.13839286
A17: 1723 | B17: Cocoa Paste | C17: Jamaica | D17: London | J17: =(E17*2240)+(F17*112)+(G17*28)+H17 -> 0 | L17: =J17/2240 -> 0
A18: 1723 | B18: Cortex Winteranus | C18: Jamaica | D18: London | J18: =(E18*2240)+(F18*112)+(G18*28)+H18 -> 0 | L18: =J18/2240 -> 0
A19: 1723 | B19: Cotton | C19: Jamaica | D19: London | H19: =701*200 -> 140200 | I19: 701bags | J19: =(E19*2240)+(F19*112)+(G19*28)+H19 -> 140200 | L19: =J19/2240 -> 62.589286
A20: 1723 | B20: Dry Ginger | C20: Jamaica | D20: London | F20: 9527 | G20: 3 | J20: =(E20*2240)+(F20*112)+(G20*28)+H20 -> 1067108 | L20: =J20/2240 -> 476.3875
A21: 1723 | B21: Elephant Teeth | C21: Jamaica | D21: London | F21: 426 | J21: =(E21*2240)+(F21*112)+(G21*28)+H21 -> 47712 | L21: =J21/2240 -> 21.3
A22: 1723 | B22: Green Ginger | C22: Jamaica | D22: London | J22: =(E22*2240)+(F22*112)+(G22*28)+H22 -> 0 | L22: =J22/2240 -> 0
A23: 1723 | B23: Hemp | C23: Jamaica | D23: London | J23: =(E23*2240)+(F23*112)+(G23*28)+H23 -> 0 | L23: =J23/2240 -> 0
A24: 1723 | B24: Indigo | C24: Jamaica | D24: London | H24: =15592+105464 -> 121056 | J24: =(E24*2240)+(F24*112)+(G24*28)+H24 -> 121056 | L24: =J24/2240 -> 54.042857
A25: 1723 | B25: Lemon Water | C25: Jamaica | D25: London | J25: =(E25*2240)+(F25*112)+(G25*28)+H25 -> 0 | L25: =J25/2240 -> 0
A26: 1723 | B26: Lignum Vitae | C26: Jamaica | D26: London | E26: 4 | J26: =(E26*2240)+(F26*112)+(G26*28)+H26 -> 8960 | L26: =J26/2240 -> 4
A27: 1723 | B27: Lime Juice | C27: Jamaica | D27: London | J27: =(E27*2240)+(F27*112)+(G27*28)+H27 -> 0 | L27: =J27/2240 -> 0
A28: 1723 | B28: Loaf Sugar | C28: Jamaica | D28: London | J28: =(E28*2240)+(F28*112)+(G28*28)+H28 -> 0 | L28: =J28/2240 -> 0
A29: 1723 | B29: Madera Wine | C29: Jamaica | D29: London | H29: 13837 | I29: 2t 3h 8g | J29: =(E29*2240)+(F29*112)+(G29*28)+H29 -> 13837 | L29: =J29/2240 -> 6.1772321
A30: 1723 | B30: Molasses | C30: Jamaica | D30: London | J30: =(E30*2240)+(F30*112)+(G30*28)+H30 -> 0 | L30: =J30/2240 -> 0
A31: 1723 | B31: Oranges | C31: Jamaica | D31: London | J31: =(E31*2240)+(F31*112)+(G31*28)+H31 -> 0 | L31: =J31/2240 -> 0
A32: 1723 | B32: Pickles | C32: Jamaica | D32: London | J32: =(E32*2240)+(F32*112)+(G32*28)+H32 -> 0 | L32: =J32/2240 -> 0
A33: 1723 | B33: Pimento | C33: Jamaica | D33: London | H33: 91537 | J33: =(E33*2240)+(F33*112)+(G33*28)+H33 -> 91537 | L33: =J33/2240 -> 40.864732
A34: 1723 | B34: Rice | C34: Jamaica | D34: London | F34: 14 | J34: =(E34*2240)+(F34*112)+(G34*28)+H34 -> 1568 | L34: =J34/2240 -> 0.7
A35: 1723 | B35: Rum | C35: Jamaica | D35: London | H35: 132415 | I35: 13120g | J35: =(E35*2240)+(F35*112)+(G35*28)+H35 -> 132415 | L35: =J35/2240 -> 59.113839
A36: 1723 | B36: Sarsparila | C36: Jamaica | D36: London | J36: =(E36*2240)+(F36*112)+(G36*28)+H36 -> 0 | L36: =J36/2240 -> 0
A37: 1723 | B37: Shruff | C37: Jamaica | D37: London | F37: 61 | G37: 3 | H37: 13 | J37: =(E37*2240)+(F37*112)+(G37*28)+H37 -> 6929 | L37: =J37/2240 -> 3.0933036
A38: 1723 | B38: Snuff | C38: Jamaica | D38: London | H38: 193201 | J38: =(E38*2240)+(F38*112)+(G38*28)+H38 -> 193201 | L38: =J38/2240 -> 86.250446
A39: 1723 | B39: Succads | C39: Jamaica | D39: London | H39: 704 | J39: =(E39*2240)+(F39*112)+(G39*28)+H39 -> 704 | L39: =J39/2240 -> 0.31428571
A40: 1723 | B40: Tobacco | C40: Jamaica | D40: London | J40: =(E40*2240)+(F40*112)+(G40*28)+H40 -> 0 | L40: =J40/2240 -> 0
...

Sheet Mountserat
A1: YEAR | B1: COMMODITY_NAME | C1: FROM_LOCATION | D1: TO_LOCATION | E1: ton | F1: hh | G1: quarter | H1: lb | J1: Total Pounds | L1: WEIGHT
A2: 1723 | B2: Almonds, Bitter | C2: Mountserat | D2: London | J2: =(E2*2240)+(F2*112)+(G2*28)+H2 -> 0 | L2: =J2/2240 -> 0
A3: 1723 | B3: Almonds, Sweet | C3: Mountserat | D3: London | J3: =(E3*2240)+(F3*112)+(G3*28)+H3 -> 0 | L3: =J3/2240 -> 0
A4: 1723 | B4: Aloes Epatica | C4: Mountserat | D4: London | J4: =(E4*2240)+(F4*112)+(G4*28)+H4 -> 0 | L4: =J4/2240 -> 0
A5: 1723 | B5: Annatto | C5: Mountserat | D5: London | J5: =(E5*2240)+(F5*112)+(G5*28)+H5 -> 0 | L5: =J5/2240 -> 0
A6: 1723 | B6: Anniseeds | C6: Mountserat | D6: London | J6: =(E6*2240)+(F6*112)+(G6*28)+H6 -> 0 | L6: =J6/2240 -> 0
A7: 1723 | B7: Bacon | C7: Mountserat | D7: London | J7: =(E7*2240)+(F7*112)+(G7*28)+H7 -> 0 | L7: =J7/2240 -> 0
A8: 1723 | B8: Barrel Staves | C8: Mountserat | D8: London | J8: =(E8*2240)+(F8*112)+(G8*28)+H8 -> 0 | L8: =J8/2240 -> 0
A9: 1723 | B9: Bees Wax | C9: Mountserat | D9: London | J9: =(E9*2240)+(F9*112)+(G9*28)+H9 -> 0 | L9: =J9/2240 -> 0
A10: 1723 | B10: Brimstone | C10: Mountserat | D10: London | J10: =(E10*2240)+(F10*112)+(G10*28)+H10 -> 0 | L10: =J10/2240 -> 0
A11: 1723 | B11: Brown Sugar | C11: Mountserat | D11: London | F11: 24938 | G11: 2 | H11: 4 | J11: =(E11*2240)+(F11*112)+(G11*28)+H11 -> 2793116 | L11: =J11/2240 -> 1246.9268
A12: 1723 | B12: Cassia Fistula | C12: Mountserat | D12: London | J12: =(E12*2240)+(F12*112)+(G12*28)+H12 -> 0 | L12: =J12/2240 -> 0
A13: 1723 | B13: Chocolate Paste | C13: Mountserat | D13: London | J13: =(E13*2240)+(F13*112)+(G13*28)+H13 -> 0 | L13: =J13/2240 -> 0
A14: 1723 | B14: Cocheneal | C14: Mountserat | D14: London | J14: =(E14*2240)+(F14*112)+(G14*28)+H14 -> 0 | L14: =J14/2240 -> 0
A15: 1723 | B15: Cocoa Nuts | C15: Mountserat | D15: London | J15: =(E15*2240)+(F15*112)+(G15*28)+H15 -> 0 | L15: =J15/2240 -> 0
A16: 1723 | B16: Cocoa Paste | C16: Mountserat | D16: London | J16: =(E16*2240)+(F16*112)+(G16*28)+H16 -> 0 | L16: =J16/2240 -> 0
A17: 1723 | B17: Cortex Winteranus | C17: Mountserat | D17: London | J17: =(E17*2240)+(F17*112)+(G17*28)+H17 -> 0 | L17: =J17/2240 -> 0
A18: 1723 | B18: Cotton | C18: Mountserat | D18: London | H18: =45*200 -> 9000 | I18: 45bags | J18: =(E18*2240)+(F18*112)+(G18*28)+H18 -> 9000 | L18: =J18/2240 -> 4.0178571
A19: 1723 | B19: Dry Ginger | C19: Mountserat | D19: London | F19: 154 | G19: 1 | J19: =(E19*2240)+(F19*112)+(G19*28)+H19 -> 17276 | L19: =J19/2240 -> 7.7125
A20: 1723 | B20: Elephant Teeth | C20: Mountserat | D20: London | J20: =(E20*2240)+(F20*112)+(G20*28)+H20 -> 0 | L20: =J20/2240 -> 0
A21: 1723 | B21: Green Ginger | C21: Mountserat | D21: London | J21: =(E21*2240)+(F21*112)+(G21*28)+H21 -> 0 | L21: =J21/2240 -> 0
A22: 1723 | B22: Hemp | C22: Mountserat | D22: London | J22: =(E22*2240)+(F22*112)+(G22*28)+H22 -> 0 | L22: =J22/2240 -> 0
A23: 1723 | B23: Indigo | C23: Mountserat | D23: London | H23: 5111 | J23: =(E23*2240)+(F23*112)+(G23*28)+H23 -> 5111 | L23: =J23/2240 -> 2.2816964
A24: 1723 | B24: Lemon Water | C24: Mountserat | D24: London | J24: =(E24*2240)+(F24*112)+(G24*28)+H24 -> 0 | L24: =J24/2240 -> 0
A25: 1723 | B25: Lignum Vitae | C25: Mountserat | D25: London | E25: 13 | F25: 13 | G25: 3 | H25: 16 | J25: =(E25*2240)+(F25*112)+(G25*28)+H25 -> 30676 | L25: =J25/2240 -> 13.694643
A26: 1723 | B26: Lime Juice | C26: Mountserat | D26: London | J26: =(E26*2240)+(F26*112)+(G26*28)+H26 -> 0 | L26: =J26/2240 -> 0
A27: 1723 | B27: Loaf Sugar | C27: Mountserat | D27: London | J27: =(E27*2240)+(F27*112)+(G27*28)+H27 -> 0 | L27: =J27/2240 -> 0
A28: 1723 | B28: Madera Wine | C28: Mountserat | D28: London | H28: 313 | I28: 31g | J28: =(E28*2240)+(F28*112)+(G28*28)+H28 -> 313 | L28: =J28/2240 -> 0.13973214
A29: 1723 | B29: Molasses | C29: Mountserat | D29: London | J29: =(E29*2240)+(F29*112)+(G29*28)+H29 -> 0 | L29: =J29/2240 -> 0
A30: 1723 | B30: Oranges | C30: Mountserat | D30: London | J30: =(E30*2240)+(F30*112)+(G30*28)+H30 -> 0 | L30: =J30/2240 -> 0
A31: 1723 | B31: Pickles | C31: Mountserat | D31: London | J31: =(E31*2240)+(F31*112)+(G31*28)+H31 -> 0 | L31: =J31/2240 -> 0
A32: 1723 | B32: Pimento | C32: Mountserat | D32: London | J32: =(E32*2240)+(F32*112)+(G32*28)+H32 -> 0 | L32: =J32/2240 -> 0
A33: 1723 | B33: Rice | C33: Mountserat | D33: London | J33: =(E33*2240)+(F33*112)+(G33*28)+H33 -> 0 | L33: =J33/2240 -> 0
A34: 1723 | B34: Rum | C34: Mountserat | D34: London | H34: 7418 | I34: 735g | J34: =(E34*2240)+(F34*112)+(G34*28)+H34 -> 7418 | L34: =J34/2240 -> 3.3116071
A35: 1723 | B35: Sarsparila | C35: Mountserat | D35: London | J35: =(E35*2240)+(F35*112)+(G35*28)+H35 -> 0 | L35: =J35/2240 -> 0
A36: 1723 | B36: Shruff | C36: Mountserat | D36: London | F36: 20 | G36: 1 | H36: 10 | J36: =(E36*2240)+(F36*112)+(G36*28)+H36 -> 2278 | L36: =J36/2240 -> 1.0169643
A37: 1723 | B37: Snuff | C37: Mountserat | D37: London | J37: =(E37*2240)+(F37*112)+(G37*28)+H37 -> 0 | L37: =J37/2240 -> 0
A38: 1723 | B38: Succads | C38: Mountserat | D38: London | H38: 8 | J38: =(E38*2240)+(F38*112)+(G38*28)+H38 -> 8 | L38: =J38/2240 -> 0.0035714286
A39: 1723 | B39: Tobacco | C39: Mountserat | D39: London | J39: =(E39*2240)+(F39*112)+(G39*28)+H39 -> 0 | L39: =J39/2240 -> 0
A40: 1723 | B40: Tortoise Shell | C40: Mountserat | D40: London | J40: =(E40*2240)+(F40*112)+(G40*28)+H40 -> 0 | L40: =J40/2240 -> 0
...

Sheet Nevis
A1: YEAR | B1: COMMODITY_NAME | C1: FROM_LOCATION | D1: TO_LOCATION | E1: ton | F1: hh | G1: quarter | H1: lb | J1: Total Pounds | L1: WEIGHT
A2: 1723 | B2: Almonds, Bitter | C2: Nevis | D2: London | J2: =(E2*2240)+(F2*112)+(G2*28)+H2 -> 0 | L2: =J2/2240 -> 0
A3: 1723 | B3: Almonds, Sweet | C3: Nevis | D3: London | J3: =(E3*2240)+(F3*112)+(G3*28)+H3 -> 0 | L3: =J3/2240 -> 0
A4: 1723 | B4: Aloes Epatica | C4: Nevis | D4: London | J4: =(E4*2240)+(F4*112)+(G4*28)+H4 -> 0 | L4: =J4/2240 -> 0
A5: 1723 | B5: Annatto | C5: Nevis | D5: London | J5: =(E5*2240)+(F5*112)+(G5*28)+H5 -> 0 | L5: =J5/2240 -> 0
A6: 1723 | B6: Anniseeds | C6: Nevis | D6: London | J6: =(E6*2240)+(F6*112)+(G6*28)+H6 -> 0 | L6: =J6/2240 -> 0
A7: 1723 | B7: Bacon | C7: Nevis | D7: London | J7: =(E7*2240)+(F7*112)+(G7*28)+H7 -> 0 | L7: =J7/2240 -> 0
A8: 1723 | B8: Barrel Staves | C8: Nevis | D8: London | J8: =(E8*2240)+(F8*112)+(G8*28)+H8 -> 0 | L8: =J8/2240 -> 0
A9: 1723 | B9: Bees Wax | C9: Nevis | D9: London | J9: =(E9*2240)+(F9*112)+(G9*28)+H9 -> 0 | L9: =J9/2240 -> 0
A10: 1723 | B10: Brimstone | C10: Nevis | D10: London | J10: =(E10*2240)+(F10*112)+(G10*28)+H10 -> 0 | L10: =J10/2240 -> 0
A11: 1723 | B11: Brown Sugar | C11: Nevis | D11: London | F11: 45219 | G11: 1 | H11: 3 | J11: =(E11*2240)+(F11*112)+(G11*28)+H11 -> 5064559 | L11: =J11/2240 -> 2260.9638
A12: 1723 | B12: Cassia Fistula | C12: Nevis | D12: London | J12: =(E12*2240)+(F12*112)+(G12*28)+H12 -> 0 | L12: =J12/2240 -> 0
A13: 1723 | B13: Chocolate Paste | C13: Nevis | D13: London | J13: =(E13*2240)+(F13*112)+(G13*28)+H13 -> 0 | L13: =J13/2240 -> 0
A14: 1723 | B14: Cocheneal | C14: Nevis | D14: London | J14: =(E14*2240)+(F14*112)+(G14*28)+H14 -> 0 | L14: =J14/2240 -> 0
A15: 1723 | B15: Cocoa Nuts | C15: Nevis | D15: London | F15: 1 | G15: 1 | J15: =(E15*2240)+(F15*112)+(G15*28)+H15 -> 140 | L15: =J15/2240 -> 0.0625
A16: 1723 | B16: Cocoa Paste | C16: Nevis | D16: London | J16: =(E16*2240)+(F16*112)+(G16*28)+H16 -> 0 | L16: =J16/2240 -> 0
A17: 1723 | B17: Cortex Winteranus | C17: Nevis | D17: London | J17: =(E17*2240)+(F17*112)+(G17*28)+H17 -> 0 | L17: =J17/2240 -> 0
A18: 1723 | B18: Cotton | C18: Nevis | D18: London | H18: =6*200 -> 1200 | I18: 6bags | J18: =(E18*2240)+(F18*112)+(G18*28)+H18 -> 1200 | L18: =J18/2240 -> 0.53571429
A19: 1723 | B19: Dry Ginger | C19: Nevis | D19: London | J19: =(E19*2240)+(F19*112)+(G19*28)+H19 -> 0 | L19: =J19/2240 -> 0
A20: 1723 | B20: Elephant Teeth | C20: Nevis | D20: London | F20: 3 | J20: =(E20*2240)+(F20*112)+(G20*28)+H20 -> 336 | L20: =J20/2240 -> 0.15
A21: 1723 | B21: Green Ginger | C21: Nevis | D21: London | J21: =(E21*2240)+(F21*112)+(G21*28)+H21 -> 0 | L21: =J21/2240 -> 0
A22: 1723 | B22: Hemp | C22: Nevis | D22: London | J22: =(E22*2240)+(F22*112)+(G22*28)+H22 -> 0 | L22: =J22/2240 -> 0
A23: 1723 | B23: Indigo | C23: Nevis | D23: London | J23: =(E23*2240)+(F23*112)+(G23*28)+H23 -> 0 | L23: =J23/2240 -> 0
A24: 1723 | B24: Lemon Water | C24: Nevis | D24: London | J24: =(E24*2240)+(F24*112)+(G24*28)+H24 -> 0 | L24: =J24/2240 -> 0
A25: 1723 | B25: Lignum Vitae | C25: Nevis | D25: London | J25: =(E25*2240)+(F25*112)+(G25*28)+H25 -> 0 | L25: =J25/2240 -> 0
A26: 1723 | B26: Lime Juice | C26: Nevis | D26: London | H26: 252 | I26: 25g | J26: =(E26*2240)+(F26*112)+(G26*28)+H26 -> 252 | L26: =J26/2240 -> 0.1125
A27: 1723 | B27: Loaf Sugar | C27: Nevis | D27: London | J27: =(E27*2240)+(F27*112)+(G27*28)+H27 -> 0 | L27: =J27/2240 -> 0
A28: 1723 | B28: Madera Wine | C28: Nevis | D28: London | H28: 7771 | I28: 770g | J28: =(E28*2240)+(F28*112)+(G28*28)+H28 -> 7771 | L28: =J28/2240 -> 3.4691964
A29: 1723 | B29: Molasses | C29: Nevis | D29: London | J29: =(E29*2240)+(F29*112)+(G29*28)+H29 -> 0 | L29: =J29/2240 -> 0
A30: 1723 | B30: Oranges | C30: Nevis | D30: London | J30: =(E30*2240)+(F30*112)+(G30*28)+H30 -> 0 | L30: =J30/2240 -> 0
A31: 1723 | B31: Pickles | C31: Nevis | D31: London | J31: =(E31*2240)+(F31*112)+(G31*28)+H31 -> 0 | L31: =J31/2240 -> 0
A32: 1723 | B32: Pimento | C32: Nevis | D32: London | J32: =(E32*2240)+(F32*112)+(G32*28)+H32 -> 0 | L32: =J32/2240 -> 0
A33: 1723 | B33: Rice | C33: Nevis | D33: London | J33: =(E33*2240)+(F33*112)+(G33*28)+H33 -> 0 | L33: =J33/2240 -> 0
A34: 1723 | B34: Rum | C34: Nevis | D34: London | H34: 6015 | I34: 596g | J34: =(E34*2240)+(F34*112)+(G34*28)+H34 -> 6015 | L34: =J34/2240 -> 2.6852679
A35: 1723 | B35: Sarsparila | C35: Nevis | D35: London | J35: =(E35*2240)+(F35*112)+(G35*28)+H35 -> 0 | L35: =J35/2240 -> 0
A36: 1723 | B36: Shruff | C36: Nevis | D36: London | F36: 12 | H36: 7 | J36: =(E36*2240)+(F36*112)+(G36*28)+H36 -> 1351 | L36: =J36/2240 -> 0.603125
A37: 1723 | B37: Snuff | C37: Nevis | D37: London | J37: =(E37*2240)+(F37*112)+(G37*28)+H37 -> 0 | L37: =J37/2240 -> 0
A38: 1723 | B38: Succads | C38: Nevis | D38: London | H38: 24 | J38: =(E38*2240)+(F38*112)+(G38*28)+H38 -> 24 | L38: =J38/2240 -> 0.010714286
A39: 1723 | B39: Tobacco | C39: Nevis | D39: London | J39: =(E39*2240)+(F39*112)+(G39*28)+H39 -> 0 | L39: =J39/2240 -> 0
A40: 1723 | B40: Tortoise Shell | C40: Nevis | D40: London | H40: 18 | J40: =(E40*2240)+(F40*112)+(G40*28)+H40 -> 18 | L40: =J40/2240 -> 0.0080357143
...

Sheet St Kitts
A1: YEAR | B1: COMMODITY_NAME | C1: FROM_LOCATION | D1: TO_LOCATION | E1: ton | F1: hh | G1: quarter | H1: lb | J1: Total Pounds | L1: WEIGHT
A2: 1723 | B2: Almonds, Bitter | C2: StKitts | D2: London | J2: =(E2*2240)+(F2*112)+(G2*28)+H2 -> 0 | L2: =J2/2240 -> 0
A3: 1723 | B3: Almonds, Sweet | C3: StKitts | D3: London | J3: =(E3*2240)+(F3*112)+(G3*28)+H3 -> 0 | L3: =J3/2240 -> 0
A4: 1723 | B4: Aloes Epatica | C4: StKitts | D4: London | J4: =(E4*2240)+(F4*112)+(G4*28)+H4 -> 0 | L4: =J4/2240 -> 0
A5: 1723 | B5: Annatto | C5: StKitts | D5: London | J5: =(E5*2240)+(F5*112)+(G5*28)+H5 -> 0 | L5: =J5/2240 -> 0
A6: 1723 | B6: Anniseeds | C6: StKitts | D6: London | J6: =(E6*2240)+(F6*112)+(G6*28)+H6 -> 0 | L6: =J6/2240 -> 0
A7: 1723 | B7: Bacon | C7: StKitts | D7: London | J7: =(E7*2240)+(F7*112)+(G7*28)+H7 -> 0 | L7: =J7/2240 -> 0
A8: 1723 | B8: Barrel Staves | C8: StKitts | D8: London | J8: =(E8*2240)+(F8*112)+(G8*28)+H8 -> 0 | L8: =J8/2240 -> 0
A9: 1723 | B9: Bees Wax | C9: StKitts | D9: London | J9: =(E9*2240)+(F9*112)+(G9*28)+H9 -> 0 | L9: =J9/2240 -> 0
A10: 1723 | B10: Brimstone | C10: StKitts | D10: London | J10: =(E10*2240)+(F10*112)+(G10*28)+H10 -> 0 | L10: =J10/2240 -> 0
A11: 1723 | B11: Brown Sugar | C11: StKitts | D11: London | F11: 107339 | G11: 3 | H11: 5 | J11: =(E11*2240)+(F11*112)+(G11*28)+H11 -> 12022057 | L11: =J11/2240 -> 5366.9897
A12: 1723 | B12: Cassia Fistula | C12: StKitts | D12: London | J12: =(E12*2240)+(F12*112)+(G12*28)+H12 -> 0 | L12: =J12/2240 -> 0
A13: 1723 | B13: Chocolate Paste | C13: StKitts | D13: London | J13: =(E13*2240)+(F13*112)+(G13*28)+H13 -> 0 | L13: =J13/2240 -> 0
A14: 1723 | B14: Cocheneal | C14: StKitts | D14: London | J14: =(E14*2240)+(F14*112)+(G14*28)+H14 -> 0 | L14: =J14/2240 -> 0
A15: 1723 | B15: Cocoa Nuts | C15: StKitts | D15: London | J15: =(E15*2240)+(F15*112)+(G15*28)+H15 -> 0 | L15: =J15/2240 -> 0
A16: 1723 | B16: Cocoa Paste | C16: StKitts | D16: London | J16: =(E16*2240)+(F16*112)+(G16*28)+H16 -> 0 | L16: =J16/2240 -> 0
A17: 1723 | B17: Cortex Winteranus | C17: StKitts | D17: London | J17: =(E17*2240)+(F17*112)+(G17*28)+H17 -> 0 | L17: =J17/2240 -> 0
A18: 1723 | B18: Cotton | C18: StKitts | D18: London | J18: =(E18*2240)+(F18*112)+(G18*28)+H18 -> 0 | L18: =J18/2240 -> 0
A19: 1723 | B19: Dry Ginger | C19: StKitts | D19: London | F19: 24 | J19: =(E19*2240)+(F19*112)+(G19*28)+H19 -> 2688 | L19: =J19/2240 -> 1.2
A20: 1723 | B20: Elephant Teeth | C20: StKitts | D20: London | F20: 47 | G20: 3 | J20: =(E20*2240)+(F20*112)+(G20*28)+H20 -> 5348 | L20: =J20/2240 -> 2.3875
A21: 1723 | B21: Green Ginger | C21: StKitts | D21: London | J21: =(E21*2240)+(F21*112)+(G21*28)+H21 -> 0 | L21: =J21/2240 -> 0
A22: 1723 | B22: Hemp | C22: StKitts | D22: London | J22: =(E22*2240)+(F22*112)+(G22*28)+H22 -> 0 | L22: =J22/2240 -> 0
A23: 1723 | B23: Indigo | C23: StKitts | D23: London | H23: 1345 | J23: =(E23*2240)+(F23*112)+(G23*28)+H23 -> 1345 | L23: =J23/2240 -> 0.60044643
A24: 1723 | B24: Lemon Water | C24: StKitts | D24: London | J24: =(E24*2240)+(F24*112)+(G24*28)+H24 -> 0 | L24: =J24/2240 -> 0
A25: 1723 | B25: Lignum Vitae | C25: StKitts | D25: London | J25: =(E25*2240)+(F25*112)+(G25*28)+H25 -> 0 | L25: =J25/2240 -> 0
A26: 1723 | B26: Lime Juice | C26: StKitts | D26: London | J26: =(E26*2240)+(F26*112)+(G26*28)+H26 -> 0 | L26: =J26/2240 -> 0
A27: 1723 | B27: Loaf Sugar | C27: StKitts | D27: London | J27: =(E27*2240)+(F27*112)+(G27*28)+H27 -> 0 | L27: =J27/2240 -> 0
A28: 1723 | B28: Madera Wine | C28: StKitts | D28: London | H28: 16158 | I28: 6t 1h 26g | J28: =(E28*2240)+(F28*112)+(G28*28)+H28 -> 16158 | L28: =J28/2240 -> 7.2133929
A29: 1723 | B29: Molasses | C29: StKitts | D29: London | J29: =(E29*2240)+(F29*112)+(G29*28)+H29 -> 0 | L29: =J29/2240 -> 0
A30: 1723 | B30: Oranges | C30: StKitts | D30: London | J30: =(E30*2240)+(F30*112)+(G30*28)+H30 -> 0 | L30: =J30/2240 -> 0
A31: 1723 | B31: Pickles | C31: StKitts | D31: London | J31: =(E31*2240)+(F31*112)+(G31*28)+H31 -> 0 | L31: =J31/2240 -> 0
A32: 1723 | B32: Pimento | C32: StKitts | D32: London | J32: =(E32*2240)+(F32*112)+(G32*28)+H32 -> 0 | L32: =J32/2240 -> 0
A33: 1723 | B33: Rice | C33: StKitts | D33: London | J33: =(E33*2240)+(F33*112)+(G33*28)+H33 -> 0 | L33: =J33/2240 -> 0
A34: 1723 | B34: Rum | C34: StKitts | D34: London | H34: 39230 | I34: 3887g | J34: =(E34*2240)+(F34*112)+(G34*28)+H34 -> 39230 | L34: =J34/2240 -> 17.513393
A35: 1723 | B35: Sarsparila | C35: StKitts | D35: London | J35: =(E35*2240)+(F35*112)+(G35*28)+H35 -> 0 | L35: =J35/2240 -> 0
A36: 1723 | B36: Shruff | C36: StKitts | D36: London | F36: 25 | H36: 11 | J36: =(E36*2240)+(F36*112)+(G36*28)+H36 -> 2811 | L36: =J36/2240 -> 1.2549107
A37: 1723 | B37: Snuff | C37: StKitts | D37: London | J37: =(E37*2240)+(F37*112)+(G37*28)+H37 -> 0 | L37: =J37/2240 -> 0
A38: 1723 | B38: Succads | C38: StKitts | D38: London | H38: 28 | J38: =(E38*2240)+(F38*112)+(G38*28)+H38 -> 28 | L38: =J38/2240 -> 0.0125
A39: 1723 | B39: Tobacco | C39: StKitts | D39: London | J39: =(E39*2240)+(F39*112)+(G39*28)+H39 -> 0 | L39: =J39/2240 -> 0
A40: 1723 | B40: Tortoise Shell | C40: StKitts | D40: London | J40: =(E40*2240)+(F40*112)+(G40*28)+H40 -> 0 | L40: =J40/2240 -> 0
...

Sheet General
A1: YEAR | B1: COMMODITY_NAME | C1: FROM_LOCATION | D1: TO_LOCATION | E1: ton | F1: hh | G1: quarter | H1: lb | J1: Total Pounds | L1: WEIGHT
A2: 1723 | B2: Almonds, Bitter | C2: General | D2: London | J2: =(E2*2240)+(F2*112)+(G2*28)+H2 -> 0 | L2: =J2/2240 -> 0
A3: 1723 | B3: Almonds, Sweet | C3: General | D3: London | J3: =(E3*2240)+(F3*112)+(G3*28)+H3 -> 0 | L3: =J3/2240 -> 0
A4: 1723 | B4: Aloes Epatica | C4: General | D4: London | H4: 600 | J4: =(E4*2240)+(F4*112)+(G4*28)+H4 -> 600 | L4: =J4/2240 -> 0.26785714
A5: 1723 | B5: Annatto | C5: General | D5: London | J5: =(E5*2240)+(F5*112)+(G5*28)+H5 -> 0 | L5: =J5/2240 -> 0
A6: 1723 | B6: Anniseeds | C6: General | D6: London | J6: =(E6*2240)+(F6*112)+(G6*28)+H6 -> 0 | L6: =J6/2240 -> 0
A7: 1723 | B7: Bacon | C7: General | D7: London | J7: =(E7*2240)+(F7*112)+(G7*28)+H7 -> 0 | L7: =J7/2240 -> 0
A8: 1723 | B8: Barrel Staves | C8: General | D8: London | J8: =(E8*2240)+(F8*112)+(G8*28)+H8 -> 0 | L8: =J8/2240 -> 0
A9: 1723 | B9: Bees Wax | C9: General | D9: London | J9: =(E9*2240)+(F9*112)+(G9*28)+H9 -> 0 | L9: =J9/2240 -> 0
A10: 1723 | B10: Brimstone | C10: General | D10: London | J10: =(E10*2240)+(F10*112)+(G10*28)+H10 -> 0 | L10: =J10/2240 -> 0
A11: 1723 | B11: Brown Sugar | C11: General | D11: London | F11: 6555 | J11: =(E11*2240)+(F11*112)+(G11*28)+H11 -> 734160 | L11: =J11/2240 -> 327.75
A12: 1723 | B12: Cassia Fistula | C12: General | D12: London | H12: 70 | J12: =(E12*2240)+(F12*112)+(G12*28)+H12 -> 70 | L12: =J12/2240 -> 0.03125
A13: 1723 | B13: Chocolate Paste | C13: General | D13: London | J13: =(E13*2240)+(F13*112)+(G13*28)+H13 -> 0 | L13: =J13/2240 -> 0
A14: 1723 | B14: Cocheneal | C14: General | D14: London | J14: =(E14*2240)+(F14*112)+(G14*28)+H14 -> 0 | L14: =J14/2240 -> 0
A15: 1723 | B15: Cocoa Nuts | C15: General | D15: London | J15: =(E15*2240)+(F15*112)+(G15*28)+H15 -> 0 | L15: =J15/2240 -> 0
A16: 1723 | B16: Cocoa Paste | C16: General | D16: London | J16: =(E16*2240)+(F16*112)+(G16*28)+H16 -> 0 | L16: =J16/2240 -> 0
A17: 1723 | B17: Cortex Winteranus | C17: General | D17: London | J17: =(E17*2240)+(F17*112)+(G17*28)+H17 -> 0 | L17: =J17/2240 -> 0
A18: 1723 | B18: Cotton | C18: General | D18: London | H18: =200*3 -> 600 | I18: 3bags | J18: =(E18*2240)+(F18*112)+(G18*28)+H18 -> 600 | L18: =J18/2240 -> 0.26785714
A19: 1723 | B19: Dry Ginger | C19: General | D19: London | F19: 266 | H19: 21 | J19: =(E19*2240)+(F19*112)+(G19*28)+H19 -> 29813 | L19: =J19/2240 -> 13.309375
A20: 1723 | B20: Elephant Teeth | C20: General | D20: London | J20: =(E20*2240)+(F20*112)+(G20*28)+H20 -> 0 | L20: =J20/2240 -> 0
A21: 1723 | B21: Green Ginger | C21: General | D21: London | J21: =(E21*2240)+(F21*112)+(G21*28)+H21 -> 0 | L21: =J21/2240 -> 0
A22: 1723 | B22: Hemp | C22: General | D22: London | J22: =(E22*2240)+(F22*112)+(G22*28)+H22 -> 0 | L22: =J22/2240 -> 0
A23: 1723 | B23: Indigo | C23: General | D23: London | H23: 2270 | J23: =(E23*2240)+(F23*112)+(G23*28)+H23 -> 2270 | L23: =J23/2240 -> 1.0133929
A24: 1723 | B24: Lemon Water | C24: General | D24: London | J24: =(E24*2240)+(F24*112)+(G24*28)+H24 -> 0 | L24: =J24/2240 -> 0
A25: 1723 | B25: Lignum Vitae | C25: General | D25: London | J25: =(E25*2240)+(F25*112)+(G25*28)+H25 -> 0 | L25: =J25/2240 -> 0
A26: 1723 | B26: Lime Juice | C26: General | D26: London | J26: =(E26*2240)+(F26*112)+(G26*28)+H26 -> 0 | L26: =J26/2240 -> 0
A27: 1723 | B27: Loaf Sugar | C27: General | D27: London | J27: =(E27*2240)+(F27*112)+(G27*28)+H27 -> 0 | L27: =J27/2240 -> 0
A28: 1723 | B28: Madera Wine | C28: General | D28: London | J28: =(E28*2240)+(F28*112)+(G28*28)+H28 -> 0 | L28: =J28/2240 -> 0
A29: 1723 | B29: Molasses | C29: General | D29: London | J29: =(E29*2240)+(F29*112)+(G29*28)+H29 -> 0 | L29: =J29/2240 -> 0
A30: 1723 | B30: Oranges | C30: General | D30: London | J30: =(E30*2240)+(F30*112)+(G30*28)+H30 -> 0 | L30: =J30/2240 -> 0
A31: 1723 | B31: Pickles | C31: General | D31: London | J31: =(E31*2240)+(F31*112)+(G31*28)+H31 -> 0 | L31: =J31/2240 -> 0
A32: 1723 | B32: Pimento | C32: General | D32: London | H32: 13100 | J32: =(E32*2240)+(F32*112)+(G32*28)+H32 -> 13100 | L32: =J32/2240 -> 5.8482143
A33: 1723 | B33: Rice | C33: General | D33: London | F33: 3 | J33: =(E33*2240)+(F33*112)+(G33*28)+H33 -> 336 | L33: =J33/2240 -> 0.15
A34: 1723 | B34: Rum | C34: General | D34: London | J34: =(E34*2240)+(F34*112)+(G34*28)+H34 -> 0 | L34: =J34/2240 -> 0
A35: 1723 | B35: Sarsparila | C35: General | D35: London | J35: =(E35*2240)+(F35*112)+(G35*28)+H35 -> 0 | L35: =J35/2240 -> 0
A36: 1723 | B36: Shruff | C36: General | D36: London | F36: 3 | J36: =(E36*2240)+(F36*112)+(G36*28)+H36 -> 336 | L36: =J36/2240 -> 0.15
A37: 1723 | B37: Snuff | C37: General | D37: London | H37: 2030 | J37: =(E37*2240)+(F37*112)+(G37*28)+H37 -> 2030 | L37: =J37/2240 -> 0.90625
A38: 1723 | B38: Succads | C38: General | D38: London | H38: 104 | J38: =(E38*2240)+(F38*112)+(G38*28)+H38 -> 104 | L38: =J38/2240 -> 0.046428571
A39: 1723 | B39: Tobacco | C39: General | D39: London | J39: =(E39*2240)+(F39*112)+(G39*28)+H39 -> 0 | L39: =J39/2240 -> 0
A40: 1723 | B40: Tortoise Shell | C40: General | D40: London | H40: 140 | J40: =(E40*2240)+(F40*112)+(G40*28)+H40 -> 140 | L40: =J40/2240 -> 0.0625
...
