Workbook

Sheet Master Goods Sheet
A1: Item | B1: Total London | C1: Total Outports | D1: Total
A2: Annatto | B2: =SUMIFS(Antigua!$L:$L, Antigua!$B:$B, $A2, Antigua!$D:$D, "London") + SUMIFS(Barbados!$L:$L, Barbados!$B:$B, $A2, Barbados!$D:$D, "London") + SUMIFS(Bermuda!$L:$L, Bermuda!$B:$B, $A2, Bermuda!$D:$D, "London") + SUMIFS(Jamaica!$L:$L, Jamaica!$B:$B, $A2, Jamaica!$D:$D, "London") + SUMIFS(Mountserat!$L:$L, Mountserat!$B:$B, $A2, Mountserat!$D:$D, "London") + SUMIFS(Nevis!$L:$L, Nevis!$B:$B, $A2, Nevis!$D:$D, "London") + SUMIFS('St Kitts'!$L:$L, 'St Kitts'!$B:$B, $A2, 'St Kitts'!$D:$D, "London") -> 0.52410714 | C2: =SUMIFS(Antigua!$L:$L, Antigua!$B:$B, $A2, Antigua!$D:$D, "Out Ports") + SUMIFS(Barbados!$L:$L, Barbados!$B:$B, $A2, Barbados!$D:$D, "Out Ports") + SUMIFS(Bermuda!$L:$L, Bermuda!$B:$B, $A2, Bermuda!$D:$D, "Out Ports") + SUMIFS(Jamaica!$L:$L, Jamaica!$B:$B, $A2, Jamaica!$D:$D, "Out Ports") + SUMIFS(Mountserat!$L:$L, Mountserat!$B:$B, $A2, Mountserat!$D:$D, "Out Ports") + SUMIFS(Nevis!$L:$L, Nevis!$B:$B, $A2, Nevis!$D:$D, "Out Ports") + SUMIFS('St Kitts'!$L:$L, 'St Kitts'!$B:$B, $A2, 'St Kitts'!$D:$D, "Out Ports") -> 0 | D2: =B2+C2 -> 0.52410714
A3: Bees Wax | B3: =SUMIFS(Antigua!$L:$L, Antigua!$B:$B, $A3, Antigua!$D:$D, "London") + SUMIFS(Barbados!$L:$L, Barbados!$B:$B, $A3, Barbados!$D:$D, "London") + SUMIFS(Bermuda!$L:$L, Bermuda!$B:$B, $A3, Bermuda!$D:$D, "London") + SUMIFS(Jamaica!$L:$L, Jamaica!$B:$B, $A3, Jamaica!$D:$D, "London") + SUMIFS(Mountserat!$L:$L, Mountserat!$B:$B, $A3, Mountserat!$D:$D, "London") + SUMIFS(Nevis!$L:$L, Nevis!$B:$B, $A3, Nevis!$D:$D, "London") + SUMIFS('St Kitts'!$L:$L, 'St Kitts'!$B:$B, $A3, 'St Kitts'!$D:$D, "London") -> 10.232143 | C3: =SUMIFS(Antigua!$L:$L, Antigua!$B:$B, $A3, Antigua!$D:$D, "Out Ports") + SUMIFS(Barbados!$L:$L, Barbados!$B:$B, $A3, Barbados!$D:$D, "Out Ports") + SUMIFS(Bermuda!$L:$L, Bermuda!$B:$B, $A3, Bermuda!$D:$D, "Out Ports") + SUMIFS(Jamaica!$L:$L, Jamaica!$B:$B, $A3, Jamaica!$D:$D, "Out Ports") + SUMIFS(Mountserat!$L:$L, Mountserat!$B:$B, $A3, Mountserat!$D:$D, "Out Ports") + SUMIFS(Nevis!$L:$L, Nevis!$B:$B, $A3, Nevis!$D:$D, "Out Ports") + SUMIFS('St Kitts'!$L:$L, 'St Kitts'!$B:$B, $A3, 'St Kitts'!$D:$D, "Out Ports") -> 0.20714286 | D3: =B3+C3 -> 10.439286
A4: Brown Sugar | B4: =SUMIFS(Antigua!$L:$L, Antigua!$B:$B, $A4, Antigua!$D:$D, "London") + SUMIFS(Barbados!$L:$L, Barbados!$B:$B, $A4, Barbados!$D:$D, "London") + SUMIFS(Bermuda!$L:$L, Bermuda!$B:$B, $A4, Bermuda!$D:$D, "London") + SUMIFS(Jamaica!$L:$L, Jamaica!$B:$B, $A4, Jamaica!$D:$D, "London") + SUMIFS(Mountserat!$L:$L, Mountserat!$B:$B, $A4, Mountserat!$D:$D, "London") + SUMIFS(Nevis!$L:$L, Nevis!$B:$B, $A4, Nevis!$D:$D, "London") + SUMIFS('St Kitts'!$L:$L, 'St Kitts'!$B:$B, $A4, 'St Kitts'!$D:$D, "London") -> 37516.705 | C4: =SUMIFS(Antigua!$L:$L, Antigua!$B:$B, $A4, Antigua!$D:$D, "Out Ports") + SUMIFS(Barbados!$L:$L, Barbados!$B:$B, $A4, Barbados!$D:$D, "Out Ports") + SUMIFS(Bermuda!$L:$L, Bermuda!$B:$B, $A4, Bermuda!$D:$D, "Out Ports") + SUMIFS(Jamaica!$L:$L, Jamaica!$B:$B, $A4, Jamaica!$D:$D, "Out Ports") + SUMIFS(Mountserat!$L:$L, Mountserat!$B:$B, $A4, Mountserat!$D:$D, "Out Ports") + SUMIFS(Nevis!$L:$L, Nevis!$B:$B, $A4, Nevis!$D:$D, "Out Ports") + SUMIFS('St Kitts'!$L:$L, 'St Kitts'!$B:$B, $A4, 'St Kitts'!$D:$D, "Out Ports") -> 13443.581 | D4: =B4+C4 -> 50960.286
A5: Chocolate | B5: =SUMIFS(Antigua!$L:$L, Antigua!$B:$B, $A5, Antigua!$D:$D, "London") + SUMIFS(Barbados!$L:$L, Barbados!$B:$B, $A5, Barbados!$D:$D, "London") + SUMIFS(Bermuda!$L:$L, Bermuda!$B:$B, $A5, Bermuda!$D:$D, "London") + SUMIFS(Jamaica!$L:$L, Jamaica!$B:$B, $A5, Jamaica!$D:$D, "London") + SUMIFS(Mountserat!$L:$L, Mountserat!$B:$B, $A5, Mountserat!$D:$D, "London") + SUMIFS(Nevis!$L:$L, Nevis!$B:$B, $A5, Nevis!$D:$D, "London") + SUMIFS('St Kitts'!$L:$L, 'St Kitts'!$B:$B, $A5, 'St Kitts'!$D:$D, "London") -> 0 | C5: =SUMIFS(Antigua!$L:$L, Antigua!$B:$B, $A5, Antigua!$D:$D, "Out Ports") + SUMIFS(Barbados!$L:$L, Barbados!$B:$B, $A5, Barbados!$D:$D, "Out Ports") + SUMIFS(Bermuda!$L:$L, Bermuda!$B:$B, $A5, Bermuda!$D:$D, "Out Ports") + SUMIFS(Jamaica!$L:$L, Jamaica!$B:$B, $A5, Jamaica!$D:$D, "Out Ports") + SUMIFS(Mountserat!$L:$L, Mountserat!$B:$B, $A5, Mountserat!$D:$D, "Out Ports") + SUMIFS(Nevis!$L:$L, Nevis!$B:$B, $A5, Nevis!$D:$D, "Out Ports") + SUMIFS('St Kitts'!$L:$L, 'St Kitts'!$B:$B, $A5, 'St Kitts'!$D:$D, "Out Ports") -> 0 | D5: =B5+C5 -> 0
A6: Cocoa Nuts | B6: =SUMIFS(Antigua!$L:$L, Antigua!$B:$B, $A6, Antigua!$D:$D, "London") + SUMIFS(Barbados!$L:$L, Barbados!$B:$B, $A6, Barbados!$D:$D, "London") + SUMIFS(Bermuda!$L:$L, Bermuda!$B:$B, $A6, Bermuda!$D:$D, "London") + SUMIFS(Jamaica!$L:$L, Jamaica!$B:$B, $A6, Jamaica!$D:$D, "London") + SUMIFS(Mountserat!$L:$L, Mountserat!$B:$B, $A6, Mountserat!$D:$D, "London") + SUMIFS(Nevis!$L:$L, Nevis!$B:$B, $A6, Nevis!$D:$D, "London") + SUMIFS('St Kitts'!$L:$L, 'St Kitts'!$B:$B, $A6, 'St Kitts'!$D:$D, "London") -> 80.222321 | C6: =SUMIFS(Antigua!$L:$L, Antigua!$B:$B, $A6, Antigua!$D:$D, "Out Ports") + SUMIFS(Barbados!$L:$L, Barbados!$B:$B, $A6, Barbados!$D:$D, "Out Ports") + SUMIFS(Bermuda!$L:$L, Bermuda!$B:$B, $A6, Bermuda!$D:$D, "Out Ports") + SUMIFS(Jamaica!$L:$L, Jamaica!$B:$B, $A6, Jamaica!$D:$D, "Out Ports") + SUMIFS(Mountserat!$L:$L, Mountserat!$B:$B, $A6, Mountserat!$D:$D, "Out Ports") + SUMIFS(Nevis!$L:$L, Nevis!$B:$B, $A6, Nevis!$D:$D, "Out Ports") + SUMIFS('St Kitts'!$L:$L, 'St Kitts'!$B:$B, $A6, 'St Kitts'!$D:$D, "Out Ports") -> 5.74375 | D6: =B6+C6 -> 85.966071
A7: Cotton | B7: =SUMIFS(Antigua!$L:$L, Antigua!$B:$B, $A7, Antigua!$D:$D, "London") + SUMIFS(Barbados!$L:$L, Barbados!$B:$B, $A7, Barbados!$D:$D, "London") + SUMIFS(Bermuda!$L:$L, Bermuda!$B:$B, $A7, Bermuda!$D:$D, "London") + SUMIFS(Jamaica!$L:$L, Jamaica!$B:$B, $A7, Jamaica!$D:$D, "London") + SUMIFS(Mountserat!$L:$L, Mountserat!$B:$B, $A7, Mountserat!$D:$D, "London") + SUMIFS(Nevis!$L:$L, Nevis!$B:$B, $A7, Nevis!$D:$D, "London") + SUMIFS('St Kitts'!$L:$L, 'St Kitts'!$B:$B, $A7, 'St Kitts'!$D:$D, "London") -> 133.90625 | C7: =SUMIFS(Antigua!$L:$L, Antigua!$B:$B, $A7, Antigua!$D:$D, "Out Ports") + SUMIFS(Barbados!$L:$L, Barbados!$B:$B, $A7, Barbados!$D:$D, "Out Ports") + SUMIFS(Bermuda!$L:$L, Bermuda!$B:$B, $A7, Bermuda!$D:$D, "Out Ports") + SUMIFS(Jamaica!$L:$L, Jamaica!$B:$B, $A7, Jamaica!$D:$D, "Out Ports") + SUMIFS(Mountserat!$L:$L, Mountserat!$B:$B, $A7, Mountserat!$D:$D, "Out Ports") + SUMIFS(Nevis!$L:$L, Nevis!$B:$B, $A7, Nevis!$D:$D, "Out Ports") + SUMIFS('St Kitts'!$L:$L, 'St Kitts'!$B:$B, $A7, 'St Kitts'!$D:$D, "Out Ports") -> 366.0808 | D7: =B7+C7 -> 499.98705
A8: Dry Ginger | B8: =SUMIFS(Antigua!$L:$L, Antigua!$B:$B, $A8, Antigua!$D:$D, "London") + SUMIFS(Barbados!$L:$L, Barbados!$B:$B, $A8, Barbados!$D:$D, "London") + SUMIFS(Bermuda!$L:$L, Bermuda!$B:$B, $A8, Bermuda!$D:$D, "London") + SUMIFS(Jamaica!$L:$L, Jamaica!$B:$B, $A8, Jamaica!$D:$D, "London") + SUMIFS(Mountserat!$L:$L, Mountserat!$B:$B, $A8, Mountserat!$D:$D, "London") + SUMIFS(Nevis!$L:$L, Nevis!$B:$B, $A8, Nevis!$D:$D, "London") + SUMIFS('St Kitts'!$L:$L, 'St Kitts'!$B:$B, $A8, 'St Kitts'!$D:$D, "London") -> 344.86473 | C8: =SUMIFS(Antigua!$L:$L, Antigua!$B:$B, $A8, Antigua!$D:$D, "Out Ports") + SUMIFS(Barbados!$L:$L, Barbados!$B:$B, $A8, Barbados!$D:$D, "Out Ports") + SUMIFS(Bermuda!$L:$L, Bermuda!$B:$B, $A8, Bermuda!$D:$D, "Out Ports") + SUMIFS(Jamaica!$L:$L, Jamaica!$B:$B, $A8, Jamaica!$D:$D, "Out Ports") + SUMIFS(Mountserat!$L:$L, Mountserat!$B:$B, $A8, Mountserat!$D:$D, "Out Ports") + SUMIFS(Nevis!$L:$L, Nevis!$B:$B, $A8, Nevis!$D:$D, "Out Ports") + SUMIFS('St Kitts'!$L:$L, 'St Kitts'!$B:$B, $A8, 'St Kitts'!$D:$D, "Out Ports") -> 264.34018 | D8: =B8+C8 -> 609.20491
A9: Elephant Teeth | B9: =SUMIFS(Antigua!$L:$L, Antigua!$B:$B, $A9, Antigua!$D:$D, "London") + SUMIFS(Barbados!$L:$L, Barbados!$B:$B, $A9, Barbados!$D:$D, "London") + SUMIFS(Bermuda!$L:$L, Bermuda!$B:$B, $A9, Bermuda!$D:$D, "London") + SUMIFS(Jamaica!$L:$L, Jamaica!$B:$B, $A9, Jamaica!$D:$D, "London") + SUMIFS(Mountserat!$L:$L, Mountserat!$B:$B, $A9, Mountserat!$D:$D, "London") + SUMIFS(Nevis!$L:$L, Nevis!$B:$B, $A9, Nevis!$D:$D, "London") + SUMIFS('St Kitts'!$L:$L, 'St Kitts'!$B:$B, $A9, 'St Kitts'!$D:$D, "London") -> 19.082589 | C9: =SUMIFS(Antigua!$L:$L, Antigua!$B:$B, $A9, Antigua!$D:$D, "Out Ports") + SUMIFS(Barbados!$L:$L, Barbados!$B:$B, $A9, Barbados!$D:$D, "Out Ports") + SUMIFS(Bermuda!$L:$L, Bermuda!$B:$B, $A9, Bermuda!$D:$D, "Out Ports") + SUMIFS(Jamaica!$L:$L, Jamaica!$B:$B, $A9, Jamaica!$D:$D, "Out Ports") + SUMIFS(Mountserat!$L:$L, Mountserat!$B:$B, $A9, Mountserat!$D:$D, "Out Ports") + SUMIFS(Nevis!$L:$L, Nevis!$B:$B, $A9, Nevis!$D:$D, "Out Ports") + SUMIFS('St Kitts'!$L:$L, 'St Kitts'!$B:$B, $A9, 'St Kitts'!$D:$D, "Out Ports") -> 22.441071 | D9: =B9+C9 -> 41.523661
A10: Indigo | B10: =SUMIFS(Antigua!$L:$L, Antigua!$B:$B, $A10, Antigua!$D:$D, "London") + SUMIFS(Barbados!$L:$L, Barbados!$B:$B, $A10, Barbados!$D:$D, "London") + SUMIFS(Bermuda!$L:$L, Bermuda!$B:$B, $A10, Bermuda!$D:$D, "London") + SUMIFS(Jamaica!$L:$L, Jamaica!$B:$B, $A10, Jamaica!$D:$D, "London") + SUMIFS(Mountserat!$L:$L, Mountserat!$B:$B, $A10, Mountserat!$D:$D, "London") + SUMIFS(Nevis!$L:$L, Nevis!$B:$B, $A10, Nevis!$D:$D, "London") + SUMIFS('St Kitts'!$L:$L, 'St Kitts'!$B:$B, $A10, 'St Kitts'!$D:$D, "London") -> 91.705804 | C10: =SUMIFS(Antigua!$L:$L, Antigua!$B:$B, $A10, Antigua!$D:$D, "Out Ports") + SUMIFS(Barbados!$L:$L, Barbados!$B:$B, $A10, Barbados!$D:$D, "Out Ports") + SUMIFS(Bermuda!$L:$L, Bermuda!$B:$B, $A10, Bermuda!$D:$D, "Out Ports") + SUMIFS(Jamaica!$L:$L, Jamaica!$B:$B, $A10, Jamaica!$D:$D, "Out Ports") + SUMIFS(Mountserat!$L:$L, Mountserat!$B:$B, $A10, Mountserat!$D:$D, "Out Ports") + SUMIFS(Nevis!$L:$L, Nevis!$B:$B, $A10, Nevis!$D:$D, "Out Ports") + SUMIFS('St Kitts'!$L:$L, 'St Kitts'!$B:$B, $A10, 'St Kitts'!$D:$D, "Out Ports") -> 54.743304 | D10: =B10+C10 -> 146.44911
A11: Lignum Vitae | B11: =SUMIFS(Antigua!$L:$L, Antigua!$B:$B, $A11, Antigua!$D:$D, "London") + SUMIFS(Barbados!$L:$L, Barbados!$B:$B, $A11, Barbados!$D:$D, "London") + SUMIFS(Bermuda!$L:$L, Bermuda!$B:$B, $A11, Bermuda!$D:$D, "London") + SUMIFS(Jamaica!$L:$L, Jamaica!$B:$B, $A11, Jamaica!$D:$D, "London") + SUMIFS(Mountserat!$L:$L, Mountserat!$B:$B, $A11, Mountserat!$D:$D, "London") + SUMIFS(Nevis!$L:$L, Nevis!$B:$B, $A11, Nevis!$D:$D, "London") + SUMIFS('St Kitts'!$L:$L, 'St Kitts'!$B:$B, $A11, 'St Kitts'!$D:$D, "London") -> 9.1625 | C11: =SUMIFS(Antigua!$L:$L, Antigua!$B:$B, $A11, Antigua!$D:$D, "Out Ports") + SUMIFS(Barbados!$L:$L, Barbados!$B:$B, $A11, Barbados!$D:$D, "Out Ports") + SUMIFS(Bermuda!$L:$L, Bermuda!$B:$B, $A11, Bermuda!$D:$D, "Out Ports") + SUMIFS(Jamaica!$L:$L, Jamaica!$B:$B, $A11, Jamaica!$D:$D, "Out Ports") + SUMIFS(Mountserat!$L:$L, Mountserat!$B:$B, $A11, Mountserat!$D:$D, "Out Ports") + SUMIFS(Nevis!$L:$L, Nevis!$B:$B, $A11, Nevis!$D:$D, "Out Ports") + SUMIFS('St Kitts'!$L:$L, 'St Kitts'!$B:$B, $A11, 'St Kitts'!$D:$D, "Out Ports") -> 44.424107 | D11: =B11+C11 -> 53.586607
A12: Lime Juice | B12: =SUMIFS(Antigua!$L:$L, Antigua!$B:$B, $A12, Antigua!$D:$D, "London") + SUMIFS(Barbados!$L:$L, Barbados!$B:$B, $A12, Barbados!$D:$D, "London") + SUMIFS(Bermuda!$L:$L, Bermuda!$B:$B, $A12, Bermuda!$D:$D, "London") + SUMIFS(Jamaica!$L:$L, Jamaica!$B:$B, $A12, Jamaica!$D:$D, "London") + SUMIFS(Mountserat!$L:$L, Mountserat!$B:$B, $A12, Mountserat!$D:$D, "London") + SUMIFS(Nevis!$L:$L, Nevis!$B:$B, $A12, Nevis!$D:$D, "London") + SUMIFS('St Kitts'!$L:$L, 'St Kitts'!$B:$B, $A12, 'St Kitts'!$D:$D, "London") -> 15.337054 | C12: =SUMIFS(Antigua!$L:$L, Antigua!$B:$B, $A12, Antigua!$D:$D, "Out Ports") + SUMIFS(Barbados!$L:$L, Barbados!$B:$B, $A12, Barbados!$D:$D, "Out Ports") + SUMIFS(Bermuda!$L:$L, Bermuda!$B:$B, $A12, Bermuda!$D:$D, "Out Ports") + SUMIFS(Jamaica!$L:$L, Jamaica!$B:$B, $A12, Jamaica!$D:$D, "Out Ports") + SUMIFS(Mountserat!$L:$L, Mountserat!$B:$B, $A12, Mountserat!$D:$D, "Out Ports") + SUMIFS(Nevis!$L:$L, Nevis!$B:$B, $A12, Nevis!$D:$D, "Out Ports") + SUMIFS('St Kitts'!$L:$L, 'St Kitts'!$B:$B, $A12, 'St Kitts'!$D:$D, "Out Ports") -> 5.0325893 | D12: =B12+C12 -> 20.369643
A13: Molasses | B13: =SUMIFS(Antigua!$L:$L, Antigua!$B:$B, $A13, Antigua!$D:$D, "London") + SUMIFS(Barbados!$L:$L, Barbados!$B:$B, $A13, Barbados!$D:$D, "London") + SUMIFS(Bermuda!$L:$L, Bermuda!$B:$B, $A13, Bermuda!$D:$D, "London") + SUMIFS(Jamaica!$L:$L, Jamaica!$B:$B, $A13, Jamaica!$D:$D, "London") + SUMIFS(Mountserat!$L:$L, Mountserat!$B:$B, $A13, Mountserat!$D:$D, "London") + SUMIFS(Nevis!$L:$L, Nevis!$B:$B, $A13, Nevis!$D:$D, "London") + SUMIFS('St Kitts'!$L:$L, 'St Kitts'!$B:$B, $A13, 'St Kitts'!$D:$D, "London") -> 2.675 | C13: =SUMIFS(Antigua!$L:$L, Antigua!$B:$B, $A13, Antigua!$D:$D, "Out Ports") + SUMIFS(Barbados!$L:$L, Barbados!$B:$B, $A13, Barbados!$D:$D, "Out Ports") + SUMIFS(Bermuda!$L:$L, Bermuda!$B:$B, $A13, Bermuda!$D:$D, "Out Ports") + SUMIFS(Jamaica!$L:$L, Jamaica!$B:$B, $A13, Jamaica!$D:$D, "Out Ports") + SUMIFS(Mountserat!$L:$L, Mountserat!$B:$B, $A13, Mountserat!$D:$D, "Out Ports") + SUMIFS(Nevis!$L:$L, Nevis!$B:$B, $A13, Nevis!$D:$D, "Out Ports") + SUMIFS('St Kitts'!$L:$L, 'St Kitts'!$B:$B, $A13, 'St Kitts'!$D:$D, "Out Ports") -> 12.141518 | D13: =B13+C13 -> 14.816518
... A31: Wood, Sweetwood | B31: =SUMIFS(Antigua!$L:$L, Antigua!$B:$B, $A31, Antigua!$D:$D, "London") + SUMIFS(Barbados!$L:$L, Barbados!$B:$B, $A31, Barbados!$D:$D, "London") + SUMIFS(Bermuda!$L:$L, Bermuda!$B:$B, $A31, Bermuda!$D:$D, "London") + SUMIFS(Jamaica!$L:$L, Jamaica!$B:$B, $A31, Jamaica!$D:$D, "London") + SUMIFS(Mountserat!$L:$L, Mountserat!$B:$B, $A31, Mountserat!$D:$D, "London") + SUMIFS(Nevis!$L:$L, Nevis!$B:$B, $A31, Nevis!$D:$D, "London") + SUMIFS('St Kitts'!$L:$L, 'St Kitts'!$B:$B, $A31, 'St Kitts'!$D:$D, "London") -> 0 | C31: =SUMIFS(Antigua!$L:$L, Antigua!$B:$B, $A31, Antigua!$D:$D, "Out Ports") + SUMIFS(Barbados!$L:$L, Barbados!$B:$B, $A31, Barbados!$D:$D, "Out Ports") + SUMIFS(Bermuda!$L:$L, Bermuda!$B:$B, $A31, Bermuda!$D:$D, "Out Ports") + SUMIFS(Jamaica!$L:$L, Jamaica!$B:$B, $A31, Jamaica!$D:$D, "Out Ports") + SUMIFS(Mountserat!$L:$L, Mountserat!$B:$B, $A31, Mountserat!$D:$D, "Out Ports") + SUMIFS(Nevis!$L:$L, Nevis!$B:$B, $A31, Nevis!$D:$D, "Out Ports") + SUMIFS('St Kitts'!$L:$L, 'St Kitts'!$B:$B, $A31, 'St Kitts'!$D:$D, "Out Ports") -> 0 | D31: =B31+C31 -> 0

Sheet Antigua
A1: YEAR | B1: COMMODITY_NAME | C1: FROM_LOCATION | D1: TO_LOCATION | E1: ton | F1: hh | G1: quarter | H1: lb | J1: Total Pounds | L1: WEIGHT
A2: 1730 | B2: Annatto | C2: Antigua | D2: London | J2: =(E2*2240)+(F2*112)+(G2*28)+H2 -> 0 | L2: =J2/2240 -> 0
A3: 1730 | B3: Bees Wax | C3: Antigua | D3: London | F3: 108 | G3: 1 | H3: 16 | J3: =(E3*2240)+(F3*112)+(G3*28)+H3 -> 12140 | L3: =J3/2240 -> 5.4196429
A4: 1730 | B4: Brown Sugar | C4: Antigua | D4: London | F4: 154347 | G4: 1 | H4: 17 | J4: =(E4*2240)+(F4*112)+(G4*28)+H4 -> 17286909 | L4: =J4/2240 -> 7717.3701
A5: 1730 | B5: Chocolate | C5: Antigua | D5: London | J5: =(E5*2240)+(F5*112)+(G5*28)+H5 -> 0 | L5: =J5/2240 -> 0
A6: 1730 | B6: Cocoa Nuts | C6: Antigua | D6: London | F6: 3 | G6: 3 | J6: =(E6*2240)+(F6*112)+(G6*28)+H6 -> 420 | L6: =J6/2240 -> 0.1875
A7: 1730 | B7: Cotton | C7: Antigua | D7: London | H7: =196.25*200 -> 39250 | I7: 196.25bag | J7: =(E7*2240)+(F7*112)+(G7*28)+H7 -> 39250 | L7: =J7/2240 -> 17.522321
A8: 1730 | B8: Dry Ginger | C8: Antigua | D8: London | F8: 278 | H8: 19 | J8: =(E8*2240)+(F8*112)+(G8*28)+H8 -> 31155 | L8: =J8/2240 -> 13.908482
A9: 1730 | B9: Elephant Teeth | C9: Antigua | D9: London | F9: 100 | G9: 2 | H9: 18 | J9: =(E9*2240)+(F9*112)+(G9*28)+H9 -> 11274 | L9: =J9/2240 -> 5.0330357
A10: 1730 | B10: Green Ginger | C10: Antigua | D10: London | J10: =(E10*2240)+(F10*112)+(G10*28)+H10 -> 0 | L10: =J10/2240 -> 0
A11: 1730 | B11: Indigo | C11: Antigua | D11: London | H11: 26 | J11: =(E11*2240)+(F11*112)+(G11*28)+H11 -> 26 | L11: =J11/2240 -> 0.011607143
A12: 1730 | B12: Lemon Water | C12: Antigua | D12: London | J12: =(E12*2240)+(F12*112)+(G12*28)+H12 -> 0 | L12: =J12/2240 -> 0
A13: 1730 | B13: Lignum Vitae | C13: Antigua | D13: London | E13: 1 | J13: =(E13*2240)+(F13*112)+(G13*28)+H13 -> 2240 | L13: =J13/2240 -> 1
A14: 1730 | B14: Lime Juice | C14: Antigua | D14: London | J14: =(E14*2240)+(F14*112)+(G14*28)+H14 -> 0 | L14: =J14/2240 -> 0
A15: 1730 | B15: Madera Wine | C15: Antigua | D15: London | H15: 76461 | I15: 30t 16g | J15: =(E15*2240)+(F15*112)+(G15*28)+H15 -> 76461 | L15: =J15/2240 -> 34.134375
A16: 1730 | B16: Molasses | C16: Antigua | D16: London | E16: 1 | F16: 10 | J16: =(E16*2240)+(F16*112)+(G16*28)+H16 -> 3360 | L16: =J16/2240 -> 1.5
A17: 1730 | B17: Pickles | C17: Antigua | D17: London | J17: =(E17*2240)+(F17*112)+(G17*28)+H17 -> 0 | L17: =J17/2240 -> 0
A18: 1730 | B18: Rum | C18: Antigua | D18: London | J18: =(E18*2240)+(F18*112)+(G18*28)+H18 -> 0 | L18: =J18/2240 -> 0
A19: 1730 | B19: Shruff | C19: Antigua | D19: London | F19: 14 | G19: 2 | H19: 11 | J19: =(E19*2240)+(F19*112)+(G19*28)+H19 -> 1635 | L19: =J19/2240 -> 0.72991071
A20: 1730 | B20: Succads | C20: Antigua | D20: London | H20: 321 | J20: =(E20*2240)+(F20*112)+(G20*28)+H20 -> 321 | L20: =J20/2240 -> 0.14330357
A21: 1730 | B21: Tobacco | C21: Antigua | D21: London | H21: 6014 | J21: =(E21*2240)+(F21*112)+(G21*28)+H21 -> 6014 | L21: =J21/2240 -> 2.6848214
A22: 1730 | B22: Tortoise Shell | C22: Antigua | D22: London | H22: 21 | J22: =(E22*2240)+(F22*112)+(G22*28)+H22 -> 21 | L22: =J22/2240 -> 0.009375
A23: 1730 | B23: White Sugar | C23: Antigua | D23: London | J23: =(E23*2240)+(F23*112)+(G23*28)+H23 -> 0 | L23: =J23/2240 -> 0
A24: 1730 | B24: Wood, Braziletto | C24: Antigua | D24: London | F24: 12 | J24: =(E24*2240)+(F24*112)+(G24*28)+H24 -> 1344 | L24: =J24/2240 -> 0.6
A25: 1730 | B25: Wood, Fustick | C25: Antigua | D25: London | F25: 19 | H25: 22 | J25: =(E25*2240)+(F25*112)+(G25*28)+H25 -> 2150 | L25: =J25/2240 -> 0.95982143
A26: 1730 | B26: Brown Sugar | C26: Antigua | D26: Out Ports | F26: 27930 | H26: 26 | J26: =(E26*2240)+(F26*112)+(G26*28)+H26 -> 3128186 | L26: =J26/2240 -> 1396.5116
A27: 1730 | B27: Cocoa | C27: Antigua | D27: Out Ports | J27: =(E27*2240)+(F27*112)+(G27*28)+H27 -> 0 | L27: =J27/2240 -> 0
A28: 1730 | B28: Cocoa Nuts | C28: Antigua | D28: Out Ports | J28: =(E28*2240)+(F28*112)+(G28*28)+H28 -> 0 | L28: =J28/2240 -> 0
A29: 1730 | B29: Cotton | C29: Antigua | D29: Out Ports | H29: 302940 | J29: =(E29*2240)+(F29*112)+(G29*28)+H29 -> 302940 | L29: =J29/2240 -> 135.24107
A30: 1730 | B30: Dry Ginger | C30: Antigua | D30: Out Ports | F30: 150 | G30: 2 | H30: 14 | J30: =(E30*2240)+(F30*112)+(G30*28)+H30 -> 16870 | L30: =J30/2240 -> 7.53125
A31: 1730 | B31: Elephant Teeth | C31: Antigua | D31: Out Ports | F31: 13 | G31: 2 | H31: 15 | J31: =(E31*2240)+(F31*112)+(G31*28)+H31 -> 1527 | L31: =J31/2240 -> 0.68169643
A32: 1730 | B32: Green Ginger | C32: Antigua | D32: Out Ports | H32: 4 | J32: =(E32*2240)+(F32*112)+(G32*28)+H32 -> 4 | L32: =J32/2240 -> 0.0017857143
A33: 1730 | B33: Indigo | C33: Antigua | D33: Out Ports | H33: 200 | J33: =(E33*2240)+(F33*112)+(G33*28)+H33 -> 200 | L33: =J33/2240 -> 0.089285714
A34: 1730 | B34: Lignum Vitae | C34: Antigua | D34: Out Ports | J34: =(E34*2240)+(F34*112)+(G34*28)+H34 -> 0 | L34: =J34/2240 -> 0
A35: 1730 | B35: Lime Juice | C35: Antigua | D35: Out Ports | J35: =(E35*2240)+(F35*112)+(G35*28)+H35 -> 0 | L35: =J35/2240 -> 0
A36: 1730 | B36: Madera Wine | C36: Antigua | D36: Out Ports | H36: 6338 | I36: 2t 1h 61g | J36: =(E36*2240)+(F36*112)+(G36*28)+H36 -> 6338 | L36: =J36/2240 -> 2.8294643
A37: 1730 | B37: Molasses | C37: Antigua | D37: Out Ports | F37: 17 | G37: 2 | H37: 27 | J37: =(E37*2240)+(F37*112)+(G37*28)+H37 -> 1987 | L37: =J37/2240 -> 0.88705357
A38: 1730 | B38: Rice | C38: Antigua | D38: Out Ports | F38: 220 | G38: 1 | H38: 5 | J38: =(E38*2240)+(F38*112)+(G38*28)+H38 -> 24673 | L38: =J38/2240 -> 11.014732
A39: 1730 | B39: Rum | C39: Antigua | D39: Out Ports | H39: 79045 | I39: 7832g | J39: =(E39*2240)+(F39*112)+(G39*28)+H39 -> 79045 | L39: =J39/2240 -> 35.287946
A40: 1730 | B40: Shruff | C40: Antigua | D40: Out Ports | F40: 1 | G40: 3 | J40: =(E40*2240)+(F40*112)+(G40*28)+H40 -> 196 | L40: =J40/2240 -> 0.0875
...

Sheet Barbados
A1: YEAR | B1: COMMODITY_NAME | C1: FROM_LOCATION | D1: TO_LOCATION | E1: ton | F1: hh | G1: quarter | H1: lb | J1: Total Pounds | L1: WEIGHT
A2: 1730 | B2: Almonds, Bitter | C2: Barbados | D2: London | H2: 40 | J2: =(E2*2240)+(F2*112)+(G2*28)+H2 -> 40 | L2: =J2/2240 -> 0.017857143
A3: 1730 | B3: Almonds, Sweet | C3: Barbados | D3: London | J3: =(E3*2240)+(F3*112)+(G3*28)+H3 -> 0 | L3: =J3/2240 -> 0
A4: 1730 | B4: Aloes Epatica | C4: Barbados | D4: London | H4: 9309 | J4: =(E4*2240)+(F4*112)+(G4*28)+H4 -> 9309 | L4: =J4/2240 -> 4.1558036
A5: 1730 | B5: Annatto | C5: Barbados | D5: London | H5: 56 | J5: =(E5*2240)+(F5*112)+(G5*28)+H5 -> 56 | L5: =J5/2240 -> 0.025
A6: 1730 | B6: Anniseeds | C6: Barbados | D6: London | J6: =(E6*2240)+(F6*112)+(G6*28)+H6 -> 0 | L6: =J6/2240 -> 0
A7: 1730 | B7: Barrel Staves | C7: Barbados | D7: London | J7: =(E7*2240)+(F7*112)+(G7*28)+H7 -> 0 | L7: =J7/2240 -> 0
A8: 1730 | B8: Bees Wax | C8: Barbados | D8: London | J8: =(E8*2240)+(F8*112)+(G8*28)+H8 -> 0 | L8: =J8/2240 -> 0
A9: 1730 | B9: Brimstone | C9: Barbados | D9: London | J9: =(E9*2240)+(F9*112)+(G9*28)+H9 -> 0 | L9: =J9/2240 -> 0
A10: 1730 | B10: Brown Sugar | C10: Barbados | D10: London | F10: 170162 | G10: 1 | H10: 3 | J10: =(E10*2240)+(F10*112)+(G10*28)+H10 -> 19058175 | L10: =J10/2240 -> 8508.1138
A11: 1730 | B11: Cassia Fistula | C11: Barbados | D11: London | H11: 4991 | J11: =(E11*2240)+(F11*112)+(G11*28)+H11 -> 4991 | L11: =J11/2240 -> 2.228125
A12: 1730 | B12: Chocolate Paste | C12: Barbados | D12: London | J12: =(E12*2240)+(F12*112)+(G12*28)+H12 -> 0 | L12: =J12/2240 -> 0
A13: 1730 | B13: Cocheneal | C13: Barbados | D13: London | J13: =(E13*2240)+(F13*112)+(G13*28)+H13 -> 0 | L13: =J13/2240 -> 0
A14: 1730 | B14: Cocoa Nuts | C14: Barbados | D14: London | F14: 40 | G14: 3 | H14: 15 | J14: =(E14*2240)+(F14*112)+(G14*28)+H14 -> 4579 | L14: =J14/2240 -> 2.0441964
A15: 1730 | B15: Cocoa Paste | C15: Barbados | D15: London | J15: =(E15*2240)+(F15*112)+(G15*28)+H15 -> 0 | L15: =J15/2240 -> 0
A16: 1730 | B16: Coffee | C16: Barbados | D16: London | H16: 61 | J16: =(E16*2240)+(F16*112)+(G16*28)+H16 -> 61 | L16: =J16/2240 -> 0.027232143
A17: 1730 | B17: Cotton | C17: Barbados | D17: London | H17: =220*200 -> 44000 | I17: 220bag | J17: =(E17*2240)+(F17*112)+(G17*28)+H17 -> 44000 | L17: =J17/2240 -> 19.642857
A18: 1730 | B18: Dry Ginger | C18: Barbados | D18: London | F18: 3301 | G18: 2 | H18: 14 | J18: =(E18*2240)+(F18*112)+(G18*28)+H18 -> 369782 | L18: =J18/2240 -> 165.08125
A19: 1730 | B19: Elephant Teeth | C19: Barbados | D19: London | F19: 114 | H19: 11 | J19: =(E19*2240)+(F19*112)+(G19*28)+H19 -> 12779 | L19: =J19/2240 -> 5.7049107
A20: 1730 | B20: Green Ginger | C20: Barbados | D20: London | H20: 185 | J20: =(E20*2240)+(F20*112)+(G20*28)+H20 -> 185 | L20: =J20/2240 -> 0.082589286
A21: 1730 | B21: Hemp | C21: Barbados | D21: London | J21: =(E21*2240)+(F21*112)+(G21*28)+H21 -> 0 | L21: =J21/2240 -> 0
A22: 1730 | B22: Indigo | C22: Barbados | D22: London | H22: 321 | J22: =(E22*2240)+(F22*112)+(G22*28)+H22 -> 321 | L22: =J22/2240 -> 0.14330357
A23: 1730 | B23: Lemon Water | C23: Barbados | D23: London | J23: =(E23*2240)+(F23*112)+(G23*28)+H23 -> 0 | L23: =J23/2240 -> 0
A24: 1730 | B24: Lignum Vitae | C24: Barbados | D24: London | J24: =(E24*2240)+(F24*112)+(G24*28)+H24 -> 0 | L24: =J24/2240 -> 0
A25: 1730 | B25: Lime Juice | C25: Barbados | D25: London | H25: 6288 | I25: 623g | J25: =(E25*2240)+(F25*112)+(G25*28)+H25 -> 6288 | L25: =J25/2240 -> 2.8071429
A26: 1730 | B26: Loaf Sugar | C26: Barbados | D26: London | J26: =(E26*2240)+(F26*112)+(G26*28)+H26 -> 0 | L26: =J26/2240 -> 0
A27: 1730 | B27: Madera Wine | C27: Barbados | D27: London | H27: 79540 | I27: 31t 1h 6g | J27: =(E27*2240)+(F27*112)+(G27*28)+H27 -> 79540 | L27: =J27/2240 -> 35.508929
A28: 1730 | B28: Molasses | C28: Barbados | D28: London | J28: =(E28*2240)+(F28*112)+(G28*28)+H28 -> 0 | L28: =J28/2240 -> 0
A29: 1730 | B29: Oranges | C29: Barbados | D29: London | J29: =(E29*2240)+(F29*112)+(G29*28)+H29 -> 0 | L29: =J29/2240 -> 0
A30: 1730 | B30: Pickles | C30: Barbados | D30: London | J30: =(E30*2240)+(F30*112)+(G30*28)+H30 -> 0 | L30: =J30/2240 -> 0
A31: 1730 | B31: Pimento | C31: Barbados | D31: London | J31: =(E31*2240)+(F31*112)+(G31*28)+H31 -> 0 | L31: =J31/2240 -> 0
A32: 1730 | B32: Rice | C32: Barbados | D32: London | F32: 68 | G32: 2 | H32: 4 | J32: =(E32*2240)+(F32*112)+(G32*28)+H32 -> 7676 | L32: =J32/2240 -> 3.4267857
A33: 1730 | B33: Rum | C33: Barbados | D33: London | H33: 425715 | I33: 42181g | J33: =(E33*2240)+(F33*112)+(G33*28)+H33 -> 425715 | L33: =J33/2240 -> 190.05134
A34: 1730 | B34: Shruff | C34: Barbados | D34: London | F34: 9 | G34: 2 | H34: 7 | J34: =(E34*2240)+(F34*112)+(G34*28)+H34 -> 1071 | L34: =J34/2240 -> 0.478125
A35: 1730 | B35: Snuff | C35: Barbados | D35: London | J35: =(E35*2240)+(F35*112)+(G35*28)+H35 -> 0 | L35: =J35/2240 -> 0
A36: 1730 | B36: Succads | C36: Barbados | D36: London | H36: 2626 | J36: =(E36*2240)+(F36*112)+(G36*28)+H36 -> 2626 | L36: =J36/2240 -> 1.1723214
A37: 1730 | B37: Tobacco | C37: Barbados | D37: London | H37: 2537 | J37: =(E37*2240)+(F37*112)+(G37*28)+H37 -> 2537 | L37: =J37/2240 -> 1.1325893
A38: 1730 | B38: Tortoise Shell | C38: Barbados | D38: London | H38: 7 | J38: =(E38*2240)+(F38*112)+(G38*28)+H38 -> 7 | L38: =J38/2240 -> 0.003125
A39: 1730 | B39: White Sugar | C39: Barbados | D39: London | J39: =(E39*2240)+(F39*112)+(G39*28)+H39 -> 0 | L39: =J39/2240 -> 0
A40: 1730 | B40: Wood, Braziletto | C40: Barbados | D40: London | J40: =(E40*2240)+(F40*112)+(G40*28)+H40 -> 0 | L40: =J40/2240 -> 0
...

Sheet Bermuda
A1: YEAR | B1: COMMODITY_NAME | C1: FROM_LOCATION | D1: TO_LOCATION | E1: ton | F1: hh | G1: quarter | H1: lb | J1: Total Pounds | L1: WEIGHT
A2: 1730 | B2: Bermudos Plat | C2: Bermuda | D2: London | J2: =(E2*2240)+(F2*112)+(G2*28)+H2 -> 0 | L2: =J2/2240 -> 0
A3: 1730 | B3: Brown Sugar | C3: Bermuda | D3: London | F3: 178 | H3: 13 | J3: =(E3*2240)+(F3*112)+(G3*28)+H3 -> 19949 | L3: =J3/2240 -> 8.9058036
A4: 1730 | B4: Cocoa Nuts | C4: Bermuda | D4: London | J4: =(E4*2240)+(F4*112)+(G4*28)+H4 -> 0 | L4: =J4/2240 -> 0
A5: 1730 | B5: Cotton | C5: Bermuda | D5: London | J5: =(E5*2240)+(F5*112)+(G5*28)+H5 -> 0 | L5: =J5/2240 -> 0
A6: 1730 | B6: Rum | C6: Bermuda | D6: London | H6: 3532 | I6: 350g | J6: =(E6*2240)+(F6*112)+(G6*28)+H6 -> 3532 | L6: =J6/2240 -> 1.5767857
A7: 1730 | B7: Wood, Braziletto | C7: Bermuda | D7: London | J7: =(E7*2240)+(F7*112)+(G7*28)+H7 -> 0 | L7: =J7/2240 -> 0
A8: 1730 | B8: Wood, Logwood | C8: Bermuda | D8: London | J8: =(E8*2240)+(F8*112)+(G8*28)+H8 -> 0 | L8: =J8/2240 -> 0
A9: 1730 | B9: Indigo | C9: Bermuda | D9: Out Ports | J9: =(E9*2240)+(F9*112)+(G9*28)+H9 -> 0 | L9: =J9/2240 -> 0
A10: 1730 | B10: Logwood | C10: Bermuda | D10: Out Ports | J10: =(E10*2240)+(F10*112)+(G10*28)+H10 -> 0 | L10: =J10/2240 -> 0
A11: 1730 | B11: Shruff | C11: Bermuda | D11: Out Ports | J11: =(E11*2240)+(F11*112)+(G11*28)+H11 -> 0 | L11: =J11/2240 -> 0
A12: 1730 | B12: Succads | C12: Bermuda | D12: Out Ports | J12: =(E12*2240)+(F12*112)+(G12*28)+H12 -> 0 | L12: =J12/2240 -> 0
A13: 1730 | B13: Cotton | C13: Bermuda | D13: Out Ports | J13: =(E13*2240)+(F13*112)+(G13*28)+H13 -> 0 | L13: =J13/2240 -> 0
A14: 1730 | B14: Cocoa Nuts | C14: Bermuda | D14: Out Ports | J14: =(E14*2240)+(F14*112)+(G14*28)+H14 -> 0 | L14: =J14/2240 -> 0
A15: 1730 | B15: Wood, Braziletto | C15: Bermuda | D15: Out Ports | J15: =(E15*2240)+(F15*112)+(G15*28)+H15 -> 0 | L15: =J15/2240 -> 0
A16: 1730 | B16: Wood, Logwood | C16: Bermuda | D16: Out Ports | J16: =(E16*2240)+(F16*112)+(G16*28)+H16 -> 0 | L16: =J16/2240 -> 0

Sheet Jamaica
A1: YEAR | B1: COMMODITY_NAME | C1: FROM_LOCATION | D1: TO_LOCATION | E1: ton | F1: hh | G1: quarter | H1: lb | J1: Total Pounds | L1: WEIGHT
A2: 1730 | B2: Almonds, Bitter | C2: Jamaica | D2: London | J2: =(E2*2240)+(F2*112)+(G2*28)+H2 -> 0 | L2: =J2/2240 -> 0
A3: 1730 | B3: Almonds, Sweet | C3: Jamaica | D3: London | J3: =(E3*2240)+(F3*112)+(G3*28)+H3 -> 0 | L3: =J3/2240 -> 0
A4: 1730 | B4: Aloes Epatica | C4: Jamaica | D4: London | J4: =(E4*2240)+(F4*112)+(G4*28)+H4 -> 0 | L4: =J4/2240 -> 0
A5: 1730 | B5: Annatto | C5: Jamaica | D5: London | H5: 1118 | J5: =(E5*2240)+(F5*112)+(G5*28)+H5 -> 1118 | L5: =J5/2240 -> 0.49910714
A6: 1730 | B6: Anniseeds | C6: Jamaica | D6: London | G6: 2 | J6: =(E6*2240)+(F6*112)+(G6*28)+H6 -> 56 | L6: =J6/2240 -> 0.025
A7: 1730 | B7: Bacon | C7: Jamaica | D7: London | J7: =(E7*2240)+(F7*112)+(G7*28)+H7 -> 0 | L7: =J7/2240 -> 0
A8: 1730 | B8: Barrel Staves | C8: Jamaica | D8: London | J8: =(E8*2240)+(F8*112)+(G8*28)+H8 -> 0 | L8: =J8/2240 -> 0
A9: 1730 | B9: Bees Wax | C9: Jamaica | D9: London | F9: 23 | G9: 1 | H9: 14 | J9: =(E9*2240)+(F9*112)+(G9*28)+H9 -> 2618 | L9: =J9/2240 -> 1.16875
A10: 1730 | B10: Brimstone | C10: Jamaica | D10: London | J10: =(E10*2240)+(F10*112)+(G10*28)+H10 -> 0 | L10: =J10/2240 -> 0
A11: 1730 | B11: Brown Sugar | C11: Jamaica | D11: London | F11: 203131 | G11: 1 | H11: 18 | J11: =(E11*2240)+(F11*112)+(G11*28)+H11 -> 22750718 | L11: =J11/2240 -> 10156.571
A12: 1730 | B12: Cassia Fistula | C12: Jamaica | D12: London | H12: 400 | J12: =(E12*2240)+(F12*112)+(G12*28)+H12 -> 400 | L12: =J12/2240 -> 0.17857143
A13: 1730 | B13: Chocolate Paste | C13: Jamaica | D13: London | J13: =(E13*2240)+(F13*112)+(G13*28)+H13 -> 0 | L13: =J13/2240 -> 0
A14: 1730 | B14: Cocheneal | C14: Jamaica | D14: London | J14: =(E14*2240)+(F14*112)+(G14*28)+H14 -> 0 | L14: =J14/2240 -> 0
A15: 1730 | B15: Cocoa Nuts | C15: Jamaica | D15: London | F15: 121 | G15: 3 | H15: 21 | J15: =(E15*2240)+(F15*112)+(G15*28)+H15 -> 13657 | L15: =J15/2240 -> 6.096875
A16: 1730 | B16: Cocoa Paste | C16: Jamaica | D16: London | J16: =(E16*2240)+(F16*112)+(G16*28)+H16 -> 0 | L16: =J16/2240 -> 0
A17: 1730 | B17: Cortex Peru | C17: Jamaica | D17: London | H17: 3441 | J17: =(E17*2240)+(F17*112)+(G17*28)+H17 -> 3441 | L17: =J17/2240 -> 1.5361607
A18: 1730 | B18: Cortex Winteranus | C18: Jamaica | D18: London | H18: 1630 | J18: =(E18*2240)+(F18*112)+(G18*28)+H18 -> 1630 | L18: =J18/2240 -> 0.72767857
A19: 1730 | B19: Cotton | C19: Jamaica | D19: London | H19: =475*200 -> 95000 | I19: 475bags | J19: =(E19*2240)+(F19*112)+(G19*28)+H19 -> 95000 | L19: =J19/2240 -> 42.410714
A20: 1730 | B20: Dry Ginger | C20: Jamaica | D20: London | F20: 3317 | G20: 2 | J20: =(E20*2240)+(F20*112)+(G20*28)+H20 -> 371560 | L20: =J20/2240 -> 165.875
A21: 1730 | B21: Elephant Teeth | C21: Jamaica | D21: London | F21: 85 | G21: 3 | H21: 1 | J21: =(E21*2240)+(F21*112)+(G21*28)+H21 -> 9605 | L21: =J21/2240 -> 4.2879464
A22: 1730 | B22: Green Ginger | C22: Jamaica | D22: London | H22: 68 | J22: =(E22*2240)+(F22*112)+(G22*28)+H22 -> 68 | L22: =J22/2240 -> 0.030357143
A23: 1730 | B23: Hemp | C23: Jamaica | D23: London | J23: =(E23*2240)+(F23*112)+(G23*28)+H23 -> 0 | L23: =J23/2240 -> 0
A24: 1730 | B24: Indigo | C24: Jamaica | D24: London | H24: 204515 | J24: =(E24*2240)+(F24*112)+(G24*28)+H24 -> 204515 | L24: =J24/2240 -> 91.301339
A25: 1730 | B25: Lemon Water | C25: Jamaica | D25: London | J25: =(E25*2240)+(F25*112)+(G25*28)+H25 -> 0 | L25: =J25/2240 -> 0
A26: 1730 | B26: Lignum Vitae | C26: Jamaica | D26: London | E26: 1 | F26: 3 | G26: 1 | J26: =(E26*2240)+(F26*112)+(G26*28)+H26 -> 2604 | L26: =J26/2240 -> 1.1625
A27: 1730 | B27: Lime Juice | C27: Jamaica | D27: London | H27: 23808 | I27: 2359g | J27: =(E27*2240)+(F27*112)+(G27*28)+H27 -> 23808 | L27: =J27/2240 -> 10.628571
A28: 1730 | B28: Loaf Sugar | C28: Jamaica | D28: London | J28: =(E28*2240)+(F28*112)+(G28*28)+H28 -> 0 | L28: =J28/2240 -> 0
A29: 1730 | B29: Madera Wine | C29: Jamaica | D29: London | H29: 188287 | I29: 74t 8g | J29: =(E29*2240)+(F29*112)+(G29*28)+H29 -> 188287 | L29: =J29/2240 -> 84.056696
A30: 1730 | B30: Molasses | C30: Jamaica | D30: London | F30: 21 | G30: 2 | J30: =(E30*2240)+(F30*112)+(G30*28)+H30 -> 2408 | L30: =J30/2240 -> 1.075
A31: 1730 | B31: Oranges | C31: Jamaica | D31: London | J31: =(E31*2240)+(F31*112)+(G31*28)+H31 -> 0 | L31: =J31/2240 -> 0
A32: 1730 | B32: Pickles | C32: Jamaica | D32: London | J32: =(E32*2240)+(F32*112)+(G32*28)+H32 -> 0 | L32: =J32/2240 -> 0
A33: 1730 | B33: Pimento | C33: Jamaica | D33: London | H33: 219858 | J33: =(E33*2240)+(F33*112)+(G33*28)+H33 -> 219858 | L33: =J33/2240 -> 98.150893
A34: 1730 | B34: Rice | C34: Jamaica | D34: London | J34: =(E34*2240)+(F34*112)+(G34*28)+H34 -> 0 | L34: =J34/2240 -> 0
A35: 1730 | B35: Rum | C35: Jamaica | D35: London | H35: 1442228 | I35: 142900g | J35: =(E35*2240)+(F35*112)+(G35*28)+H35 -> 1442228 | L35: =J35/2240 -> 643.85179
A36: 1730 | B36: Sarsparila | C36: Jamaica | D36: London | J36: =(E36*2240)+(F36*112)+(G36*28)+H36 -> 0 | L36: =J36/2240 -> 0
A37: 1730 | B37: Sassafras | C37: Jamaica | D37: London | F37: 10 | J37: =(E37*2240)+(F37*112)+(G37*28)+H37 -> 1120 | L37: =J37/2240 -> 0.5
A38: 1730 | B38: Shruff | C38: Jamaica | D38: London | H38: 12263 | J38: =(E38*2240)+(F38*112)+(G38*28)+H38 -> 12263 | L38: =J38/2240 -> 5.4745536
A39: 1730 | B39: Snuff | C39: Jamaica | D39: London | F39: 14 | H39: 14298 | J39: =(E39*2240)+(F39*112)+(G39*28)+H39 -> 15866 | L39: =J39/2240 -> 7.0830357
A40: 1730 | B40: Succads | C40: Jamaica | D40: London | H40: 2717 | J40: =(E40*2240)+(F40*112)+(G40*28)+H40 -> 2717 | L40: =J40/2240 -> 1.2129464
...

Sheet Mountserat
A1: YEAR | B1: COMMODITY_NAME | C1: FROM_LOCATION | D1: TO_LOCATION | E1: ton | F1: hh | G1: quarter | H1: lb | J1: Total Pounds | L1: WEIGHT
A2: 1730 | B2: Almonds, Bitter | C2: Mountserat | D2: London | J2: =(E2*2240)+(F2*112)+(G2*28)+H2 -> 0 | L2: =J2/2240 -> 0
A3: 1730 | B3: Almonds, Sweet | C3: Mountserat | D3: London | J3: =(E3*2240)+(F3*112)+(G3*28)+H3 -> 0 | L3: =J3/2240 -> 0
A4: 1730 | B4: Aloes Epatica | C4: Mountserat | D4: London | J4: =(E4*2240)+(F4*112)+(G4*28)+H4 -> 0 | L4: =J4/2240 -> 0
A5: 1730 | B5: Annatto | C5: Mountserat | D5: London | J5: =(E5*2240)+(F5*112)+(G5*28)+H5 -> 0 | L5: =J5/2240 -> 0
A6: 1730 | B6: Anniseeds | C6: Mountserat | D6: London | J6: =(E6*2240)+(F6*112)+(G6*28)+H6 -> 0 | L6: =J6/2240 -> 0
A7: 1730 | B7: Bacon | C7: Mountserat | D7: London | J7: =(E7*2240)+(F7*112)+(G7*28)+H7 -> 0 | L7: =J7/2240 -> 0
A8: 1730 | B8: Barrel Staves | C8: Mountserat | D8: London | J8: =(E8*2240)+(F8*112)+(G8*28)+H8 -> 0 | L8: =J8/2240 -> 0
A9: 1730 | B9: Bees Wax | C9: Mountserat | D9: London | F9: 72 | G9: 3 | H9: 14 | J9: =(E9*2240)+(F9*112)+(G9*28)+H9 -> 8162 | L9: =J9/2240 -> 3.64375
A10: 1730 | B10: Brimstone | C10: Mountserat | D10: London | J10: =(E10*2240)+(F10*112)+(G10*28)+H10 -> 0 | L10: =J10/2240 -> 0
A11: 1730 | B11: Brown Sugar | C11: Mountserat | D11: London | F11: 41286 | H11: 7 | J11: =(E11*2240)+(F11*112)+(G11*28)+H11 -> 4624039 | L11: =J11/2240 -> 2064.3031
A12: 1730 | B12: Cassia Fistula | C12: Mountserat | D12: London | J12: =(E12*2240)+(F12*112)+(G12*28)+H12 -> 0 | L12: =J12/2240 -> 0
A13: 1730 | B13: Chocolate Paste | C13: Mountserat | D13: London | J13: =(E13*2240)+(F13*112)+(G13*28)+H13 -> 0 | L13: =J13/2240 -> 0
A14: 1730 | B14: Cocheneal | C14: Mountserat | D14: London | J14: =(E14*2240)+(F14*112)+(G14*28)+H14 -> 0 | L14: =J14/2240 -> 0
A15: 1730 | B15: Cocoa Nuts | C15: Mountserat | D15: London | J15: =(E15*2240)+(F15*112)+(G15*28)+H15 -> 0 | L15: =J15/2240 -> 0
A16: 1730 | B16: Cocoa Paste | C16: Mountserat | D16: London | J16: =(E16*2240)+(F16*112)+(G16*28)+H16 -> 0 | L16: =J16/2240 -> 0
A17: 1730 | B17: Cortex Winteranus | C17: Mountserat | D17: London | J17: =(E17*2240)+(F17*112)+(G17*28)+H17 -> 0 | L17: =J17/2240 -> 0
A18: 1730 | B18: Cotton | C18: Mountserat | D18: London | H18: =13*200 -> 2600 | I18: 13bags | J18: =(E18*2240)+(F18*112)+(G18*28)+H18 -> 2600 | L18: =J18/2240 -> 1.1607143
A19: 1730 | B19: Dry Ginger | C19: Mountserat | D19: London | J19: =(E19*2240)+(F19*112)+(G19*28)+H19 -> 0 | L19: =J19/2240 -> 0
A20: 1730 | B20: Elephant Teeth | C20: Mountserat | D20: London | F20: 45 | G20: 3 | H20: 21 | J20: =(E20*2240)+(F20*112)+(G20*28)+H20 -> 5145 | L20: =J20/2240 -> 2.296875
A21: 1730 | B21: Green Ginger | C21: Mountserat | D21: London | J21: =(E21*2240)+(F21*112)+(G21*28)+H21 -> 0 | L21: =J21/2240 -> 0
A22: 1730 | B22: Hemp | C22: Mountserat | D22: London | J22: =(E22*2240)+(F22*112)+(G22*28)+H22 -> 0 | L22: =J22/2240 -> 0
A23: 1730 | B23: Indigo | C23: Mountserat | D23: London | H23: 365 | J23: =(E23*2240)+(F23*112)+(G23*28)+H23 -> 365 | L23: =J23/2240 -> 0.16294643
A24: 1730 | B24: Lemon Water | C24: Mountserat | D24: London | J24: =(E24*2240)+(F24*112)+(G24*28)+H24 -> 0 | L24: =J24/2240 -> 0
A25: 1730 | B25: Lignum Vitae | C25: Mountserat | D25: London | J25: =(E25*2240)+(F25*112)+(G25*28)+H25 -> 0 | L25: =J25/2240 -> 0
A26: 1730 | B26: Lime Juice | C26: Mountserat | D26: London | H26: 4259 | I26: 422g | J26: =(E26*2240)+(F26*112)+(G26*28)+H26 -> 4259 | L26: =J26/2240 -> 1.9013393
A27: 1730 | B27: Loaf Sugar | C27: Mountserat | D27: London | J27: =(E27*2240)+(F27*112)+(G27*28)+H27 -> 0 | L27: =J27/2240 -> 0
A28: 1730 | B28: Madera Wine | C28: Mountserat | D28: London | H28: 4219 | I28: 1t 2h 40g | J28: =(E28*2240)+(F28*112)+(G28*28)+H28 -> 4219 | L28: =J28/2240 -> 1.8834821
A29: 1730 | B29: Molasses | C29: Mountserat | D29: London | J29: =(E29*2240)+(F29*112)+(G29*28)+H29 -> 0 | L29: =J29/2240 -> 0
A30: 1730 | B30: Oranges | C30: Mountserat | D30: London | J30: =(E30*2240)+(F30*112)+(G30*28)+H30 -> 0 | L30: =J30/2240 -> 0
A31: 1730 | B31: Pickles | C31: Mountserat | D31: London | J31: =(E31*2240)+(F31*112)+(G31*28)+H31 -> 0 | L31: =J31/2240 -> 0
A32: 1730 | B32: Pimento | C32: Mountserat | D32: London | H32: 474 | J32: =(E32*2240)+(F32*112)+(G32*28)+H32 -> 474 | L32: =J32/2240 -> 0.21160714
A33: 1730 | B33: Rice | C33: Mountserat | D33: London | J33: =(E33*2240)+(F33*112)+(G33*28)+H33 -> 0 | L33: =J33/2240 -> 0
A34: 1730 | B34: Rum | C34: Mountserat | D34: London | H34: 63129 | I34: 6255g | J34: =(E34*2240)+(F34*112)+(G34*28)+H34 -> 63129 | L34: =J34/2240 -> 28.182589
A35: 1730 | B35: Sarsparila | C35: Mountserat | D35: London | J35: =(E35*2240)+(F35*112)+(G35*28)+H35 -> 0 | L35: =J35/2240 -> 0
A36: 1730 | B36: Shruff | C36: Mountserat | D36: London | J36: =(E36*2240)+(F36*112)+(G36*28)+H36 -> 0 | L36: =J36/2240 -> 0
A37: 1730 | B37: Snuff | C37: Mountserat | D37: London | J37: =(E37*2240)+(F37*112)+(G37*28)+H37 -> 0 | L37: =J37/2240 -> 0
A38: 1730 | B38: Succads | C38: Mountserat | D38: London | H38: 201 | J38: =(E38*2240)+(F38*112)+(G38*28)+H38 -> 201 | L38: =J38/2240 -> 0.089732143
A39: 1730 | B39: Tobacco | C39: Mountserat | D39: London | H39: 15074 | J39: =(E39*2240)+(F39*112)+(G39*28)+H39 -> 15074 | L39: =J39/2240 -> 6.7294643
A40: 1730 | B40: Tortoise Shell | C40: Mountserat | D40: London | J40: =(E40*2240)+(F40*112)+(G40*28)+H40 -> 0 | L40: =J40/2240 -> 0
...

Sheet Nevis
A1: YEAR | B1: COMMODITY_NAME | C1: FROM_LOCATION | D1: TO_LOCATION | E1: ton | F1: hh | G1: quarter | H1: lb | J1: Total Pounds | L1: WEIGHT
A2: 1730 | B2: Almonds, Bitter | C2: Nevis | D2: London | J2: =(E2*2240)+(F2*112)+(G2*28)+H2 -> 0 | L2: =J2/2240 -> 0
A3: 1730 | B3: Almonds, Sweet | C3: Nevis | D3: London | J3: =(E3*2240)+(F3*112)+(G3*28)+H3 -> 0 | L3: =J3/2240 -> 0
A4: 1730 | B4: Aloes Epatica | C4: Nevis | D4: London | J4: =(E4*2240)+(F4*112)+(G4*28)+H4 -> 0 | L4: =J4/2240 -> 0
A5: 1730 | B5: Annatto | C5: Nevis | D5: London | J5: =(E5*2240)+(F5*112)+(G5*28)+H5 -> 0 | L5: =J5/2240 -> 0
A6: 1730 | B6: Anniseeds | C6: Nevis | D6: London | J6: =(E6*2240)+(F6*112)+(G6*28)+H6 -> 0 | L6: =J6/2240 -> 0
A7: 1730 | B7: Bacon | C7: Nevis | D7: London | J7: =(E7*2240)+(F7*112)+(G7*28)+H7 -> 0 | L7: =J7/2240 -> 0
A8: 1730 | B8: Barrel Staves | C8: Nevis | D8: London | J8: =(E8*2240)+(F8*112)+(G8*28)+H8 -> 0 | L8: =J8/2240 -> 0
A9: 1730 | B9: Bees Wax | C9: Nevis | D9: London | J9: =(E9*2240)+(F9*112)+(G9*28)+H9 -> 0 | L9: =J9/2240 -> 0
A10: 1730 | B10: Brimstone | C10: Nevis | D10: London | J10: =(E10*2240)+(F10*112)+(G10*28)+H10 -> 0 | L10: =J10/2240 -> 0
A11: 1730 | B11: Brown Sugar | C11: Nevis | D11: London | F11: 43115 | H11: 8 | J11: =(E11*2240)+(F11*112)+(G11*28)+H11 -> 4828888 | L11: =J11/2240 -> 2155.7536
A12: 1730 | B12: Cassia Fistula | C12: Nevis | D12: London | J12: =(E12*2240)+(F12*112)+(G12*28)+H12 -> 0 | L12: =J12/2240 -> 0
A13: 1730 | B13: Chocolate Paste | C13: Nevis | D13: London | J13: =(E13*2240)+(F13*112)+(G13*28)+H13 -> 0 | L13: =J13/2240 -> 0
A14: 1730 | B14: Cocheneal | C14: Nevis | D14: London | J14: =(E14*2240)+(F14*112)+(G14*28)+H14 -> 0 | L14: =J14/2240 -> 0
A15: 1730 | B15: Cocoa Nuts | C15: Nevis | D15: London | J15: =(E15*2240)+(F15*112)+(G15*28)+H15 -> 0 | L15: =J15/2240 -> 0
A16: 1730 | B16: Cocoa Paste | C16: Nevis | D16: London | J16: =(E16*2240)+(F16*112)+(G16*28)+H16 -> 0 | L16: =J16/2240 -> 0
A17: 1730 | B17: Cortex Winteranus | C17: Nevis | D17: London | J17: =(E17*2240)+(F17*112)+(G17*28)+H17 -> 0 | L17: =J17/2240 -> 0
A18: 1730 | B18: Cotton | C18: Nevis | D18: London | H18: =38*200 -> 7600 | I18: 38bags | J18: =(E18*2240)+(F18*112)+(G18*28)+H18 -> 7600 | L18: =J18/2240 -> 3.3928571
A19: 1730 | B19: Dry Ginger | C19: Nevis | D19: London | J19: =(E19*2240)+(F19*112)+(G19*28)+H19 -> 0 | L19: =J19/2240 -> 0
A20: 1730 | B20: Elephant Teeth | C20: Nevis | D20: London | J20: =(E20*2240)+(F20*112)+(G20*28)+H20 -> 0 | L20: =J20/2240 -> 0
A21: 1730 | B21: Green Ginger | C21: Nevis | D21: London | J21: =(E21*2240)+(F21*112)+(G21*28)+H21 -> 0 | L21: =J21/2240 -> 0
A22: 1730 | B22: Hemp | C22: Nevis | D22: London | J22: =(E22*2240)+(F22*112)+(G22*28)+H22 -> 0 | L22: =J22/2240 -> 0
A23: 1730 | B23: Indigo | C23: Nevis | D23: London | J23: =(E23*2240)+(F23*112)+(G23*28)+H23 -> 0 | L23: =J23/2240 -> 0
A24: 1730 | B24: Lemon Water | C24: Nevis | D24: London | J24: =(E24*2240)+(F24*112)+(G24*28)+H24 -> 0 | L24: =J24/2240 -> 0
A25: 1730 | B25: Lignum Vitae | C25: Nevis | D25: London | J25: =(E25*2240)+(F25*112)+(G25*28)+H25 -> 0 | L25: =J25/2240 -> 0
A26: 1730 | B26: Lime Juice | C26: Nevis | D26: London | J26: =(E26*2240)+(F26*112)+(G26*28)+H26 -> 0 | L26: =J26/2240 -> 0
A27: 1730 | B27: Loaf Sugar | C27: Nevis | D27: London | J27: =(E27*2240)+(F27*112)+(G27*28)+H27 -> 0 | L27: =J27/2240 -> 0
A28: 1730 | B28: Madera Wine | C28: Nevis | D28: London | H28: 16390 | I28: 6t 1h 49g | J28: =(E28*2240)+(F28*112)+(G28*28)+H28 -> 16390 | L28: =J28/2240 -> 7.3169643
A29: 1730 | B29: Molasses | C29: Nevis | D29: London | F29: 2 | J29: =(E29*2240)+(F29*112)+(G29*28)+H29 -> 224 | L29: =J29/2240 -> 0.1
A30: 1730 | B30: Oranges | C30: Nevis | D30: London | J30: =(E30*2240)+(F30*112)+(G30*28)+H30 -> 0 | L30: =J30/2240 -> 0
A31: 1730 | B31: Pickles | C31: Nevis | D31: London | J31: =(E31*2240)+(F31*112)+(G31*28)+H31 -> 0 | L31: =J31/2240 -> 0
A32: 1730 | B32: Pimento | C32: Nevis | D32: London | J32: =(E32*2240)+(F32*112)+(G32*28)+H32 -> 0 | L32: =J32/2240 -> 0
A33: 1730 | B33: Rice | C33: Nevis | D33: London | J33: =(E33*2240)+(F33*112)+(G33*28)+H33 -> 0 | L33: =J33/2240 -> 0
A34: 1730 | B34: Rum | C34: Nevis | D34: London | H34: 15961 | I34: 1581.5g | J34: =(E34*2240)+(F34*112)+(G34*28)+H34 -> 15961 | L34: =J34/2240 -> 7.1254464
A35: 1730 | B35: Sarsparila | C35: Nevis | D35: London | J35: =(E35*2240)+(F35*112)+(G35*28)+H35 -> 0 | L35: =J35/2240 -> 0
A36: 1730 | B36: Shruff | C36: Nevis | D36: London | J36: =(E36*2240)+(F36*112)+(G36*28)+H36 -> 0 | L36: =J36/2240 -> 0
A37: 1730 | B37: Snuff | C37: Nevis | D37: London | J37: =(E37*2240)+(F37*112)+(G37*28)+H37 -> 0 | L37: =J37/2240 -> 0
A38: 1730 | B38: Succads | C38: Nevis | D38: London | H38: 53 | J38: =(E38*2240)+(F38*112)+(G38*28)+H38 -> 53 | L38: =J38/2240 -> 0.023660714
A39: 1730 | B39: Tobacco | C39: Nevis | D39: London | J39: =(E39*2240)+(F39*112)+(G39*28)+H39 -> 0 | L39: =J39/2240 -> 0
A40: 1730 | B40: Tortoise Shell | C40: Nevis | D40: London | H40: 6 | J40: =(E40*2240)+(F40*112)+(G40*28)+H40 -> 6 | L40: =J40/2240 -> 0.0026785714
...

Sheet St Kitts
A1: YEAR | B1: COMMODITY_NAME | C1: FROM_LOCATION | D1: TO_LOCATION | E1: ton | F1: hh | G1: quarter | H1: lb | J1: Total Pounds | L1: WEIGHT
A2: 1730 | B2: Almonds, Bitter | C2: StKitts | D2: London | J2: =(E2*2240)+(F2*112)+(G2*28)+H2 -> 0 | L2: =J2/2240 -> 0
A3: 1730 | B3: Almonds, Sweet | C3: StKitts | D3: London | J3: =(E3*2240)+(F3*112)+(G3*28)+H3 -> 0 | L3: =J3/2240 -> 0
A4: 1730 | B4: Aloes Epatica | C4: StKitts | D4: London | J4: =(E4*2240)+(F4*112)+(G4*28)+H4 -> 0 | L4: =J4/2240 -> 0
A5: 1730 | B5: Annatto | C5: StKitts | D5: London | J5: =(E5*2240)+(F5*112)+(G5*28)+H5 -> 0 | L5: =J5/2240 -> 0
A6: 1730 | B6: Anniseeds | C6: StKitts | D6: London | J6: =(E6*2240)+(F6*112)+(G6*28)+H6 -> 0 | L6: =J6/2240 -> 0
A7: 1730 | B7: Bacon | C7: StKitts | D7: London | J7: =(E7*2240)+(F7*112)+(G7*28)+H7 -> 0 | L7: =J7/2240 -> 0
A8: 1730 | B8: Barrel Staves | C8: StKitts | D8: London | J8: =(E8*2240)+(F8*112)+(G8*28)+H8 -> 0 | L8: =J8/2240 -> 0
A9: 1730 | B9: Bees Wax | C9: StKitts | D9: London | J9: =(E9*2240)+(F9*112)+(G9*28)+H9 -> 0 | L9: =J9/2240 -> 0
A10: 1730 | B10: Brimstone | C10: StKitts | D10: London | J10: =(E10*2240)+(F10*112)+(G10*28)+H10 -> 0 | L10: =J10/2240 -> 0
A11: 1730 | B11: Brown Sugar | C11: StKitts | D11: London | F11: 138113 | G11: 3 | H11: 1 | J11: =(E11*2240)+(F11*112)+(G11*28)+H11 -> 15468741 | L11: =J11/2240 -> 6905.6879
A12: 1730 | B12: Cassia Fistula | C12: StKitts | D12: London | J12: =(E12*2240)+(F12*112)+(G12*28)+H12 -> 0 | L12: =J12/2240 -> 0
A13: 1730 | B13: Chocolate Paste | C13: StKitts | D13: London | J13: =(E13*2240)+(F13*112)+(G13*28)+H13 -> 0 | L13: =J13/2240 -> 0
A14: 1730 | B14: Cocheneal | C14: StKitts | D14: London | J14: =(E14*2240)+(F14*112)+(G14*28)+H14 -> 0 | L14: =J14/2240 -> 0
A15: 1730 | B15: Cocoa Nuts | C15: StKitts | D15: London | F15: 1437 | G15: 3 | H15: 14 | J15: =(E15*2240)+(F15*112)+(G15*28)+H15 -> 161042 | L15: =J15/2240 -> 71.89375
A16: 1730 | B16: Cocoa Paste | C16: StKitts | D16: London | J16: =(E16*2240)+(F16*112)+(G16*28)+H16 -> 0 | L16: =J16/2240 -> 0
A17: 1730 | B17: Cortex Winteranus | C17: StKitts | D17: London | J17: =(E17*2240)+(F17*112)+(G17*28)+H17 -> 0 | L17: =J17/2240 -> 0
A18: 1730 | B18: Cotton | C18: StKitts | D18: London | H18: =557.5*200 -> 111500 | I18: 557.5bags | J18: =(E18*2240)+(F18*112)+(G18*28)+H18 -> 111500 | L18: =J18/2240 -> 49.776786
A19: 1730 | B19: Dry Ginger | C19: StKitts | D19: London | J19: =(E19*2240)+(F19*112)+(G19*28)+H19 -> 0 | L19: =J19/2240 -> 0
A20: 1730 | B20: Elephant Teeth | C20: StKitts | D20: London | F20: 35 | H20: 22 | J20: =(E20*2240)+(F20*112)+(G20*28)+H20 -> 3942 | L20: =J20/2240 -> 1.7598214
A21: 1730 | B21: Green Ginger | C21: StKitts | D21: London | J21: =(E21*2240)+(F21*112)+(G21*28)+H21 -> 0 | L21: =J21/2240 -> 0
A22: 1730 | B22: Hemp | C22: StKitts | D22: London | J22: =(E22*2240)+(F22*112)+(G22*28)+H22 -> 0 | L22: =J22/2240 -> 0
A23: 1730 | B23: Indigo | C23: StKitts | D23: London | H23: 194 | J23: =(E23*2240)+(F23*112)+(G23*28)+H23 -> 194 | L23: =J23/2240 -> 0.086607143
A24: 1730 | B24: Lemon Water | C24: StKitts | D24: London | J24: =(E24*2240)+(F24*112)+(G24*28)+H24 -> 0 | L24: =J24/2240 -> 0
A25: 1730 | B25: Lignum Vitae | C25: StKitts | D25: London | E25: 7 | J25: =(E25*2240)+(F25*112)+(G25*28)+H25 -> 15680 | L25: =J25/2240 -> 7
A26: 1730 | B26: Lime Juice | C26: StKitts | D26: London | J26: =(E26*2240)+(F26*112)+(G26*28)+H26 -> 0 | L26: =J26/2240 -> 0
A27: 1730 | B27: Loaf Sugar | C27: StKitts | D27: London | J27: =(E27*2240)+(F27*112)+(G27*28)+H27 -> 0 | L27: =J27/2240 -> 0
A28: 1730 | B28: Madera Wine | C28: StKitts | D28: London | H28: 50412 | I28: 19t 3h 18g | J28: =(E28*2240)+(F28*112)+(G28*28)+H28 -> 50412 | L28: =J28/2240 -> 22.505357
A29: 1730 | B29: Molasses | C29: StKitts | D29: London | J29: =(E29*2240)+(F29*112)+(G29*28)+H29 -> 0 | L29: =J29/2240 -> 0
A30: 1730 | B30: Oranges | C30: StKitts | D30: London | J30: =(E30*2240)+(F30*112)+(G30*28)+H30 -> 0 | L30: =J30/2240 -> 0
A31: 1730 | B31: Pickles | C31: StKitts | D31: London | J31: =(E31*2240)+(F31*112)+(G31*28)+H31 -> 0 | L31: =J31/2240 -> 0
A32: 1730 | B32: Pimento | C32: StKitts | D32: London | H32: 200 | J32: =(E32*2240)+(F32*112)+(G32*28)+H32 -> 200 | L32: =J32/2240 -> 0.089285714
A33: 1730 | B33: Rice | C33: StKitts | D33: London | F33: 44 | J33: =(E33*2240)+(F33*112)+(G33*28)+H33 -> 4928 | L33: =J33/2240 -> 2.2
A34: 1730 | B34: Rum | C34: StKitts | D34: London | H34: 42036 | I34: 4165g | J34: =(E34*2240)+(F34*112)+(G34*28)+H34 -> 42036 | L34: =J34/2240 -> 18.766071
A35: 1730 | B35: Sarsparila | C35: StKitts | D35: London | J35: =(E35*2240)+(F35*112)+(G35*28)+H35 -> 0 | L35: =J35/2240 -> 0
A36: 1730 | B36: Shruff | C36: StKitts | D36: London | F36: 2 | G36: 1 | J36: =(E36*2240)+(F36*112)+(G36*28)+H36 -> 252 | L36: =J36/2240 -> 0.1125
A37: 1730 | B37: Snuff | C37: StKitts | D37: London | J37: =(E37*2240)+(F37*112)+(G37*28)+H37 -> 0 | L37: =J37/2240 -> 0
A38: 1730 | B38: Succads | C38: StKitts | D38: London | H38: 614 | J38: =(E38*2240)+(F38*112)+(G38*28)+H38 -> 614 | L38: =J38/2240 -> 0.27410714
A39: 1730 | B39: Tobacco | C39: StKitts | D39: London | J39: =(E39*2240)+(F39*112)+(G39*28)+H39 -> 0 | L39: =J39/2240 -> 0
A40: 1730 | B40: Tortoise Shell | C40: StKitts | D40: London | H40: 46 | J40: =(E40*2240)+(F40*112)+(G40*28)+H40 -> 46 | L40: =J40/2240 -> 0.020535714
...

Sheet General
A1: YEAR | B1: COMMODITY_NAME | C1: FROM_LOCATION | D1: TO_LOCATION | E1: ton | F1: hh | G1: quarter | H1: lb | J1: Total Pounds | L1: WEIGHT
A2: 1730 | B2: Almonds, Bitter | C2: General | D2: London | J2: =(E2*2240)+(F2*112)+(G2*28)+H2 -> 0 | L2: =J2/2240 -> 0
A3: 1730 | B3: Almonds, Sweet | C3: General | D3: London | J3: =(E3*2240)+(F3*112)+(G3*28)+H3 -> 0 | L3: =J3/2240 -> 0
A4: 1730 | B4: Aloes Epatica | C4: General | D4: London | H4: 1904 | J4: =(E4*2240)+(F4*112)+(G4*28)+H4 -> 1904 | L4: =J4/2240 -> 0.85
A5: 1730 | B5: Annatto | C5: General | D5: London | H5: 100 | J5: =(E5*2240)+(F5*112)+(G5*28)+H5 -> 100 | L5: =J5/2240 -> 0.044642857
A6: 1730 | B6: Anniseeds | C6: General | D6: London | J6: =(E6*2240)+(F6*112)+(G6*28)+H6 -> 0 | L6: =J6/2240 -> 0
A7: 1730 | B7: Bacon | C7: General | D7: London | J7: =(E7*2240)+(F7*112)+(G7*28)+H7 -> 0 | L7: =J7/2240 -> 0
A8: 1730 | B8: Barrel Staves | C8: General | D8: London | J8: =(E8*2240)+(F8*112)+(G8*28)+H8 -> 0 | L8: =J8/2240 -> 0
A9: 1730 | B9: Bees Wax | C9: General | D9: London | J9: =(E9*2240)+(F9*112)+(G9*28)+H9 -> 0 | L9: =J9/2240 -> 0
A10: 1730 | B10: Brimstone | C10: General | D10: London | J10: =(E10*2240)+(F10*112)+(G10*28)+H10 -> 0 | L10: =J10/2240 -> 0
A11: 1730 | B11: Brown Sugar | C11: General | D11: London | F11: 1741 | H11: 23 | J11: =(E11*2240)+(F11*112)+(G11*28)+H11 -> 195015 | L11: =J11/2240 -> 87.060268
A12: 1730 | B12: Cassia Fistula | C12: General | D12: London | H12: 2070 | J12: =(E12*2240)+(F12*112)+(G12*28)+H12 -> 2070 | L12: =J12/2240 -> 0.92410714
A13: 1730 | B13: Chocolate Paste | C13: General | D13: London | J13: =(E13*2240)+(F13*112)+(G13*28)+H13 -> 0 | L13: =J13/2240 -> 0
A14: 1730 | B14: Cocheneal | C14: General | D14: London | J14: =(E14*2240)+(F14*112)+(G14*28)+H14 -> 0 | L14: =J14/2240 -> 0
A15: 1730 | B15: Cocoa Nuts | C15: General | D15: London | J15: =(E15*2240)+(F15*112)+(G15*28)+H15 -> 0 | L15: =J15/2240 -> 0
A16: 1730 | B16: Cocoa Paste | C16: General | D16: London | J16: =(E16*2240)+(F16*112)+(G16*28)+H16 -> 0 | L16: =J16/2240 -> 0
A17: 1730 | B17: Cortex Winteranus | C17: General | D17: London | J17: =(E17*2240)+(F17*112)+(G17*28)+H17 -> 0 | L17: =J17/2240 -> 0
A18: 1730 | B18: Cotton | C18: General | D18: London | H18: =12*200 -> 2400 | I18: 12bags | J18: =(E18*2240)+(F18*112)+(G18*28)+H18 -> 2400 | L18: =J18/2240 -> 1.0714286
A19: 1730 | B19: Dry Ginger | C19: General | D19: London | F19: 111 | G19: 2 | J19: =(E19*2240)+(F19*112)+(G19*28)+H19 -> 12488 | L19: =J19/2240 -> 5.575
A20: 1730 | B20: Elephant Teeth | C20: General | D20: London | J20: =(E20*2240)+(F20*112)+(G20*28)+H20 -> 0 | L20: =J20/2240 -> 0
A21: 1730 | B21: Green Ginger | C21: General | D21: London | J21: =(E21*2240)+(F21*112)+(G21*28)+H21 -> 0 | L21: =J21/2240 -> 0
A22: 1730 | B22: Hemp | C22: General | D22: London | J22: =(E22*2240)+(F22*112)+(G22*28)+H22 -> 0 | L22: =J22/2240 -> 0
A23: 1730 | B23: Indigo | C23: General | D23: London | H23: 700 | J23: =(E23*2240)+(F23*112)+(G23*28)+H23 -> 700 | L23: =J23/2240 -> 0.3125
A24: 1730 | B24: Lemon Water | C24: General | D24: London | J24: =(E24*2240)+(F24*112)+(G24*28)+H24 -> 0 | L24: =J24/2240 -> 0
A25: 1730 | B25: Lignum Vitae | C25: General | D25: London | J25: =(E25*2240)+(F25*112)+(G25*28)+H25 -> 0 | L25: =J25/2240 -> 0
A26: 1730 | B26: Lime Juice | C26: General | D26: London | J26: =(E26*2240)+(F26*112)+(G26*28)+H26 -> 0 | L26: =J26/2240 -> 0
A27: 1730 | B27: Loaf Sugar | C27: General | D27: London | J27: =(E27*2240)+(F27*112)+(G27*28)+H27 -> 0 | L27: =J27/2240 -> 0
A28: 1730 | B28: Madera Wine | C28: General | D28: London | H28: 1060 | I28: 1h 42g | J28: =(E28*2240)+(F28*112)+(G28*28)+H28 -> 1060 | L28: =J28/2240 -> 0.47321429
A29: 1730 | B29: Molasses | C29: General | D29: London | J29: =(E29*2240)+(F29*112)+(G29*28)+H29 -> 0 | L29: =J29/2240 -> 0
A30: 1730 | B30: Oranges | C30: General | D30: London | J30: =(E30*2240)+(F30*112)+(G30*28)+H30 -> 0 | L30: =J30/2240 -> 0
A31: 1730 | B31: Pickles | C31: General | D31: London | J31: =(E31*2240)+(F31*112)+(G31*28)+H31 -> 0 | L31: =J31/2240 -> 0
A32: 1730 | B32: Pimento | C32: General | D32: London | H32: 1400 | J32: =(E32*2240)+(F32*112)+(G32*28)+H32 -> 1400 | L32: =J32/2240 -> 0.625
A33: 1730 | B33: Rice | C33: General | D33: London | F33: 110 | J33: =(E33*2240)+(F33*112)+(G33*28)+H33 -> 12320 | L33: =J33/2240 -> 5.5
A34: 1730 | B34: Rum | C34: General | D34: London | H34: 8104 | I34: 803g | J34: =(E34*2240)+(F34*112)+(G34*28)+H34 -> 8104 | L34: =J34/2240 -> 3.6178571
A35: 1730 | B35: Sarsparila | C35: General | D35: London | H35: 600 | J35: =(E35*2240)+(F35*112)+(G35*28)+H35 -> 600 | L35: =J35/2240 -> 0.26785714
A36: 1730 | B36: Shruff | C36: General | D36: London | F36: 2 | G36: 1 | J36: =(E36*2240)+(F36*112)+(G36*28)+H36 -> 252 | L36: =J36/2240 -> 0.1125
A37: 1730 | B37: Snuff | C37: General | D37: London | J37: =(E37*2240)+(F37*112)+(G37*28)+H37 -> 0 | L37: =J37/2240 -> 0
A38: 1730 | B38: Succads | C38: General | D38: London | H38: 10 | J38: =(E38*2240)+(F38*112)+(G38*28)+H38 -> 10 | L38: =J38/2240 -> 0.0044642857
A39: 1730 | B39: Tobacco | C39: General | D39: London | J39: =(E39*2240)+(F39*112)+(G39*28)+H39 -> 0 | L39: =J39/2240 -> 0
A40: 1730 | B40: Tortoise Shell | C40: General | D40: London | H40: 160 | J40: =(E40*2240)+(F40*112)+(G40*28)+H40 -> 160 | L40: =J40/2240 -> 0.071428571
...
