Workbook

Sheet Master Goods Sheet
A1: Item | B1: Total London | C1: Total Outports | D1: Total
A2: Annatto | B2: =SUMIFS(Antigua!$L:$L, Antigua!$B:$B, $A2, Antigua!$D:$D, "London") + SUMIFS(Barbados!$L:$L, Barbados!$B:$B, $A2, Barbados!$D:$D, "London") + SUMIFS(Bermuda!$L:$L, Bermuda!$B:$B, $A2, Bermuda!$D:$D, "London") + SUMIFS(Jamaica!$L:$L, Jamaica!$B:$B, $A2, Jamaica!$D:$D, "London") + SUMIFS(Mountserat!$L:$L, Mountserat!$B:$B, $A2, Mountserat!$D:$D, "London") + SUMIFS(Nevis!$L:$L, Nevis!$B:$B, $A2, Nevis!$D:$D, "London") + SUMIFS('St Kitts'!$L:$L, 'St Kitts'!$B:$B, $A2, 'St Kitts'!$D:$D, "London") + SUMIFS(WestIndiesGeneral!$L:$L, WestIndiesGeneral!$B:$B, $A2, WestIndiesGeneral!$D:$D, "London") -> 0.055803571 | C2: =SUMIFS(Antigua!$L:$L, Antigua!$B:$B, $A2, Antigua!$D:$D, "Out Ports") + SUMIFS(Barbados!$L:$L, Barbados!$B:$B, $A2, Barbados!$D:$D, "Out Ports") + SUMIFS(Bermuda!$L:$L, Bermuda!$B:$B, $A2, Bermuda!$D:$D, "Out Ports") + SUMIFS(Jamaica!$L:$L, Jamaica!$B:$B, $A2, Jamaica!$D:$D, "Out Ports") + SUMIFS(Mountserat!$L:$L, Mountserat!$B:$B, $A2, Mountserat!$D:$D, "Out Ports") + SUMIFS(Nevis!$L:$L, Nevis!$B:$B, $A2, Nevis!$D:$D, "Out Ports") + SUMIFS('St Kitts'!$L:$L, 'St Kitts'!$B:$B, $A2, 'St Kitts'!$D:$D, "Out Ports") + SUMIFS(WestIndiesGeneral!$L:$L, WestIndiesGeneral!$B:$B, $A2, WestIndiesGeneral!$D:$D, "London") -> 0 | D2: =B2+C2 -> 0.055803571
A3: Bees Wax | B3: =SUMIFS(Antigua!$L:$L, Antigua!$B:$B, $A3, Antigua!$D:$D, "London") + SUMIFS(Barbados!$L:$L, Barbados!$B:$B, $A3, Barbados!$D:$D, "London") + SUMIFS(Bermuda!$L:$L, Bermuda!$B:$B, $A3, Bermuda!$D:$D, "London") + SUMIFS(Jamaica!$L:$L, Jamaica!$B:$B, $A3, Jamaica!$D:$D, "London") + SUMIFS(Mountserat!$L:$L, Mountserat!$B:$B, $A3, Mountserat!$D:$D, "London") + SUMIFS(Nevis!$L:$L, Nevis!$B:$B, $A3, Nevis!$D:$D, "London") + SUMIFS('St Kitts'!$L:$L, 'St Kitts'!$B:$B, $A3, 'St Kitts'!$D:$D, "London") + SUMIFS(WestIndiesGeneral!$L:$L, WestIndiesGeneral!$B:$B, $A3, WestIndiesGeneral!$D:$D, "London") -> 8.8883929 | C3: =SUMIFS(Antigua!$L:$L, Antigua!$B:$B, $A3, Antigua!$D:$D, "Out Ports") + SUMIFS(Barbados!$L:$L, Barbados!$B:$B, $A3, Barbados!$D:$D, "Out Ports") + SUMIFS(Bermuda!$L:$L, Bermuda!$B:$B, $A3, Bermuda!$D:$D, "Out Ports") + SUMIFS(Jamaica!$L:$L, Jamaica!$B:$B, $A3, Jamaica!$D:$D, "Out Ports") + SUMIFS(Mountserat!$L:$L, Mountserat!$B:$B, $A3, Mountserat!$D:$D, "Out Ports") + SUMIFS(Nevis!$L:$L, Nevis!$B:$B, $A3, Nevis!$D:$D, "Out Ports") + SUMIFS('St Kitts'!$L:$L, 'St Kitts'!$B:$B, $A3, 'St Kitts'!$D:$D, "Out Ports") + SUMIFS(WestIndiesGeneral!$L:$L, WestIndiesGeneral!$B:$B, $A3, WestIndiesGeneral!$D:$D, "London") -> 0.25 | D3: =B3+C3 -> 9.1383929
A4: Brown Sugar | B4: =SUMIFS(Antigua!$L:$L, Antigua!$B:$B, $A4, Antigua!$D:$D, "London") + SUMIFS(Barbados!$L:$L, Barbados!$B:$B, $A4, Barbados!$D:$D, "London") + SUMIFS(Bermuda!$L:$L, Bermuda!$B:$B, $A4, Bermuda!$D:$D, "London") + SUMIFS(Jamaica!$L:$L, Jamaica!$B:$B, $A4, Jamaica!$D:$D, "London") + SUMIFS(Mountserat!$L:$L, Mountserat!$B:$B, $A4, Mountserat!$D:$D, "London") + SUMIFS(Nevis!$L:$L, Nevis!$B:$B, $A4, Nevis!$D:$D, "London") + SUMIFS('St Kitts'!$L:$L, 'St Kitts'!$B:$B, $A4, 'St Kitts'!$D:$D, "London") + SUMIFS(WestIndiesGeneral!$L:$L, WestIndiesGeneral!$B:$B, $A4, WestIndiesGeneral!$D:$D, "London") -> 30220.321 | C4: =SUMIFS(Antigua!$L:$L, Antigua!$B:$B, $A4, Antigua!$D:$D, "Out Ports") + SUMIFS(Barbados!$L:$L, Barbados!$B:$B, $A4, Barbados!$D:$D, "Out Ports") + SUMIFS(Bermuda!$L:$L, Bermuda!$B:$B, $A4, Bermuda!$D:$D, "Out Ports") + SUMIFS(Jamaica!$L:$L, Jamaica!$B:$B, $A4, Jamaica!$D:$D, "Out Ports") + SUMIFS(Mountserat!$L:$L, Mountserat!$B:$B, $A4, Mountserat!$D:$D, "Out Ports") + SUMIFS(Nevis!$L:$L, Nevis!$B:$B, $A4, Nevis!$D:$D, "Out Ports") + SUMIFS('St Kitts'!$L:$L, 'St Kitts'!$B:$B, $A4, 'St Kitts'!$D:$D, "Out Ports") + SUMIFS(WestIndiesGeneral!$L:$L, WestIndiesGeneral!$B:$B, $A4, WestIndiesGeneral!$D:$D, "London") -> 10450.29 | D4: =B4+C4 -> 40670.61
A5: Chocolate | B5: =SUMIFS(Antigua!$L:$L, Antigua!$B:$B, $A5, Antigua!$D:$D, "London") + SUMIFS(Barbados!$L:$L, Barbados!$B:$B, $A5, Barbados!$D:$D, "London") + SUMIFS(Bermuda!$L:$L, Bermuda!$B:$B, $A5, Bermuda!$D:$D, "London") + SUMIFS(Jamaica!$L:$L, Jamaica!$B:$B, $A5, Jamaica!$D:$D, "London") + SUMIFS(Mountserat!$L:$L, Mountserat!$B:$B, $A5, Mountserat!$D:$D, "London") + SUMIFS(Nevis!$L:$L, Nevis!$B:$B, $A5, Nevis!$D:$D, "London") + SUMIFS('St Kitts'!$L:$L, 'St Kitts'!$B:$B, $A5, 'St Kitts'!$D:$D, "London") + SUMIFS(WestIndiesGeneral!$L:$L, WestIndiesGeneral!$B:$B, $A5, WestIndiesGeneral!$D:$D, "London") -> 0 | C5: =SUMIFS(Antigua!$L:$L, Antigua!$B:$B, $A5, Antigua!$D:$D, "Out Ports") + SUMIFS(Barbados!$L:$L, Barbados!$B:$B, $A5, Barbados!$D:$D, "Out Ports") + SUMIFS(Bermuda!$L:$L, Bermuda!$B:$B, $A5, Bermuda!$D:$D, "Out Ports") + SUMIFS(Jamaica!$L:$L, Jamaica!$B:$B, $A5, Jamaica!$D:$D, "Out Ports") + SUMIFS(Mountserat!$L:$L, Mountserat!$B:$B, $A5, Mountserat!$D:$D, "Out Ports") + SUMIFS(Nevis!$L:$L, Nevis!$B:$B, $A5, Nevis!$D:$D, "Out Ports") + SUMIFS('St Kitts'!$L:$L, 'St Kitts'!$B:$B, $A5, 'St Kitts'!$D:$D, "Out Ports") + SUMIFS(WestIndiesGeneral!$L:$L, WestIndiesGeneral!$B:$B, $A5, WestIndiesGeneral!$D:$D, "London") -> 0 | D5: =B5+C5 -> 0
A6: Cocoa Nuts | B6: =SUMIFS(Antigua!$L:$L, Antigua!$B:$B, $A6, Antigua!$D:$D, "London") + SUMIFS(Barbados!$L:$L, Barbados!$B:$B, $A6, Barbados!$D:$D, "London") + SUMIFS(Bermuda!$L:$L, Bermuda!$B:$B, $A6, Bermuda!$D:$D, "London") + SUMIFS(Jamaica!$L:$L, Jamaica!$B:$B, $A6, Jamaica!$D:$D, "London") + SUMIFS(Mountserat!$L:$L, Mountserat!$B:$B, $A6, Mountserat!$D:$D, "London") + SUMIFS(Nevis!$L:$L, Nevis!$B:$B, $A6, Nevis!$D:$D, "London") + SUMIFS('St Kitts'!$L:$L, 'St Kitts'!$B:$B, $A6, 'St Kitts'!$D:$D, "London") + SUMIFS(WestIndiesGeneral!$L:$L, WestIndiesGeneral!$B:$B, $A6, WestIndiesGeneral!$D:$D, "London") -> 0.044642857 | C6: =SUMIFS(Antigua!$L:$L, Antigua!$B:$B, $A6, Antigua!$D:$D, "Out Ports") + SUMIFS(Barbados!$L:$L, Barbados!$B:$B, $A6, Barbados!$D:$D, "Out Ports") + SUMIFS(Bermuda!$L:$L, Bermuda!$B:$B, $A6, Bermuda!$D:$D, "Out Ports") + SUMIFS(Jamaica!$L:$L, Jamaica!$B:$B, $A6, Jamaica!$D:$D, "Out Ports") + SUMIFS(Mountserat!$L:$L, Mountserat!$B:$B, $A6, Mountserat!$D:$D, "Out Ports") + SUMIFS(Nevis!$L:$L, Nevis!$B:$B, $A6, Nevis!$D:$D, "Out Ports") + SUMIFS('St Kitts'!$L:$L, 'St Kitts'!$B:$B, $A6, 'St Kitts'!$D:$D, "Out Ports") + SUMIFS(WestIndiesGeneral!$L:$L, WestIndiesGeneral!$B:$B, $A6, WestIndiesGeneral!$D:$D, "London") -> 5.9138393 | D6: =B6+C6 -> 5.9584821
A7: Cotton | B7: =SUMIFS(Antigua!$L:$L, Antigua!$B:$B, $A7, Antigua!$D:$D, "London") + SUMIFS(Barbados!$L:$L, Barbados!$B:$B, $A7, Barbados!$D:$D, "London") + SUMIFS(Bermuda!$L:$L, Bermuda!$B:$B, $A7, Bermuda!$D:$D, "London") + SUMIFS(Jamaica!$L:$L, Jamaica!$B:$B, $A7, Jamaica!$D:$D, "London") + SUMIFS(Mountserat!$L:$L, Mountserat!$B:$B, $A7, Mountserat!$D:$D, "London") + SUMIFS(Nevis!$L:$L, Nevis!$B:$B, $A7, Nevis!$D:$D, "London") + SUMIFS('St Kitts'!$L:$L, 'St Kitts'!$B:$B, $A7, 'St Kitts'!$D:$D, "London") + SUMIFS(WestIndiesGeneral!$L:$L, WestIndiesGeneral!$B:$B, $A7, WestIndiesGeneral!$D:$D, "London") -> 166.74107 | C7: =SUMIFS(Antigua!$L:$L, Antigua!$B:$B, $A7, Antigua!$D:$D, "Out Ports") + SUMIFS(Barbados!$L:$L, Barbados!$B:$B, $A7, Barbados!$D:$D, "Out Ports") + SUMIFS(Bermuda!$L:$L, Bermuda!$B:$B, $A7, Bermuda!$D:$D, "Out Ports") + SUMIFS(Jamaica!$L:$L, Jamaica!$B:$B, $A7, Jamaica!$D:$D, "Out Ports") + SUMIFS(Mountserat!$L:$L, Mountserat!$B:$B, $A7, Mountserat!$D:$D, "Out Ports") + SUMIFS(Nevis!$L:$L, Nevis!$B:$B, $A7, Nevis!$D:$D, "Out Ports") + SUMIFS('St Kitts'!$L:$L, 'St Kitts'!$B:$B, $A7, 'St Kitts'!$D:$D, "Out Ports") + SUMIFS(WestIndiesGeneral!$L:$L, WestIndiesGeneral!$B:$B, $A7, WestIndiesGeneral!$D:$D, "London") -> 309.86607 | D7: =B7+C7 -> 476.60714
A8: Dry Ginger | B8: =SUMIFS(Antigua!$L:$L, Antigua!$B:$B, $A8, Antigua!$D:$D, "London") + SUMIFS(Barbados!$L:$L, Barbados!$B:$B, $A8, Barbados!$D:$D, "London") + SUMIFS(Bermuda!$L:$L, Bermuda!$B:$B, $A8, Bermuda!$D:$D, "London") + SUMIFS(Jamaica!$L:$L, Jamaica!$B:$B, $A8, Jamaica!$D:$D, "London") + SUMIFS(Mountserat!$L:$L, Mountserat!$B:$B, $A8, Mountserat!$D:$D, "London") + SUMIFS(Nevis!$L:$L, Nevis!$B:$B, $A8, Nevis!$D:$D, "London") + SUMIFS('St Kitts'!$L:$L, 'St Kitts'!$B:$B, $A8, 'St Kitts'!$D:$D, "London") + SUMIFS(WestIndiesGeneral!$L:$L, WestIndiesGeneral!$B:$B, $A8, WestIndiesGeneral!$D:$D, "London") -> 289.10491 | C8: =SUMIFS(Antigua!$L:$L, Antigua!$B:$B, $A8, Antigua!$D:$D, "Out Ports") + SUMIFS(Barbados!$L:$L, Barbados!$B:$B, $A8, Barbados!$D:$D, "Out Ports") + SUMIFS(Bermuda!$L:$L, Bermuda!$B:$B, $A8, Bermuda!$D:$D, "Out Ports") + SUMIFS(Jamaica!$L:$L, Jamaica!$B:$B, $A8, Jamaica!$D:$D, "Out Ports") + SUMIFS(Mountserat!$L:$L, Mountserat!$B:$B, $A8, Mountserat!$D:$D, "Out Ports") + SUMIFS(Nevis!$L:$L, Nevis!$B:$B, $A8, Nevis!$D:$D, "Out Ports") + SUMIFS('St Kitts'!$L:$L, 'St Kitts'!$B:$B, $A8, 'St Kitts'!$D:$D, "Out Ports") + SUMIFS(WestIndiesGeneral!$L:$L, WestIndiesGeneral!$B:$B, $A8, WestIndiesGeneral!$D:$D, "London") -> 306.24375 | D8: =B8+C8 -> 595.34866
A9: Elephant Teeth | B9: =SUMIFS(Antigua!$L:$L, Antigua!$B:$B, $A9, Antigua!$D:$D, "London") + SUMIFS(Barbados!$L:$L, Barbados!$B:$B, $A9, Barbados!$D:$D, "London") + SUMIFS(Bermuda!$L:$L, Bermuda!$B:$B, $A9, Bermuda!$D:$D, "London") + SUMIFS(Jamaica!$L:$L, Jamaica!$B:$B, $A9, Jamaica!$D:$D, "London") + SUMIFS(Mountserat!$L:$L, Mountserat!$B:$B, $A9, Mountserat!$D:$D, "London") + SUMIFS(Nevis!$L:$L, Nevis!$B:$B, $A9, Nevis!$D:$D, "London") + SUMIFS('St Kitts'!$L:$L, 'St Kitts'!$B:$B, $A9, 'St Kitts'!$D:$D, "London") + SUMIFS(WestIndiesGeneral!$L:$L, WestIndiesGeneral!$B:$B, $A9, WestIndiesGeneral!$D:$D, "London") -> 30.728571 | C9: =SUMIFS(Antigua!$L:$L, Antigua!$B:$B, $A9, Antigua!$D:$D, "Out Ports") + SUMIFS(Barbados!$L:$L, Barbados!$B:$B, $A9, Barbados!$D:$D, "Out Ports") + SUMIFS(Bermuda!$L:$L, Bermuda!$B:$B, $A9, Bermuda!$D:$D, "Out Ports") + SUMIFS(Jamaica!$L:$L, Jamaica!$B:$B, $A9, Jamaica!$D:$D, "Out Ports") + SUMIFS(Mountserat!$L:$L, Mountserat!$B:$B, $A9, Mountserat!$D:$D, "Out Ports") + SUMIFS(Nevis!$L:$L, Nevis!$B:$B, $A9, Nevis!$D:$D, "Out Ports") + SUMIFS('St Kitts'!$L:$L, 'St Kitts'!$B:$B, $A9, 'St Kitts'!$D:$D, "Out Ports") + SUMIFS(WestIndiesGeneral!$L:$L, WestIndiesGeneral!$B:$B, $A9, WestIndiesGeneral!$D:$D, "London") -> 23.2 | D9: =B9+C9 -> 53.928571
A10: Indigo | B10: =SUMIFS(Antigua!$L:$L, Antigua!$B:$B, $A10, Antigua!$D:$D, "London") + SUMIFS(Barbados!$L:$L, Barbados!$B:$B, $A10, Barbados!$D:$D, "London") + SUMIFS(Bermuda!$L:$L, Bermuda!$B:$B, $A10, Bermuda!$D:$D, "London") + SUMIFS(Jamaica!$L:$L, Jamaica!$B:$B, $A10, Jamaica!$D:$D, "London") + SUMIFS(Mountserat!$L:$L, Mountserat!$B:$B, $A10, Mountserat!$D:$D, "London") + SUMIFS(Nevis!$L:$L, Nevis!$B:$B, $A10, Nevis!$D:$D, "London") + SUMIFS('St Kitts'!$L:$L, 'St Kitts'!$B:$B, $A10, 'St Kitts'!$D:$D, "London") + SUMIFS(WestIndiesGeneral!$L:$L, WestIndiesGeneral!$B:$B, $A10, WestIndiesGeneral!$D:$D, "London") -> 43.639286 | C10: =SUMIFS(Antigua!$L:$L, Antigua!$B:$B, $A10, Antigua!$D:$D, "Out Ports") + SUMIFS(Barbados!$L:$L, Barbados!$B:$B, $A10, Barbados!$D:$D, "Out Ports") + SUMIFS(Bermuda!$L:$L, Bermuda!$B:$B, $A10, Bermuda!$D:$D, "Out Ports") + SUMIFS(Jamaica!$L:$L, Jamaica!$B:$B, $A10, Jamaica!$D:$D, "Out Ports") + SUMIFS(Mountserat!$L:$L, Mountserat!$B:$B, $A10, Mountserat!$D:$D, "Out Ports") + SUMIFS(Nevis!$L:$L, Nevis!$B:$B, $A10, Nevis!$D:$D, "Out Ports") + SUMIFS('St Kitts'!$L:$L, 'St Kitts'!$B:$B, $A10, 'St Kitts'!$D:$D, "Out Ports") + SUMIFS(WestIndiesGeneral!$L:$L, WestIndiesGeneral!$B:$B, $A10, WestIndiesGeneral!$D:$D, "London") -> 54.376786 | D10: =B10+C10 -> 98.016071
A11: Lignum Vitae | B11: =SUMIFS(Antigua!$L:$L, Antigua!$B:$B, $A11, Antigua!$D:$D, "London") + SUMIFS(Barbados!$L:$L, Barbados!$B:$B, $A11, Barbados!$D:$D, "London") + SUMIFS(Bermuda!$L:$L, Bermuda!$B:$B, $A11, Bermuda!$D:$D, "London") + SUMIFS(Jamaica!$L:$L, Jamaica!$B:$B, $A11, Jamaica!$D:$D, "London") + SUMIFS(Mountserat!$L:$L, Mountserat!$B:$B, $A11, Mountserat!$D:$D, "London") + SUMIFS(Nevis!$L:$L, Nevis!$B:$B, $A11, Nevis!$D:$D, "London") + SUMIFS('St Kitts'!$L:$L, 'St Kitts'!$B:$B, $A11, 'St Kitts'!$D:$D, "London") + SUMIFS(WestIndiesGeneral!$L:$L, WestIndiesGeneral!$B:$B, $A11, WestIndiesGeneral!$D:$D, "London") -> 35.325 | C11: =SUMIFS(Antigua!$L:$L, Antigua!$B:$B, $A11, Antigua!$D:$D, "Out Ports") + SUMIFS(Barbados!$L:$L, Barbados!$B:$B, $A11, Barbados!$D:$D, "Out Ports") + SUMIFS(Bermuda!$L:$L, Bermuda!$B:$B, $A11, Bermuda!$D:$D, "Out Ports") + SUMIFS(Jamaica!$L:$L, Jamaica!$B:$B, $A11, Jamaica!$D:$D, "Out Ports") + SUMIFS(Mountserat!$L:$L, Mountserat!$B:$B, $A11, Mountserat!$D:$D, "Out Ports") + SUMIFS(Nevis!$L:$L, Nevis!$B:$B, $A11, Nevis!$D:$D, "Out Ports") + SUMIFS('St Kitts'!$L:$L, 'St Kitts'!$B:$B, $A11, 'St Kitts'!$D:$D, "Out Ports") + SUMIFS(WestIndiesGeneral!$L:$L, WestIndiesGeneral!$B:$B, $A11, WestIndiesGeneral!$D:$D, "London") -> 22.833036 | D11: =B11+C11 -> 58.158036
A12: Lime Juice | B12: =SUMIFS(Antigua!$L:$L, Antigua!$B:$B, $A12, Antigua!$D:$D, "London") + SUMIFS(Barbados!$L:$L, Barbados!$B:$B, $A12, Barbados!$D:$D, "London") + SUMIFS(Bermuda!$L:$L, Bermuda!$B:$B, $A12, Bermuda!$D:$D, "London") + SUMIFS(Jamaica!$L:$L, Jamaica!$B:$B, $A12, Jamaica!$D:$D, "London") + SUMIFS(Mountserat!$L:$L, Mountserat!$B:$B, $A12, Mountserat!$D:$D, "London") + SUMIFS(Nevis!$L:$L, Nevis!$B:$B, $A12, Nevis!$D:$D, "London") + SUMIFS('St Kitts'!$L:$L, 'St Kitts'!$B:$B, $A12, 'St Kitts'!$D:$D, "London") + SUMIFS(WestIndiesGeneral!$L:$L, WestIndiesGeneral!$B:$B, $A12, WestIndiesGeneral!$D:$D, "London") -> 22.836161 | C12: =SUMIFS(Antigua!$L:$L, Antigua!$B:$B, $A12, Antigua!$D:$D, "Out Ports") + SUMIFS(Barbados!$L:$L, Barbados!$B:$B, $A12, Barbados!$D:$D, "Out Ports") + SUMIFS(Bermuda!$L:$L, Bermuda!$B:$B, $A12, Bermuda!$D:$D, "Out Ports") + SUMIFS(Jamaica!$L:$L, Jamaica!$B:$B, $A12, Jamaica!$D:$D, "Out Ports") + SUMIFS(Mountserat!$L:$L, Mountserat!$B:$B, $A12, Mountserat!$D:$D, "Out Ports") + SUMIFS(Nevis!$L:$L, Nevis!$B:$B, $A12, Nevis!$D:$D, "Out Ports") + SUMIFS('St Kitts'!$L:$L, 'St Kitts'!$B:$B, $A12, 'St Kitts'!$D:$D, "Out Ports") + SUMIFS(WestIndiesGeneral!$L:$L, WestIndiesGeneral!$B:$B, $A12, WestIndiesGeneral!$D:$D, "London") -> 16.941741 | D12: =B12+C12 -> 39.777902
A13: Molasses | B13: =SUMIFS(Antigua!$L:$L, Antigua!$B:$B, $A13, Antigua!$D:$D, "London") + SUMIFS(Barbados!$L:$L, Barbados!$B:$B, $A13, Barbados!$D:$D, "London") + SUMIFS(Bermuda!$L:$L, Bermuda!$B:$B, $A13, Bermuda!$D:$D, "London") + SUMIFS(Jamaica!$L:$L, Jamaica!$B:$B, $A13, Jamaica!$D:$D, "London") + SUMIFS(Mountserat!$L:$L, Mountserat!$B:$B, $A13, Mountserat!$D:$D, "London") + SUMIFS(Nevis!$L:$L, Nevis!$B:$B, $A13, Nevis!$D:$D, "London") + SUMIFS('St Kitts'!$L:$L, 'St Kitts'!$B:$B, $A13, 'St Kitts'!$D:$D, "London") + SUMIFS(WestIndiesGeneral!$L:$L, WestIndiesGeneral!$B:$B, $A13, WestIndiesGeneral!$D:$D, "London") -> 2.2602679 | C13: =SUMIFS(Antigua!$L:$L, Antigua!$B:$B, $A13, Antigua!$D:$D, "Out Ports") + SUMIFS(Barbados!$L:$L, Barbados!$B:$B, $A13, Barbados!$D:$D, "Out Ports") + SUMIFS(Bermuda!$L:$L, Bermuda!$B:$B, $A13, Bermuda!$D:$D, "Out Ports") + SUMIFS(Jamaica!$L:$L, Jamaica!$B:$B, $A13, Jamaica!$D:$D, "Out Ports") + SUMIFS(Mountserat!$L:$L, Mountserat!$B:$B, $A13, Mountserat!$D:$D, "Out Ports") + SUMIFS(Nevis!$L:$L, Nevis!$B:$B, $A13, Nevis!$D:$D, "Out Ports") + SUMIFS('St Kitts'!$L:$L, 'St Kitts'!$B:$B, $A13, 'St Kitts'!$D:$D, "Out Ports") + SUMIFS(WestIndiesGeneral!$L:$L, WestIndiesGeneral!$B:$B, $A13, WestIndiesGeneral!$D:$D, "London") -> 0 | D13: =B13+C13 -> 2.2602679
... A31: Wood, Sweetwood | B31: =SUMIFS(Antigua!$L:$L, Antigua!$B:$B, $A31, Antigua!$D:$D, "London") + SUMIFS(Barbados!$L:$L, Barbados!$B:$B, $A31, Barbados!$D:$D, "London") + SUMIFS(Bermuda!$L:$L, Bermuda!$B:$B, $A31, Bermuda!$D:$D, "London") + SUMIFS(Jamaica!$L:$L, Jamaica!$B:$B, $A31, Jamaica!$D:$D, "London") + SUMIFS(Mountserat!$L:$L, Mountserat!$B:$B, $A31, Mountserat!$D:$D, "London") + SUMIFS(Nevis!$L:$L, Nevis!$B:$B, $A31, Nevis!$D:$D, "London") + SUMIFS('St Kitts'!$L:$L, 'St Kitts'!$B:$B, $A31, 'St Kitts'!$D:$D, "London") + SUMIFS(WestIndiesGeneral!$L:$L, WestIndiesGeneral!$B:$B, $A31, WestIndiesGeneral!$D:$D, "London") -> 0 | C31: =SUMIFS(Antigua!$L:$L, Antigua!$B:$B, $A31, Antigua!$D:$D, "Out Ports") + SUMIFS(Barbados!$L:$L, Barbados!$B:$B, $A31, Barbados!$D:$D, "Out Ports") + SUMIFS(Bermuda!$L:$L, Bermuda!$B:$B, $A31, Bermuda!$D:$D, "Out Ports") + SUMIFS(Jamaica!$L:$L, Jamaica!$B:$B, $A31, Jamaica!$D:$D, "Out Ports") + SUMIFS(Mountserat!$L:$L, Mountserat!$B:$B, $A31, Mountserat!$D:$D, "Out Ports") + SUMIFS(Nevis!$L:$L, Nevis!$B:$B, $A31, Nevis!$D:$D, "Out Ports") + SUMIFS('St Kitts'!$L:$L, 'St Kitts'!$B:$B, $A31, 'St Kitts'!$D:$D, "Out Ports") + SUMIFS(WestIndiesGeneral!$L:$L, WestIndiesGeneral!$B:$B, $A31, WestIndiesGeneral!$D:$D, "London") -> 0 | D31: =B31+C31 -> 0

Sheet Anguilla
A1: YEAR | B1: COMMODITY_NAME | C1: FROM_LOCATION | D1: TO_LOCATION | E1: ton | F1: hh | G1: quarter | H1: lb | J1: Total Pounds | L1: WEIGHT
B2: Almonds, Bitter | C2: Anguilla | D2: London
B3: Almonds, Sweet | C3: Anguilla | D3: London
B4: Aloes Epatica | C4: Anguilla | D4: London
B5: Annatto | C5: Anguilla | D5: London
B6: Anniseeds | C6: Anguilla | D6: London
B7: Bacon | C7: Anguilla | D7: London
B8: Barrel Staves | C8: Anguilla | D8: London
B9: Bay Berries | C9: Anguilla | D9: London
B10: Bees Wax | C10: Anguilla | D10: London
B11: Brimstone | C11: Anguilla | D11: London
B12: Brown Sugar | C12: Anguilla | D12: London
B13: Cassia Fistula | C13: Anguilla | D13: London
... B88: Wood, Redwood | C88: Anguilla | D88: Out Ports

Sheet Antigua
A1: YEAR | B1: COMMODITY_NAME | C1: FROM_LOCATION | D1: TO_LOCATION | E1: ton | F1: hh | G1: quarter | H1: lb | J1: Total Pounds | L1: WEIGHT
A2: 1731 | B2: Almonds, Bitter | C2: Antigua | D2: London | J2: =(E2*2240)+(F2*112)+(G2*28)+H2 -> 0 | L2: =J2/2240 -> 0
A3: 1731 | B3: Almonds, Sweet | C3: Antigua | D3: London | J3: =(E3*2240)+(F3*112)+(G3*28)+H3 -> 0 | L3: =J3/2240 -> 0
A4: 1731 | B4: Aloes Epatica | C4: Antigua | D4: London | J4: =(E4*2240)+(F4*112)+(G4*28)+H4 -> 0 | L4: =J4/2240 -> 0
A5: 1731 | B5: Annatto | C5: Antigua | D5: London | J5: =(E5*2240)+(F5*112)+(G5*28)+H5 -> 0 | L5: =J5/2240 -> 0
A6: 1731 | B6: Anniseeds | C6: Antigua | D6: London | J6: =(E6*2240)+(F6*112)+(G6*28)+H6 -> 0 | L6: =J6/2240 -> 0
A7: 1731 | B7: Bacon | C7: Antigua | D7: London | J7: =(E7*2240)+(F7*112)+(G7*28)+H7 -> 0 | L7: =J7/2240 -> 0
A8: 1731 | B8: Balsam Natural | C8: Antigua | D8: London | J8: =(E8*2240)+(F8*112)+(G8*28)+H8 -> 0 | L8: =J8/2240 -> 0
A9: 1731 | B9: Barbados Tarr | C9: Antigua | D9: London | H9: 24 | J9: =(E9*2240)+(F9*112)+(G9*28)+H9 -> 24 | L9: =J9/2240 -> 0.010714286
A10: 1731 | B10: Barrel Staves | C10: Antigua | D10: London | J10: =(E10*2240)+(F10*112)+(G10*28)+H10 -> 0 | L10: =J10/2240 -> 0
A11: 1731 | B11: Bay Berries | C11: Antigua | D11: London | J11: =(E11*2240)+(F11*112)+(G11*28)+H11 -> 0 | L11: =J11/2240 -> 0
A12: 1731 | B12: Bees Wax | C12: Antigua | D12: London | F12: 109 | H12: 18 | J12: =(E12*2240)+(F12*112)+(G12*28)+H12 -> 12226 | L12: =J12/2240 -> 5.4580357
A13: 1731 | B13: Brimstone | C13: Antigua | D13: London | J13: =(E13*2240)+(F13*112)+(G13*28)+H13 -> 0 | L13: =J13/2240 -> 0
A14: 1731 | B14: Brown Sugar | C14: Antigua | D14: London | F14: 99437 | G14: 2 | H14: 17 | J14: =(E14*2240)+(F14*112)+(G14*28)+H14 -> 11137017 | L14: =J14/2240 -> 4971.8826
A15: 1731 | B15: Cascarilla | C15: Antigua | D15: London | J15: =(E15*2240)+(F15*112)+(G15*28)+H15 -> 0 | L15: =J15/2240 -> 0
A16: 1731 | B16: Cassia Fistula | C16: Antigua | D16: London | J16: =(E16*2240)+(F16*112)+(G16*28)+H16 -> 0 | L16: =J16/2240 -> 0
A17: 1731 | B17: Chocolate | C17: Antigua | D17: London | J17: =(E17*2240)+(F17*112)+(G17*28)+H17 -> 0 | L17: =J17/2240 -> 0
A18: 1731 | B18: Cocheneal | C18: Antigua | D18: London | J18: =(E18*2240)+(F18*112)+(G18*28)+H18 -> 0 | L18: =J18/2240 -> 0
A19: 1731 | B19: Cocoa Nuts | C19: Antigua | D19: London | J19: =(E19*2240)+(F19*112)+(G19*28)+H19 -> 0 | L19: =J19/2240 -> 0
A20: 1731 | B20: Cocoa Paste | C20: Antigua | D20: London | J20: =(E20*2240)+(F20*112)+(G20*28)+H20 -> 0 | L20: =J20/2240 -> 0
A21: 1731 | B21: Coffee | C21: Antigua | D21: London | J21: =(E21*2240)+(F21*112)+(G21*28)+H21 -> 0 | L21: =J21/2240 -> 0
A22: 1731 | B22: Cortex Peru | C22: Antigua | D22: London | J22: =(E22*2240)+(F22*112)+(G22*28)+H22 -> 0 | L22: =J22/2240 -> 0
A23: 1731 | B23: Cortex Winteranus | C23: Antigua | D23: London | J23: =(E23*2240)+(F23*112)+(G23*28)+H23 -> 0 | L23: =J23/2240 -> 0
A24: 1731 | B24: Cotton | C24: Antigua | D24: London | H24: =256.5*200 -> 51300 | I24: 256.5bags | J24: =(E24*2240)+(F24*112)+(G24*28)+H24 -> 51300 | L24: =J24/2240 -> 22.901786
A25: 1731 | B25: Dry Ginger | C25: Antigua | D25: London | F25: 87 | H25: 5 | J25: =(E25*2240)+(F25*112)+(G25*28)+H25 -> 9749 | L25: =J25/2240 -> 4.3522321
A26: 1731 | B26: Elephant Teeth | C26: Antigua | D26: London | F26: 417 | H26: 11 | J26: =(E26*2240)+(F26*112)+(G26*28)+H26 -> 46715 | L26: =J26/2240 -> 20.854911
A27: 1731 | B27: Green Ginger | C27: Antigua | D27: London | J27: =(E27*2240)+(F27*112)+(G27*28)+H27 -> 0 | L27: =J27/2240 -> 0
A28: 1731 | B28: Guinea Grains | C28: Antigua | D28: London | H28: 4116 | J28: =(E28*2240)+(F28*112)+(G28*28)+H28 -> 4116 | L28: =J28/2240 -> 1.8375
A29: 1731 | B29: Gum Guiaci | C29: Antigua | D29: London | J29: =(E29*2240)+(F29*112)+(G29*28)+H29 -> 0 | L29: =J29/2240 -> 0
A30: 1731 | B30: Gum Seneca | C30: Antigua | D30: London | J30: =(E30*2240)+(F30*112)+(G30*28)+H30 -> 0 | L30: =J30/2240 -> 0
A31: 1731 | B31: Hemp | C31: Antigua | D31: London | J31: =(E31*2240)+(F31*112)+(G31*28)+H31 -> 0 | L31: =J31/2240 -> 0
A32: 1731 | B32: Hypococania | C32: Antigua | D32: London | J32: =(E32*2240)+(F32*112)+(G32*28)+H32 -> 0 | L32: =J32/2240 -> 0
A33: 1731 | B33: Indigo | C33: Antigua | D33: London | J33: =(E33*2240)+(F33*112)+(G33*28)+H33 -> 0 | L33: =J33/2240 -> 0
A34: 1731 | B34: Jallop? | C34: Antigua | D34: London | J34: =(E34*2240)+(F34*112)+(G34*28)+H34 -> 0 | L34: =J34/2240 -> 0
A35: 1731 | B35: Lemon Water | C35: Antigua | D35: London | J35: =(E35*2240)+(F35*112)+(G35*28)+H35 -> 0 | L35: =J35/2240 -> 0
A36: 1731 | B36: Lignum Vitae | C36: Antigua | D36: London | E36: 6 | J36: =(E36*2240)+(F36*112)+(G36*28)+H36 -> 13440 | L36: =J36/2240 -> 6
A37: 1731 | B37: Lime Juice | C37: Antigua | D37: London | H37: 290 | I37: 29g | J37: =(E37*2240)+(F37*112)+(G37*28)+H37 -> 290 | L37: =J37/2240 -> 0.12946429
A38: 1731 | B38: Loaf Sugar | C38: Antigua | D38: London | J38: =(E38*2240)+(F38*112)+(G38*28)+H38 -> 0 | L38: =J38/2240 -> 0
A39: 1731 | B39: Madera Wine | C39: Antigua | D39: London | H39: 169403.5 | I39: 67t 52g | J39: =(E39*2240)+(F39*112)+(G39*28)+H39 -> 169403.5 | L39: =J39/2240 -> 75.626563
A40: 1731 | B40: Molasses | C40: Antigua | D40: London | F40: 21 | G40: 1 | H40: 6 | J40: =(E40*2240)+(F40*112)+(G40*28)+H40 -> 2386 | L40: =J40/2240 -> 1.0651786
...

Sheet Barbados
A1: YEAR | B1: COMMODITY_NAME | C1: FROM_LOCATION | D1: TO_LOCATION | E1: ton | F1: hh | G1: quarter | H1: lb | J1: Total Pounds | L1: WEIGHT
A2: 1731 | B2: Almonds, Bitter | C2: Barbados | D2: London | F2: 15 | J2: =(E2*2240)+(F2*112)+(G2*28)+H2 -> 1680 | L2: =J2/2240 -> 0.75
A3: 1731 | B3: Almonds, Sweet | C3: Barbados | D3: London | J3: =(E3*2240)+(F3*112)+(G3*28)+H3 -> 0 | L3: =J3/2240 -> 0
A4: 1731 | B4: Aloes Epatica | C4: Barbados | D4: London | H4: 10452 | J4: =(E4*2240)+(F4*112)+(G4*28)+H4 -> 10452 | L4: =J4/2240 -> 4.6660714
A5: 1731 | B5: Annatto | C5: Barbados | D5: London | J5: =(E5*2240)+(F5*112)+(G5*28)+H5 -> 0 | L5: =J5/2240 -> 0
A6: 1731 | B6: Anniseeds | C6: Barbados | D6: London | J6: =(E6*2240)+(F6*112)+(G6*28)+H6 -> 0 | L6: =J6/2240 -> 0
A7: 1731 | B7: Archelia | C7: Barbados | D7: London | F7: 2 | J7: =(E7*2240)+(F7*112)+(G7*28)+H7 -> 224 | L7: =J7/2240 -> 0.1
A8: 1731 | B8: Balsam Capavia | C8: Barbados | D8: London | H8: 867 | J8: =(E8*2240)+(F8*112)+(G8*28)+H8 -> 867 | L8: =J8/2240 -> 0.38705357
A9: 1731 | B9: Barbados Tarr | C9: Barbados | D9: London | H9: 2571 | J9: =(E9*2240)+(F9*112)+(G9*28)+H9 -> 2571 | L9: =J9/2240 -> 1.1477679
A10: 1731 | B10: Barrel Staves | C10: Barbados | D10: London | J10: =(E10*2240)+(F10*112)+(G10*28)+H10 -> 0 | L10: =J10/2240 -> 0
A11: 1731 | B11: Bees Wax | C11: Barbados | D11: London | F11: 60 | J11: =(E11*2240)+(F11*112)+(G11*28)+H11 -> 6720 | L11: =J11/2240 -> 3
A12: 1731 | B12: Brimstone | C12: Barbados | D12: London | J12: =(E12*2240)+(F12*112)+(G12*28)+H12 -> 0 | L12: =J12/2240 -> 0
A13: 1731 | B13: Brown Sugar | C13: Barbados | D13: London | F13: 111526 | G13: 1 | H13: 21 | J13: =(E13*2240)+(F13*112)+(G13*28)+H13 -> 12490961 | L13: =J13/2240 -> 5576.3219
A14: 1731 | B14: Cassia Fistula | C14: Barbados | D14: London | H14: 5268 | J14: =(E14*2240)+(F14*112)+(G14*28)+H14 -> 5268 | L14: =J14/2240 -> 2.3517857
A15: 1731 | B15: Chocolate | C15: Barbados | D15: London | J15: =(E15*2240)+(F15*112)+(G15*28)+H15 -> 0 | L15: =J15/2240 -> 0
A16: 1731 | B16: Cocheneal | C16: Barbados | D16: London | J16: =(E16*2240)+(F16*112)+(G16*28)+H16 -> 0 | L16: =J16/2240 -> 0
A17: 1731 | B17: Cocoa Nuts | C17: Barbados | D17: London | J17: =(E17*2240)+(F17*112)+(G17*28)+H17 -> 0 | L17: =J17/2240 -> 0
A18: 1731 | B18: Cocoa Paste | C18: Barbados | D18: London | J18: =(E18*2240)+(F18*112)+(G18*28)+H18 -> 0 | L18: =J18/2240 -> 0
A19: 1731 | B19: Cortex Peru | C19: Barbados | D19: London | J19: =(E19*2240)+(F19*112)+(G19*28)+H19 -> 0 | L19: =J19/2240 -> 0
A20: 1731 | B20: Cotton | C20: Barbados | D20: London | H20: =184*200 -> 36800 | I20: 184bags | J20: =(E20*2240)+(F20*112)+(G20*28)+H20 -> 36800 | L20: =J20/2240 -> 16.428571
A21: 1731 | B21: Dry Ginger | C21: Barbados | D21: London | F21: 2019 | H21: 15 | J21: =(E21*2240)+(F21*112)+(G21*28)+H21 -> 226143 | L21: =J21/2240 -> 100.9567
A22: 1731 | B22: Elephant Teeth | C22: Barbados | D22: London | F22: 20 | J22: =(E22*2240)+(F22*112)+(G22*28)+H22 -> 2240 | L22: =J22/2240 -> 1
A23: 1731 | B23: Green Ginger | C23: Barbados | D23: London | H23: 413 | J23: =(E23*2240)+(F23*112)+(G23*28)+H23 -> 413 | L23: =J23/2240 -> 0.184375
A24: 1731 | B24: Guinea Grains | C24: Barbados | D24: London | F24: 2 | G24: 3 | H24: 14 | J24: =(E24*2240)+(F24*112)+(G24*28)+H24 -> 322 | L24: =J24/2240 -> 0.14375
A25: 1731 | B25: Gum Arabick | C25: Barbados | D25: London | F25: 100 | J25: =(E25*2240)+(F25*112)+(G25*28)+H25 -> 11200 | L25: =J25/2240 -> 5
A26: 1731 | B26: Hemp | C26: Barbados | D26: London | J26: =(E26*2240)+(F26*112)+(G26*28)+H26 -> 0 | L26: =J26/2240 -> 0
A27: 1731 | B27: Indigo | C27: Barbados | D27: London | H27: 56 | J27: =(E27*2240)+(F27*112)+(G27*28)+H27 -> 56 | L27: =J27/2240 -> 0.025
A28: 1731 | B28: Lemon Water | C28: Barbados | D28: London | J28: =(E28*2240)+(F28*112)+(G28*28)+H28 -> 0 | L28: =J28/2240 -> 0
A29: 1731 | B29: Lignum Vitae | C29: Barbados | D29: London | J29: =(E29*2240)+(F29*112)+(G29*28)+H29 -> 0 | L29: =J29/2240 -> 0
A30: 1731 | B30: Lime Juice | C30: Barbados | D30: London | H30: 18294.5 | I30: 1829g | J30: =(E30*2240)+(F30*112)+(G30*28)+H30 -> 18294.5 | L30: =J30/2240 -> 8.1671875
A31: 1731 | B31: Loaf Sugar | C31: Barbados | D31: London | J31: =(E31*2240)+(F31*112)+(G31*28)+H31 -> 0 | L31: =J31/2240 -> 0
A32: 1731 | B32: Madera Wine | C32: Barbados | D32: London | H32: 249124 | I32: 98t 3h 21g | J32: =(E32*2240)+(F32*112)+(G32*28)+H32 -> 249124 | L32: =J32/2240 -> 111.21607
A33: 1731 | B33: Molasses | C33: Barbados | D33: London | F33: 15 | J33: =(E33*2240)+(F33*112)+(G33*28)+H33 -> 1680 | L33: =J33/2240 -> 0.75
A34: 1731 | B34: Oranges | C34: Barbados | D34: London | J34: =(E34*2240)+(F34*112)+(G34*28)+H34 -> 0 | L34: =J34/2240 -> 0
A35: 1731 | B35: Pickles | C35: Barbados | D35: London | H35: 785 | I35: 78.5g | J35: =(E35*2240)+(F35*112)+(G35*28)+H35 -> 785 | L35: =J35/2240 -> 0.35044643
A36: 1731 | B36: Pimento | C36: Barbados | D36: London | J36: =(E36*2240)+(F36*112)+(G36*28)+H36 -> 0 | L36: =J36/2240 -> 0
A37: 1731 | B37: Rice | C37: Barbados | D37: London | F37: 282 | G37: 3 | H37: 7 | J37: =(E37*2240)+(F37*112)+(G37*28)+H37 -> 31675 | L37: =J37/2240 -> 14.140625
A38: 1731 | B38: Rum | C38: Barbados | D38: London | H38: 402713.5 | I38: 40261g | J38: =(E38*2240)+(F38*112)+(G38*28)+H38 -> 402713.5 | L38: =J38/2240 -> 179.78281
A39: 1731 | B39: Sasparilla | C39: Barbados | D39: London | J39: =(E39*2240)+(F39*112)+(G39*28)+H39 -> 0 | L39: =J39/2240 -> 0
A40: 1731 | B40: Shruff | C40: Barbados | D40: London | F40: 4 | J40: =(E40*2240)+(F40*112)+(G40*28)+H40 -> 448 | L40: =J40/2240 -> 0.2
...

Sheet Bermuda
A1: YEAR | B1: COMMODITY_NAME | C1: FROM_LOCATION | D1: TO_LOCATION | E1: ton | F1: hh | G1: quarter | H1: lb | J1: Total Pounds | L1: WEIGHT
B2: Bermudos Plat | C2: Bermuda | D2: London | J2: =(E2*2240)+(F2*112)+(G2*28)+H2 -> 0 | L2: =J2/2240 -> 0
B3: Brown Sugar | C3: Bermuda | D3: London | J3: =(E3*2240)+(F3*112)+(G3*28)+H3 -> 0 | L3: =J3/2240 -> 0
B4: Cocoa Nuts | C4: Bermuda | D4: London | J4: =(E4*2240)+(F4*112)+(G4*28)+H4 -> 0 | L4: =J4/2240 -> 0
B5: Cotton | C5: Bermuda | D5: London | J5: =(E5*2240)+(F5*112)+(G5*28)+H5 -> 0 | L5: =J5/2240 -> 0
B6: Elephant Teeth | C6: Bermuda | D6: London | J6: =(E6*2240)+(F6*112)+(G6*28)+H6 -> 0 | L6: =J6/2240 -> 0
B7: Indigo | C7: Bermuda | D7: London | J7: =(E7*2240)+(F7*112)+(G7*28)+H7 -> 0 | L7: =J7/2240 -> 0
B8: Madera Wine | C8: Bermuda | D8: London | J8: =(E8*2240)+(F8*112)+(G8*28)+H8 -> 0 | L8: =J8/2240 -> 0
B9: Molasses | C9: Bermuda | D9: London | J9: =(E9*2240)+(F9*112)+(G9*28)+H9 -> 0 | L9: =J9/2240 -> 0
B10: Rice | C10: Bermuda | D10: London | J10: =(E10*2240)+(F10*112)+(G10*28)+H10 -> 0 | L10: =J10/2240 -> 0
B11: Rum | C11: Bermuda | D11: London | J11: =(E11*2240)+(F11*112)+(G11*28)+H11 -> 0 | L11: =J11/2240 -> 0
B12: Shruff | C12: Bermuda | D12: London | J12: =(E12*2240)+(F12*112)+(G12*28)+H12 -> 0 | L12: =J12/2240 -> 0
B13: Tortoise Shell | C13: Bermuda | D13: London | J13: =(E13*2240)+(F13*112)+(G13*28)+H13 -> 0 | L13: =J13/2240 -> 0
... B28: Wood, Logwood | C28: Bermuda | D28: Out Ports | J28: =(E28*2240)+(F28*112)+(G28*28)+H28 -> 0 | L28: =J28/2240 -> 0

Sheet Jamaica
A1: YEAR | B1: COMMODITY_NAME | C1: FROM_LOCATION | D1: TO_LOCATION | E1: ton | F1: hh | G1: quarter | H1: lb | J1: Total Pounds | L1: WEIGHT
A2: 1731 | B2: Almonds, Bitter | C2: Jamaica | D2: London | J2: =(E2*2240)+(F2*112)+(G2*28)+H2 -> 0 | L2: =J2/2240 -> 0
A3: 1731 | B3: Almonds, Sweet | C3: Jamaica | D3: London | J3: =(E3*2240)+(F3*112)+(G3*28)+H3 -> 0 | L3: =J3/2240 -> 0
A4: 1731 | B4: Aloes Epatica | C4: Jamaica | D4: London | J4: =(E4*2240)+(F4*112)+(G4*28)+H4 -> 0 | L4: =J4/2240 -> 0
A5: 1731 | B5: Annatto | C5: Jamaica | D5: London | H5: 125 | J5: =(E5*2240)+(F5*112)+(G5*28)+H5 -> 125 | L5: =J5/2240 -> 0.055803571
A6: 1731 | B6: Anniseeds | C6: Jamaica | D6: London | J6: =(E6*2240)+(F6*112)+(G6*28)+H6 -> 0 | L6: =J6/2240 -> 0
A7: 1731 | B7: Bacon | C7: Jamaica | D7: London | J7: =(E7*2240)+(F7*112)+(G7*28)+H7 -> 0 | L7: =J7/2240 -> 0
A8: 1731 | B8: Balsam Artificial | C8: Jamaica | D8: London | H8: 710 | J8: =(E8*2240)+(F8*112)+(G8*28)+H8 -> 710 | L8: =J8/2240 -> 0.31696429
A9: 1731 | B9: Balsam Natural | C9: Jamaica | D9: London | H9: 100 | J9: =(E9*2240)+(F9*112)+(G9*28)+H9 -> 100 | L9: =J9/2240 -> 0.044642857
A10: 1731 | B10: Barrel Staves | C10: Jamaica | D10: London | J10: =(E10*2240)+(F10*112)+(G10*28)+H10 -> 0 | L10: =J10/2240 -> 0
A11: 1731 | B11: Bay Berries | C11: Jamaica | D11: London | J11: =(E11*2240)+(F11*112)+(G11*28)+H11 -> 0 | L11: =J11/2240 -> 0
A12: 1731 | B12: Bees Wax | C12: Jamaica | D12: London | H12: 40 | J12: =(E12*2240)+(F12*112)+(G12*28)+H12 -> 40 | L12: =J12/2240 -> 0.017857143
A13: 1731 | B13: Brimstone | C13: Jamaica | D13: London | J13: =(E13*2240)+(F13*112)+(G13*28)+H13 -> 0 | L13: =J13/2240 -> 0
A14: 1731 | B14: Brown Sugar | C14: Jamaica | D14: London | F14: 193240 | G14: 3 | H14: 15 | J14: =(E14*2240)+(F14*112)+(G14*28)+H14 -> 21642979 | L14: =J14/2240 -> 9662.0442
A15: 1731 | B15: Cascarilla | C15: Jamaica | D15: London | J15: =(E15*2240)+(F15*112)+(G15*28)+H15 -> 0 | L15: =J15/2240 -> 0
A16: 1731 | B16: Cassia Fistula | C16: Jamaica | D16: London | J16: =(E16*2240)+(F16*112)+(G16*28)+H16 -> 0 | L16: =J16/2240 -> 0
A17: 1731 | B17: Chocolate | C17: Jamaica | D17: London | J17: =(E17*2240)+(F17*112)+(G17*28)+H17 -> 0 | L17: =J17/2240 -> 0
A18: 1731 | B18: Cocheneal | C18: Jamaica | D18: London | J18: =(E18*2240)+(F18*112)+(G18*28)+H18 -> 0 | L18: =J18/2240 -> 0
A19: 1731 | B19: Cocoa Nuts | C19: Jamaica | D19: London | J19: =(E19*2240)+(F19*112)+(G19*28)+H19 -> 0 | L19: =J19/2240 -> 0
A20: 1731 | B20: Cocoa Paste | C20: Jamaica | D20: London | J20: =(E20*2240)+(F20*112)+(G20*28)+H20 -> 0 | L20: =J20/2240 -> 0
A21: 1731 | B21: Coffee | C21: Jamaica | D21: London | J21: =(E21*2240)+(F21*112)+(G21*28)+H21 -> 0 | L21: =J21/2240 -> 0
A22: 1731 | B22: Cortex Peru | C22: Jamaica | D22: London | H22: 121701 | J22: =(E22*2240)+(F22*112)+(G22*28)+H22 -> 121701 | L22: =J22/2240 -> 54.330804
A23: 1731 | B23: Cortex Winteranus | C23: Jamaica | D23: London | H23: 4230 | J23: =(E23*2240)+(F23*112)+(G23*28)+H23 -> 4230 | L23: =J23/2240 -> 1.8883929
A24: 1731 | B24: Cotton | C24: Jamaica | D24: London | H24: =258*200 -> 51600 | I24: 258bags | J24: =(E24*2240)+(F24*112)+(G24*28)+H24 -> 51600 | L24: =J24/2240 -> 23.035714
A25: 1731 | B25: Dry Ginger | C25: Jamaica | D25: London | F25: 3675 | G25: 3 | H25: 19 | J25: =(E25*2240)+(F25*112)+(G25*28)+H25 -> 411703 | L25: =J25/2240 -> 183.79598
A26: 1731 | B26: Elephant Teeth | C26: Jamaica | D26: London | F26: 125 | G26: 2 | H26: 22 | J26: =(E26*2240)+(F26*112)+(G26*28)+H26 -> 14078 | L26: =J26/2240 -> 6.2848214
A27: 1731 | B27: Green Ginger | C27: Jamaica | D27: London | H27: 82 | J27: =(E27*2240)+(F27*112)+(G27*28)+H27 -> 82 | L27: =J27/2240 -> 0.036607143
A28: 1731 | B28: Guinea Grains | C28: Jamaica | D28: London | H28: 2532 | J28: =(E28*2240)+(F28*112)+(G28*28)+H28 -> 2532 | L28: =J28/2240 -> 1.1303571
A29: 1731 | B29: Gum Elemni | C29: Jamaica | D29: London | H29: 506 | J29: =(E29*2240)+(F29*112)+(G29*28)+H29 -> 506 | L29: =J29/2240 -> 0.22589286
A30: 1731 | B30: Gum Guiaci | C30: Jamaica | D30: London | H30: 2746 | J30: =(E30*2240)+(F30*112)+(G30*28)+H30 -> 2746 | L30: =J30/2240 -> 1.2258929
A31: 1731 | B31: Hemp | C31: Jamaica | D31: London | J31: =(E31*2240)+(F31*112)+(G31*28)+H31 -> 0 | L31: =J31/2240 -> 0
A32: 1731 | B32: Hypococania | C32: Jamaica | D32: London | H32: 424 | J32: =(E32*2240)+(F32*112)+(G32*28)+H32 -> 424 | L32: =J32/2240 -> 0.18928571
A33: 1731 | B33: Indigo | C33: Jamaica | D33: London | H33: 96714 | J33: =(E33*2240)+(F33*112)+(G33*28)+H33 -> 96714 | L33: =J33/2240 -> 43.175893
A34: 1731 | B34: Jollop | C34: Jamaica | D34: London | H34: 1308 | J34: =(E34*2240)+(F34*112)+(G34*28)+H34 -> 1308 | L34: =J34/2240 -> 0.58392857
A35: 1731 | B35: Lemon Water | C35: Jamaica | D35: London | J35: =(E35*2240)+(F35*112)+(G35*28)+H35 -> 0 | L35: =J35/2240 -> 0
A36: 1731 | B36: Lignum Vitae | C36: Jamaica | D36: London | J36: =(E36*2240)+(F36*112)+(G36*28)+H36 -> 0 | L36: =J36/2240 -> 0
A37: 1731 | B37: Lime Juice | C37: Jamaica | D37: London | H37: 32568.5 | I37: 3256g | J37: =(E37*2240)+(F37*112)+(G37*28)+H37 -> 32568.5 | L37: =J37/2240 -> 14.539509
A38: 1731 | B38: Loaf Sugar | C38: Jamaica | D38: London | J38: =(E38*2240)+(F38*112)+(G38*28)+H38 -> 0 | L38: =J38/2240 -> 0
A39: 1731 | B39: Madera Wine | C39: Jamaica | D39: London | H39: 26397 | I39: 10t 1h 56g | J39: =(E39*2240)+(F39*112)+(G39*28)+H39 -> 26397 | L39: =J39/2240 -> 11.784375
A40: 1731 | B40: Molasses | C40: Jamaica | D40: London | J40: =(E40*2240)+(F40*112)+(G40*28)+H40 -> 0 | L40: =J40/2240 -> 0
...

Sheet Mountserat
A1: YEAR | B1: COMMODITY_NAME | C1: FROM_LOCATION | D1: TO_LOCATION | E1: ton | F1: hh | G1: quarter | H1: lb | J1: Total Pounds | L1: WEIGHT
A2: 1731 | B2: Almonds, Bitter | C2: Mountserat | D2: London | J2: =(E2*2240)+(F2*112)+(G2*28)+H2 -> 0 | L2: =J2/2240 -> 0
A3: 1731 | B3: Almonds, Sweet | C3: Mountserat | D3: London | J3: =(E3*2240)+(F3*112)+(G3*28)+H3 -> 0 | L3: =J3/2240 -> 0
A4: 1731 | B4: Aloes Epatica | C4: Mountserat | D4: London | J4: =(E4*2240)+(F4*112)+(G4*28)+H4 -> 0 | L4: =J4/2240 -> 0
A5: 1731 | B5: Annatto | C5: Mountserat | D5: London | J5: =(E5*2240)+(F5*112)+(G5*28)+H5 -> 0 | L5: =J5/2240 -> 0
A6: 1731 | B6: Anniseeds | C6: Mountserat | D6: London | J6: =(E6*2240)+(F6*112)+(G6*28)+H6 -> 0 | L6: =J6/2240 -> 0
A7: 1731 | B7: Bacon | C7: Mountserat | D7: London | J7: =(E7*2240)+(F7*112)+(G7*28)+H7 -> 0 | L7: =J7/2240 -> 0
A8: 1731 | B8: Barbados Tarr | C8: Mountserat | D8: London | H8: 30 | J8: =(E8*2240)+(F8*112)+(G8*28)+H8 -> 30 | L8: =J8/2240 -> 0.013392857
A9: 1731 | B9: Barrel Staves | C9: Mountserat | D9: London | J9: =(E9*2240)+(F9*112)+(G9*28)+H9 -> 0 | L9: =J9/2240 -> 0
A10: 1731 | B10: Bay Berries | C10: Mountserat | D10: London | J10: =(E10*2240)+(F10*112)+(G10*28)+H10 -> 0 | L10: =J10/2240 -> 0
A11: 1731 | B11: Bees Wax | C11: Mountserat | D11: London | J11: =(E11*2240)+(F11*112)+(G11*28)+H11 -> 0 | L11: =J11/2240 -> 0
A12: 1731 | B12: Brimstone | C12: Mountserat | D12: London | J12: =(E12*2240)+(F12*112)+(G12*28)+H12 -> 0 | L12: =J12/2240 -> 0
A13: 1731 | B13: Brown Sugar | C13: Mountserat | D13: London | F13: 27959 | G13: 3 | H13: 16 | J13: =(E13*2240)+(F13*112)+(G13*28)+H13 -> 3131508 | L13: =J13/2240 -> 1397.9946
A14: 1731 | B14: Cascarilla | C14: Mountserat | D14: London | J14: =(E14*2240)+(F14*112)+(G14*28)+H14 -> 0 | L14: =J14/2240 -> 0
A15: 1731 | B15: Cassia Fistula | C15: Mountserat | D15: London | J15: =(E15*2240)+(F15*112)+(G15*28)+H15 -> 0 | L15: =J15/2240 -> 0
A16: 1731 | B16: Chocolate | C16: Mountserat | D16: London | J16: =(E16*2240)+(F16*112)+(G16*28)+H16 -> 0 | L16: =J16/2240 -> 0
A17: 1731 | B17: Cocheneal | C17: Mountserat | D17: London | J17: =(E17*2240)+(F17*112)+(G17*28)+H17 -> 0 | L17: =J17/2240 -> 0
A18: 1731 | B18: Cocoa Nuts | C18: Mountserat | D18: London | J18: =(E18*2240)+(F18*112)+(G18*28)+H18 -> 0 | L18: =J18/2240 -> 0
A19: 1731 | B19: Cocoa Paste | C19: Mountserat | D19: London | J19: =(E19*2240)+(F19*112)+(G19*28)+H19 -> 0 | L19: =J19/2240 -> 0
A20: 1731 | B20: Coffee | C20: Mountserat | D20: London | J20: =(E20*2240)+(F20*112)+(G20*28)+H20 -> 0 | L20: =J20/2240 -> 0
A21: 1731 | B21: Cortex Peru | C21: Mountserat | D21: London | J21: =(E21*2240)+(F21*112)+(G21*28)+H21 -> 0 | L21: =J21/2240 -> 0
A22: 1731 | B22: Cortex Winteranus | C22: Mountserat | D22: London | J22: =(E22*2240)+(F22*112)+(G22*28)+H22 -> 0 | L22: =J22/2240 -> 0
A23: 1731 | B23: Cotton | C23: Mountserat | D23: London | H23: =47*200 -> 9400 | I23: 47bags | J23: =(E23*2240)+(F23*112)+(G23*28)+H23 -> 9400 | L23: =J23/2240 -> 4.1964286
A24: 1731 | B24: Dry Ginger | C24: Mountserat | D24: London | J24: =(E24*2240)+(F24*112)+(G24*28)+H24 -> 0 | L24: =J24/2240 -> 0
A25: 1731 | B25: Elephant Teeth | C25: Mountserat | D25: London | F25: 15 | H25: 21 | J25: =(E25*2240)+(F25*112)+(G25*28)+H25 -> 1701 | L25: =J25/2240 -> 0.759375
A26: 1731 | B26: Green Ginger | C26: Mountserat | D26: London | J26: =(E26*2240)+(F26*112)+(G26*28)+H26 -> 0 | L26: =J26/2240 -> 0
A27: 1731 | B27: Guinea Grains | C27: Mountserat | D27: London | J27: =(E27*2240)+(F27*112)+(G27*28)+H27 -> 0 | L27: =J27/2240 -> 0
A28: 1731 | B28: Gum Guiaci | C28: Mountserat | D28: London | J28: =(E28*2240)+(F28*112)+(G28*28)+H28 -> 0 | L28: =J28/2240 -> 0
A29: 1731 | B29: Hemp | C29: Mountserat | D29: London | J29: =(E29*2240)+(F29*112)+(G29*28)+H29 -> 0 | L29: =J29/2240 -> 0
A30: 1731 | B30: Hypococania | C30: Mountserat | D30: London | J30: =(E30*2240)+(F30*112)+(G30*28)+H30 -> 0 | L30: =J30/2240 -> 0
A31: 1731 | B31: Indigo | C31: Mountserat | D31: London | H31: 344 | J31: =(E31*2240)+(F31*112)+(G31*28)+H31 -> 344 | L31: =J31/2240 -> 0.15357143
A32: 1731 | B32: Jallop? | C32: Mountserat | D32: London | J32: =(E32*2240)+(F32*112)+(G32*28)+H32 -> 0 | L32: =J32/2240 -> 0
A33: 1731 | B33: Lemon Water | C33: Mountserat | D33: London | J33: =(E33*2240)+(F33*112)+(G33*28)+H33 -> 0 | L33: =J33/2240 -> 0
A34: 1731 | B34: Lignum Vitae | C34: Mountserat | D34: London | J34: =(E34*2240)+(F34*112)+(G34*28)+H34 -> 0 | L34: =J34/2240 -> 0
A35: 1731 | B35: Lime Juice | C35: Mountserat | D35: London | J35: =(E35*2240)+(F35*112)+(G35*28)+H35 -> 0 | L35: =J35/2240 -> 0
A36: 1731 | B36: Loaf Sugar | C36: Mountserat | D36: London | J36: =(E36*2240)+(F36*112)+(G36*28)+H36 -> 0 | L36: =J36/2240 -> 0
A37: 1731 | B37: Madera Wine | C37: Mountserat | D37: London | J37: =(E37*2240)+(F37*112)+(G37*28)+H37 -> 0 | L37: =J37/2240 -> 0
A38: 1731 | B38: Molasses | C38: Mountserat | D38: London | J38: =(E38*2240)+(F38*112)+(G38*28)+H38 -> 0 | L38: =J38/2240 -> 0
A39: 1731 | B39: Oranges | C39: Mountserat | D39: London | J39: =(E39*2240)+(F39*112)+(G39*28)+H39 -> 0 | L39: =J39/2240 -> 0
A40: 1731 | B40: Orchelia | C40: Mountserat | D40: London | J40: =(E40*2240)+(F40*112)+(G40*28)+H40 -> 0 | L40: =J40/2240 -> 0
...

Sheet Nevis
A1: YEAR | B1: COMMODITY_NAME | C1: FROM_LOCATION | D1: TO_LOCATION | E1: ton | F1: hh | G1: quarter | H1: lb | J1: Total Pounds | L1: WEIGHT
A2: 1731 | B2: Almonds, Bitter | C2: Nevis | D2: London | J2: =(E2*2240)+(F2*112)+(G2*28)+H2 -> 0 | L2: =J2/2240 -> 0
A3: 1731 | B3: Almonds, Sweet | C3: Nevis | D3: London | J3: =(E3*2240)+(F3*112)+(G3*28)+H3 -> 0 | L3: =J3/2240 -> 0
A4: 1731 | B4: Aloes Epatica | C4: Nevis | D4: London | J4: =(E4*2240)+(F4*112)+(G4*28)+H4 -> 0 | L4: =J4/2240 -> 0
A5: 1731 | B5: Annatto | C5: Nevis | D5: London | J5: =(E5*2240)+(F5*112)+(G5*28)+H5 -> 0 | L5: =J5/2240 -> 0
A6: 1731 | B6: Anniseeds | C6: Nevis | D6: London | J6: =(E6*2240)+(F6*112)+(G6*28)+H6 -> 0 | L6: =J6/2240 -> 0
A7: 1731 | B7: Bacon | C7: Nevis | D7: London | J7: =(E7*2240)+(F7*112)+(G7*28)+H7 -> 0 | L7: =J7/2240 -> 0
A8: 1731 | B8: Barrel Staves | C8: Nevis | D8: London | J8: =(E8*2240)+(F8*112)+(G8*28)+H8 -> 0 | L8: =J8/2240 -> 0
A9: 1731 | B9: Bay Berries | C9: Nevis | D9: London | J9: =(E9*2240)+(F9*112)+(G9*28)+H9 -> 0 | L9: =J9/2240 -> 0
A10: 1731 | B10: Bees Wax | C10: Nevis | D10: London | J10: =(E10*2240)+(F10*112)+(G10*28)+H10 -> 0 | L10: =J10/2240 -> 0
A11: 1731 | B11: Brimstone | C11: Nevis | D11: London | J11: =(E11*2240)+(F11*112)+(G11*28)+H11 -> 0 | L11: =J11/2240 -> 0
A12: 1731 | B12: Brown Sugar | C12: Nevis | D12: London | F12: 21372 | G12: 2 | H12: 15 | J12: =(E12*2240)+(F12*112)+(G12*28)+H12 -> 2393735 | L12: =J12/2240 -> 1068.6317
A13: 1731 | B13: Cascarilla | C13: Nevis | D13: London | J13: =(E13*2240)+(F13*112)+(G13*28)+H13 -> 0 | L13: =J13/2240 -> 0
A14: 1731 | B14: Cassia Fistula | C14: Nevis | D14: London | J14: =(E14*2240)+(F14*112)+(G14*28)+H14 -> 0 | L14: =J14/2240 -> 0
A15: 1731 | B15: Chocolate | C15: Nevis | D15: London | J15: =(E15*2240)+(F15*112)+(G15*28)+H15 -> 0 | L15: =J15/2240 -> 0
A16: 1731 | B16: Cocheneal | C16: Nevis | D16: London | J16: =(E16*2240)+(F16*112)+(G16*28)+H16 -> 0 | L16: =J16/2240 -> 0
A17: 1731 | B17: Cocoa Nuts | C17: Nevis | D17: London | G17: 3 | H17: 16 | J17: =(E17*2240)+(F17*112)+(G17*28)+H17 -> 100 | L17: =J17/2240 -> 0.044642857
A18: 1731 | B18: Cocoa Paste | C18: Nevis | D18: London | J18: =(E18*2240)+(F18*112)+(G18*28)+H18 -> 0 | L18: =J18/2240 -> 0
A19: 1731 | B19: Coffee | C19: Nevis | D19: London | J19: =(E19*2240)+(F19*112)+(G19*28)+H19 -> 0 | L19: =J19/2240 -> 0
A20: 1731 | B20: Cortex Peru | C20: Nevis | D20: London | J20: =(E20*2240)+(F20*112)+(G20*28)+H20 -> 0 | L20: =J20/2240 -> 0
A21: 1731 | B21: Cortex Winteranus | C21: Nevis | D21: London | J21: =(E21*2240)+(F21*112)+(G21*28)+H21 -> 0 | L21: =J21/2240 -> 0
A22: 1731 | B22: Cotton | C22: Nevis | D22: London | H22: =31*200 -> 6200 | I22: 31bags | J22: =(E22*2240)+(F22*112)+(G22*28)+H22 -> 6200 | L22: =J22/2240 -> 2.7678571
A23: 1731 | B23: Dry Ginger | C23: Nevis | D23: London | J23: =(E23*2240)+(F23*112)+(G23*28)+H23 -> 0 | L23: =J23/2240 -> 0
A24: 1731 | B24: Elephant Teeth | C24: Nevis | D24: London | F24: 4 | J24: =(E24*2240)+(F24*112)+(G24*28)+H24 -> 448 | L24: =J24/2240 -> 0.2
A25: 1731 | B25: Green Ginger | C25: Nevis | D25: London | J25: =(E25*2240)+(F25*112)+(G25*28)+H25 -> 0 | L25: =J25/2240 -> 0
A26: 1731 | B26: Guinea Grains | C26: Nevis | D26: London | J26: =(E26*2240)+(F26*112)+(G26*28)+H26 -> 0 | L26: =J26/2240 -> 0
A27: 1731 | B27: Gum Guiaci | C27: Nevis | D27: London | J27: =(E27*2240)+(F27*112)+(G27*28)+H27 -> 0 | L27: =J27/2240 -> 0
A28: 1731 | B28: Hemp | C28: Nevis | D28: London | J28: =(E28*2240)+(F28*112)+(G28*28)+H28 -> 0 | L28: =J28/2240 -> 0
A29: 1731 | B29: Hypococania | C29: Nevis | D29: London | J29: =(E29*2240)+(F29*112)+(G29*28)+H29 -> 0 | L29: =J29/2240 -> 0
A30: 1731 | B30: Indigo | C30: Nevis | D30: London | J30: =(E30*2240)+(F30*112)+(G30*28)+H30 -> 0 | L30: =J30/2240 -> 0
A31: 1731 | B31: Jallop? | C31: Nevis | D31: London | J31: =(E31*2240)+(F31*112)+(G31*28)+H31 -> 0 | L31: =J31/2240 -> 0
A32: 1731 | B32: Lemon Water | C32: Nevis | D32: London | J32: =(E32*2240)+(F32*112)+(G32*28)+H32 -> 0 | L32: =J32/2240 -> 0
A33: 1731 | B33: Lignum Vitae | C33: Nevis | D33: London | E33: 22 | F33: 6 | G33: 2 | J33: =(E33*2240)+(F33*112)+(G33*28)+H33 -> 50008 | L33: =J33/2240 -> 22.325
A34: 1731 | B34: Lime Juice | C34: Nevis | D34: London | J34: =(E34*2240)+(F34*112)+(G34*28)+H34 -> 0 | L34: =J34/2240 -> 0
A35: 1731 | B35: Loaf Sugar | C35: Nevis | D35: London | J35: =(E35*2240)+(F35*112)+(G35*28)+H35 -> 0 | L35: =J35/2240 -> 0
A36: 1731 | B36: Madera Wine | C36: Nevis | D36: London | H36: 14894 | I36: 5t 3h 40g | J36: =(E36*2240)+(F36*112)+(G36*28)+H36 -> 14894 | L36: =J36/2240 -> 6.6491071
A37: 1731 | B37: Molasses | C37: Nevis | D37: London | F37: 7 | G37: 3 | J37: =(E37*2240)+(F37*112)+(G37*28)+H37 -> 868 | L37: =J37/2240 -> 0.3875
A38: 1731 | B38: Oranges | C38: Nevis | D38: London | J38: =(E38*2240)+(F38*112)+(G38*28)+H38 -> 0 | L38: =J38/2240 -> 0
A39: 1731 | B39: Orchelia | C39: Nevis | D39: London | J39: =(E39*2240)+(F39*112)+(G39*28)+H39 -> 0 | L39: =J39/2240 -> 0
A40: 1731 | B40: Pickles | C40: Nevis | D40: London | H40: 50 | I40: 5g | J40: =(E40*2240)+(F40*112)+(G40*28)+H40 -> 50 | L40: =J40/2240 -> 0.022321429
...

Sheet St Kitts
A1: YEAR | B1: COMMODITY_NAME | C1: FROM_LOCATION | D1: TO_LOCATION | E1: ton | F1: hh | G1: quarter | H1: lb | J1: Total Pounds | L1: WEIGHT
A2: 1731 | B2: Almonds, Bitter | C2: StKitts | D2: London | J2: =(E2*2240)+(F2*112)+(G2*28)+H2 -> 0 | L2: =J2/2240 -> 0
A3: 1731 | B3: Almonds, Sweet | C3: StKitts | D3: London | J3: =(E3*2240)+(F3*112)+(G3*28)+H3 -> 0 | L3: =J3/2240 -> 0
A4: 1731 | B4: Aloes Epatica | C4: StKitts | D4: London | J4: =(E4*2240)+(F4*112)+(G4*28)+H4 -> 0 | L4: =J4/2240 -> 0
A5: 1731 | B5: Annatto | C5: StKitts | D5: London | J5: =(E5*2240)+(F5*112)+(G5*28)+H5 -> 0 | L5: =J5/2240 -> 0
A6: 1731 | B6: Anniseeds | C6: StKitts | D6: London | J6: =(E6*2240)+(F6*112)+(G6*28)+H6 -> 0 | L6: =J6/2240 -> 0
A7: 1731 | B7: Bacon | C7: StKitts | D7: London | J7: =(E7*2240)+(F7*112)+(G7*28)+H7 -> 0 | L7: =J7/2240 -> 0
A8: 1731 | B8: Barrel Staves | C8: StKitts | D8: London | J8: =(E8*2240)+(F8*112)+(G8*28)+H8 -> 0 | L8: =J8/2240 -> 0
A9: 1731 | B9: Bay Berries | C9: StKitts | D9: London | J9: =(E9*2240)+(F9*112)+(G9*28)+H9 -> 0 | L9: =J9/2240 -> 0
A10: 1731 | B10: Bees Wax | C10: StKitts | D10: London | F10: 8 | G10: 1 | J10: =(E10*2240)+(F10*112)+(G10*28)+H10 -> 924 | L10: =J10/2240 -> 0.4125
A11: 1731 | B11: Brimstone | C11: StKitts | D11: London | J11: =(E11*2240)+(F11*112)+(G11*28)+H11 -> 0 | L11: =J11/2240 -> 0
A12: 1731 | B12: Brown Sugar | C12: StKitts | D12: London | F12: 150143 | G12: 1 | H12: 4 | J12: =(E12*2240)+(F12*112)+(G12*28)+H12 -> 16816048 | L12: =J12/2240 -> 7507.1643
A13: 1731 | B13: Cascarilla | C13: StKitts | D13: London | J13: =(E13*2240)+(F13*112)+(G13*28)+H13 -> 0 | L13: =J13/2240 -> 0
A14: 1731 | B14: Cassia Fistula | C14: StKitts | D14: London | H14: 620 | J14: =(E14*2240)+(F14*112)+(G14*28)+H14 -> 620 | L14: =J14/2240 -> 0.27678571
A15: 1731 | B15: Chocolate | C15: StKitts | D15: London | J15: =(E15*2240)+(F15*112)+(G15*28)+H15 -> 0 | L15: =J15/2240 -> 0
A16: 1731 | B16: Cocheneal | C16: StKitts | D16: London | J16: =(E16*2240)+(F16*112)+(G16*28)+H16 -> 0 | L16: =J16/2240 -> 0
A17: 1731 | B17: Cocoa Nuts | C17: StKitts | D17: London | J17: =(E17*2240)+(F17*112)+(G17*28)+H17 -> 0 | L17: =J17/2240 -> 0
A18: 1731 | B18: Cocoa Paste | C18: StKitts | D18: London | J18: =(E18*2240)+(F18*112)+(G18*28)+H18 -> 0 | L18: =J18/2240 -> 0
A19: 1731 | B19: Coffee | C19: StKitts | D19: London | J19: =(E19*2240)+(F19*112)+(G19*28)+H19 -> 0 | L19: =J19/2240 -> 0
A20: 1731 | B20: Cortex Peru | C20: StKitts | D20: London | J20: =(E20*2240)+(F20*112)+(G20*28)+H20 -> 0 | L20: =J20/2240 -> 0
A21: 1731 | B21: Cortex Winteranus | C21: StKitts | D21: London | J21: =(E21*2240)+(F21*112)+(G21*28)+H21 -> 0 | L21: =J21/2240 -> 0
A22: 1731 | B22: Cotton | C22: StKitts | D22: London | H22: =1091*200 -> 218200 | I22: 1091bags | J22: =(E22*2240)+(F22*112)+(G22*28)+H22 -> 218200 | L22: =J22/2240 -> 97.410714
A23: 1731 | B23: Dry Ginger | C23: StKitts | D23: London | J23: =(E23*2240)+(F23*112)+(G23*28)+H23 -> 0 | L23: =J23/2240 -> 0
A24: 1731 | B24: Elephant Teeth | C24: StKitts | D24: London | F24: 32 | G24: 2 | H24: 10 | J24: =(E24*2240)+(F24*112)+(G24*28)+H24 -> 3650 | L24: =J24/2240 -> 1.6294643
A25: 1731 | B25: Green Ginger | C25: StKitts | D25: London | H25: 33 | J25: =(E25*2240)+(F25*112)+(G25*28)+H25 -> 33 | L25: =J25/2240 -> 0.014732143
A26: 1731 | B26: Guinea Grains | C26: StKitts | D26: London | H26: 750 | J26: =(E26*2240)+(F26*112)+(G26*28)+H26 -> 750 | L26: =J26/2240 -> 0.33482143
A27: 1731 | B27: Gum Copal | C27: StKitts | D27: London | H27: 3101 | J27: =(E27*2240)+(F27*112)+(G27*28)+H27 -> 3101 | L27: =J27/2240 -> 1.384375
A28: 1731 | B28: Gum Guiaci | C28: StKitts | D28: London | H28: 269 | J28: =(E28*2240)+(F28*112)+(G28*28)+H28 -> 269 | L28: =J28/2240 -> 0.12008929
A29: 1731 | B29: Hemp | C29: StKitts | D29: London | J29: =(E29*2240)+(F29*112)+(G29*28)+H29 -> 0 | L29: =J29/2240 -> 0
A30: 1731 | B30: Hypococania | C30: StKitts | D30: London | J30: =(E30*2240)+(F30*112)+(G30*28)+H30 -> 0 | L30: =J30/2240 -> 0
A31: 1731 | B31: Indigo | C31: StKitts | D31: London | H31: 638 | J31: =(E31*2240)+(F31*112)+(G31*28)+H31 -> 638 | L31: =J31/2240 -> 0.28482143
A32: 1731 | B32: Jallop? | C32: StKitts | D32: London | J32: =(E32*2240)+(F32*112)+(G32*28)+H32 -> 0 | L32: =J32/2240 -> 0
A33: 1731 | B33: Lemon Water | C33: StKitts | D33: London | J33: =(E33*2240)+(F33*112)+(G33*28)+H33 -> 0 | L33: =J33/2240 -> 0
A34: 1731 | B34: Lignum Vitae | C34: StKitts | D34: London | E34: 7 | J34: =(E34*2240)+(F34*112)+(G34*28)+H34 -> 15680 | L34: =J34/2240 -> 7
A35: 1731 | B35: Lime Juice | C35: StKitts | D35: London | J35: =(E35*2240)+(F35*112)+(G35*28)+H35 -> 0 | L35: =J35/2240 -> 0
A36: 1731 | B36: Loaf Sugar | C36: StKitts | D36: London | J36: =(E36*2240)+(F36*112)+(G36*28)+H36 -> 0 | L36: =J36/2240 -> 0
A37: 1731 | B37: Madera Wine | C37: StKitts | D37: London | H37: 38440 | I37: 15t 1h | J37: =(E37*2240)+(F37*112)+(G37*28)+H37 -> 38440 | L37: =J37/2240 -> 17.160714
A38: 1731 | B38: Molasses | C38: StKitts | D38: London | F38: 1 | H38: 17 | J38: =(E38*2240)+(F38*112)+(G38*28)+H38 -> 129 | L38: =J38/2240 -> 0.057589286
A39: 1731 | B39: Oranges | C39: StKitts | D39: London | J39: =(E39*2240)+(F39*112)+(G39*28)+H39 -> 0 | L39: =J39/2240 -> 0
A40: 1731 | B40: Orchelia | C40: StKitts | D40: London | J40: =(E40*2240)+(F40*112)+(G40*28)+H40 -> 0 | L40: =J40/2240 -> 0
...

Sheet Tortola
A1: YEAR | B1: COMMODITY_NAME | C1: FROM_LOCATION | D1: TO_LOCATION | E1: ton | F1: hh | G1: quarter | H1: lb | J1: Total Pounds | L1: WEIGHT
B2: Almonds, Bitter | C2: Tortola | D2: London | J2: =(E2*2240)+(F2*112)+(G2*28)+H2 -> 0 | L2: =J2/2240 -> 0
B3: Almonds, Sweet | C3: Tortola | D3: London | J3: =(E3*2240)+(F3*112)+(G3*28)+H3 -> 0 | L3: =J3/2240 -> 0
B4: Aloes Epatica | C4: Tortola | D4: London | J4: =(E4*2240)+(F4*112)+(G4*28)+H4 -> 0 | L4: =J4/2240 -> 0
B5: Annatto | C5: Tortola | D5: London | J5: =(E5*2240)+(F5*112)+(G5*28)+H5 -> 0 | L5: =J5/2240 -> 0
B6: Anniseeds | C6: Tortola | D6: London | J6: =(E6*2240)+(F6*112)+(G6*28)+H6 -> 0 | L6: =J6/2240 -> 0
B7: Bacon | C7: Tortola | D7: London | J7: =(E7*2240)+(F7*112)+(G7*28)+H7 -> 0 | L7: =J7/2240 -> 0
B8: Barrel Staves | C8: Tortola | D8: London | J8: =(E8*2240)+(F8*112)+(G8*28)+H8 -> 0 | L8: =J8/2240 -> 0
B9: Bay Berries | C9: Tortola | D9: London | J9: =(E9*2240)+(F9*112)+(G9*28)+H9 -> 0 | L9: =J9/2240 -> 0
B10: Bees Wax | C10: Tortola | D10: London | J10: =(E10*2240)+(F10*112)+(G10*28)+H10 -> 0 | L10: =J10/2240 -> 0
B11: Brimstone | C11: Tortola | D11: London | J11: =(E11*2240)+(F11*112)+(G11*28)+H11 -> 0 | L11: =J11/2240 -> 0
B12: Brown Sugar | C12: Tortola | D12: London | J12: =(E12*2240)+(F12*112)+(G12*28)+H12 -> 0 | L12: =J12/2240 -> 0
B13: Cascarilla | C13: Tortola | D13: London | J13: =(E13*2240)+(F13*112)+(G13*28)+H13 -> 0 | L13: =J13/2240 -> 0
... B126: Wood, Sweetwood | C126: Tortola | D126: Out Ports | J126: =(E126*2240)+(F126*112)+(G126*28)+H126 -> 0 | L126: =J126/2240 -> 0

Sheet WestIndiesGeneral
A1: YEAR | B1: COMMODITY_NAME | C1: FROM_LOCATION | D1: TO_LOCATION | E1: ton | F1: hh | G1: quarter | H1: lb | J1: Total Pounds | L1: WEIGHT
A2: 1731 | B2: Almonds, Bitter | C2: WestIndiesGeneral | D2: London | J2: =(E2*2240)+(F2*112)+(G2*28)+H2 -> 0 | L2: =J2/2240 -> 0
A3: 1731 | B3: Almonds, Sweet | C3: WestIndiesGeneral | D3: London | J3: =(E3*2240)+(F3*112)+(G3*28)+H3 -> 0 | L3: =J3/2240 -> 0
A4: 1731 | B4: Aloes Epatica | C4: WestIndiesGeneral | D4: London | J4: =(E4*2240)+(F4*112)+(G4*28)+H4 -> 0 | L4: =J4/2240 -> 0
A5: 1731 | B5: Annatto | C5: WestIndiesGeneral | D5: London | J5: =(E5*2240)+(F5*112)+(G5*28)+H5 -> 0 | L5: =J5/2240 -> 0
A6: 1731 | B6: Anniseeds | C6: WestIndiesGeneral | D6: London | J6: =(E6*2240)+(F6*112)+(G6*28)+H6 -> 0 | L6: =J6/2240 -> 0
A7: 1731 | B7: Bacon | C7: WestIndiesGeneral | D7: London | J7: =(E7*2240)+(F7*112)+(G7*28)+H7 -> 0 | L7: =J7/2240 -> 0
A8: 1731 | B8: Balsam Natural | C8: WestIndiesGeneral | D8: London | H8: 250 | J8: =(E8*2240)+(F8*112)+(G8*28)+H8 -> 250 | L8: =J8/2240 -> 0.11160714
A9: 1731 | B9: Barrel Staves | C9: WestIndiesGeneral | D9: London | J9: =(E9*2240)+(F9*112)+(G9*28)+H9 -> 0 | L9: =J9/2240 -> 0
A10: 1731 | B10: Bay Berries | C10: WestIndiesGeneral | D10: London | J10: =(E10*2240)+(F10*112)+(G10*28)+H10 -> 0 | L10: =J10/2240 -> 0
A11: 1731 | B11: Beaver Skins | C11: WestIndiesGeneral | D11: London | J11: =(E11*2240)+(F11*112)+(G11*28)+H11 -> 0 | L11: =J11/2240 -> 0
A12: 1731 | B12: Bees Wax | C12: WestIndiesGeneral | D12: London | J12: =(E12*2240)+(F12*112)+(G12*28)+H12 -> 0 | L12: =J12/2240 -> 0
A13: 1731 | B13: Brimstone | C13: WestIndiesGeneral | D13: London | J13: =(E13*2240)+(F13*112)+(G13*28)+H13 -> 0 | L13: =J13/2240 -> 0
A14: 1731 | B14: Brown Sugar | C14: WestIndiesGeneral | D14: London | F14: 725 | G14: 2 | H14: 14 | J14: =(E14*2240)+(F14*112)+(G14*28)+H14 -> 81270 | L14: =J14/2240 -> 36.28125
A15: 1731 | B15: Cascarilla | C15: WestIndiesGeneral | D15: London | J15: =(E15*2240)+(F15*112)+(G15*28)+H15 -> 0 | L15: =J15/2240 -> 0
A16: 1731 | B16: Cassia Fistula | C16: WestIndiesGeneral | D16: London | J16: =(E16*2240)+(F16*112)+(G16*28)+H16 -> 0 | L16: =J16/2240 -> 0
A17: 1731 | B17: Chocolate | C17: WestIndiesGeneral | D17: London | J17: =(E17*2240)+(F17*112)+(G17*28)+H17 -> 0 | L17: =J17/2240 -> 0
A18: 1731 | B18: Cocheneal | C18: WestIndiesGeneral | D18: London | J18: =(E18*2240)+(F18*112)+(G18*28)+H18 -> 0 | L18: =J18/2240 -> 0
A19: 1731 | B19: Cocoa Nuts | C19: WestIndiesGeneral | D19: London | J19: =(E19*2240)+(F19*112)+(G19*28)+H19 -> 0 | L19: =J19/2240 -> 0
A20: 1731 | B20: Cocoa Paste | C20: WestIndiesGeneral | D20: London | J20: =(E20*2240)+(F20*112)+(G20*28)+H20 -> 0 | L20: =J20/2240 -> 0
A21: 1731 | B21: Coffee | C21: WestIndiesGeneral | D21: London | J21: =(E21*2240)+(F21*112)+(G21*28)+H21 -> 0 | L21: =J21/2240 -> 0
A22: 1731 | B22: Cortex Peru | C22: WestIndiesGeneral | D22: London | J22: =(E22*2240)+(F22*112)+(G22*28)+H22 -> 0 | L22: =J22/2240 -> 0
A23: 1731 | B23: Cortex Winteranus | C23: WestIndiesGeneral | D23: London | J23: =(E23*2240)+(F23*112)+(G23*28)+H23 -> 0 | L23: =J23/2240 -> 0
A24: 1731 | B24: Cotton | C24: WestIndiesGeneral | D24: London | J24: =(E24*2240)+(F24*112)+(G24*28)+H24 -> 0 | L24: =J24/2240 -> 0
A25: 1731 | B25: Dry Ginger | C25: WestIndiesGeneral | D25: London | J25: =(E25*2240)+(F25*112)+(G25*28)+H25 -> 0 | L25: =J25/2240 -> 0
A26: 1731 | B26: Elephant Teeth | C26: WestIndiesGeneral | D26: London | J26: =(E26*2240)+(F26*112)+(G26*28)+H26 -> 0 | L26: =J26/2240 -> 0
... A28: 1731 | B28: Guinea Grains | C28: WestIndiesGeneral | D28: London | J28: =(E28*2240)+(F28*112)+(G28*28)+H28 -> 0 | L28: =J28/2240 -> 0
A29: 1731 | B29: Gum Elemni | C29: WestIndiesGeneral | D29: London | H29: 1400 | J29: =(E29*2240)+(F29*112)+(G29*28)+H29 -> 1400 | L29: =J29/2240 -> 0.625
A30: 1731 | B30: Hemp | C30: WestIndiesGeneral | D30: London | J30: =(E30*2240)+(F30*112)+(G30*28)+H30 -> 0 | L30: =J30/2240 -> 0
A31: 1731 | B31: Hypococania | C31: WestIndiesGeneral | D31: London | J31: =(E31*2240)+(F31*112)+(G31*28)+H31 -> 0 | L31: =J31/2240 -> 0
A32: 1731 | B32: Indigo | C32: WestIndiesGeneral | D32: London | J32: =(E32*2240)+(F32*112)+(G32*28)+H32 -> 0 | L32: =J32/2240 -> 0
A33: 1731 | B33: Jallop? | C33: WestIndiesGeneral | D33: London | J33: =(E33*2240)+(F33*112)+(G33*28)+H33 -> 0 | L33: =J33/2240 -> 0
A34: 1731 | B34: Lemon Water | C34: WestIndiesGeneral | D34: London | J34: =(E34*2240)+(F34*112)+(G34*28)+H34 -> 0 | L34: =J34/2240 -> 0
A35: 1731 | B35: Lignum Vitae | C35: WestIndiesGeneral | D35: London | J35: =(E35*2240)+(F35*112)+(G35*28)+H35 -> 0 | L35: =J35/2240 -> 0
A36: 1731 | B36: Lime Juice | C36: WestIndiesGeneral | D36: London | J36: =(E36*2240)+(F36*112)+(G36*28)+H36 -> 0 | L36: =J36/2240 -> 0
A37: 1731 | B37: Loaf Sugar | C37: WestIndiesGeneral | D37: London | J37: =(E37*2240)+(F37*112)+(G37*28)+H37 -> 0 | L37: =J37/2240 -> 0
A38: 1731 | B38: Madera Wine | C38: WestIndiesGeneral | D38: London | H38: 1000.5 | I38: 1h 37g | J38: =(E38*2240)+(F38*112)+(G38*28)+H38 -> 1000.5 | L38: =J38/2240 -> 0.44665179
A39: 1731 | B39: Molasses | C39: WestIndiesGeneral | D39: London | J39: =(E39*2240)+(F39*112)+(G39*28)+H39 -> 0 | L39: =J39/2240 -> 0
A40: 1731 | B40: Oranges | C40: WestIndiesGeneral | D40: London | J40: =(E40*2240)+(F40*112)+(G40*28)+H40 -> 0 | L40: =J40/2240 -> 0
A41: 1731 | B41: Orchelia | C41: WestIndiesGeneral | D41: London | J41: =(E41*2240)+(F41*112)+(G41*28)+H41 -> 0 | L41: =J41/2240 -> 0
...
