Workbook

Sheet Master Goods Sheet
A1: Item | B1: Total London | C1: Total Outports | D1: Total
A2: Annatto | B2: =SUMIFS(Antigua!$L:$L, Antigua!$B:$B, $A2, Antigua!$D:$D, "London") + SUMIFS(Barbados!$L:$L, Barbados!$B:$B, $A2, Barbados!$D:$D, "London") + SUMIFS(Bermuda!$L:$L, Bermuda!$B:$B, $A2, Bermuda!$D:$D, "London") + SUMIFS(Jamaica!$L:$L, Jamaica!$B:$B, $A2, Jamaica!$D:$D, "London") + SUMIFS(Mountserat!$L:$L, Mountserat!$B:$B, $A2, Mountserat!$D:$D, "London") + SUMIFS(Nevis!$L:$L, Nevis!$B:$B, $A2, Nevis!$D:$D, "London") + SUMIFS('St Kitts'!$L:$L, 'St Kitts'!$B:$B, $A2, 'St Kitts'!$D:$D, "London") -> 0.17857143 | C2: =SUMIFS(Antigua!$L:$L, Antigua!$B:$B, $A2, Antigua!$D:$D, "Out Ports") + SUMIFS(Barbados!$L:$L, Barbados!$B:$B, $A2, Barbados!$D:$D, "Out Ports") + SUMIFS(Bermuda!$L:$L, Bermuda!$B:$B, $A2, Bermuda!$D:$D, "Out Ports") + SUMIFS(Jamaica!$L:$L, Jamaica!$B:$B, $A2, Jamaica!$D:$D, "Out Ports") + SUMIFS(Mountserat!$L:$L, Mountserat!$B:$B, $A2, Mountserat!$D:$D, "Out Ports") + SUMIFS(Nevis!$L:$L, Nevis!$B:$B, $A2, Nevis!$D:$D, "Out Ports") + SUMIFS('St Kitts'!$L:$L, 'St Kitts'!$B:$B, $A2, 'St Kitts'!$D:$D, "Out Ports") -> 0 | D2: =B2+C2 -> 0.17857143
A3: Bees Wax | B3: =SUMIFS(Antigua!$L:$L, Antigua!$B:$B, $A3, Antigua!$D:$D, "London") + SUMIFS(Barbados!$L:$L, Barbados!$B:$B, $A3, Barbados!$D:$D, "London") + SUMIFS(Bermuda!$L:$L, Bermuda!$B:$B, $A3, Bermuda!$D:$D, "London") + SUMIFS(Jamaica!$L:$L, Jamaica!$B:$B, $A3, Jamaica!$D:$D, "London") + SUMIFS(Mountserat!$L:$L, Mountserat!$B:$B, $A3, Mountserat!$D:$D, "London") + SUMIFS(Nevis!$L:$L, Nevis!$B:$B, $A3, Nevis!$D:$D, "London") + SUMIFS('St Kitts'!$L:$L, 'St Kitts'!$B:$B, $A3, 'St Kitts'!$D:$D, "London") -> 0.640625 | C3: =SUMIFS(Antigua!$L:$L, Antigua!$B:$B, $A3, Antigua!$D:$D, "Out Ports") + SUMIFS(Barbados!$L:$L, Barbados!$B:$B, $A3, Barbados!$D:$D, "Out Ports") + SUMIFS(Bermuda!$L:$L, Bermuda!$B:$B, $A3, Bermuda!$D:$D, "Out Ports") + SUMIFS(Jamaica!$L:$L, Jamaica!$B:$B, $A3, Jamaica!$D:$D, "Out Ports") + SUMIFS(Mountserat!$L:$L, Mountserat!$B:$B, $A3, Mountserat!$D:$D, "Out Ports") + SUMIFS(Nevis!$L:$L, Nevis!$B:$B, $A3, Nevis!$D:$D, "Out Ports") + SUMIFS('St Kitts'!$L:$L, 'St Kitts'!$B:$B, $A3, 'St Kitts'!$D:$D, "Out Ports") -> 0 | D3: =B3+C3 -> 0.640625
A4: Brown Sugar | B4: =SUMIFS(Antigua!$L:$L, Antigua!$B:$B, $A4, Antigua!$D:$D, "London") + SUMIFS(Barbados!$L:$L, Barbados!$B:$B, $A4, Barbados!$D:$D, "London") + SUMIFS(Bermuda!$L:$L, Bermuda!$B:$B, $A4, Bermuda!$D:$D, "London") + SUMIFS(Jamaica!$L:$L, Jamaica!$B:$B, $A4, Jamaica!$D:$D, "London") + SUMIFS(Mountserat!$L:$L, Mountserat!$B:$B, $A4, Mountserat!$D:$D, "London") + SUMIFS(Nevis!$L:$L, Nevis!$B:$B, $A4, Nevis!$D:$D, "London") + SUMIFS('St Kitts'!$L:$L, 'St Kitts'!$B:$B, $A4, 'St Kitts'!$D:$D, "London") -> 33616.271 | C4: =SUMIFS(Antigua!$L:$L, Antigua!$B:$B, $A4, Antigua!$D:$D, "Out Ports") + SUMIFS(Barbados!$L:$L, Barbados!$B:$B, $A4, Barbados!$D:$D, "Out Ports") + SUMIFS(Bermuda!$L:$L, Bermuda!$B:$B, $A4, Bermuda!$D:$D, "Out Ports") + SUMIFS(Jamaica!$L:$L, Jamaica!$B:$B, $A4, Jamaica!$D:$D, "Out Ports") + SUMIFS(Mountserat!$L:$L, Mountserat!$B:$B, $A4, Mountserat!$D:$D, "Out Ports") + SUMIFS(Nevis!$L:$L, Nevis!$B:$B, $A4, Nevis!$D:$D, "Out Ports") + SUMIFS('St Kitts'!$L:$L, 'St Kitts'!$B:$B, $A4, 'St Kitts'!$D:$D, "Out Ports") -> 10648.371 | D4: =B4+C4 -> 44264.642
A5: Chocolate | B5: =SUMIFS(Antigua!$L:$L, Antigua!$B:$B, $A5, Antigua!$D:$D, "London") + SUMIFS(Barbados!$L:$L, Barbados!$B:$B, $A5, Barbados!$D:$D, "London") + SUMIFS(Bermuda!$L:$L, Bermuda!$B:$B, $A5, Bermuda!$D:$D, "London") + SUMIFS(Jamaica!$L:$L, Jamaica!$B:$B, $A5, Jamaica!$D:$D, "London") + SUMIFS(Mountserat!$L:$L, Mountserat!$B:$B, $A5, Mountserat!$D:$D, "London") + SUMIFS(Nevis!$L:$L, Nevis!$B:$B, $A5, Nevis!$D:$D, "London") + SUMIFS('St Kitts'!$L:$L, 'St Kitts'!$B:$B, $A5, 'St Kitts'!$D:$D, "London") -> 0 | C5: =SUMIFS(Antigua!$L:$L, Antigua!$B:$B, $A5, Antigua!$D:$D, "Out Ports") + SUMIFS(Barbados!$L:$L, Barbados!$B:$B, $A5, Barbados!$D:$D, "Out Ports") + SUMIFS(Bermuda!$L:$L, Bermuda!$B:$B, $A5, Bermuda!$D:$D, "Out Ports") + SUMIFS(Jamaica!$L:$L, Jamaica!$B:$B, $A5, Jamaica!$D:$D, "Out Ports") + SUMIFS(Mountserat!$L:$L, Mountserat!$B:$B, $A5, Mountserat!$D:$D, "Out Ports") + SUMIFS(Nevis!$L:$L, Nevis!$B:$B, $A5, Nevis!$D:$D, "Out Ports") + SUMIFS('St Kitts'!$L:$L, 'St Kitts'!$B:$B, $A5, 'St Kitts'!$D:$D, "Out Ports") -> 0 | D5: =B5+C5 -> 0
A6: Cocoa Nuts | B6: =SUMIFS(Antigua!$L:$L, Antigua!$B:$B, $A6, Antigua!$D:$D, "London") + SUMIFS(Barbados!$L:$L, Barbados!$B:$B, $A6, Barbados!$D:$D, "London") + SUMIFS(Bermuda!$L:$L, Bermuda!$B:$B, $A6, Bermuda!$D:$D, "London") + SUMIFS(Jamaica!$L:$L, Jamaica!$B:$B, $A6, Jamaica!$D:$D, "London") + SUMIFS(Mountserat!$L:$L, Mountserat!$B:$B, $A6, Mountserat!$D:$D, "London") + SUMIFS(Nevis!$L:$L, Nevis!$B:$B, $A6, Nevis!$D:$D, "London") + SUMIFS('St Kitts'!$L:$L, 'St Kitts'!$B:$B, $A6, 'St Kitts'!$D:$D, "London") -> 47.616964 | C6: =SUMIFS(Antigua!$L:$L, Antigua!$B:$B, $A6, Antigua!$D:$D, "Out Ports") + SUMIFS(Barbados!$L:$L, Barbados!$B:$B, $A6, Barbados!$D:$D, "Out Ports") + SUMIFS(Bermuda!$L:$L, Bermuda!$B:$B, $A6, Bermuda!$D:$D, "Out Ports") + SUMIFS(Jamaica!$L:$L, Jamaica!$B:$B, $A6, Jamaica!$D:$D, "Out Ports") + SUMIFS(Mountserat!$L:$L, Mountserat!$B:$B, $A6, Mountserat!$D:$D, "Out Ports") + SUMIFS(Nevis!$L:$L, Nevis!$B:$B, $A6, Nevis!$D:$D, "Out Ports") + SUMIFS('St Kitts'!$L:$L, 'St Kitts'!$B:$B, $A6, 'St Kitts'!$D:$D, "Out Ports") -> 2.7294643 | D6: =B6+C6 -> 50.346429
A7: Cotton | B7: =SUMIFS(Antigua!$L:$L, Antigua!$B:$B, $A7, Antigua!$D:$D, "London") + SUMIFS(Barbados!$L:$L, Barbados!$B:$B, $A7, Barbados!$D:$D, "London") + SUMIFS(Bermuda!$L:$L, Bermuda!$B:$B, $A7, Bermuda!$D:$D, "London") + SUMIFS(Jamaica!$L:$L, Jamaica!$B:$B, $A7, Jamaica!$D:$D, "London") + SUMIFS(Mountserat!$L:$L, Mountserat!$B:$B, $A7, Mountserat!$D:$D, "London") + SUMIFS(Nevis!$L:$L, Nevis!$B:$B, $A7, Nevis!$D:$D, "London") + SUMIFS('St Kitts'!$L:$L, 'St Kitts'!$B:$B, $A7, 'St Kitts'!$D:$D, "London") -> 246.03482 | C7: =SUMIFS(Antigua!$L:$L, Antigua!$B:$B, $A7, Antigua!$D:$D, "Out Ports") + SUMIFS(Barbados!$L:$L, Barbados!$B:$B, $A7, Barbados!$D:$D, "Out Ports") + SUMIFS(Bermuda!$L:$L, Bermuda!$B:$B, $A7, Bermuda!$D:$D, "Out Ports") + SUMIFS(Jamaica!$L:$L, Jamaica!$B:$B, $A7, Jamaica!$D:$D, "Out Ports") + SUMIFS(Mountserat!$L:$L, Mountserat!$B:$B, $A7, Mountserat!$D:$D, "Out Ports") + SUMIFS(Nevis!$L:$L, Nevis!$B:$B, $A7, Nevis!$D:$D, "Out Ports") + SUMIFS('St Kitts'!$L:$L, 'St Kitts'!$B:$B, $A7, 'St Kitts'!$D:$D, "Out Ports") -> 419.10714 | D7: =B7+C7 -> 665.14196
A8: Dry Ginger | B8: =SUMIFS(Antigua!$L:$L, Antigua!$B:$B, $A8, Antigua!$D:$D, "London") + SUMIFS(Barbados!$L:$L, Barbados!$B:$B, $A8, Barbados!$D:$D, "London") + SUMIFS(Bermuda!$L:$L, Bermuda!$B:$B, $A8, Bermuda!$D:$D, "London") + SUMIFS(Jamaica!$L:$L, Jamaica!$B:$B, $A8, Jamaica!$D:$D, "London") + SUMIFS(Mountserat!$L:$L, Mountserat!$B:$B, $A8, Mountserat!$D:$D, "London") + SUMIFS(Nevis!$L:$L, Nevis!$B:$B, $A8, Nevis!$D:$D, "London") + SUMIFS('St Kitts'!$L:$L, 'St Kitts'!$B:$B, $A8, 'St Kitts'!$D:$D, "London") -> 1639.3379 | C8: =SUMIFS(Antigua!$L:$L, Antigua!$B:$B, $A8, Antigua!$D:$D, "Out Ports") + SUMIFS(Barbados!$L:$L, Barbados!$B:$B, $A8, Barbados!$D:$D, "Out Ports") + SUMIFS(Bermuda!$L:$L, Bermuda!$B:$B, $A8, Bermuda!$D:$D, "Out Ports") + SUMIFS(Jamaica!$L:$L, Jamaica!$B:$B, $A8, Jamaica!$D:$D, "Out Ports") + SUMIFS(Mountserat!$L:$L, Mountserat!$B:$B, $A8, Mountserat!$D:$D, "Out Ports") + SUMIFS(Nevis!$L:$L, Nevis!$B:$B, $A8, Nevis!$D:$D, "Out Ports") + SUMIFS('St Kitts'!$L:$L, 'St Kitts'!$B:$B, $A8, 'St Kitts'!$D:$D, "Out Ports") -> 539.2192 | D8: =B8+C8 -> 2178.5571
A9: Elephant Teeth | B9: =SUMIFS(Antigua!$L:$L, Antigua!$B:$B, $A9, Antigua!$D:$D, "London") + SUMIFS(Barbados!$L:$L, Barbados!$B:$B, $A9, Barbados!$D:$D, "London") + SUMIFS(Bermuda!$L:$L, Bermuda!$B:$B, $A9, Bermuda!$D:$D, "London") + SUMIFS(Jamaica!$L:$L, Jamaica!$B:$B, $A9, Jamaica!$D:$D, "London") + SUMIFS(Mountserat!$L:$L, Mountserat!$B:$B, $A9, Mountserat!$D:$D, "London") + SUMIFS(Nevis!$L:$L, Nevis!$B:$B, $A9, Nevis!$D:$D, "London") + SUMIFS('St Kitts'!$L:$L, 'St Kitts'!$B:$B, $A9, 'St Kitts'!$D:$D, "London") -> 32.537054 | C9: =SUMIFS(Antigua!$L:$L, Antigua!$B:$B, $A9, Antigua!$D:$D, "Out Ports") + SUMIFS(Barbados!$L:$L, Barbados!$B:$B, $A9, Barbados!$D:$D, "Out Ports") + SUMIFS(Bermuda!$L:$L, Bermuda!$B:$B, $A9, Bermuda!$D:$D, "Out Ports") + SUMIFS(Jamaica!$L:$L, Jamaica!$B:$B, $A9, Jamaica!$D:$D, "Out Ports") + SUMIFS(Mountserat!$L:$L, Mountserat!$B:$B, $A9, Mountserat!$D:$D, "Out Ports") + SUMIFS(Nevis!$L:$L, Nevis!$B:$B, $A9, Nevis!$D:$D, "Out Ports") + SUMIFS('St Kitts'!$L:$L, 'St Kitts'!$B:$B, $A9, 'St Kitts'!$D:$D, "Out Ports") -> 20.84375 | D9: =B9+C9 -> 53.380804
A10: Indigo | B10: =SUMIFS(Antigua!$L:$L, Antigua!$B:$B, $A10, Antigua!$D:$D, "London") + SUMIFS(Barbados!$L:$L, Barbados!$B:$B, $A10, Barbados!$D:$D, "London") + SUMIFS(Bermuda!$L:$L, Bermuda!$B:$B, $A10, Bermuda!$D:$D, "London") + SUMIFS(Jamaica!$L:$L, Jamaica!$B:$B, $A10, Jamaica!$D:$D, "London") + SUMIFS(Mountserat!$L:$L, Mountserat!$B:$B, $A10, Mountserat!$D:$D, "London") + SUMIFS(Nevis!$L:$L, Nevis!$B:$B, $A10, Nevis!$D:$D, "London") + SUMIFS('St Kitts'!$L:$L, 'St Kitts'!$B:$B, $A10, 'St Kitts'!$D:$D, "London") -> 47.150893 | C10: =SUMIFS(Antigua!$L:$L, Antigua!$B:$B, $A10, Antigua!$D:$D, "Out Ports") + SUMIFS(Barbados!$L:$L, Barbados!$B:$B, $A10, Barbados!$D:$D, "Out Ports") + SUMIFS(Bermuda!$L:$L, Bermuda!$B:$B, $A10, Bermuda!$D:$D, "Out Ports") + SUMIFS(Jamaica!$L:$L, Jamaica!$B:$B, $A10, Jamaica!$D:$D, "Out Ports") + SUMIFS(Mountserat!$L:$L, Mountserat!$B:$B, $A10, Mountserat!$D:$D, "Out Ports") + SUMIFS(Nevis!$L:$L, Nevis!$B:$B, $A10, Nevis!$D:$D, "Out Ports") + SUMIFS('St Kitts'!$L:$L, 'St Kitts'!$B:$B, $A10, 'St Kitts'!$D:$D, "Out Ports") -> 12.453571 | D10: =B10+C10 -> 59.604464
A11: Lignum Vitae | B11: =SUMIFS(Antigua!$L:$L, Antigua!$B:$B, $A11, Antigua!$D:$D, "London") + SUMIFS(Barbados!$L:$L, Barbados!$B:$B, $A11, Barbados!$D:$D, "London") + SUMIFS(Bermuda!$L:$L, Bermuda!$B:$B, $A11, Bermuda!$D:$D, "London") + SUMIFS(Jamaica!$L:$L, Jamaica!$B:$B, $A11, Jamaica!$D:$D, "London") + SUMIFS(Mountserat!$L:$L, Mountserat!$B:$B, $A11, Mountserat!$D:$D, "London") + SUMIFS(Nevis!$L:$L, Nevis!$B:$B, $A11, Nevis!$D:$D, "London") + SUMIFS('St Kitts'!$L:$L, 'St Kitts'!$B:$B, $A11, 'St Kitts'!$D:$D, "London") -> 159.4125 | C11: =SUMIFS(Antigua!$L:$L, Antigua!$B:$B, $A11, Antigua!$D:$D, "Out Ports") + SUMIFS(Barbados!$L:$L, Barbados!$B:$B, $A11, Barbados!$D:$D, "Out Ports") + SUMIFS(Bermuda!$L:$L, Bermuda!$B:$B, $A11, Bermuda!$D:$D, "Out Ports") + SUMIFS(Jamaica!$L:$L, Jamaica!$B:$B, $A11, Jamaica!$D:$D, "Out Ports") + SUMIFS(Mountserat!$L:$L, Mountserat!$B:$B, $A11, Mountserat!$D:$D, "Out Ports") + SUMIFS(Nevis!$L:$L, Nevis!$B:$B, $A11, Nevis!$D:$D, "Out Ports") + SUMIFS('St Kitts'!$L:$L, 'St Kitts'!$B:$B, $A11, 'St Kitts'!$D:$D, "Out Ports") -> 44.408929 | D11: =B11+C11 -> 203.82143
A12: Lime Juice | B12: =SUMIFS(Antigua!$L:$L, Antigua!$B:$B, $A12, Antigua!$D:$D, "London") + SUMIFS(Barbados!$L:$L, Barbados!$B:$B, $A12, Barbados!$D:$D, "London") + SUMIFS(Bermuda!$L:$L, Bermuda!$B:$B, $A12, Bermuda!$D:$D, "London") + SUMIFS(Jamaica!$L:$L, Jamaica!$B:$B, $A12, Jamaica!$D:$D, "London") + SUMIFS(Mountserat!$L:$L, Mountserat!$B:$B, $A12, Mountserat!$D:$D, "London") + SUMIFS(Nevis!$L:$L, Nevis!$B:$B, $A12, Nevis!$D:$D, "London") + SUMIFS('St Kitts'!$L:$L, 'St Kitts'!$B:$B, $A12, 'St Kitts'!$D:$D, "London") -> 41.813839 | C12: =SUMIFS(Antigua!$L:$L, Antigua!$B:$B, $A12, Antigua!$D:$D, "Out Ports") + SUMIFS(Barbados!$L:$L, Barbados!$B:$B, $A12, Barbados!$D:$D, "Out Ports") + SUMIFS(Bermuda!$L:$L, Bermuda!$B:$B, $A12, Bermuda!$D:$D, "Out Ports") + SUMIFS(Jamaica!$L:$L, Jamaica!$B:$B, $A12, Jamaica!$D:$D, "Out Ports") + SUMIFS(Mountserat!$L:$L, Mountserat!$B:$B, $A12, Mountserat!$D:$D, "Out Ports") + SUMIFS(Nevis!$L:$L, Nevis!$B:$B, $A12, Nevis!$D:$D, "Out Ports") + SUMIFS('St Kitts'!$L:$L, 'St Kitts'!$B:$B, $A12, 'St Kitts'!$D:$D, "Out Ports") -> 11.80625 | D12: =B12+C12 -> 53.620089
A13: Molasses | B13: =SUMIFS(Antigua!$L:$L, Antigua!$B:$B, $A13, Antigua!$D:$D, "London") + SUMIFS(Barbados!$L:$L, Barbados!$B:$B, $A13, Barbados!$D:$D, "London") + SUMIFS(Bermuda!$L:$L, Bermuda!$B:$B, $A13, Bermuda!$D:$D, "London") + SUMIFS(Jamaica!$L:$L, Jamaica!$B:$B, $A13, Jamaica!$D:$D, "London") + SUMIFS(Mountserat!$L:$L, Mountserat!$B:$B, $A13, Mountserat!$D:$D, "London") + SUMIFS(Nevis!$L:$L, Nevis!$B:$B, $A13, Nevis!$D:$D, "London") + SUMIFS('St Kitts'!$L:$L, 'St Kitts'!$B:$B, $A13, 'St Kitts'!$D:$D, "London") -> 0.7625 | C13: =SUMIFS(Antigua!$L:$L, Antigua!$B:$B, $A13, Antigua!$D:$D, "Out Ports") + SUMIFS(Barbados!$L:$L, Barbados!$B:$B, $A13, Barbados!$D:$D, "Out Ports") + SUMIFS(Bermuda!$L:$L, Bermuda!$B:$B, $A13, Bermuda!$D:$D, "Out Ports") + SUMIFS(Jamaica!$L:$L, Jamaica!$B:$B, $A13, Jamaica!$D:$D, "Out Ports") + SUMIFS(Mountserat!$L:$L, Mountserat!$B:$B, $A13, Mountserat!$D:$D, "Out Ports") + SUMIFS(Nevis!$L:$L, Nevis!$B:$B, $A13, Nevis!$D:$D, "Out Ports") + SUMIFS('St Kitts'!$L:$L, 'St Kitts'!$B:$B, $A13, 'St Kitts'!$D:$D, "Out Ports") -> 0.75 | D13: =B13+C13 -> 1.5125
... A31: Wood, Sweetwood | B31: =SUMIFS(Antigua!$L:$L, Antigua!$B:$B, $A31, Antigua!$D:$D, "London") + SUMIFS(Barbados!$L:$L, Barbados!$B:$B, $A31, Barbados!$D:$D, "London") + SUMIFS(Bermuda!$L:$L, Bermuda!$B:$B, $A31, Bermuda!$D:$D, "London") + SUMIFS(Jamaica!$L:$L, Jamaica!$B:$B, $A31, Jamaica!$D:$D, "London") + SUMIFS(Mountserat!$L:$L, Mountserat!$B:$B, $A31, Mountserat!$D:$D, "London") + SUMIFS(Nevis!$L:$L, Nevis!$B:$B, $A31, Nevis!$D:$D, "London") + SUMIFS('St Kitts'!$L:$L, 'St Kitts'!$B:$B, $A31, 'St Kitts'!$D:$D, "London") -> 0 | C31: =SUMIFS(Antigua!$L:$L, Antigua!$B:$B, $A31, Antigua!$D:$D, "Out Ports") + SUMIFS(Barbados!$L:$L, Barbados!$B:$B, $A31, Barbados!$D:$D, "Out Ports") + SUMIFS(Bermuda!$L:$L, Bermuda!$B:$B, $A31, Bermuda!$D:$D, "Out Ports") + SUMIFS(Jamaica!$L:$L, Jamaica!$B:$B, $A31, Jamaica!$D:$D, "Out Ports") + SUMIFS(Mountserat!$L:$L, Mountserat!$B:$B, $A31, Mountserat!$D:$D, "Out Ports") + SUMIFS(Nevis!$L:$L, Nevis!$B:$B, $A31, Nevis!$D:$D, "Out Ports") + SUMIFS('St Kitts'!$L:$L, 'St Kitts'!$B:$B, $A31, 'St Kitts'!$D:$D, "Out Ports") -> 0 | D31: =B31+C31 -> 0

Sheet Anguilla
A1: YEAR | B1: COMMODITY_NAME | C1: FROM_LOCATION | D1: TO_LOCATION | E1: ton | F1: hh | G1: quarter | H1: lb | J1: Total Pounds | L1: WEIGHT
B2: Almonds, Bitter | C2: Anguilla | D2: London
B3: Almonds, Sweet | C3: Anguilla | D3: London
B4: Aloes Epatica | C4: Anguilla | D4: London
B5: Annatto | C5: Anguilla | D5: London
B6: Anniseeds | C6: Anguilla | D6: London
B7: Bacon | C7: Anguilla | D7: London
B8: Barrel Staves | C8: Anguilla | D8: London
B9: Bay Berries | C9: Anguilla | D9: London
B10: Bees Wax | C10: Anguilla | D10: London
B11: Brimstone | C11: Anguilla | D11: London
B12: Brown Sugar | C12: Anguilla | D12: London
B13: Cassia Fistula | C13: Anguilla | D13: London
... B88: Wood, Redwood | C88: Anguilla | D88: Out Ports

Sheet Antigua
A1: YEAR | B1: COMMODITY_NAME | C1: FROM_LOCATION | D1: TO_LOCATION | E1: ton | F1: hh | G1: quarter | H1: lb | J1: Total Pounds | L1: WEIGHT
A2: 1735 | B2: Aloes Epatica | C2: Antigua | D2: London | J2: =(E2*2240)+(F2*112)+(G2*28)+H2 -> 0 | L2: =J2/2240 -> 0
A3: 1735 | B3: Annatto | C3: Antigua | D3: London | J3: =(E3*2240)+(F3*112)+(G3*28)+H3 -> 0 | L3: =J3/2240 -> 0
A4: 1735 | B4: Bees Wax | C4: Antigua | D4: London | J4: =(E4*2240)+(F4*112)+(G4*28)+H4 -> 0 | L4: =J4/2240 -> 0
A5: 1735 | B5: Brown Sugar | C5: Antigua | D5: London | F5: 147162 | G5: 2 | H5: 4 | J5: =(E5*2240)+(F5*112)+(G5*28)+H5 -> 16482204 | L5: =J5/2240 -> 7358.1268
A6: 1735 | B6: Chocolate | C6: Antigua | D6: London | J6: =(E6*2240)+(F6*112)+(G6*28)+H6 -> 0 | L6: =J6/2240 -> 0
A7: 1735 | B7: Cocoa Nuts | C7: Antigua | D7: London | J7: =(E7*2240)+(F7*112)+(G7*28)+H7 -> 0 | L7: =J7/2240 -> 0
A8: 1735 | B8: Coffee | C8: Antigua | D8: London | F8: 8 | G8: 3 | J8: =(E8*2240)+(F8*112)+(G8*28)+H8 -> 980 | L8: =J8/2240 -> 0.4375
A9: 1735 | B9: Cortex Winteranus | C9: Antigua | D9: London | J9: =(E9*2240)+(F9*112)+(G9*28)+H9 -> 0 | L9: =J9/2240 -> 0
A10: 1735 | B10: Cotton | C10: Antigua | D10: London | F10: 31 | H10: =200*445 -> 89000 | I10: 445bags | J10: =(E10*2240)+(F10*112)+(G10*28)+H10 -> 92472 | L10: =J10/2240 -> 41.282143
A11: 1735 | B11: Dry Ginger | C11: Antigua | D11: London | F11: 2973 | H11: 26 | J11: =(E11*2240)+(F11*112)+(G11*28)+H11 -> 333002 | L11: =J11/2240 -> 148.66161
A12: 1735 | B12: Elephant Teeth | C12: Antigua | D12: London | F12: 93 | H12: 15 | J12: =(E12*2240)+(F12*112)+(G12*28)+H12 -> 10431 | L12: =J12/2240 -> 4.6566964
A13: 1735 | B13: Green Ginger | C13: Antigua | D13: London | J13: =(E13*2240)+(F13*112)+(G13*28)+H13 -> 0 | L13: =J13/2240 -> 0
A14: 1735 | B14: Guinea Grains | C14: Antigua | D14: London | F14: 60 | G14: 1 | H14: 17 | J14: =(E14*2240)+(F14*112)+(G14*28)+H14 -> 6765 | L14: =J14/2240 -> 3.0200893
A15: 1735 | B15: Indigo | C15: Antigua | D15: London | J15: =(E15*2240)+(F15*112)+(G15*28)+H15 -> 0 | L15: =J15/2240 -> 0
A16: 1735 | B16: Lemon Water | C16: Antigua | D16: London | J16: =(E16*2240)+(F16*112)+(G16*28)+H16 -> 0 | L16: =J16/2240 -> 0
A17: 1735 | B17: Lignum Vitae | C17: Antigua | D17: London | E17: 10 | F17: 13 | G17: 1 | J17: =(E17*2240)+(F17*112)+(G17*28)+H17 -> 23884 | L17: =J17/2240 -> 10.6625
A18: 1735 | B18: Lime Juice | C18: Antigua | D18: London | J18: =(E18*2240)+(F18*112)+(G18*28)+H18 -> 0 | L18: =J18/2240 -> 0
A19: 1735 | B19: Madera Wine | C19: Antigua | D19: London | H19: 356161 | I19: 141t 1h 12g | J19: =(E19*2240)+(F19*112)+(G19*28)+H19 -> 356161 | L19: =J19/2240 -> 159.00045
A20: 1735 | B20: Molasses | C20: Antigua | D20: London | J20: =(E20*2240)+(F20*112)+(G20*28)+H20 -> 0 | L20: =J20/2240 -> 0
A21: 1735 | B21: Pickles | C21: Antigua | D21: London | H21: 150 | I21: 15g | J21: =(E21*2240)+(F21*112)+(G21*28)+H21 -> 150 | L21: =J21/2240 -> 0.066964286
A22: 1735 | B22: Port | C22: Antigua | D22: London | H22: 72389 | I22: 28t 2h 55g | J22: =(E22*2240)+(F22*112)+(G22*28)+H22 -> 72389 | L22: =J22/2240 -> 32.316518
A23: 1735 | B23: Rice | C23: Antigua | D23: London | J23: =(E23*2240)+(F23*112)+(G23*28)+H23 -> 0 | L23: =J23/2240 -> 0
A24: 1735 | B24: Rum | C24: Antigua | D24: London | H24: 155065 | I24: 15502.5g | J24: =(E24*2240)+(F24*112)+(G24*28)+H24 -> 155065 | L24: =J24/2240 -> 69.225446
A25: 1735 | B25: Shruff | C25: Antigua | D25: London | J25: =(E25*2240)+(F25*112)+(G25*28)+H25 -> 0 | L25: =J25/2240 -> 0
A26: 1735 | B26: Succads | C26: Antigua | D26: London | H26: 757 | J26: =(E26*2240)+(F26*112)+(G26*28)+H26 -> 757 | L26: =J26/2240 -> 0.33794643
A27: 1735 | B27: Tamarinds | C27: Antigua | D27: London | H27: 77 | J27: =(E27*2240)+(F27*112)+(G27*28)+H27 -> 77 | L27: =J27/2240 -> 0.034375
A28: 1735 | B28: Tobacco | C28: Antigua | D28: London | J28: =(E28*2240)+(F28*112)+(G28*28)+H28 -> 0 | L28: =J28/2240 -> 0
A29: 1735 | B29: Tortoise Shell | C29: Antigua | D29: London | H29: 11 | J29: =(E29*2240)+(F29*112)+(G29*28)+H29 -> 11 | L29: =J29/2240 -> 0.0049107143
A30: 1735 | B30: Train Oyl | C30: Antigua | D30: London | J30: =(E30*2240)+(F30*112)+(G30*28)+H30 -> 0 | L30: =J30/2240 -> 0
A31: 1735 | B31: White Sugar | C31: Antigua | D31: London | J31: =(E31*2240)+(F31*112)+(G31*28)+H31 -> 0 | L31: =J31/2240 -> 0
A32: 1735 | B32: Wood, Fustick | C32: Antigua | D32: London | E32: 251 | F32: 12 | J32: =(E32*2240)+(F32*112)+(G32*28)+H32 -> 563584 | L32: =J32/2240 -> 251.6
A33: 1735 | B33: Wood, Mahogany | C33: Antigua | D33: London | J33: =(E33*2240)+(F33*112)+(G33*28)+H33 -> 0 | L33: =J33/2240 -> 0
A34: 1735 | B34: Wood, Redwood | C34: Antigua | D34: London | F34: 11 | J34: =(E34*2240)+(F34*112)+(G34*28)+H34 -> 1232 | L34: =J34/2240 -> 0.55
A35: 1735 | B35: Bees Wax | C35: Antigua | D35: Out Ports | J35: =(E35*2240)+(F35*112)+(G35*28)+H35 -> 0 | L35: =J35/2240 -> 0
A36: 1735 | B36: Brown Sugar | C36: Antigua | D36: Out Ports | F36: 37895 | G36: 3 | H36: 10 | J36: =(E36*2240)+(F36*112)+(G36*28)+H36 -> 4244334 | L36: =J36/2240 -> 1894.792
A37: 1735 | B37: Cocoa | C37: Antigua | D37: Out Ports | J37: =(E37*2240)+(F37*112)+(G37*28)+H37 -> 0 | L37: =J37/2240 -> 0
A38: 1735 | B38: Cocoa Nuts | C38: Antigua | D38: Out Ports | J38: =(E38*2240)+(F38*112)+(G38*28)+H38 -> 0 | L38: =J38/2240 -> 0
A39: 1735 | B39: Cotton | C39: Antigua | D39: Out Ports | H39: =1759*200 -> 351800 | I39: 1759bags | J39: =(E39*2240)+(F39*112)+(G39*28)+H39 -> 351800 | L39: =J39/2240 -> 157.05357
A40: 1735 | B40: Dry Ginger | C40: Antigua | D40: Out Ports | F40: 1289 | G40: 2 | H40: 1 | J40: =(E40*2240)+(F40*112)+(G40*28)+H40 -> 144425 | L40: =J40/2240 -> 64.475446
...

Sheet Barbados
A1: YEAR | B1: COMMODITY_NAME | C1: FROM_LOCATION | D1: TO_LOCATION | E1: ton | F1: hh | G1: quarter | H1: lb | J1: Total Pounds | L1: WEIGHT
A2: 1735 | B2: Almonds, Bitter | C2: Barbados | D2: London | F2: 43 | J2: =(E2*2240)+(F2*112)+(G2*28)+H2 -> 4816 | L2: =J2/2240 -> 2.15
A3: 1735 | B3: Almonds, Sweet | C3: Barbados | D3: London | H3: 1 | J3: =(E3*2240)+(F3*112)+(G3*28)+H3 -> 1 | L3: =J3/2240 -> 0.00044642857
A4: 1735 | B4: Aloes Epatica | C4: Barbados | D4: London | H4: 20055 | J4: =(E4*2240)+(F4*112)+(G4*28)+H4 -> 20055 | L4: =J4/2240 -> 8.953125
A5: 1735 | B5: Annatto | C5: Barbados | D5: London | J5: =(E5*2240)+(F5*112)+(G5*28)+H5 -> 0 | L5: =J5/2240 -> 0
A6: 1735 | B6: Anniseeds | C6: Barbados | D6: London | J6: =(E6*2240)+(F6*112)+(G6*28)+H6 -> 0 | L6: =J6/2240 -> 0
A7: 1735 | B7: Barbados T… | C7: Barbados | D7: London | H7: 879 | J7: =(E7*2240)+(F7*112)+(G7*28)+H7 -> 879 | L7: =J7/2240 -> 0.39241071
A8: 1735 | B8: Barrel Staves | C8: Barbados | D8: London | J8: =(E8*2240)+(F8*112)+(G8*28)+H8 -> 0 | L8: =J8/2240 -> 0
A9: 1735 | B9: Bees Wax | C9: Barbados | D9: London | F9: 3 | G9: 1 | H9: 7 | J9: =(E9*2240)+(F9*112)+(G9*28)+H9 -> 371 | L9: =J9/2240 -> 0.165625
A10: 1735 | B10: Brimstone | C10: Barbados | D10: London | J10: =(E10*2240)+(F10*112)+(G10*28)+H10 -> 0 | L10: =J10/2240 -> 0
A11: 1735 | B11: Brown Sugar | C11: Barbados | D11: London | F11: 92543 | G11: 1 | H11: 7 | J11: =(E11*2240)+(F11*112)+(G11*28)+H11 -> 10364851 | L11: =J11/2240 -> 4627.1656
A12: 1735 | B12: Cassia Fistula | C12: Barbados | D12: London | J12: =(E12*2240)+(F12*112)+(G12*28)+H12 -> 0 | L12: =J12/2240 -> 0
A13: 1735 | B13: Chocolate Paste | C13: Barbados | D13: London | J13: =(E13*2240)+(F13*112)+(G13*28)+H13 -> 0 | L13: =J13/2240 -> 0
A14: 1735 | B14: Cocheneal | C14: Barbados | D14: London | H14: 374 | J14: =(E14*2240)+(F14*112)+(G14*28)+H14 -> 374 | L14: =J14/2240 -> 0.16696429
A15: 1735 | B15: Cocoa Nuts | C15: Barbados | D15: London | F15: 388 | G15: 1 | H15: 12 | J15: =(E15*2240)+(F15*112)+(G15*28)+H15 -> 43496 | L15: =J15/2240 -> 19.417857
A16: 1735 | B16: Cocoa Paste | C16: Barbados | D16: London | J16: =(E16*2240)+(F16*112)+(G16*28)+H16 -> 0 | L16: =J16/2240 -> 0
A17: 1735 | B17: Coffee | C17: Barbados | D17: London | F17: 7 | G17: 2 | H17: 18 | J17: =(E17*2240)+(F17*112)+(G17*28)+H17 -> 858 | L17: =J17/2240 -> 0.38303571
A18: 1735 | B18: Cortex Peru | C18: Barbados | D18: London | J18: =(E18*2240)+(F18*112)+(G18*28)+H18 -> 0 | L18: =J18/2240 -> 0
A19: 1735 | B19: Cotton | C19: Barbados | D19: London | F19: 162 | H19: =939*200 -> 187800 | I19: 939bags | J19: =(E19*2240)+(F19*112)+(G19*28)+H19 -> 205944 | L19: =J19/2240 -> 91.939286
A20: 1735 | B20: Dry Ginger | C20: Barbados | D20: London | F20: 2855 | G20: 1 | J20: =(E20*2240)+(F20*112)+(G20*28)+H20 -> 319788 | L20: =J20/2240 -> 142.7625
A21: 1735 | B21: Elephant Teeth | C21: Barbados | D21: London | F21: 331 | G21: 2 | H21: 26 | J21: =(E21*2240)+(F21*112)+(G21*28)+H21 -> 37154 | L21: =J21/2240 -> 16.586607
A22: 1735 | B22: Green Ginger | C22: Barbados | D22: London | H22: 411 | J22: =(E22*2240)+(F22*112)+(G22*28)+H22 -> 411 | L22: =J22/2240 -> 0.18348214
A23: 1735 | B23: Guinea Grains | C23: Barbados | D23: London | H23: 5000 | J23: =(E23*2240)+(F23*112)+(G23*28)+H23 -> 5000 | L23: =J23/2240 -> 2.2321429
A24: 1735 | B24: Hemp | C24: Barbados | D24: London | J24: =(E24*2240)+(F24*112)+(G24*28)+H24 -> 0 | L24: =J24/2240 -> 0
A25: 1735 | B25: Indigo | C25: Barbados | D25: London | J25: =(E25*2240)+(F25*112)+(G25*28)+H25 -> 0 | L25: =J25/2240 -> 0
A26: 1735 | B26: Lemon Water | C26: Barbados | D26: London | J26: =(E26*2240)+(F26*112)+(G26*28)+H26 -> 0 | L26: =J26/2240 -> 0
A27: 1735 | B27: Lignum Vitae | C27: Barbados | D27: London | E27: 18 | J27: =(E27*2240)+(F27*112)+(G27*28)+H27 -> 40320 | L27: =J27/2240 -> 18
A28: 1735 | B28: Lime Juice | C28: Barbados | D28: London | H28: 2220 | I28: 222g | J28: =(E28*2240)+(F28*112)+(G28*28)+H28 -> 2220 | L28: =J28/2240 -> 0.99107143
A29: 1735 | B29: Loaf Sugar | C29: Barbados | D29: London | J29: =(E29*2240)+(F29*112)+(G29*28)+H29 -> 0 | L29: =J29/2240 -> 0
A30: 1735 | B30: Madera Wine | C30: Barbados | D30: London | H30: 288744 | I30: 114t 2h 13g | J30: =(E30*2240)+(F30*112)+(G30*28)+H30 -> 288744 | L30: =J30/2240 -> 128.90357
A31: 1735 | B31: Molasses | C31: Barbados | D31: London | J31: =(E31*2240)+(F31*112)+(G31*28)+H31 -> 0 | L31: =J31/2240 -> 0
A32: 1735 | B32: Oranges | C32: Barbados | D32: London | J32: =(E32*2240)+(F32*112)+(G32*28)+H32 -> 0 | L32: =J32/2240 -> 0
A33: 1735 | B33: Pickles | C33: Barbados | D33: London | J33: =(E33*2240)+(F33*112)+(G33*28)+H33 -> 0 | L33: =J33/2240 -> 0
A34: 1735 | B34: Pimento | C34: Barbados | D34: London | J34: =(E34*2240)+(F34*112)+(G34*28)+H34 -> 0 | L34: =J34/2240 -> 0
A35: 1735 | B35: Port | C35: Barbados | D35: London | H35: 1981 | I35: 3h 9g | J35: =(E35*2240)+(F35*112)+(G35*28)+H35 -> 1981 | L35: =J35/2240 -> 0.884375
A36: 1735 | B36: Rice | C36: Barbados | D36: London | J36: =(E36*2240)+(F36*112)+(G36*28)+H36 -> 0 | L36: =J36/2240 -> 0
A37: 1735 | B37: Rum | C37: Barbados | D37: London | H37: 177171 | I37: 17712.5g | J37: =(E37*2240)+(F37*112)+(G37*28)+H37 -> 177171 | L37: =J37/2240 -> 79.094196
A38: 1735 | B38: Sasparilla | C38: Barbados | D38: London | H38: 128 | J38: =(E38*2240)+(F38*112)+(G38*28)+H38 -> 128 | L38: =J38/2240 -> 0.057142857
A39: 1735 | B39: Shruff | C39: Barbados | D39: London | J39: =(E39*2240)+(F39*112)+(G39*28)+H39 -> 0 | L39: =J39/2240 -> 0
A40: 1735 | B40: Snuff | C40: Barbados | D40: London | J40: =(E40*2240)+(F40*112)+(G40*28)+H40 -> 0 | L40: =J40/2240 -> 0
...

Sheet Bermuda
A1: YEAR | B1: COMMODITY_NAME | C1: FROM_LOCATION | D1: TO_LOCATION | E1: ton | F1: hh | G1: quarter | H1: lb | J1: Total Pounds | L1: WEIGHT
A2: 1735 | B2: Bermudos Plat | C2: Bermuda | D2: London | J2: =(E2*2240)+(F2*112)+(G2*28)+H2 -> 0 | L2: =J2/2240 -> 0
A3: 1735 | B3: Brown Sugar | C3: Bermuda | D3: London | J3: =(E3*2240)+(F3*112)+(G3*28)+H3 -> 0 | L3: =J3/2240 -> 0
A4: 1735 | B4: Cocoa Nuts | C4: Bermuda | D4: London | F4: 3 | H4: 12 | J4: =(E4*2240)+(F4*112)+(G4*28)+H4 -> 348 | L4: =J4/2240 -> 0.15535714
A5: 1735 | B5: Cotton | C5: Bermuda | D5: London | J5: =(E5*2240)+(F5*112)+(G5*28)+H5 -> 0 | L5: =J5/2240 -> 0
A6: 1735 | B6: Indigo | C6: Bermuda | D6: London | H6: 930 | J6: =(E6*2240)+(F6*112)+(G6*28)+H6 -> 930 | L6: =J6/2240 -> 0.41517857
A7: 1735 | B7: Madera Wine | C7: Bermuda | D7: London | J7: =(E7*2240)+(F7*112)+(G7*28)+H7 -> 0 | L7: =J7/2240 -> 0
A8: 1735 | B8: Rice | C8: Bermuda | D8: London | J8: =(E8*2240)+(F8*112)+(G8*28)+H8 -> 0 | L8: =J8/2240 -> 0
A9: 1735 | B9: Rum | C9: Bermuda | D9: London | H9: 600 | I9: 60g | J9: =(E9*2240)+(F9*112)+(G9*28)+H9 -> 600 | L9: =J9/2240 -> 0.26785714
A10: 1735 | B10: Succads | C10: Bermuda | D10: London | H10: 16 | J10: =(E10*2240)+(F10*112)+(G10*28)+H10 -> 16 | L10: =J10/2240 -> 0.0071428571
A11: 1735 | B11: Tortoise Shell | C11: Bermuda | D11: London | H11: 4 | J11: =(E11*2240)+(F11*112)+(G11*28)+H11 -> 4 | L11: =J11/2240 -> 0.0017857143
A12: 1735 | B12: Wood, Braziletto | C12: Bermuda | D12: London | E12: 1 | F12: 16 | J12: =(E12*2240)+(F12*112)+(G12*28)+H12 -> 4032 | L12: =J12/2240 -> 1.8
A13: 1735 | B13: Wood, Logwood | C13: Bermuda | D13: London | J13: =(E13*2240)+(F13*112)+(G13*28)+H13 -> 0 | L13: =J13/2240 -> 0
A14: 1735 | B14: Wood, Mahogany | C14: Bermuda | D14: London | E14: 2 | J14: =(E14*2240)+(F14*112)+(G14*28)+H14 -> 4480 | L14: =J14/2240 -> 2
A15: 1735 | B15: Brown Sugar | C15: Bermuda | D15: Out Ports | J15: =(E15*2240)+(F15*112)+(G15*28)+H15 -> 0 | L15: =J15/2240 -> 0
A16: 1735 | B16: Indigo | C16: Bermuda | D16: Out Ports | J16: =(E16*2240)+(F16*112)+(G16*28)+H16 -> 0 | L16: =J16/2240 -> 0
A17: 1735 | B17: Logwood | C17: Bermuda | D17: Out Ports | J17: =(E17*2240)+(F17*112)+(G17*28)+H17 -> 0 | L17: =J17/2240 -> 0
A18: 1735 | B18: Madera Wine | C18: Bermuda | D18: Out Ports | J18: =(E18*2240)+(F18*112)+(G18*28)+H18 -> 0 | L18: =J18/2240 -> 0
A19: 1735 | B19: Rice | C19: Bermuda | D19: Out Ports | J19: =(E19*2240)+(F19*112)+(G19*28)+H19 -> 0 | L19: =J19/2240 -> 0
A20: 1735 | B20: Shruff | C20: Bermuda | D20: Out Ports | J20: =(E20*2240)+(F20*112)+(G20*28)+H20 -> 0 | L20: =J20/2240 -> 0
A21: 1735 | B21: Succads | C21: Bermuda | D21: Out Ports | J21: =(E21*2240)+(F21*112)+(G21*28)+H21 -> 0 | L21: =J21/2240 -> 0
A22: 1735 | B22: Cotton | C22: Bermuda | D22: Out Ports | J22: =(E22*2240)+(F22*112)+(G22*28)+H22 -> 0 | L22: =J22/2240 -> 0
A23: 1735 | B23: Cocoa Nuts | C23: Bermuda | D23: Out Ports | J23: =(E23*2240)+(F23*112)+(G23*28)+H23 -> 0 | L23: =J23/2240 -> 0
A24: 1735 | B24: Wood, Braziletto | C24: Bermuda | D24: Out Ports | J24: =(E24*2240)+(F24*112)+(G24*28)+H24 -> 0 | L24: =J24/2240 -> 0
A25: 1735 | B25: Wood, Logwood | C25: Bermuda | D25: Out Ports | J25: =(E25*2240)+(F25*112)+(G25*28)+H25 -> 0 | L25: =J25/2240 -> 0

Sheet Jamaica
A1: YEAR | B1: COMMODITY_NAME | C1: FROM_LOCATION | D1: TO_LOCATION | E1: ton | F1: hh | G1: quarter | H1: lb | J1: Total Pounds | L1: WEIGHT
A2: 1735 | B2: Almonds, Bitter | C2: Jamaica | D2: London | J2: =(E2*2240)+(F2*112)+(G2*28)+H2 -> 0 | L2: =J2/2240 -> 0
A3: 1735 | B3: Almonds, Sweet | C3: Jamaica | D3: London | J3: =(E3*2240)+(F3*112)+(G3*28)+H3 -> 0 | L3: =J3/2240 -> 0
A4: 1735 | B4: Aloes Epatica | C4: Jamaica | D4: London | J4: =(E4*2240)+(F4*112)+(G4*28)+H4 -> 0 | L4: =J4/2240 -> 0
A5: 1735 | B5: Annatto | C5: Jamaica | D5: London | H5: 400 | J5: =(E5*2240)+(F5*112)+(G5*28)+H5 -> 400 | L5: =J5/2240 -> 0.17857143
A6: 1735 | B6: Anniseeds | C6: Jamaica | D6: London | J6: =(E6*2240)+(F6*112)+(G6*28)+H6 -> 0 | L6: =J6/2240 -> 0
A7: 1735 | B7: Bacon | C7: Jamaica | D7: London | H7: 16 | J7: =(E7*2240)+(F7*112)+(G7*28)+H7 -> 16 | L7: =J7/2240 -> 0.0071428571
A8: 1735 | B8: Barrel Staves | C8: Jamaica | D8: London | J8: =(E8*2240)+(F8*112)+(G8*28)+H8 -> 0 | L8: =J8/2240 -> 0
A9: 1735 | B9: Bay Berries | C9: Jamaica | D9: London | J9: =(E9*2240)+(F9*112)+(G9*28)+H9 -> 0 | L9: =J9/2240 -> 0
A10: 1735 | B10: Bees Wax | C10: Jamaica | D10: London | F10: 9 | G10: 2 | J10: =(E10*2240)+(F10*112)+(G10*28)+H10 -> 1064 | L10: =J10/2240 -> 0.475
A11: 1735 | B11: Brimstone | C11: Jamaica | D11: London | J11: =(E11*2240)+(F11*112)+(G11*28)+H11 -> 0 | L11: =J11/2240 -> 0
A12: 1735 | B12: Brown Sugar | C12: Jamaica | D12: London | F12: 178132 | G12: 3 | H12: 11 | J12: =(E12*2240)+(F12*112)+(G12*28)+H12 -> 19950879 | L12: =J12/2240 -> 8906.6424
A13: 1735 | B13: Cascarilla | C13: Jamaica | D13: London | J13: =(E13*2240)+(F13*112)+(G13*28)+H13 -> 0 | L13: =J13/2240 -> 0
A14: 1735 | B14: Cassia Fistula | C14: Jamaica | D14: London | H14: 11 | J14: =(E14*2240)+(F14*112)+(G14*28)+H14 -> 11 | L14: =J14/2240 -> 0.0049107143
A15: 1735 | B15: Chocolate Paste | C15: Jamaica | D15: London | J15: =(E15*2240)+(F15*112)+(G15*28)+H15 -> 0 | L15: =J15/2240 -> 0
A16: 1735 | B16: Cocheneal | C16: Jamaica | D16: London | H16: 1300 | J16: =(E16*2240)+(F16*112)+(G16*28)+H16 -> 1300 | L16: =J16/2240 -> 0.58035714
A17: 1735 | B17: Cocoa Nuts | C17: Jamaica | D17: London | F17: 330 | G17: 3 | H17: 3 | J17: =(E17*2240)+(F17*112)+(G17*28)+H17 -> 37047 | L17: =J17/2240 -> 16.538839
A18: 1735 | B18: Cocoa Paste | C18: Jamaica | D18: London | J18: =(E18*2240)+(F18*112)+(G18*28)+H18 -> 0 | L18: =J18/2240 -> 0
A19: 1735 | B19: Coffee | C19: Jamaica | D19: London | F19: 171 | H19: 25 | J19: =(E19*2240)+(F19*112)+(G19*28)+H19 -> 19177 | L19: =J19/2240 -> 8.5611607
A20: 1735 | B20: Cortex Peru | C20: Jamaica | D20: London | H20: 37108 | J20: =(E20*2240)+(F20*112)+(G20*28)+H20 -> 37108 | L20: =J20/2240 -> 16.566071
A21: 1735 | B21: Cortex Winteranus | C21: Jamaica | D21: London | H21: 197 | J21: =(E21*2240)+(F21*112)+(G21*28)+H21 -> 197 | L21: =J21/2240 -> 0.087946429
A22: 1735 | B22: Cotton | C22: Jamaica | D22: London | F22: 7 | H22: =666*170 -> 113220 | I22: 666 | J22: =(E22*2240)+(F22*112)+(G22*28)+H22 -> 114004 | L22: =J22/2240 -> 50.894643
A23: 1735 | B23: Dry Ginger | C23: Jamaica | D23: London | F23: 26954 | G23: 1 | H23: 3 | J23: =(E23*2240)+(F23*112)+(G23*28)+H23 -> 3018879 | L23: =J23/2240 -> 1347.7138
A24: 1735 | B24: Elephant Teeth | C24: Jamaica | D24: London | F24: 160 | H24: 9 | J24: =(E24*2240)+(F24*112)+(G24*28)+H24 -> 17929 | L24: =J24/2240 -> 8.0040179
A25: 1735 | B25: Green Ginger | C25: Jamaica | D25: London | H25: 36 | J25: =(E25*2240)+(F25*112)+(G25*28)+H25 -> 36 | L25: =J25/2240 -> 0.016071429
A26: 1735 | B26: Guinea Grains | C26: Jamaica | D26: London | H26: 15348 | J26: =(E26*2240)+(F26*112)+(G26*28)+H26 -> 15348 | L26: =J26/2240 -> 6.8517857
A27: 1735 | B27: Gum Guiacum | C27: Jamaica | D27: London | H27: 4613 | J27: =(E27*2240)+(F27*112)+(G27*28)+H27 -> 4613 | L27: =J27/2240 -> 2.059375
A28: 1735 | B28: Hemp | C28: Jamaica | D28: London | J28: =(E28*2240)+(F28*112)+(G28*28)+H28 -> 0 | L28: =J28/2240 -> 0
A29: 1735 | B29: Hypococania | C29: Jamaica | D29: London | J29: =(E29*2240)+(F29*112)+(G29*28)+H29 -> 0 | L29: =J29/2240 -> 0
A30: 1735 | B30: Indigo | C30: Jamaica | D30: London | H30: =17310+87022 -> 104332 | J30: =(E30*2240)+(F30*112)+(G30*28)+H30 -> 104332 | L30: =J30/2240 -> 46.576786
A31: 1735 | B31: Jallop? | C31: Jamaica | D31: London | H31: 3455 | J31: =(E31*2240)+(F31*112)+(G31*28)+H31 -> 3455 | L31: =J31/2240 -> 1.5424107
A32: 1735 | B32: Lemon Water | C32: Jamaica | D32: London | J32: =(E32*2240)+(F32*112)+(G32*28)+H32 -> 0 | L32: =J32/2240 -> 0
A33: 1735 | B33: Lignum Vitae | C33: Jamaica | D33: London | E33: 52 | F33: 10 | J33: =(E33*2240)+(F33*112)+(G33*28)+H33 -> 117600 | L33: =J33/2240 -> 52.5
A34: 1735 | B34: Lime Juice | C34: Jamaica | D34: London | H34: 91443 | I34: 9142g | J34: =(E34*2240)+(F34*112)+(G34*28)+H34 -> 91443 | L34: =J34/2240 -> 40.822768
A35: 1735 | B35: Loaf Sugar | C35: Jamaica | D35: London | J35: =(E35*2240)+(F35*112)+(G35*28)+H35 -> 0 | L35: =J35/2240 -> 0
A36: 1735 | B36: Madera Wine | C36: Jamaica | D36: London | H36: 162212 | I36: 64t 1h 26g | J36: =(E36*2240)+(F36*112)+(G36*28)+H36 -> 162212 | L36: =J36/2240 -> 72.416071
A37: 1735 | B37: Molasses | C37: Jamaica | D37: London | J37: =(E37*2240)+(F37*112)+(G37*28)+H37 -> 0 | L37: =J37/2240 -> 0
A38: 1735 | B38: Oranges | C38: Jamaica | D38: London | J38: =(E38*2240)+(F38*112)+(G38*28)+H38 -> 0 | L38: =J38/2240 -> 0
A39: 1735 | B39: Orchelia | C39: Jamaica | D39: London | J39: =(E39*2240)+(F39*112)+(G39*28)+H39 -> 0 | L39: =J39/2240 -> 0
A40: 1735 | B40: Pickles | C40: Jamaica | D40: London | H40: 1140 | I40: 114g | J40: =(E40*2240)+(F40*112)+(G40*28)+H40 -> 1140 | L40: =J40/2240 -> 0.50892857
...

Sheet Mountserat
A1: YEAR | B1: COMMODITY_NAME | C1: FROM_LOCATION | D1: TO_LOCATION | E1: ton | F1: hh | G1: quarter | H1: lb | J1: Total Pounds | L1: WEIGHT
A2: 1735 | B2: Almonds, Bitter | C2: Mountserat | D2: London | J2: =(E2*2240)+(F2*112)+(G2*28)+H2 -> 0 | L2: =J2/2240 -> 0
A3: 1735 | B3: Almonds, Sweet | C3: Mountserat | D3: London | J3: =(E3*2240)+(F3*112)+(G3*28)+H3 -> 0 | L3: =J3/2240 -> 0
A4: 1735 | B4: Aloes Epatica | C4: Mountserat | D4: London | J4: =(E4*2240)+(F4*112)+(G4*28)+H4 -> 0 | L4: =J4/2240 -> 0
A5: 1735 | B5: Annatto | C5: Mountserat | D5: London | J5: =(E5*2240)+(F5*112)+(G5*28)+H5 -> 0 | L5: =J5/2240 -> 0
A6: 1735 | B6: Anniseeds | C6: Mountserat | D6: London | J6: =(E6*2240)+(F6*112)+(G6*28)+H6 -> 0 | L6: =J6/2240 -> 0
A7: 1735 | B7: Bacon | C7: Mountserat | D7: London | J7: =(E7*2240)+(F7*112)+(G7*28)+H7 -> 0 | L7: =J7/2240 -> 0
A8: 1735 | B8: Barrel Staves | C8: Mountserat | D8: London | J8: =(E8*2240)+(F8*112)+(G8*28)+H8 -> 0 | L8: =J8/2240 -> 0
A9: 1735 | B9: Bees Wax | C9: Mountserat | D9: London | J9: =(E9*2240)+(F9*112)+(G9*28)+H9 -> 0 | L9: =J9/2240 -> 0
A10: 1735 | B10: Brimstone | C10: Mountserat | D10: London | J10: =(E10*2240)+(F10*112)+(G10*28)+H10 -> 0 | L10: =J10/2240 -> 0
A11: 1735 | B11: Brown Sugar | C11: Mountserat | D11: London | F11: 52631 | G11: 1 | H11: 27 | J11: =(E11*2240)+(F11*112)+(G11*28)+H11 -> 5894727 | L11: =J11/2240 -> 2631.5746
A12: 1735 | B12: Cassia Fistula | C12: Mountserat | D12: London | J12: =(E12*2240)+(F12*112)+(G12*28)+H12 -> 0 | L12: =J12/2240 -> 0
A13: 1735 | B13: Chocolate Paste | C13: Mountserat | D13: London | J13: =(E13*2240)+(F13*112)+(G13*28)+H13 -> 0 | L13: =J13/2240 -> 0
A14: 1735 | B14: Cocheneal | C14: Mountserat | D14: London | J14: =(E14*2240)+(F14*112)+(G14*28)+H14 -> 0 | L14: =J14/2240 -> 0
A15: 1735 | B15: Cocoa Nuts | C15: Mountserat | D15: London | J15: =(E15*2240)+(F15*112)+(G15*28)+H15 -> 0 | L15: =J15/2240 -> 0
A16: 1735 | B16: Cocoa Paste | C16: Mountserat | D16: London | J16: =(E16*2240)+(F16*112)+(G16*28)+H16 -> 0 | L16: =J16/2240 -> 0
A17: 1735 | B17: Coffee | C17: Mountserat | D17: London | J17: =(E17*2240)+(F17*112)+(G17*28)+H17 -> 0 | L17: =J17/2240 -> 0
A18: 1735 | B18: Cortex Winteranus | C18: Mountserat | D18: London | J18: =(E18*2240)+(F18*112)+(G18*28)+H18 -> 0 | L18: =J18/2240 -> 0
A19: 1735 | B19: Cotton | C19: Mountserat | D19: London | F19: 20 | H19: =58*200 -> 11600 | I19: 58bags | J19: =(E19*2240)+(F19*112)+(G19*28)+H19 -> 13840 | L19: =J19/2240 -> 6.1785714
A20: 1735 | B20: Dry Ginger | C20: Mountserat | D20: London | F20: 2 | J20: =(E20*2240)+(F20*112)+(G20*28)+H20 -> 224 | L20: =J20/2240 -> 0.1
A21: 1735 | B21: Elephant Teeth | C21: Mountserat | D21: London | J21: =(E21*2240)+(F21*112)+(G21*28)+H21 -> 0 | L21: =J21/2240 -> 0
A22: 1735 | B22: Green Ginger | C22: Mountserat | D22: London | J22: =(E22*2240)+(F22*112)+(G22*28)+H22 -> 0 | L22: =J22/2240 -> 0
A23: 1735 | B23: Hemp | C23: Mountserat | D23: London | J23: =(E23*2240)+(F23*112)+(G23*28)+H23 -> 0 | L23: =J23/2240 -> 0
A24: 1735 | B24: Indigo | C24: Mountserat | D24: London | H24: 356 | J24: =(E24*2240)+(F24*112)+(G24*28)+H24 -> 356 | L24: =J24/2240 -> 0.15892857
A25: 1735 | B25: Lemon Water | C25: Mountserat | D25: London | J25: =(E25*2240)+(F25*112)+(G25*28)+H25 -> 0 | L25: =J25/2240 -> 0
A26: 1735 | B26: Lignum Vitae | C26: Mountserat | D26: London | J26: =(E26*2240)+(F26*112)+(G26*28)+H26 -> 0 | L26: =J26/2240 -> 0
A27: 1735 | B27: Lime Juice | C27: Mountserat | D27: London | J27: =(E27*2240)+(F27*112)+(G27*28)+H27 -> 0 | L27: =J27/2240 -> 0
A28: 1735 | B28: Loaf Sugar | C28: Mountserat | D28: London | J28: =(E28*2240)+(F28*112)+(G28*28)+H28 -> 0 | L28: =J28/2240 -> 0
A29: 1735 | B29: Madera Wine | C29: Mountserat | D29: London | H29: 1090 | I29: 1h 46g | J29: =(E29*2240)+(F29*112)+(G29*28)+H29 -> 1090 | L29: =J29/2240 -> 0.48660714
A30: 1735 | B30: Molasses | C30: Mountserat | D30: London | J30: =(E30*2240)+(F30*112)+(G30*28)+H30 -> 0 | L30: =J30/2240 -> 0
A31: 1735 | B31: Oranges | C31: Mountserat | D31: London | J31: =(E31*2240)+(F31*112)+(G31*28)+H31 -> 0 | L31: =J31/2240 -> 0
A32: 1735 | B32: Pickles | C32: Mountserat | D32: London | H32: 20 | I32: 2g | J32: =(E32*2240)+(F32*112)+(G32*28)+H32 -> 20 | L32: =J32/2240 -> 0.0089285714
A33: 1735 | B33: Pimento | C33: Mountserat | D33: London | H33: 193 | J33: =(E33*2240)+(F33*112)+(G33*28)+H33 -> 193 | L33: =J33/2240 -> 0.086160714
A34: 1735 | B34: Rice | C34: Mountserat | D34: London | J34: =(E34*2240)+(F34*112)+(G34*28)+H34 -> 0 | L34: =J34/2240 -> 0
A35: 1735 | B35: Rum | C35: Mountserat | D35: London | H35: 56014 | I35: 5600g | J35: =(E35*2240)+(F35*112)+(G35*28)+H35 -> 56014 | L35: =J35/2240 -> 25.00625
A36: 1735 | B36: Sarsparila | C36: Mountserat | D36: London | J36: =(E36*2240)+(F36*112)+(G36*28)+H36 -> 0 | L36: =J36/2240 -> 0
A37: 1735 | B37: Shruff | C37: Mountserat | D37: London | J37: =(E37*2240)+(F37*112)+(G37*28)+H37 -> 0 | L37: =J37/2240 -> 0
A38: 1735 | B38: Snuff | C38: Mountserat | D38: London | J38: =(E38*2240)+(F38*112)+(G38*28)+H38 -> 0 | L38: =J38/2240 -> 0
A39: 1735 | B39: Succads | C39: Mountserat | D39: London | H39: 58 | J39: =(E39*2240)+(F39*112)+(G39*28)+H39 -> 58 | L39: =J39/2240 -> 0.025892857
A40: 1735 | B40: Tamarinds | C40: Mountserat | D40: London | H40: 67 | J40: =(E40*2240)+(F40*112)+(G40*28)+H40 -> 67 | L40: =J40/2240 -> 0.029910714
...

Sheet Nevis
A1: YEAR | B1: COMMODITY_NAME | C1: FROM_LOCATION | D1: TO_LOCATION | E1: ton | F1: hh | G1: quarter | H1: lb | J1: Total Pounds | L1: WEIGHT
A2: 1735 | B2: Almonds, Bitter | C2: Nevis | D2: London | J2: =(E2*2240)+(F2*112)+(G2*28)+H2 -> 0 | L2: =J2/2240 -> 0
A3: 1735 | B3: Almonds, Sweet | C3: Nevis | D3: London | J3: =(E3*2240)+(F3*112)+(G3*28)+H3 -> 0 | L3: =J3/2240 -> 0
A4: 1735 | B4: Aloes Epatica | C4: Nevis | D4: London | J4: =(E4*2240)+(F4*112)+(G4*28)+H4 -> 0 | L4: =J4/2240 -> 0
A5: 1735 | B5: Annatto | C5: Nevis | D5: London | J5: =(E5*2240)+(F5*112)+(G5*28)+H5 -> 0 | L5: =J5/2240 -> 0
A6: 1735 | B6: Anniseeds | C6: Nevis | D6: London | J6: =(E6*2240)+(F6*112)+(G6*28)+H6 -> 0 | L6: =J6/2240 -> 0
A7: 1735 | B7: Bacon | C7: Nevis | D7: London | J7: =(E7*2240)+(F7*112)+(G7*28)+H7 -> 0 | L7: =J7/2240 -> 0
A8: 1735 | B8: Barrel Staves | C8: Nevis | D8: London | J8: =(E8*2240)+(F8*112)+(G8*28)+H8 -> 0 | L8: =J8/2240 -> 0
A9: 1735 | B9: Bees Wax | C9: Nevis | D9: London | J9: =(E9*2240)+(F9*112)+(G9*28)+H9 -> 0 | L9: =J9/2240 -> 0
A10: 1735 | B10: Brimstone | C10: Nevis | D10: London | J10: =(E10*2240)+(F10*112)+(G10*28)+H10 -> 0 | L10: =J10/2240 -> 0
A11: 1735 | B11: Brown Sugar | C11: Nevis | D11: London | F11: 34662 | G11: 3 | H11: 11 | J11: =(E11*2240)+(F11*112)+(G11*28)+H11 -> 3882239 | L11: =J11/2240 -> 1733.1424
A12: 1735 | B12: Cassia Fistula | C12: Nevis | D12: London | J12: =(E12*2240)+(F12*112)+(G12*28)+H12 -> 0 | L12: =J12/2240 -> 0
A13: 1735 | B13: Chocolate Paste | C13: Nevis | D13: London | J13: =(E13*2240)+(F13*112)+(G13*28)+H13 -> 0 | L13: =J13/2240 -> 0
A14: 1735 | B14: Cocheneal | C14: Nevis | D14: London | J14: =(E14*2240)+(F14*112)+(G14*28)+H14 -> 0 | L14: =J14/2240 -> 0
A15: 1735 | B15: Cocoa Nuts | C15: Nevis | D15: London | F15: 17 | H15: 3 | J15: =(E15*2240)+(F15*112)+(G15*28)+H15 -> 1907 | L15: =J15/2240 -> 0.85133929
A16: 1735 | B16: Cocoa Paste | C16: Nevis | D16: London | J16: =(E16*2240)+(F16*112)+(G16*28)+H16 -> 0 | L16: =J16/2240 -> 0
A17: 1735 | B17: Cortex Winteranus | C17: Nevis | D17: London | J17: =(E17*2240)+(F17*112)+(G17*28)+H17 -> 0 | L17: =J17/2240 -> 0
A18: 1735 | B18: Cotton | C18: Nevis | D18: London | F18: 109 | H18: =70*200 -> 14000 | I18: 70bags | J18: =(E18*2240)+(F18*112)+(G18*28)+H18 -> 26208 | L18: =J18/2240 -> 11.7
A19: 1735 | B19: Dry Ginger | C19: Nevis | D19: London | J19: =(E19*2240)+(F19*112)+(G19*28)+H19 -> 0 | L19: =J19/2240 -> 0
A20: 1735 | B20: Elephant Teeth | C20: Nevis | D20: London | J20: =(E20*2240)+(F20*112)+(G20*28)+H20 -> 0 | L20: =J20/2240 -> 0
A21: 1735 | B21: Green Ginger | C21: Nevis | D21: London | J21: =(E21*2240)+(F21*112)+(G21*28)+H21 -> 0 | L21: =J21/2240 -> 0
A22: 1735 | B22: Hemp | C22: Nevis | D22: London | J22: =(E22*2240)+(F22*112)+(G22*28)+H22 -> 0 | L22: =J22/2240 -> 0
A23: 1735 | B23: Indigo | C23: Nevis | D23: London | J23: =(E23*2240)+(F23*112)+(G23*28)+H23 -> 0 | L23: =J23/2240 -> 0
A24: 1735 | B24: Lemon Water | C24: Nevis | D24: London | J24: =(E24*2240)+(F24*112)+(G24*28)+H24 -> 0 | L24: =J24/2240 -> 0
A25: 1735 | B25: Lignum Vitae | C25: Nevis | D25: London | J25: =(E25*2240)+(F25*112)+(G25*28)+H25 -> 0 | L25: =J25/2240 -> 0
A26: 1735 | B26: Lime Juice | C26: Nevis | D26: London | J26: =(E26*2240)+(F26*112)+(G26*28)+H26 -> 0 | L26: =J26/2240 -> 0
A27: 1735 | B27: Loaf Sugar | C27: Nevis | D27: London | J27: =(E27*2240)+(F27*112)+(G27*28)+H27 -> 0 | L27: =J27/2240 -> 0
A28: 1735 | B28: Madera Wine | C28: Nevis | D28: London | H28: 6592 | I28: 2t 2h 29g | J28: =(E28*2240)+(F28*112)+(G28*28)+H28 -> 6592 | L28: =J28/2240 -> 2.9428571
A29: 1735 | B29: Molasses | C29: Nevis | D29: London | F29: 15 | G29: 1 | J29: =(E29*2240)+(F29*112)+(G29*28)+H29 -> 1708 | L29: =J29/2240 -> 0.7625
A30: 1735 | B30: Oranges | C30: Nevis | D30: London | J30: =(E30*2240)+(F30*112)+(G30*28)+H30 -> 0 | L30: =J30/2240 -> 0
A31: 1735 | B31: Pickles | C31: Nevis | D31: London | H31: 40 | I31: 4g | J31: =(E31*2240)+(F31*112)+(G31*28)+H31 -> 40 | L31: =J31/2240 -> 0.017857143
A32: 1735 | B32: Pimento | C32: Nevis | D32: London | J32: =(E32*2240)+(F32*112)+(G32*28)+H32 -> 0 | L32: =J32/2240 -> 0
A33: 1735 | B33: Rice | C33: Nevis | D33: London | J33: =(E33*2240)+(F33*112)+(G33*28)+H33 -> 0 | L33: =J33/2240 -> 0
A34: 1735 | B34: Rum | C34: Nevis | D34: London | H34: 3271 | I34: 327g | J34: =(E34*2240)+(F34*112)+(G34*28)+H34 -> 3271 | L34: =J34/2240 -> 1.4602679
A35: 1735 | B35: Sarsparila | C35: Nevis | D35: London | J35: =(E35*2240)+(F35*112)+(G35*28)+H35 -> 0 | L35: =J35/2240 -> 0
A36: 1735 | B36: Shruff | C36: Nevis | D36: London | J36: =(E36*2240)+(F36*112)+(G36*28)+H36 -> 0 | L36: =J36/2240 -> 0
A37: 1735 | B37: Snuff | C37: Nevis | D37: London | J37: =(E37*2240)+(F37*112)+(G37*28)+H37 -> 0 | L37: =J37/2240 -> 0
A38: 1735 | B38: Succads | C38: Nevis | D38: London | H38: 69 | J38: =(E38*2240)+(F38*112)+(G38*28)+H38 -> 69 | L38: =J38/2240 -> 0.030803571
A39: 1735 | B39: Tamarinds | C39: Nevis | D39: London | J39: =(E39*2240)+(F39*112)+(G39*28)+H39 -> 0 | L39: =J39/2240 -> 0
A40: 1735 | B40: Tobacco | C40: Nevis | D40: London | J40: =(E40*2240)+(F40*112)+(G40*28)+H40 -> 0 | L40: =J40/2240 -> 0
...

Sheet St Kitts
A1: YEAR | B1: COMMODITY_NAME | C1: FROM_LOCATION | D1: TO_LOCATION | E1: ton | F1: hh | G1: quarter | H1: lb | J1: Total Pounds | L1: WEIGHT
A2: 1735 | B2: Almonds, Bitter | C2: StKitts | D2: London | J2: =(E2*2240)+(F2*112)+(G2*28)+H2 -> 0 | L2: =J2/2240 -> 0
A3: 1735 | B3: Almonds, Sweet | C3: StKitts | D3: London | J3: =(E3*2240)+(F3*112)+(G3*28)+H3 -> 0 | L3: =J3/2240 -> 0
A4: 1735 | B4: Aloes Epatica | C4: StKitts | D4: London | J4: =(E4*2240)+(F4*112)+(G4*28)+H4 -> 0 | L4: =J4/2240 -> 0
A5: 1735 | B5: Annatto | C5: StKitts | D5: London | J5: =(E5*2240)+(F5*112)+(G5*28)+H5 -> 0 | L5: =J5/2240 -> 0
A6: 1735 | B6: Anniseeds | C6: StKitts | D6: London | J6: =(E6*2240)+(F6*112)+(G6*28)+H6 -> 0 | L6: =J6/2240 -> 0
A7: 1735 | B7: Bacon | C7: StKitts | D7: London | J7: =(E7*2240)+(F7*112)+(G7*28)+H7 -> 0 | L7: =J7/2240 -> 0
A8: 1735 | B8: Barrel Staves | C8: StKitts | D8: London | J8: =(E8*2240)+(F8*112)+(G8*28)+H8 -> 0 | L8: =J8/2240 -> 0
A9: 1735 | B9: Bees Wax | C9: StKitts | D9: London | J9: =(E9*2240)+(F9*112)+(G9*28)+H9 -> 0 | L9: =J9/2240 -> 0
A10: 1735 | B10: Brimstone | C10: StKitts | D10: London | J10: =(E10*2240)+(F10*112)+(G10*28)+H10 -> 0 | L10: =J10/2240 -> 0
A11: 1735 | B11: Brown Sugar | C11: StKitts | D11: London | F11: 167192 | G11: 1 | H11: 15 | J11: =(E11*2240)+(F11*112)+(G11*28)+H11 -> 18725547 | L11: =J11/2240 -> 8359.6192
A12: 1735 | B12: Cassia Fistula | C12: StKitts | D12: London | J12: =(E12*2240)+(F12*112)+(G12*28)+H12 -> 0 | L12: =J12/2240 -> 0
A13: 1735 | B13: Chocolate Paste | C13: StKitts | D13: London | J13: =(E13*2240)+(F13*112)+(G13*28)+H13 -> 0 | L13: =J13/2240 -> 0
A14: 1735 | B14: Cocheneal | C14: StKitts | D14: London | J14: =(E14*2240)+(F14*112)+(G14*28)+H14 -> 0 | L14: =J14/2240 -> 0
A15: 1735 | B15: Cocoa Nuts | C15: StKitts | D15: London | F15: 213 | H15: 8 | J15: =(E15*2240)+(F15*112)+(G15*28)+H15 -> 23864 | L15: =J15/2240 -> 10.653571
A16: 1735 | B16: Cocoa Paste | C16: StKitts | D16: London | J16: =(E16*2240)+(F16*112)+(G16*28)+H16 -> 0 | L16: =J16/2240 -> 0
A17: 1735 | B17: Coffee | C17: StKitts | D17: London | F17: 27 | H17: 3 | J17: =(E17*2240)+(F17*112)+(G17*28)+H17 -> 3027 | L17: =J17/2240 -> 1.3513393
A18: 1735 | B18: Copper Ore | C18: StKitts | D18: London | J18: =(E18*2240)+(F18*112)+(G18*28)+H18 -> 0 | L18: =J18/2240 -> 0
A19: 1735 | B19: Cortex Winteranus | C19: StKitts | D19: London | J19: =(E19*2240)+(F19*112)+(G19*28)+H19 -> 0 | L19: =J19/2240 -> 0
A20: 1735 | B20: Cotton | C20: StKitts | D20: London | F20: 5 | H20: =577*170 -> 98090 | I20: 577 | J20: =(E20*2240)+(F20*112)+(G20*28)+H20 -> 98650 | L20: =J20/2240 -> 44.040179
A21: 1735 | B21: Dry Ginger | C21: StKitts | D21: London | F21: 2 | J21: =(E21*2240)+(F21*112)+(G21*28)+H21 -> 224 | L21: =J21/2240 -> 0.1
A22: 1735 | B22: Elephant Teeth | C22: StKitts | D22: London | F22: 65 | G22: 3 | H22: 5 | J22: =(E22*2240)+(F22*112)+(G22*28)+H22 -> 7369 | L22: =J22/2240 -> 3.2897321
A23: 1735 | B23: Green Ginger | C23: StKitts | D23: London | J23: =(E23*2240)+(F23*112)+(G23*28)+H23 -> 0 | L23: =J23/2240 -> 0
A24: 1735 | B24: Guinea Grains | C24: StKitts | D24: London | H24: 16312 | J24: =(E24*2240)+(F24*112)+(G24*28)+H24 -> 16312 | L24: =J24/2240 -> 7.2821429
A25: 1735 | B25: Gum Guiaci | C25: StKitts | D25: London | H25: 295 | J25: =(E25*2240)+(F25*112)+(G25*28)+H25 -> 295 | L25: =J25/2240 -> 0.13169643
A26: 1735 | B26: Hemp | C26: StKitts | D26: London | J26: =(E26*2240)+(F26*112)+(G26*28)+H26 -> 0 | L26: =J26/2240 -> 0
A27: 1735 | B27: Indigo | C27: StKitts | D27: London | J27: =(E27*2240)+(F27*112)+(G27*28)+H27 -> 0 | L27: =J27/2240 -> 0
A28: 1735 | B28: Lemon Water | C28: StKitts | D28: London | J28: =(E28*2240)+(F28*112)+(G28*28)+H28 -> 0 | L28: =J28/2240 -> 0
A29: 1735 | B29: Lignum Vitae | C29: StKitts | D29: London | E29: 78 | F29: 5 | J29: =(E29*2240)+(F29*112)+(G29*28)+H29 -> 175280 | L29: =J29/2240 -> 78.25
A30: 1735 | B30: Lime Juice | C30: StKitts | D30: London | J30: =(E30*2240)+(F30*112)+(G30*28)+H30 -> 0 | L30: =J30/2240 -> 0
A31: 1735 | B31: Loaf Sugar | C31: StKitts | D31: London | J31: =(E31*2240)+(F31*112)+(G31*28)+H31 -> 0 | L31: =J31/2240 -> 0
A32: 1735 | B32: Madera Wine | C32: StKitts | D32: London | H32: 135465 | I32: 53t 2h 61g | J32: =(E32*2240)+(F32*112)+(G32*28)+H32 -> 135465 | L32: =J32/2240 -> 60.475446
A33: 1735 | B33: Molasses | C33: StKitts | D33: London | J33: =(E33*2240)+(F33*112)+(G33*28)+H33 -> 0 | L33: =J33/2240 -> 0
A34: 1735 | B34: Oranges | C34: StKitts | D34: London | J34: =(E34*2240)+(F34*112)+(G34*28)+H34 -> 0 | L34: =J34/2240 -> 0
A35: 1735 | B35: Pickles | C35: StKitts | D35: London | H35: 100 | I35: 10g | J35: =(E35*2240)+(F35*112)+(G35*28)+H35 -> 100 | L35: =J35/2240 -> 0.044642857
A36: 1735 | B36: Pig Iron | C36: StKitts | D36: London | E36: 1 | F36: 13 | J36: =(E36*2240)+(F36*112)+(G36*28)+H36 -> 3696 | L36: =J36/2240 -> 1.65
A37: 1735 | B37: Pimento | C37: StKitts | D37: London | H37: 1143 | J37: =(E37*2240)+(F37*112)+(G37*28)+H37 -> 1143 | L37: =J37/2240 -> 0.51026786
A38: 1735 | B38: Port | C38: StKitts | D38: London | H38: 31138 | I38: 12t 1h 26g | J38: =(E38*2240)+(F38*112)+(G38*28)+H38 -> 31138 | L38: =J38/2240 -> 13.900893
A39: 1735 | B39: Rice | C39: StKitts | D39: London | J39: =(E39*2240)+(F39*112)+(G39*28)+H39 -> 0 | L39: =J39/2240 -> 0
A40: 1735 | B40: Rum | C40: StKitts | D40: London | H40: 63266 | I40: 6325g | J40: =(E40*2240)+(F40*112)+(G40*28)+H40 -> 63266 | L40: =J40/2240 -> 28.24375
...

Sheet Tortola
A1: YEAR | B1: COMMODITY_NAME | C1: FROM_LOCATION | D1: TO_LOCATION | E1: ton | F1: hh | G1: quarter | H1: lb | J1: Total Pounds | L1: WEIGHT
B2: Almonds, Bitter | C2: Tortola | D2: London | J2: =(E2*2240)+(F2*112)+(G2*28)+H2 -> 0 | L2: =J2/2240 -> 0
B3: Almonds, Sweet | C3: Tortola | D3: London | J3: =(E3*2240)+(F3*112)+(G3*28)+H3 -> 0 | L3: =J3/2240 -> 0
B4: Aloes Epatica | C4: Tortola | D4: London | J4: =(E4*2240)+(F4*112)+(G4*28)+H4 -> 0 | L4: =J4/2240 -> 0
B5: Annatto | C5: Tortola | D5: London | J5: =(E5*2240)+(F5*112)+(G5*28)+H5 -> 0 | L5: =J5/2240 -> 0
B6: Anniseeds | C6: Tortola | D6: London | J6: =(E6*2240)+(F6*112)+(G6*28)+H6 -> 0 | L6: =J6/2240 -> 0
B7: Bacon | C7: Tortola | D7: London | J7: =(E7*2240)+(F7*112)+(G7*28)+H7 -> 0 | L7: =J7/2240 -> 0
B8: Barrel Staves | C8: Tortola | D8: London | J8: =(E8*2240)+(F8*112)+(G8*28)+H8 -> 0 | L8: =J8/2240 -> 0
B9: Bees Wax | C9: Tortola | D9: London | J9: =(E9*2240)+(F9*112)+(G9*28)+H9 -> 0 | L9: =J9/2240 -> 0
B10: Brimstone | C10: Tortola | D10: London | J10: =(E10*2240)+(F10*112)+(G10*28)+H10 -> 0 | L10: =J10/2240 -> 0
B11: Brown Sugar | C11: Tortola | D11: London | J11: =(E11*2240)+(F11*112)+(G11*28)+H11 -> 0 | L11: =J11/2240 -> 0
B12: Cassia Fistula | C12: Tortola | D12: London | J12: =(E12*2240)+(F12*112)+(G12*28)+H12 -> 0 | L12: =J12/2240 -> 0
B13: Chocolate Paste | C13: Tortola | D13: London | J13: =(E13*2240)+(F13*112)+(G13*28)+H13 -> 0 | L13: =J13/2240 -> 0
... B70: Wood, Redwood | C70: Tortola | D70: Out Ports | J70: =(E70*2240)+(F70*112)+(G70*28)+H70 -> 0 | L70: =J70/2240 -> 0
