Workbook

Sheet Master Goods Sheet
A1: Item | B1: Total London | C1: Total Outports | D1: Total
A2: Annatto | B2: =SUMIFS(Antigua!$L:$L, Antigua!$B:$B, $A2, Antigua!$D:$D, "London") + SUMIFS(Barbados!$L:$L, Barbados!$B:$B, $A2, Barbados!$D:$D, "London") + SUMIFS(Bermuda!$L:$L, Bermuda!$B:$B, $A2, Bermuda!$D:$D, "London") + SUMIFS(Jamaica!$L:$L, Jamaica!$B:$B, $A2, Jamaica!$D:$D, "London") + SUMIFS(Mountserat!$L:$L, Mountserat!$B:$B, $A2, Mountserat!$D:$D, "London") + SUMIFS(Nevis!$L:$L, Nevis!$B:$B, $A2, Nevis!$D:$D, "London") + SUMIFS('St Kitts'!$L:$L, 'St Kitts'!$B:$B, $A2, 'St Kitts'!$D:$D, "London") + SUMIFS(WestIndiesGeneral!$L:$L, WestIndiesGeneral!$B:$B, $A2, WestIndiesGeneral!$D:$D, "London") + SUMIFS(Tortola!$L:$L, Tortola!$B:$B, $A2, Tortola!$D:$D, "London") + SUMIFS(Anguilla!$L:$L, Anguilla!$B:$B, $A2, Anguilla!$D:$D, "London") -> 0 | C2: =SUMIFS(Antigua!$L:$L, Antigua!$B:$B, $A2, Antigua!$D:$D, "Out Ports") + SUMIFS(Barbados!$L:$L, Barbados!$B:$B, $A2, Barbados!$D:$D, "Out Ports") + SUMIFS(Bermuda!$L:$L, Bermuda!$B:$B, $A2, Bermuda!$D:$D, "Out Ports") + SUMIFS(Jamaica!$L:$L, Jamaica!$B:$B, $A2, Jamaica!$D:$D, "Out Ports") + SUMIFS(Mountserat!$L:$L, Mountserat!$B:$B, $A2, Mountserat!$D:$D, "Out Ports") + SUMIFS(Nevis!$L:$L, Nevis!$B:$B, $A2, Nevis!$D:$D, "Out Ports") + SUMIFS('St Kitts'!$L:$L, 'St Kitts'!$B:$B, $A2, 'St Kitts'!$D:$D, "Out Ports") + SUMIFS(WestIndiesGeneral!$L:$L, WestIndiesGeneral!$B:$B, $A2, WestIndiesGeneral!$D:$D, "Out Ports") + SUMIFS(Tortola!$L:$L, Tortola!$B:$B, $A2, Tortola!$D:$D, "Out Ports") + SUMIFS(Anguilla!$L:$L, Anguilla!$B:$B, $A2, Anguilla!$D:$D, "Out Ports") -> 0 | D2: =B2+C2 -> 0
A3: Bees Wax | B3: =SUMIFS(Antigua!$L:$L, Antigua!$B:$B, $A3, Antigua!$D:$D, "London") + SUMIFS(Barbados!$L:$L, Barbados!$B:$B, $A3, Barbados!$D:$D, "London") + SUMIFS(Bermuda!$L:$L, Bermuda!$B:$B, $A3, Bermuda!$D:$D, "London") + SUMIFS(Jamaica!$L:$L, Jamaica!$B:$B, $A3, Jamaica!$D:$D, "London") + SUMIFS(Mountserat!$L:$L, Mountserat!$B:$B, $A3, Mountserat!$D:$D, "London") + SUMIFS(Nevis!$L:$L, Nevis!$B:$B, $A3, Nevis!$D:$D, "London") + SUMIFS('St Kitts'!$L:$L, 'St Kitts'!$B:$B, $A3, 'St Kitts'!$D:$D, "London") + SUMIFS(WestIndiesGeneral!$L:$L, WestIndiesGeneral!$B:$B, $A3, WestIndiesGeneral!$D:$D, "London") + SUMIFS(Tortola!$L:$L, Tortola!$B:$B, $A3, Tortola!$D:$D, "London") + SUMIFS(Anguilla!$L:$L, Anguilla!$B:$B, $A3, Anguilla!$D:$D, "London") -> 2.0375 | C3: =SUMIFS(Antigua!$L:$L, Antigua!$B:$B, $A3, Antigua!$D:$D, "Out Ports") + SUMIFS(Barbados!$L:$L, Barbados!$B:$B, $A3, Barbados!$D:$D, "Out Ports") + SUMIFS(Bermuda!$L:$L, Bermuda!$B:$B, $A3, Bermuda!$D:$D, "Out Ports") + SUMIFS(Jamaica!$L:$L, Jamaica!$B:$B, $A3, Jamaica!$D:$D, "Out Ports") + SUMIFS(Mountserat!$L:$L, Mountserat!$B:$B, $A3, Mountserat!$D:$D, "Out Ports") + SUMIFS(Nevis!$L:$L, Nevis!$B:$B, $A3, Nevis!$D:$D, "Out Ports") + SUMIFS('St Kitts'!$L:$L, 'St Kitts'!$B:$B, $A3, 'St Kitts'!$D:$D, "Out Ports") + SUMIFS(WestIndiesGeneral!$L:$L, WestIndiesGeneral!$B:$B, $A3, WestIndiesGeneral!$D:$D, "Out Ports") + SUMIFS(Tortola!$L:$L, Tortola!$B:$B, $A3, Tortola!$D:$D, "Out Ports") + SUMIFS(Anguilla!$L:$L, Anguilla!$B:$B, $A3, Anguilla!$D:$D, "Out Ports") -> 3.2446429 | D3: =B3+C3 -> 5.2821429
A4: Brown Sugar | B4: =SUMIFS(Antigua!$L:$L, Antigua!$B:$B, $A4, Antigua!$D:$D, "London") + SUMIFS(Barbados!$L:$L, Barbados!$B:$B, $A4, Barbados!$D:$D, "London") + SUMIFS(Bermuda!$L:$L, Bermuda!$B:$B, $A4, Bermuda!$D:$D, "London") + SUMIFS(Jamaica!$L:$L, Jamaica!$B:$B, $A4, Jamaica!$D:$D, "London") + SUMIFS(Mountserat!$L:$L, Mountserat!$B:$B, $A4, Mountserat!$D:$D, "London") + SUMIFS(Nevis!$L:$L, Nevis!$B:$B, $A4, Nevis!$D:$D, "London") + SUMIFS('St Kitts'!$L:$L, 'St Kitts'!$B:$B, $A4, 'St Kitts'!$D:$D, "London") + SUMIFS(WestIndiesGeneral!$L:$L, WestIndiesGeneral!$B:$B, $A4, WestIndiesGeneral!$D:$D, "London") + SUMIFS(Tortola!$L:$L, Tortola!$B:$B, $A4, Tortola!$D:$D, "London") + SUMIFS(Anguilla!$L:$L, Anguilla!$B:$B, $A4, Anguilla!$D:$D, "London") -> 35830.193 | C4: =SUMIFS(Antigua!$L:$L, Antigua!$B:$B, $A4, Antigua!$D:$D, "Out Ports") + SUMIFS(Barbados!$L:$L, Barbados!$B:$B, $A4, Barbados!$D:$D, "Out Ports") + SUMIFS(Bermuda!$L:$L, Bermuda!$B:$B, $A4, Bermuda!$D:$D, "Out Ports") + SUMIFS(Jamaica!$L:$L, Jamaica!$B:$B, $A4, Jamaica!$D:$D, "Out Ports") + SUMIFS(Mountserat!$L:$L, Mountserat!$B:$B, $A4, Mountserat!$D:$D, "Out Ports") + SUMIFS(Nevis!$L:$L, Nevis!$B:$B, $A4, Nevis!$D:$D, "Out Ports") + SUMIFS('St Kitts'!$L:$L, 'St Kitts'!$B:$B, $A4, 'St Kitts'!$D:$D, "Out Ports") + SUMIFS(WestIndiesGeneral!$L:$L, WestIndiesGeneral!$B:$B, $A4, WestIndiesGeneral!$D:$D, "Out Ports") + SUMIFS(Tortola!$L:$L, Tortola!$B:$B, $A4, Tortola!$D:$D, "Out Ports") + SUMIFS(Anguilla!$L:$L, Anguilla!$B:$B, $A4, Anguilla!$D:$D, "Out Ports") -> 13204.562 | D4: =B4+C4 -> 49034.756
A5: Chocolate | B5: =SUMIFS(Antigua!$L:$L, Antigua!$B:$B, $A5, Antigua!$D:$D, "London") + SUMIFS(Barbados!$L:$L, Barbados!$B:$B, $A5, Barbados!$D:$D, "London") + SUMIFS(Bermuda!$L:$L, Bermuda!$B:$B, $A5, Bermuda!$D:$D, "London") + SUMIFS(Jamaica!$L:$L, Jamaica!$B:$B, $A5, Jamaica!$D:$D, "London") + SUMIFS(Mountserat!$L:$L, Mountserat!$B:$B, $A5, Mountserat!$D:$D, "London") + SUMIFS(Nevis!$L:$L, Nevis!$B:$B, $A5, Nevis!$D:$D, "London") + SUMIFS('St Kitts'!$L:$L, 'St Kitts'!$B:$B, $A5, 'St Kitts'!$D:$D, "London") + SUMIFS(WestIndiesGeneral!$L:$L, WestIndiesGeneral!$B:$B, $A5, WestIndiesGeneral!$D:$D, "London") + SUMIFS(Tortola!$L:$L, Tortola!$B:$B, $A5, Tortola!$D:$D, "London") + SUMIFS(Anguilla!$L:$L, Anguilla!$B:$B, $A5, Anguilla!$D:$D, "London") -> 0 | C5: =SUMIFS(Antigua!$L:$L, Antigua!$B:$B, $A5, Antigua!$D:$D, "Out Ports") + SUMIFS(Barbados!$L:$L, Barbados!$B:$B, $A5, Barbados!$D:$D, "Out Ports") + SUMIFS(Bermuda!$L:$L, Bermuda!$B:$B, $A5, Bermuda!$D:$D, "Out Ports") + SUMIFS(Jamaica!$L:$L, Jamaica!$B:$B, $A5, Jamaica!$D:$D, "Out Ports") + SUMIFS(Mountserat!$L:$L, Mountserat!$B:$B, $A5, Mountserat!$D:$D, "Out Ports") + SUMIFS(Nevis!$L:$L, Nevis!$B:$B, $A5, Nevis!$D:$D, "Out Ports") + SUMIFS('St Kitts'!$L:$L, 'St Kitts'!$B:$B, $A5, 'St Kitts'!$D:$D, "Out Ports") + SUMIFS(WestIndiesGeneral!$L:$L, WestIndiesGeneral!$B:$B, $A5, WestIndiesGeneral!$D:$D, "Out Ports") + SUMIFS(Tortola!$L:$L, Tortola!$B:$B, $A5, Tortola!$D:$D, "Out Ports") + SUMIFS(Anguilla!$L:$L, Anguilla!$B:$B, $A5, Anguilla!$D:$D, "Out Ports") -> 0 | D5: =B5+C5 -> 0
A6: Cocoa Nuts | B6: =SUMIFS(Antigua!$L:$L, Antigua!$B:$B, $A6, Antigua!$D:$D, "London") + SUMIFS(Barbados!$L:$L, Barbados!$B:$B, $A6, Barbados!$D:$D, "London") + SUMIFS(Bermuda!$L:$L, Bermuda!$B:$B, $A6, Bermuda!$D:$D, "London") + SUMIFS(Jamaica!$L:$L, Jamaica!$B:$B, $A6, Jamaica!$D:$D, "London") + SUMIFS(Mountserat!$L:$L, Mountserat!$B:$B, $A6, Mountserat!$D:$D, "London") + SUMIFS(Nevis!$L:$L, Nevis!$B:$B, $A6, Nevis!$D:$D, "London") + SUMIFS('St Kitts'!$L:$L, 'St Kitts'!$B:$B, $A6, 'St Kitts'!$D:$D, "London") + SUMIFS(WestIndiesGeneral!$L:$L, WestIndiesGeneral!$B:$B, $A6, WestIndiesGeneral!$D:$D, "London") + SUMIFS(Tortola!$L:$L, Tortola!$B:$B, $A6, Tortola!$D:$D, "London") + SUMIFS(Anguilla!$L:$L, Anguilla!$B:$B, $A6, Anguilla!$D:$D, "London") -> 256.04509 | C6: =SUMIFS(Antigua!$L:$L, Antigua!$B:$B, $A6, Antigua!$D:$D, "Out Ports") + SUMIFS(Barbados!$L:$L, Barbados!$B:$B, $A6, Barbados!$D:$D, "Out Ports") + SUMIFS(Bermuda!$L:$L, Bermuda!$B:$B, $A6, Bermuda!$D:$D, "Out Ports") + SUMIFS(Jamaica!$L:$L, Jamaica!$B:$B, $A6, Jamaica!$D:$D, "Out Ports") + SUMIFS(Mountserat!$L:$L, Mountserat!$B:$B, $A6, Mountserat!$D:$D, "Out Ports") + SUMIFS(Nevis!$L:$L, Nevis!$B:$B, $A6, Nevis!$D:$D, "Out Ports") + SUMIFS('St Kitts'!$L:$L, 'St Kitts'!$B:$B, $A6, 'St Kitts'!$D:$D, "Out Ports") + SUMIFS(WestIndiesGeneral!$L:$L, WestIndiesGeneral!$B:$B, $A6, WestIndiesGeneral!$D:$D, "Out Ports") + SUMIFS(Tortola!$L:$L, Tortola!$B:$B, $A6, Tortola!$D:$D, "Out Ports") + SUMIFS(Anguilla!$L:$L, Anguilla!$B:$B, $A6, Anguilla!$D:$D, "Out Ports") -> 3.1066964 | D6: =B6+C6 -> 259.15179
A7: Cotton | B7: =SUMIFS(Antigua!$L:$L, Antigua!$B:$B, $A7, Antigua!$D:$D, "London") + SUMIFS(Barbados!$L:$L, Barbados!$B:$B, $A7, Barbados!$D:$D, "London") + SUMIFS(Bermuda!$L:$L, Bermuda!$B:$B, $A7, Bermuda!$D:$D, "London") + SUMIFS(Jamaica!$L:$L, Jamaica!$B:$B, $A7, Jamaica!$D:$D, "London") + SUMIFS(Mountserat!$L:$L, Mountserat!$B:$B, $A7, Mountserat!$D:$D, "London") + SUMIFS(Nevis!$L:$L, Nevis!$B:$B, $A7, Nevis!$D:$D, "London") + SUMIFS('St Kitts'!$L:$L, 'St Kitts'!$B:$B, $A7, 'St Kitts'!$D:$D, "London") + SUMIFS(WestIndiesGeneral!$L:$L, WestIndiesGeneral!$B:$B, $A7, WestIndiesGeneral!$D:$D, "London") + SUMIFS(Tortola!$L:$L, Tortola!$B:$B, $A7, Tortola!$D:$D, "London") + SUMIFS(Anguilla!$L:$L, Anguilla!$B:$B, $A7, Anguilla!$D:$D, "London") -> 175.40179 | C7: =SUMIFS(Antigua!$L:$L, Antigua!$B:$B, $A7, Antigua!$D:$D, "Out Ports") + SUMIFS(Barbados!$L:$L, Barbados!$B:$B, $A7, Barbados!$D:$D, "Out Ports") + SUMIFS(Bermuda!$L:$L, Bermuda!$B:$B, $A7, Bermuda!$D:$D, "Out Ports") + SUMIFS(Jamaica!$L:$L, Jamaica!$B:$B, $A7, Jamaica!$D:$D, "Out Ports") + SUMIFS(Mountserat!$L:$L, Mountserat!$B:$B, $A7, Mountserat!$D:$D, "Out Ports") + SUMIFS(Nevis!$L:$L, Nevis!$B:$B, $A7, Nevis!$D:$D, "Out Ports") + SUMIFS('St Kitts'!$L:$L, 'St Kitts'!$B:$B, $A7, 'St Kitts'!$D:$D, "Out Ports") + SUMIFS(WestIndiesGeneral!$L:$L, WestIndiesGeneral!$B:$B, $A7, WestIndiesGeneral!$D:$D, "Out Ports") + SUMIFS(Tortola!$L:$L, Tortola!$B:$B, $A7, Tortola!$D:$D, "Out Ports") + SUMIFS(Anguilla!$L:$L, Anguilla!$B:$B, $A7, Anguilla!$D:$D, "Out Ports") -> 1198.0357 | D7: =B7+C7 -> 1373.4375
A8: Dry Ginger | B8: =SUMIFS(Antigua!$L:$L, Antigua!$B:$B, $A8, Antigua!$D:$D, "London") + SUMIFS(Barbados!$L:$L, Barbados!$B:$B, $A8, Barbados!$D:$D, "London") + SUMIFS(Bermuda!$L:$L, Bermuda!$B:$B, $A8, Bermuda!$D:$D, "London") + SUMIFS(Jamaica!$L:$L, Jamaica!$B:$B, $A8, Jamaica!$D:$D, "London") + SUMIFS(Mountserat!$L:$L, Mountserat!$B:$B, $A8, Mountserat!$D:$D, "London") + SUMIFS(Nevis!$L:$L, Nevis!$B:$B, $A8, Nevis!$D:$D, "London") + SUMIFS('St Kitts'!$L:$L, 'St Kitts'!$B:$B, $A8, 'St Kitts'!$D:$D, "London") + SUMIFS(WestIndiesGeneral!$L:$L, WestIndiesGeneral!$B:$B, $A8, WestIndiesGeneral!$D:$D, "London") + SUMIFS(Tortola!$L:$L, Tortola!$B:$B, $A8, Tortola!$D:$D, "London") + SUMIFS(Anguilla!$L:$L, Anguilla!$B:$B, $A8, Anguilla!$D:$D, "London") -> 183.61607 | C8: =SUMIFS(Antigua!$L:$L, Antigua!$B:$B, $A8, Antigua!$D:$D, "Out Ports") + SUMIFS(Barbados!$L:$L, Barbados!$B:$B, $A8, Barbados!$D:$D, "Out Ports") + SUMIFS(Bermuda!$L:$L, Bermuda!$B:$B, $A8, Bermuda!$D:$D, "Out Ports") + SUMIFS(Jamaica!$L:$L, Jamaica!$B:$B, $A8, Jamaica!$D:$D, "Out Ports") + SUMIFS(Mountserat!$L:$L, Mountserat!$B:$B, $A8, Mountserat!$D:$D, "Out Ports") + SUMIFS(Nevis!$L:$L, Nevis!$B:$B, $A8, Nevis!$D:$D, "Out Ports") + SUMIFS('St Kitts'!$L:$L, 'St Kitts'!$B:$B, $A8, 'St Kitts'!$D:$D, "Out Ports") + SUMIFS(WestIndiesGeneral!$L:$L, WestIndiesGeneral!$B:$B, $A8, WestIndiesGeneral!$D:$D, "Out Ports") + SUMIFS(Tortola!$L:$L, Tortola!$B:$B, $A8, Tortola!$D:$D, "Out Ports") + SUMIFS(Anguilla!$L:$L, Anguilla!$B:$B, $A8, Anguilla!$D:$D, "Out Ports") -> 86.53125 | D8: =B8+C8 -> 270.14732
A9: Elephant Teeth | B9: =SUMIFS(Antigua!$L:$L, Antigua!$B:$B, $A9, Antigua!$D:$D, "London") + SUMIFS(Barbados!$L:$L, Barbados!$B:$B, $A9, Barbados!$D:$D, "London") + SUMIFS(Bermuda!$L:$L, Bermuda!$B:$B, $A9, Bermuda!$D:$D, "London") + SUMIFS(Jamaica!$L:$L, Jamaica!$B:$B, $A9, Jamaica!$D:$D, "London") + SUMIFS(Mountserat!$L:$L, Mountserat!$B:$B, $A9, Mountserat!$D:$D, "London") + SUMIFS(Nevis!$L:$L, Nevis!$B:$B, $A9, Nevis!$D:$D, "London") + SUMIFS('St Kitts'!$L:$L, 'St Kitts'!$B:$B, $A9, 'St Kitts'!$D:$D, "London") + SUMIFS(WestIndiesGeneral!$L:$L, WestIndiesGeneral!$B:$B, $A9, WestIndiesGeneral!$D:$D, "London") + SUMIFS(Tortola!$L:$L, Tortola!$B:$B, $A9, Tortola!$D:$D, "London") + SUMIFS(Anguilla!$L:$L, Anguilla!$B:$B, $A9, Anguilla!$D:$D, "London") -> 27.625 | C9: =SUMIFS(Antigua!$L:$L, Antigua!$B:$B, $A9, Antigua!$D:$D, "Out Ports") + SUMIFS(Barbados!$L:$L, Barbados!$B:$B, $A9, Barbados!$D:$D, "Out Ports") + SUMIFS(Bermuda!$L:$L, Bermuda!$B:$B, $A9, Bermuda!$D:$D, "Out Ports") + SUMIFS(Jamaica!$L:$L, Jamaica!$B:$B, $A9, Jamaica!$D:$D, "Out Ports") + SUMIFS(Mountserat!$L:$L, Mountserat!$B:$B, $A9, Mountserat!$D:$D, "Out Ports") + SUMIFS(Nevis!$L:$L, Nevis!$B:$B, $A9, Nevis!$D:$D, "Out Ports") + SUMIFS('St Kitts'!$L:$L, 'St Kitts'!$B:$B, $A9, 'St Kitts'!$D:$D, "Out Ports") + SUMIFS(WestIndiesGeneral!$L:$L, WestIndiesGeneral!$B:$B, $A9, WestIndiesGeneral!$D:$D, "Out Ports") + SUMIFS(Tortola!$L:$L, Tortola!$B:$B, $A9, Tortola!$D:$D, "Out Ports") + SUMIFS(Anguilla!$L:$L, Anguilla!$B:$B, $A9, Anguilla!$D:$D, "Out Ports") -> 41.290179 | D9: =B9+C9 -> 68.915179
A10: Indigo | B10: =SUMIFS(Antigua!$L:$L, Antigua!$B:$B, $A10, Antigua!$D:$D, "London") + SUMIFS(Barbados!$L:$L, Barbados!$B:$B, $A10, Barbados!$D:$D, "London") + SUMIFS(Bermuda!$L:$L, Bermuda!$B:$B, $A10, Bermuda!$D:$D, "London") + SUMIFS(Jamaica!$L:$L, Jamaica!$B:$B, $A10, Jamaica!$D:$D, "London") + SUMIFS(Mountserat!$L:$L, Mountserat!$B:$B, $A10, Mountserat!$D:$D, "London") + SUMIFS(Nevis!$L:$L, Nevis!$B:$B, $A10, Nevis!$D:$D, "London") + SUMIFS('St Kitts'!$L:$L, 'St Kitts'!$B:$B, $A10, 'St Kitts'!$D:$D, "London") + SUMIFS(WestIndiesGeneral!$L:$L, WestIndiesGeneral!$B:$B, $A10, WestIndiesGeneral!$D:$D, "London") + SUMIFS(Tortola!$L:$L, Tortola!$B:$B, $A10, Tortola!$D:$D, "London") + SUMIFS(Anguilla!$L:$L, Anguilla!$B:$B, $A10, Anguilla!$D:$D, "London") -> 83.066964 | C10: =SUMIFS(Antigua!$L:$L, Antigua!$B:$B, $A10, Antigua!$D:$D, "Out Ports") + SUMIFS(Barbados!$L:$L, Barbados!$B:$B, $A10, Barbados!$D:$D, "Out Ports") + SUMIFS(Bermuda!$L:$L, Bermuda!$B:$B, $A10, Bermuda!$D:$D, "Out Ports") + SUMIFS(Jamaica!$L:$L, Jamaica!$B:$B, $A10, Jamaica!$D:$D, "Out Ports") + SUMIFS(Mountserat!$L:$L, Mountserat!$B:$B, $A10, Mountserat!$D:$D, "Out Ports") + SUMIFS(Nevis!$L:$L, Nevis!$B:$B, $A10, Nevis!$D:$D, "Out Ports") + SUMIFS('St Kitts'!$L:$L, 'St Kitts'!$B:$B, $A10, 'St Kitts'!$D:$D, "Out Ports") + SUMIFS(WestIndiesGeneral!$L:$L, WestIndiesGeneral!$B:$B, $A10, WestIndiesGeneral!$D:$D, "Out Ports") + SUMIFS(Tortola!$L:$L, Tortola!$B:$B, $A10, Tortola!$D:$D, "Out Ports") + SUMIFS(Anguilla!$L:$L, Anguilla!$B:$B, $A10, Anguilla!$D:$D, "Out Ports") -> 43.133036 | D10: =B10+C10 -> 126.2
A11: Lignum Vitae | B11: =SUMIFS(Antigua!$L:$L, Antigua!$B:$B, $A11, Antigua!$D:$D, "London") + SUMIFS(Barbados!$L:$L, Barbados!$B:$B, $A11, Barbados!$D:$D, "London") + SUMIFS(Bermuda!$L:$L, Bermuda!$B:$B, $A11, Bermuda!$D:$D, "London") + SUMIFS(Jamaica!$L:$L, Jamaica!$B:$B, $A11, Jamaica!$D:$D, "London") + SUMIFS(Mountserat!$L:$L, Mountserat!$B:$B, $A11, Mountserat!$D:$D, "London") + SUMIFS(Nevis!$L:$L, Nevis!$B:$B, $A11, Nevis!$D:$D, "London") + SUMIFS('St Kitts'!$L:$L, 'St Kitts'!$B:$B, $A11, 'St Kitts'!$D:$D, "London") + SUMIFS(WestIndiesGeneral!$L:$L, WestIndiesGeneral!$B:$B, $A11, WestIndiesGeneral!$D:$D, "London") + SUMIFS(Tortola!$L:$L, Tortola!$B:$B, $A11, Tortola!$D:$D, "London") + SUMIFS(Anguilla!$L:$L, Anguilla!$B:$B, $A11, Anguilla!$D:$D, "London") -> 106.36875 | C11: =SUMIFS(Antigua!$L:$L, Antigua!$B:$B, $A11, Antigua!$D:$D, "Out Ports") + SUMIFS(Barbados!$L:$L, Barbados!$B:$B, $A11, Barbados!$D:$D, "Out Ports") + SUMIFS(Bermuda!$L:$L, Bermuda!$B:$B, $A11, Bermuda!$D:$D, "Out Ports") + SUMIFS(Jamaica!$L:$L, Jamaica!$B:$B, $A11, Jamaica!$D:$D, "Out Ports") + SUMIFS(Mountserat!$L:$L, Mountserat!$B:$B, $A11, Mountserat!$D:$D, "Out Ports") + SUMIFS(Nevis!$L:$L, Nevis!$B:$B, $A11, Nevis!$D:$D, "Out Ports") + SUMIFS('St Kitts'!$L:$L, 'St Kitts'!$B:$B, $A11, 'St Kitts'!$D:$D, "Out Ports") + SUMIFS(WestIndiesGeneral!$L:$L, WestIndiesGeneral!$B:$B, $A11, WestIndiesGeneral!$D:$D, "Out Ports") + SUMIFS(Tortola!$L:$L, Tortola!$B:$B, $A11, Tortola!$D:$D, "Out Ports") + SUMIFS(Anguilla!$L:$L, Anguilla!$B:$B, $A11, Anguilla!$D:$D, "Out Ports") -> 26.15 | D11: =B11+C11 -> 132.51875
A12: Lime Juice | B12: =SUMIFS(Antigua!$L:$L, Antigua!$B:$B, $A12, Antigua!$D:$D, "London") + SUMIFS(Barbados!$L:$L, Barbados!$B:$B, $A12, Barbados!$D:$D, "London") + SUMIFS(Bermuda!$L:$L, Bermuda!$B:$B, $A12, Bermuda!$D:$D, "London") + SUMIFS(Jamaica!$L:$L, Jamaica!$B:$B, $A12, Jamaica!$D:$D, "London") + SUMIFS(Mountserat!$L:$L, Mountserat!$B:$B, $A12, Mountserat!$D:$D, "London") + SUMIFS(Nevis!$L:$L, Nevis!$B:$B, $A12, Nevis!$D:$D, "London") + SUMIFS('St Kitts'!$L:$L, 'St Kitts'!$B:$B, $A12, 'St Kitts'!$D:$D, "London") + SUMIFS(WestIndiesGeneral!$L:$L, WestIndiesGeneral!$B:$B, $A12, WestIndiesGeneral!$D:$D, "London") + SUMIFS(Tortola!$L:$L, Tortola!$B:$B, $A12, Tortola!$D:$D, "London") + SUMIFS(Anguilla!$L:$L, Anguilla!$B:$B, $A12, Anguilla!$D:$D, "London") -> 0 | C12: =SUMIFS(Antigua!$L:$L, Antigua!$B:$B, $A12, Antigua!$D:$D, "Out Ports") + SUMIFS(Barbados!$L:$L, Barbados!$B:$B, $A12, Barbados!$D:$D, "Out Ports") + SUMIFS(Bermuda!$L:$L, Bermuda!$B:$B, $A12, Bermuda!$D:$D, "Out Ports") + SUMIFS(Jamaica!$L:$L, Jamaica!$B:$B, $A12, Jamaica!$D:$D, "Out Ports") + SUMIFS(Mountserat!$L:$L, Mountserat!$B:$B, $A12, Mountserat!$D:$D, "Out Ports") + SUMIFS(Nevis!$L:$L, Nevis!$B:$B, $A12, Nevis!$D:$D, "Out Ports") + SUMIFS('St Kitts'!$L:$L, 'St Kitts'!$B:$B, $A12, 'St Kitts'!$D:$D, "Out Ports") + SUMIFS(WestIndiesGeneral!$L:$L, WestIndiesGeneral!$B:$B, $A12, WestIndiesGeneral!$D:$D, "Out Ports") + SUMIFS(Tortola!$L:$L, Tortola!$B:$B, $A12, Tortola!$D:$D, "Out Ports") + SUMIFS(Anguilla!$L:$L, Anguilla!$B:$B, $A12, Anguilla!$D:$D, "Out Ports") -> 0 | D12: =B12+C12 -> 0
A13: Molasses | B13: =SUMIFS(Antigua!$L:$L, Antigua!$B:$B, $A13, Antigua!$D:$D, "London") + SUMIFS(Barbados!$L:$L, Barbados!$B:$B, $A13, Barbados!$D:$D, "London") + SUMIFS(Bermuda!$L:$L, Bermuda!$B:$B, $A13, Bermuda!$D:$D, "London") + SUMIFS(Jamaica!$L:$L, Jamaica!$B:$B, $A13, Jamaica!$D:$D, "London") + SUMIFS(Mountserat!$L:$L, Mountserat!$B:$B, $A13, Mountserat!$D:$D, "London") + SUMIFS(Nevis!$L:$L, Nevis!$B:$B, $A13, Nevis!$D:$D, "London") + SUMIFS('St Kitts'!$L:$L, 'St Kitts'!$B:$B, $A13, 'St Kitts'!$D:$D, "London") + SUMIFS(WestIndiesGeneral!$L:$L, WestIndiesGeneral!$B:$B, $A13, WestIndiesGeneral!$D:$D, "London") + SUMIFS(Tortola!$L:$L, Tortola!$B:$B, $A13, Tortola!$D:$D, "London") + SUMIFS(Anguilla!$L:$L, Anguilla!$B:$B, $A13, Anguilla!$D:$D, "London") -> 0.64375 | C13: =SUMIFS(Antigua!$L:$L, Antigua!$B:$B, $A13, Antigua!$D:$D, "Out Ports") + SUMIFS(Barbados!$L:$L, Barbados!$B:$B, $A13, Barbados!$D:$D, "Out Ports") + SUMIFS(Bermuda!$L:$L, Bermuda!$B:$B, $A13, Bermuda!$D:$D, "Out Ports") + SUMIFS(Jamaica!$L:$L, Jamaica!$B:$B, $A13, Jamaica!$D:$D, "Out Ports") + SUMIFS(Mountserat!$L:$L, Mountserat!$B:$B, $A13, Mountserat!$D:$D, "Out Ports") + SUMIFS(Nevis!$L:$L, Nevis!$B:$B, $A13, Nevis!$D:$D, "Out Ports") + SUMIFS('St Kitts'!$L:$L, 'St Kitts'!$B:$B, $A13, 'St Kitts'!$D:$D, "Out Ports") + SUMIFS(WestIndiesGeneral!$L:$L, WestIndiesGeneral!$B:$B, $A13, WestIndiesGeneral!$D:$D, "Out Ports") + SUMIFS(Tortola!$L:$L, Tortola!$B:$B, $A13, Tortola!$D:$D, "Out Ports") + SUMIFS(Anguilla!$L:$L, Anguilla!$B:$B, $A13, Anguilla!$D:$D, "Out Ports") -> 0 | D13: =B13+C13 -> 0.64375
... A30: Wood, Redwood | B30: =SUMIFS(Antigua!$L:$L, Antigua!$B:$B, $A30, Antigua!$D:$D, "London") + SUMIFS(Barbados!$L:$L, Barbados!$B:$B, $A30, Barbados!$D:$D, "London") + SUMIFS(Bermuda!$L:$L, Bermuda!$B:$B, $A30, Bermuda!$D:$D, "London") + SUMIFS(Jamaica!$L:$L, Jamaica!$B:$B, $A30, Jamaica!$D:$D, "London") + SUMIFS(Mountserat!$L:$L, Mountserat!$B:$B, $A30, Mountserat!$D:$D, "London") + SUMIFS(Nevis!$L:$L, Nevis!$B:$B, $A30, Nevis!$D:$D, "London") + SUMIFS('St Kitts'!$L:$L, 'St Kitts'!$B:$B, $A30, 'St Kitts'!$D:$D, "London") + SUMIFS(WestIndiesGeneral!$L:$L, WestIndiesGeneral!$B:$B, $A30, WestIndiesGeneral!$D:$D, "London") + SUMIFS(Tortola!$L:$L, Tortola!$B:$B, $A30, Tortola!$D:$D, "London") + SUMIFS(Anguilla!$L:$L, Anguilla!$B:$B, $A30, Anguilla!$D:$D, "London") -> 18.9 | C30: =SUMIFS(Antigua!$L:$L, Antigua!$B:$B, $A30, Antigua!$D:$D, "Out Ports") + SUMIFS(Barbados!$L:$L, Barbados!$B:$B, $A30, Barbados!$D:$D, "Out Ports") + SUMIFS(Bermuda!$L:$L, Bermuda!$B:$B, $A30, Bermuda!$D:$D, "Out Ports") + SUMIFS(Jamaica!$L:$L, Jamaica!$B:$B, $A30, Jamaica!$D:$D, "Out Ports") + SUMIFS(Mountserat!$L:$L, Mountserat!$B:$B, $A30, Mountserat!$D:$D, "Out Ports") + SUMIFS(Nevis!$L:$L, Nevis!$B:$B, $A30, Nevis!$D:$D, "Out Ports") + SUMIFS('St Kitts'!$L:$L, 'St Kitts'!$B:$B, $A30, 'St Kitts'!$D:$D, "Out Ports") + SUMIFS(WestIndiesGeneral!$L:$L, WestIndiesGeneral!$B:$B, $A30, WestIndiesGeneral!$D:$D, "Out Ports") + SUMIFS(Tortola!$L:$L, Tortola!$B:$B, $A30, Tortola!$D:$D, "Out Ports") + SUMIFS(Anguilla!$L:$L, Anguilla!$B:$B, $A30, Anguilla!$D:$D, "Out Ports") -> 56.070089 | D30: =B30+C30 -> 74.970089
A31: Wood, Sweetwood | B31: =SUMIFS(Antigua!$L:$L, Antigua!$B:$B, $A31, Antigua!$D:$D, "London") + SUMIFS(Barbados!$L:$L, Barbados!$B:$B, $A31, Barbados!$D:$D, "London") + SUMIFS(Bermuda!$L:$L, Bermuda!$B:$B, $A31, Bermuda!$D:$D, "London") + SUMIFS(Jamaica!$L:$L, Jamaica!$B:$B, $A31, Jamaica!$D:$D, "London") + SUMIFS(Mountserat!$L:$L, Mountserat!$B:$B, $A31, Mountserat!$D:$D, "London") + SUMIFS(Nevis!$L:$L, Nevis!$B:$B, $A31, Nevis!$D:$D, "London") + SUMIFS('St Kitts'!$L:$L, 'St Kitts'!$B:$B, $A31, 'St Kitts'!$D:$D, "London") + SUMIFS(WestIndiesGeneral!$L:$L, WestIndiesGeneral!$B:$B, $A31, WestIndiesGeneral!$D:$D, "London") -> 0 | C31: =SUMIFS(Antigua!$L:$L, Antigua!$B:$B, $A31, Antigua!$D:$D, "Out Ports") + SUMIFS(Barbados!$L:$L, Barbados!$B:$B, $A31, Barbados!$D:$D, "Out Ports") + SUMIFS(Bermuda!$L:$L, Bermuda!$B:$B, $A31, Bermuda!$D:$D, "Out Ports") + SUMIFS(Jamaica!$L:$L, Jamaica!$B:$B, $A31, Jamaica!$D:$D, "Out Ports") + SUMIFS(Mountserat!$L:$L, Mountserat!$B:$B, $A31, Mountserat!$D:$D, "Out Ports") + SUMIFS(Nevis!$L:$L, Nevis!$B:$B, $A31, Nevis!$D:$D, "Out Ports") + SUMIFS('St Kitts'!$L:$L, 'St Kitts'!$B:$B, $A31, 'St Kitts'!$D:$D, "Out Ports") + SUMIFS(WestIndiesGeneral!$L:$L, WestIndiesGeneral!$B:$B, $A31, WestIndiesGeneral!$D:$D, "Out Ports") + SUMIFS(Tortola!$L:$L, Tortola!$B:$B, $A31, Tortola!$D:$D, "Out Ports") + SUMIFS(Anguilla!$L:$L, Anguilla!$B:$B, $A31, Anguilla!$D:$D, "Out Ports") -> 0 | D31: =B31+C31 -> 0

Sheet Anguilla
A1: YEAR | B1: COMMODITY_NAME | C1: FROM_LOCATION | D1: TO_LOCATION | E1: ton | F1: hh | G1: quarter | H1: lb | J1: Total Pounds | L1: WEIGHT
A2: 1748 | B2: Almonds, Bitter | C2: Anguilla | D2: London | J2: =(E2*2240)+(F2*112)+(G2*28)+H2 -> 0 | L2: =J2/2240 -> 0
A3: 1748 | B3: Almonds, Sweet | C3: Anguilla | D3: London | J3: =(E3*2240)+(F3*112)+(G3*28)+H3 -> 0 | L3: =J3/2240 -> 0
A4: 1748 | B4: Aloes Epatica | C4: Anguilla | D4: London | J4: =(E4*2240)+(F4*112)+(G4*28)+H4 -> 0 | L4: =J4/2240 -> 0
A5: 1748 | B5: Annatto | C5: Anguilla | D5: London | J5: =(E5*2240)+(F5*112)+(G5*28)+H5 -> 0 | L5: =J5/2240 -> 0
A6: 1748 | B6: Anniseeds | C6: Anguilla | D6: London | J6: =(E6*2240)+(F6*112)+(G6*28)+H6 -> 0 | L6: =J6/2240 -> 0
A7: 1748 | B7: Bacon | C7: Anguilla | D7: London | J7: =(E7*2240)+(F7*112)+(G7*28)+H7 -> 0 | L7: =J7/2240 -> 0
A8: 1748 | B8: Barrel Staves | C8: Anguilla | D8: London | J8: =(E8*2240)+(F8*112)+(G8*28)+H8 -> 0 | L8: =J8/2240 -> 0
A9: 1748 | B9: Bay Berries | C9: Anguilla | D9: London | J9: =(E9*2240)+(F9*112)+(G9*28)+H9 -> 0 | L9: =J9/2240 -> 0
A10: 1748 | B10: Bees Wax | C10: Anguilla | D10: London | J10: =(E10*2240)+(F10*112)+(G10*28)+H10 -> 0 | L10: =J10/2240 -> 0
A11: 1748 | B11: Brimstone | C11: Anguilla | D11: London | J11: =(E11*2240)+(F11*112)+(G11*28)+H11 -> 0 | L11: =J11/2240 -> 0
A12: 1748 | B12: Brown Sugar | C12: Anguilla | D12: London | J12: =(E12*2240)+(F12*112)+(G12*28)+H12 -> 0 | L12: =J12/2240 -> 0
A13: 1748 | B13: Cassia Fistula | C13: Anguilla | D13: London | J13: =(E13*2240)+(F13*112)+(G13*28)+H13 -> 0 | L13: =J13/2240 -> 0
... A62: 1748 | B62: Annatto | C62: Anguilla | D62: Out Ports | J62: =(E62*2240)+(F62*112)+(G62*28)+H62 -> 0 | L62: =J62/2240 -> 0
A63: 1748 | B63: Brown Sugar | C63: Anguilla | D63: Out Ports | F63: 280 | J63: =(E63*2240)+(F63*112)+(G63*28)+H63 -> 31360 | L63: =J63/2240 -> 14
A64: 1748 | B64: Cassia Fistula | C64: Anguilla | D64: Out Ports | J64: =(E64*2240)+(F64*112)+(G64*28)+H64 -> 0 | L64: =J64/2240 -> 0
A65: 1748 | B65: Chocolate | C65: Anguilla | D65: Out Ports | J65: =(E65*2240)+(F65*112)+(G65*28)+H65 -> 0 | L65: =J65/2240 -> 0
A66: 1748 | B66: Cocoa Nuts | C66: Anguilla | D66: Out Ports | J66: =(E66*2240)+(F66*112)+(G66*28)+H66 -> 0 | L66: =J66/2240 -> 0
A67: 1748 | B67: Cotton | C67: Anguilla | D67: Out Ports | H67: =52*200 -> 10400 | I67: 52bags | J67: =(E67*2240)+(F67*112)+(G67*28)+H67 -> 10400 | L67: =J67/2240 -> 4.6428571
A68: 1748 | B68: Dry Ginger | C68: Anguilla | D68: Out Ports | J68: =(E68*2240)+(F68*112)+(G68*28)+H68 -> 0 | L68: =J68/2240 -> 0
A69: 1748 | B69: Elephant Teeth | C69: Anguilla | D69: Out Ports | J69: =(E69*2240)+(F69*112)+(G69*28)+H69 -> 0 | L69: =J69/2240 -> 0
A70: 1748 | B70: Indigo | C70: Anguilla | D70: Out Ports | J70: =(E70*2240)+(F70*112)+(G70*28)+H70 -> 0 | L70: =J70/2240 -> 0
A71: 1748 | B71: Lignum Vitae | C71: Anguilla | D71: Out Ports | E71: 2 | J71: =(E71*2240)+(F71*112)+(G71*28)+H71 -> 4480 | L71: =J71/2240 -> 2
A72: 1748 | B72: Lime Juice | C72: Anguilla | D72: Out Ports | J72: =(E72*2240)+(F72*112)+(G72*28)+H72 -> 0 | L72: =J72/2240 -> 0
A73: 1748 | B73: Madera Wine | C73: Anguilla | D73: Out Ports | J73: =(E73*2240)+(F73*112)+(G73*28)+H73 -> 0 | L73: =J73/2240 -> 0
A74: 1748 | B74: Molasses | C74: Anguilla | D74: Out Ports | J74: =(E74*2240)+(F74*112)+(G74*28)+H74 -> 0 | L74: =J74/2240 -> 0
A75: 1748 | B75: Pimento | C75: Anguilla | D75: Out Ports | J75: =(E75*2240)+(F75*112)+(G75*28)+H75 -> 0 | L75: =J75/2240 -> 0
A76: 1748 | B76: Rice | C76: Anguilla | D76: Out Ports | J76: =(E76*2240)+(F76*112)+(G76*28)+H76 -> 0 | L76: =J76/2240 -> 0
A77: 1748 | B77: Rum | C77: Anguilla | D77: Out Ports | J77: =(E77*2240)+(F77*112)+(G77*28)+H77 -> 0 | L77: =J77/2240 -> 0
A78: 1748 | B78: Shruff | C78: Anguilla | D78: Out Ports | J78: =(E78*2240)+(F78*112)+(G78*28)+H78 -> 0 | L78: =J78/2240 -> 0
A79: 1748 | B79: Snuff | C79: Anguilla | D79: Out Ports | J79: =(E79*2240)+(F79*112)+(G79*28)+H79 -> 0 | L79: =J79/2240 -> 0
A80: 1748 | B80: Succads | C80: Anguilla | D80: Out Ports | J80: =(E80*2240)+(F80*112)+(G80*28)+H80 -> 0 | L80: =J80/2240 -> 0
A81: 1748 | B81: Tallow | C81: Anguilla | D81: Out Ports | J81: =(E81*2240)+(F81*112)+(G81*28)+H81 -> 0 | L81: =J81/2240 -> 0
A82: 1748 | B82: Tortoise Shell | C82: Anguilla | D82: Out Ports | J82: =(E82*2240)+(F82*112)+(G82*28)+H82 -> 0 | L82: =J82/2240 -> 0
A83: 1748 | B83: White Sugar | C83: Anguilla | D83: Out Ports | J83: =(E83*2240)+(F83*112)+(G83*28)+H83 -> 0 | L83: =J83/2240 -> 0
... A88: 1748 | B88: Wood, Redwood | C88: Anguilla | D88: Out Ports | J88: =(E88*2240)+(F88*112)+(G88*28)+H88 -> 0 | L88: =J88/2240 -> 0
J89: =(E89*2240)+(F89*112)+(G89*28)+H89 -> 0 | L89: =J89/2240 -> 0
J90: =(E90*2240)+(F90*112)+(G90*28)+H90 -> 0 | L90: =J90/2240 -> 0
J91: =(E91*2240)+(F91*112)+(G91*28)+H91 -> 0 | L91: =J91/2240 -> 0
J92: =(E92*2240)+(F92*112)+(G92*28)+H92 -> 0 | L92: =J92/2240 -> 0
...

Sheet Antigua
A1: YEAR | B1: COMMODITY_NAME | C1: FROM_LOCATION | D1: TO_LOCATION | E1: ton | F1: hh | G1: quarter | H1: lb | J1: Total Pounds | L1: WEIGHT
A2: 1748 | B2: Almonds, Bitter | C2: Antigua | D2: London | J2: =(E2*2240)+(F2*112)+(G2*28)+H2 -> 0 | L2: =J2/2240 -> 0
A3: 1748 | B3: Almonds, Sweet | C3: Antigua | D3: London | J3: =(E3*2240)+(F3*112)+(G3*28)+H3 -> 0 | L3: =J3/2240 -> 0
A4: 1748 | B4: Aloes Epatica | C4: Antigua | D4: London | J4: =(E4*2240)+(F4*112)+(G4*28)+H4 -> 0 | L4: =J4/2240 -> 0
A5: 1748 | B5: Annatto | C5: Antigua | D5: London | J5: =(E5*2240)+(F5*112)+(G5*28)+H5 -> 0 | L5: =J5/2240 -> 0
A6: 1748 | B6: Anniseeds | C6: Antigua | D6: London | J6: =(E6*2240)+(F6*112)+(G6*28)+H6 -> 0 | L6: =J6/2240 -> 0
A7: 1748 | B7: Bacon | C7: Antigua | D7: London | J7: =(E7*2240)+(F7*112)+(G7*28)+H7 -> 0 | L7: =J7/2240 -> 0
A8: 1748 | B8: Balsam Natural | C8: Antigua | D8: London | J8: =(E8*2240)+(F8*112)+(G8*28)+H8 -> 0 | L8: =J8/2240 -> 0
A9: 1748 | B9: Barrel Staves | C9: Antigua | D9: London | J9: =(E9*2240)+(F9*112)+(G9*28)+H9 -> 0 | L9: =J9/2240 -> 0
A10: 1748 | B10: Bay Berries | C10: Antigua | D10: London | J10: =(E10*2240)+(F10*112)+(G10*28)+H10 -> 0 | L10: =J10/2240 -> 0
A11: 1748 | B11: Bees Wax | C11: Antigua | D11: London | G11: 2 | J11: =(E11*2240)+(F11*112)+(G11*28)+H11 -> 56 | L11: =J11/2240 -> 0.025
A12: 1748 | B12: Brimstone | C12: Antigua | D12: London | J12: =(E12*2240)+(F12*112)+(G12*28)+H12 -> 0 | L12: =J12/2240 -> 0
A13: 1748 | B13: Brown Sugar | C13: Antigua | D13: London | F13: 142551 | G13: 2 | J13: =(E13*2240)+(F13*112)+(G13*28)+H13 -> 15965768 | L13: =J13/2240 -> 7127.575
A14: 1748 | B14: Cascarilla | C14: Antigua | D14: London | J14: =(E14*2240)+(F14*112)+(G14*28)+H14 -> 0 | L14: =J14/2240 -> 0
A15: 1748 | B15: Cassia Fistula | C15: Antigua | D15: London | H15: 8948 | J15: =(E15*2240)+(F15*112)+(G15*28)+H15 -> 8948 | L15: =J15/2240 -> 3.9946429
A16: 1748 | B16: Chocolate | C16: Antigua | D16: London | J16: =(E16*2240)+(F16*112)+(G16*28)+H16 -> 0 | L16: =J16/2240 -> 0
A17: 1748 | B17: Cocheneal | C17: Antigua | D17: London | J17: =(E17*2240)+(F17*112)+(G17*28)+H17 -> 0 | L17: =J17/2240 -> 0
A18: 1748 | B18: Cocoa Nuts | C18: Antigua | D18: London | F18: 130 | G18: 3 | H18: 10 | J18: =(E18*2240)+(F18*112)+(G18*28)+H18 -> 14654 | L18: =J18/2240 -> 6.5419643
A19: 1748 | B19: Cocoa Paste | C19: Antigua | D19: London | J19: =(E19*2240)+(F19*112)+(G19*28)+H19 -> 0 | L19: =J19/2240 -> 0
A20: 1748 | B20: Coffee | C20: Antigua | D20: London | J20: =(E20*2240)+(F20*112)+(G20*28)+H20 -> 0 | L20: =J20/2240 -> 0
A21: 1748 | B21: Cortex Peru | C21: Antigua | D21: London | J21: =(E21*2240)+(F21*112)+(G21*28)+H21 -> 0 | L21: =J21/2240 -> 0
A22: 1748 | B22: Cortex Winteranus | C22: Antigua | D22: London | J22: =(E22*2240)+(F22*112)+(G22*28)+H22 -> 0 | L22: =J22/2240 -> 0
A23: 1748 | B23: Cotton | C23: Antigua | D23: London | H23: =119.75*200 -> 23950 | I23: 119.75bags | J23: =(E23*2240)+(F23*112)+(G23*28)+H23 -> 23950 | L23: =J23/2240 -> 10.691964
A24: 1748 | B24: Dry Ginger | C24: Antigua | D24: London | J24: =(E24*2240)+(F24*112)+(G24*28)+H24 -> 0 | L24: =J24/2240 -> 0
A25: 1748 | B25: Elephant Teeth | C25: Antigua | D25: London | F25: 17 | H25: 16 | J25: =(E25*2240)+(F25*112)+(G25*28)+H25 -> 1920 | L25: =J25/2240 -> 0.85714286
A26: 1748 | B26: Green Ginger | C26: Antigua | D26: London | H26: 133 | J26: =(E26*2240)+(F26*112)+(G26*28)+H26 -> 133 | L26: =J26/2240 -> 0.059375
A27: 1748 | B27: Guinea Grains | C27: Antigua | D27: London | J27: =(E27*2240)+(F27*112)+(G27*28)+H27 -> 0 | L27: =J27/2240 -> 0
A28: 1748 | B28: Gum Guiaci | C28: Antigua | D28: London | J28: =(E28*2240)+(F28*112)+(G28*28)+H28 -> 0 | L28: =J28/2240 -> 0
A29: 1748 | B29: Gum Seneca | C29: Antigua | D29: London | J29: =(E29*2240)+(F29*112)+(G29*28)+H29 -> 0 | L29: =J29/2240 -> 0
A30: 1748 | B30: Hemp | C30: Antigua | D30: London | J30: =(E30*2240)+(F30*112)+(G30*28)+H30 -> 0 | L30: =J30/2240 -> 0
A31: 1748 | B31: Hypococania | C31: Antigua | D31: London | J31: =(E31*2240)+(F31*112)+(G31*28)+H31 -> 0 | L31: =J31/2240 -> 0
A32: 1748 | B32: Indigo | C32: Antigua | D32: London | J32: =(E32*2240)+(F32*112)+(G32*28)+H32 -> 0 | L32: =J32/2240 -> 0
A33: 1748 | B33: Jallop? | C33: Antigua | D33: London | J33: =(E33*2240)+(F33*112)+(G33*28)+H33 -> 0 | L33: =J33/2240 -> 0
A34: 1748 | B34: Lemon Water | C34: Antigua | D34: London | J34: =(E34*2240)+(F34*112)+(G34*28)+H34 -> 0 | L34: =J34/2240 -> 0
A35: 1748 | B35: Lignum Vitae | C35: Antigua | D35: London | E35: 12 | F35: 15 | G35: 3 | H35: 12 | J35: =(E35*2240)+(F35*112)+(G35*28)+H35 -> 28656 | L35: =J35/2240 -> 12.792857
A36: 1748 | B36: Lime Juice | C36: Antigua | D36: London | J36: =(E36*2240)+(F36*112)+(G36*28)+H36 -> 0 | L36: =J36/2240 -> 0
A37: 1748 | B37: Loaf Sugar | C37: Antigua | D37: London | J37: =(E37*2240)+(F37*112)+(G37*28)+H37 -> 0 | L37: =J37/2240 -> 0
A38: 1748 | B38: Madera Wine | C38: Antigua | D38: London | H38: 106297.5 | I38: 42t 43g | J38: =(E38*2240)+(F38*112)+(G38*28)+H38 -> 106297.5 | L38: =J38/2240 -> 47.454241
A39: 1748 | B39: Molasses | C39: Antigua | D39: London | J39: =(E39*2240)+(F39*112)+(G39*28)+H39 -> 0 | L39: =J39/2240 -> 0
A40: 1748 | B40: Oranges | C40: Antigua | D40: London | J40: =(E40*2240)+(F40*112)+(G40*28)+H40 -> 0 | L40: =J40/2240 -> 0
...

Sheet Barbados
A1: YEAR | B1: COMMODITY_NAME | C1: FROM_LOCATION | D1: TO_LOCATION | E1: ton | F1: hh | G1: quarter | H1: lb | J1: Total Pounds | L1: WEIGHT
A2: 1748 | B2: Almonds, Bitter | C2: Barbados | D2: London | J2: =(E2*2240)+(F2*112)+(G2*28)+H2 -> 0 | L2: =J2/2240 -> 0
A3: 1748 | B3: Almonds, Sweet | C3: Barbados | D3: London | J3: =(E3*2240)+(F3*112)+(G3*28)+H3 -> 0 | L3: =J3/2240 -> 0
A4: 1748 | B4: Aloes Epatica | C4: Barbados | D4: London | H4: 12332 | J4: =(E4*2240)+(F4*112)+(G4*28)+H4 -> 12332 | L4: =J4/2240 -> 5.5053571
A5: 1748 | B5: Annatto | C5: Barbados | D5: London | J5: =(E5*2240)+(F5*112)+(G5*28)+H5 -> 0 | L5: =J5/2240 -> 0
A6: 1748 | B6: Anniseeds | C6: Barbados | D6: London | J6: =(E6*2240)+(F6*112)+(G6*28)+H6 -> 0 | L6: =J6/2240 -> 0
A7: 1748 | B7: Balsam Artificial | C7: Barbados | D7: London | H7: 225 | J7: =(E7*2240)+(F7*112)+(G7*28)+H7 -> 225 | L7: =J7/2240 -> 0.10044643
A8: 1748 | B8: Balsam Capavia | C8: Barbados | D8: London | H8: 210 | J8: =(E8*2240)+(F8*112)+(G8*28)+H8 -> 210 | L8: =J8/2240 -> 0.09375
A9: 1748 | B9: Barbados T… | C9: Barbados | D9: London | H9: 5241 | J9: =(E9*2240)+(F9*112)+(G9*28)+H9 -> 5241 | L9: =J9/2240 -> 2.3397321
A10: 1748 | B10: Barrel Staves | C10: Barbados | D10: London | J10: =(E10*2240)+(F10*112)+(G10*28)+H10 -> 0 | L10: =J10/2240 -> 0
A11: 1748 | B11: Bees Wax | C11: Barbados | D11: London | F11: 40 | G11: 1 | J11: =(E11*2240)+(F11*112)+(G11*28)+H11 -> 4508 | L11: =J11/2240 -> 2.0125
A12: 1748 | B12: Brimstone | C12: Barbados | D12: London | J12: =(E12*2240)+(F12*112)+(G12*28)+H12 -> 0 | L12: =J12/2240 -> 0
A13: 1748 | B13: Brown Sugar | C13: Barbados | D13: London | F13: 114251 | G13: 1 | H13: 7 | J13: =(E13*2240)+(F13*112)+(G13*28)+H13 -> 12796147 | L13: =J13/2240 -> 5712.5656
A14: 1748 | B14: Cassia Fistula | C14: Barbados | D14: London | H14: 3580 | J14: =(E14*2240)+(F14*112)+(G14*28)+H14 -> 3580 | L14: =J14/2240 -> 1.5982143
A15: 1748 | B15: Chocolate | C15: Barbados | D15: London | J15: =(E15*2240)+(F15*112)+(G15*28)+H15 -> 0 | L15: =J15/2240 -> 0
A16: 1748 | B16: Cocheneal | C16: Barbados | D16: London | J16: =(E16*2240)+(F16*112)+(G16*28)+H16 -> 0 | L16: =J16/2240 -> 0
A17: 1748 | B17: Cocoa Nuts | C17: Barbados | D17: London | F17: 371 | J17: =(E17*2240)+(F17*112)+(G17*28)+H17 -> 41552 | L17: =J17/2240 -> 18.55
A18: 1748 | B18: Cocoa Paste | C18: Barbados | D18: London | J18: =(E18*2240)+(F18*112)+(G18*28)+H18 -> 0 | L18: =J18/2240 -> 0
A19: 1748 | B19: Coffee | C19: Barbados | D19: London | H19: 11 | J19: =(E19*2240)+(F19*112)+(G19*28)+H19 -> 11 | L19: =J19/2240 -> 0.0049107143
A20: 1748 | B20: Cortex Peru | C20: Barbados | D20: London | J20: =(E20*2240)+(F20*112)+(G20*28)+H20 -> 0 | L20: =J20/2240 -> 0
A21: 1748 | B21: Cotton | C21: Barbados | D21: London | H21: =223*200 -> 44600 | I21: 223bags | J21: =(E21*2240)+(F21*112)+(G21*28)+H21 -> 44600 | L21: =J21/2240 -> 19.910714
A22: 1748 | B22: Dry Ginger | C22: Barbados | D22: London | F22: 2508 | G22: 3 | H22: 18 | J22: =(E22*2240)+(F22*112)+(G22*28)+H22 -> 280998 | L22: =J22/2240 -> 125.44554
A23: 1748 | B23: Elephant Teeth | C23: Barbados | D23: London | F23: 327 | G23: 3 | J23: =(E23*2240)+(F23*112)+(G23*28)+H23 -> 36708 | L23: =J23/2240 -> 16.3875
A24: 1748 | B24: Green Ginger | C24: Barbados | D24: London | H24: 547 | J24: =(E24*2240)+(F24*112)+(G24*28)+H24 -> 547 | L24: =J24/2240 -> 0.24419643
A25: 1748 | B25: Gum Elemni | C25: Barbados | D25: London | H25: 1497 | J25: =(E25*2240)+(F25*112)+(G25*28)+H25 -> 1497 | L25: =J25/2240 -> 0.66830357
A26: 1748 | B26: Hemp | C26: Barbados | D26: London | J26: =(E26*2240)+(F26*112)+(G26*28)+H26 -> 0 | L26: =J26/2240 -> 0
A27: 1748 | B27: Indigo | C27: Barbados | D27: London | J27: =(E27*2240)+(F27*112)+(G27*28)+H27 -> 0 | L27: =J27/2240 -> 0
A28: 1748 | B28: Jollop | C28: Barbados | D28: London | H28: 985 | J28: =(E28*2240)+(F28*112)+(G28*28)+H28 -> 985 | L28: =J28/2240 -> 0.43973214
A29: 1748 | B29: Lemon Water | C29: Barbados | D29: London | J29: =(E29*2240)+(F29*112)+(G29*28)+H29 -> 0 | L29: =J29/2240 -> 0
A30: 1748 | B30: Lignum Vitae | C30: Barbados | D30: London | J30: =(E30*2240)+(F30*112)+(G30*28)+H30 -> 0 | L30: =J30/2240 -> 0
A31: 1748 | B31: Lime Juice | C31: Barbados | D31: London | J31: =(E31*2240)+(F31*112)+(G31*28)+H31 -> 0 | L31: =J31/2240 -> 0
A32: 1748 | B32: Loaf Sugar | C32: Barbados | D32: London | J32: =(E32*2240)+(F32*112)+(G32*28)+H32 -> 0 | L32: =J32/2240 -> 0
A33: 1748 | B33: Madera Wine | C33: Barbados | D33: London | H33: 196280.5 | I33: 77t 3h 30g | J33: =(E33*2240)+(F33*112)+(G33*28)+H33 -> 196280.5 | L33: =J33/2240 -> 87.625223
A34: 1748 | B34: Molasses | C34: Barbados | D34: London | J34: =(E34*2240)+(F34*112)+(G34*28)+H34 -> 0 | L34: =J34/2240 -> 0
A35: 1748 | B35: Oranges | C35: Barbados | D35: London | J35: =(E35*2240)+(F35*112)+(G35*28)+H35 -> 0 | L35: =J35/2240 -> 0
A36: 1748 | B36: Pickles | C36: Barbados | D36: London | H36: 510 | I36: 51g | J36: =(E36*2240)+(F36*112)+(G36*28)+H36 -> 510 | L36: =J36/2240 -> 0.22767857
A37: 1748 | B37: Pimento | C37: Barbados | D37: London | J37: =(E37*2240)+(F37*112)+(G37*28)+H37 -> 0 | L37: =J37/2240 -> 0
A38: 1748 | B38: Port | C38: Barbados | D38: London | H38: 35939 | I38: 14t 1h 2g | J38: =(E38*2240)+(F38*112)+(G38*28)+H38 -> 35939 | L38: =J38/2240 -> 16.044196
A39: 1748 | B39: Rice | C39: Barbados | D39: London | J39: =(E39*2240)+(F39*112)+(G39*28)+H39 -> 0 | L39: =J39/2240 -> 0
A40: 1748 | B40: Rum | C40: Barbados | D40: London | H40: 445164.5 | I40: 44505g | J40: =(E40*2240)+(F40*112)+(G40*28)+H40 -> 445164.5 | L40: =J40/2240 -> 198.73415
...

Sheet Bermuda
A1: YEAR | B1: COMMODITY_NAME | C1: FROM_LOCATION | D1: TO_LOCATION | E1: ton | F1: hh | G1: quarter | H1: lb | J1: Total Pounds | L1: WEIGHT
A2: 1748 | B2: Bermudos Plat | C2: Bermuda | D2: London | J2: =(E2*2240)+(F2*112)+(G2*28)+H2 -> 0 | L2: =J2/2240 -> 0
A3: 1748 | B3: Brown Sugar | C3: Bermuda | D3: London | J3: =(E3*2240)+(F3*112)+(G3*28)+H3 -> 0 | L3: =J3/2240 -> 0
A4: 1748 | B4: Cocoa Nuts | C4: Bermuda | D4: London | F4: 1 | G4: 2 | H4: 20 | J4: =(E4*2240)+(F4*112)+(G4*28)+H4 -> 188 | L4: =J4/2240 -> 0.083928571
A5: 1748 | B5: Cotton | C5: Bermuda | D5: London | H5: =1.25*200 -> 250 | I5: 1.25bags | J5: =(E5*2240)+(F5*112)+(G5*28)+H5 -> 250 | L5: =J5/2240 -> 0.11160714
A6: 1748 | B6: Elephant Teeth | C6: Bermuda | D6: London | J6: =(E6*2240)+(F6*112)+(G6*28)+H6 -> 0 | L6: =J6/2240 -> 0
A7: 1748 | B7: Indigo | C7: Bermuda | D7: London | J7: =(E7*2240)+(F7*112)+(G7*28)+H7 -> 0 | L7: =J7/2240 -> 0
A8: 1748 | B8: Madera Wine | C8: Bermuda | D8: London | H8: 1890.5 | I8: 3h | J8: =(E8*2240)+(F8*112)+(G8*28)+H8 -> 1890.5 | L8: =J8/2240 -> 0.84397321
A9: 1748 | B9: Molasses | C9: Bermuda | D9: London | J9: =(E9*2240)+(F9*112)+(G9*28)+H9 -> 0 | L9: =J9/2240 -> 0
A10: 1748 | B10: Rice | C10: Bermuda | D10: London | J10: =(E10*2240)+(F10*112)+(G10*28)+H10 -> 0 | L10: =J10/2240 -> 0
A11: 1748 | B11: Rum | C11: Bermuda | D11: London | H11: 1470.5 | I11: 147g | J11: =(E11*2240)+(F11*112)+(G11*28)+H11 -> 1470.5 | L11: =J11/2240 -> 0.65647321
A12: 1748 | B12: Shruff | C12: Bermuda | D12: London | J12: =(E12*2240)+(F12*112)+(G12*28)+H12 -> 0 | L12: =J12/2240 -> 0
A13: 1748 | B13: Tortoise Shell | C13: Bermuda | D13: London | H13: 12 | J13: =(E13*2240)+(F13*112)+(G13*28)+H13 -> 12 | L13: =J13/2240 -> 0.0053571429
A14: 1748 | B14: Turpentine | C14: Bermuda | D14: London | J14: =(E14*2240)+(F14*112)+(G14*28)+H14 -> 0 | L14: =J14/2240 -> 0
A15: 1748 | B15: Wood, Braziletto | C15: Bermuda | D15: London | J15: =(E15*2240)+(F15*112)+(G15*28)+H15 -> 0 | L15: =J15/2240 -> 0
A16: 1748 | B16: Wood, Fustick | C16: Bermuda | D16: London | J16: =(E16*2240)+(F16*112)+(G16*28)+H16 -> 0 | L16: =J16/2240 -> 0
A17: 1748 | B17: Wood, Logwood | C17: Bermuda | D17: London | J17: =(E17*2240)+(F17*112)+(G17*28)+H17 -> 0 | L17: =J17/2240 -> 0
A18: 1748 | B18: Brown Sugar | C18: Bermuda | D18: Out Ports | J18: =(E18*2240)+(F18*112)+(G18*28)+H18 -> 0 | L18: =J18/2240 -> 0
A19: 1748 | B19: Indigo | C19: Bermuda | D19: Out Ports | J19: =(E19*2240)+(F19*112)+(G19*28)+H19 -> 0 | L19: =J19/2240 -> 0
A20: 1748 | B20: Logwood | C20: Bermuda | D20: Out Ports | J20: =(E20*2240)+(F20*112)+(G20*28)+H20 -> 0 | L20: =J20/2240 -> 0
A21: 1748 | B21: Madera Wine | C21: Bermuda | D21: Out Ports | J21: =(E21*2240)+(F21*112)+(G21*28)+H21 -> 0 | L21: =J21/2240 -> 0
A22: 1748 | B22: Rice | C22: Bermuda | D22: Out Ports | J22: =(E22*2240)+(F22*112)+(G22*28)+H22 -> 0 | L22: =J22/2240 -> 0
A23: 1748 | B23: Shruff | C23: Bermuda | D23: Out Ports | J23: =(E23*2240)+(F23*112)+(G23*28)+H23 -> 0 | L23: =J23/2240 -> 0
A24: 1748 | B24: Succads | C24: Bermuda | D24: Out Ports | J24: =(E24*2240)+(F24*112)+(G24*28)+H24 -> 0 | L24: =J24/2240 -> 0
A25: 1748 | B25: Cotton | C25: Bermuda | D25: Out Ports | J25: =(E25*2240)+(F25*112)+(G25*28)+H25 -> 0 | L25: =J25/2240 -> 0
... A28: 1748 | B28: Wood, Logwood | C28: Bermuda | D28: Out Ports | J28: =(E28*2240)+(F28*112)+(G28*28)+H28 -> 0 | L28: =J28/2240 -> 0

Sheet Jamaica
A1: YEAR | B1: COMMODITY_NAME | C1: FROM_LOCATION | D1: TO_LOCATION | E1: ton | F1: hh | G1: quarter | H1: lb | J1: Total Pounds | L1: WEIGHT
A2: 1748 | B2: Almonds, Bitter | C2: Jamaica | D2: London | J2: =(E2*2240)+(F2*112)+(G2*28)+H2 -> 0 | L2: =J2/2240 -> 0
A3: 1748 | B3: Almonds, Sweet | C3: Jamaica | D3: London | J3: =(E3*2240)+(F3*112)+(G3*28)+H3 -> 0 | L3: =J3/2240 -> 0
A4: 1748 | B4: Aloes Epatica | C4: Jamaica | D4: London | J4: =(E4*2240)+(F4*112)+(G4*28)+H4 -> 0 | L4: =J4/2240 -> 0
A5: 1748 | B5: Annatto | C5: Jamaica | D5: London | J5: =(E5*2240)+(F5*112)+(G5*28)+H5 -> 0 | L5: =J5/2240 -> 0
A6: 1748 | B6: Anniseeds | C6: Jamaica | D6: London | J6: =(E6*2240)+(F6*112)+(G6*28)+H6 -> 0 | L6: =J6/2240 -> 0
A7: 1748 | B7: Bacon | C7: Jamaica | D7: London | J7: =(E7*2240)+(F7*112)+(G7*28)+H7 -> 0 | L7: =J7/2240 -> 0
A8: 1748 | B8: Balsam Artificial | C8: Jamaica | D8: London | H8: 246 | J8: =(E8*2240)+(F8*112)+(G8*28)+H8 -> 246 | L8: =J8/2240 -> 0.10982143
A9: 1748 | B9: Balsam Natural | C9: Jamaica | D9: London | H9: 31.5 | J9: =(E9*2240)+(F9*112)+(G9*28)+H9 -> 31.5 | L9: =J9/2240 -> 0.0140625
A10: 1748 | B10: Barrel Staves | C10: Jamaica | D10: London | J10: =(E10*2240)+(F10*112)+(G10*28)+H10 -> 0 | L10: =J10/2240 -> 0
A11: 1748 | B11: Bay Berries | C11: Jamaica | D11: London | J11: =(E11*2240)+(F11*112)+(G11*28)+H11 -> 0 | L11: =J11/2240 -> 0
A12: 1748 | B12: Bees Wax | C12: Jamaica | D12: London | J12: =(E12*2240)+(F12*112)+(G12*28)+H12 -> 0 | L12: =J12/2240 -> 0
A13: 1748 | B13: Brimstone | C13: Jamaica | D13: London | J13: =(E13*2240)+(F13*112)+(G13*28)+H13 -> 0 | L13: =J13/2240 -> 0
A14: 1748 | B14: Brown Sugar | C14: Jamaica | D14: London | F14: 223527 | H14: 18 | J14: =(E14*2240)+(F14*112)+(G14*28)+H14 -> 25035042 | L14: =J14/2240 -> 11176.358
A15: 1748 | B15: Cascarilla | C15: Jamaica | D15: London | J15: =(E15*2240)+(F15*112)+(G15*28)+H15 -> 0 | L15: =J15/2240 -> 0
A16: 1748 | B16: Cassia Fistula | C16: Jamaica | D16: London | H16: 2 | J16: =(E16*2240)+(F16*112)+(G16*28)+H16 -> 2 | L16: =J16/2240 -> 0.00089285714
A17: 1748 | B17: Chocolate | C17: Jamaica | D17: London | J17: =(E17*2240)+(F17*112)+(G17*28)+H17 -> 0 | L17: =J17/2240 -> 0
A18: 1748 | B18: Cocheneal | C18: Jamaica | D18: London | H18: 20 | J18: =(E18*2240)+(F18*112)+(G18*28)+H18 -> 20 | L18: =J18/2240 -> 0.0089285714
A19: 1748 | B19: Cocoa Nuts | C19: Jamaica | D19: London | F19: 4590 | G19: 1 | H19: 10 | J19: =(E19*2240)+(F19*112)+(G19*28)+H19 -> 514118 | L19: =J19/2240 -> 229.51696
A20: 1748 | B20: Cocoa Paste | C20: Jamaica | D20: London | J20: =(E20*2240)+(F20*112)+(G20*28)+H20 -> 0 | L20: =J20/2240 -> 0
A21: 1748 | B21: Coffee | C21: Jamaica | D21: London | F21: 319 | G21: 1 | J21: =(E21*2240)+(F21*112)+(G21*28)+H21 -> 35756 | L21: =J21/2240 -> 15.9625
A22: 1748 | B22: Cortex Peru | C22: Jamaica | D22: London | H22: 12261 | J22: =(E22*2240)+(F22*112)+(G22*28)+H22 -> 12261 | L22: =J22/2240 -> 5.4736607
A23: 1748 | B23: Cortex Winteranus | C23: Jamaica | D23: London | H23: 250 | J23: =(E23*2240)+(F23*112)+(G23*28)+H23 -> 250 | L23: =J23/2240 -> 0.11160714
A24: 1748 | B24: Cotton | C24: Jamaica | D24: London | H24: =205*200 -> 41000 | I24: 205bags | J24: =(E24*2240)+(F24*112)+(G24*28)+H24 -> 41000 | L24: =J24/2240 -> 18.303571
A25: 1748 | B25: Dry Ginger | C25: Jamaica | D25: London | F25: 1163 | G25: 1 | H25: 18 | J25: =(E25*2240)+(F25*112)+(G25*28)+H25 -> 130302 | L25: =J25/2240 -> 58.170536
A26: 1748 | B26: Elephant Teeth | C26: Jamaica | D26: London | F26: 124 | G26: 2 | H26: 10 | J26: =(E26*2240)+(F26*112)+(G26*28)+H26 -> 13954 | L26: =J26/2240 -> 6.2294643
A27: 1748 | B27: Green Ginger | C27: Jamaica | D27: London | H27: 250 | J27: =(E27*2240)+(F27*112)+(G27*28)+H27 -> 250 | L27: =J27/2240 -> 0.11160714
A28: 1748 | B28: Guinea Grains | C28: Jamaica | D28: London | J28: =(E28*2240)+(F28*112)+(G28*28)+H28 -> 0 | L28: =J28/2240 -> 0
A29: 1748 | B29: Gum Guiaci | C29: Jamaica | D29: London | H29: 522 | J29: =(E29*2240)+(F29*112)+(G29*28)+H29 -> 522 | L29: =J29/2240 -> 0.23303571
A30: 1748 | B30: Hemp | C30: Jamaica | D30: London | J30: =(E30*2240)+(F30*112)+(G30*28)+H30 -> 0 | L30: =J30/2240 -> 0
A31: 1748 | B31: Hypococania | C31: Jamaica | D31: London | J31: =(E31*2240)+(F31*112)+(G31*28)+H31 -> 0 | L31: =J31/2240 -> 0
A32: 1748 | B32: Indigo | C32: Jamaica | D32: London | H32: 181270 | J32: =(E32*2240)+(F32*112)+(G32*28)+H32 -> 181270 | L32: =J32/2240 -> 80.924107
A33: 1748 | B33: Jallop? | C33: Jamaica | D33: London | J33: =(E33*2240)+(F33*112)+(G33*28)+H33 -> 0 | L33: =J33/2240 -> 0
A34: 1748 | B34: Lemon Water | C34: Jamaica | D34: London | J34: =(E34*2240)+(F34*112)+(G34*28)+H34 -> 0 | L34: =J34/2240 -> 0
A35: 1748 | B35: Lignum Vitae | C35: Jamaica | D35: London | E35: 40 | F35: 11 | G35: 1 | H35: 18 | J35: =(E35*2240)+(F35*112)+(G35*28)+H35 -> 90878 | L35: =J35/2240 -> 40.570536
A36: 1748 | B36: Lime Juice | C36: Jamaica | D36: London | J36: =(E36*2240)+(F36*112)+(G36*28)+H36 -> 0 | L36: =J36/2240 -> 0
A37: 1748 | B37: Loaf Sugar | C37: Jamaica | D37: London | J37: =(E37*2240)+(F37*112)+(G37*28)+H37 -> 0 | L37: =J37/2240 -> 0
A38: 1748 | B38: Madera Wine | C38: Jamaica | D38: London | H38: 49242.5 | I38: 19t 2h 9g | J38: =(E38*2240)+(F38*112)+(G38*28)+H38 -> 49242.5 | L38: =J38/2240 -> 21.983259
A39: 1748 | B39: Molasses | C39: Jamaica | D39: London | J39: =(E39*2240)+(F39*112)+(G39*28)+H39 -> 0 | L39: =J39/2240 -> 0
A40: 1748 | B40: Oranges | C40: Jamaica | D40: London | J40: =(E40*2240)+(F40*112)+(G40*28)+H40 -> 0 | L40: =J40/2240 -> 0
...

Sheet Mountserat
A1: YEAR | B1: COMMODITY_NAME | C1: FROM_LOCATION | D1: TO_LOCATION | E1: ton | F1: hh | G1: quarter | H1: lb | J1: Total Pounds | L1: WEIGHT
A2: 1748 | B2: Almonds, Bitter | C2: Mountserat | D2: London | J2: =(E2*2240)+(F2*112)+(G2*28)+H2 -> 0 | L2: =J2/2240 -> 0
A3: 1748 | B3: Almonds, Sweet | C3: Mountserat | D3: London | J3: =(E3*2240)+(F3*112)+(G3*28)+H3 -> 0 | L3: =J3/2240 -> 0
A4: 1748 | B4: Aloes Epatica | C4: Mountserat | D4: London | J4: =(E4*2240)+(F4*112)+(G4*28)+H4 -> 0 | L4: =J4/2240 -> 0
A5: 1748 | B5: Annatto | C5: Mountserat | D5: London | J5: =(E5*2240)+(F5*112)+(G5*28)+H5 -> 0 | L5: =J5/2240 -> 0
A6: 1748 | B6: Anniseeds | C6: Mountserat | D6: London | J6: =(E6*2240)+(F6*112)+(G6*28)+H6 -> 0 | L6: =J6/2240 -> 0
A7: 1748 | B7: Bacon | C7: Mountserat | D7: London | J7: =(E7*2240)+(F7*112)+(G7*28)+H7 -> 0 | L7: =J7/2240 -> 0
A8: 1748 | B8: Barrel Staves | C8: Mountserat | D8: London | J8: =(E8*2240)+(F8*112)+(G8*28)+H8 -> 0 | L8: =J8/2240 -> 0
A9: 1748 | B9: Bay Berries | C9: Mountserat | D9: London | J9: =(E9*2240)+(F9*112)+(G9*28)+H9 -> 0 | L9: =J9/2240 -> 0
A10: 1748 | B10: Bees Wax | C10: Mountserat | D10: London | J10: =(E10*2240)+(F10*112)+(G10*28)+H10 -> 0 | L10: =J10/2240 -> 0
A11: 1748 | B11: Brimstone | C11: Mountserat | D11: London | J11: =(E11*2240)+(F11*112)+(G11*28)+H11 -> 0 | L11: =J11/2240 -> 0
A12: 1748 | B12: Brown Sugar | C12: Mountserat | D12: London | F12: 41003 | G12: 1 | H12: 12 | J12: =(E12*2240)+(F12*112)+(G12*28)+H12 -> 4592376 | L12: =J12/2240 -> 2050.1679
A13: 1748 | B13: Cascarilla | C13: Mountserat | D13: London | J13: =(E13*2240)+(F13*112)+(G13*28)+H13 -> 0 | L13: =J13/2240 -> 0
A14: 1748 | B14: Cassia Fistula | C14: Mountserat | D14: London | J14: =(E14*2240)+(F14*112)+(G14*28)+H14 -> 0 | L14: =J14/2240 -> 0
A15: 1748 | B15: Chocolate | C15: Mountserat | D15: London | J15: =(E15*2240)+(F15*112)+(G15*28)+H15 -> 0 | L15: =J15/2240 -> 0
A16: 1748 | B16: Cocheneal | C16: Mountserat | D16: London | J16: =(E16*2240)+(F16*112)+(G16*28)+H16 -> 0 | L16: =J16/2240 -> 0
A17: 1748 | B17: Cocoa Nuts | C17: Mountserat | D17: London | J17: =(E17*2240)+(F17*112)+(G17*28)+H17 -> 0 | L17: =J17/2240 -> 0
A18: 1748 | B18: Cocoa Paste | C18: Mountserat | D18: London | J18: =(E18*2240)+(F18*112)+(G18*28)+H18 -> 0 | L18: =J18/2240 -> 0
A19: 1748 | B19: Coffee | C19: Mountserat | D19: London | J19: =(E19*2240)+(F19*112)+(G19*28)+H19 -> 0 | L19: =J19/2240 -> 0
A20: 1748 | B20: Cortex Peru | C20: Mountserat | D20: London | J20: =(E20*2240)+(F20*112)+(G20*28)+H20 -> 0 | L20: =J20/2240 -> 0
A21: 1748 | B21: Cortex Winteranus | C21: Mountserat | D21: London | J21: =(E21*2240)+(F21*112)+(G21*28)+H21 -> 0 | L21: =J21/2240 -> 0
A22: 1748 | B22: Cotton | C22: Mountserat | D22: London | H22: =76*200 -> 15200 | I22: 76bags | J22: =(E22*2240)+(F22*112)+(G22*28)+H22 -> 15200 | L22: =J22/2240 -> 6.7857143
A23: 1748 | B23: Dry Ginger | C23: Mountserat | D23: London | J23: =(E23*2240)+(F23*112)+(G23*28)+H23 -> 0 | L23: =J23/2240 -> 0
A24: 1748 | B24: Elephant Teeth | C24: Mountserat | D24: London | J24: =(E24*2240)+(F24*112)+(G24*28)+H24 -> 0 | L24: =J24/2240 -> 0
A25: 1748 | B25: Green Ginger | C25: Mountserat | D25: London | J25: =(E25*2240)+(F25*112)+(G25*28)+H25 -> 0 | L25: =J25/2240 -> 0
A26: 1748 | B26: Guinea Grains | C26: Mountserat | D26: London | J26: =(E26*2240)+(F26*112)+(G26*28)+H26 -> 0 | L26: =J26/2240 -> 0
A27: 1748 | B27: Gum Guiaci | C27: Mountserat | D27: London | J27: =(E27*2240)+(F27*112)+(G27*28)+H27 -> 0 | L27: =J27/2240 -> 0
A28: 1748 | B28: Hemp | C28: Mountserat | D28: London | J28: =(E28*2240)+(F28*112)+(G28*28)+H28 -> 0 | L28: =J28/2240 -> 0
A29: 1748 | B29: Hypococania | C29: Mountserat | D29: London | J29: =(E29*2240)+(F29*112)+(G29*28)+H29 -> 0 | L29: =J29/2240 -> 0
A30: 1748 | B30: Indigo | C30: Mountserat | D30: London | H30: 1900 | J30: =(E30*2240)+(F30*112)+(G30*28)+H30 -> 1900 | L30: =J30/2240 -> 0.84821429
A31: 1748 | B31: Jallop? | C31: Mountserat | D31: London | J31: =(E31*2240)+(F31*112)+(G31*28)+H31 -> 0 | L31: =J31/2240 -> 0
A32: 1748 | B32: Lemon Water | C32: Mountserat | D32: London | J32: =(E32*2240)+(F32*112)+(G32*28)+H32 -> 0 | L32: =J32/2240 -> 0
A33: 1748 | B33: Lignum Vitae | C33: Mountserat | D33: London | J33: =(E33*2240)+(F33*112)+(G33*28)+H33 -> 0 | L33: =J33/2240 -> 0
A34: 1748 | B34: Lime Juice | C34: Mountserat | D34: London | J34: =(E34*2240)+(F34*112)+(G34*28)+H34 -> 0 | L34: =J34/2240 -> 0
A35: 1748 | B35: Loaf Sugar | C35: Mountserat | D35: London | J35: =(E35*2240)+(F35*112)+(G35*28)+H35 -> 0 | L35: =J35/2240 -> 0
A36: 1748 | B36: Madera Wine | C36: Mountserat | D36: London | H36: 3271 | I36: 1t 1h 12g | J36: =(E36*2240)+(F36*112)+(G36*28)+H36 -> 3271 | L36: =J36/2240 -> 1.4602679
A37: 1748 | B37: Molasses | C37: Mountserat | D37: London | J37: =(E37*2240)+(F37*112)+(G37*28)+H37 -> 0 | L37: =J37/2240 -> 0
A38: 1748 | B38: Oranges | C38: Mountserat | D38: London | J38: =(E38*2240)+(F38*112)+(G38*28)+H38 -> 0 | L38: =J38/2240 -> 0
A39: 1748 | B39: Orchelia | C39: Mountserat | D39: London | J39: =(E39*2240)+(F39*112)+(G39*28)+H39 -> 0 | L39: =J39/2240 -> 0
A40: 1748 | B40: Pickles | C40: Mountserat | D40: London | H40: 20 | I40: 2g | J40: =(E40*2240)+(F40*112)+(G40*28)+H40 -> 20 | L40: =J40/2240 -> 0.0089285714
...

Sheet Nevis
A1: YEAR | B1: COMMODITY_NAME | C1: FROM_LOCATION | D1: TO_LOCATION | E1: ton | F1: hh | G1: quarter | H1: lb | J1: Total Pounds | L1: WEIGHT
A2: 1748 | B2: Almonds, Bitter | C2: Nevis | D2: London | J2: =(E2*2240)+(F2*112)+(G2*28)+H2 -> 0 | L2: =J2/2240 -> 0
A3: 1748 | B3: Almonds, Sweet | C3: Nevis | D3: London | J3: =(E3*2240)+(F3*112)+(G3*28)+H3 -> 0 | L3: =J3/2240 -> 0
A4: 1748 | B4: Aloes Epatica | C4: Nevis | D4: London | J4: =(E4*2240)+(F4*112)+(G4*28)+H4 -> 0 | L4: =J4/2240 -> 0
A5: 1748 | B5: Annatto | C5: Nevis | D5: London | J5: =(E5*2240)+(F5*112)+(G5*28)+H5 -> 0 | L5: =J5/2240 -> 0
A6: 1748 | B6: Anniseeds | C6: Nevis | D6: London | J6: =(E6*2240)+(F6*112)+(G6*28)+H6 -> 0 | L6: =J6/2240 -> 0
A7: 1748 | B7: Bacon | C7: Nevis | D7: London | J7: =(E7*2240)+(F7*112)+(G7*28)+H7 -> 0 | L7: =J7/2240 -> 0
A8: 1748 | B8: Barrel Staves | C8: Nevis | D8: London | J8: =(E8*2240)+(F8*112)+(G8*28)+H8 -> 0 | L8: =J8/2240 -> 0
A9: 1748 | B9: Bay Berries | C9: Nevis | D9: London | J9: =(E9*2240)+(F9*112)+(G9*28)+H9 -> 0 | L9: =J9/2240 -> 0
A10: 1748 | B10: Bees Wax | C10: Nevis | D10: London | J10: =(E10*2240)+(F10*112)+(G10*28)+H10 -> 0 | L10: =J10/2240 -> 0
A11: 1748 | B11: Brimstone | C11: Nevis | D11: London | J11: =(E11*2240)+(F11*112)+(G11*28)+H11 -> 0 | L11: =J11/2240 -> 0
A12: 1748 | B12: Brown Sugar | C12: Nevis | D12: London | F12: 35382 | G12: 1 | H12: 12 | J12: =(E12*2240)+(F12*112)+(G12*28)+H12 -> 3962824 | L12: =J12/2240 -> 1769.1179
A13: 1748 | B13: Cascarilla | C13: Nevis | D13: London | J13: =(E13*2240)+(F13*112)+(G13*28)+H13 -> 0 | L13: =J13/2240 -> 0
A14: 1748 | B14: Cassia Fistula | C14: Nevis | D14: London | J14: =(E14*2240)+(F14*112)+(G14*28)+H14 -> 0 | L14: =J14/2240 -> 0
A15: 1748 | B15: Chocolate | C15: Nevis | D15: London | J15: =(E15*2240)+(F15*112)+(G15*28)+H15 -> 0 | L15: =J15/2240 -> 0
A16: 1748 | B16: Cocheneal | C16: Nevis | D16: London | J16: =(E16*2240)+(F16*112)+(G16*28)+H16 -> 0 | L16: =J16/2240 -> 0
A17: 1748 | B17: Cocoa Nuts | C17: Nevis | D17: London | J17: =(E17*2240)+(F17*112)+(G17*28)+H17 -> 0 | L17: =J17/2240 -> 0
A18: 1748 | B18: Cocoa Paste | C18: Nevis | D18: London | J18: =(E18*2240)+(F18*112)+(G18*28)+H18 -> 0 | L18: =J18/2240 -> 0
A19: 1748 | B19: Coffee | C19: Nevis | D19: London | J19: =(E19*2240)+(F19*112)+(G19*28)+H19 -> 0 | L19: =J19/2240 -> 0
A20: 1748 | B20: Cortex Peru | C20: Nevis | D20: London | J20: =(E20*2240)+(F20*112)+(G20*28)+H20 -> 0 | L20: =J20/2240 -> 0
A21: 1748 | B21: Cortex Winteranus | C21: Nevis | D21: London | J21: =(E21*2240)+(F21*112)+(G21*28)+H21 -> 0 | L21: =J21/2240 -> 0
A22: 1748 | B22: Cotton | C22: Nevis | D22: London | J22: =(E22*2240)+(F22*112)+(G22*28)+H22 -> 0 | L22: =J22/2240 -> 0
A23: 1748 | B23: Dry Ginger | C23: Nevis | D23: London | J23: =(E23*2240)+(F23*112)+(G23*28)+H23 -> 0 | L23: =J23/2240 -> 0
A24: 1748 | B24: Elephant Teeth | C24: Nevis | D24: London | F24: 3 | G24: 1 | H24: 20 | J24: =(E24*2240)+(F24*112)+(G24*28)+H24 -> 384 | L24: =J24/2240 -> 0.17142857
A25: 1748 | B25: Green Ginger | C25: Nevis | D25: London | H25: 27 | J25: =(E25*2240)+(F25*112)+(G25*28)+H25 -> 27 | L25: =J25/2240 -> 0.012053571
A26: 1748 | B26: Guinea Grains | C26: Nevis | D26: London | J26: =(E26*2240)+(F26*112)+(G26*28)+H26 -> 0 | L26: =J26/2240 -> 0
A27: 1748 | B27: Gum Guiaci | C27: Nevis | D27: London | J27: =(E27*2240)+(F27*112)+(G27*28)+H27 -> 0 | L27: =J27/2240 -> 0
A28: 1748 | B28: Hemp | C28: Nevis | D28: London | J28: =(E28*2240)+(F28*112)+(G28*28)+H28 -> 0 | L28: =J28/2240 -> 0
A29: 1748 | B29: Hypococania | C29: Nevis | D29: London | J29: =(E29*2240)+(F29*112)+(G29*28)+H29 -> 0 | L29: =J29/2240 -> 0
A30: 1748 | B30: Indigo | C30: Nevis | D30: London | H30: 1200 | J30: =(E30*2240)+(F30*112)+(G30*28)+H30 -> 1200 | L30: =J30/2240 -> 0.53571429
A31: 1748 | B31: Jallop? | C31: Nevis | D31: London | J31: =(E31*2240)+(F31*112)+(G31*28)+H31 -> 0 | L31: =J31/2240 -> 0
A32: 1748 | B32: Lemon Water | C32: Nevis | D32: London | J32: =(E32*2240)+(F32*112)+(G32*28)+H32 -> 0 | L32: =J32/2240 -> 0
A33: 1748 | B33: Lignum Vitae | C33: Nevis | D33: London | J33: =(E33*2240)+(F33*112)+(G33*28)+H33 -> 0 | L33: =J33/2240 -> 0
A34: 1748 | B34: Lime Juice | C34: Nevis | D34: London | J34: =(E34*2240)+(F34*112)+(G34*28)+H34 -> 0 | L34: =J34/2240 -> 0
A35: 1748 | B35: Loaf Sugar | C35: Nevis | D35: London | J35: =(E35*2240)+(F35*112)+(G35*28)+H35 -> 0 | L35: =J35/2240 -> 0
A36: 1748 | B36: Madera Wine | C36: Nevis | D36: London | H36: 1110.5 | I36: 1h 48g | J36: =(E36*2240)+(F36*112)+(G36*28)+H36 -> 1110.5 | L36: =J36/2240 -> 0.49575893
A37: 1748 | B37: Molasses | C37: Nevis | D37: London | F37: 9 | G37: 2 | J37: =(E37*2240)+(F37*112)+(G37*28)+H37 -> 1064 | L37: =J37/2240 -> 0.475
A38: 1748 | B38: Oranges | C38: Nevis | D38: London | J38: =(E38*2240)+(F38*112)+(G38*28)+H38 -> 0 | L38: =J38/2240 -> 0
A39: 1748 | B39: Orchelia | C39: Nevis | D39: London | J39: =(E39*2240)+(F39*112)+(G39*28)+H39 -> 0 | L39: =J39/2240 -> 0
A40: 1748 | B40: Pickles | C40: Nevis | D40: London | H40: 55 | I40: 5.5g | J40: =(E40*2240)+(F40*112)+(G40*28)+H40 -> 55 | L40: =J40/2240 -> 0.024553571
...

Sheet St Kitts
A1: YEAR | B1: COMMODITY_NAME | C1: FROM_LOCATION | D1: TO_LOCATION | E1: ton | F1: hh | G1: quarter | H1: lb | J1: Total Pounds | L1: WEIGHT
A2: 1748 | B2: Almonds, Bitter | C2: StKitts | D2: London | J2: =(E2*2240)+(F2*112)+(G2*28)+H2 -> 0 | L2: =J2/2240 -> 0
A3: 1748 | B3: Almonds, Sweet | C3: StKitts | D3: London | J3: =(E3*2240)+(F3*112)+(G3*28)+H3 -> 0 | L3: =J3/2240 -> 0
A4: 1748 | B4: Aloes Epatica | C4: StKitts | D4: London | J4: =(E4*2240)+(F4*112)+(G4*28)+H4 -> 0 | L4: =J4/2240 -> 0
A5: 1748 | B5: Annatto | C5: StKitts | D5: London | J5: =(E5*2240)+(F5*112)+(G5*28)+H5 -> 0 | L5: =J5/2240 -> 0
A6: 1748 | B6: Anniseeds | C6: StKitts | D6: London | J6: =(E6*2240)+(F6*112)+(G6*28)+H6 -> 0 | L6: =J6/2240 -> 0
A7: 1748 | B7: Bacon | C7: StKitts | D7: London | J7: =(E7*2240)+(F7*112)+(G7*28)+H7 -> 0 | L7: =J7/2240 -> 0
A8: 1748 | B8: Barrel Staves | C8: StKitts | D8: London | J8: =(E8*2240)+(F8*112)+(G8*28)+H8 -> 0 | L8: =J8/2240 -> 0
A9: 1748 | B9: Bay Berries | C9: StKitts | D9: London | J9: =(E9*2240)+(F9*112)+(G9*28)+H9 -> 0 | L9: =J9/2240 -> 0
A10: 1748 | B10: Bees Wax | C10: StKitts | D10: London | J10: =(E10*2240)+(F10*112)+(G10*28)+H10 -> 0 | L10: =J10/2240 -> 0
A11: 1748 | B11: Brimstone | C11: StKitts | D11: London | J11: =(E11*2240)+(F11*112)+(G11*28)+H11 -> 0 | L11: =J11/2240 -> 0
A12: 1748 | B12: Brown Sugar | C12: StKitts | D12: London | F12: 157263 | G12: 1 | H12: 20 | J12: =(E12*2240)+(F12*112)+(G12*28)+H12 -> 17613504 | L12: =J12/2240 -> 7863.1714
A13: 1748 | B13: Cascarilla | C13: StKitts | D13: London | J13: =(E13*2240)+(F13*112)+(G13*28)+H13 -> 0 | L13: =J13/2240 -> 0
A14: 1748 | B14: Cassia Fistula | C14: StKitts | D14: London | J14: =(E14*2240)+(F14*112)+(G14*28)+H14 -> 0 | L14: =J14/2240 -> 0
A15: 1748 | B15: Chocolate | C15: StKitts | D15: London | J15: =(E15*2240)+(F15*112)+(G15*28)+H15 -> 0 | L15: =J15/2240 -> 0
A16: 1748 | B16: Cocheneal | C16: StKitts | D16: London | J16: =(E16*2240)+(F16*112)+(G16*28)+H16 -> 0 | L16: =J16/2240 -> 0
A17: 1748 | B17: Cocoa Nuts | C17: StKitts | D17: London | F17: 7 | H17: 5 | J17: =(E17*2240)+(F17*112)+(G17*28)+H17 -> 789 | L17: =J17/2240 -> 0.35223214
A18: 1748 | B18: Cocoa Paste | C18: StKitts | D18: London | J18: =(E18*2240)+(F18*112)+(G18*28)+H18 -> 0 | L18: =J18/2240 -> 0
A19: 1748 | B19: Coffee | C19: StKitts | D19: London | F19: 1 | H19: 8 | J19: =(E19*2240)+(F19*112)+(G19*28)+H19 -> 120 | L19: =J19/2240 -> 0.053571429
A20: 1748 | B20: Cortex Peru | C20: StKitts | D20: London | J20: =(E20*2240)+(F20*112)+(G20*28)+H20 -> 0 | L20: =J20/2240 -> 0
