Workbook

Sheet Master Goods Sheet
A1: Item | B1: Total London | C1: Total Outports | D1: Total | H1: COMMODITY_NAME
A2: Almonds, Bitter | B2: =SUMIFS(Antigua!$L:$L, Antigua!$B:$B, $A2, Antigua!$D:$D, "London") + SUMIFS(Barbados!$L:$L, Barbados!$B:$B, $A2, Barbados!$D:$D, "London") + SUMIFS(Bermuda!$L:$L, Bermuda!$B:$B, $A2, Bermuda!$D:$D, "London") + SUMIFS(Jamaica!$L:$L, Jamaica!$B:$B, $A2, Jamaica!$D:$D, "London") + SUMIFS(Mountserat!$L:$L, Mountserat!$B:$B, $A2, Mountserat!$D:$D, "London") + SUMIFS(Nevis!$L:$L, Nevis!$B:$B, $A2, Nevis!$D:$D, "London") + SUMIFS('St Kitts'!$L:$L, 'St Kitts'!$B:$B, $A2, 'St Kitts'!$D:$D, "London") + SUMIFS(WestIndiesGeneral!$L:$L, WestIndiesGeneral!$B:$B, $A2, WestIndiesGeneral!$D:$D, "London") + SUMIFS(Anguilla!$L:$L, Anguilla!$B:$B, $A2, Anguilla!$D:$D, "London") + SUMIFS(Tortola!$L:$L, Tortola!$B:$B, $A2, Tortola!$D:$D, "London") -> 0 | C2: =SUMIFS(Antigua!$L:$L, Antigua!$B:$B, $A2, Antigua!$D:$D, "Out Ports") + SUMIFS(Barbados!$L:$L, Barbados!$B:$B, $A2, Barbados!$D:$D, "Out Ports") + SUMIFS(Bermuda!$L:$L, Bermuda!$B:$B, $A2, Bermuda!$D:$D, "Out Ports") + SUMIFS(Jamaica!$L:$L, Jamaica!$B:$B, $A2, Jamaica!$D:$D, "Out Ports") + SUMIFS(Mountserat!$L:$L, Mountserat!$B:$B, $A2, Mountserat!$D:$D, "Out Ports") + SUMIFS(Nevis!$L:$L, Nevis!$B:$B, $A2, Nevis!$D:$D, "Out Ports") + SUMIFS('St Kitts'!$L:$L, 'St Kitts'!$B:$B, $A2, 'St Kitts'!$D:$D, "Out Ports") + SUMIFS(WestIndiesGeneral!$L:$L, WestIndiesGeneral!$B:$B, $A2, WestIndiesGeneral!$D:$D, "Out Ports") + SUMIFS(Anguilla!$L:$L, Anguilla!$B:$B, $A2, Anguilla!$D:$D, "Out Ports") + SUMIFS(Tortola!$L:$L, Tortola!$B:$B, $A2, Tortola!$D:$D, "Out Ports") -> 0 | D2: =B2+C2 -> 0
A3: Almonds, Sweet | B3: =SUMIFS(Antigua!$L:$L, Antigua!$B:$B, $A3, Antigua!$D:$D, "London") + SUMIFS(Barbados!$L:$L, Barbados!$B:$B, $A3, Barbados!$D:$D, "London") + SUMIFS(Bermuda!$L:$L, Bermuda!$B:$B, $A3, Bermuda!$D:$D, "London") + SUMIFS(Jamaica!$L:$L, Jamaica!$B:$B, $A3, Jamaica!$D:$D, "London") + SUMIFS(Mountserat!$L:$L, Mountserat!$B:$B, $A3, Mountserat!$D:$D, "London") + SUMIFS(Nevis!$L:$L, Nevis!$B:$B, $A3, Nevis!$D:$D, "London") + SUMIFS('St Kitts'!$L:$L, 'St Kitts'!$B:$B, $A3, 'St Kitts'!$D:$D, "London") + SUMIFS(WestIndiesGeneral!$L:$L, WestIndiesGeneral!$B:$B, $A3, WestIndiesGeneral!$D:$D, "London") + SUMIFS(Anguilla!$L:$L, Anguilla!$B:$B, $A3, Anguilla!$D:$D, "London") + SUMIFS(Tortola!$L:$L, Tortola!$B:$B, $A3, Tortola!$D:$D, "London") -> 0 | C3: =SUMIFS(Antigua!$L:$L, Antigua!$B:$B, $A3, Antigua!$D:$D, "Out Ports") + SUMIFS(Barbados!$L:$L, Barbados!$B:$B, $A3, Barbados!$D:$D, "Out Ports") + SUMIFS(Bermuda!$L:$L, Bermuda!$B:$B, $A3, Bermuda!$D:$D, "Out Ports") + SUMIFS(Jamaica!$L:$L, Jamaica!$B:$B, $A3, Jamaica!$D:$D, "Out Ports") + SUMIFS(Mountserat!$L:$L, Mountserat!$B:$B, $A3, Mountserat!$D:$D, "Out Ports") + SUMIFS(Nevis!$L:$L, Nevis!$B:$B, $A3, Nevis!$D:$D, "Out Ports") + SUMIFS('St Kitts'!$L:$L, 'St Kitts'!$B:$B, $A3, 'St Kitts'!$D:$D, "Out Ports") + SUMIFS(WestIndiesGeneral!$L:$L, WestIndiesGeneral!$B:$B, $A3, WestIndiesGeneral!$D:$D, "Out Ports") + SUMIFS(Anguilla!$L:$L, Anguilla!$B:$B, $A3, Anguilla!$D:$D, "Out Ports") + SUMIFS(Tortola!$L:$L, Tortola!$B:$B, $A3, Tortola!$D:$D, "Out Ports") -> 0 | D3: =B3+C3 -> 0
A4: Aloes Epatica | B4: =SUMIFS(Antigua!$L:$L, Antigua!$B:$B, $A4, Antigua!$D:$D, "London") + SUMIFS(Barbados!$L:$L, Barbados!$B:$B, $A4, Barbados!$D:$D, "London") + SUMIFS(Bermuda!$L:$L, Bermuda!$B:$B, $A4, Bermuda!$D:$D, "London") + SUMIFS(Jamaica!$L:$L, Jamaica!$B:$B, $A4, Jamaica!$D:$D, "London") + SUMIFS(Mountserat!$L:$L, Mountserat!$B:$B, $A4, Mountserat!$D:$D, "London") + SUMIFS(Nevis!$L:$L, Nevis!$B:$B, $A4, Nevis!$D:$D, "London") + SUMIFS('St Kitts'!$L:$L, 'St Kitts'!$B:$B, $A4, 'St Kitts'!$D:$D, "London") + SUMIFS(WestIndiesGeneral!$L:$L, WestIndiesGeneral!$B:$B, $A4, WestIndiesGeneral!$D:$D, "London") + SUMIFS(Anguilla!$L:$L, Anguilla!$B:$B, $A4, Anguilla!$D:$D, "London") + SUMIFS(Tortola!$L:$L, Tortola!$B:$B, $A4, Tortola!$D:$D, "London") -> 7.8370536 | C4: =SUMIFS(Antigua!$L:$L, Antigua!$B:$B, $A4, Antigua!$D:$D, "Out Ports") + SUMIFS(Barbados!$L:$L, Barbados!$B:$B, $A4, Barbados!$D:$D, "Out Ports") + SUMIFS(Bermuda!$L:$L, Bermuda!$B:$B, $A4, Bermuda!$D:$D, "Out Ports") + SUMIFS(Jamaica!$L:$L, Jamaica!$B:$B, $A4, Jamaica!$D:$D, "Out Ports") + SUMIFS(Mountserat!$L:$L, Mountserat!$B:$B, $A4, Mountserat!$D:$D, "Out Ports") + SUMIFS(Nevis!$L:$L, Nevis!$B:$B, $A4, Nevis!$D:$D, "Out Ports") + SUMIFS('St Kitts'!$L:$L, 'St Kitts'!$B:$B, $A4, 'St Kitts'!$D:$D, "Out Ports") + SUMIFS(WestIndiesGeneral!$L:$L, WestIndiesGeneral!$B:$B, $A4, WestIndiesGeneral!$D:$D, "Out Ports") + SUMIFS(Anguilla!$L:$L, Anguilla!$B:$B, $A4, Anguilla!$D:$D, "Out Ports") + SUMIFS(Tortola!$L:$L, Tortola!$B:$B, $A4, Tortola!$D:$D, "Out Ports") -> 0.75446429 | D4: =B4+C4 -> 8.5915179
A5: Annatto | B5: =SUMIFS(Antigua!$L:$L, Antigua!$B:$B, $A5, Antigua!$D:$D, "London") + SUMIFS(Barbados!$L:$L, Barbados!$B:$B, $A5, Barbados!$D:$D, "London") + SUMIFS(Bermuda!$L:$L, Bermuda!$B:$B, $A5, Bermuda!$D:$D, "London") + SUMIFS(Jamaica!$L:$L, Jamaica!$B:$B, $A5, Jamaica!$D:$D, "London") + SUMIFS(Mountserat!$L:$L, Mountserat!$B:$B, $A5, Mountserat!$D:$D, "London") + SUMIFS(Nevis!$L:$L, Nevis!$B:$B, $A5, Nevis!$D:$D, "London") + SUMIFS('St Kitts'!$L:$L, 'St Kitts'!$B:$B, $A5, 'St Kitts'!$D:$D, "London") + SUMIFS(WestIndiesGeneral!$L:$L, WestIndiesGeneral!$B:$B, $A5, WestIndiesGeneral!$D:$D, "London") + SUMIFS(Anguilla!$L:$L, Anguilla!$B:$B, $A5, Anguilla!$D:$D, "London") + SUMIFS(Tortola!$L:$L, Tortola!$B:$B, $A5, Tortola!$D:$D, "London") -> 0 | C5: =SUMIFS(Antigua!$L:$L, Antigua!$B:$B, $A5, Antigua!$D:$D, "Out Ports") + SUMIFS(Barbados!$L:$L, Barbados!$B:$B, $A5, Barbados!$D:$D, "Out Ports") + SUMIFS(Bermuda!$L:$L, Bermuda!$B:$B, $A5, Bermuda!$D:$D, "Out Ports") + SUMIFS(Jamaica!$L:$L, Jamaica!$B:$B, $A5, Jamaica!$D:$D, "Out Ports") + SUMIFS(Mountserat!$L:$L, Mountserat!$B:$B, $A5, Mountserat!$D:$D, "Out Ports") + SUMIFS(Nevis!$L:$L, Nevis!$B:$B, $A5, Nevis!$D:$D, "Out Ports") + SUMIFS('St Kitts'!$L:$L, 'St Kitts'!$B:$B, $A5, 'St Kitts'!$D:$D, "Out Ports") + SUMIFS(WestIndiesGeneral!$L:$L, WestIndiesGeneral!$B:$B, $A5, WestIndiesGeneral!$D:$D, "Out Ports") + SUMIFS(Anguilla!$L:$L, Anguilla!$B:$B, $A5, Anguilla!$D:$D, "Out Ports") + SUMIFS(Tortola!$L:$L, Tortola!$B:$B, $A5, Tortola!$D:$D, "Out Ports") -> 0 | D5: =B5+C5 -> 0
A6: Anniseeds | B6: =SUMIFS(Antigua!$L:$L, Antigua!$B:$B, $A6, Antigua!$D:$D, "London") + SUMIFS(Barbados!$L:$L, Barbados!$B:$B, $A6, Barbados!$D:$D, "London") + SUMIFS(Bermuda!$L:$L, Bermuda!$B:$B, $A6, Bermuda!$D:$D, "London") + SUMIFS(Jamaica!$L:$L, Jamaica!$B:$B, $A6, Jamaica!$D:$D, "London") + SUMIFS(Mountserat!$L:$L, Mountserat!$B:$B, $A6, Mountserat!$D:$D, "London") + SUMIFS(Nevis!$L:$L, Nevis!$B:$B, $A6, Nevis!$D:$D, "London") + SUMIFS('St Kitts'!$L:$L, 'St Kitts'!$B:$B, $A6, 'St Kitts'!$D:$D, "London") + SUMIFS(WestIndiesGeneral!$L:$L, WestIndiesGeneral!$B:$B, $A6, WestIndiesGeneral!$D:$D, "London") + SUMIFS(Anguilla!$L:$L, Anguilla!$B:$B, $A6, Anguilla!$D:$D, "London") + SUMIFS(Tortola!$L:$L, Tortola!$B:$B, $A6, Tortola!$D:$D, "London") -> 0 | C6: =SUMIFS(Antigua!$L:$L, Antigua!$B:$B, $A6, Antigua!$D:$D, "Out Ports") + SUMIFS(Barbados!$L:$L, Barbados!$B:$B, $A6, Barbados!$D:$D, "Out Ports") + SUMIFS(Bermuda!$L:$L, Bermuda!$B:$B, $A6, Bermuda!$D:$D, "Out Ports") + SUMIFS(Jamaica!$L:$L, Jamaica!$B:$B, $A6, Jamaica!$D:$D, "Out Ports") + SUMIFS(Mountserat!$L:$L, Mountserat!$B:$B, $A6, Mountserat!$D:$D, "Out Ports") + SUMIFS(Nevis!$L:$L, Nevis!$B:$B, $A6, Nevis!$D:$D, "Out Ports") + SUMIFS('St Kitts'!$L:$L, 'St Kitts'!$B:$B, $A6, 'St Kitts'!$D:$D, "Out Ports") + SUMIFS(WestIndiesGeneral!$L:$L, WestIndiesGeneral!$B:$B, $A6, WestIndiesGeneral!$D:$D, "Out Ports") + SUMIFS(Anguilla!$L:$L, Anguilla!$B:$B, $A6, Anguilla!$D:$D, "Out Ports") + SUMIFS(Tortola!$L:$L, Tortola!$B:$B, $A6, Tortola!$D:$D, "Out Ports") -> 0 | D6: =B6+C6 -> 0
A7: Archelia | B7: =SUMIFS(Antigua!$L:$L, Antigua!$B:$B, $A7, Antigua!$D:$D, "London") + SUMIFS(Barbados!$L:$L, Barbados!$B:$B, $A7, Barbados!$D:$D, "London") + SUMIFS(Bermuda!$L:$L, Bermuda!$B:$B, $A7, Bermuda!$D:$D, "London") + SUMIFS(Jamaica!$L:$L, Jamaica!$B:$B, $A7, Jamaica!$D:$D, "London") + SUMIFS(Mountserat!$L:$L, Mountserat!$B:$B, $A7, Mountserat!$D:$D, "London") + SUMIFS(Nevis!$L:$L, Nevis!$B:$B, $A7, Nevis!$D:$D, "London") + SUMIFS('St Kitts'!$L:$L, 'St Kitts'!$B:$B, $A7, 'St Kitts'!$D:$D, "London") + SUMIFS(WestIndiesGeneral!$L:$L, WestIndiesGeneral!$B:$B, $A7, WestIndiesGeneral!$D:$D, "London") + SUMIFS(Anguilla!$L:$L, Anguilla!$B:$B, $A7, Anguilla!$D:$D, "London") + SUMIFS(Tortola!$L:$L, Tortola!$B:$B, $A7, Tortola!$D:$D, "London") -> 3 | C7: =SUMIFS(Antigua!$L:$L, Antigua!$B:$B, $A7, Antigua!$D:$D, "Out Ports") + SUMIFS(Barbados!$L:$L, Barbados!$B:$B, $A7, Barbados!$D:$D, "Out Ports") + SUMIFS(Bermuda!$L:$L, Bermuda!$B:$B, $A7, Bermuda!$D:$D, "Out Ports") + SUMIFS(Jamaica!$L:$L, Jamaica!$B:$B, $A7, Jamaica!$D:$D, "Out Ports") + SUMIFS(Mountserat!$L:$L, Mountserat!$B:$B, $A7, Mountserat!$D:$D, "Out Ports") + SUMIFS(Nevis!$L:$L, Nevis!$B:$B, $A7, Nevis!$D:$D, "Out Ports") + SUMIFS('St Kitts'!$L:$L, 'St Kitts'!$B:$B, $A7, 'St Kitts'!$D:$D, "Out Ports") + SUMIFS(WestIndiesGeneral!$L:$L, WestIndiesGeneral!$B:$B, $A7, WestIndiesGeneral!$D:$D, "Out Ports") + SUMIFS(Anguilla!$L:$L, Anguilla!$B:$B, $A7, Anguilla!$D:$D, "Out Ports") + SUMIFS(Tortola!$L:$L, Tortola!$B:$B, $A7, Tortola!$D:$D, "Out Ports") -> 0 | D7: =B7+C7 -> 3
A8: Bacon | B8: =SUMIFS(Antigua!$L:$L, Antigua!$B:$B, $A8, Antigua!$D:$D, "London") + SUMIFS(Barbados!$L:$L, Barbados!$B:$B, $A8, Barbados!$D:$D, "London") + SUMIFS(Bermuda!$L:$L, Bermuda!$B:$B, $A8, Bermuda!$D:$D, "London") + SUMIFS(Jamaica!$L:$L, Jamaica!$B:$B, $A8, Jamaica!$D:$D, "London") + SUMIFS(Mountserat!$L:$L, Mountserat!$B:$B, $A8, Mountserat!$D:$D, "London") + SUMIFS(Nevis!$L:$L, Nevis!$B:$B, $A8, Nevis!$D:$D, "London") + SUMIFS('St Kitts'!$L:$L, 'St Kitts'!$B:$B, $A8, 'St Kitts'!$D:$D, "London") + SUMIFS(WestIndiesGeneral!$L:$L, WestIndiesGeneral!$B:$B, $A8, WestIndiesGeneral!$D:$D, "London") + SUMIFS(Anguilla!$L:$L, Anguilla!$B:$B, $A8, Anguilla!$D:$D, "London") + SUMIFS(Tortola!$L:$L, Tortola!$B:$B, $A8, Tortola!$D:$D, "London") -> 0 | C8: =SUMIFS(Antigua!$L:$L, Antigua!$B:$B, $A8, Antigua!$D:$D, "Out Ports") + SUMIFS(Barbados!$L:$L, Barbados!$B:$B, $A8, Barbados!$D:$D, "Out Ports") + SUMIFS(Bermuda!$L:$L, Bermuda!$B:$B, $A8, Bermuda!$D:$D, "Out Ports") + SUMIFS(Jamaica!$L:$L, Jamaica!$B:$B, $A8, Jamaica!$D:$D, "Out Ports") + SUMIFS(Mountserat!$L:$L, Mountserat!$B:$B, $A8, Mountserat!$D:$D, "Out Ports") + SUMIFS(Nevis!$L:$L, Nevis!$B:$B, $A8, Nevis!$D:$D, "Out Ports") + SUMIFS('St Kitts'!$L:$L, 'St Kitts'!$B:$B, $A8, 'St Kitts'!$D:$D, "Out Ports") + SUMIFS(WestIndiesGeneral!$L:$L, WestIndiesGeneral!$B:$B, $A8, WestIndiesGeneral!$D:$D, "Out Ports") + SUMIFS(Anguilla!$L:$L, Anguilla!$B:$B, $A8, Anguilla!$D:$D, "Out Ports") + SUMIFS(Tortola!$L:$L, Tortola!$B:$B, $A8, Tortola!$D:$D, "Out Ports") -> 0 | D8: =B8+C8 -> 0
A9: Balsam Artificial | B9: =SUMIFS(Antigua!$L:$L, Antigua!$B:$B, $A9, Antigua!$D:$D, "London") + SUMIFS(Barbados!$L:$L, Barbados!$B:$B, $A9, Barbados!$D:$D, "London") + SUMIFS(Bermuda!$L:$L, Bermuda!$B:$B, $A9, Bermuda!$D:$D, "London") + SUMIFS(Jamaica!$L:$L, Jamaica!$B:$B, $A9, Jamaica!$D:$D, "London") + SUMIFS(Mountserat!$L:$L, Mountserat!$B:$B, $A9, Mountserat!$D:$D, "London") + SUMIFS(Nevis!$L:$L, Nevis!$B:$B, $A9, Nevis!$D:$D, "London") + SUMIFS('St Kitts'!$L:$L, 'St Kitts'!$B:$B, $A9, 'St Kitts'!$D:$D, "London") + SUMIFS(WestIndiesGeneral!$L:$L, WestIndiesGeneral!$B:$B, $A9, WestIndiesGeneral!$D:$D, "London") + SUMIFS(Anguilla!$L:$L, Anguilla!$B:$B, $A9, Anguilla!$D:$D, "London") + SUMIFS(Tortola!$L:$L, Tortola!$B:$B, $A9, Tortola!$D:$D, "London") -> 1.4513393 | C9: =SUMIFS(Antigua!$L:$L, Antigua!$B:$B, $A9, Antigua!$D:$D, "Out Ports") + SUMIFS(Barbados!$L:$L, Barbados!$B:$B, $A9, Barbados!$D:$D, "Out Ports") + SUMIFS(Bermuda!$L:$L, Bermuda!$B:$B, $A9, Bermuda!$D:$D, "Out Ports") + SUMIFS(Jamaica!$L:$L, Jamaica!$B:$B, $A9, Jamaica!$D:$D, "Out Ports") + SUMIFS(Mountserat!$L:$L, Mountserat!$B:$B, $A9, Mountserat!$D:$D, "Out Ports") + SUMIFS(Nevis!$L:$L, Nevis!$B:$B, $A9, Nevis!$D:$D, "Out Ports") + SUMIFS('St Kitts'!$L:$L, 'St Kitts'!$B:$B, $A9, 'St Kitts'!$D:$D, "Out Ports") + SUMIFS(WestIndiesGeneral!$L:$L, WestIndiesGeneral!$B:$B, $A9, WestIndiesGeneral!$D:$D, "Out Ports") + SUMIFS(Anguilla!$L:$L, Anguilla!$B:$B, $A9, Anguilla!$D:$D, "Out Ports") + SUMIFS(Tortola!$L:$L, Tortola!$B:$B, $A9, Tortola!$D:$D, "Out Ports") -> 0 | D9: =B9+C9 -> 1.4513393
A10: Balsam Natural | B10: =SUMIFS(Antigua!$L:$L, Antigua!$B:$B, $A10, Antigua!$D:$D, "London") + SUMIFS(Barbados!$L:$L, Barbados!$B:$B, $A10, Barbados!$D:$D, "London") + SUMIFS(Bermuda!$L:$L, Bermuda!$B:$B, $A10, Bermuda!$D:$D, "London") + SUMIFS(Jamaica!$L:$L, Jamaica!$B:$B, $A10, Jamaica!$D:$D, "London") + SUMIFS(Mountserat!$L:$L, Mountserat!$B:$B, $A10, Mountserat!$D:$D, "London") + SUMIFS(Nevis!$L:$L, Nevis!$B:$B, $A10, Nevis!$D:$D, "London") + SUMIFS('St Kitts'!$L:$L, 'St Kitts'!$B:$B, $A10, 'St Kitts'!$D:$D, "London") + SUMIFS(WestIndiesGeneral!$L:$L, WestIndiesGeneral!$B:$B, $A10, WestIndiesGeneral!$D:$D, "London") + SUMIFS(Anguilla!$L:$L, Anguilla!$B:$B, $A10, Anguilla!$D:$D, "London") + SUMIFS(Tortola!$L:$L, Tortola!$B:$B, $A10, Tortola!$D:$D, "London") -> 0 | C10: =SUMIFS(Antigua!$L:$L, Antigua!$B:$B, $A10, Antigua!$D:$D, "Out Ports") + SUMIFS(Barbados!$L:$L, Barbados!$B:$B, $A10, Barbados!$D:$D, "Out Ports") + SUMIFS(Bermuda!$L:$L, Bermuda!$B:$B, $A10, Bermuda!$D:$D, "Out Ports") + SUMIFS(Jamaica!$L:$L, Jamaica!$B:$B, $A10, Jamaica!$D:$D, "Out Ports") + SUMIFS(Mountserat!$L:$L, Mountserat!$B:$B, $A10, Mountserat!$D:$D, "Out Ports") + SUMIFS(Nevis!$L:$L, Nevis!$B:$B, $A10, Nevis!$D:$D, "Out Ports") + SUMIFS('St Kitts'!$L:$L, 'St Kitts'!$B:$B, $A10, 'St Kitts'!$D:$D, "Out Ports") + SUMIFS(WestIndiesGeneral!$L:$L, WestIndiesGeneral!$B:$B, $A10, WestIndiesGeneral!$D:$D, "Out Ports") + SUMIFS(Anguilla!$L:$L, Anguilla!$B:$B, $A10, Anguilla!$D:$D, "Out Ports") + SUMIFS(Tortola!$L:$L, Tortola!$B:$B, $A10, Tortola!$D:$D, "Out Ports") -> 0 | D10: =B10+C10 -> 0
A11: Barbados Tarr | B11: =SUMIFS(Antigua!$L:$L, Antigua!$B:$B, $A11, Antigua!$D:$D, "London") + SUMIFS(Barbados!$L:$L, Barbados!$B:$B, $A11, Barbados!$D:$D, "London") + SUMIFS(Bermuda!$L:$L, Bermuda!$B:$B, $A11, Bermuda!$D:$D, "London") + SUMIFS(Jamaica!$L:$L, Jamaica!$B:$B, $A11, Jamaica!$D:$D, "London") + SUMIFS(Mountserat!$L:$L, Mountserat!$B:$B, $A11, Mountserat!$D:$D, "London") + SUMIFS(Nevis!$L:$L, Nevis!$B:$B, $A11, Nevis!$D:$D, "London") + SUMIFS('St Kitts'!$L:$L, 'St Kitts'!$B:$B, $A11, 'St Kitts'!$D:$D, "London") + SUMIFS(WestIndiesGeneral!$L:$L, WestIndiesGeneral!$B:$B, $A11, WestIndiesGeneral!$D:$D, "London") + SUMIFS(Anguilla!$L:$L, Anguilla!$B:$B, $A11, Anguilla!$D:$D, "London") + SUMIFS(Tortola!$L:$L, Tortola!$B:$B, $A11, Tortola!$D:$D, "London") -> 1.4883929 | C11: =SUMIFS(Antigua!$L:$L, Antigua!$B:$B, $A11, Antigua!$D:$D, "Out Ports") + SUMIFS(Barbados!$L:$L, Barbados!$B:$B, $A11, Barbados!$D:$D, "Out Ports") + SUMIFS(Bermuda!$L:$L, Bermuda!$B:$B, $A11, Bermuda!$D:$D, "Out Ports") + SUMIFS(Jamaica!$L:$L, Jamaica!$B:$B, $A11, Jamaica!$D:$D, "Out Ports") + SUMIFS(Mountserat!$L:$L, Mountserat!$B:$B, $A11, Mountserat!$D:$D, "Out Ports") + SUMIFS(Nevis!$L:$L, Nevis!$B:$B, $A11, Nevis!$D:$D, "Out Ports") + SUMIFS('St Kitts'!$L:$L, 'St Kitts'!$B:$B, $A11, 'St Kitts'!$D:$D, "Out Ports") + SUMIFS(WestIndiesGeneral!$L:$L, WestIndiesGeneral!$B:$B, $A11, WestIndiesGeneral!$D:$D, "Out Ports") + SUMIFS(Anguilla!$L:$L, Anguilla!$B:$B, $A11, Anguilla!$D:$D, "Out Ports") + SUMIFS(Tortola!$L:$L, Tortola!$B:$B, $A11, Tortola!$D:$D, "Out Ports") -> 0 | D11: =B11+C11 -> 1.4883929
A12: Barrel Staves | B12: =SUMIFS(Antigua!$L:$L, Antigua!$B:$B, $A12, Antigua!$D:$D, "London") + SUMIFS(Barbados!$L:$L, Barbados!$B:$B, $A12, Barbados!$D:$D, "London") + SUMIFS(Bermuda!$L:$L, Bermuda!$B:$B, $A12, Bermuda!$D:$D, "London") + SUMIFS(Jamaica!$L:$L, Jamaica!$B:$B, $A12, Jamaica!$D:$D, "London") + SUMIFS(Mountserat!$L:$L, Mountserat!$B:$B, $A12, Mountserat!$D:$D, "London") + SUMIFS(Nevis!$L:$L, Nevis!$B:$B, $A12, Nevis!$D:$D, "London") + SUMIFS('St Kitts'!$L:$L, 'St Kitts'!$B:$B, $A12, 'St Kitts'!$D:$D, "London") + SUMIFS(WestIndiesGeneral!$L:$L, WestIndiesGeneral!$B:$B, $A12, WestIndiesGeneral!$D:$D, "London") + SUMIFS(Anguilla!$L:$L, Anguilla!$B:$B, $A12, Anguilla!$D:$D, "London") + SUMIFS(Tortola!$L:$L, Tortola!$B:$B, $A12, Tortola!$D:$D, "London") -> 0 | C12: =SUMIFS(Antigua!$L:$L, Antigua!$B:$B, $A12, Antigua!$D:$D, "Out Ports") + SUMIFS(Barbados!$L:$L, Barbados!$B:$B, $A12, Barbados!$D:$D, "Out Ports") + SUMIFS(Bermuda!$L:$L, Bermuda!$B:$B, $A12, Bermuda!$D:$D, "Out Ports") + SUMIFS(Jamaica!$L:$L, Jamaica!$B:$B, $A12, Jamaica!$D:$D, "Out Ports") + SUMIFS(Mountserat!$L:$L, Mountserat!$B:$B, $A12, Mountserat!$D:$D, "Out Ports") + SUMIFS(Nevis!$L:$L, Nevis!$B:$B, $A12, Nevis!$D:$D, "Out Ports") + SUMIFS('St Kitts'!$L:$L, 'St Kitts'!$B:$B, $A12, 'St Kitts'!$D:$D, "Out Ports") + SUMIFS(WestIndiesGeneral!$L:$L, WestIndiesGeneral!$B:$B, $A12, WestIndiesGeneral!$D:$D, "Out Ports") + SUMIFS(Anguilla!$L:$L, Anguilla!$B:$B, $A12, Anguilla!$D:$D, "Out Ports") + SUMIFS(Tortola!$L:$L, Tortola!$B:$B, $A12, Tortola!$D:$D, "Out Ports") -> 0 | D12: =B12+C12 -> 0
A13: Bay Berries | B13: =SUMIFS(Antigua!$L:$L, Antigua!$B:$B, $A13, Antigua!$D:$D, "London") + SUMIFS(Barbados!$L:$L, Barbados!$B:$B, $A13, Barbados!$D:$D, "London") + SUMIFS(Bermuda!$L:$L, Bermuda!$B:$B, $A13, Bermuda!$D:$D, "London") + SUMIFS(Jamaica!$L:$L, Jamaica!$B:$B, $A13, Jamaica!$D:$D, "London") + SUMIFS(Mountserat!$L:$L, Mountserat!$B:$B, $A13, Mountserat!$D:$D, "London") + SUMIFS(Nevis!$L:$L, Nevis!$B:$B, $A13, Nevis!$D:$D, "London") + SUMIFS('St Kitts'!$L:$L, 'St Kitts'!$B:$B, $A13, 'St Kitts'!$D:$D, "London") + SUMIFS(WestIndiesGeneral!$L:$L, WestIndiesGeneral!$B:$B, $A13, WestIndiesGeneral!$D:$D, "London") + SUMIFS(Anguilla!$L:$L, Anguilla!$B:$B, $A13, Anguilla!$D:$D, "London") + SUMIFS(Tortola!$L:$L, Tortola!$B:$B, $A13, Tortola!$D:$D, "London") -> 0 | C13: =SUMIFS(Antigua!$L:$L, Antigua!$B:$B, $A13, Antigua!$D:$D, "Out Ports") + SUMIFS(Barbados!$L:$L, Barbados!$B:$B, $A13, Barbados!$D:$D, "Out Ports") + SUMIFS(Bermuda!$L:$L, Bermuda!$B:$B, $A13, Bermuda!$D:$D, "Out Ports") + SUMIFS(Jamaica!$L:$L, Jamaica!$B:$B, $A13, Jamaica!$D:$D, "Out Ports") + SUMIFS(Mountserat!$L:$L, Mountserat!$B:$B, $A13, Mountserat!$D:$D, "Out Ports") + SUMIFS(Nevis!$L:$L, Nevis!$B:$B, $A13, Nevis!$D:$D, "Out Ports") + SUMIFS('St Kitts'!$L:$L, 'St Kitts'!$B:$B, $A13, 'St Kitts'!$D:$D, "Out Ports") + SUMIFS(WestIndiesGeneral!$L:$L, WestIndiesGeneral!$B:$B, $A13, WestIndiesGeneral!$D:$D, "Out Ports") + SUMIFS(Anguilla!$L:$L, Anguilla!$B:$B, $A13, Anguilla!$D:$D, "Out Ports") + SUMIFS(Tortola!$L:$L, Tortola!$B:$B, $A13, Tortola!$D:$D, "Out Ports") -> 0 | D13: =B13+C13 -> 0
... A74: Wood, Sweetwood | B74: =SUMIFS(Antigua!$L:$L, Antigua!$B:$B, $A74, Antigua!$D:$D, "London") + SUMIFS(Barbados!$L:$L, Barbados!$B:$B, $A74, Barbados!$D:$D, "London") + SUMIFS(Bermuda!$L:$L, Bermuda!$B:$B, $A74, Bermuda!$D:$D, "London") + SUMIFS(Jamaica!$L:$L, Jamaica!$B:$B, $A74, Jamaica!$D:$D, "London") + SUMIFS(Mountserat!$L:$L, Mountserat!$B:$B, $A74, Mountserat!$D:$D, "London") + SUMIFS(Nevis!$L:$L, Nevis!$B:$B, $A74, Nevis!$D:$D, "London") + SUMIFS('St Kitts'!$L:$L, 'St Kitts'!$B:$B, $A74, 'St Kitts'!$D:$D, "London") + SUMIFS(WestIndiesGeneral!$L:$L, WestIndiesGeneral!$B:$B, $A74, WestIndiesGeneral!$D:$D, "London") + SUMIFS(Anguilla!$L:$L, Anguilla!$B:$B, $A74, Anguilla!$D:$D, "London") + SUMIFS(Tortola!$L:$L, Tortola!$B:$B, $A74, Tortola!$D:$D, "London") -> 0 | C74: =SUMIFS(Antigua!$L:$L, Antigua!$B:$B, $A74, Antigua!$D:$D, "Out Ports") + SUMIFS(Barbados!$L:$L, Barbados!$B:$B, $A74, Barbados!$D:$D, "Out Ports") + SUMIFS(Bermuda!$L:$L, Bermuda!$B:$B, $A74, Bermuda!$D:$D, "Out Ports") + SUMIFS(Jamaica!$L:$L, Jamaica!$B:$B, $A74, Jamaica!$D:$D, "Out Ports") + SUMIFS(Mountserat!$L:$L, Mountserat!$B:$B, $A74, Mountserat!$D:$D, "Out Ports") + SUMIFS(Nevis!$L:$L, Nevis!$B:$B, $A74, Nevis!$D:$D, "Out Ports") + SUMIFS('St Kitts'!$L:$L, 'St Kitts'!$B:$B, $A74, 'St Kitts'!$D:$D, "Out Ports") + SUMIFS(WestIndiesGeneral!$L:$L, WestIndiesGeneral!$B:$B, $A74, WestIndiesGeneral!$D:$D, "Out Ports") + SUMIFS(Anguilla!$L:$L, Anguilla!$B:$B, $A74, Anguilla!$D:$D, "Out Ports") + SUMIFS(Tortola!$L:$L, Tortola!$B:$B, $A74, Tortola!$D:$D, "Out Ports") -> 0 | D74: =B74+C74 -> 0

Sheet Anguilla
A1: YEAR | B1: COMMODITY_NAME | C1: FROM_LOCATION | D1: TO_LOCATION | E1: ton | F1: hh | G1: quarter | H1: lb | J1: Total Pounds | L1: WEIGHT
A2: 1754 | B2: Almonds, Bitter | C2: Anguilla | D2: London | J2: =(E2*2240)+(F2*112)+(G2*28)+H2 -> 0 | L2: =J2/2240 -> 0
A3: 1754 | B3: Almonds, Sweet | C3: Anguilla | D3: London | J3: =(E3*2240)+(F3*112)+(G3*28)+H3 -> 0 | L3: =J3/2240 -> 0
A4: 1754 | B4: Aloes Epatica | C4: Anguilla | D4: London | J4: =(E4*2240)+(F4*112)+(G4*28)+H4 -> 0 | L4: =J4/2240 -> 0
A5: 1754 | B5: Annatto | C5: Anguilla | D5: London | J5: =(E5*2240)+(F5*112)+(G5*28)+H5 -> 0 | L5: =J5/2240 -> 0
A6: 1754 | B6: Anniseeds | C6: Anguilla | D6: London | J6: =(E6*2240)+(F6*112)+(G6*28)+H6 -> 0 | L6: =J6/2240 -> 0
A7: 1754 | B7: Bacon | C7: Anguilla | D7: London | J7: =(E7*2240)+(F7*112)+(G7*28)+H7 -> 0 | L7: =J7/2240 -> 0
A8: 1754 | B8: Barrel Staves | C8: Anguilla | D8: London | J8: =(E8*2240)+(F8*112)+(G8*28)+H8 -> 0 | L8: =J8/2240 -> 0
A9: 1754 | B9: Bay Berries | C9: Anguilla | D9: London | J9: =(E9*2240)+(F9*112)+(G9*28)+H9 -> 0 | L9: =J9/2240 -> 0
A10: 1754 | B10: Bees Wax | C10: Anguilla | D10: London | J10: =(E10*2240)+(F10*112)+(G10*28)+H10 -> 0 | L10: =J10/2240 -> 0
A11: 1754 | B11: Brimstone | C11: Anguilla | D11: London | J11: =(E11*2240)+(F11*112)+(G11*28)+H11 -> 0 | L11: =J11/2240 -> 0
A12: 1754 | B12: Brown Sugar | C12: Anguilla | D12: London | F12: 80 | J12: =(E12*2240)+(F12*112)+(G12*28)+H12 -> 8960 | L12: =J12/2240 -> 4
A13: 1754 | B13: Cassia Fistula | C13: Anguilla | D13: London | J13: =(E13*2240)+(F13*112)+(G13*28)+H13 -> 0 | L13: =J13/2240 -> 0
A14: 1754 | B14: Chocolate Paste | C14: Anguilla | D14: London | J14: =(E14*2240)+(F14*112)+(G14*28)+H14 -> 0 | L14: =J14/2240 -> 0
A15: 1754 | B15: Cocheneal | C15: Anguilla | D15: London | J15: =(E15*2240)+(F15*112)+(G15*28)+H15 -> 0 | L15: =J15/2240 -> 0
A16: 1754 | B16: Cocoa Nuts | C16: Anguilla | D16: London | J16: =(E16*2240)+(F16*112)+(G16*28)+H16 -> 0 | L16: =J16/2240 -> 0
A17: 1754 | B17: Cocoa Paste | C17: Anguilla | D17: London | J17: =(E17*2240)+(F17*112)+(G17*28)+H17 -> 0 | L17: =J17/2240 -> 0
A18: 1754 | B18: Coffee | C18: Anguilla | D18: London | J18: =(E18*2240)+(F18*112)+(G18*28)+H18 -> 0 | L18: =J18/2240 -> 0
A19: 1754 | B19: Cortex Peru | C19: Anguilla | D19: London | J19: =(E19*2240)+(F19*112)+(G19*28)+H19 -> 0 | L19: =J19/2240 -> 0
A20: 1754 | B20: Cortex Winteranus | C20: Anguilla | D20: London | J20: =(E20*2240)+(F20*112)+(G20*28)+H20 -> 0 | L20: =J20/2240 -> 0
A21: 1754 | B21: Cotton | C21: Anguilla | D21: London | H21: =20*200 -> 4000 | I21: 20bags | J21: =(E21*2240)+(F21*112)+(G21*28)+H21 -> 4000 | L21: =J21/2240 -> 1.7857143
A22: 1754 | B22: Dry Ginger | C22: Anguilla | D22: London | J22: =(E22*2240)+(F22*112)+(G22*28)+H22 -> 0 | L22: =J22/2240 -> 0
A23: 1754 | B23: Elephant Teeth | C23: Anguilla | D23: London | J23: =(E23*2240)+(F23*112)+(G23*28)+H23 -> 0 | L23: =J23/2240 -> 0
A24: 1754 | B24: Green Ginger | C24: Anguilla | D24: London | J24: =(E24*2240)+(F24*112)+(G24*28)+H24 -> 0 | L24: =J24/2240 -> 0
A25: 1754 | B25: Guinea Grains | C25: Anguilla | D25: London | J25: =(E25*2240)+(F25*112)+(G25*28)+H25 -> 0 | L25: =J25/2240 -> 0
A26: 1754 | B26: Gum Guiaci | C26: Anguilla | D26: London | J26: =(E26*2240)+(F26*112)+(G26*28)+H26 -> 0 | L26: =J26/2240 -> 0
A27: 1754 | B27: Hemp | C27: Anguilla | D27: London | J27: =(E27*2240)+(F27*112)+(G27*28)+H27 -> 0 | L27: =J27/2240 -> 0
A28: 1754 | B28: Indigo, Plantation | C28: Anguilla | D28: London | J28: =(E28*2240)+(F28*112)+(G28*28)+H28 -> 0 | L28: =J28/2240 -> 0
A29: 1754 | B29: Indigo, Spanish | C29: Anguilla | D29: London | J29: =(E29*2240)+(F29*112)+(G29*28)+H29 -> 0 | L29: =J29/2240 -> 0
A30: 1754 | B30: Jollop | C30: Anguilla | D30: London | J30: =(E30*2240)+(F30*112)+(G30*28)+H30 -> 0 | L30: =J30/2240 -> 0
A31: 1754 | B31: Lemon Water | C31: Anguilla | D31: London | J31: =(E31*2240)+(F31*112)+(G31*28)+H31 -> 0 | L31: =J31/2240 -> 0
A32: 1754 | B32: Lignum Vitae | C32: Anguilla | D32: London | J32: =(E32*2240)+(F32*112)+(G32*28)+H32 -> 0 | L32: =J32/2240 -> 0
A33: 1754 | B33: Lime Juice | C33: Anguilla | D33: London | J33: =(E33*2240)+(F33*112)+(G33*28)+H33 -> 0 | L33: =J33/2240 -> 0
... A41: 1754 | B41: Rice | C41: Anguilla | D41: London | J41: =(E41*2240)+(F41*112)+(G41*28)+H41 -> 0 | L41: =J41/2240 -> 0
A42: 1754 | B42: Rum | C42: Anguilla | D42: London | H42: 240 | I42: 24g | J42: =(E42*2240)+(F42*112)+(G42*28)+H42 -> 240 | L42: =J42/2240 -> 0.10714286
A43: 1754 | B43: Sasparilla | C43: Anguilla | D43: London | J43: =(E43*2240)+(F43*112)+(G43*28)+H43 -> 0 | L43: =J43/2240 -> 0
A44: 1754 | B44: Saunders Yellow | C44: Anguilla | D44: London | J44: =(E44*2240)+(F44*112)+(G44*28)+H44 -> 0 | L44: =J44/2240 -> 0
A45: 1754 | B45: Shruff | C45: Anguilla | D45: London | J45: =(E45*2240)+(F45*112)+(G45*28)+H45 -> 0 | L45: =J45/2240 -> 0
A46: 1754 | B46: Snuff | C46: Anguilla | D46: London | J46: =(E46*2240)+(F46*112)+(G46*28)+H46 -> 0 | L46: =J46/2240 -> 0
A47: 1754 | B47: Smalts | C47: Anguilla | D47: London | J47: =(E47*2240)+(F47*112)+(G47*28)+H47 -> 0 | L47: =J47/2240 -> 0
...

Sheet Antigua
A1: YEAR | B1: COMMODITY_NAME | C1: FROM_LOCATION | D1: TO_LOCATION | E1: ton | F1: hh | G1: quarter | H1: lb | J1: Total Pounds | L1: WEIGHT
A2: 1754 | B2: Almonds, Bitter | C2: Antigua | D2: London | J2: =(E2*2240)+(F2*112)+(G2*28)+H2 -> 0 | L2: =J2/2240 -> 0
A3: 1754 | B3: Almonds, Sweet | C3: Antigua | D3: London | J3: =(E3*2240)+(F3*112)+(G3*28)+H3 -> 0 | L3: =J3/2240 -> 0
A4: 1754 | B4: Aloes Epatica | C4: Antigua | D4: London | J4: =(E4*2240)+(F4*112)+(G4*28)+H4 -> 0 | L4: =J4/2240 -> 0
A5: 1754 | B5: Annatto | C5: Antigua | D5: London | J5: =(E5*2240)+(F5*112)+(G5*28)+H5 -> 0 | L5: =J5/2240 -> 0
A6: 1754 | B6: Anniseeds | C6: Antigua | D6: London | J6: =(E6*2240)+(F6*112)+(G6*28)+H6 -> 0 | L6: =J6/2240 -> 0
A7: 1754 | B7: Bacon | C7: Antigua | D7: London | J7: =(E7*2240)+(F7*112)+(G7*28)+H7 -> 0 | L7: =J7/2240 -> 0
A8: 1754 | B8: Balsam Artificial | C8: Antigua | D8: London | J8: =(E8*2240)+(F8*112)+(G8*28)+H8 -> 0 | L8: =J8/2240 -> 0
A9: 1754 | B9: Balsam Natural | C9: Antigua | D9: London | J9: =(E9*2240)+(F9*112)+(G9*28)+H9 -> 0 | L9: =J9/2240 -> 0
A10: 1754 | B10: Barrel Staves | C10: Antigua | D10: London | J10: =(E10*2240)+(F10*112)+(G10*28)+H10 -> 0 | L10: =J10/2240 -> 0
A11: 1754 | B11: Bay Berries | C11: Antigua | D11: London | J11: =(E11*2240)+(F11*112)+(G11*28)+H11 -> 0 | L11: =J11/2240 -> 0
A12: 1754 | B12: Bees Wax | C12: Antigua | D12: London | F12: 2 | G12: 1 | J12: =(E12*2240)+(F12*112)+(G12*28)+H12 -> 252 | L12: =J12/2240 -> 0.1125
A13: 1754 | B13: Brimstone | C13: Antigua | D13: London | J13: =(E13*2240)+(F13*112)+(G13*28)+H13 -> 0 | L13: =J13/2240 -> 0
A14: 1754 | B14: Brown Sugar | C14: Antigua | D14: London | F14: 51365 | G14: 1 | H14: 8 | J14: =(E14*2240)+(F14*112)+(G14*28)+H14 -> 5752916 | L14: =J14/2240 -> 2568.2661
A15: 1754 | B15: Cascarilla | C15: Antigua | D15: London | J15: =(E15*2240)+(F15*112)+(G15*28)+H15 -> 0 | L15: =J15/2240 -> 0
A16: 1754 | B16: Cassia Fistula | C16: Antigua | D16: London | J16: =(E16*2240)+(F16*112)+(G16*28)+H16 -> 0 | L16: =J16/2240 -> 0
A17: 1754 | B17: Chocolate | C17: Antigua | D17: London | J17: =(E17*2240)+(F17*112)+(G17*28)+H17 -> 0 | L17: =J17/2240 -> 0
A18: 1754 | B18: Cocheneal | C18: Antigua | D18: London | J18: =(E18*2240)+(F18*112)+(G18*28)+H18 -> 0 | L18: =J18/2240 -> 0
A19: 1754 | B19: Cocoa Nuts | C19: Antigua | D19: London | F19: 1 | J19: =(E19*2240)+(F19*112)+(G19*28)+H19 -> 112 | L19: =J19/2240 -> 0.05
A20: 1754 | B20: Cocoa Paste | C20: Antigua | D20: London | J20: =(E20*2240)+(F20*112)+(G20*28)+H20 -> 0 | L20: =J20/2240 -> 0
A21: 1754 | B21: Coffee | C21: Antigua | D21: London | J21: =(E21*2240)+(F21*112)+(G21*28)+H21 -> 0 | L21: =J21/2240 -> 0
A22: 1754 | B22: Cortex Peru | C22: Antigua | D22: London | J22: =(E22*2240)+(F22*112)+(G22*28)+H22 -> 0 | L22: =J22/2240 -> 0
A23: 1754 | B23: Cortex Winteranus | C23: Antigua | D23: London | H23: 944 | J23: =(E23*2240)+(F23*112)+(G23*28)+H23 -> 944 | L23: =J23/2240 -> 0.42142857
A24: 1754 | B24: Cotton | C24: Antigua | D24: London | H24: =90*200 -> 18000 | I24: 90bags | J24: =(E24*2240)+(F24*112)+(G24*28)+H24 -> 18000 | L24: =J24/2240 -> 8.0357143
A25: 1754 | B25: Dry Ginger | C25: Antigua | D25: London | F25: 259 | G25: 2 | H25: 16 | J25: =(E25*2240)+(F25*112)+(G25*28)+H25 -> 29080 | L25: =J25/2240 -> 12.982143
A26: 1754 | B26: Elephant Teeth | C26: Antigua | D26: London | F26: 43 | H26: 12 | J26: =(E26*2240)+(F26*112)+(G26*28)+H26 -> 4828 | L26: =J26/2240 -> 2.1553571
A27: 1754 | B27: Green Ginger | C27: Antigua | D27: London | H27: 53 | J27: =(E27*2240)+(F27*112)+(G27*28)+H27 -> 53 | L27: =J27/2240 -> 0.023660714
A28: 1754 | B28: Guinea Grains | C28: Antigua | D28: London | J28: =(E28*2240)+(F28*112)+(G28*28)+H28 -> 0 | L28: =J28/2240 -> 0
A29: 1754 | B29: Gum Guiaci | C29: Antigua | D29: London | H29: 59 | J29: =(E29*2240)+(F29*112)+(G29*28)+H29 -> 59 | L29: =J29/2240 -> 0.026339286
A30: 1754 | B30: Gum Seneca | C30: Antigua | D30: London | J30: =(E30*2240)+(F30*112)+(G30*28)+H30 -> 0 | L30: =J30/2240 -> 0
A31: 1754 | B31: Hemp | C31: Antigua | D31: London | J31: =(E31*2240)+(F31*112)+(G31*28)+H31 -> 0 | L31: =J31/2240 -> 0
A32: 1754 | B32: Hypococania | C32: Antigua | D32: London | J32: =(E32*2240)+(F32*112)+(G32*28)+H32 -> 0 | L32: =J32/2240 -> 0
A33: 1754 | B33: Indigo | C33: Antigua | D33: London | J33: =(E33*2240)+(F33*112)+(G33*28)+H33 -> 0 | L33: =J33/2240 -> 0
A34: 1754 | B34: Jollop | C34: Antigua | D34: London | J34: =(E34*2240)+(F34*112)+(G34*28)+H34 -> 0 | L34: =J34/2240 -> 0
A35: 1754 | B35: Lemon Water | C35: Antigua | D35: London | J35: =(E35*2240)+(F35*112)+(G35*28)+H35 -> 0 | L35: =J35/2240 -> 0
A36: 1754 | B36: Lignum Vitae | C36: Antigua | D36: London | E36: 1 | J36: =(E36*2240)+(F36*112)+(G36*28)+H36 -> 2240 | L36: =J36/2240 -> 1
A37: 1754 | B37: Lime Juice | C37: Antigua | D37: London | J37: =(E37*2240)+(F37*112)+(G37*28)+H37 -> 0 | L37: =J37/2240 -> 0
A38: 1754 | B38: Loaf Sugar | C38: Antigua | D38: London | J38: =(E38*2240)+(F38*112)+(G38*28)+H38 -> 0 | L38: =J38/2240 -> 0
A39: 1754 | B39: Madera Wine | C39: Antigua | D39: London | H39: 224417.5 | I39: 89t 8g | J39: =(E39*2240)+(F39*112)+(G39*28)+H39 -> 224417.5 | L39: =J39/2240 -> 100.18638
A40: 1754 | B40: Molasses | C40: Antigua | D40: London | J40: =(E40*2240)+(F40*112)+(G40*28)+H40 -> 0 | L40: =J40/2240 -> 0
...

Sheet Barbados
A1: YEAR | B1: COMMODITY_NAME | C1: FROM_LOCATION | D1: TO_LOCATION | E1: ton | F1: hh | G1: quarter | H1: lb | J1: Total Pounds | L1: WEIGHT
A2: 1754 | B2: Almonds, Bitter | C2: Barbados | D2: London | J2: =(E2*2240)+(F2*112)+(G2*28)+H2 -> 0 | L2: =J2/2240 -> 0
A3: 1754 | B3: Almonds, Sweet | C3: Barbados | D3: London | J3: =(E3*2240)+(F3*112)+(G3*28)+H3 -> 0 | L3: =J3/2240 -> 0
A4: 1754 | B4: Aloes Epatica | C4: Barbados | D4: London | H4: 16368 | J4: =(E4*2240)+(F4*112)+(G4*28)+H4 -> 16368 | L4: =J4/2240 -> 7.3071429
A5: 1754 | B5: Annatto | C5: Barbados | D5: London | J5: =(E5*2240)+(F5*112)+(G5*28)+H5 -> 0 | L5: =J5/2240 -> 0
A6: 1754 | B6: Anniseeds | C6: Barbados | D6: London | J6: =(E6*2240)+(F6*112)+(G6*28)+H6 -> 0 | L6: =J6/2240 -> 0
A7: 1754 | B7: Archelia | C7: Barbados | D7: London | E7: 3 | J7: =(E7*2240)+(F7*112)+(G7*28)+H7 -> 6720 | L7: =J7/2240 -> 3
A8: 1754 | B8: Barbados Tarr | C8: Barbados | D8: London | H8: 3334 | J8: =(E8*2240)+(F8*112)+(G8*28)+H8 -> 3334 | L8: =J8/2240 -> 1.4883929
A9: 1754 | B9: Barrel Staves | C9: Barbados | D9: London | J9: =(E9*2240)+(F9*112)+(G9*28)+H9 -> 0 | L9: =J9/2240 -> 0
A10: 1754 | B10: Bees Wax | C10: Barbados | D10: London | F10: 30 | H10: 14 | J10: =(E10*2240)+(F10*112)+(G10*28)+H10 -> 3374 | L10: =J10/2240 -> 1.50625
A11: 1754 | B11: Brimstone | C11: Barbados | D11: London | J11: =(E11*2240)+(F11*112)+(G11*28)+H11 -> 0 | L11: =J11/2240 -> 0
A12: 1754 | B12: Brown Sugar | C12: Barbados | D12: London | F12: 79864 | G12: 1 | H12: 24 | J12: =(E12*2240)+(F12*112)+(G12*28)+H12 -> 8944820 | L12: =J12/2240 -> 3993.2232
A13: 1754 | B13: Cassia Fistula | C13: Barbados | D13: London | H13: 1117 | J13: =(E13*2240)+(F13*112)+(G13*28)+H13 -> 1117 | L13: =J13/2240 -> 0.49866071
A14: 1754 | B14: Chocolate | C14: Barbados | D14: London | J14: =(E14*2240)+(F14*112)+(G14*28)+H14 -> 0 | L14: =J14/2240 -> 0
A15: 1754 | B15: Cocheneal | C15: Barbados | D15: London | J15: =(E15*2240)+(F15*112)+(G15*28)+H15 -> 0 | L15: =J15/2240 -> 0
A16: 1754 | B16: Cocoa Nuts | C16: Barbados | D16: London | F16: 90 | H16: 8 | J16: =(E16*2240)+(F16*112)+(G16*28)+H16 -> 10088 | L16: =J16/2240 -> 4.5035714
A17: 1754 | B17: Cocoa Paste | C17: Barbados | D17: London | J17: =(E17*2240)+(F17*112)+(G17*28)+H17 -> 0 | L17: =J17/2240 -> 0
A18: 1754 | B18: Cortex Eletheria | C18: Barbados | D18: London | H18: 20 | J18: =(E18*2240)+(F18*112)+(G18*28)+H18 -> 20 | L18: =J18/2240 -> 0.0089285714
A19: 1754 | B19: Cortex Peru | C19: Barbados | D19: London | J19: =(E19*2240)+(F19*112)+(G19*28)+H19 -> 0 | L19: =J19/2240 -> 0
A20: 1754 | B20: Cotton | C20: Barbados | D20: London | H20: =1196.5*200 -> 239300 | I20: 1196.5bags | J20: =(E20*2240)+(F20*112)+(G20*28)+H20 -> 239300 | L20: =J20/2240 -> 106.83036
A21: 1754 | B21: Dry Ginger | C21: Barbados | D21: London | F21: 3574 | G21: 2 | H21: 10 | J21: =(E21*2240)+(F21*112)+(G21*28)+H21 -> 400354 | L21: =J21/2240 -> 178.72946
A22: 1754 | B22: Elephant Teeth | C22: Barbados | D22: London | F22: 42 | G22: 3 | J22: =(E22*2240)+(F22*112)+(G22*28)+H22 -> 4788 | L22: =J22/2240 -> 2.1375
A23: 1754 | B23: Green Ginger | C23: Barbados | D23: London | H23: 664 | J23: =(E23*2240)+(F23*112)+(G23*28)+H23 -> 664 | L23: =J23/2240 -> 0.29642857
A24: 1754 | B24: Guinea Grains | C24: Barbados | D24: London | H24: 1427 | J24: =(E24*2240)+(F24*112)+(G24*28)+H24 -> 1427 | L24: =J24/2240 -> 0.63705357
A25: 1754 | B25: Gum Seneca | C25: Barbados | D25: London | J25: =(E25*2240)+(F25*112)+(G25*28)+H25 -> 0 | L25: =J25/2240 -> 0
A26: 1754 | B26: Hemp | C26: Barbados | D26: London | J26: =(E26*2240)+(F26*112)+(G26*28)+H26 -> 0 | L26: =J26/2240 -> 0
A27: 1754 | B27: Indigo | C27: Barbados | D27: London | H27: 500 | J27: =(E27*2240)+(F27*112)+(G27*28)+H27 -> 500 | L27: =J27/2240 -> 0.22321429
A28: 1754 | B28: Lemon Water | C28: Barbados | D28: London | J28: =(E28*2240)+(F28*112)+(G28*28)+H28 -> 0 | L28: =J28/2240 -> 0
A29: 1754 | B29: Lignum Vitae | C29: Barbados | D29: London | E29: 21 | J29: =(E29*2240)+(F29*112)+(G29*28)+H29 -> 47040 | L29: =J29/2240 -> 21
A30: 1754 | B30: Lime Juice | C30: Barbados | D30: London | J30: =(E30*2240)+(F30*112)+(G30*28)+H30 -> 0 | L30: =J30/2240 -> 0
A31: 1754 | B31: Loaf Sugar | C31: Barbados | D31: London | J31: =(E31*2240)+(F31*112)+(G31*28)+H31 -> 0 | L31: =J31/2240 -> 0
A32: 1754 | B32: Madera Wine | C32: Barbados | D32: London | H32: 337777 | I32: 134t 1g | J32: =(E32*2240)+(F32*112)+(G32*28)+H32 -> 337777 | L32: =J32/2240 -> 150.7933
A33: 1754 | B33: Molasses | C33: Barbados | D33: London | J33: =(E33*2240)+(F33*112)+(G33*28)+H33 -> 0 | L33: =J33/2240 -> 0
A34: 1754 | B34: Oranges | C34: Barbados | D34: London | J34: =(E34*2240)+(F34*112)+(G34*28)+H34 -> 0 | L34: =J34/2240 -> 0
A35: 1754 | B35: Pickles | C35: Barbados | D35: London | H35: 310 | I35: 31g | J35: =(E35*2240)+(F35*112)+(G35*28)+H35 -> 310 | L35: =J35/2240 -> 0.13839286
A36: 1754 | B36: Pig Iron | C36: Barbados | D36: London | E36: 30 | J36: =(E36*2240)+(F36*112)+(G36*28)+H36 -> 67200 | L36: =J36/2240 -> 30
A37: 1754 | B37: Pimento | C37: Barbados | D37: London | J37: =(E37*2240)+(F37*112)+(G37*28)+H37 -> 0 | L37: =J37/2240 -> 0
A38: 1754 | B38: Rice | C38: Barbados | D38: London | J38: =(E38*2240)+(F38*112)+(G38*28)+H38 -> 0 | L38: =J38/2240 -> 0
A39: 1754 | B39: Rum | C39: Barbados | D39: London | H39: 195027.5 | I39: 19497.75g | J39: =(E39*2240)+(F39*112)+(G39*28)+H39 -> 195027.5 | L39: =J39/2240 -> 87.065848
A40: 1754 | B40: Sasparilla | C40: Barbados | D40: London | H40: 336 | J40: =(E40*2240)+(F40*112)+(G40*28)+H40 -> 336 | L40: =J40/2240 -> 0.15
...

Sheet Bermuda
A1: YEAR | B1: COMMODITY_NAME | C1: FROM_LOCATION | D1: TO_LOCATION | E1: ton | F1: hh | G1: quarter | H1: lb | J1: Total Pounds | L1: WEIGHT
A2: 1754 | B2: Aloes Epatica | C2: Bermuda | D2: London | H2: 963 | J2: =(E2*2240)+(F2*112)+(G2*28)+H2 -> 963 | L2: =J2/2240 -> 0.42991071
A3: 1754 | B3: Bermudos Plat | C3: Bermuda | D3: London | J3: =(E3*2240)+(F3*112)+(G3*28)+H3 -> 0 | L3: =J3/2240 -> 0
A4: 1754 | B4: Brown Sugar | C4: Bermuda | D4: London | J4: =(E4*2240)+(F4*112)+(G4*28)+H4 -> 0 | L4: =J4/2240 -> 0
A5: 1754 | B5: Cocoa Nuts | C5: Bermuda | D5: London | J5: =(E5*2240)+(F5*112)+(G5*28)+H5 -> 0 | L5: =J5/2240 -> 0
A6: 1754 | B6: Cotton | C6: Bermuda | D6: London | H6: =45*200 -> 9000 | I6: 45bags | J6: =(E6*2240)+(F6*112)+(G6*28)+H6 -> 9000 | L6: =J6/2240 -> 4.0178571
A7: 1754 | B7: Elephant Teeth | C7: Bermuda | D7: London | J7: =(E7*2240)+(F7*112)+(G7*28)+H7 -> 0 | L7: =J7/2240 -> 0
A8: 1754 | B8: Gum Guiaci | C8: Bermuda | D8: London | H8: 108 | J8: =(E8*2240)+(F8*112)+(G8*28)+H8 -> 108 | L8: =J8/2240 -> 0.048214286
A9: 1754 | B9: Indigo | C9: Bermuda | D9: London | J9: =(E9*2240)+(F9*112)+(G9*28)+H9 -> 0 | L9: =J9/2240 -> 0
A10: 1754 | B10: Madera Wine | C10: Bermuda | D10: London | J10: =(E10*2240)+(F10*112)+(G10*28)+H10 -> 0 | L10: =J10/2240 -> 0
A11: 1754 | B11: Molasses | C11: Bermuda | D11: London | J11: =(E11*2240)+(F11*112)+(G11*28)+H11 -> 0 | L11: =J11/2240 -> 0
A12: 1754 | B12: Rice | C12: Bermuda | D12: London | J12: =(E12*2240)+(F12*112)+(G12*28)+H12 -> 0 | L12: =J12/2240 -> 0
A13: 1754 | B13: Rum | C13: Bermuda | D13: London | H13: 590 | I13: 59g | J13: =(E13*2240)+(F13*112)+(G13*28)+H13 -> 590 | L13: =J13/2240 -> 0.26339286
A14: 1754 | B14: Shruff | C14: Bermuda | D14: London | J14: =(E14*2240)+(F14*112)+(G14*28)+H14 -> 0 | L14: =J14/2240 -> 0
A15: 1754 | B15: Succads | C15: Bermuda | D15: London | H15: 28 | J15: =(E15*2240)+(F15*112)+(G15*28)+H15 -> 28 | L15: =J15/2240 -> 0.0125
A16: 1754 | B16: Tortoise Shell | C16: Bermuda | D16: London | H16: 336 | J16: =(E16*2240)+(F16*112)+(G16*28)+H16 -> 336 | L16: =J16/2240 -> 0.15
A17: 1754 | B17: Turpentine | C17: Bermuda | D17: London | J17: =(E17*2240)+(F17*112)+(G17*28)+H17 -> 0 | L17: =J17/2240 -> 0
A18: 1754 | B18: Wood, Braziletto | C18: Bermuda | D18: London | E18: 12 | J18: =(E18*2240)+(F18*112)+(G18*28)+H18 -> 26880 | L18: =J18/2240 -> 12
A19: 1754 | B19: Wood, Fustick | C19: Bermuda | D19: London | F19: 2 | G19: 3 | H19: 19 | J19: =(E19*2240)+(F19*112)+(G19*28)+H19 -> 327 | L19: =J19/2240 -> 0.14598214
A20: 1754 | B20: Wood, Logwood | C20: Bermuda | D20: London | E20: 80 | J20: =(E20*2240)+(F20*112)+(G20*28)+H20 -> 179200 | L20: =J20/2240 -> 80
A21: 1754 | B21: Brown Sugar | C21: Bermuda | D21: Out Ports | J21: =(E21*2240)+(F21*112)+(G21*28)+H21 -> 0 | L21: =J21/2240 -> 0
A22: 1754 | B22: Indigo | C22: Bermuda | D22: Out Ports | J22: =(E22*2240)+(F22*112)+(G22*28)+H22 -> 0 | L22: =J22/2240 -> 0
A23: 1754 | B23: Logwood | C23: Bermuda | D23: Out Ports | J23: =(E23*2240)+(F23*112)+(G23*28)+H23 -> 0 | L23: =J23/2240 -> 0
A24: 1754 | B24: Madera Wine | C24: Bermuda | D24: Out Ports | J24: =(E24*2240)+(F24*112)+(G24*28)+H24 -> 0 | L24: =J24/2240 -> 0
A25: 1754 | B25: Rice | C25: Bermuda | D25: Out Ports | J25: =(E25*2240)+(F25*112)+(G25*28)+H25 -> 0 | L25: =J25/2240 -> 0
A26: 1754 | B26: Shruff | C26: Bermuda | D26: Out Ports | J26: =(E26*2240)+(F26*112)+(G26*28)+H26 -> 0 | L26: =J26/2240 -> 0
A27: 1754 | B27: Succads | C27: Bermuda | D27: Out Ports | J27: =(E27*2240)+(F27*112)+(G27*28)+H27 -> 0 | L27: =J27/2240 -> 0
A28: 1754 | B28: Cotton | C28: Bermuda | D28: Out Ports | J28: =(E28*2240)+(F28*112)+(G28*28)+H28 -> 0 | L28: =J28/2240 -> 0
A29: 1754 | B29: Cocoa Nuts | C29: Bermuda | D29: Out Ports | J29: =(E29*2240)+(F29*112)+(G29*28)+H29 -> 0 | L29: =J29/2240 -> 0
A30: 1754 | B30: Wood, Braziletto | C30: Bermuda | D30: Out Ports | J30: =(E30*2240)+(F30*112)+(G30*28)+H30 -> 0 | L30: =J30/2240 -> 0
A31: 1754 | B31: Wood, Logwood | C31: Bermuda | D31: Out Ports | J31: =(E31*2240)+(F31*112)+(G31*28)+H31 -> 0 | L31: =J31/2240 -> 0

Sheet Jamaica
A1: YEAR | B1: COMMODITY_NAME | C1: FROM_LOCATION | D1: TO_LOCATION | E1: ton | F1: hh | G1: quarter | H1: lb | J1: Total Pounds | L1: WEIGHT
A2: 1754 | B2: Almonds, Bitter | C2: Jamaica | D2: London | J2: =(E2*2240)+(F2*112)+(G2*28)+H2 -> 0 | L2: =J2/2240 -> 0
A3: 1754 | B3: Almonds, Sweet | C3: Jamaica | D3: London | J3: =(E3*2240)+(F3*112)+(G3*28)+H3 -> 0 | L3: =J3/2240 -> 0
A4: 1754 | B4: Aloes Epatica | C4: Jamaica | D4: London | H4: 224 | J4: =(E4*2240)+(F4*112)+(G4*28)+H4 -> 224 | L4: =J4/2240 -> 0.1
A5: 1754 | B5: Annatto | C5: Jamaica | D5: London | J5: =(E5*2240)+(F5*112)+(G5*28)+H5 -> 0 | L5: =J5/2240 -> 0
A6: 1754 | B6: Anniseeds | C6: Jamaica | D6: London | J6: =(E6*2240)+(F6*112)+(G6*28)+H6 -> 0 | L6: =J6/2240 -> 0
A7: 1754 | B7: Bacon | C7: Jamaica | D7: London | J7: =(E7*2240)+(F7*112)+(G7*28)+H7 -> 0 | L7: =J7/2240 -> 0
A8: 1754 | B8: Balsam Artificial | C8: Jamaica | D8: London | H8: 3251 | J8: =(E8*2240)+(F8*112)+(G8*28)+H8 -> 3251 | L8: =J8/2240 -> 1.4513393
A9: 1754 | B9: Balsam Natural | C9: Jamaica | D9: London | J9: =(E9*2240)+(F9*112)+(G9*28)+H9 -> 0 | L9: =J9/2240 -> 0
A10: 1754 | B10: Barrel Staves | C10: Jamaica | D10: London | J10: =(E10*2240)+(F10*112)+(G10*28)+H10 -> 0 | L10: =J10/2240 -> 0
A11: 1754 | B11: Bay Berries | C11: Jamaica | D11: London | J11: =(E11*2240)+(F11*112)+(G11*28)+H11 -> 0 | L11: =J11/2240 -> 0
A12: 1754 | B12: Bees Wax | C12: Jamaica | D12: London | F12: 4 | G12: 3 | H12: 9 | J12: =(E12*2240)+(F12*112)+(G12*28)+H12 -> 541 | L12: =J12/2240 -> 0.24151786
A13: 1754 | B13: Brimstone | C13: Jamaica | D13: London | J13: =(E13*2240)+(F13*112)+(G13*28)+H13 -> 0 | L13: =J13/2240 -> 0
A14: 1754 | B14: Brown Sugar | C14: Jamaica | D14: London | F14: 267186 | H14: 6 | J14: =(E14*2240)+(F14*112)+(G14*28)+H14 -> 29924838 | L14: =J14/2240 -> 13359.303
A15: 1754 | B15: Cascarilla | C15: Jamaica | D15: London | J15: =(E15*2240)+(F15*112)+(G15*28)+H15 -> 0 | L15: =J15/2240 -> 0
A16: 1754 | B16: Cassia Fistula | C16: Jamaica | D16: London | J16: =(E16*2240)+(F16*112)+(G16*28)+H16 -> 0 | L16: =J16/2240 -> 0
A17: 1754 | B17: Chocolate | C17: Jamaica | D17: London | J17: =(E17*2240)+(F17*112)+(G17*28)+H17 -> 0 | L17: =J17/2240 -> 0
A18: 1754 | B18: Cocheneal | C18: Jamaica | D18: London | H18: 40 | J18: =(E18*2240)+(F18*112)+(G18*28)+H18 -> 40 | L18: =J18/2240 -> 0.017857143
A19: 1754 | B19: Cocoa Nuts | C19: Jamaica | D19: London | F19: 176 | G19: 1 | H19: 18 | J19: =(E19*2240)+(F19*112)+(G19*28)+H19 -> 19758 | L19: =J19/2240 -> 8.8205357
A20: 1754 | B20: Cocoa Paste | C20: Jamaica | D20: London | J20: =(E20*2240)+(F20*112)+(G20*28)+H20 -> 0 | L20: =J20/2240 -> 0
A21: 1754 | B21: Coffee | C21: Jamaica | D21: London | F21: 702 | H21: 2 | J21: =(E21*2240)+(F21*112)+(G21*28)+H21 -> 78626 | L21: =J21/2240 -> 35.100893
A22: 1754 | B22: Cortex Peru | C22: Jamaica | D22: London | H22: 55983 | J22: =(E22*2240)+(F22*112)+(G22*28)+H22 -> 55983 | L22: =J22/2240 -> 24.992411
A23: 1754 | B23: Cortex Winteranus | C23: Jamaica | D23: London | H23: 784 | J23: =(E23*2240)+(F23*112)+(G23*28)+H23 -> 784 | L23: =J23/2240 -> 0.35
A24: 1754 | B24: Cotton | C24: Jamaica | D24: London | H24: =1078*200 -> 215600 | I24: 1078bags | J24: =(E24*2240)+(F24*112)+(G24*28)+H24 -> 215600 | L24: =J24/2240 -> 96.25
A25: 1754 | B25: Dry Ginger | C25: Jamaica | D25: London | F25: 4732 | G25: 2 | H25: 2 | J25: =(E25*2240)+(F25*112)+(G25*28)+H25 -> 530042 | L25: =J25/2240 -> 236.62589
A26: 1754 | B26: Elephant Teeth | C26: Jamaica | D26: London | F26: 140 | G26: 2 | H26: 14 | J26: =(E26*2240)+(F26*112)+(G26*28)+H26 -> 15750 | L26: =J26/2240 -> 7.03125
A27: 1754 | B27: Green Ginger | C27: Jamaica | D27: London | H27: 499 | J27: =(E27*2240)+(F27*112)+(G27*28)+H27 -> 499 | L27: =J27/2240 -> 0.22276786
A28: 1754 | B28: Guinea Grains | C28: Jamaica | D28: London | H28: 618 | J28: =(E28*2240)+(F28*112)+(G28*28)+H28 -> 618 | L28: =J28/2240 -> 0.27589286
A29: 1754 | B29: Gum Guiaci | C29: Jamaica | D29: London | H29: 4663 | J29: =(E29*2240)+(F29*112)+(G29*28)+H29 -> 4663 | L29: =J29/2240 -> 2.0816964
A30: 1754 | B30: Hemp | C30: Jamaica | D30: London | J30: =(E30*2240)+(F30*112)+(G30*28)+H30 -> 0 | L30: =J30/2240 -> 0
A31: 1754 | B31: Hypococania | C31: Jamaica | D31: London | H31: 3 | J31: =(E31*2240)+(F31*112)+(G31*28)+H31 -> 3 | L31: =J31/2240 -> 0.0013392857
A32: 1754 | B32: Indigo | C32: Jamaica | D32: London | H32: 7954 | J32: =(E32*2240)+(F32*112)+(G32*28)+H32 -> 7954 | L32: =J32/2240 -> 3.5508929
A33: 1754 | B33: Jollop | C33: Jamaica | D33: London | J33: =(E33*2240)+(F33*112)+(G33*28)+H33 -> 0 | L33: =J33/2240 -> 0
A34: 1754 | B34: Lemon Water | C34: Jamaica | D34: London | J34: =(E34*2240)+(F34*112)+(G34*28)+H34 -> 0 | L34: =J34/2240 -> 0
A35: 1754 | B35: Lignum Vitae | C35: Jamaica | D35: London | E35: 115 | F35: 10 | J35: =(E35*2240)+(F35*112)+(G35*28)+H35 -> 258720 | L35: =J35/2240 -> 115.5
A36: 1754 | B36: Lime Juice | C36: Jamaica | D36: London | H36: 4001 | I36: 400g | J36: =(E36*2240)+(F36*112)+(G36*28)+H36 -> 4001 | L36: =J36/2240 -> 1.7861607
A37: 1754 | B37: Loaf Sugar | C37: Jamaica | D37: London | J37: =(E37*2240)+(F37*112)+(G37*28)+H37 -> 0 | L37: =J37/2240 -> 0
A38: 1754 | B38: Madera Wine | C38: Jamaica | D38: London | H38: 176495.5 | I38: 70t 5g | J38: =(E38*2240)+(F38*112)+(G38*28)+H38 -> 176495.5 | L38: =J38/2240 -> 78.792634
A39: 1754 | B39: Molasses | C39: Jamaica | D39: London | J39: =(E39*2240)+(F39*112)+(G39*28)+H39 -> 0 | L39: =J39/2240 -> 0
A40: 1754 | B40: Oranges | C40: Jamaica | D40: London | J40: =(E40*2240)+(F40*112)+(G40*28)+H40 -> 0 | L40: =J40/2240 -> 0
...

Sheet Mountserat
A1: YEAR | B1: COMMODITY_NAME | C1: FROM_LOCATION | D1: TO_LOCATION | E1: ton | F1: hh | G1: quarter | H1: lb | J1: Total Pounds | L1: WEIGHT
A2: 1754 | B2: Almonds, Bitter | C2: Mountserat | D2: London | J2: =(E2*2240)+(F2*112)+(G2*28)+H2 -> 0 | L2: =J2/2240 -> 0
A3: 1754 | B3: Almonds, Sweet | C3: Mountserat | D3: London | J3: =(E3*2240)+(F3*112)+(G3*28)+H3 -> 0 | L3: =J3/2240 -> 0
A4: 1754 | B4: Aloes Epatica | C4: Mountserat | D4: London | J4: =(E4*2240)+(F4*112)+(G4*28)+H4 -> 0 | L4: =J4/2240 -> 0
A5: 1754 | B5: Annatto | C5: Mountserat | D5: London | J5: =(E5*2240)+(F5*112)+(G5*28)+H5 -> 0 | L5: =J5/2240 -> 0
A6: 1754 | B6: Anniseeds | C6: Mountserat | D6: London | J6: =(E6*2240)+(F6*112)+(G6*28)+H6 -> 0 | L6: =J6/2240 -> 0
A7: 1754 | B7: Bacon | C7: Mountserat | D7: London | J7: =(E7*2240)+(F7*112)+(G7*28)+H7 -> 0 | L7: =J7/2240 -> 0
A8: 1754 | B8: Barrel Staves | C8: Mountserat | D8: London | J8: =(E8*2240)+(F8*112)+(G8*28)+H8 -> 0 | L8: =J8/2240 -> 0
A9: 1754 | B9: Bay Berries | C9: Mountserat | D9: London | J9: =(E9*2240)+(F9*112)+(G9*28)+H9 -> 0 | L9: =J9/2240 -> 0
A10: 1754 | B10: Bees Wax | C10: Mountserat | D10: London | J10: =(E10*2240)+(F10*112)+(G10*28)+H10 -> 0 | L10: =J10/2240 -> 0
A11: 1754 | B11: Brimstone | C11: Mountserat | D11: London | J11: =(E11*2240)+(F11*112)+(G11*28)+H11 -> 0 | L11: =J11/2240 -> 0
A12: 1754 | B12: Brown Sugar | C12: Mountserat | D12: London | F12: 33178 | G12: 3 | H12: 10 | J12: =(E12*2240)+(F12*112)+(G12*28)+H12 -> 3716030 | L12: =J12/2240 -> 1658.942
A13: 1754 | B13: Cascarilla | C13: Mountserat | D13: London | J13: =(E13*2240)+(F13*112)+(G13*28)+H13 -> 0 | L13: =J13/2240 -> 0
A14: 1754 | B14: Cassia Fistula | C14: Mountserat | D14: London | J14: =(E14*2240)+(F14*112)+(G14*28)+H14 -> 0 | L14: =J14/2240 -> 0
A15: 1754 | B15: Chocolate | C15: Mountserat | D15: London | J15: =(E15*2240)+(F15*112)+(G15*28)+H15 -> 0 | L15: =J15/2240 -> 0
A16: 1754 | B16: Cocheneal | C16: Mountserat | D16: London | J16: =(E16*2240)+(F16*112)+(G16*28)+H16 -> 0 | L16: =J16/2240 -> 0
A17: 1754 | B17: Cocoa Nuts | C17: Mountserat | D17: London | J17: =(E17*2240)+(F17*112)+(G17*28)+H17 -> 0 | L17: =J17/2240 -> 0
A18: 1754 | B18: Cocoa Paste | C18: Mountserat | D18: London | J18: =(E18*2240)+(F18*112)+(G18*28)+H18 -> 0 | L18: =J18/2240 -> 0
A19: 1754 | B19: Coffee | C19: Mountserat | D19: London | J19: =(E19*2240)+(F19*112)+(G19*28)+H19 -> 0 | L19: =J19/2240 -> 0
A20: 1754 | B20: Cortex Peru | C20: Mountserat | D20: London | J20: =(E20*2240)+(F20*112)+(G20*28)+H20 -> 0 | L20: =J20/2240 -> 0
A21: 1754 | B21: Cortex Winteranus | C21: Mountserat | D21: London | J21: =(E21*2240)+(F21*112)+(G21*28)+H21 -> 0 | L21: =J21/2240 -> 0
A22: 1754 | B22: Cotton | C22: Mountserat | D22: London | H22: =120*200 -> 24000 | I22: 120bags | J22: =(E22*2240)+(F22*112)+(G22*28)+H22 -> 24000 | L22: =J22/2240 -> 10.714286
A23: 1754 | B23: Dry Ginger | C23: Mountserat | D23: London | F23: 512 | G23: 2 | H23: 8 | J23: =(E23*2240)+(F23*112)+(G23*28)+H23 -> 57408 | L23: =J23/2240 -> 25.628571
A24: 1754 | B24: Elephant Teeth | C24: Mountserat | D24: London | F24: 3 | G24: 3 | H24: 20 | J24: =(E24*2240)+(F24*112)+(G24*28)+H24 -> 440 | L24: =J24/2240 -> 0.19642857
A25: 1754 | B25: Green Ginger | C25: Mountserat | D25: London | H25: 23 | J25: =(E25*2240)+(F25*112)+(G25*28)+H25 -> 23 | L25: =J25/2240 -> 0.010267857
A26: 1754 | B26: Guinea Grains | C26: Mountserat | D26: London | H26: 419 | J26: =(E26*2240)+(F26*112)+(G26*28)+H26 -> 419 | L26: =J26/2240 -> 0.18705357
A27: 1754 | B27: Gum Guiaci | C27: Mountserat | D27: London | H27: 169 | J27: =(E27*2240)+(F27*112)+(G27*28)+H27 -> 169 | L27: =J27/2240 -> 0.075446429
A28: 1754 | B28: Hemp | C28: Mountserat | D28: London | J28: =(E28*2240)+(F28*112)+(G28*28)+H28 -> 0 | L28: =J28/2240 -> 0
A29: 1754 | B29: Hypococania | C29: Mountserat | D29: London | J29: =(E29*2240)+(F29*112)+(G29*28)+H29 -> 0 | L29: =J29/2240 -> 0
A30: 1754 | B30: Indigo | C30: Mountserat | D30: London | H30: 1275 | J30: =(E30*2240)+(F30*112)+(G30*28)+H30 -> 1275 | L30: =J30/2240 -> 0.56919643
A31: 1754 | B31: Jollop | C31: Mountserat | D31: London | J31: =(E31*2240)+(F31*112)+(G31*28)+H31 -> 0 | L31: =J31/2240 -> 0
A32: 1754 | B32: Lemon Water | C32: Mountserat | D32: London | J32: =(E32*2240)+(F32*112)+(G32*28)+H32 -> 0 | L32: =J32/2240 -> 0
A33: 1754 | B33: Lignum Vitae | C33: Mountserat | D33: London | E33: 14 | F33: 14 | J33: =(E33*2240)+(F33*112)+(G33*28)+H33 -> 32928 | L33: =J33/2240 -> 14.7
A34: 1754 | B34: Lime Juice | C34: Mountserat | D34: London | J34: =(E34*2240)+(F34*112)+(G34*28)+H34 -> 0 | L34: =J34/2240 -> 0
A35: 1754 | B35: Loaf Sugar | C35: Mountserat | D35: London | J35: =(E35*2240)+(F35*112)+(G35*28)+H35 -> 0 | L35: =J35/2240 -> 0
A36: 1754 | B36: Madera Wine | C36: Mountserat | D36: London | H36: 141816.5 | I36: 56t 1h 3g | J36: =(E36*2240)+(F36*112)+(G36*28)+H36 -> 141816.5 | L36: =J36/2240 -> 63.310938
A37: 1754 | B37: Molasses | C37: Mountserat | D37: London | J37: =(E37*2240)+(F37*112)+(G37*28)+H37 -> 0 | L37: =J37/2240 -> 0
A38: 1754 | B38: Oranges | C38: Mountserat | D38: London | J38: =(E38*2240)+(F38*112)+(G38*28)+H38 -> 0 | L38: =J38/2240 -> 0
A39: 1754 | B39: Orchelia | C39: Mountserat | D39: London | J39: =(E39*2240)+(F39*112)+(G39*28)+H39 -> 0 | L39: =J39/2240 -> 0
A40: 1754 | B40: Pickles | C40: Mountserat | D40: London | J40: =(E40*2240)+(F40*112)+(G40*28)+H40 -> 0 | L40: =J40/2240 -> 0
...

Sheet Nevis
A1: YEAR | B1: COMMODITY_NAME | C1: FROM_LOCATION | D1: TO_LOCATION | E1: ton | F1: hh | G1: quarter | H1: lb | J1: Total Pounds | L1: WEIGHT
A2: 1754 | B2: Almonds, Bitter | C2: Nevis | D2: London | J2: =(E2*2240)+(F2*112)+(G2*28)+H2 -> 0 | L2: =J2/2240 -> 0
A3: 1754 | B3: Almonds, Sweet | C3: Nevis | D3: London | J3: =(E3*2240)+(F3*112)+(G3*28)+H3 -> 0 | L3: =J3/2240 -> 0
A4: 1754 | B4: Aloes Epatica | C4: Nevis | D4: London | J4: =(E4*2240)+(F4*112)+(G4*28)+H4 -> 0 | L4: =J4/2240 -> 0
A5: 1754 | B5: Annatto | C5: Nevis | D5: London | J5: =(E5*2240)+(F5*112)+(G5*28)+H5 -> 0 | L5: =J5/2240 -> 0
A6: 1754 | B6: Anniseeds | C6: Nevis | D6: London | J6: =(E6*2240)+(F6*112)+(G6*28)+H6 -> 0 | L6: =J6/2240 -> 0
A7: 1754 | B7: Bacon | C7: Nevis | D7: London | J7: =(E7*2240)+(F7*112)+(G7*28)+H7 -> 0 | L7: =J7/2240 -> 0
A8: 1754 | B8: Barrel Staves | C8: Nevis | D8: London | J8: =(E8*2240)+(F8*112)+(G8*28)+H8 -> 0 | L8: =J8/2240 -> 0
A9: 1754 | B9: Bay Berries | C9: Nevis | D9: London | J9: =(E9*2240)+(F9*112)+(G9*28)+H9 -> 0 | L9: =J9/2240 -> 0
A10: 1754 | B10: Bees Wax | C10: Nevis | D10: London | J10: =(E10*2240)+(F10*112)+(G10*28)+H10 -> 0 | L10: =J10/2240 -> 0
A11: 1754 | B11: Brimstone | C11: Nevis | D11: London | J11: =(E11*2240)+(F11*112)+(G11*28)+H11 -> 0 | L11: =J11/2240 -> 0
A12: 1754 | B12: Brown Sugar | C12: Nevis | D12: London | F12: 24568 | H12: 12 | J12: =(E12*2240)+(F12*112)+(G12*28)+H12 -> 2751628 | L12: =J12/2240 -> 1228.4054
A13: 1754 | B13: Cascarilla | C13: Nevis | D13: London | J13: =(E13*2240)+(F13*112)+(G13*28)+H13 -> 0 | L13: =J13/2240 -> 0
A14: 1754 | B14: Cassia Fistula | C14: Nevis | D14: London | J14: =(E14*2240)+(F14*112)+(G14*28)+H14 -> 0 | L14: =J14/2240 -> 0
A15: 1754 | B15: Chocolate | C15: Nevis | D15: London | J15: =(E15*2240)+(F15*112)+(G15*28)+H15 -> 0 | L15: =J15/2240 -> 0
A16: 1754 | B16: Cocheneal | C16: Nevis | D16: London | J16: =(E16*2240)+(F16*112)+(G16*28)+H16 -> 0 | L16: =J16/2240 -> 0
A17: 1754 | B17: Cocoa Nuts | C17: Nevis | D17: London | J17: =(E17*2240)+(F17*112)+(G17*28)+H17 -> 0 | L17: =J17/2240 -> 0
A18: 1754 | B18: Cocoa Paste | C18: Nevis | D18: London | J18: =(E18*2240)+(F18*112)+(G18*28)+H18 -> 0 | L18: =J18/2240 -> 0
A19: 1754 | B19: Coffee | C19: Nevis | D19: London | J19: =(E19*2240)+(F19*112)+(G19*28)+H19 -> 0 | L19: =J19/2240 -> 0
A20: 1754 | B20: Cortex Peru | C20: Nevis | D20: London | J20: =(E20*2240)+(F20*112)+(G20*28)+H20 -> 0 | L20: =J20/2240 -> 0
A21: 1754 | B21: Cortex Winteranus | C21: Nevis | D21: London | J21: =(E21*2240)+(F21*112)+(G21*28)+H21 -> 0 | L21: =J21/2240 -> 0
A22: 1754 | B22: Cotton | C22: Nevis | D22: London | H22: =54*200 -> 10800 | I22: 54bags | J22: =(E22*2240)+(F22*112)+(G22*28)+H22 -> 10800 | L22: =J22/2240 -> 4.8214286
A23: 1754 | B23: Dry Ginger | C23: Nevis | D23: London | J23: =(E23*2240)+(F23*112)+(G23*28)+H23 -> 0 | L23: =J23/2240 -> 0
A24: 1754 | B24: Elephant Teeth | C24: Nevis | D24: London | J24: =(E24*2240)+(F24*112)+(G24*28)+H24 -> 0 | L24: =J24/2240 -> 0
A25: 1754 | B25: Green Ginger | C25: Nevis | D25: London | J25: =(E25*2240)+(F25*112)+(G25*28)+H25 -> 0 | L25: =J25/2240 -> 0
A26: 1754 | B26: Guinea Grains | C26: Nevis | D26: London | J26: =(E26*2240)+(F26*112)+(G26*28)+H26 -> 0 | L26: =J26/2240 -> 0
A27: 1754 | B27: Gum Guiaci | C27: Nevis | D27: London | J27: =(E27*2240)+(F27*112)+(G27*28)+H27 -> 0 | L27: =J27/2240 -> 0
A28: 1754 | B28: Hemp | C28: Nevis | D28: London | J28: =(E28*2240)+(F28*112)+(G28*28)+H28 -> 0 | L28: =J28/2240 -> 0
A29: 1754 | B29: Hypococania | C29: Nevis | D29: London | J29: =(E29*2240)+(F29*112)+(G29*28)+H29 -> 0 | L29: =J29/2240 -> 0
A30: 1754 | B30: Indigo | C30: Nevis | D30: London | J30: =(E30*2240)+(F30*112)+(G30*28)+H30 -> 0 | L30: =J30/2240 -> 0
A31: 1754 | B31: Jollop | C31: Nevis | D31: London | J31: =(E31*2240)+(F31*112)+(G31*28)+H31 -> 0 | L31: =J31/2240 -> 0
A32: 1754 | B32: Lemon Water | C32: Nevis | D32: London | J32: =(E32*2240)+(F32*112)+(G32*28)+H32 -> 0 | L32: =J32/2240 -> 0
A33: 1754 | B33: Lignum Vitae | C33: Nevis | D33: London | J33: =(E33*2240)+(F33*112)+(G33*28)+H33 -> 0 | L33: =J33/2240 -> 0
A34: 1754 | B34: Lime Juice | C34: Nevis | D34: London | J34: =(E34*2240)+(F34*112)+(G34*28)+H34 -> 0 | L34: =J34/2240 -> 0
A35: 1754 | B35: Loaf Sugar | C35: Nevis | D35: London | J35: =(E35*2240)+(F35*112)+(G35*28)+H35 -> 0 | L35: =J35/2240 -> 0
A36: 1754 | B36: Madera Wine | C36: Nevis | D36: London | H36: 3991 | I36: 1t 2h 21g | J36: =(E36*2240)+(F36*112)+(G36*28)+H36 -> 3991 | L36: =J36/2240 -> 1.7816964
A37: 1754 | B37: Molasses | C37: Nevis | D37: London | J37: =(E37*2240)+(F37*112)+(G37*28)+H37 -> 0 | L37: =J37/2240 -> 0
A38: 1754 | B38: Oranges | C38: Nevis | D38: London | J38: =(E38*2240)+(F38*112)+(G38*28)+H38 -> 0 | L38: =J38/2240 -> 0
A39: 1754 | B39: Orchelia | C39: Nevis | D39: London | J39: =(E39*2240)+(F39*112)+(G39*28)+H39 -> 0 | L39: =J39/2240 -> 0
A40: 1754 | B40: Pickles | C40: Nevis | D40: London | J40: =(E40*2240)+(F40*112)+(G40*28)+H40 -> 0 | L40: =J40/2240 -> 0
...

Sheet St Kitts
A1: YEAR | B1: COMMODITY_NAME | C1: FROM_LOCATION | D1: TO_LOCATION | E1: ton | F1: hh | G1: quarter | H1: lb | J1: Total Pounds | L1: WEIGHT
A2: 1754 | B2: Almonds, Bitter | C2: StKitts | D2: London | J2: =(E2*2240)+(F2*112)+(G2*28)+H2 -> 0 | L2: =J2/2240 -> 0
A3: 1754 | B3: Almonds, Sweet | C3: StKitts | D3: London | J3: =(E3*2240)+(F3*112)+(G3*28)+H3 -> 0 | L3: =J3/2240 -> 0
A4: 1754 | B4: Aloes Epatica | C4: StKitts | D4: London | J4: =(E4*2240)+(F4*112)+(G4*28)+H4 -> 0 | L4: =J4/2240 -> 0
A5: 1754 | B5: Annatto | C5: StKitts | D5: London | J5: =(E5*2240)+(F5*112)+(G5*28)+H5 -> 0 | L5: =J5/2240 -> 0
A6: 1754 | B6: Anniseeds | C6: StKitts | D6: London | J6: =(E6*2240)+(F6*112)+(G6*28)+H6 -> 0 | L6: =J6/2240 -> 0
A7: 1754 | B7: Bacon | C7: StKitts | D7: London | J7: =(E7*2240)+(F7*112)+(G7*28)+H7 -> 0 | L7: =J7/2240 -> 0
A8: 1754 | B8: Barrel Staves | C8: StKitts | D8: London | J8: =(E8*2240)+(F8*112)+(G8*28)+H8 -> 0 | L8: =J8/2240 -> 0
A9: 1754 | B9: Bay Berries | C9: StKitts | D9: London | J9: =(E9*2240)+(F9*112)+(G9*28)+H9 -> 0 | L9: =J9/2240 -> 0
A10: 1754 | B10: Bees Wax | C10: StKitts | D10: London | J10: =(E10*2240)+(F10*112)+(G10*28)+H10 -> 0 | L10: =J10/2240 -> 0
A11: 1754 | B11: Brimstone | C11: StKitts | D11: London | J11: =(E11*2240)+(F11*112)+(G11*28)+H11 -> 0 | L11: =J11/2240 -> 0
A12: 1754 | B12: Brown Sugar | C12: StKitts | D12: London | F12: 108109 | H12: 18 | J12: =(E12*2240)+(F12*112)+(G12*28)+H12 -> 12108226 | L12: =J12/2240 -> 5405.458
A13: 1754 | B13: Cascarilla | C13: StKitts | D13: London | J13: =(E13*2240)+(F13*112)+(G13*28)+H13 -> 0 | L13: =J13/2240 -> 0
A14: 1754 | B14: Cassia Fistula | C14: StKitts | D14: London | J14: =(E14*2240)+(F14*112)+(G14*28)+H14 -> 0 | L14: =J14/2240 -> 0
A15: 1754 | B15: Chocolate | C15: StKitts | D15: London | J15: =(E15*2240)+(F15*112)+(G15*28)+H15 -> 0 | L15: =J15/2240 -> 0
A16: 1754 | B16: Cocheneal | C16: StKitts | D16: London | J16: =(E16*2240)+(F16*112)+(G16*28)+H16 -> 0 | L16: =J16/2240 -> 0
A17: 1754 | B17: Cocoa Nuts | C17: StKitts | D17: London | F17: 1 | G17: 2 | H17: 23 | J17: =(E17*2240)+(F17*112)+(G17*28)+H17 -> 191 | L17: =J17/2240 -> 0.085267857
A18: 1754 | B18: Cocoa Paste | C18: StKitts | D18: London | J18: =(E18*2240)+(F18*112)+(G18*28)+H18 -> 0 | L18: =J18/2240 -> 0
A19: 1754 | B19: Coffee | C19: StKitts | D19: London | J19: =(E19*2240)+(F19*112)+(G19*28)+H19 -> 0 | L19: =J19/2240 -> 0
A20: 1754 | B20: Cortex Peru | C20: StKitts | D20: London | J20: =(E20*2240)+(F20*112)+(G20*28)+H20 -> 0 | L20: =J20/2240 -> 0
A21: 1754 | B21: Cortex Winteranus | C21: StKitts | D21: London | J21: =(E21*2240)+(F21*112)+(G21*28)+H21 -> 0 | L21: =J21/2240 -> 0
A22: 1754 | B22: Cotton | C22: StKitts | D22: London | H22: =121.5*200 -> 24300 | I22: 121.5bags | J22: =(E22*2240)+(F22*112)+(G22*28)+H22 -> 24300 | L22: =J22/2240 -> 10.848214
A23: 1754 | B23: Dry Ginger | C23: StKitts | D23: London | F23: 13 | G23: 1 | H23: 20 | J23: =(E23*2240)+(F23*112)+(G23*28)+H23 -> 1504 | L23: =J23/2240 -> 0.67142857
