Workbook

Sheet Master Goods Sheet
A1: Item | B1: Total London | C1: Total Outports | D1: Total
A2: Annatto | B2: =SUMIFS(Anguilla!$L:$L, Anguilla!$B:$B, $A2, Anguilla!$D:$D, "London") + SUMIFS(Antigua!$L:$L, Antigua!$B:$B, $A2, Antigua!$D:$D, "London") + SUMIFS(Barbados!$L:$L, Barbados!$B:$B, $A2, Barbados!$D:$D, "London") + SUMIFS(Bermuda!$L:$L, Bermuda!$B:$B, $A2, Bermuda!$D:$D, "London") + SUMIFS(Jamaica!$L:$L, Jamaica!$B:$B, $A2, Jamaica!$D:$D, "London") + SUMIFS(Mountserat!$L:$L, Mountserat!$B:$B, $A2, Mountserat!$D:$D, "London") + SUMIFS(Nevis!$L:$L, Nevis!$B:$B, $A2, Nevis!$D:$D, "London") + SUMIFS('St Kitts'!$L:$L, 'St Kitts'!$B:$B, $A2, 'St Kitts'!$D:$D, "London") + SUMIFS(Tortola!$L:$L, Tortola!$B:$B, $A2, Tortola!$D:$D, "London") -> 0 | C2: =SUMIFS(Anguilla!$L:$L, Anguilla!$B:$B, $A2, Anguilla!$D:$D, "Out Ports") + SUMIFS(Antigua!$L:$L, Antigua!$B:$B, $A2, Antigua!$D:$D, "Out Ports") + SUMIFS(Barbados!$L:$L, Barbados!$B:$B, $A2, Barbados!$D:$D, "Out Ports") + SUMIFS(Bermuda!$L:$L, Bermuda!$B:$B, $A2, Bermuda!$D:$D, "Out Ports") + SUMIFS(Jamaica!$L:$L, Jamaica!$B:$B, $A2, Jamaica!$D:$D, "Out Ports") + SUMIFS(Mountserat!$L:$L, Mountserat!$B:$B, $A2, Mountserat!$D:$D, "Out Ports") + SUMIFS(Nevis!$L:$L, Nevis!$B:$B, $A2, Nevis!$D:$D, "Out Ports") + SUMIFS('St Kitts'!$L:$L, 'St Kitts'!$B:$B, $A2, 'St Kitts'!$D:$D, "Out Ports") + SUMIFS(Tortola!$L:$L, Tortola!$B:$B, $A2, Tortola!$D:$D, "Out Ports") -> 0 | D2: =B2+C2 -> 0
A3: Bees Wax | B3: =SUMIFS(Anguilla!$L:$L, Anguilla!$B:$B, $A3, Anguilla!$D:$D, "London") + SUMIFS(Antigua!$L:$L, Antigua!$B:$B, $A3, Antigua!$D:$D, "London") + SUMIFS(Barbados!$L:$L, Barbados!$B:$B, $A3, Barbados!$D:$D, "London") + SUMIFS(Bermuda!$L:$L, Bermuda!$B:$B, $A3, Bermuda!$D:$D, "London") + SUMIFS(Jamaica!$L:$L, Jamaica!$B:$B, $A3, Jamaica!$D:$D, "London") + SUMIFS(Mountserat!$L:$L, Mountserat!$B:$B, $A3, Mountserat!$D:$D, "London") + SUMIFS(Nevis!$L:$L, Nevis!$B:$B, $A3, Nevis!$D:$D, "London") + SUMIFS('St Kitts'!$L:$L, 'St Kitts'!$B:$B, $A3, 'St Kitts'!$D:$D, "London") + SUMIFS(Tortola!$L:$L, Tortola!$B:$B, $A3, Tortola!$D:$D, "London") -> 4.1866071 | C3: =SUMIFS(Anguilla!$L:$L, Anguilla!$B:$B, $A3, Anguilla!$D:$D, "Out Ports") + SUMIFS(Antigua!$L:$L, Antigua!$B:$B, $A3, Antigua!$D:$D, "Out Ports") + SUMIFS(Barbados!$L:$L, Barbados!$B:$B, $A3, Barbados!$D:$D, "Out Ports") + SUMIFS(Bermuda!$L:$L, Bermuda!$B:$B, $A3, Bermuda!$D:$D, "Out Ports") + SUMIFS(Jamaica!$L:$L, Jamaica!$B:$B, $A3, Jamaica!$D:$D, "Out Ports") + SUMIFS(Mountserat!$L:$L, Mountserat!$B:$B, $A3, Mountserat!$D:$D, "Out Ports") + SUMIFS(Nevis!$L:$L, Nevis!$B:$B, $A3, Nevis!$D:$D, "Out Ports") + SUMIFS('St Kitts'!$L:$L, 'St Kitts'!$B:$B, $A3, 'St Kitts'!$D:$D, "Out Ports") + SUMIFS(Tortola!$L:$L, Tortola!$B:$B, $A3, Tortola!$D:$D, "Out Ports") -> 6.0566964 | D3: =B3+C3 -> 10.243304
A4: Brown Sugar | B4: =SUMIFS(Anguilla!$L:$L, Anguilla!$B:$B, $A4, Anguilla!$D:$D, "London") + SUMIFS(Antigua!$L:$L, Antigua!$B:$B, $A4, Antigua!$D:$D, "London") + SUMIFS(Barbados!$L:$L, Barbados!$B:$B, $A4, Barbados!$D:$D, "London") + SUMIFS(Bermuda!$L:$L, Bermuda!$B:$B, $A4, Bermuda!$D:$D, "London") + SUMIFS(Jamaica!$L:$L, Jamaica!$B:$B, $A4, Jamaica!$D:$D, "London") + SUMIFS(Mountserat!$L:$L, Mountserat!$B:$B, $A4, Mountserat!$D:$D, "London") + SUMIFS(Nevis!$L:$L, Nevis!$B:$B, $A4, Nevis!$D:$D, "London") + SUMIFS('St Kitts'!$L:$L, 'St Kitts'!$B:$B, $A4, 'St Kitts'!$D:$D, "London") + SUMIFS(Tortola!$L:$L, Tortola!$B:$B, $A4, Tortola!$D:$D, "London") -> 42776.415 | C4: =SUMIFS(Anguilla!$L:$L, Anguilla!$B:$B, $A4, Anguilla!$D:$D, "Out Ports") + SUMIFS(Antigua!$L:$L, Antigua!$B:$B, $A4, Antigua!$D:$D, "Out Ports") + SUMIFS(Barbados!$L:$L, Barbados!$B:$B, $A4, Barbados!$D:$D, "Out Ports") + SUMIFS(Bermuda!$L:$L, Bermuda!$B:$B, $A4, Bermuda!$D:$D, "Out Ports") + SUMIFS(Jamaica!$L:$L, Jamaica!$B:$B, $A4, Jamaica!$D:$D, "Out Ports") + SUMIFS(Mountserat!$L:$L, Mountserat!$B:$B, $A4, Mountserat!$D:$D, "Out Ports") + SUMIFS(Nevis!$L:$L, Nevis!$B:$B, $A4, Nevis!$D:$D, "Out Ports") + SUMIFS('St Kitts'!$L:$L, 'St Kitts'!$B:$B, $A4, 'St Kitts'!$D:$D, "Out Ports") + SUMIFS(Tortola!$L:$L, Tortola!$B:$B, $A4, Tortola!$D:$D, "Out Ports") -> 14464.636 | D4: =B4+C4 -> 57241.051
A5: Chocolate | B5: =SUMIFS(Anguilla!$L:$L, Anguilla!$B:$B, $A5, Anguilla!$D:$D, "London") + SUMIFS(Antigua!$L:$L, Antigua!$B:$B, $A5, Antigua!$D:$D, "London") + SUMIFS(Barbados!$L:$L, Barbados!$B:$B, $A5, Barbados!$D:$D, "London") + SUMIFS(Bermuda!$L:$L, Bermuda!$B:$B, $A5, Bermuda!$D:$D, "London") + SUMIFS(Jamaica!$L:$L, Jamaica!$B:$B, $A5, Jamaica!$D:$D, "London") + SUMIFS(Mountserat!$L:$L, Mountserat!$B:$B, $A5, Mountserat!$D:$D, "London") + SUMIFS(Nevis!$L:$L, Nevis!$B:$B, $A5, Nevis!$D:$D, "London") + SUMIFS('St Kitts'!$L:$L, 'St Kitts'!$B:$B, $A5, 'St Kitts'!$D:$D, "London") + SUMIFS(Tortola!$L:$L, Tortola!$B:$B, $A5, Tortola!$D:$D, "London") -> 0 | C5: =SUMIFS(Anguilla!$L:$L, Anguilla!$B:$B, $A5, Anguilla!$D:$D, "Out Ports") + SUMIFS(Antigua!$L:$L, Antigua!$B:$B, $A5, Antigua!$D:$D, "Out Ports") + SUMIFS(Barbados!$L:$L, Barbados!$B:$B, $A5, Barbados!$D:$D, "Out Ports") + SUMIFS(Bermuda!$L:$L, Bermuda!$B:$B, $A5, Bermuda!$D:$D, "Out Ports") + SUMIFS(Jamaica!$L:$L, Jamaica!$B:$B, $A5, Jamaica!$D:$D, "Out Ports") + SUMIFS(Mountserat!$L:$L, Mountserat!$B:$B, $A5, Mountserat!$D:$D, "Out Ports") + SUMIFS(Nevis!$L:$L, Nevis!$B:$B, $A5, Nevis!$D:$D, "Out Ports") + SUMIFS('St Kitts'!$L:$L, 'St Kitts'!$B:$B, $A5, 'St Kitts'!$D:$D, "Out Ports") + SUMIFS(Tortola!$L:$L, Tortola!$B:$B, $A5, Tortola!$D:$D, "Out Ports") -> 0 | D5: =B5+C5 -> 0
A6: Cocoa Nuts | B6: =SUMIFS(Anguilla!$L:$L, Anguilla!$B:$B, $A6, Anguilla!$D:$D, "London") + SUMIFS(Antigua!$L:$L, Antigua!$B:$B, $A6, Antigua!$D:$D, "London") + SUMIFS(Barbados!$L:$L, Barbados!$B:$B, $A6, Barbados!$D:$D, "London") + SUMIFS(Bermuda!$L:$L, Bermuda!$B:$B, $A6, Bermuda!$D:$D, "London") + SUMIFS(Jamaica!$L:$L, Jamaica!$B:$B, $A6, Jamaica!$D:$D, "London") + SUMIFS(Mountserat!$L:$L, Mountserat!$B:$B, $A6, Mountserat!$D:$D, "London") + SUMIFS(Nevis!$L:$L, Nevis!$B:$B, $A6, Nevis!$D:$D, "London") + SUMIFS('St Kitts'!$L:$L, 'St Kitts'!$B:$B, $A6, 'St Kitts'!$D:$D, "London") + SUMIFS(Tortola!$L:$L, Tortola!$B:$B, $A6, Tortola!$D:$D, "London") -> 12.201786 | C6: =SUMIFS(Anguilla!$L:$L, Anguilla!$B:$B, $A6, Anguilla!$D:$D, "Out Ports") + SUMIFS(Antigua!$L:$L, Antigua!$B:$B, $A6, Antigua!$D:$D, "Out Ports") + SUMIFS(Barbados!$L:$L, Barbados!$B:$B, $A6, Barbados!$D:$D, "Out Ports") + SUMIFS(Bermuda!$L:$L, Bermuda!$B:$B, $A6, Bermuda!$D:$D, "Out Ports") + SUMIFS(Jamaica!$L:$L, Jamaica!$B:$B, $A6, Jamaica!$D:$D, "Out Ports") + SUMIFS(Mountserat!$L:$L, Mountserat!$B:$B, $A6, Mountserat!$D:$D, "Out Ports") + SUMIFS(Nevis!$L:$L, Nevis!$B:$B, $A6, Nevis!$D:$D, "Out Ports") + SUMIFS('St Kitts'!$L:$L, 'St Kitts'!$B:$B, $A6, 'St Kitts'!$D:$D, "Out Ports") + SUMIFS(Tortola!$L:$L, Tortola!$B:$B, $A6, Tortola!$D:$D, "Out Ports") -> 3.86875 | D6: =B6+C6 -> 16.070536
A7: Cotton | B7: =SUMIFS(Anguilla!$L:$L, Anguilla!$B:$B, $A7, Anguilla!$D:$D, "London") + SUMIFS(Antigua!$L:$L, Antigua!$B:$B, $A7, Antigua!$D:$D, "London") + SUMIFS(Barbados!$L:$L, Barbados!$B:$B, $A7, Barbados!$D:$D, "London") + SUMIFS(Bermuda!$L:$L, Bermuda!$B:$B, $A7, Bermuda!$D:$D, "London") + SUMIFS(Jamaica!$L:$L, Jamaica!$B:$B, $A7, Jamaica!$D:$D, "London") + SUMIFS(Mountserat!$L:$L, Mountserat!$B:$B, $A7, Mountserat!$D:$D, "London") + SUMIFS(Nevis!$L:$L, Nevis!$B:$B, $A7, Nevis!$D:$D, "London") + SUMIFS('St Kitts'!$L:$L, 'St Kitts'!$B:$B, $A7, 'St Kitts'!$D:$D, "London") + SUMIFS(Tortola!$L:$L, Tortola!$B:$B, $A7, Tortola!$D:$D, "London") -> 147.85714 | C7: =SUMIFS(Anguilla!$L:$L, Anguilla!$B:$B, $A7, Anguilla!$D:$D, "Out Ports") + SUMIFS(Antigua!$L:$L, Antigua!$B:$B, $A7, Antigua!$D:$D, "Out Ports") + SUMIFS(Barbados!$L:$L, Barbados!$B:$B, $A7, Barbados!$D:$D, "Out Ports") + SUMIFS(Bermuda!$L:$L, Bermuda!$B:$B, $A7, Bermuda!$D:$D, "Out Ports") + SUMIFS(Jamaica!$L:$L, Jamaica!$B:$B, $A7, Jamaica!$D:$D, "Out Ports") + SUMIFS(Mountserat!$L:$L, Mountserat!$B:$B, $A7, Mountserat!$D:$D, "Out Ports") + SUMIFS(Nevis!$L:$L, Nevis!$B:$B, $A7, Nevis!$D:$D, "Out Ports") + SUMIFS('St Kitts'!$L:$L, 'St Kitts'!$B:$B, $A7, 'St Kitts'!$D:$D, "Out Ports") + SUMIFS(Tortola!$L:$L, Tortola!$B:$B, $A7, Tortola!$D:$D, "Out Ports") -> 616.75 | D7: =B7+C7 -> 764.60714
A8: Dry Ginger | B8: =SUMIFS(Anguilla!$L:$L, Anguilla!$B:$B, $A8, Anguilla!$D:$D, "London") + SUMIFS(Antigua!$L:$L, Antigua!$B:$B, $A8, Antigua!$D:$D, "London") + SUMIFS(Barbados!$L:$L, Barbados!$B:$B, $A8, Barbados!$D:$D, "London") + SUMIFS(Bermuda!$L:$L, Bermuda!$B:$B, $A8, Bermuda!$D:$D, "London") + SUMIFS(Jamaica!$L:$L, Jamaica!$B:$B, $A8, Jamaica!$D:$D, "London") + SUMIFS(Mountserat!$L:$L, Mountserat!$B:$B, $A8, Mountserat!$D:$D, "London") + SUMIFS(Nevis!$L:$L, Nevis!$B:$B, $A8, Nevis!$D:$D, "London") + SUMIFS('St Kitts'!$L:$L, 'St Kitts'!$B:$B, $A8, 'St Kitts'!$D:$D, "London") + SUMIFS(Tortola!$L:$L, Tortola!$B:$B, $A8, Tortola!$D:$D, "London") -> 747.7375 | C8: =SUMIFS(Anguilla!$L:$L, Anguilla!$B:$B, $A8, Anguilla!$D:$D, "Out Ports") + SUMIFS(Antigua!$L:$L, Antigua!$B:$B, $A8, Antigua!$D:$D, "Out Ports") + SUMIFS(Barbados!$L:$L, Barbados!$B:$B, $A8, Barbados!$D:$D, "Out Ports") + SUMIFS(Bermuda!$L:$L, Bermuda!$B:$B, $A8, Bermuda!$D:$D, "Out Ports") + SUMIFS(Jamaica!$L:$L, Jamaica!$B:$B, $A8, Jamaica!$D:$D, "Out Ports") + SUMIFS(Mountserat!$L:$L, Mountserat!$B:$B, $A8, Mountserat!$D:$D, "Out Ports") + SUMIFS(Nevis!$L:$L, Nevis!$B:$B, $A8, Nevis!$D:$D, "Out Ports") + SUMIFS('St Kitts'!$L:$L, 'St Kitts'!$B:$B, $A8, 'St Kitts'!$D:$D, "Out Ports") + SUMIFS(Tortola!$L:$L, Tortola!$B:$B, $A8, Tortola!$D:$D, "Out Ports") -> 405.13973 | D8: =B8+C8 -> 1152.8772
A9: Elephant Teeth | B9: =SUMIFS(Anguilla!$L:$L, Anguilla!$B:$B, $A9, Anguilla!$D:$D, "London") + SUMIFS(Antigua!$L:$L, Antigua!$B:$B, $A9, Antigua!$D:$D, "London") + SUMIFS(Barbados!$L:$L, Barbados!$B:$B, $A9, Barbados!$D:$D, "London") + SUMIFS(Bermuda!$L:$L, Bermuda!$B:$B, $A9, Bermuda!$D:$D, "London") + SUMIFS(Jamaica!$L:$L, Jamaica!$B:$B, $A9, Jamaica!$D:$D, "London") + SUMIFS(Mountserat!$L:$L, Mountserat!$B:$B, $A9, Mountserat!$D:$D, "London") + SUMIFS(Nevis!$L:$L, Nevis!$B:$B, $A9, Nevis!$D:$D, "London") + SUMIFS('St Kitts'!$L:$L, 'St Kitts'!$B:$B, $A9, 'St Kitts'!$D:$D, "London") + SUMIFS(Tortola!$L:$L, Tortola!$B:$B, $A9, Tortola!$D:$D, "London") -> 8.2825893 | C9: =SUMIFS(Anguilla!$L:$L, Anguilla!$B:$B, $A9, Anguilla!$D:$D, "Out Ports") + SUMIFS(Antigua!$L:$L, Antigua!$B:$B, $A9, Antigua!$D:$D, "Out Ports") + SUMIFS(Barbados!$L:$L, Barbados!$B:$B, $A9, Barbados!$D:$D, "Out Ports") + SUMIFS(Bermuda!$L:$L, Bermuda!$B:$B, $A9, Bermuda!$D:$D, "Out Ports") + SUMIFS(Jamaica!$L:$L, Jamaica!$B:$B, $A9, Jamaica!$D:$D, "Out Ports") + SUMIFS(Mountserat!$L:$L, Mountserat!$B:$B, $A9, Mountserat!$D:$D, "Out Ports") + SUMIFS(Nevis!$L:$L, Nevis!$B:$B, $A9, Nevis!$D:$D, "Out Ports") + SUMIFS('St Kitts'!$L:$L, 'St Kitts'!$B:$B, $A9, 'St Kitts'!$D:$D, "Out Ports") + SUMIFS(Tortola!$L:$L, Tortola!$B:$B, $A9, Tortola!$D:$D, "Out Ports") -> 39.811607 | D9: =B9+C9 -> 48.094196
A10: Indigo | B10: =SUMIFS(Anguilla!$L:$L, Anguilla!$B:$B, $A10, Anguilla!$D:$D, "London") + SUMIFS(Antigua!$L:$L, Antigua!$B:$B, $A10, Antigua!$D:$D, "London") + SUMIFS(Barbados!$L:$L, Barbados!$B:$B, $A10, Barbados!$D:$D, "London") + SUMIFS(Bermuda!$L:$L, Bermuda!$B:$B, $A10, Bermuda!$D:$D, "London") + SUMIFS(Jamaica!$L:$L, Jamaica!$B:$B, $A10, Jamaica!$D:$D, "London") + SUMIFS(Mountserat!$L:$L, Mountserat!$B:$B, $A10, Mountserat!$D:$D, "London") + SUMIFS(Nevis!$L:$L, Nevis!$B:$B, $A10, Nevis!$D:$D, "London") + SUMIFS('St Kitts'!$L:$L, 'St Kitts'!$B:$B, $A10, 'St Kitts'!$D:$D, "London") + SUMIFS(Tortola!$L:$L, Tortola!$B:$B, $A10, Tortola!$D:$D, "London") -> 1.4794643 | C10: =SUMIFS(Anguilla!$L:$L, Anguilla!$B:$B, $A10, Anguilla!$D:$D, "Out Ports") + SUMIFS(Antigua!$L:$L, Antigua!$B:$B, $A10, Antigua!$D:$D, "Out Ports") + SUMIFS(Barbados!$L:$L, Barbados!$B:$B, $A10, Barbados!$D:$D, "Out Ports") + SUMIFS(Bermuda!$L:$L, Bermuda!$B:$B, $A10, Bermuda!$D:$D, "Out Ports") + SUMIFS(Jamaica!$L:$L, Jamaica!$B:$B, $A10, Jamaica!$D:$D, "Out Ports") + SUMIFS(Mountserat!$L:$L, Mountserat!$B:$B, $A10, Mountserat!$D:$D, "Out Ports") + SUMIFS(Nevis!$L:$L, Nevis!$B:$B, $A10, Nevis!$D:$D, "Out Ports") + SUMIFS('St Kitts'!$L:$L, 'St Kitts'!$B:$B, $A10, 'St Kitts'!$D:$D, "Out Ports") + SUMIFS(Tortola!$L:$L, Tortola!$B:$B, $A10, Tortola!$D:$D, "Out Ports") -> 0.84776786 | D10: =B10+C10 -> 2.3272321
A11: Lignum Vitae | B11: =SUMIFS(Anguilla!$L:$L, Anguilla!$B:$B, $A11, Anguilla!$D:$D, "London") + SUMIFS(Antigua!$L:$L, Antigua!$B:$B, $A11, Antigua!$D:$D, "London") + SUMIFS(Barbados!$L:$L, Barbados!$B:$B, $A11, Barbados!$D:$D, "London") + SUMIFS(Bermuda!$L:$L, Bermuda!$B:$B, $A11, Bermuda!$D:$D, "London") + SUMIFS(Jamaica!$L:$L, Jamaica!$B:$B, $A11, Jamaica!$D:$D, "London") + SUMIFS(Mountserat!$L:$L, Mountserat!$B:$B, $A11, Mountserat!$D:$D, "London") + SUMIFS(Nevis!$L:$L, Nevis!$B:$B, $A11, Nevis!$D:$D, "London") + SUMIFS('St Kitts'!$L:$L, 'St Kitts'!$B:$B, $A11, 'St Kitts'!$D:$D, "London") + SUMIFS(Tortola!$L:$L, Tortola!$B:$B, $A11, Tortola!$D:$D, "London") -> 163.2125 | C11: =SUMIFS(Anguilla!$L:$L, Anguilla!$B:$B, $A11, Anguilla!$D:$D, "Out Ports") + SUMIFS(Antigua!$L:$L, Antigua!$B:$B, $A11, Antigua!$D:$D, "Out Ports") + SUMIFS(Barbados!$L:$L, Barbados!$B:$B, $A11, Barbados!$D:$D, "Out Ports") + SUMIFS(Bermuda!$L:$L, Bermuda!$B:$B, $A11, Bermuda!$D:$D, "Out Ports") + SUMIFS(Jamaica!$L:$L, Jamaica!$B:$B, $A11, Jamaica!$D:$D, "Out Ports") + SUMIFS(Mountserat!$L:$L, Mountserat!$B:$B, $A11, Mountserat!$D:$D, "Out Ports") + SUMIFS(Nevis!$L:$L, Nevis!$B:$B, $A11, Nevis!$D:$D, "Out Ports") + SUMIFS('St Kitts'!$L:$L, 'St Kitts'!$B:$B, $A11, 'St Kitts'!$D:$D, "Out Ports") + SUMIFS(Tortola!$L:$L, Tortola!$B:$B, $A11, Tortola!$D:$D, "Out Ports") -> 158.99107 | D11: =B11+C11 -> 322.20357
A12: Lime Juice | B12: =SUMIFS(Anguilla!$L:$L, Anguilla!$B:$B, $A12, Anguilla!$D:$D, "London") + SUMIFS(Antigua!$L:$L, Antigua!$B:$B, $A12, Antigua!$D:$D, "London") + SUMIFS(Barbados!$L:$L, Barbados!$B:$B, $A12, Barbados!$D:$D, "London") + SUMIFS(Bermuda!$L:$L, Bermuda!$B:$B, $A12, Bermuda!$D:$D, "London") + SUMIFS(Jamaica!$L:$L, Jamaica!$B:$B, $A12, Jamaica!$D:$D, "London") + SUMIFS(Mountserat!$L:$L, Mountserat!$B:$B, $A12, Mountserat!$D:$D, "London") + SUMIFS(Nevis!$L:$L, Nevis!$B:$B, $A12, Nevis!$D:$D, "London") + SUMIFS('St Kitts'!$L:$L, 'St Kitts'!$B:$B, $A12, 'St Kitts'!$D:$D, "London") + SUMIFS(Tortola!$L:$L, Tortola!$B:$B, $A12, Tortola!$D:$D, "London") -> 13.954018 | C12: =SUMIFS(Anguilla!$L:$L, Anguilla!$B:$B, $A12, Anguilla!$D:$D, "Out Ports") + SUMIFS(Antigua!$L:$L, Antigua!$B:$B, $A12, Antigua!$D:$D, "Out Ports") + SUMIFS(Barbados!$L:$L, Barbados!$B:$B, $A12, Barbados!$D:$D, "Out Ports") + SUMIFS(Bermuda!$L:$L, Bermuda!$B:$B, $A12, Bermuda!$D:$D, "Out Ports") + SUMIFS(Jamaica!$L:$L, Jamaica!$B:$B, $A12, Jamaica!$D:$D, "Out Ports") + SUMIFS(Mountserat!$L:$L, Mountserat!$B:$B, $A12, Mountserat!$D:$D, "Out Ports") + SUMIFS(Nevis!$L:$L, Nevis!$B:$B, $A12, Nevis!$D:$D, "Out Ports") + SUMIFS('St Kitts'!$L:$L, 'St Kitts'!$B:$B, $A12, 'St Kitts'!$D:$D, "Out Ports") + SUMIFS(Tortola!$L:$L, Tortola!$B:$B, $A12, Tortola!$D:$D, "Out Ports") -> 0.045089286 | D12: =B12+C12 -> 13.999107
A13: Molasses | B13: =SUMIFS(Anguilla!$L:$L, Anguilla!$B:$B, $A13, Anguilla!$D:$D, "London") + SUMIFS(Antigua!$L:$L, Antigua!$B:$B, $A13, Antigua!$D:$D, "London") + SUMIFS(Barbados!$L:$L, Barbados!$B:$B, $A13, Barbados!$D:$D, "London") + SUMIFS(Bermuda!$L:$L, Bermuda!$B:$B, $A13, Bermuda!$D:$D, "London") + SUMIFS(Jamaica!$L:$L, Jamaica!$B:$B, $A13, Jamaica!$D:$D, "London") + SUMIFS(Mountserat!$L:$L, Mountserat!$B:$B, $A13, Mountserat!$D:$D, "London") + SUMIFS(Nevis!$L:$L, Nevis!$B:$B, $A13, Nevis!$D:$D, "London") + SUMIFS('St Kitts'!$L:$L, 'St Kitts'!$B:$B, $A13, 'St Kitts'!$D:$D, "London") + SUMIFS(Tortola!$L:$L, Tortola!$B:$B, $A13, Tortola!$D:$D, "London") -> 0 | C13: =SUMIFS(Anguilla!$L:$L, Anguilla!$B:$B, $A13, Anguilla!$D:$D, "Out Ports") + SUMIFS(Antigua!$L:$L, Antigua!$B:$B, $A13, Antigua!$D:$D, "Out Ports") + SUMIFS(Barbados!$L:$L, Barbados!$B:$B, $A13, Barbados!$D:$D, "Out Ports") + SUMIFS(Bermuda!$L:$L, Bermuda!$B:$B, $A13, Bermuda!$D:$D, "Out Ports") + SUMIFS(Jamaica!$L:$L, Jamaica!$B:$B, $A13, Jamaica!$D:$D, "Out Ports") + SUMIFS(Mountserat!$L:$L, Mountserat!$B:$B, $A13, Mountserat!$D:$D, "Out Ports") + SUMIFS(Nevis!$L:$L, Nevis!$B:$B, $A13, Nevis!$D:$D, "Out Ports") + SUMIFS('St Kitts'!$L:$L, 'St Kitts'!$B:$B, $A13, 'St Kitts'!$D:$D, "Out Ports") + SUMIFS(Tortola!$L:$L, Tortola!$B:$B, $A13, Tortola!$D:$D, "Out Ports") -> 0 | D13: =B13+C13 -> 0
... A31: Wood, Sweetwood | B31: =SUMIFS(Anguilla!$L:$L, Anguilla!$B:$B, $A31, Anguilla!$D:$D, "London") + SUMIFS(Antigua!$L:$L, Antigua!$B:$B, $A31, Antigua!$D:$D, "London") + SUMIFS(Barbados!$L:$L, Barbados!$B:$B, $A31, Barbados!$D:$D, "London") + SUMIFS(Bermuda!$L:$L, Bermuda!$B:$B, $A31, Bermuda!$D:$D, "London") + SUMIFS(Jamaica!$L:$L, Jamaica!$B:$B, $A31, Jamaica!$D:$D, "London") + SUMIFS(Mountserat!$L:$L, Mountserat!$B:$B, $A31, Mountserat!$D:$D, "London") + SUMIFS(Nevis!$L:$L, Nevis!$B:$B, $A31, Nevis!$D:$D, "London") + SUMIFS('St Kitts'!$L:$L, 'St Kitts'!$B:$B, $A31, 'St Kitts'!$D:$D, "London") + SUMIFS(Tortola!$L:$L, Tortola!$B:$B, $A31, Tortola!$D:$D, "London") -> 0 | C31: =SUMIFS(Anguilla!$L:$L, Anguilla!$B:$B, $A31, Anguilla!$D:$D, "Out Ports") + SUMIFS(Antigua!$L:$L, Antigua!$B:$B, $A31, Antigua!$D:$D, "Out Ports") + SUMIFS(Barbados!$L:$L, Barbados!$B:$B, $A31, Barbados!$D:$D, "Out Ports") + SUMIFS(Bermuda!$L:$L, Bermuda!$B:$B, $A31, Bermuda!$D:$D, "Out Ports") + SUMIFS(Jamaica!$L:$L, Jamaica!$B:$B, $A31, Jamaica!$D:$D, "Out Ports") + SUMIFS(Mountserat!$L:$L, Mountserat!$B:$B, $A31, Mountserat!$D:$D, "Out Ports") + SUMIFS(Nevis!$L:$L, Nevis!$B:$B, $A31, Nevis!$D:$D, "Out Ports") + SUMIFS('St Kitts'!$L:$L, 'St Kitts'!$B:$B, $A31, 'St Kitts'!$D:$D, "Out Ports") + SUMIFS(Tortola!$L:$L, Tortola!$B:$B, $A31, Tortola!$D:$D, "Out Ports") -> 0 | D31: =B31+C31 -> 0
F36: t | G36: hh | H36: q | I36: lb
A37: Exports of Ginger this Year | C37: =SUM(K37:K47) -> 451.68348 | E37: Denmark/Norway | G37: 52 | I37: 7 | K37: =((F37*2240)+(G37*112)+(H37*28)+I37)/2240 -> 2.603125
A38: Stayed in Britain | C38: =D8-C37 -> 701.19375 | E38: East Country | G38: 829 | H38: 3 | K38: =((F38*2240)+(G38*112)+(H38*28)+I38)/2240 -> 41.4875
E39: Flanders | H39: 2 | I39: 22 | K39: =((F39*2240)+(G39*112)+(H39*28)+I39)/2240 -> 0.034821429
E40: Germany | G40: 7323 | H40: 2 | I40: 21 | K40: =((F40*2240)+(G40*112)+(H40*28)+I40)/2240 -> 366.18437
E41: Holland | G41: 274 | H41: 2 | I41: 6 | K41: =((F41*2240)+(G41*112)+(H41*28)+I41)/2240 -> 13.727679
E42: Ireland | G42: 12 | H42: 3 | I42: 26 | K42: =((F42*2240)+(G42*112)+(H42*28)+I42)/2240 -> 0.64910714
E43: Portugal | G43: 21 | I43: 9 | K43: =((F43*2240)+(G43*112)+(H43*28)+I43)/2240 -> 1.0540179
E44: Spain | G44: 34 | H44: 1 | I44: 17 | K44: =((F44*2240)+(G44*112)+(H44*28)+I44)/2240 -> 1.7200893
E45: Straights | G45: 479 | H45: 3 | I45: 9 | K45: =((F45*2240)+(G45*112)+(H45*28)+I45)/2240 -> 23.991518
E46: Carolina | H46: 1 | K46: =((F46*2240)+(G46*112)+(H46*28)+I46)/2240 -> 0.0125
E47: Virginia and Maryland | G47: 4 | H47: 1 | I47: 14 | K47: =((F47*2240)+(G47*112)+(H47*28)+I47)/2240 -> 0.21875
E48: Africa | H48: 1 | K48: =((F48*2240)+(G48*112)+(H48*28)+I48)/2240 -> 0.0125
E49: Germany | G49: 2799 | H49: 3 | I49: 1 | K49: =((F49*2240)+(G49*112)+(H49*28)+I49)/2240 -> 139.98795
E50: Holland | G50: 1126 | K50: =((F50*2240)+(G50*112)+(H50*28)+I50)/2240 -> 56.3
E51: Italy | G51: 74 | H51: 2 | I51: 18 | K51: =((F51*2240)+(G51*112)+(H51*28)+I51)/2240 -> 3.7330357
K52: =((F52*2240)+(G52*112)+(H52*28)+I52)/2240 -> 0
K53: =((F53*2240)+(G53*112)+(H53*28)+I53)/2240 -> 0
K54: =((F54*2240)+(G54*112)+(H54*28)+I54)/2240 -> 0
K55: =((F55*2240)+(G55*112)+(H55*28)+I55)/2240 -> 0
K56: =((F56*2240)+(G56*112)+(H56*28)+I56)/2240 -> 0
K57: =((F57*2240)+(G57*112)+(H57*28)+I57)/2240 -> 0

Sheet Anguilla
A1: YEAR | B1: COMMODITY_NAME | C1: FROM_LOCATION | D1: TO_LOCATION | E1: ton | F1: hh | G1: quarter | H1: lb | J1: Total Pounds | L1: WEIGHT
A2: 1755 | B2: Almonds, Bitter | C2: Anguilla | D2: London | J2: =(E2*2240)+(F2*112)+(G2*28)+H2 -> 0 | L2: =J2/2240 -> 0
A3: 1755 | B3: Almonds, Sweet | C3: Anguilla | D3: London | J3: =(E3*2240)+(F3*112)+(G3*28)+H3 -> 0 | L3: =J3/2240 -> 0
A4: 1755 | B4: Aloes Epatica | C4: Anguilla | D4: London | J4: =(E4*2240)+(F4*112)+(G4*28)+H4 -> 0 | L4: =J4/2240 -> 0
A5: 1755 | B5: Annatto | C5: Anguilla | D5: London | J5: =(E5*2240)+(F5*112)+(G5*28)+H5 -> 0 | L5: =J5/2240 -> 0
A6: 1755 | B6: Anniseeds | C6: Anguilla | D6: London | J6: =(E6*2240)+(F6*112)+(G6*28)+H6 -> 0 | L6: =J6/2240 -> 0
A7: 1755 | B7: Bacon | C7: Anguilla | D7: London | J7: =(E7*2240)+(F7*112)+(G7*28)+H7 -> 0 | L7: =J7/2240 -> 0
A8: 1755 | B8: Barrel Staves | C8: Anguilla | D8: London | J8: =(E8*2240)+(F8*112)+(G8*28)+H8 -> 0 | L8: =J8/2240 -> 0
A9: 1755 | B9: Bay Berries | C9: Anguilla | D9: London | J9: =(E9*2240)+(F9*112)+(G9*28)+H9 -> 0 | L9: =J9/2240 -> 0
A10: 1755 | B10: Bees Wax | C10: Anguilla | D10: London | J10: =(E10*2240)+(F10*112)+(G10*28)+H10 -> 0 | L10: =J10/2240 -> 0
A11: 1755 | B11: Brimstone | C11: Anguilla | D11: London | J11: =(E11*2240)+(F11*112)+(G11*28)+H11 -> 0 | L11: =J11/2240 -> 0
A12: 1755 | B12: Brown Sugar | C12: Anguilla | D12: London | J12: =(E12*2240)+(F12*112)+(G12*28)+H12 -> 0 | L12: =J12/2240 -> 0
A13: 1755 | B13: Cassia Fistula | C13: Anguilla | D13: London | J13: =(E13*2240)+(F13*112)+(G13*28)+H13 -> 0 | L13: =J13/2240 -> 0
... A62: 1755 | B62: Annatto | C62: Anguilla | D62: Out Ports | J62: =(E62*2240)+(F62*112)+(G62*28)+H62 -> 0 | L62: =J62/2240 -> 0
A63: 1755 | B63: Brown Sugar | C63: Anguilla | D63: Out Ports | F63: 638 | G63: 0 | H63: 11 | J63: =(E63*2240)+(F63*112)+(G63*28)+H63 -> 71467 | L63: =J63/2240 -> 31.904911
A64: 1755 | B64: Cassia Fistula | C64: Anguilla | D64: Out Ports | J64: =(E64*2240)+(F64*112)+(G64*28)+H64 -> 0 | L64: =J64/2240 -> 0
A65: 1755 | B65: Chocolate | C65: Anguilla | D65: Out Ports | J65: =(E65*2240)+(F65*112)+(G65*28)+H65 -> 0 | L65: =J65/2240 -> 0
A66: 1755 | B66: Cocoa Nuts | C66: Anguilla | D66: Out Ports | J66: =(E66*2240)+(F66*112)+(G66*28)+H66 -> 0 | L66: =J66/2240 -> 0
A67: 1755 | B67: Cotton | C67: Anguilla | D67: Out Ports | H67: =176.5*200 -> 35300 | I67: 176.5 bags | J67: =(E67*2240)+(F67*112)+(G67*28)+H67 -> 35300 | L67: =J67/2240 -> 15.758929
A68: 1755 | B68: Dry Ginger | C68: Anguilla | D68: Out Ports | J68: =(E68*2240)+(F68*112)+(G68*28)+H68 -> 0 | L68: =J68/2240 -> 0
A69: 1755 | B69: Elephant Teeth | C69: Anguilla | D69: Out Ports | J69: =(E69*2240)+(F69*112)+(G69*28)+H69 -> 0 | L69: =J69/2240 -> 0
A70: 1755 | B70: Indigo | C70: Anguilla | D70: Out Ports | J70: =(E70*2240)+(F70*112)+(G70*28)+H70 -> 0 | L70: =J70/2240 -> 0
A71: 1755 | B71: Lignum Vitae | C71: Anguilla | D71: Out Ports | J71: =(E71*2240)+(F71*112)+(G71*28)+H71 -> 0 | L71: =J71/2240 -> 0
A72: 1755 | B72: Lime Juice | C72: Anguilla | D72: Out Ports | J72: =(E72*2240)+(F72*112)+(G72*28)+H72 -> 0 | L72: =J72/2240 -> 0
A73: 1755 | B73: Madera Wine | C73: Anguilla | D73: Out Ports | J73: =(E73*2240)+(F73*112)+(G73*28)+H73 -> 0 | L73: =J73/2240 -> 0
A74: 1755 | B74: Molasses | C74: Anguilla | D74: Out Ports | J74: =(E74*2240)+(F74*112)+(G74*28)+H74 -> 0 | L74: =J74/2240 -> 0
A75: 1755 | B75: Pimento | C75: Anguilla | D75: Out Ports | J75: =(E75*2240)+(F75*112)+(G75*28)+H75 -> 0 | L75: =J75/2240 -> 0
A76: 1755 | B76: Rice | C76: Anguilla | D76: Out Ports | J76: =(E76*2240)+(F76*112)+(G76*28)+H76 -> 0 | L76: =J76/2240 -> 0
A77: 1755 | B77: Rum | C77: Anguilla | D77: Out Ports | J77: =(E77*2240)+(F77*112)+(G77*28)+H77 -> 0 | L77: =J77/2240 -> 0
A78: 1755 | B78: Shruff | C78: Anguilla | D78: Out Ports | J78: =(E78*2240)+(F78*112)+(G78*28)+H78 -> 0 | L78: =J78/2240 -> 0
A79: 1755 | B79: Snuff | C79: Anguilla | D79: Out Ports | J79: =(E79*2240)+(F79*112)+(G79*28)+H79 -> 0 | L79: =J79/2240 -> 0
... A84: 1755 | B84: Wood, Braziletto | C84: Anguilla | D84: Out Ports | J84: =(E84*2240)+(F84*112)+(G84*28)+H84 -> 0 | L84: =J84/2240 -> 0
A85: 1755 | B85: Wood, Fustick | C85: Anguilla | D85: Out Ports | E85: 7 | F85: 8 | G85: 2 | H85: 27 | J85: =(E85*2240)+(F85*112)+(G85*28)+H85 -> 16659 | L85: =J85/2240 -> 7.4370536
A86: 1755 | B86: Wood, Logwood | C86: Anguilla | D86: Out Ports | J86: =(E86*2240)+(F86*112)+(G86*28)+H86 -> 0 | L86: =J86/2240 -> 0
A87: 1755 | B87: Wood, Nicaragua | C87: Anguilla | D87: Out Ports | J87: =(E87*2240)+(F87*112)+(G87*28)+H87 -> 0 | L87: =J87/2240 -> 0
A88: 1755 | B88: Wood, Redwood | C88: Anguilla | D88: Out Ports | J88: =(E88*2240)+(F88*112)+(G88*28)+H88 -> 0 | L88: =J88/2240 -> 0

Sheet Antigua
A1: YEAR | B1: COMMODITY_NAME | C1: FROM_LOCATION | D1: TO_LOCATION | E1: ton | F1: hh | G1: quarter | H1: lb | J1: Total Pounds | L1: WEIGHT
A2: 1755 | B2: Aloes Epatica | C2: Antigua | D2: London | H2: 45 | J2: =(E2*2240)+(F2*112)+(G2*28)+H2 -> 45 | L2: =J2/2240 -> 0.020089286
A3: 1755 | B3: Annatto | C3: Antigua | D3: London | J3: =(E3*2240)+(F3*112)+(G3*28)+H3 -> 0 | L3: =J3/2240 -> 0
A4: 1755 | B4: Bees Wax | C4: Antigua | D4: London | F4: 61 | G4: 1 | H4: 26 | J4: =(E4*2240)+(F4*112)+(G4*28)+H4 -> 6886 | L4: =J4/2240 -> 3.0741071
A5: 1755 | B5: Brown Sugar | C5: Antigua | D5: London | F5: 211904 | G5: 2 | H5: 4 | J5: =(E5*2240)+(F5*112)+(G5*28)+H5 -> 23733308 | L5: =J5/2240 -> 10595.227
A6: 1755 | B6: Chocolate | C6: Antigua | D6: London | J6: =(E6*2240)+(F6*112)+(G6*28)+H6 -> 0 | L6: =J6/2240 -> 0
A7: 1755 | B7: Cocoa Nuts | C7: Antigua | D7: London | J7: =(E7*2240)+(F7*112)+(G7*28)+H7 -> 0 | L7: =J7/2240 -> 0
A8: 1755 | B8: Cortex Winteranus | C8: Antigua | D8: London | H8: 300 | J8: =(E8*2240)+(F8*112)+(G8*28)+H8 -> 300 | L8: =J8/2240 -> 0.13392857
A9: 1755 | B9: Cotton | C9: Antigua | D9: London | H9: =179*200 -> 35800 | I9: 179 bags | J9: =(E9*2240)+(F9*112)+(G9*28)+H9 -> 35800 | L9: =J9/2240 -> 15.982143
A10: 1755 | B10: Dry Ginger | C10: Antigua | D10: London | F10: 5076 | G10: 3 | H10: 10 | J10: =(E10*2240)+(F10*112)+(G10*28)+H10 -> 568606 | L10: =J10/2240 -> 253.84196
A11: 1755 | B11: Elephant Teeth | C11: Antigua | D11: London | F11: 25 | G11: 1 | J11: =(E11*2240)+(F11*112)+(G11*28)+H11 -> 2828 | L11: =J11/2240 -> 1.2625
A12: 1755 | B12: Green Ginger | C12: Antigua | D12: London | H12: 47 | J12: =(E12*2240)+(F12*112)+(G12*28)+H12 -> 47 | L12: =J12/2240 -> 0.020982143
A13: 1755 | B13: Indigo | C13: Antigua | D13: London | J13: =(E13*2240)+(F13*112)+(G13*28)+H13 -> 0 | L13: =J13/2240 -> 0
A14: 1755 | B14: Lemon Water | C14: Antigua | D14: London | J14: =(E14*2240)+(F14*112)+(G14*28)+H14 -> 0 | L14: =J14/2240 -> 0
A15: 1755 | B15: Lignum Vitae | C15: Antigua | D15: London | E15: 91 | F15: 14 | G15: 1 | J15: =(E15*2240)+(F15*112)+(G15*28)+H15 -> 205436 | L15: =J15/2240 -> 91.7125
A16: 1755 | B16: Lime Juice | C16: Antigua | D16: London | J16: =(E16*2240)+(F16*112)+(G16*28)+H16 -> 0 | L16: =J16/2240 -> 0
A17: 1755 | B17: Madera Wine | C17: Antigua | D17: London | H17: 192089 | I17: 76t 0hh 52g | J17: =(E17*2240)+(F17*112)+(G17*28)+H17 -> 192089 | L17: =J17/2240 -> 85.754018
A18: 1755 | B18: Molasses | C18: Antigua | D18: London | J18: =(E18*2240)+(F18*112)+(G18*28)+H18 -> 0 | L18: =J18/2240 -> 0
A19: 1755 | B19: Pickles | C19: Antigua | D19: London | H19: 45 | I19: 4.5g | J19: =(E19*2240)+(F19*112)+(G19*28)+H19 -> 45 | L19: =J19/2240 -> 0.020089286
A20: 1755 | B20: Rice | C20: Antigua | D20: London | F20: 94 | G20: 3 | J20: =(E20*2240)+(F20*112)+(G20*28)+H20 -> 10612 | L20: =J20/2240 -> 4.7375
A21: 1755 | B21: Rum | C21: Antigua | D21: London | H21: 449395 | I21: 44928g | J21: =(E21*2240)+(F21*112)+(G21*28)+H21 -> 449395 | L21: =J21/2240 -> 200.62277
A22: 1755 | B22: Shruff | C22: Antigua | D22: London | J22: =(E22*2240)+(F22*112)+(G22*28)+H22 -> 0 | L22: =J22/2240 -> 0
A23: 1755 | B23: Succads | C23: Antigua | D23: London | H23: 129 | J23: =(E23*2240)+(F23*112)+(G23*28)+H23 -> 129 | L23: =J23/2240 -> 0.057589286
A24: 1755 | B24: Tobacco | C24: Antigua | D24: London | J24: =(E24*2240)+(F24*112)+(G24*28)+H24 -> 0 | L24: =J24/2240 -> 0
A25: 1755 | B25: Tortoise Shell | C25: Antigua | D25: London | H25: 4 | J25: =(E25*2240)+(F25*112)+(G25*28)+H25 -> 4 | L25: =J25/2240 -> 0.0017857143
A26: 1755 | B26: Train Oyl | C26: Antigua | D26: London | E26: 40 | J26: =(E26*2240)+(F26*112)+(G26*28)+H26 -> 89600 | L26: =J26/2240 -> 40
A27: 1755 | B27: White Sugar | C27: Antigua | D27: London | J27: =(E27*2240)+(F27*112)+(G27*28)+H27 -> 0 | L27: =J27/2240 -> 0
A28: 1755 | B28: Wood, Fustick | C28: Antigua | D28: London | E28: 174 | F28: 14 | G28: 0 | H28: 14 | J28: =(E28*2240)+(F28*112)+(G28*28)+H28 -> 391342 | L28: =J28/2240 -> 174.70625
A29: 1755 | B29: Wood, Mahogany | C29: Antigua | D29: London | E29: 13 | F29: 14 | J29: =(E29*2240)+(F29*112)+(G29*28)+H29 -> 30688 | L29: =J29/2240 -> 13.7
A30: 1755 | B30: Bees Wax | C30: Antigua | D30: Out Ports | F30: 20 | G30: 3 | H30: 10 | J30: =(E30*2240)+(F30*112)+(G30*28)+H30 -> 2334 | L30: =J30/2240 -> 1.0419643
A31: 1755 | B31: Brown Sugar | C31: Antigua | D31: Out Ports | F31: 37287 | H31: 12 | J31: =(E31*2240)+(F31*112)+(G31*28)+H31 -> 4176156 | L31: =J31/2240 -> 1864.3554
A32: 1755 | B32: Cocoa | C32: Antigua | D32: Out Ports | J32: =(E32*2240)+(F32*112)+(G32*28)+H32 -> 0 | L32: =J32/2240 -> 0
A33: 1755 | B33: Cocoa Nuts | C33: Antigua | D33: Out Ports | J33: =(E33*2240)+(F33*112)+(G33*28)+H33 -> 0 | L33: =J33/2240 -> 0
A34: 1755 | B34: Cotton | C34: Antigua | D34: Out Ports | H34: =170*511 -> 86870 | I34: 511b | J34: =(E34*2240)+(F34*112)+(G34*28)+H34 -> 86870 | L34: =J34/2240 -> 38.78125
A35: 1755 | B35: Dry Ginger | C35: Antigua | D35: Out Ports | F35: 140 | G35: 2 | H35: 4 | J35: =(E35*2240)+(F35*112)+(G35*28)+H35 -> 15740 | L35: =J35/2240 -> 7.0267857
A36: 1755 | B36: Elephant Teeth | C36: Antigua | D36: Out Ports | F36: 36 | G36: 1 | H36: 8 | J36: =(E36*2240)+(F36*112)+(G36*28)+H36 -> 4068 | L36: =J36/2240 -> 1.8160714
A37: 1755 | B37: Fustic | C37: Antigua | D37: Out Ports | J37: =(E37*2240)+(F37*112)+(G37*28)+H37 -> 0 | L37: =J37/2240 -> 0
A38: 1755 | B38: Green Ginger | C38: Antigua | D38: Out Ports | H38: 27 | J38: =(E38*2240)+(F38*112)+(G38*28)+H38 -> 27 | L38: =J38/2240 -> 0.012053571
A39: 1755 | B39: Indigo | C39: Antigua | D39: Out Ports | J39: =(E39*2240)+(F39*112)+(G39*28)+H39 -> 0 | L39: =J39/2240 -> 0
A40: 1755 | B40: Lignum Vitae | C40: Antigua | D40: Out Ports | E40: 23 | F40: 16 | J40: =(E40*2240)+(F40*112)+(G40*28)+H40 -> 53312 | L40: =J40/2240 -> 23.8
...

Sheet Barbados
A1: YEAR | B1: COMMODITY_NAME | C1: FROM_LOCATION | D1: TO_LOCATION | E1: ton | F1: hh | G1: quarter | H1: lb | J1: Total Pounds | L1: WEIGHT
A2: 1755 | B2: Almonds, Bitter | C2: Barbados | D2: London | J2: =(E2*2240)+(F2*112)+(G2*28)+H2 -> 0 | L2: =J2/2240 -> 0
A3: 1755 | B3: Almonds, Sweet | C3: Barbados | D3: London | J3: =(E3*2240)+(F3*112)+(G3*28)+H3 -> 0 | L3: =J3/2240 -> 0
A4: 1755 | B4: Aloes Epatica | C4: Barbados | D4: London | H4: 12216 | J4: =(E4*2240)+(F4*112)+(G4*28)+H4 -> 12216 | L4: =J4/2240 -> 5.4535714
A5: 1755 | B5: Annatto | C5: Barbados | D5: London | J5: =(E5*2240)+(F5*112)+(G5*28)+H5 -> 0 | L5: =J5/2240 -> 0
A6: 1755 | B6: Anniseeds | C6: Barbados | D6: London | J6: =(E6*2240)+(F6*112)+(G6*28)+H6 -> 0 | L6: =J6/2240 -> 0
A7: 1755 | B7: Barbados T… | C7: Barbados | D7: London | H7: 4310 | J7: =(E7*2240)+(F7*112)+(G7*28)+H7 -> 4310 | L7: =J7/2240 -> 1.9241071
A8: 1755 | B8: Barrel Staves | C8: Barbados | D8: London | J8: =(E8*2240)+(F8*112)+(G8*28)+H8 -> 0 | L8: =J8/2240 -> 0
A9: 1755 | B9: Bees Wax | C9: Barbados | D9: London | F9: 2 | J9: =(E9*2240)+(F9*112)+(G9*28)+H9 -> 224 | L9: =J9/2240 -> 0.1
A10: 1755 | B10: Brimstone | C10: Barbados | D10: London | J10: =(E10*2240)+(F10*112)+(G10*28)+H10 -> 0 | L10: =J10/2240 -> 0
A11: 1755 | B11: Brown Sugar | C11: Barbados | D11: London | F11: 113177 | G11: 0 | H11: 25 | J11: =(E11*2240)+(F11*112)+(G11*28)+H11 -> 12675849 | L11: =J11/2240 -> 5658.8612
A12: 1755 | B12: Cassia Fistula | C12: Barbados | D12: London | H12: 238 | J12: =(E12*2240)+(F12*112)+(G12*28)+H12 -> 238 | L12: =J12/2240 -> 0.10625
A13: 1755 | B13: Chocolate Paste | C13: Barbados | D13: London | J13: =(E13*2240)+(F13*112)+(G13*28)+H13 -> 0 | L13: =J13/2240 -> 0
A14: 1755 | B14: Cocheneal | C14: Barbados | D14: London | J14: =(E14*2240)+(F14*112)+(G14*28)+H14 -> 0 | L14: =J14/2240 -> 0
A15: 1755 | B15: Cocoa Nuts | C15: Barbados | D15: London | F15: 31 | J15: =(E15*2240)+(F15*112)+(G15*28)+H15 -> 3472 | L15: =J15/2240 -> 1.55
A16: 1755 | B16: Cocoa Paste | C16: Barbados | D16: London | J16: =(E16*2240)+(F16*112)+(G16*28)+H16 -> 0 | L16: =J16/2240 -> 0
A17: 1755 | B17: Cotton | C17: Barbados | D17: London | H17: =54*200 -> 10800 | I17: 54 bags | J17: =(E17*2240)+(F17*112)+(G17*28)+H17 -> 10800 | L17: =J17/2240 -> 4.8214286
A18: 1755 | B18: Dry Ginger | C18: Barbados | D18: London | F18: 4233 | G18: 3 | H18: 21 | J18: =(E18*2240)+(F18*112)+(G18*28)+H18 -> 474201 | L18: =J18/2240 -> 211.69688
A19: 1755 | B19: Elephant Teeth | C19: Barbados | D19: London | F19: 35 | G19: 2 | H19: 14 | J19: =(E19*2240)+(F19*112)+(G19*28)+H19 -> 3990 | L19: =J19/2240 -> 1.78125
A20: 1755 | B20: Green Ginger | C20: Barbados | D20: London | H20: 707 | J20: =(E20*2240)+(F20*112)+(G20*28)+H20 -> 707 | L20: =J20/2240 -> 0.315625
A21: 1755 | B21: Hemp | C21: Barbados | D21: London | J21: =(E21*2240)+(F21*112)+(G21*28)+H21 -> 0 | L21: =J21/2240 -> 0
A22: 1755 | B22: Indigo | C22: Barbados | D22: London | J22: =(E22*2240)+(F22*112)+(G22*28)+H22 -> 0 | L22: =J22/2240 -> 0
A23: 1755 | B23: Lemon Water | C23: Barbados | D23: London | J23: =(E23*2240)+(F23*112)+(G23*28)+H23 -> 0 | L23: =J23/2240 -> 0
A24: 1755 | B24: Lignum Vitae | C24: Barbados | D24: London | J24: =(E24*2240)+(F24*112)+(G24*28)+H24 -> 0 | L24: =J24/2240 -> 0
A25: 1755 | B25: Lime Juice | C25: Barbados | D25: London | J25: =(E25*2240)+(F25*112)+(G25*28)+H25 -> 0 | L25: =J25/2240 -> 0
A26: 1755 | B26: Loaf Sugar | C26: Barbados | D26: London | J26: =(E26*2240)+(F26*112)+(G26*28)+H26 -> 0 | L26: =J26/2240 -> 0
A27: 1755 | B27: Madera Wine | C27: Barbados | D27: London | H27: 650377 | I27: 258t 0hh 5g | J27: =(E27*2240)+(F27*112)+(G27*28)+H27 -> 650377 | L27: =J27/2240 -> 290.34688
A28: 1755 | B28: Molasses | C28: Barbados | D28: London | J28: =(E28*2240)+(F28*112)+(G28*28)+H28 -> 0 | L28: =J28/2240 -> 0
A29: 1755 | B29: Oranges | C29: Barbados | D29: London | J29: =(E29*2240)+(F29*112)+(G29*28)+H29 -> 0 | L29: =J29/2240 -> 0
A30: 1755 | B30: Pickles | C30: Barbados | D30: London | H30: 215 | I30: 21.5g | J30: =(E30*2240)+(F30*112)+(G30*28)+H30 -> 215 | L30: =J30/2240 -> 0.095982143
A31: 1755 | B31: Pimento | C31: Barbados | D31: London | H31: 494 | J31: =(E31*2240)+(F31*112)+(G31*28)+H31 -> 494 | L31: =J31/2240 -> 0.22053571
A32: 1755 | B32: Rice | C32: Barbados | D32: London | J32: =(E32*2240)+(F32*112)+(G32*28)+H32 -> 0 | L32: =J32/2240 -> 0
A33: 1755 | B33: Rum | C33: Barbados | D33: London | H33: 94850 | I33: 9398g | J33: =(E33*2240)+(F33*112)+(G33*28)+H33 -> 94850 | L33: =J33/2240 -> 42.34375
A34: 1755 | B34: Sasparilla | C34: Barbados | D34: London | H34: 206 | J34: =(E34*2240)+(F34*112)+(G34*28)+H34 -> 206 | L34: =J34/2240 -> 0.091964286
A35: 1755 | B35: Shruff | C35: Barbados | D35: London | J35: =(E35*2240)+(F35*112)+(G35*28)+H35 -> 0 | L35: =J35/2240 -> 0
A36: 1755 | B36: Snuff | C36: Barbados | D36: London | J36: =(E36*2240)+(F36*112)+(G36*28)+H36 -> 0 | L36: =J36/2240 -> 0
A37: 1755 | B37: Succads | C37: Barbados | D37: London | H37: 1689 | J37: =(E37*2240)+(F37*112)+(G37*28)+H37 -> 1689 | L37: =J37/2240 -> 0.75401786
A38: 1755 | B38: Tamerinds | C38: Barbados | D38: London | H38: 744 | J38: =(E38*2240)+(F38*112)+(G38*28)+H38 -> 744 | L38: =J38/2240 -> 0.33214286
A39: 1755 | B39: Tobacco | C39: Barbados | D39: London | J39: =(E39*2240)+(F39*112)+(G39*28)+H39 -> 0 | L39: =J39/2240 -> 0
A40: 1755 | B40: Tortoise Shell | C40: Barbados | D40: London | J40: =(E40*2240)+(F40*112)+(G40*28)+H40 -> 0 | L40: =J40/2240 -> 0
...

Sheet Bermuda
A1: YEAR | B1: COMMODITY_NAME | C1: FROM_LOCATION | D1: TO_LOCATION | E1: ton | F1: hh | G1: quarter | H1: lb | J1: Total Pounds | L1: WEIGHT
B2: Bermudos Plat | C2: Bermuda | D2: London | J2: =(E2*2240)+(F2*112)+(G2*28)+H2 -> 0 | L2: =J2/2240 -> 0
B3: Cocoa Nuts | C3: Bermuda | D3: London | J3: =(E3*2240)+(F3*112)+(G3*28)+H3 -> 0 | L3: =J3/2240 -> 0
B4: Cotton | C4: Bermuda | D4: London | J4: =(E4*2240)+(F4*112)+(G4*28)+H4 -> 0 | L4: =J4/2240 -> 0
B5: Wood, Braziletto | C5: Bermuda | D5: London | J5: =(E5*2240)+(F5*112)+(G5*28)+H5 -> 0 | L5: =J5/2240 -> 0
B6: Wood, Logwood | C6: Bermuda | D6: London | J6: =(E6*2240)+(F6*112)+(G6*28)+H6 -> 0 | L6: =J6/2240 -> 0
B7: Indigo | C7: Bermuda | D7: Out Ports | J7: =(E7*2240)+(F7*112)+(G7*28)+H7 -> 0 | L7: =J7/2240 -> 0
B8: Logwood | C8: Bermuda | D8: Out Ports | J8: =(E8*2240)+(F8*112)+(G8*28)+H8 -> 0 | L8: =J8/2240 -> 0
B9: Shruff | C9: Bermuda | D9: Out Ports | J9: =(E9*2240)+(F9*112)+(G9*28)+H9 -> 0 | L9: =J9/2240 -> 0
B10: Succads | C10: Bermuda | D10: Out Ports | J10: =(E10*2240)+(F10*112)+(G10*28)+H10 -> 0 | L10: =J10/2240 -> 0
B11: Cotton | C11: Bermuda | D11: Out Ports | J11: =(E11*2240)+(F11*112)+(G11*28)+H11 -> 0 | L11: =J11/2240 -> 0
B12: Cocoa Nuts | C12: Bermuda | D12: Out Ports | J12: =(E12*2240)+(F12*112)+(G12*28)+H12 -> 0 | L12: =J12/2240 -> 0
B13: Wood, Braziletto | C13: Bermuda | D13: Out Ports | J13: =(E13*2240)+(F13*112)+(G13*28)+H13 -> 0 | L13: =J13/2240 -> 0
B14: Wood, Logwood | C14: Bermuda | D14: Out Ports | J14: =(E14*2240)+(F14*112)+(G14*28)+H14 -> 0 | L14: =J14/2240 -> 0

Sheet Jamaica
A1: YEAR | B1: COMMODITY_NAME | C1: FROM_LOCATION | D1: TO_LOCATION | E1: ton | F1: hh | G1: quarter | H1: lb | J1: Total Pounds | L1: WEIGHT
A2: 1755 | B2: Almonds, Bitter | C2: Jamaica | D2: London | J2: =(E2*2240)+(F2*112)+(G2*28)+H2 -> 0 | L2: =J2/2240 -> 0
A3: 1755 | B3: Almonds, Sweet | C3: Jamaica | D3: London | J3: =(E3*2240)+(F3*112)+(G3*28)+H3 -> 0 | L3: =J3/2240 -> 0
A4: 1755 | B4: Aloes Epatica | C4: Jamaica | D4: London | J4: =(E4*2240)+(F4*112)+(G4*28)+H4 -> 0 | L4: =J4/2240 -> 0
A5: 1755 | B5: Annatto | C5: Jamaica | D5: London | J5: =(E5*2240)+(F5*112)+(G5*28)+H5 -> 0 | L5: =J5/2240 -> 0
A6: 1755 | B6: Anniseeds | C6: Jamaica | D6: London | J6: =(E6*2240)+(F6*112)+(G6*28)+H6 -> 0 | L6: =J6/2240 -> 0
A7: 1755 | B7: Bacon | C7: Jamaica | D7: London | J7: =(E7*2240)+(F7*112)+(G7*28)+H7 -> 0 | L7: =J7/2240 -> 0
A8: 1755 | B8: Barrel Staves | C8: Jamaica | D8: London | J8: =(E8*2240)+(F8*112)+(G8*28)+H8 -> 0 | L8: =J8/2240 -> 0
A9: 1755 | B9: Bay Berries | C9: Jamaica | D9: London | F9: 50 | J9: =(E9*2240)+(F9*112)+(G9*28)+H9 -> 5600 | L9: =J9/2240 -> 2.5
A10: 1755 | B10: Bees Wax | C10: Jamaica | D10: London | F10: 10 | J10: =(E10*2240)+(F10*112)+(G10*28)+H10 -> 1120 | L10: =J10/2240 -> 0.5
A11: 1755 | B11: Brimstone | C11: Jamaica | D11: London | J11: =(E11*2240)+(F11*112)+(G11*28)+H11 -> 0 | L11: =J11/2240 -> 0
A12: 1755 | B12: Brown Sugar | C12: Jamaica | D12: London | F12: 271888 | G12: 2 | H12: 7 | J12: =(E12*2240)+(F12*112)+(G12*28)+H12 -> 30451519 | L12: =J12/2240 -> 13594.428
A13: 1755 | B13: Cassia Fistula | C13: Jamaica | D13: London | H13: 184 | J13: =(E13*2240)+(F13*112)+(G13*28)+H13 -> 184 | L13: =J13/2240 -> 0.082142857
A14: 1755 | B14: Chocolate Paste | C14: Jamaica | D14: London | J14: =(E14*2240)+(F14*112)+(G14*28)+H14 -> 0 | L14: =J14/2240 -> 0
A15: 1755 | B15: Cocheneal | C15: Jamaica | D15: London | J15: =(E15*2240)+(F15*112)+(G15*28)+H15 -> 0 | L15: =J15/2240 -> 0
A16: 1755 | B16: Cocoa Nuts | C16: Jamaica | D16: London | F16: 213 | H16: 4 | J16: =(E16*2240)+(F16*112)+(G16*28)+H16 -> 23860 | L16: =J16/2240 -> 10.651786
A17: 1755 | B17: Cocoa Paste | C17: Jamaica | D17: London | J17: =(E17*2240)+(F17*112)+(G17*28)+H17 -> 0 | L17: =J17/2240 -> 0
A18: 1755 | B18: Coffee | C18: Jamaica | D18: London | F18: 555 | G18: 3 | H18: 20 | J18: =(E18*2240)+(F18*112)+(G18*28)+H18 -> 62264 | L18: =J18/2240 -> 27.796429
A19: 1755 | B19: Cortex Peru | C19: Jamaica | D19: London | H19: 731 | J19: =(E19*2240)+(F19*112)+(G19*28)+H19 -> 731 | L19: =J19/2240 -> 0.32633929
A20: 1755 | B20: Cortex Winteranus | C20: Jamaica | D20: London | J20: =(E20*2240)+(F20*112)+(G20*28)+H20 -> 0 | L20: =J20/2240 -> 0
A21: 1755 | B21: Cotton | C21: Jamaica | D21: London | H21: =1031*200 -> 206200 | I21: 1031 bags | J21: =(E21*2240)+(F21*112)+(G21*28)+H21 -> 206200 | L21: =J21/2240 -> 92.053571
A22: 1755 | B22: Dry Ginger | C22: Jamaica | D22: London | F22: 5565 | G22: 1 | H22: 6 | J22: =(E22*2240)+(F22*112)+(G22*28)+H22 -> 623314 | L22: =J22/2240 -> 278.26518
A23: 1755 | B23: Elephant Teeth | C23: Jamaica | D23: London | F23: 38 | H23: 3 | J23: =(E23*2240)+(F23*112)+(G23*28)+H23 -> 4259 | L23: =J23/2240 -> 1.9013393
A24: 1755 | B24: Green Ginger | C24: Jamaica | D24: London | H24: 433 | J24: =(E24*2240)+(F24*112)+(G24*28)+H24 -> 433 | L24: =J24/2240 -> 0.19330357
A25: 1755 | B25: Guinea Grains | C25: Jamaica | D25: London | H25: 1268 | J25: =(E25*2240)+(F25*112)+(G25*28)+H25 -> 1268 | L25: =J25/2240 -> 0.56607143
A26: 1755 | B26: Gum Guiacum | C26: Jamaica | D26: London | H26: 2997 | J26: =(E26*2240)+(F26*112)+(G26*28)+H26 -> 2997 | L26: =J26/2240 -> 1.3379464
A27: 1755 | B27: Hemp | C27: Jamaica | D27: London | J27: =(E27*2240)+(F27*112)+(G27*28)+H27 -> 0 | L27: =J27/2240 -> 0
A28: 1755 | B28: Indigo, Plantation | C28: Jamaica | D28: London | H28: 440 | J28: =(E28*2240)+(F28*112)+(G28*28)+H28 -> 440 | L28: =J28/2240 -> 0.19642857
A29: 1755 | B29: Indigo, Spanish | C29: Jamaica | D29: London | H29: 2645 | J29: =(E29*2240)+(F29*112)+(G29*28)+H29 -> 2645 | L29: =J29/2240 -> 1.1808036
A30: 1755 | B30: Jallop? | C30: Jamaica | D30: London | H30: 3929 | J30: =(E30*2240)+(F30*112)+(G30*28)+H30 -> 3929 | L30: =J30/2240 -> 1.7540179
A31: 1755 | B31: Lemon Water | C31: Jamaica | D31: London | J31: =(E31*2240)+(F31*112)+(G31*28)+H31 -> 0 | L31: =J31/2240 -> 0
A32: 1755 | B32: Lignum Vitae | C32: Jamaica | D32: London | E32: 65 | F32: 10 | J32: =(E32*2240)+(F32*112)+(G32*28)+H32 -> 146720 | L32: =J32/2240 -> 65.5
A33: 1755 | B33: Lime Juice | C33: Jamaica | D33: London | H33: 31257 | I33: 3097g | J33: =(E33*2240)+(F33*112)+(G33*28)+H33 -> 31257 | L33: =J33/2240 -> 13.954018
A34: 1755 | B34: Loaf Sugar | C34: Jamaica | D34: London | J34: =(E34*2240)+(F34*112)+(G34*28)+H34 -> 0 | L34: =J34/2240 -> 0
A35: 1755 | B35: Madera Wine | C35: Jamaica | D35: London | H35: 84495 | I35: 38t 3hh 8g | J35: =(E35*2240)+(F35*112)+(G35*28)+H35 -> 84495 | L35: =J35/2240 -> 37.720982
A36: 1755 | B36: Molasses | C36: Jamaica | D36: London | J36: =(E36*2240)+(F36*112)+(G36*28)+H36 -> 0 | L36: =J36/2240 -> 0
A37: 1755 | B37: Oranges | C37: Jamaica | D37: London | J37: =(E37*2240)+(F37*112)+(G37*28)+H37 -> 0 | L37: =J37/2240 -> 0
A38: 1755 | B38: Orchelia | C38: Jamaica | D38: London | F38: 10 | J38: =(E38*2240)+(F38*112)+(G38*28)+H38 -> 1120 | L38: =J38/2240 -> 0.5
A39: 1755 | B39: Pickles | C39: Jamaica | D39: London | H39: 159 | I39: 15.75g | J39: =(E39*2240)+(F39*112)+(G39*28)+H39 -> 159 | L39: =J39/2240 -> 0.070982143
A40: 1755 | B40: Pimento | C40: Jamaica | D40: London | H40: 264682 | J40: =(E40*2240)+(F40*112)+(G40*28)+H40 -> 264682 | L40: =J40/2240 -> 118.16161
...

Sheet Mountserat
A1: YEAR | B1: COMMODITY_NAME | C1: FROM_LOCATION | D1: TO_LOCATION | E1: ton | F1: hh | G1: quarter | H1: lb | J1: Total Pounds | L1: WEIGHT
A2: 1755 | B2: Almonds, Bitter | C2: Mountserat | D2: London | J2: =(E2*2240)+(F2*112)+(G2*28)+H2 -> 0 | L2: =J2/2240 -> 0
A3: 1755 | B3: Almonds, Sweet | C3: Mountserat | D3: London | J3: =(E3*2240)+(F3*112)+(G3*28)+H3 -> 0 | L3: =J3/2240 -> 0
A4: 1755 | B4: Aloes Epatica | C4: Mountserat | D4: London | J4: =(E4*2240)+(F4*112)+(G4*28)+H4 -> 0 | L4: =J4/2240 -> 0
A5: 1755 | B5: Annatto | C5: Mountserat | D5: London | J5: =(E5*2240)+(F5*112)+(G5*28)+H5 -> 0 | L5: =J5/2240 -> 0
A6: 1755 | B6: Anniseeds | C6: Mountserat | D6: London | J6: =(E6*2240)+(F6*112)+(G6*28)+H6 -> 0 | L6: =J6/2240 -> 0
A7: 1755 | B7: Bacon | C7: Mountserat | D7: London | J7: =(E7*2240)+(F7*112)+(G7*28)+H7 -> 0 | L7: =J7/2240 -> 0
A8: 1755 | B8: Barrel Staves | C8: Mountserat | D8: London | J8: =(E8*2240)+(F8*112)+(G8*28)+H8 -> 0 | L8: =J8/2240 -> 0
A9: 1755 | B9: Bees Wax | C9: Mountserat | D9: London | F9: 10 | G9: 1 | J9: =(E9*2240)+(F9*112)+(G9*28)+H9 -> 1148 | L9: =J9/2240 -> 0.5125
A10: 1755 | B10: Brimstone | C10: Mountserat | D10: London | J10: =(E10*2240)+(F10*112)+(G10*28)+H10 -> 0 | L10: =J10/2240 -> 0
A11: 1755 | B11: Brown Sugar | C11: Mountserat | D11: London | F11: 47959 | G11: 1 | H11: 20 | J11: =(E11*2240)+(F11*112)+(G11*28)+H11 -> 5371456 | L11: =J11/2240 -> 2397.9714
A12: 1755 | B12: Cassia Fistula | C12: Mountserat | D12: London | J12: =(E12*2240)+(F12*112)+(G12*28)+H12 -> 0 | L12: =J12/2240 -> 0
A13: 1755 | B13: Chocolate Paste | C13: Mountserat | D13: London | J13: =(E13*2240)+(F13*112)+(G13*28)+H13 -> 0 | L13: =J13/2240 -> 0
A14: 1755 | B14: Cocheneal | C14: Mountserat | D14: London | J14: =(E14*2240)+(F14*112)+(G14*28)+H14 -> 0 | L14: =J14/2240 -> 0
A15: 1755 | B15: Cocoa Nuts | C15: Mountserat | D15: London | J15: =(E15*2240)+(F15*112)+(G15*28)+H15 -> 0 | L15: =J15/2240 -> 0
A16: 1755 | B16: Cocoa Paste | C16: Mountserat | D16: London | J16: =(E16*2240)+(F16*112)+(G16*28)+H16 -> 0 | L16: =J16/2240 -> 0
A17: 1755 | B17: Coffee | C17: Mountserat | D17: London | F17: 1 | G17: 1 | H17: 7 | J17: =(E17*2240)+(F17*112)+(G17*28)+H17 -> 147 | L17: =J17/2240 -> 0.065625
A18: 1755 | B18: Cortex Winteranus | C18: Mountserat | D18: London | J18: =(E18*2240)+(F18*112)+(G18*28)+H18 -> 0 | L18: =J18/2240 -> 0
A19: 1755 | B19: Cotton | C19: Mountserat | D19: London | H19: =95*200 -> 19000 | I19: 95 bags | J19: =(E19*2240)+(F19*112)+(G19*28)+H19 -> 19000 | L19: =J19/2240 -> 8.4821429
A20: 1755 | B20: Dry Ginger | C20: Mountserat | D20: London | F20: 11 | G20: 1 | H20: 12 | J20: =(E20*2240)+(F20*112)+(G20*28)+H20 -> 1272 | L20: =J20/2240 -> 0.56785714
A21: 1755 | B21: Elephant Teeth | C21: Mountserat | D21: London | F21: 2 | J21: =(E21*2240)+(F21*112)+(G21*28)+H21 -> 224 | L21: =J21/2240 -> 0.1
A22: 1755 | B22: Green Ginger | C22: Mountserat | D22: London | J22: =(E22*2240)+(F22*112)+(G22*28)+H22 -> 0 | L22: =J22/2240 -> 0
A23: 1755 | B23: Hemp | C23: Mountserat | D23: London | J23: =(E23*2240)+(F23*112)+(G23*28)+H23 -> 0 | L23: =J23/2240 -> 0
A24: 1755 | B24: Indigo | C24: Mountserat | D24: London | H24: 2814 | J24: =(E24*2240)+(F24*112)+(G24*28)+H24 -> 2814 | L24: =J24/2240 -> 1.25625
A25: 1755 | B25: Lemon Water | C25: Mountserat | D25: London | J25: =(E25*2240)+(F25*112)+(G25*28)+H25 -> 0 | L25: =J25/2240 -> 0
A26: 1755 | B26: Lignum Vitae | C26: Mountserat | D26: London | J26: =(E26*2240)+(F26*112)+(G26*28)+H26 -> 0 | L26: =J26/2240 -> 0
A27: 1755 | B27: Lime Juice | C27: Mountserat | D27: London | J27: =(E27*2240)+(F27*112)+(G27*28)+H27 -> 0 | L27: =J27/2240 -> 0
A28: 1755 | B28: Loaf Sugar | C28: Mountserat | D28: London | J28: =(E28*2240)+(F28*112)+(G28*28)+H28 -> 0 | L28: =J28/2240 -> 0
A29: 1755 | B29: Madera Wine | C29: Mountserat | D29: London | H29: 122685 | I29: 56t 0hh 60g | J29: =(E29*2240)+(F29*112)+(G29*28)+H29 -> 122685 | L29: =J29/2240 -> 54.770089
A30: 1755 | B30: Molasses | C30: Mountserat | D30: London | J30: =(E30*2240)+(F30*112)+(G30*28)+H30 -> 0 | L30: =J30/2240 -> 0
A31: 1755 | B31: Oranges | C31: Mountserat | D31: London | J31: =(E31*2240)+(F31*112)+(G31*28)+H31 -> 0 | L31: =J31/2240 -> 0
A32: 1755 | B32: Pickles | C32: Mountserat | D32: London | H32: 20 | I32: 2g | J32: =(E32*2240)+(F32*112)+(G32*28)+H32 -> 20 | L32: =J32/2240 -> 0.0089285714
A33: 1755 | B33: Pimento | C33: Mountserat | D33: London | J33: =(E33*2240)+(F33*112)+(G33*28)+H33 -> 0 | L33: =J33/2240 -> 0
A34: 1755 | B34: Rice | C34: Mountserat | D34: London | J34: =(E34*2240)+(F34*112)+(G34*28)+H34 -> 0 | L34: =J34/2240 -> 0
A35: 1755 | B35: Rum | C35: Mountserat | D35: London | H35: 38270 | I35: 3826g | J35: =(E35*2240)+(F35*112)+(G35*28)+H35 -> 38270 | L35: =J35/2240 -> 17.084821
A36: 1755 | B36: Sarsparila | C36: Mountserat | D36: London | J36: =(E36*2240)+(F36*112)+(G36*28)+H36 -> 0 | L36: =J36/2240 -> 0
A37: 1755 | B37: Shruff | C37: Mountserat | D37: London | J37: =(E37*2240)+(F37*112)+(G37*28)+H37 -> 0 | L37: =J37/2240 -> 0
A38: 1755 | B38: Snuff | C38: Mountserat | D38: London | J38: =(E38*2240)+(F38*112)+(G38*28)+H38 -> 0 | L38: =J38/2240 -> 0
A39: 1755 | B39: Succads | C39: Mountserat | D39: London | H39: 63 | J39: =(E39*2240)+(F39*112)+(G39*28)+H39 -> 63 | L39: =J39/2240 -> 0.028125
A40: 1755 | B40: Tobacco | C40: Mountserat | D40: London | J40: =(E40*2240)+(F40*112)+(G40*28)+H40 -> 0 | L40: =J40/2240 -> 0
...

Sheet Nevis
A1: YEAR | B1: COMMODITY_NAME | C1: FROM_LOCATION | D1: TO_LOCATION | E1: ton | F1: hh | G1: quarter | H1: lb | J1: Total Pounds | L1: WEIGHT
A2: 1755 | B2: Almonds, Bitter | C2: Nevis | D2: London | J2: =(E2*2240)+(F2*112)+(G2*28)+H2 -> 0 | L2: =J2/2240 -> 0
A3: 1755 | B3: Almonds, Sweet | C3: Nevis | D3: London | J3: =(E3*2240)+(F3*112)+(G3*28)+H3 -> 0 | L3: =J3/2240 -> 0
A4: 1755 | B4: Aloes Epatica | C4: Nevis | D4: London | J4: =(E4*2240)+(F4*112)+(G4*28)+H4 -> 0 | L4: =J4/2240 -> 0
A5: 1755 | B5: Annatto | C5: Nevis | D5: London | J5: =(E5*2240)+(F5*112)+(G5*28)+H5 -> 0 | L5: =J5/2240 -> 0
A6: 1755 | B6: Anniseeds | C6: Nevis | D6: London | J6: =(E6*2240)+(F6*112)+(G6*28)+H6 -> 0 | L6: =J6/2240 -> 0
A7: 1755 | B7: Bacon | C7: Nevis | D7: London | J7: =(E7*2240)+(F7*112)+(G7*28)+H7 -> 0 | L7: =J7/2240 -> 0
A8: 1755 | B8: Barrel Staves | C8: Nevis | D8: London | J8: =(E8*2240)+(F8*112)+(G8*28)+H8 -> 0 | L8: =J8/2240 -> 0
A9: 1755 | B9: Bees Wax | C9: Nevis | D9: London | J9: =(E9*2240)+(F9*112)+(G9*28)+H9 -> 0 | L9: =J9/2240 -> 0
A10: 1755 | B10: Brimstone | C10: Nevis | D10: London | J10: =(E10*2240)+(F10*112)+(G10*28)+H10 -> 0 | L10: =J10/2240 -> 0
A11: 1755 | B11: Brown Sugar | C11: Nevis | D11: London | F11: 48710 | G11: 0 | H11: 11 | J11: =(E11*2240)+(F11*112)+(G11*28)+H11 -> 5455531 | L11: =J11/2240 -> 2435.5049
A12: 1755 | B12: Cassia Fistula | C12: Nevis | D12: London | J12: =(E12*2240)+(F12*112)+(G12*28)+H12 -> 0 | L12: =J12/2240 -> 0
A13: 1755 | B13: Chocolate Paste | C13: Nevis | D13: London | J13: =(E13*2240)+(F13*112)+(G13*28)+H13 -> 0 | L13: =J13/2240 -> 0
A14: 1755 | B14: Cocheneal | C14: Nevis | D14: London | J14: =(E14*2240)+(F14*112)+(G14*28)+H14 -> 0 | L14: =J14/2240 -> 0
A15: 1755 | B15: Cocoa Nuts | C15: Nevis | D15: London | J15: =(E15*2240)+(F15*112)+(G15*28)+H15 -> 0 | L15: =J15/2240 -> 0
A16: 1755 | B16: Cocoa Paste | C16: Nevis | D16: London | J16: =(E16*2240)+(F16*112)+(G16*28)+H16 -> 0 | L16: =J16/2240 -> 0
A17: 1755 | B17: Cortex Winteranus | C17: Nevis | D17: London | J17: =(E17*2240)+(F17*112)+(G17*28)+H17 -> 0 | L17: =J17/2240 -> 0
A18: 1755 | B18: Cotton | C18: Nevis | D18: London | H18: =26*200 -> 5200 | I18: 26 bags | J18: =(E18*2240)+(F18*112)+(G18*28)+H18 -> 5200 | L18: =J18/2240 -> 2.3214286
A19: 1755 | B19: Dry Ginger | C19: Nevis | D19: London | F19: 6 | G19: 3 | H19: 21 | J19: =(E19*2240)+(F19*112)+(G19*28)+H19 -> 777 | L19: =J19/2240 -> 0.346875
A20: 1755 | B20: Elephant Teeth | C20: Nevis | D20: London | J20: =(E20*2240)+(F20*112)+(G20*28)+H20 -> 0 | L20: =J20/2240 -> 0
A21: 1755 | B21: Green Ginger | C21: Nevis | D21: London | J21: =(E21*2240)+(F21*112)+(G21*28)+H21 -> 0 | L21: =J21/2240 -> 0
A22: 1755 | B22: Hemp | C22: Nevis | D22: London | J22: =(E22*2240)+(F22*112)+(G22*28)+H22 -> 0 | L22: =J22/2240 -> 0
A23: 1755 | B23: Indigo | C23: Nevis | D23: London | J23: =(E23*2240)+(F23*112)+(G23*28)+H23 -> 0 | L23: =J23/2240 -> 0
A24: 1755 | B24: Lemon Water | C24: Nevis | D24: London | J24: =(E24*2240)+(F24*112)+(G24*28)+H24 -> 0 | L24: =J24/2240 -> 0
A25: 1755 | B25: Lignum Vitae | C25: Nevis | D25: London | J25: =(E25*2240)+(F25*112)+(G25*28)+H25 -> 0 | L25: =J25/2240 -> 0
A26: 1755 | B26: Lime Juice | C26: Nevis | D26: London | J26: =(E26*2240)+(F26*112)+(G26*28)+H26 -> 0 | L26: =J26/2240 -> 0
A27: 1755 | B27: Loaf Sugar | C27: Nevis | D27: London | J27: =(E27*2240)+(F27*112)+(G27*28)+H27 -> 0 | L27: =J27/2240 -> 0
A28: 1755 | B28: Madera Wine | C28: Nevis | D28: London | H28: 91543 | I28: 42t 1h 28g | J28: =(E28*2240)+(F28*112)+(G28*28)+H28 -> 91543 | L28: =J28/2240 -> 40.867411
A29: 1755 | B29: Molasses | C29: Nevis | D29: London | J29: =(E29*2240)+(F29*112)+(G29*28)+H29 -> 0 | L29: =J29/2240 -> 0
A30: 1755 | B30: Oranges | C30: Nevis | D30: London | J30: =(E30*2240)+(F30*112)+(G30*28)+H30 -> 0 | L30: =J30/2240 -> 0
A31: 1755 | B31: Pickles | C31: Nevis | D31: London | J31: =(E31*2240)+(F31*112)+(G31*28)+H31 -> 0 | L31: =J31/2240 -> 0
A32: 1755 | B32: Pimento | C32: Nevis | D32: London | J32: =(E32*2240)+(F32*112)+(G32*28)+H32 -> 0 | L32: =J32/2240 -> 0
A33: 1755 | B33: Rice | C33: Nevis | D33: London | J33: =(E33*2240)+(F33*112)+(G33*28)+H33 -> 0 | L33: =J33/2240 -> 0
A34: 1755 | B34: Rum | C34: Nevis | D34: London | H34: 26577 | I34: 2657g | J34: =(E34*2240)+(F34*112)+(G34*28)+H34 -> 26577 | L34: =J34/2240 -> 11.864732
A35: 1755 | B35: Sarsparila | C35: Nevis | D35: London | J35: =(E35*2240)+(F35*112)+(G35*28)+H35 -> 0 | L35: =J35/2240 -> 0
A36: 1755 | B36: Shruff | C36: Nevis | D36: London | J36: =(E36*2240)+(F36*112)+(G36*28)+H36 -> 0 | L36: =J36/2240 -> 0
A37: 1755 | B37: Snuff | C37: Nevis | D37: London | J37: =(E37*2240)+(F37*112)+(G37*28)+H37 -> 0 | L37: =J37/2240 -> 0
A38: 1755 | B38: Succads | C38: Nevis | D38: London | H38: 75 | J38: =(E38*2240)+(F38*112)+(G38*28)+H38 -> 75 | L38: =J38/2240 -> 0.033482143
A39: 1755 | B39: Tamerinds | C39: Nevis | D39: London | H39: 9 | J39: =(E39*2240)+(F39*112)+(G39*28)+H39 -> 9 | L39: =J39/2240 -> 0.0040178571
A40: 1755 | B40: Tobacco | C40: Nevis | D40: London | J40: =(E40*2240)+(F40*112)+(G40*28)+H40 -> 0 | L40: =J40/2240 -> 0
...

Sheet St Kitts
A1: YEAR | B1: COMMODITY_NAME | C1: FROM_LOCATION | D1: TO_LOCATION | E1: ton | F1: hh | G1: quarter | H1: lb | J1: Total Pounds | L1: WEIGHT
A2: 1755 | B2: Almonds, Bitter | C2: StKitts | D2: London | J2: =(E2*2240)+(F2*112)+(G2*28)+H2 -> 0 | L2: =J2/2240 -> 0
A3: 1755 | B3: Almonds, Sweet | C3: StKitts | D3: London | J3: =(E3*2240)+(F3*112)+(G3*28)+H3 -> 0 | L3: =J3/2240 -> 0
A4: 1755 | B4: Aloes Epatica | C4: StKitts | D4: London | J4: =(E4*2240)+(F4*112)+(G4*28)+H4 -> 0 | L4: =J4/2240 -> 0
A5: 1755 | B5: Annatto | C5: StKitts | D5: London | J5: =(E5*2240)+(F5*112)+(G5*28)+H5 -> 0 | L5: =J5/2240 -> 0
A6: 1755 | B6: Anniseeds | C6: StKitts | D6: London | J6: =(E6*2240)+(F6*112)+(G6*28)+H6 -> 0 | L6: =J6/2240 -> 0
A7: 1755 | B7: Bacon | C7: StKitts | D7: London | J7: =(E7*2240)+(F7*112)+(G7*28)+H7 -> 0 | L7: =J7/2240 -> 0
A8: 1755 | B8: Barrel Staves | C8: StKitts | D8: London | J8: =(E8*2240)+(F8*112)+(G8*28)+H8 -> 0 | L8: =J8/2240 -> 0
A9: 1755 | B9: Bees Wax | C9: StKitts | D9: London | J9: =(E9*2240)+(F9*112)+(G9*28)+H9 -> 0 | L9: =J9/2240 -> 0
A10: 1755 | B10: Brimstone | C10: StKitts | D10: London | J10: =(E10*2240)+(F10*112)+(G10*28)+H10 -> 0 | L10: =J10/2240 -> 0
A11: 1755 | B11: Brown Sugar | C11: StKitts | D11: London | F11: 161591 | G11: 3 | H11: 9 | J11: =(E11*2240)+(F11*112)+(G11*28)+H11 -> 18098285 | L11: =J11/2240 -> 8079.5915
A12: 1755 | B12: Cassia Fistula | C12: StKitts | D12: London | J12: =(E12*2240)+(F12*112)+(G12*28)+H12 -> 0 | L12: =J12/2240 -> 0
A13: 1755 | B13: Chocolate Paste | C13: StKitts | D13: London | J13: =(E13*2240)+(F13*112)+(G13*28)+H13 -> 0 | L13: =J13/2240 -> 0
A14: 1755 | B14: Cocheneal | C14: StKitts | D14: London | J14: =(E14*2240)+(F14*112)+(G14*28)+H14 -> 0 | L14: =J14/2240 -> 0
A15: 1755 | B15: Cocoa Nuts | C15: StKitts | D15: London | J15: =(E15*2240)+(F15*112)+(G15*28)+H15 -> 0 | L15: =J15/2240 -> 0
A16: 1755 | B16: Cocoa Paste | C16: StKitts | D16: London | J16: =(E16*2240)+(F16*112)+(G16*28)+H16 -> 0 | L16: =J16/2240 -> 0
A17: 1755 | B17: Copper Ore | C17: StKitts | D17: London | F17: 300 | J17: =(E17*2240)+(F17*112)+(G17*28)+H17 -> 33600 | L17: =J17/2240 -> 15
A18: 1755 | B18: Cortex Winteranus | C18: StKitts | D18: London | J18: =(E18*2240)+(F18*112)+(G18*28)+H18 -> 0 | L18: =J18/2240 -> 0
A19: 1755 | B19: Cotton | C19: StKitts | D19: London | H19: =266*200 -> 53200 | I19: 266 bags | J19: =(E19*2240)+(F19*112)+(G19*28)+H19 -> 53200 | L19: =J19/2240 -> 23.75
A20: 1755 | B20: Dry Ginger | C20: StKitts | D20: London | F20: 60 | G20: 1 | H20: 14 | J20: =(E20*2240)+(F20*112)+(G20*28)+H20 -> 6762 | L20: =J20/2240 -> 3.01875
A21: 1755 | B21: Elephant Teeth | C21: StKitts | D21: London | F21: 64 | G21: 3 | J21: =(E21*2240)+(F21*112)+(G21*28)+H21 -> 7252 | L21: =J21/2240 -> 3.2375
A22: 1755 | B22: Green Ginger | C22: StKitts | D22: London | H22: 62 | J22: =(E22*2240)+(F22*112)+(G22*28)+H22 -> 62 | L22: =J22/2240 -> 0.027678571
A23: 1755 | B23: Hemp | C23: StKitts | D23: London | J23: =(E23*2240)+(F23*112)+(G23*28)+H23 -> 0 | L23: =J23/2240 -> 0
A24: 1755 | B24: Indigo | C24: StKitts | D24: London | H24: 500 | J24: =(E24*2240)+(F24*112)+(G24*28)+H24 -> 500 | L24: =J24/2240 -> 0.22321429
A25: 1755 | B25: Lemon Water | C25: StKitts | D25: London | J25: =(E25*2240)+(F25*112)+(G25*28)+H25 -> 0 | L25: =J25/2240 -> 0
A26: 1755 | B26: Lignum Vitae | C26: StKitts | D26: London | E26: 6 | J26: =(E26*2240)+(F26*112)+(G26*28)+H26 -> 13440 | L26: =J26/2240 -> 6
A27: 1755 | B27: Lime Juice | C27: StKitts | D27: London | J27: =(E27*2240)+(F27*112)+(G27*28)+H27 -> 0 | L27: =J27/2240 -> 0
A28: 1755 | B28: Loaf Sugar | C28: StKitts | D28: London | J28: =(E28*2240)+(F28*112)+(G28*28)+H28 -> 0 | L28: =J28/2240 -> 0
A29: 1755 | B29: Madera Wine | C29: StKitts | D29: London | H29: 161841 | I29: 74t 3h 40g | J29: =(E29*2240)+(F29*112)+(G29*28)+H29 -> 161841 | L29: =J29/2240 -> 72.250446
A30: 1755 | B30: Molasses | C30: StKitts | D30: London | J30: =(E30*2240)+(F30*112)+(G30*28)+H30 -> 0 | L30: =J30/2240 -> 0
A31: 1755 | B31: Oranges | C31: StKitts | D31: London | J31: =(E31*2240)+(F31*112)+(G31*28)+H31 -> 0 | L31: =J31/2240 -> 0
A32: 1755 | B32: Pickles | C32: StKitts | D32: London | H32: 25 | I32: 2.5g | J32: =(E32*2240)+(F32*112)+(G32*28)+H32 -> 25 | L32: =J32/2240 -> 0.011160714
A33: 1755 | B33: Pimento | C33: StKitts | D33: London | H33: 300 | J33: =(E33*2240)+(F33*112)+(G33*28)+H33 -> 300 | L33: =J33/2240 -> 0.13392857
A34: 1755 | B34: Port | C34: StKitts | D34: London | H34: 18995 | I34: 8t 3h 15g | J34: =(E34*2240)+(F34*112)+(G34*28)+H34 -> 18995 | L34: =J34/2240 -> 8.4799107
A35: 1755 | B35: Rice | C35: StKitts | D35: London | J35: =(E35*2240)+(F35*112)+(G35*28)+H35 -> 0 | L35: =J35/2240 -> 0
A36: 1755 | B36: Rum | C36: StKitts | D36: London | H36: 126522 | I36: 12649g | J36: =(E36*2240)+(F36*112)+(G36*28)+H36 -> 126522 | L36: =J36/2240 -> 56.483036
A37: 1755 | B37: Sarsparila | C37: StKitts | D37: London | J37: =(E37*2240)+(F37*112)+(G37*28)+H37 -> 0 | L37: =J37/2240 -> 0
A38: 1755 | B38: Shruff | C38: StKitts | D38: London | F38: 1 | G38: 1 | J38: =(E38*2240)+(F38*112)+(G38*28)+H38 -> 140 | L38: =J38/2240 -> 0.0625
A39: 1755 | B39: Snuff | C39: StKitts | D39: London | J39: =(E39*2240)+(F39*112)+(G39*28)+H39 -> 0 | L39: =J39/2240 -> 0
A40: 1755 | B40: Succads | C40: StKitts | D40: London | H40: 448 | J40: =(E40*2240)+(F40*112)+(G40*28)+H40 -> 448 | L40: =J40/2240 -> 0.2
...

Sheet Tortola
A1: YEAR | B1: COMMODITY_NAME | C1: FROM_LOCATION | D1: TO_LOCATION | E1: ton | F1: hh | G1: quarter | H1: lb | J1: Total Pounds | L1: WEIGHT
A2: 1755 | B2: Almonds, Bitter | C2: Tortola | D2: London | J2: =(E2*2240)+(F2*112)+(G2*28)+H2 -> 0 | L2: =J2/2240 -> 0
A3: 1755 | B3: Almonds, Sweet | C3: Tortola | D3: London | J3: =(E3*2240)+(F3*112)+(G3*28)+H3 -> 0 | L3: =J3/2240 -> 0
A4: 1755 | B4: Aloes Epatica | C4: Tortola | D4: London | J4: =(E4*2240)+(F4*112)+(G4*28)+H4 -> 0 | L4: =J4/2240 -> 0
A5: 1755 | B5: Annatto | C5: Tortola | D5: London | J5: =(E5*2240)+(F5*112)+(G5*28)+H5 -> 0 | L5: =J5/2240 -> 0
